Workbook
Name _1: #REF!
Name _1: #REF!
Name _1: #REF!
Name _1: #REF!
Name _1: #REF!
Name _1: #REF!
Name _1: #REF!
Name _1: #REF!
Name _2: #REF!
Name _2: #REF!
Name _2: #REF!
Name _2: #REF!
Name _2: #REF!
Name _2: #REF!
Name _2: #REF!
Name _2: #REF!
Name _3: #REF!
Name _3: #REF!
Name _3: #REF!
Name _3: #REF!
Name _3: #REF!
Name _3: #REF!
Name _3: #REF!
Name _4: #REF!
Name _4: #REF!
Name a: #REF!
Name a: #REF!
Name a: #REF!
Name a: #REF!
Name AA: #REF!
Name AA: #REF!
Name AA: #REF!
Name AB: #REF!
Name AB: #REF!
Name AB: #REF!
Name AC: #REF!
Name AC: #REF!
Name AD: #REF!
Name AD: #REF!
Name AE: #REF!
Name AE: #REF!
Name AF: #REF!
Name AF: #REF!
Name AG: #REF!
Name AG: #REF!
Name AH: #REF!
Name AH: #REF!
Name AI: #REF!
Name AI: #REF!
Name AK: #REF!
Name AK: #REF!
Name AL: #REF!
Name AL: #REF!
Name AM: #REF!
Name AM: #REF!
Name AN: #REF!
Name AN: #REF!
Name AS: #REF!
Name AS: #REF!
Name CL: #REF!

Sheet Maj Production Summ
B1: MAJOR PRODUCTION SUMMARY | D1: 341.01687 | E1: 29 | F1: =F2-'B-FCE'!F3 -> 26.666667 | G1: 30 | H1: =H2-'B-FCE'!H3 -> 29.791667 | I1: =E1+G1 -> 59 | J1: =F1+H1 -> 56.458333 | K1: 29 | L1: =L2-'B-FCE'!L3 -> 29.61125 | M1: =+E1+G1+K1 -> 88 | N1: =+F1+H1+L1 -> 86.069583 | O1: 30 | P1: =P2-'B-FCE'!P3 -> 31 | Q1: =+M1+O1 -> 118 | R1: =+N1+P1 -> 117.06958 | S1: 30 | T1: =T2-'B-FCE'!T3 -> 30.024306 | U1: =+Q1+S1 -> 148 | V1: =+R1+T1 -> 147.09389 | W1: 17.016867 | X1: =X2-'B-FCE'!X3 -> 29.67375 | Y1: =+O1+S1+W1 -> 77.016867 | Z1: =+P1+T1+X1 -> 90.698056 | AA1: =+U1+W1 -> 165.01687 | AB1: =+V1+X1 -> 176.76764 | AC1: 30 | AD1: =AD2-'B-FCE'!AD3-2 -> 24.930556 | AE1: =AA1+AC1 -> 195.01687 | AF1: =AB1+AD1 -> 201.69819 | AG1: 29 | AH1: =AH2-'B-FCE'!AH3 -> 29.1075 | AI1: =AE1+AG1 -> 224.01687 | AJ1: =AF1+AH1 -> 230.80569 | AK1: 30 | AL1: =31-'B-FCE'!AL3 -> 30.697917 | AM1: =+AC1+AG1+AK1 -> 89 | AN1: =+AD1+AH1+AL1 -> 84.735972 | AO1: =AI1+AK1 -> 254.01687 | AP1: =AJ1+AL1 -> 261.50361 | AQ1: 30 | AR1: =31-'B-FCE'!AR3 -> 30.413194 | AS1: =AO1+AQ1 -> 284.01687 | AT1: =AP1+AR1 -> 291.91681 | AU1: 27 | AV1: =28-'B-FCE'!AV3 -> 27.57625 | AW1: =AS1+AU1 -> 311.01687 | AX1: =AT1+AV1 -> 319.49306 | AY1: 30 | AZ1: =31-'B-FCE'!AZ3 -> 29.972222 | BA1: =+AQ1+AU1+AY1 -> 87 | BB1: =+AR1+AV1+AZ1 -> 87.961667 | BC1: =+AM1+BA1 -> 176 | BD1: =+AN1+BB1 -> 172.69764 | BE1: =AW1+AY1 -> 341.01687 | BF1: =AX1+AZ1 -> 349.46528
D2: 365 | E2: 30 | F2: 30 | G2: 31 | H2: 31 | I2: =+E2+G2 -> 61 | J2: =+F2+H2 -> 61 | K2: 30 | L2: 30 | M2: =+I2+K2 -> 91 | N2: =+J2+L2 -> 91 | O2: 31 | P2: 31 | Q2: =+M2+O2 -> 122 | R2: =+N2+P2 -> 122 | S2: 31 | T2: 31 | U2: =+Q2+S2 -> 153 | V2: =+R2+T2 -> 153 | W2: 30 | X2: 30 | Y2: =+O2+S2+W2 -> 92 | Z2: =+P2+T2+X2 -> 92 | AA2: =+U2+W2 -> 183 | AB2: =+V2+X2 -> 183 | AC2: 31 | AD2: 31 | AE2: =AA2+AC2 -> 214 | AF2: =AB2+AD2 -> 214 | AG2: 30 | AH2: 30 | AI2: =AE2+AG2 -> 244 | AJ2: =AF2+AH2 -> 244 | AK2: 31 | AL2: 31 | AM2: =+AC2+AG2+AK2 -> 92 | AN2: =+AD2+AH2+AL2 -> 92 | AO2: =AI2+AK2 -> 275 | AP2: =AJ2+AL2 -> 275 | AQ2: 31 | AR2: 31 | AS2: =AO2+AQ2 -> 306 | AT2: =AP2+AR2 -> 306 | AU2: 28 | AV2: 28 | AW2: =AS2+AU2 -> 334 | AX2: =AT2+AV2 -> 334 | AY2: 31 | AZ2: 31 | BA2: =+AQ2+AU2+AY2 -> 90 | BB2: =+AR2+AV2+AZ2 -> 90 | BC2: =+AM2+BA2 -> 182 | BD2: =+AN2+BB2 -> 182 | BE2: =AW2+AY2 -> 365 | BF2: =AX2+AZ2 -> 365 | BN2: 365 | BO2: 365 | BP2: 366 | BQ2: 366
A3: 1000 | B3: ITEM | C3: Unit | D3: 2025-26 ABP | E3: Apr'25 | G3: May'25 | I3: 2M | K3: Jun'25 | M3: QTR-1 | O3: Jul'25 | Q3: 4M | S3: Aug'25 | U3: 5M | W3: Sep'25 | Y3: QTR 2 | AA3: H1 | AC3: Oct'25 | AE3: 7M | AG3: Nov'25 | AI3: 8M | AK3: Dec'25 | AM3: QTR 3 | AO3: 9M | AQ3: Jan'26 | AS3: 10M | AU3: Feb'26 | AW3: 11M | AY3: Mar'26 | BA3: QTR 4 | BC3: H2 | BE3: 2025-26 | BG3: 2024-25 | BI3: 2023-24 | BK3: 2022-23 | BL3: 2021-22 | BN3: 2020-21 | BP3: 2019-20
E4: ABP | F4: ACT | G4: ABP | H4: ACT | I4: ABP | J4: ACT | K4: ABP | L4: ACT | M4: ABP | N4: ACT | O4: ABP | P4: ACT | Q4: ABP | R4: ACT | S4: ABP | T4: ACT | U4: ABP | V4: ACT | W4: ABP | X4: ACT | Y4: ABP | Z4: ACT | AA4: ABP | AB4: ACT | AC4: ABP | AD4: ACT | AE4: ABP | AF4: ACT | AG4: ABP | AH4: ACT | AI4: ABP | AJ4: ACT | AK4: ABP | AL4: ACT | AM4: ABP | AN4: ACT | AO4: ABP | AP4: ACT | AQ4: ABP | AR4: ACT | AS4: ABP | AT4: ACT | AU4: ABP | AV4: ACT | AW4: ABP | AX4: ACT | AY4: ABP | AZ4: ACT | BA4: ABP | BB4: ACT | BC4: ABP | BD4: ACT | BE4: ABP | BF4: ACT | BG4: ABP | BH4: ACT | BI4: ABP | BJ4: ACT | BK4: ACT | BL4: ABP | BM4: ACT | BN4: ABP | BO4: ACT | BP4: ABP | BQ4: ACT
B5: COKE OVENS PUSHING
B6: (COB#10) | C6: Nos/ day | D6: 94.512329 | E6: 98 | F6: =+F9/F2 -> 97.2 | G6: 98 | H6: =+H9/H2 -> 97.612903 | I6: =+((E6*$E$2)+(G6*$G$2))/$I$2 -> 98 | J6: =+((F6*$F$2)+(H6*$H$2))/$J$2 -> 97.409836 | K6: 94 | L6: =+L9/L2 -> 96.066667 | M6: =+((E6*$E$2)+(G6*$G$2)+(K6*$K$2))/$M$2 -> 96.681319 | N6: =+((F6*$F$2)+(H6*$H$2)+(L6*$L$2))/$N$2 -> 96.967033 | O6: 94 | P6: =+P9/P2 -> 95.419355 | Q6: =+((M6*M$2)+(O6*O$2))/Q$2 -> 96 | R6: =+((N6*N$2)+(P6*P$2))/R$2 -> 96.57377 | S6: 94 | T6: =+T9/T2 -> 98 | U6: =+((Q6*Q$2)+(S6*S$2))/U$2 -> 95.594771 | V6: =+((R6*R$2)+(T6*T$2))/V$2 -> 96.862745 | W6: 92.1 | X6: =+X9/X2 -> 98 | Y6: =+((O$6*O$2)+(S$6*S$2)+(W$6*W$2))/Y$2 -> 93.380435 | Z6: =+((P$6*P$2)+(T$6*T$2)+(X$6*X$2))/Z$2 -> 97.130435 | AA6: =+((M6*M$2)+(Y6*Y$2))/AA$2 -> 95.021858 | AB6: =+((N6*N$2)+(Z6*Z$2))/AB$2 -> 97.04918 | AC6: 94 | AD6: =+AD9/AD2 -> 96.548387 | AE6: =+((AA6*$AA$2)+(AC6*$AC$2))/$AE$2 -> 94.873832 | AF6: =+((AB6*$AB$2)+(AD6*$AD$2))/$AF$2 -> 96.976636 | AG6: 94 | AH6: =+AH9/AH2 -> 94.233333 | AI6: =+((AE6*$AE$2)+(AG6*$AG$2))/$AI$2 -> 94.766393 | AJ6: =+((AF6*$AF$2)+(AH6*$AH$2))/$AJ$2 -> 96.639344 | AK6: 94 | AL6: =+AL9/AL2 -> 94.096774 | AM6: =+((AC$6*AC$2)+(AG$6*AG$2)+(AK$6*AK$2))/AM$2 -> 94 | AN6: =+((AD$6*AD$2)+(AH$6*AH$2)+(AL$6*AL$2))/AN$2 -> 94.967391 | AO6: =+((AK6*$AK$2)+(AI6*$AI$2))/$AO$2 -> 94.68 | AP6: =+((AL6*$AL$2)+(AJ6*$AJ$2))/$AP$2 -> 96.352727 | AQ6: 94 | AR6: =+AR9/AR2 -> 94.83871 | AS6: =+((AO6*$AO$2)+(AQ6*$AQ$2))/$AS$2 -> 94.611111 | AT6: =+((AP6*$AP$2)+(AR6*$AR$2))/$AT$2 -> 96.199346 | AU6: 94 | AV6: =+AV9/AV2 -> 94.428571 | AW6: =+((AS6*$AS$2)+(AU6*$AU$2))/$AW$2 -> 94.55988 | AX6: =+((AT6*$AT$2)+(AV6*$AV$2))/$AX$2 -> 96.050898 | AY6: 94 | AZ6: =+AZ9/AZ2 -> 98 | BA6: =+((AQ$6*AQ$2)+(AU$6*AU$2)+(AY$6*AY$2))/BA$2 -> 94 | BB6: =+((AR$6*AR$2)+(AV$6*AV$2)+(AZ$6*AZ$2))/BB$2 -> 95.8 | BC6: =+((AM6*AM$2)+(BA6*BA$2))/BC$2 -> 94 | BD6: =+((AN6*AN$2)+(BB6*BB$2))/BD$2 -> 95.379121 | BE6: =+((AW6*$AW$2)+(AY6*$AY$2))/$BE$2 -> 94.512329 | BF6: =+((AZ6*$AZ$2)+(AX6*$AX$2))/$BF$2 -> 96.216438 | BG6: 96.420548 | BH6: 97.709589 | BI6: 99 | BJ6: 98.976067 | BK6: 98.783562 | BL6: 99 | BM6: 97.824658 | BN6: 95.547945 | BO6: 95.342466 | BP6: 97 | BQ6: 97.10959
B7: (COB#11) | C7: Nos/ day | D7: 97.630137 | E7: 98 | F7: =+F10/F2 -> 97.1 | G7: 98 | H7: =+H10/H2 -> 97.483871 | I7: =+((E7*$E$2)+(G7*$G$2))/$I$2 -> 98 | J7: =+((F7*$F$2)+(H7*$H$2))/$J$2 -> 97.295082 | K7: 98 | L7: =+L10/L2 -> 98.466667 | M7: =+((E7*$E$2)+(G7*$G$2)+(K7*$K$2))/$M$2 -> 98 | N7: =+((F7*$F$2)+(H7*$H$2)+(L7*$L$2))/$N$2 -> 97.681319 | O7: 98 | P7: =+P10/P2 -> 99 | Q7: =+((M7*M$2)+(O7*O$2))/Q$2 -> 98 | R7: =+((N7*N$2)+(P7*P$2))/R$2 -> 98.016393 | S7: 98 | T7: =+T10/T2 -> 98.516129 | U7: =+((Q7*Q$2)+(S7*S$2))/U$2 -> 98 | V7: =+((R7*R$2)+(T7*T$2))/V$2 -> 98.117647 | W7: 93.5 | X7: =+X10/X2 -> 98.766667 | Y7: =((O7*O2)+(S7*S2)+(W7*W2))/Y2 -> 96.532609 | Z7: =+((P$7*P$2)+(T$7*T$2)+(X$7*X$2))/Z$2 -> 98.76087 | AA7: =+((M7*M$2)+(Y7*Y$2))/AA$2 -> 97.262295 | AB7: =+((N7*N$2)+(Z7*Z$2))/AB$2 -> 98.224044 | AC7: 98 | AD7: =+AD10/AD2 -> 97.193548 | AE7: =+((AA7*$AA$2)+(AC7*$AC$2))/$AE$2 -> 97.369159 | AF7: =+((AB7*$AB$2)+(AD7*$AD$2))/$AF$2 -> 98.074766 | AG7: 98 | AH7: =+AH10/AH2 -> 98.666667 | AI7: =+((AE7*$AE$2)+(AG7*$AG$2))/$AI$2 -> 97.446721 | AJ7: =+((AF7*$AF$2)+(AH7*$AH$2))/$AJ$2 -> 98.147541 | AK7: 98 | AL7: =+AL10/AL2 -> 98.741935 | AM7: =+((AC$7*AC$2)+(AG$7*AG$2)+(AK$7*AK$2))/AM$2 -> 98 | AN7: =+((AD$7*AD$2)+(AH$7*AH$2)+(AL$7*AL$2))/AN$2 -> 98.195652 | AO7: =+((AK7*$AK$2)+(AI7*$AI$2))/$AO$2 -> 97.509091 | AP7: =+((AL7*$AL$2)+(AJ7*$AJ$2))/$AP$2 -> 98.214545 | AQ7: 98 | AR7: =+AR10/AR2 -> 97.870968 | AS7: =+((AO7*$AO$2)+(AQ7*$AQ$2))/$AS$2 -> 97.558824 | AT7: =+((AP7*$AP$2)+(AR7*$AR$2))/$AT$2 -> 98.179739 | AU7: 98 | AV7: =+AV10/AV2 -> 98.035714 | AW7: =+((AS7*$AS$2)+(AU7*$AU$2))/$AW$2 -> 97.595808 | AX7: =+((AT7*$AT$2)+(AV7*$AV$2))/$AX$2 -> 98.167665 | AY7: 98 | AZ7: =+AZ10/AZ2 -> 98.677419 | BA7: =+((AQ$7*AQ$2)+(AU$7*AU$2)+(AY$7*AY$2))/BA$2 -> 98 | BB7: =+((AR$7*AR$2)+(AV$7*AV$2)+(AZ$7*AZ$2))/BB$2 -> 98.2 | BC7: =+((AM7*AM$2)+(BA7*BA$2))/BC$2 -> 98 | BD7: =+((AN7*AN$2)+(BB7*BB$2))/BD$2 -> 98.197802 | BE7: =+((AW7*$AW$2)+(AY7*$AY$2))/$BE$2 -> 97.630137 | BF7: =+((AZ7*$AZ$2)+(AX7*$AX$2))/$BF$2 -> 98.210959 | BG7: 98.167671 | BH7: 97.991781 | BI7: 98.000061 | BJ7: 96.670251 | BK7: 92.210959 | BL7: 99 | BM7: 96.816438 | BN7: 94.2 | BO7: 90.778082 | BP7: 97 | BQ7: 95.710246
B8: Overall Equiv. Ovens Pushed/ Day | C8: Nos/ day | D8: =+D6+(D7*(31.55/17.2)) -> 273.59552 | E8: =+E6+(E7*(31.55/17.2)) -> 277.76163 | F8: =+F6+(F7*(31.55/17.2)) -> 275.31076 | G8: =+G6+(G7*(31.55/17.2)) -> 277.76163 | H8: =+H6+(H7*(31.55/17.2)) -> 276.42779 | I8: =+I6+(I7*(31.55/17.2)) -> 277.76163 | J8: =+J6+(J7*(31.55/17.2)) -> 275.87843 | K8: =+K6+(K7*(31.55/17.2)) -> 273.76163 | ... X8: =+X6+(X7*(31.55/17.2)) -> 279.16793 | Y8: =Y6+(Y7*31.55/17.2) -> 270.45042 | Z8: =Z6+(Z7*31.55/17.2) -> 278.28773 | AA8: =AA6+(AA7*31.55/17.2) -> 273.43031 | AB8: =AB6+(AB7*31.55/17.2) -> 277.22177 | AC8: =+AC6+(AC7*(31.55/17.2)) -> 273.76163 | AD8: =+AD6+(AD7*(31.55/17.2)) -> 274.83074 | AE8: =+AE6+(AE7*(31.55/17.2)) -> 273.47831 | AF8: =+AF6+(AF7*(31.55/17.2)) -> 276.87541 | AG8: =+AG6+(AG7*(31.55/17.2)) -> 273.76163 | AH8: =+AH6+(AH7*(31.55/17.2)) -> 275.21783 | AI8: =+AI6+(AI7*(31.55/17.2)) -> 273.51314 | AJ8: =+AJ6+(AJ7*(31.55/17.2)) -> 276.67161 | ... AL8: =+AL6+(AL7*(31.55/17.2)) -> 275.21934 | AM8: =AM6+(AM7*31.55/17.2) -> 273.76163 | AN8: =AN6+(AN7*31.55/17.2) -> 275.0879 | AO8: =+AO6+(AO7*(31.55/17.2)) -> 273.54115 | AP8: =+AP6+(AP7*(31.55/17.2)) -> 276.5079 | AQ8: =+AQ6+(AQ7*(31.55/17.2)) -> 273.76163 | AR8: =+AR6+(AR7*(31.55/17.2)) -> 274.36365 | AS8: =+AS6+(AS7*(31.55/17.2)) -> 273.56349 | AT8: =+AT6+(AT7*(31.55/17.2)) -> 276.29067 | AU8: =+AU6+(AU7*(31.55/17.2)) -> 273.76163 | AV8: =+AV6+(AV7*(31.55/17.2)) -> 274.25571 | ... AZ8: =+AZ6+(AZ7*(31.55/17.2)) -> 279.00422 | BA8: =BA6+(BA7*31.55/17.2) -> 273.76163 | BB8: =BB6+(BB7*31.55/17.2) -> 275.92849 | BC8: =BC6+(BC7*31.55/17.2) -> 273.76163 | BD8: =BD6+(BD7*31.55/17.2) -> 275.50358 | BE8: =+BE6+(BE7*(31.55/17.2)) -> 273.59552 | BF8: =+BF6+(BF7*(31.55/17.2)) -> 276.36503 | BG8: 276.48974 | BH8: 277.45614 | BI8: 278.76174 | BJ8: 276.29853 | BK8: 267.92634 | BL8: 280.59593 | BM8: 275.41528 | BN8: 268.33922 | BO8: 261.85691 | BP8: 274.92733 | BQ8: 272.67112
B9: (COB#10) | C9: Nos | D9: =+D6*D2 -> 34497 | E9: =+E6*E2 -> 2940 | F9: 2916 | G9: =+G6*G2 -> 3038 | H9: 3026 | I9: =+I6*I2 -> 5978 | J9: =+F9+H9 -> 5942 | K9: =+K6*K2 -> 2820 | L9: 2882 | M9: =+E9+G9+K9 -> 8798 | N9: =+F9+H9+L9 -> 8824 | O9: =+O6*O2 -> 2914 | P9: 2958 | Q9: =+M9+O9 -> 11712 | R9: =+N9+P9 -> 11782 | S9: =+S6*S2 -> 2914 | T9: 3038 | U9: =+Q9+S9 -> 14626 | V9: =+R9+T9 -> 14820 | W9: =+W6*W2 -> 2763 | X9: 2940 | Y9: =+O9+S9+W9 -> 8591 | Z9: =+P9+T9+X9 -> 8936 | AA9: =M9+Y9 -> 17389 | AB9: =+N9+Z9 -> 17760 | AC9: =+AC6*AC2 -> 2914 | AD9: 2993 | AE9: =+AE6*AE2 -> 20303 | AF9: =+AB9+AD9 -> 20753 | AG9: =+AG6*AG2 -> 2820 | AH9: 2827 | AI9: =+AI6*AI2 -> 23123 | AJ9: =+AF9+AH9 -> 23580 | AK9: =+AK6*AK2 -> 2914 | AL9: 2917 | AM9: =+AC9+AG9+AK9 -> 8648 | AN9: =+AD9+AH9+AL9 -> 8737 | AO9: =AI9+AK9 -> 26037 | AP9: =AJ9+AL9 -> 26497 | AQ9: =+AQ6*AQ2 -> 2914 | AR9: 2940 | AS9: =+AS6*AS2 -> 28951 | AT9: =+AP9+AR9 -> 29437 | AU9: =+AU6*AU2 -> 2632 | AV9: 2644 | AW9: =+AW6*AW2 -> 31583 | AX9: =+AT9+AV9 -> 32081 | AY9: =+AY6*AY2 -> 2914 | AZ9: 3038 | BA9: =+AQ9+AU9+AY9 -> 8460 | BB9: =+AR9+AV9+AZ9 -> 8622 | BC9: =AM9+BA9 -> 17108 | BD9: =AN9+BB9 -> 17359 | BE9: =AW9+AY9 -> 34497 | BF9: =AX9+AZ9 -> 35119 | BG9: 35193.5 | BH9: 35664 | BI9: 36234 | BJ9: 36225 | BK9: 36056 | BL9: 36135 | BM9: 35706 | BN9: 34875 | BO9: 34800 | BP9: 35502 | BQ9: 35543
B10: (COB#11) | C10: Nos | D10: =+D7*D2 -> 35635 | E10: =+E7*E2 -> 2940 | F10: 2913 | G10: =+G7*G2 -> 3038 | H10: 3022 | I10: =+I7*I2 -> 5978 | J10: =+F10+H10 -> 5935 | K10: =+K7*K2 -> 2940 | L10: 2954 | M10: =+E10+G10+K10 -> 8918 | N10: =+F10+H10+L10 -> 8889 | O10: =+O7*O2 -> 3038 | P10: 3069 | Q10: =+M10+O10 -> 11956 | R10: =+N10+P10 -> 11958 | S10: =+S7*S2 -> 3038 | T10: 3054 | U10: =+Q10+S10 -> 14994 | V10: =+R10+T10 -> 15012 | W10: =+W7*W2 -> 2805 | X10: 2963 | Y10: =+O10+S10+W10 -> 8881 | Z10: =+P10+T10+X10 -> 9086 | AA10: =+M10+Y10 -> 17799 | AB10: =+N10+Z10 -> 17975 | AC10: =+AC7*AC2 -> 3038 | AD10: 3013 | AE10: =+AE7*AE2 -> 20837 | AF10: =+AB10+AD10 -> 20988 | AG10: =+AG7*AG2 -> 2940 | AH10: 2960 | AI10: =+AI7*AI2 -> 23777 | AJ10: =+AF10+AH10 -> 23948 | AK10: =+AK7*AK2 -> 3038 | AL10: 3061 | AM10: =+AC10+AG10+AK10 -> 9016 | AN10: =+AD10+AH10+AL10 -> 9034 | AO10: =AI10+AK10 -> 26815 | AP10: =AJ10+AL10 -> 27009 | AQ10: =+AQ7*AQ2 -> 3038 | AR10: 3034 | AS10: =+AS7*AS2 -> 29853 | AT10: =+AP10+AR10 -> 30043 | AU10: =+AU7*AU2 -> 2744 | AV10: 2745 | AW10: =+AW7*AW2 -> 32597 | AX10: =+AT10+AV10 -> 32788 | AY10: =+AY7*AY2 -> 3038 | AZ10: 3059 | BA10: =+AQ10+AU10+AY10 -> 8820 | BB10: =+AR10+AV10+AZ10 -> 8838 | BC10: =AM10+BA10 -> 17836 | BD10: =AN10+BB10 -> 17872 | BE10: =AW10+AY10 -> 35635 | BF10: =AX10+AZ10 -> 35847 | BG10: 35831.2 | BH10: 35767 | BI10: 35868.022 | BJ10: 35382 | BK10: 33657 | BL10: 36135 | BM10: 35338 | BN10: 34383 | BO10: 33134 | BP10: 35502 | BQ10: 35030
B11: Overall Equiv. Ovens Pushed | C11: Nos | D11: =+D9+(D10*(31.55/17.2)) -> 99862.363 | E11: =+E9+(E10*(31.55/17.2)) -> 8332.8488 | F11: =+F9+(F10*(31.55/17.2)) -> 8259.3227 | G11: =+G9+(G10*(31.55/17.2)) -> 8610.6105 | H11: =+H9+(H10*(31.55/17.2)) -> 8569.2616 | I11: =+I9+(I10*(31.55/17.2)) -> 16943.459 | J11: =+J9+(J10*(31.55/17.2)) -> 16828.584 | K11: =+K9+(K10*(31.55/17.2)) -> 8212.8488 | ... X11: =+X9+(X10*(31.55/17.2)) -> 8375.0378 | Y11: =Y9+(Y10*31.55/17.2) -> 24881.439 | Z11: =Z9+(Z10*31.55/17.2) -> 25602.471 | AA11: =AA9+(AA10*31.55/17.2) -> 50037.747 | AB11: =AB9+(AB10*31.55/17.2) -> 50731.584 | AC11: =+AC9+(AC10*(31.55/17.2)) -> 8486.6105 | AD11: =+AD9+(AD10*(31.55/17.2)) -> 8519.7529 | AE11: =+AE9+(AE10*(31.55/17.2)) -> 58524.358 | AF11: =+AF9+(AF10*(31.55/17.2)) -> 59251.337 | AG11: =+AG9+(AG10*(31.55/17.2)) -> 8212.8488 | AH11: =+AH9+(AH10*(31.55/17.2)) -> 8256.5349 | AI11: =+AI9+(AI10*(31.55/17.2)) -> 66737.206 | AJ11: =+AJ9+(AJ10*(31.55/17.2)) -> 67507.872 | ... AL11: =+AL9+(AL10*(31.55/17.2)) -> 8531.7994 | AM11: =AM9+(AM10*31.55/17.2) -> 25186.07 | AN11: =AN9+(AN10*31.55/17.2) -> 25308.087 | AO11: =+AO9+(AO10*(31.55/17.2)) -> 75223.817 | AP11: =+AP9+(AP10*(31.55/17.2)) -> 76039.672 | AQ11: =+AQ9+(AQ10*(31.55/17.2)) -> 8486.6105 | AR11: =+AR9+(AR10*(31.55/17.2)) -> 8505.2733 | AS11: =+AS9+(AS10*(31.55/17.2)) -> 83710.427 | AT11: =+AT9+(AT10*(31.55/17.2)) -> 84544.945 | AU11: =+AU9+(AU10*(31.55/17.2)) -> 7665.3256 | AV11: =+AV9+(AV10*(31.55/17.2)) -> 7679.1599 | ... AZ11: =+AZ9+(AZ10*(31.55/17.2)) -> 8649.1308 | BA11: =BA9+(BA10*31.55/17.2) -> 24638.547 | BB11: =BB9+(BB10*31.55/17.2) -> 24833.564 | BC11: =BC9+(BC10*31.55/17.2) -> 49824.616 | BD11: =BD9+(BD10*31.55/17.2) -> 50141.651 | BE11: =+BE9+(BE10*(31.55/17.2)) -> 99862.363 | BF11: =+BF9+(BF10*(31.55/17.2)) -> 100873.24 | BG11: 100918.75 | BH11: 101271.49 | BI11: 102026.8 | BJ11: 101126.28 | BK11: 97793.113 | BL11: 102417.51 | BM11: 100526.58 | BN11: 97943.817 | BO11: 95577.773 | BP11: 100623.4 | BQ11: 99798.61
B12: BF COKE
B13: COB#10 | C13: Mt | D13: =+D9*0.7*17.2 -> 415343.88 | E13: =+E9*0.7*17.2 -> 35397.6 | F13: ='COKE OVENS'!F21 -> 35108.64 | G13: =+G9*0.7*17.2 -> 36577.52 | H13: ='COKE OVENS'!H21 -> 36433.04 | I13: =+E13+G13 -> 71975.12 | J13: =+F13+H13 -> 71541.68 | K13: =+K9*0.7*17.2 -> 33952.8 | L13: ='COKE OVENS'!L21 -> 34699.28 | M13: =+E13+G13+K13 -> 105927.92 | N13: =+F13+H13+L13 -> 106240.96 | O13: =+O9*0.7*17.2 -> 35084.56 | P13: ='COKE OVENS'!P21 -> 35614.32 | Q13: =+M13+O13 -> 141012.48 | R13: =+N13+P13 -> 141855.28 | S13: =+S9*0.7*17.2 -> 35084.56 | T13: ='COKE OVENS'!T21 -> 36577.52 | U13: =+Q13+S13 -> 176097.04 | V13: =+R13+T13 -> 178432.8 | W13: =+W9*0.7*17.2 -> 33266.52 | X13: ='COKE OVENS'!X21 -> 35397.6 | Y13: =+O13+S13+W13 -> 103435.64 | Z13: =+P13+T13+X13 -> 107589.44 | AA13: =+M13+Y13 -> 209363.56 | AB13: =+N13+Z13 -> 213830.4 | AC13: =+AC9*0.7*17.2 -> 35084.56 | AD13: ='COKE OVENS'!AD21 -> 35881.281 | AE13: =+AA13+AC13 -> 244448.12 | AF13: =+AB13+AD13 -> 249711.68 | AG13: =+AG9*0.7*17.2 -> 33952.8 | AH13: ='COKE OVENS'!AH21 -> 33793.958 | AI13: =+AE13+AG13 -> 278400.92 | AJ13: =+AF13+AH13 -> 283505.64 | AK13: =+AK9*0.7*17.2 -> 35084.56 | AL13: ='COKE OVENS'!AL21 -> 34869.818 | AM13: =+AC13+AG13+AK13 -> 104121.92 | AN13: =+AD13+AH13+AL13 -> 104545.06 | AO13: =AI13+AK13 -> 313485.48 | AP13: =AJ13+AL13 -> 318375.46 | AQ13: =+AQ9*0.7*17.2 -> 35084.56 | AR13: ='COKE OVENS'!AR21 -> 35144.76 | AS13: =+AO13+AQ13 -> 348570.04 | AT13: =+AP13+AR13 -> 353520.22 | AU13: =+AU9*0.7*17.2 -> 31689.28 | AV13: ='COKE OVENS'!AV21 -> 31606.376 | AW13: =+AS13+AU13 -> 380259.32 | AX13: =+AT13+AV13 -> 385126.59 | AY13: =+AY9*0.7*17.2 -> 35084.56 | AZ13: ='COKE OVENS'!AZ21 -> 36316.252 | BA13: =+AQ13+AU13+AY13 -> 101858.4 | BB13: =+AR13+AV13+AZ13 -> 103067.39 | BC13: =AM13+BA13 -> 205980.32 | BD13: =AN13+BB13 -> 207612.45 | BE13: =AW13+AY13 -> 415343.88 | BF13: =AX13+AZ13 -> 421442.85 | BG13: 423729.74 | BH13: 431508.84 | BI13: 433141.24 | BJ13: 432382.85 | BK13: 430769.03 | BL13: 438172.79 | BM13: 428806 | BN13: 425506 | BO13: 430922.2 | BP13: 406071.88 | BQ13: 412610.14
B14: COB#11 | C14: Mt | D14: =+D10*0.7*31.55 -> 786998.97 | E14: =+E10*31.55*0.7 -> 64929.9 | F14: ='COKE OVENS'!F22 -> 64333.605 | G14: =+G10*31.55*0.7 -> 67094.23 | H14: ='COKE OVENS'!H22 -> 66740.87 | I14: =+E14+G14 -> 132024.13 | J14: =+F14+H14 -> 131074.48 | K14: =+K10*31.55*0.7 -> 64929.9 | L14: ='COKE OVENS'!L22 -> 65239.09 | M14: =+E14+G14+K14 -> 196954.03 | N14: =+F14+H14+L14 -> 196313.57 | O14: =+O10*31.55*0.7 -> 67094.23 | P14: ='COKE OVENS'!P22 -> 67778.865 | Q14: =+M14+O14 -> 264048.26 | R14: =+N14+P14 -> 264092.43 | S14: =+S10*31.55*0.7 -> 67094.23 | T14: ='COKE OVENS'!T22 -> 67447.59 | U14: =+Q14+S14 -> 331142.49 | V14: =+R14+T14 -> 331540.02 | W14: =+W10*31.55*0.7 -> 61948.425 | X14: ='COKE OVENS'!X22 -> 64963.855 | Y14: =+O14+S14+W14 -> 196136.88 | Z14: =+P14+T14+X14 -> 200190.31 | AA14: =+M14+Y14 -> 393090.91 | AB14: =+N14+Z14 -> 396503.88 | AC14: =+AC10*31.55*0.7 -> 67094.23 | AD14: ='COKE OVENS'!AD22 -> 66256.925 | AE14: =+AA14+AC14 -> 460185.14 | AF14: =+AB14+AD14 -> 462760.8 | AG14: =+AG10*31.55*0.7 -> 64929.9 | AH14: ='COKE OVENS'!AH22 -> 64904.66 | AI14: =+AE14+AG14 -> 525115.04 | AJ14: =+AF14+AH14 -> 527665.46 | AK14: =+AK10*31.55*0.7 -> 67094.23 | AL14: ='COKE OVENS'!AL22 -> 67119.312 | AM14: =+AC14+AG14+AK14 -> 199118.36 | AN14: =+AD14+AH14+AL14 -> 198280.9 | AO14: =AI14+AK14 -> 592209.27 | AP14: =AJ14+AL14 -> 594784.77 | AQ14: =+AQ10*31.55*0.7 -> 67094.23 | AR14: ='COKE OVENS'!AR22 -> 66527.276 | AS14: =+AO14+AQ14 -> 659303.5 | AT14: =+AP14+AR14 -> 661312.05 | AU14: =+AU10*31.55*0.7 -> 60601.24 | AV14: ='COKE OVENS'!AV22 -> 60190.301 | AW14: =+AS14+AU14 -> 719904.74 | AX14: =+AT14+AV14 -> 721502.35 | AY14: =+AY10*31.55*0.7 -> 67094.23 | AZ14: ='COKE OVENS'!AZ22 -> 67075.458 | BA14: =+AQ14+AU14+AY14 -> 194789.7 | BB14: =+AR14+AV14+AZ14 -> 193793.04 | BC14: =AM14+BA14 -> 393908.06 | BD14: =AN14+BB14 -> 392073.93 | BE14: =AW14+AY14 -> 786998.97 | BF14: =AX14+AZ14 -> 788577.81 | BG14: 791332.05 | BH14: 793765.31 | BI14: 786486.6 | BJ14: 774691.65 | BK14: 737579.38 | BL14: 803741.8 | BM14: 778192 | BN14: 770203 | BO14: 752591.4 | BP14: 744858.59 | BQ14: 745859.84
B15: Total BF COKE | C15: Mt | D15: =SUM(D13:D14) -> 1202342.9 | E15: =SUM(E13:E14) -> 100327.5 | F15: =SUM(F13:F14) -> 99442.245 | G15: =SUM(G13:G14) -> 103671.75 | H15: =SUM(H13:H14) -> 103173.91 | I15: =SUM(I13:I14) -> 203999.25 | J15: =SUM(J13:J14) -> 202616.15 | K15: =SUM(K13:K14) -> 98882.7 | ... BF15: =SUM(BF13:BF14) -> 1210020.7 | BG15: 1215061.8 | BH15: 1225274.2 | BI15: 1219627.8 | BJ15: 1207074.5 | BK15: 1168348.4 | BL15: 1241914.6 | BM15: 1206998 | BN15: 1195709 | BO15: 1183513.6 | BP15: 1150930.5 | BQ15: 1158470
B16: SINTER | C16: Mt | D16: =4362.87596292192*1000+124 -> 4363000 | E16: =372.191438188584*1000 -> 372191.44 | F16: 321830 | G16: =383.372118766*1000 -> 383372.12 | H16: 355306 | I16: =+E16+G16 -> 755563.56 | J16: =+F16+H16 -> 677136 | K16: =372.191438188584*1000 -> 372191.44 | L16: 376274 | M16: =+E16+G16+K16 -> 1127755 | N16: =+F16+H16+L16 -> 1053410 | O16: =376.384193405115*1000 -> 376384.19 | P16: 397960 | Q16: =+M16+O16 -> 1504139.2 | R16: =+N16+P16 -> 1451370 | S16: =376.384193405115*1000 -> 376384.19 | T16: 383179 | U16: =+Q16+S16 -> 1880523.4 | V16: =+R16+T16 -> 1834549 | W16: =207.661910104769*1000 -> 207661.91 | X16: 374784 | Y16: =+O16+S16+W16 -> 960430.3 | Z16: =+P16+T16+X16 -> 1155923 | AA16: =+M16+Y16 -> 2088185.3 | AB16: =+N16+Z16 -> 2209333 | AC16: =383.372118766*1000 -> 383372.12 | AD16: 301448 | AE16: =+AA16+AC16 -> 2471557.4 | AF16: =+AB16+AD16 -> 2510781 | AG16: =376.191438188584*1000 -> 376191.44 | AH16: 366206 | AI16: =+AE16+AG16 -> 2847748.8 | AJ16: =+AF16+AH16 -> 2876987 | AK16: =387.372118766*1000 -> 387372.12 | AL16: 360713 | AM16: =+AC16+AG16+AK16 -> 1146935.7 | AN16: =+AD16+AH16+AL16 -> 1028367 | AO16: =AI16+AK16 -> 3235121 | AP16: =AJ16+AL16 -> 3237700 | AQ16: 388962.46 | AR16: 366580 | AS16: =+AO16+AQ16 -> 3624083.4 | AT16: =+AP16+AR16 -> 3604280 | AU16: 349830.08 | AV16: 314846 | AW16: =+AS16+AU16 -> 3973913.5 | AX16: =+AT16+AV16 -> 3919126 | AY16: 388962.46 | AZ16: 379828 | BA16: =+AQ16+AU16+AY16 -> 1127755 | BB16: =+AR16+AV16+AZ16 -> 1061254 | BC16: =AM16+BA16 -> 2274690.7 | BD16: =AN16+BB16 -> 2089621 | BE16: =AW16+AY16 -> 4362876 | BF16: =AX16+AZ16 -> 4298954 | BG16: 4387544.5 | BH16: 3980714 | BI16: 4499999.9 | BJ16: 4398445 | BK16: 4395665 | BL16: 4183927.8 | BM16: 4277831 | BN16: 3665891.3 | BO16: 3629577 | BP16: 3903932.5 | BQ16: 3709525
B17: HOT METAL | C17: Mt | D17: 2950000 | E17: 252000 | F17: 226125.6 | G17: 260000 | H17: 255730.9 | I17: =+E17+G17 -> 512000 | J17: =+F17+H17 -> 481856.5 | K17: =252*1000 -> 252000 | L17: 261489.9 | M17: =+E17+G17+K17 -> 764000 | N17: =+F17+H17+L17 -> 743346.4 | O17: 255000 | P17: 268142.3 | Q17: =+M17+O17 -> 1019000 | R17: =+N17+P17 -> 1011488.7 | S17: 255000 | T17: 253263.6 | U17: =+Q17+S17 -> 1274000 | V17: =+R17+T17 -> 1264752.3 | W17: 140000 | X17: 243297.4 | Y17: =+O17+S17+W17 -> 650000 | Z17: =+P17+T17+X17 -> 764703.3 | AA17: =+M17+Y17 -> 1414000 | AB17: =+N17+Z17 -> 1508049.7 | AC17: 260000 | AD17: 202962.1 | AE17: =+AA17+AC17 -> 1674000 | AF17: =+AB17+AD17 -> 1711011.8 | AG17: 252000 | AH17: 244148.2 | AI17: =+AE17+AG17 -> 1926000 | AJ17: =+AF17+AH17 -> 1955160 | AK17: 260000 | AL17: 251561 | AM17: =+AC17+AG17+AK17 -> 772000 | AN17: =+AD17+AH17+AL17 -> 698671.3 | AO17: =AI17+AK17 -> 2186000 | AP17: =AJ17+AL17 -> 2206721 | AQ17: 264000 | AR17: 244851.4 | AS17: =+AO17+AQ17 -> 2450000 | AT17: =+AP17+AR17 -> 2451572.4 | AU17: 236000 | AV17: 196575.3 | AW17: =+AS17+AU17 -> 2686000 | AX17: =+AT17+AV17 -> 2648147.7 | AY17: 264000 | AZ17: 251871.7 | BA17: =+AQ17+AU17+AY17 -> 764000 | BB17: =+AR17+AV17+AZ17 -> 693298.4 | BC17: =AM17+BA17 -> 1536000 | BD17: =AN17+BB17 -> 1391969.7 | BE17: =AW17+AY17 -> 2950000 | BF17: =AX17+AZ17 -> 2900019.4 | BG17: 2650000 | BH17: 2622585.7 | BI17: 2800000 | BJ17: 2721268.1 | BK17: 2592119.6 | BL17: 2650001 | BM17: 2406785.7 | BN17: 2496672.2 | BO17: 2092798 | BP17: 2700000 | BQ17: 2505193
B18: CRUDE STEEL | C18: Mt | D18: =2770.01888574126*1000-19 -> 2769999.9 | E18: =237.110481586402*1000 -> 237110.48 | F18: 207020 | G18: =244.66477809254*1000 -> 244664.78 | H18: 236638 | I18: =+E18+G18 -> 481775.26 | J18: =+F18+H18 -> 443658 | K18: =237.110481586402*1000 -> 237110.48 | L18: 243453 | M18: =+E18+G18+K18 -> 718885.74 | N18: =+F18+H18+L18 -> 687111 | O18: =239.943342776204*1000 -> 239943.34 | P18: 253662 | Q18: =+M18+O18 -> 958829.08 | R18: =+N18+P18 -> 940773 | S18: =239.943342776204*1000 -> 239943.34 | T18: 237622 | U18: =+Q18+S18 -> 1198772.4 | V18: =+R18+T18 -> 1178395 | W18: =125.920679886686*1000 -> 125920.68 | X18: 226847 | Y18: =+O18+S18+W18 -> 605807.37 | Z18: =+P18+T18+X18 -> 718131 | AA18: =+M18+Y18 -> 1324693.1 | AB18: =+N18+Z18 -> 1405242 | AC18: =244.66477809254*1000 -> 244664.78 | AD18: 179201 | AE18: =+AA18+AC18 -> 1569357.9 | AF18: =+AB18+AD18 -> 1584443 | AG18: =237.110481586402*1000 -> 237110.48 | AH18: 229502 | AI18: =+AE18+AG18 -> 1806468.4 | AJ18: =+AF18+AH18 -> 1813945 | AK18: =244.66477809254*1000 -> 244664.78 | AL18: 234365 | AM18: =+AC18+AG18+AK18 -> 726440.04 | AN18: =+AD18+AH18+AL18 -> 643068 | AO18: =AI18+AK18 -> 2051133.1 | AP18: =AJ18+AL18 -> 2048310 | AQ18: 248441.93 | AR18: 228047 | AS18: =+AO18+AQ18 -> 2299575.1 | AT18: =+AP18+AR18 -> 2276357 | AU18: 222001.89 | AV18: 185016 | AW18: =+AS18+AU18 -> 2521577 | AX18: =+AT18+AV18 -> 2461373 | AY18: 248441.93 | AZ18: 241240 | BA18: =+AQ18+AU18+AY18 -> 718885.74 | BB18: =+AR18+AV18+AZ18 -> 654303 | BC18: =AM18+BA18 -> 1445325.8 | BD18: =AN18+BB18 -> 1297371 | BE18: =AW18+AY18 -> 2770018.9 | BF18: =AX18+AZ18 -> 2702613 | BG18: 2489528.3 | BH18: 2436959 | BI18: 2620075.5 | BJ18: 2528925 | BK18: 2422324.3 | BL18: 2451737.7 | BM18: 2227867 | BN18: 2297163.5 | BO18: 1847433 | BP18: 2500000 | BQ18: 2083412
B19: Caster #(1+2 ) | C19: Mt | D19: =1978.46215750908*1000-2 -> 1978460.2 | E19: =SMS!E29 -> 171675.13 | F19: =SMS!F37 -> 149261 | G19: =SMS!G29 -> 176063.19 | H19: =SMS!H37 -> 175199.54 | I19: =+E19+G19 -> 347738.32 | J19: =SMS!J37 -> 324460.54 | K19: =SMS!K29 -> 171147.42 | L19: =SMS!L37 -> 182735 | M19: =+E19+G19+K19 -> 518885.74 | N19: =+F19+H19+L19 -> 507195.54 | O19: =SMS!O29 -> 171341.76 | P19: =SMS!P37 -> 189077 | Q19: =+M19+O19 -> 690227.5 | R19: =+N19+P19 -> 696272.54 | S19: =SMS!S29 -> 171341.76 | T19: =SMS!T37 -> 179543 | U19: =+Q19+S19 -> 861569.26 | V19: =+R19+T19 -> 875815.54 | W19: =SMS!W29 -> 90564.479 | X19: =SMS!X37 -> 172339.6 | Y19: =+O19+S19+W19 -> 433248 | Z19: =+P19+T19+X19 -> 540959.6 | AA19: =+M19+Y19 -> 952133.74 | AB19: =+N19+Z19 -> 1048155.1 | AC19: =SMS!AC29 -> 173952.38 | AD19: =SMS!AD37 -> 135241 | AE19: =+AA19+AC19 -> 1126086.1 | AF19: =+AB19+AD19 -> 1183396.1 | AG19: =SMS!AG29 -> 168508.9 | AH19: =SMS!AH37 -> 178010.44 | AI19: =SMS!AI29 -> 1294595 | AJ19: =SMS!AJ37 -> 1361406.6 | AK19: =SMS!AK29 -> 173424.67 | AL19: =SMS!AL37 -> 168781 | AM19: =SMS!AM29 -> 515885.95 | AN19: =SMS!AN37 -> 482032.44 | AO19: =SMS!AO29 -> 1468019.7 | AP19: =SMS!AP37 -> 1530187.6 | AQ19: =SMS!AQ29 -> 176674.12 | AR19: =SMS!AR37 -> 164934.28 | AS19: =+AO19+AQ19 -> 1644693.8 | AT19: =+AP19+AR19 -> 1695121.9 | AU19: =SMS!AU29 -> 157621.94 | AV19: =SMS!AV37 -> 135607.79 | AW19: =+AS19+AU19 -> 1802315.7 | AX19: =+AT19+AV19 -> 1830729.6 | AY19: =SMS!AY29 -> 176146.41 | AZ19: =SMS!AZ37 -> 176644.91 | BA19: =+AQ19+AU19+AY19 -> 510442.47 | BB19: =+AR19+AV19+AZ19 -> 477186.98 | BC19: =AM19+BA19 -> 1026328.4 | BD19: =AN19+BB19 -> 959219.42 | BE19: =AW19+AY19 -> 1978462.2 | BF19: =AX19+AZ19 -> 2007374.6 | BG19: 1880445.4 | BH19: 1818588.7 | BJ19: 1922629.6 | BK19: 1903696 | BM19: 1777963.7
B20: Caster #3 | C20: Mt | D20: =791.55672823219*1000-17 -> 791539.73 | E20: =SMS!E38 -> 65435.356 | F20: =SMS!F46 -> 57758.57 | G20: =SMS!G38 -> 68601.583 | H20: =SMS!H46 -> 61438.56 | I20: =+E20+G20 -> 134036.94 | J20: =SMS!J46 -> 119197.13 | K20: =SMS!K38 -> 65963.061 | L20: =SMS!L46 -> 60718.3 | M20: =+E20+G20+K20 -> 200000 | N20: =+F20+H20+L20 -> 179915.43 | O20: =SMS!O38 -> 68601.583 | P20: =SMS!P46 -> 64584.79 | Q20: =+M20+O20 -> 268601.58 | R20: =+N20+P20 -> 244500.22 | S20: =SMS!S38 -> 68601.583 | T20: =SMS!T46 -> 58078.79 | U20: =+Q20+S20 -> 337203.17 | V20: =+R20+T20 -> 302579.01 | W20: =SMS!W38 -> 35356.201 | X20: =SMS!X46 -> 54507 | Y20: =+O20+S20+W20 -> 172559.37 | Z20: =+P20+T20+X20 -> 177170.58 | AA20: =+M20+Y20 -> 372559.37 | AB20: =+N20+Z20 -> 357086.01 | AC20: =SMS!AC38 -> 70712.4 | AD20: =SMS!AD46 -> 43960.31 | AE20: =+AA20+AC20 -> 443271.77 | AF20: =+AB20+AD20 -> 401046.32 | AG20: =SMS!AG38 -> 68601.583 | AH20: =SMS!AH46 -> 51491.21 | AI20: =SMS!AI38 -> 511873.35 | AJ20: =SMS!AJ46 -> 452537.53 | AK20: =SMS!AK38 -> 71240.106 | AL20: =SMS!AL46 -> 65584.38 | AM20: =SMS!AM38 -> 210554.09 | AN20: =SMS!AN46 -> 161035.9 | AO20: =SMS!AO38 -> 583113.46 | AP20: =SMS!AP46 -> 518121.91 | AQ20: =SMS!AQ38 -> 71767.81 | AR20: =SMS!AR46 -> 63113.1 | AS20: =+AO20+AQ20 -> 654881.27 | AT20: =+AP20+AR20 -> 581235.01 | AU20: =SMS!AU38 -> 64379.947 | AV20: =SMS!AV46 -> 49408.38 | AW20: =+AS20+AU20 -> 719261.21 | AX20: =+AT20+AV20 -> 630643.39 | AY20: =SMS!AY38 -> 72295.515 | AZ20: =SMS!AZ46 -> 64595.04 | BA20: =+AQ20+AU20+AY20 -> 208443.27 | BB20: =+AR20+AV20+AZ20 -> 177116.52 | BC20: =AM20+BA20 -> 418997.36 | BD20: =AN20+BB20 -> 338152.42 | BE20: =AW20+AY20 -> 791556.73 | BF20: =AX20+AZ20 -> 695238.43 | BG20: 609083.07 | BH20: 618370.32 | BJ20: 606294.79 | BK20: 518629.33 | BM20: 449903.88
B21: Avg Heats Cast per Day | C21: Nos. / day | D21: =D53/D1 -> 54.152138 | E21: =+E53/E1 -> 54.508157 | F21: =+F53/F1 -> 49.6125 | G21: =+G53/G1 -> 54.369951 | H21: =+H53/H1 -> 50.886713 | I21: =+I53/I1 -> 54.437882 | J21: =+J53/J1 -> 50.284871 | K21: =+K53/K1 -> 54.508157 | L21: =+L53/L1 -> 52.547596 | ... BF21: =+BF53/BF1 -> 49.349681 | BG21: 51.463117 | BH21: 49.270546 | BI21: 50.337665 | BJ21: 48.130368 | BK21: 45.269663 | BL21: 44.780041 | BM21: 40.065753 | BN21: 41.920046 | BO21: 33.309589 | BP21: 47.014645 | BQ21: 38.663934
B22: Cold Pig & Pig Equivalent
B23: MOG | C23: Mt | D23: 12645 | E23: =0.81*1000 -> 810 | F23: 3914.4926 | G23: 810 | H23: 2383.6528 | I23: =+E23+G23 -> 1620 | J23: =+F23+H23 -> 6298.1454 | K23: =0.81*1000 -> 810 | L23: 902.97846 | M23: =+E23+G23+K23 -> 2430 | N23: =+F23+H23+L23 -> 7201.1238 | O23: 810 | P23: 0 | Q23: =+M23+O23 -> 3240 | R23: =+N23+P23 -> 7201.1238 | S23: =0.81*1000 -> 810 | T23: 144.06922 | U23: =+Q23+S23 -> 4050 | V23: =+R23+T23 -> 7345.1931 | W23: =5360-1625 -> 3735 | X23: 256.58678 | Y23: =+O23+S23+W23 -> 5355 | Z23: =+P23+T23+X23 -> 400.656 | AA23: =+M23+Y23 -> 7785 | AB23: =+N23+Z23 -> 7601.7798 | AC23: 810 | AD23: 3014.2686 | AE23: =+AA23+AC23 -> 8595 | AF23: =+AB23+AD23 -> 10616.048 | AG23: 810 | AH23: 135.13793 | AI23: =+AE23+AG23 -> 9405 | AJ23: =+AF23+AH23 -> 10751.186 | AK23: 810 | AL23: 35.72516 | AM23: =+AC23+AG23+AK23 -> 2430 | AN23: =+AD23+AH23+AL23 -> 3185.1317 | AO23: =AI23+AK23 -> 10215 | AP23: =AJ23+AL23 -> 10786.912 | AQ23: 810 | AR23: 662.91874 | AS23: =+AO23+AQ23 -> 11025 | AT23: =+AP23+AR23 -> 11449.83 | AU23: 810 | AV23: 0 | AW23: =+AS23+AU23 -> 11835 | AX23: =+AT23+AV23 -> 11449.83 | AY23: 810 | AZ23: 80.29814 | BA23: =+AQ23+AU23+AY23 -> 2430 | BB23: =+AR23+AV23+AZ23 -> 743.21688 | BC23: =AM23+BA23 -> 4860 | BD23: =AN23+BB23 -> 3928.3486 | BE23: =AW23+AY23 -> 12645 | BF23: =AX23+AZ23 -> 11530.128 | BG23: 7740 | BH23: 12917.886 | BI23: 19561.1 | BJ23: 7548.2756 | BK23: 9129.3344 | BL23: 19735.515 | BM23: 22361.072 | BN23: 20755.018 | BO23: 58220.7 | BP23: 29957.856 | BQ23: 134629.18
B24: UPIS | C24: Mt | D24: 0 | E24: 0 | F24: 552.63425 | G24: 0 | H24: 336.51569 | I24: =+E24+G24 -> 0 | J24: =+F24+H24 -> 889.14994 | K24: 0 | L24: 127.47931 | M24: =+E24+G24+K24 -> 0 | N24: =+F24+H24+L24 -> 1016.6292 | O24: 0 | P24: 0 | Q24: =+M24+O24 -> 0 | R24: =+N24+P24 -> 1016.6292 | S24: 0 | T24: 20.339184 | U24: =+Q24+S24 -> 0 | V24: =+R24+T24 -> 1036.9684 | W24: 0 | X24: 36.224016 | Y24: =+O24+S24+W24 -> 0 | Z24: =+P24+T24+X24 -> 56.5632 | AA24: =+M24+Y24 -> 0 | AB24: =+N24+Z24 -> 1073.1924 | AC24: 0 | AD24: 426 | AE24: =+AA24+AC24 -> 0 | AF24: =+AB24+AD24 -> 1499.1924 | AG24: 0 | AH24: 19.078296 | AI24: =+AE24+AG24 -> 0 | AJ24: =+AF24+AH24 -> 1518.2707 | AK24: 0 | AL24: 5 | AM24: =+AC24+AG24+AK24 -> 0 | AN24: =+AD24+AH24+AL24 -> 450.0783 | AO24: =AI24+AK24 -> 0 | AP24: =AJ24+AL24 -> 1523.2707 | AQ24: 0 | AR24: 93.588528 | AS24: =+AO24+AQ24 -> 0 | AT24: =+AP24+AR24 -> 1616.8593 | AU24: 0 | AV24: 0 | AW24: =+AS24+AU24 -> 0 | AX24: =+AT24+AV24 -> 1616.8593 | AY24: 0 | AZ24: 11.336208 | BA24: =+AQ24+AU24+AY24 -> 0 | BB24: =+AR24+AV24+AZ24 -> 104.92474 | BC24: =AM24+BA24 -> 0 | BD24: =AN24+BB24 -> 555.00303 | BE24: =AW24+AY24 -> 0 | BF24: =AX24+AZ24 -> 1628.1955 | BG24: 0 | BH24: 1823.7656 | BI24: 0 | BJ24: 1026.6221 | BK24: 2541.6495 | BL24: 0 | BM24: 2774.7649 | BN24: 392 | BO24: 3852.3 | BP24: 1419.0563 | BQ24: 8272.9783
B25: Equiv. Pig Iron @ 65% of HM sent to Sand Pit | C25: Mt | D25: =2500*0.65 -> 1625 | E25: 0 | F25: 194.6 | G25: 0 | H25: 230 | I25: =+E25+G25 -> 0 | J25: =+F25+H25 -> 424.6 | K25: 0 | L25: 0 | M25: =+E25+G25+K25 -> 0 | N25: =+F25+H25+L25 -> 424.6 | O25: 0 | P25: 0 | Q25: =+M25+O25 -> 0 | R25: =+N25+P25 -> 424.6 | S25: 0 | T25: 0 | U25: =+Q25+S25 -> 0 | V25: =+R25+T25 -> 424.6 | W25: =2500*0.65 -> 1625 | X25: 0 | Y25: =+O25+S25+W25 -> 1625 | Z25: =+P25+T25+X25 -> 0 | AA25: =+M25+Y25 -> 1625 | AB25: =+N25+Z25 -> 424.6 | AC25: 0 | AD25: 5603 | AE25: =+AA25+AC25 -> 1625 | AF25: =+AB25+AD25 -> 6027.6 | AG25: 0 | AH25: 0 | AI25: =+AE25+AG25 -> 1625 | AJ25: =+AF25+AH25 -> 6027.6 | AK25: 0 | AL25: 0 | AM25: =+AC25+AG25+AK25 -> 0 | AN25: =+AD25+AH25+AL25 -> 5603 | AO25: =AI25+AK25 -> 1625 | AP25: =AJ25+AL25 -> 6027.6 | AQ25: 0 | AR25: 800.6 | AS25: =+AO25+AQ25 -> 1625 | AT25: =+AP25+AR25 -> 6828.2 | AU25: 0 | AV25: 920 | AW25: =+AS25+AU25 -> 1625 | AX25: =+AT25+AV25 -> 7748.2 | AY25: 0 | AZ25: 310 | BA25: =+AQ25+AU25+AY25 -> 0 | BB25: =+AR25+AV25+AZ25 -> 2030.6 | BC25: =AM25+BA25 -> 0 | BD25: =AN25+BB25 -> 7633.6 | BE25: =AW25+AY25 -> 1625 | BF25: =AX25+AZ25 -> 8058.2 | BG25: 1625 | BH25: 11114.8 | BI25: 2000 | BJ25: 5022 | BK25: 4664.8 | BL25: 14800 | BM25: 9214.4 | BN25: 0 | BO25: 0 | BP25: 0 | BQ25: 26220.8
B26: TOTAL EQUIVALENT PIG IRON | C26: Mt | D26: =SUM(D23:D25) -> 14270 | E26: =SUM(E23:E25) -> 810 | F26: =SUM(F23:F25) -> 4661.7268 | G26: =SUM(G23:G25) -> 810 | H26: =SUM(H23:H25) -> 2950.1685 | I26: =SUM(I23:I25) -> 1620 | J26: =SUM(J23:J25) -> 7611.8953 | K26: =SUM(K23:K25) -> 810 | ... BF26: =SUM(BF23:BF25) -> 21216.524 | BG26: 9365 | BH26: 25856.451 | BI26: 21561.1 | BJ26: 13596.898 | BK26: 16335.784 | BL26: 34535.515 | BM26: 34350.237 | BN26: 21147.018 | BO26: 62073 | BP26: 31376.912 | BQ26: 169122.96
B27: Net PCI Production | C27: Mt | D27: 3541.35 | E27: 273.996 | F27: 374.5 | G27: 279.98 | H27: 603.862 | I27: =+E27+G27 -> 553.976 | J27: =+F27+H27 -> 978.362 | K27: 273.996 | L27: 0 | M27: =+E27+G27+K27 -> 827.972 | N27: =+F27+H27+L27 -> 978.362 | O27: 276.24 | P27: 0 | Q27: =+M27+O27 -> 1104.212 | R27: =+N27+P27 -> 978.362 | S27: 276.24 | T27: 0 | U27: =+Q27+S27 -> 1380.452 | V27: =+R27+T27 -> 978.362 | W27: 498.97 | X27: 0 | Y27: =+O27+S27+W27 -> 1051.45 | Z27: =+P27+T27+X27 -> 0 | AA27: =+M27+Y27 -> 1879.422 | AB27: =+N27+Z27 -> 978.362 | AC27: 279.98 | AD27: 549.087 | AE27: =+AA27+AC27 -> 2159.402 | AF27: =+AB27+AD27 -> 1527.449 | AG27: 273.996 | AH27: 833.469 | AI27: =+AE27+AG27 -> 2433.398 | AJ27: =+AF27+AH27 -> 2360.918 | AK27: 279.98 | AL27: 1510.747 | AM27: =+AC27+AG27+AK27 -> 833.956 | AN27: =+AD27+AH27+AL27 -> 2893.303 | AO27: =AI27+AK27 -> 2713.378 | AP27: =AJ27+AL27 -> 3871.665 | AQ27: 282.972 | AR27: 1549.45 | AS27: =+AO27+AQ27 -> 2996.35 | AT27: =+AP27+AR27 -> 5421.115 | AU27: 262.028 | AV27: 755.405 | AW27: =+AS27+AU27 -> 3258.378 | AX27: =+AT27+AV27 -> 6176.52 | AY27: 282.972 | AZ27: 209.86 | BA27: =+AQ27+AU27+AY27 -> 827.972 | BB27: =+AR27+AV27+AZ27 -> 2514.715 | BC27: =AM27+BA27 -> 1661.928 | BD27: =AN27+BB27 -> 5408.018 | BE27: =AW27+AY27 -> 3541.35 | BF27: =AX27+AZ27 -> 6386.38 | BG27: 2831.5 | BH27: 7991.486 | BI27: 2377.872 | BJ27: 6141.395 | BK27: 5885.734 | BL27: 2398.56 | BM27: 13377.679 | BN27: 11568.99 | BO27: 41093.9 | BP27: 0 | BQ27: 44255.19
B28: Net Granulated Slag Production | C28: Mt | D28: 1081234 | E28: 92363.04 | F28: 70955.831 | G28: 95295.2 | H28: 75418.546 | I28: =+E28+G28 -> 187658.24 | J28: =+F28+H28 -> 146374.38 | K28: 92363.04 | L28: 72846.055 | M28: =+E28+G28+K28 -> 280021.28 | N28: =+F28+H28+L28 -> 219220.43 | O28: 93462.6 | P28: 75682.97 | Q28: =+M28+O28 -> 373483.88 | R28: =+N28+P28 -> 294903.4 | S28: 93462.6 | T28: 80832.023 | U28: =+Q28+S28 -> 466946.48 | V28: =+R28+T28 -> 375735.43 | W28: 51312.8 | X28: 79584.049 | Y28: =+O28+S28+W28 -> 238238 | Z28: =+P28+T28+X28 -> 236099.04 | AA28: =+M28+Y28 -> 518259.28 | AB28: =+N28+Z28 -> 455319.47 | AC28: 95295.2 | AD28: 63840.922 | AE28: =+AA28+AC28 -> 613554.48 | AF28: =+AB28+AD28 -> 519160.4 | AG28: 92363.04 | AH28: 88321.763 | AI28: =+AE28+AG28 -> 705917.52 | AJ28: =+AF28+AH28 -> 607482.16 | AK28: 95295.2 | AL28: 84104.855 | AM28: =+AC28+AG28+AK28 -> 282953.44 | AN28: =+AD28+AH28+AL28 -> 236267.54 | AO28: =AI28+AK28 -> 801212.72 | AP28: =AJ28+AL28 -> 691587.01 | AQ28: 96761.28 | AR28: 81040.671 | AS28: =+AO28+AQ28 -> 897974 | AT28: =+AP28+AR28 -> 772627.69 | AU28: 86498.72 | AV28: 67236.848 | AW28: =+AS28+AU28 -> 984472.72 | AX28: =+AT28+AV28 -> 839864.53 | AY28: 96761.28 | AZ28: 71373.052 | BA28: =+AQ28+AU28+AY28 -> 280021.28 | BB28: =+AR28+AV28+AZ28 -> 219650.57 | BC28: =AM28+BA28 -> 562974.72 | BD28: =AN28+BB28 -> 455918.11 | BE28: =AW28+AY28 -> 1081234 | BF28: =AX28+AZ28 -> 911237.59 | BG28: 987899.89 | BH28: 899258.76 | BI28: 1063047 | BJ28: 1075244.6 | BK28: 1065593 | BL28: 157305.12 | BM28: 920129.3 | BN28: 882599.97 | BO28: 776699 | BP28: 854658 | BQ28: 809638.21
B29: Saleable Steel Production (Mill Wise)
B30: WR Mill | C30: Mt | D30: 500000 | E30: 42500 | F30: =+WRM!F159 -> 36742.13 | G30: 44000 | H30: =+WRM!H159 -> 39351.8 | I30: =+E30+G30 -> 86500 | J30: =+F30+H30 -> 76093.93 | K30: 42500 | L30: =+WRM!L159 -> 38291.35 | M30: =+E30+G30+K30 -> 129000 | N30: =+F30+H30+L30 -> 114385.28 | O30: 44000 | P30: =+WRM!P159 -> 47063.9 | Q30: =+M30+O30 -> 173000 | R30: =+N30+P30 -> 161449.18 | S30: 44000 | T30: =+WRM!T159 -> 38718.35 | U30: =+Q30+S30 -> 217000 | V30: =+R30+T30 -> 200167.53 | W30: 25000 | X30: =+WRM!X159 -> 41006.15 | Y30: =+O30+S30+W30 -> 113000 | Z30: =+P30+T30+X30 -> 126788.4 | AA30: =+M30+Y30 -> 242000 | AB30: =+N30+Z30 -> 241173.68 | AC30: 42500 | AD30: =+WRM!AD159 -> 30034.55 | AE30: =+AA30+AC30 -> 284500 | AF30: =+AB30+AD30 -> 271208.23 | AG30: 42500 | AH30: =+WRM!AH159 -> 34614.25 | AI30: =+AE30+AG30 -> 327000 | AJ30: =+AF30+AH30 -> 305822.48 | AK30: 44000 | AL30: =+WRM!AL159 -> 44007.35 | AM30: =+AC30+AG30+AK30 -> 129000 | AN30: =+AD30+AH30+AL30 -> 108656.15 | AO30: =AI30+AK30 -> 371000 | AP30: =AJ30+AL30 -> 349829.83 | AQ30: 44500 | AR30: =+WRM!AR159 -> 44589.55 | AS30: =+AO30+AQ30 -> 415500 | AT30: =+AP30+AR30 -> 394419.38 | AU30: 40000 | AV30: =+WRM!AV159 -> 37420.7 | AW30: =+AS30+AU30 -> 455500 | AX30: =+AT30+AV30 -> 431840.08 | AY30: 44500 | AZ30: =+WRM!AZ159 -> 46692.85 | BA30: =+AQ30+AU30+AY30 -> 129000 | BB30: =+AR30+AV30+AZ30 -> 128703.1 | BC30: =AM30+BA30 -> 258000 | BD30: =AN30+BB30 -> 237359.25 | BE30: =AW30+AY30 -> 500000 | BF30: =AX30+AZ30 -> 478532.93 | BG30: 500000 | BH30: 459030.64 | BI30: 500000 | BJ30: 478528.39 | BK30: 466114.65 | BL30: 500000 | BM30: 465343.77 | BN30: 435965.96 | BO30: 356518.66 | BP30: 500000 | BQ30: 412025.22
B31: Bar Mill | C31: Mt | D31: 900000 | E31: 76000 | F31: =+BM!F56 -> 66895.455 | G31: 79000 | H31: =+BM!H56 -> 76175.635 | I31: =+E31+G31 -> 155000 | J31: =+F31+H31 -> 143071.09 | K31: 76000 | L31: =+BM!L56 -> 73644.015 | M31: =+E31+G31+K31 -> 231000 | N31: =+F31+H31+L31 -> 216715.11 | O31: 79000 | P31: =+BM!P56 -> 88056.49 | Q31: =+M31+O31 -> 310000 | R31: =+N31+P31 -> 304771.6 | S31: 79000 | T31: =+BM!T56 -> 75853.695 | U31: =+Q31+S31 -> 389000 | V31: =+R31+T31 -> 380625.29 | W31: =47.5*1000 -> 47500 | X31: =+BM!X56 -> 76319.035 | Y31: =+O31+S31+W31 -> 205500 | Z31: =+P31+T31+X31 -> 240229.22 | AA31: =+M31+Y31 -> 436500 | AB31: =+N31+Z31 -> 456944.33 | AC31: 78000 | AD31: =+BM!AD56 -> 50950.275 | AE31: =+AA31+AC31 -> 514500 | AF31: =+AB31+AD31 -> 507894.6 | AG31: 76000 | AH31: =+BM!AH56 -> 69720.765 | AI31: =+AE31+AG31 -> 590500 | AJ31: =+AF31+AH31 -> 577615.37 | AK31: 79000 | AL31: =+BM!AL56 -> 81616.765 | AM31: =+AC31+AG31+AK31 -> 233000 | AN31: =+AD31+AH31+AL31 -> 202287.81 | AO31: =AI31+AK31 -> 669500 | AP31: =AJ31+AL31 -> 659232.13 | AQ31: 79000 | AR31: =+BM!AR56 -> 85804.6 | AS31: =+AO31+AQ31 -> 748500 | AT31: =+AP31+AR31 -> 745036.73 | AU31: 71500 | AV31: =+BM!AV56 -> 74058.32 | AW31: =+AS31+AU31 -> 820000 | AX31: =+AT31+AV31 -> 819095.05 | AY31: 80000 | AZ31: =+BM!AZ56 -> 81200 | BA31: =+AQ31+AU31+AY31 -> 230500 | BB31: =+AR31+AV31+AZ31 -> 241062.92 | BC31: =AM31+BA31 -> 463500 | BD31: =AN31+BB31 -> 443350.73 | BE31: =AW31+AY31 -> 900000 | BF31: =AX31+AZ31 -> 900295.05 | BG31: 870000 | BH31: 750867.85 | BI31: 850000 | BJ31: 795322.27 | BK31: 775906.63 | BL31: 750000 | BM31: 649840.96 | BN31: 674875.14 | BO31: 440547.27 | BP31: 800000 | BQ31: 632220.18
B32: US Mill | C32: Mt | D32: 750000 | E32: 62000 | F32: =+USM!G121 -> 49543.777 | G32: 65000 | H32: =+USM!I121 -> 57219.144 | I32: =+E32+G32 -> 127000 | J32: =+F32+H32 -> 106762.92 | K32: 62500 | L32: =+USM!M121 -> 58674.633 | M32: =+E32+G32+K32 -> 189500 | N32: =+F32+H32+L32 -> 165437.55 | O32: 65000 | P32: =+USM!Q121 -> 57327.387 | Q32: =+M32+O32 -> 254500 | R32: =+N32+P32 -> 222764.94 | S32: 65000 | T32: =+USM!U121 -> 44406.293 | U32: =+Q32+S32 -> 319500 | V32: =+R32+T32 -> 267171.23 | W32: 33500 | X32: =+USM!Y121 -> 49996.716 | Y32: =+O32+S32+W32 -> 163500 | Z32: =+P32+T32+X32 -> 151730.4 | AA32: =+M32+Y32 -> 353000 | AB32: =+N32+Z32 -> 317167.95 | AC32: 67000 | AD32: =+USM!AE121 -> 29659.897 | AE32: =+AA32+AC32 -> 420000 | AF32: =+AB32+AD32 -> 346827.85 | AG32: 65000 | AH32: =+USM!AI121 -> 49060.044 | AI32: =+AE32+AG32 -> 485000 | AJ32: =+AF32+AH32 -> 395887.89 | AK32: =67.5*1000 -> 67500 | AL32: =+USM!AM121 -> 52987.18 | AM32: =+AC32+AG32+AK32 -> 199500 | AN32: =+AD32+AH32+AL32 -> 131707.12 | AO32: =AI32+AK32 -> 552500 | AP32: =AJ32+AL32 -> 448875.07 | AQ32: 68000 | AR32: =+USM!AS121 -> 56169.978 | AS32: =+AO32+AQ32 -> 620500 | AT32: =+AP32+AR32 -> 505045.05 | AU32: 61000 | AV32: =+USM!AW121 -> 54279.398 | AW32: =+AS32+AU32 -> 681500 | AX32: =+AT32+AV32 -> 559324.45 | AY32: 68500 | AZ32: =+USM!BA121 -> 63120.146 | BA32: =+AQ32+AU32+AY32 -> 197500 | BB32: =+AR32+AV32+AZ32 -> 173569.52 | BC32: =AM32+BA32 -> 397000 | BD32: =AN32+BB32 -> 305276.64 | BE32: =AW32+AY32 -> 750000 | BF32: =AX32+AZ32 -> 622444.59 | BG32: 560000 | BH32: 499887.23 | BI32: 525000 | BJ32: 459141.95 | BK32: 361987.56 | BL32: 450000 | BM32: 213226.16 | BN32: 220000 | BO32: 88943.894 | BP32: 535000 | BQ32: 171634.81
B33: Finished Steel | C33: Mt | D33: =SUM(D30:D32) -> 2150000 | E33: =SUM(E30:E32) -> 180500 | F33: =SUM(F30:F32) -> 153181.36 | G33: =SUM(G30:G32) -> 188000 | H33: =SUM(H30:H32) -> 172746.58 | I33: =SUM(I30:I32) -> 368500 | J33: =SUM(J30:J32) -> 325927.94 | K33: =SUM(K30:K32) -> 181000 | ... BF33: =SUM(BF30:BF32) -> 2001272.6 | BG33: 1930000 | BH33: 1709785.7 | BI33: 1875000 | BJ33: 1732992.6 | BK33: 1604008.8 | BL33: 1700000 | BM33: 1328410.9 | BN33: 1330841.1 | BO33: 886009.82 | BP33: =SUM(BP30:BP32) -> 1835000 | BQ33: =SUM(BQ30:BQ32) -> 1215880.2
B34: 150x150 mm | C34: Mt | D34: =524.79833712911*1000 -> 524798.34 | E34: =48.4998153686034*1000 -> 48499.815 | F34: 45616.588 | G34: 48499.577 | H34: 52556 | I34: =+E34+G34 -> 96999.392 | J34: =+F34+H34 -> 98172.588 | K34: =48.0001108831152*1000 -> 48000.111 | L34: 56218 | M34: =+E34+G34+K34 -> 144999.5 | N34: =+F34+H34+L34 -> 154390.59 | O34: =43.5001413553209*1000 -> 43500.141 | P34: 50303 | Q34: =+M34+O34 -> 188499.64 | R34: =+N34+P34 -> 204693.59 | S34: =43.5001413553209*1000 -> 43500.141 | T34: 51235.42 | U34: =+Q34+S34 -> 231999.79 | V34: =+R34+T34 -> 255929.01 | W34: =15.3000147648532*1000 -> 15300.015 | X34: 54076 | Y34: =+O34+S34+W34 -> 102300.3 | Z34: =+P34+T34+X34 -> 155614.42 | AA34: =+M34+Y34 -> 247299.8 | AB34: =+N34+Z34 -> 310005.01 | AC34: =48.9995281597563*1000 -> 48999.528 | AD34: 54595 | AE34: =+AA34+AC34 -> 296299.33 | AF34: =+AB34+AD34 -> 364600.01 | AG34: =45.4995884556746*1000 -> 45499.588 | AH34: 61080 | AI34: =+AE34+AG34 -> 341798.92 | AJ34: =+AF34+AH34 -> 425680.01 | AK34: =46.0000542442164*1000 -> 46000.054 | AL34: 52347.66 | AM34: =+AC34+AG34+AK34 -> 140499.17 | AN34: =+AD34+AH34+AL34 -> 168022.66 | AO34: =AI34+AK34 -> 387798.97 | AP34: =AJ34+AL34 -> 478027.67 | AQ34: 48499.665 | AR34: 30958 | AS34: =+AO34+AQ34 -> 436298.64 | AT34: =+AP34+AR34 -> 508985.67 | AU34: 41500.01 | AV34: 16550 | AW34: =+AS34+AU34 -> 477798.65 | AX34: =+AT34+AV34 -> 525535.67 | AY34: 46999.691 | AZ34: =38139.639-111 -> 38028.639 | BA34: =+AQ34+AU34+AY34 -> 136999.37 | BB34: =+AR34+AV34+AZ34 -> 85536.639 | BC34: =AM34+BA34 -> 277498.54 | BD34: =AN34+BB34 -> 253559.3 | BE34: =AW34+AY34 -> 524798.34 | BF34: =AX34+AZ34 -> 563564.31 | BG34: 461999.56 | BH34: 558374.45 | BI34: 592000 | BJ34: 574823.37 | BK34: 595119.91 | BL34: 516406.77 | BM34: 627684.57 | BN34: 533055.82 | BO34: 608495.73 | BP34: 304999.74 | BQ34: 629438.96
B35: 200x280 mm | C35: Mt | D35: 0 | E35: 0 | F35: 0 | G35: 0 | H35: 3000 | I35: =+E35+G35 -> 0 | J35: =+F35+H35 -> 3000 | K35: 0 | L35: 1066 | M35: =+E35+G35+K35 -> 0 | N35: =+F35+H35+L35 -> 4066 | O35: 0 | P35: 463 | Q35: =+M35+O35 -> 0 | R35: =+N35+P35 -> 4529 | S35: 0 | T35: 8811.77 | U35: =+Q35+S35 -> 0 | V35: =+R35+T35 -> 13340.77 | W35: 0 | X35: 1414 | Y35: =+O35+S35+W35 -> 0 | Z35: =+P35+T35+X35 -> 10688.77 | AA35: =+M35+Y35 -> 0 | AB35: =+N35+Z35 -> 14754.77 | AC35: 0 | AD35: =11175+37 -> 11212 | AE35: =+AA35+AC35 -> 0 | AF35: =+AB35+AD35 -> 25966.77 | AG35: 0 | AH35: 0 | AI35: =+AE35+AG35 -> 0 | AJ35: =+AF35+AH35 -> 25966.77 | AK35: 0 | AL35: 703.34 | AM35: =+AC35+AG35+AK35 -> 0 | AN35: =+AD35+AH35+AL35 -> 11915.34 | AO35: =AI35+AK35 -> 0 | AP35: =AJ35+AL35 -> 26670.11 | AQ35: 0 | AR35: 7040 | AS35: =+AO35+AQ35 -> 0 | AT35: =+AP35+AR35 -> 33710.11 | AU35: 0 | AV35: 1892 | AW35: =+AS35+AU35 -> 0 | AX35: =+AT35+AV35 -> 35602.11 | AY35: 0 | AZ35: =4180.26+111 -> 4291.26 | BA35: =+AQ35+AU35+AY35 -> 0 | BB35: =+AR35+AV35+AZ35 -> 13223.26 | BC35: =AM35+BA35 -> 0 | BD35: =AN35+BB35 -> 25138.6 | BE35: =AW35+AY35 -> 0 | BF35: =AX35+AZ35 -> 39893.37 | BG35: 17999.996 | BH35: 63663.849 | BI35: 57999.916 | BJ35: 101828.14 | BK35: 116079.05 | BL35: 153592.34 | BM35: 204330.35 | BN35: 371378.01 | BO35: 329378.8 | BP35: 267000 | BQ35: 248401
B36: Saleable Semis | C36: Mt | D36: =SUM(D34:D35) -> 524798.34 | E36: =SUM(E34:E35) -> 48499.815 | F36: =SUM(F34:F35) -> 45616.588 | G36: =SUM(G34:G35) -> 48499.577 | H36: =SUM(H34:H35) -> 55556 | I36: =SUM(I34:I35) -> 96999.392 | J36: =SUM(J34:J35) -> 101172.59 | K36: =SUM(K34:K35) -> 48000.111 | ... BF36: =SUM(BF34:BF35) -> 603457.68 | BG36: 479999.56 | BH36: 622038.3 | BI36: 649999.92 | BJ36: 676651.51 | BK36: 711198.96 | BL36: 669999.11 | BM36: 832014.92 | BN36: 904433.83 | BO36: 937874.53 | BP36: =SUM(BP34:BP35) -> 571999.74 | BQ36: =SUM(BQ34:BQ35) -> 877839.96
B37: TOTAL SALEABLE STEEL | C37: Mt | D37: =+D33+D36 -> 2674798.3 | E37: =+E33+E36 -> 228999.82 | F37: =+F33+F36 -> 198797.95 | G37: =+G33+G36 -> 236499.58 | H37: =+H33+H36 -> 228302.58 | I37: =+I33+I36 -> 465499.39 | J37: =+J33+J36 -> 427100.53 | K37: =+K33+K36 -> 229000.11 | ... BF37: =+BF33+BF36 -> 2604730.3 | BG37: 2409999.6 | BH37: 2331824 | BI37: 2524999.9 | BJ37: 2409644.1 | BK37: 2315207.8 | BL37: 2369999.1 | BM37: 2160425.8 | BN37: 2235274.9 | BO37: 1823884.4 | BP37: =+BP33+BP36 -> 2406999.7 | BQ37: =+BQ33+BQ36 -> 2093720.2
B38: SAL STEEL PRODN (CATEGORY WISE)
B39: Wire Rod Plain Coils | C39: Mt | D39: =+D30 -> 500000 | E39: =+E30 -> 42500 | F39: =+WRM!F199 -> 36742.13 | G39: =+G30 -> 44000 | H39: =+WRM!H199 -> 39351.8 | I39: =+E39+G39 -> 86500 | J39: =+F39+H39 -> 76093.93 | K39: =+K30 -> 42500 | L39: =+WRM!L199 -> 28929.6 | M39: =+E39+G39+K39 -> 129000 | N39: =+F39+H39+L39 -> 105023.53 | O39: =+O30 -> 44000 | P39: =+WRM!P199 -> 35815.55 | Q39: =+M39+O39 -> 173000 | R39: =+N39+P39 -> 140839.08 | S39: =+S30 -> 44000 | T39: =+WRM!T199 -> 38718.35 | U39: =+Q39+S39 -> 217000 | V39: =+R39+T39 -> 179557.43 | W39: =+W30 -> 25000 | X39: =+WRM!X199 -> 41006.15 | Y39: =+O39+S39+W39 -> 113000 | Z39: =+P39+T39+X39 -> 115540.05 | AA39: =+M39+Y39 -> 242000 | AB39: =+N39+Z39 -> 220563.58 | AC39: =+AC30 -> 42500 | AD39: =+WRM!AD199 -> 30034.55 | AE39: =+AA39+AC39 -> 284500 | AF39: =+AB39+AD39 -> 250598.13 | AG39: =+AG30 -> 42500 | AH39: =+WRM!AH199 -> 34614.25 | AI39: =+AE39+AG39 -> 327000 | AJ39: =+AF39+AH39 -> 285212.38 | AK39: =+AK30 -> 44000 | AL39: =+WRM!AL199 -> 44007.35 | AM39: =+AC39+AG39+AK39 -> 129000 | AN39: =+AD39+AH39+AL39 -> 108656.15 | AO39: =AI39+AK39 -> 371000 | AP39: =AJ39+AL39 -> 329219.73 | AQ39: =+AQ30 -> 44500 | AR39: =+WRM!AR199 -> 44589.55 | AS39: =+AO39+AQ39 -> 415500 | AT39: =+AP39+AR39 -> 373809.28 | AU39: =+AU30 -> 40000 | AV39: =+WRM!AV199 -> 37420.7 | AW39: =+AS39+AU39 -> 455500 | AX39: =+AT39+AV39 -> 411229.98 | AY39: =+AY30 -> 44500 | AZ39: =+WRM!AZ199 -> 46692.85 | BA39: =+AQ39+AU39+AY39 -> 129000 | BB39: =+AR39+AV39+AZ39 -> 128703.1 | BC39: =AM39+BA39 -> 258000 | BD39: =AN39+BB39 -> 237359.25 | BE39: =AW39+AY39 -> 500000 | BF39: =AX39+AZ39 -> 457922.83 | BG39: 500000 | BH39: 459030.64 | BI39: 500000 | BJ39: 471802.34 | BK39: 410762.6 | BL39: =+BL30 -> 500000 | BM39: 456374.84 | BN39: =+BN30 -> 435965.96 | BO39: 333534.61 | BP39: 500000 | BQ39: 270654.57
B40: TMT Coils | C40: Mt | F40: =+WRM!F200 -> 0 | H40: =+WRM!H200 -> 0 | J40: =+F40+H40 -> 0 | L40: =+WRM!L200 -> 9361.75 | N40: =+F40+H40+L40 -> 9361.75 | P40: =+WRM!P200 -> 11248.35 | R40: =+N40+P40 -> 20610.1 | T40: =+WRM!T200 -> 0 | V40: =+R40+T40 -> 20610.1 | X40: =+WRM!X200 -> 0 | Z40: =+P40+T40+X40 -> 11248.35 | AB40: =+N40+Z40 -> 20610.1 | AD40: =+WRM!AD200 -> 0 | AF40: =+AB40+AD40 -> 20610.1 | AH40: =+WRM!AH200 -> 0 | AJ40: =+AF40+AH40 -> 20610.1 | AL40: =+WRM!AL200 -> 0 | AN40: =+AD40+AH40+AL40 -> 0 | AP40: =AJ40+AL40 -> 20610.1 | AR40: =+WRM!AR200 -> 0 | AT40: =+AP40+AR40 -> 20610.1 | AV40: =+WRM!AV200 -> 0 | AX40: =+AT40+AV40 -> 20610.1 | AZ40: =+WRM!AZ200 -> 0 | BA40: =+AQ40+AU40+AY40 -> 0 | BB40: =+AR40+AV40+AZ40 -> 0 | BC40: =AM40+BA40 -> 0 | BD40: =AN40+BB40 -> 0 | BF40: =AX40+AZ40 -> 20610.1 | BH40: 0 | BJ40: 6726.05 | BK40: 55352.05 | BM40: 8968.93 | BO40: 22983.766 | BQ40: 141370.65
...

Sheet Maj Despatch Summ
B1: MAJOR DESPATCH SUMMARY 2025-26 (As per Finance CENVAT report)
E2: 30 | F2: 30 | G2: 31 | H2: 31 | I2: =+G2+E2 -> 61 | J2: =+H2+F2 -> 61 | K2: 30 | L2: 30 | M2: =+E2+G2+K2 -> 91 | N2: =+F2+H2+L2 -> 91 | O2: 31 | P2: 31 | Q2: =+M2+O2 -> 122 | R2: =+N2+P2 -> 122 | S2: 31 | T2: 31 | U2: =+Q2+S2 -> 153 | V2: =+R2+T2 -> 153 | W2: 30 | X2: 30 | Y2: =+O2+S2+W2 -> 92 | Z2: =+P2+T2+X2 -> 92 | AA2: =+M2+Y2 -> 183 | AB2: =+N2+Z2 -> 183 | AC2: 31 | AD2: 31 | AE2: =AA2+AC2 -> 214 | AF2: =AB2+AD2 -> 214 | AG2: 30 | AH2: 30 | AI2: =AE2+AG2 -> 244 | AJ2: =AF2+AH2 -> 244 | AK2: 31 | AL2: 31 | AM2: =+AC2+AG2+AK2 -> 92 | AN2: =+AD2+AH2+AL2 -> 92 | AO2: =AI2+AK2 -> 275 | AP2: =AJ2+AL2 -> 275 | AQ2: 31 | AR2: 31 | AS2: =AO2+AQ2 -> 306 | AT2: =AP2+AR2 -> 306 | AU2: 28 | AV2: 28 | AW2: =AS2+AU2 -> 334 | AX2: =AT2+AV2 -> 334 | AY2: 31 | AZ2: 31 | BA2: =+AQ2+AU2+AY2 -> 90 | BB2: =+AR2+AV2+AZ2 -> 90 | BC2: =AM2+BA2 -> 182 | BD2: =AN2+BB2 -> 182 | BE2: =AW2+AY2 -> 365 | BF2: =AX2+AZ2 -> 365 | BO2: 365 | BP2: 365 | BQ2: 366 | BR2: 366
B3: ITEM | C3: Unit | D3: 2025-26 ABP | E3: Apr'25 | G3: May'25 | I3: 2M | K3: Jun'25 | M3: QTR-1 | O3: Jul'25 | Q3: 4M | S3: Aug'25 | U3: 5M | W3: Sep'25 | Y3: QTR-2 | AA3: H1 | AC3: Oct'25 | AE3: 7M | AG3: Nov'25 | AI3: 8M | AK3: Dec'25 | AM3: QTR-3 | AO3: 9M | AQ3: Jan'26 | AS3: 10M | AU3: Feb'26 | AW3: 11M | AY3: Mar'26 | BA3: QTR-4 | BC3: H2 | BE3: 2025-26 | BG3: 2024-25 | BI3: 2023-24 | BK3: 2022-23 | BM3: 2021-22 | BO3: 2020-21 | BQ3: 2019-20
E4: ABP | F4: ACT | G4: ABP | H4: ACT | I4: ABP | J4: ACT | K4: ABP | L4: ACT | M4: ABP | N4: ACT | O4: ABP | P4: ACT | Q4: ABP | R4: ACT | S4: ABP | T4: ACT | U4: ABP | V4: ACT | W4: ABP | X4: ACT | Y4: ABP | Z4: ACT | AA4: ABP | AB4: ACT | AC4: ABP | AD4: ACT | AE4: ABP | AF4: ACT | AG4: ABP | AH4: ACT | AI4: ABP | AJ4: ACT | AK4: ABP | AL4: ACT | AM4: ABP | AN4: ACT | AO4: ABP | AP4: ACT | AQ4: ABP | AR4: ACT | AS4: ABP | AT4: ACT | AU4: ABP | AV4: ACT | AW4: ABP | AX4: ACT | AY4: ABP | AZ4: ACT | BA4: ABP | BB4: ACT | BC4: ABP | BD4: ACT | BE4: ABP | BF4: ACT | BG4: ABP | BH4: ACT | BI4: ABP | BJ4: ACT | BK4: ABP | BL4: ACT | BM4: ABP | BN4: ACT | BO4: ABP | BP4: ACT | BQ4: ABP | BR4: ACT
B5: Saleable Steel (mill-wise)
B6: MKTG-Plant sales | C6: MT | D6: 25000 | E6: 2083.3333 | F6: 1095.89 | G6: 2083.3333 | H6: 2704.95 | I6: =+E6+G6 -> 4166.6667 | J6: =+F6+H6 -> 3800.84 | K6: 2083.3333 | L6: 6803.81 | M6: =+E6+G6+K6 -> 6250 | N6: =+F6+H6+L6 -> 10604.65 | O6: 2083.3333 | P6: 3865.36 | Q6: =+M6+O6 -> 8333.3333 | R6: =+N6+P6 -> 14470.01 | S6: 2083.3333 | T6: 6257.93 | U6: =+Q6+S6 -> 10416.667 | V6: =+R6+T6 -> 20727.94 | W6: 2083 | X6: 5182.59 | Y6: =+O6+S6+W6 -> 6249.6667 | Z6: =+P6+T6+X6 -> 15305.88 | AA6: =+M6+Y6 -> 12499.667 | AB6: =+N6+Z6 -> 25910.53 | AC6: =83.3333333333333+2000 -> 2083.3333 | AD6: 5221.92 | AE6: =+AA6+AC6 -> 14583 | AF6: =+AB6+AD6 -> 31132.45 | AG6: 2083.3333 | AH6: 0 | AI6: =+AE6+AG6 -> 16666.333 | AJ6: =+AF6+AH6 -> 31132.45 | AK6: 2083.3333 | AL6: 2960.73 | AM6: =+AC6+AG6+AK6 -> 6250 | AN6: =+AD6+AH6+AL6 -> 8182.65 | AO6: =AI6+AK6 -> 18749.667 | AP6: =AJ6+AL6 -> 34093.18 | AQ6: 2083.3333 | AR6: 6204.61 | AS6: =+AO6+AQ6 -> 20833 | AT6: =+AP6+AR6 -> 40297.79 | AU6: 2083.3333 | AV6: 3912.15 | AW6: =+AS6+AU6 -> 22916.333 | AX6: =+AT6+AV6 -> 44209.94 | AY6: 2083.3333 | AZ6: 3740.4 | BA6: =+AQ6+AU6+AY6 -> 6250 | BB6: =+AR6+AV6+AZ6 -> 13857.16 | BC6: =AM6+BA6 -> 12500 | BD6: =AN6+BB6 -> 22039.81 | BE6: =+AW6+AY6 -> 24999.667 | BF6: =+AX6+AZ6 -> 47950.34 | BG6: 21500 | BH6: 53987.54 | BI6: 21500 | BJ6: 30649.84 | BK6: 25500 | BL6: 34807.22 | BM6: 16050 | BN6: 33201.15 | BO6: 0 | BP6: 35268.25 | BQ6: 2000 | BR6: 28405.85
B7: IPT | C7: MT | D7: 0 | E7: 0 | F7: 0 | G7: 0 | H7: 0 | I7: =+E7+G7 -> 0 | J7: =+F7+H7 -> 0 | K7: 0 | L7: 0 | M7: =+E7+G7+K7 -> 0 | N7: =+F7+H7+L7 -> 0 | O7: 0 | P7: 64.1 | Q7: =+M7+O7 -> 0 | R7: =+N7+P7 -> 64.1 | S7: 0 | T7: 1485.16 | U7: =+Q7+S7 -> 0 | V7: =+R7+T7 -> 1549.26 | W7: 0 | X7: 694 | Y7: =+O7+S7+W7 -> 0 | Z7: =+P7+T7+X7 -> 2243.26 | AA7: =+M7+Y7 -> 0 | AB7: =+N7+Z7 -> 2243.26 | AC7: 0 | AD7: 747.82 | AE7: =+AA7+AC7 -> 0 | AF7: =+AB7+AD7 -> 2991.08 | AG7: 0 | AH7: 0 | AI7: =+AE7+AG7 -> 0 | AJ7: =+AF7+AH7 -> 2991.08 | AK7: 0 | AL7: 244.1 | AM7: =+AC7+AG7+AK7 -> 0 | AN7: =+AD7+AH7+AL7 -> 991.92 | AO7: =AI7+AK7 -> 0 | AP7: =AJ7+AL7 -> 3235.18 | AQ7: 0 | AR7: 0 | AS7: =+AO7+AQ7 -> 0 | AT7: =+AP7+AR7 -> 3235.18 | AU7: 0 | AV7: 2333.64 | AW7: =+AS7+AU7 -> 0 | AX7: =+AT7+AV7 -> 5568.82 | AY7: 0 | AZ7: 2066.9 | BA7: =+AQ7+AU7+AY7 -> 0 | BB7: =+AR7+AV7+AZ7 -> 4400.54 | BC7: =AM7+BA7 -> 0 | BD7: =AN7+BB7 -> 5392.46 | BE7: =+AW7+AY7 -> 0 | BF7: =+AX7+AZ7 -> 7635.72 | BG7: 0 | BH7: 322.72 | BI7: 0 | BJ7: 3076.2 | BK7: 123000 | BL7: 42263.08 | BM7: 0 | BN7: 71707.42 | BO7: 10800 | BP7: 9758.51 | BQ7: 24210 | BR7: 5928.095
B8: CMO-WR MILL | C8: MT | D8: 499000 | E8: 42416.667 | F8: 33332.8 | G8: 43916.667 | H8: 39367.02 | I8: =+E8+G8 -> 86333.333 | J8: =+F8+H8 -> 72699.82 | K8: 42416.667 | L8: 37508.06 | M8: =+E8+G8+K8 -> 128750 | N8: =+F8+H8+L8 -> 110207.88 | O8: 43916.667 | P8: 44133.19 | Q8: =+M8+O8 -> 172666.67 | R8: =+N8+P8 -> 154341.07 | S8: 43916.667 | T8: 40726.54 | U8: =+Q8+S8 -> 216583.33 | V8: =+R8+T8 -> 195067.61 | W8: 24916.667 | X8: 36332.97 | Y8: =+O8+S8+W8 -> 112750 | Z8: =+P8+T8+X8 -> 121192.7 | AA8: =+M8+Y8 -> 241500 | AB8: =+N8+Z8 -> 231400.58 | AC8: 42416.667 | AD8: 31032.3 | AE8: =+AA8+AC8 -> 283916.67 | AF8: =+AB8+AD8 -> 262432.88 | AG8: 42416.667 | AH8: 38334.736 | AI8: =+AE8+AG8 -> 326333.33 | AJ8: =+AF8+AH8 -> 300767.62 | AK8: 43916.667 | AL8: 41187.81 | AM8: =+AC8+AG8+AK8 -> 128750 | AN8: =+AD8+AH8+AL8 -> 110554.85 | AO8: =AI8+AK8 -> 370250 | AP8: =AJ8+AL8 -> 341955.43 | AQ8: 44416.667 | AR8: 39752.561 | AS8: =+AO8+AQ8 -> 414666.67 | AT8: =+AP8+AR8 -> 381707.99 | AU8: 39916.667 | AV8: 41871.84 | AW8: =+AS8+AU8 -> 454583.33 | AX8: =+AT8+AV8 -> 423579.83 | AY8: 44416.667 | AZ8: 48073.32 | BA8: =+AQ8+AU8+AY8 -> 128750 | BB8: =+AR8+AV8+AZ8 -> 129697.72 | BC8: =AM8+BA8 -> 257500 | BD8: =AN8+BB8 -> 240252.57 | BE8: =+AW8+AY8 -> 499000 | BF8: =+AX8+AZ8 -> 471653.15 | BG8: 498500 | BH8: 459216.41 | BI8: 498500 | BJ8: 473494.21 | BK8: 498500 | BL8: 453432.75 | BM8: 498500 | BN8: 467953.64 | BO8: 435166.29 | BP8: 351267.02 | BQ8: 498000 | BR8: 399090.26
B9: CMO-BAR MILL | C9: MT | D9: 900000 | E9: 76000 | F9: 60011.21 | G9: 79000 | H9: 67347.9 | I9: =+E9+G9 -> 155000 | J9: =+F9+H9 -> 127359.11 | K9: 76000 | L9: 73175.63 | M9: =+E9+G9+K9 -> 231000 | N9: =+F9+H9+L9 -> 200534.74 | O9: 79000 | P9: 84102.5 | Q9: =+M9+O9 -> 310000 | R9: =+N9+P9 -> 284637.24 | S9: 79000 | T9: 86905.93 | U9: =+Q9+S9 -> 389000 | V9: =+R9+T9 -> 371543.17 | W9: 47500 | X9: 68689.99 | Y9: =+O9+S9+W9 -> 205500 | Z9: =+P9+T9+X9 -> 239698.42 | AA9: =+M9+Y9 -> 436500 | AB9: =+N9+Z9 -> 440233.16 | AC9: 78000 | AD9: 52260.41 | AE9: =+AA9+AC9 -> 514500 | AF9: =+AB9+AD9 -> 492493.57 | AG9: 76000 | AH9: 70091.169 | AI9: =+AE9+AG9 -> 590500 | AJ9: =+AF9+AH9 -> 562584.74 | AK9: 79000 | AL9: 83237.28 | AM9: =+AC9+AG9+AK9 -> 233000 | AN9: =+AD9+AH9+AL9 -> 205588.86 | AO9: =AI9+AK9 -> 669500 | AP9: =AJ9+AL9 -> 645822.02 | AQ9: 79000 | AR9: 79536.07 | AS9: =+AO9+AQ9 -> 748500 | AT9: =+AP9+AR9 -> 725358.09 | AU9: 71500 | AV9: 77559.29 | AW9: =+AS9+AU9 -> 820000 | AX9: =+AT9+AV9 -> 802917.38 | AY9: 80000 | AZ9: 81642.31 | BA9: =+AQ9+AU9+AY9 -> 230500 | BB9: =+AR9+AV9+AZ9 -> 238737.67 | BC9: =AM9+BA9 -> 463500 | BD9: =AN9+BB9 -> 444326.53 | BE9: =+AW9+AY9 -> 900000 | BF9: =+AX9+AZ9 -> 884559.69 | BG9: 870000 | BH9: 750184.19 | BI9: 850000 | BJ9: 781402.45 | BK9: 780000 | BL9: 768402.31 | BM9: 750000 | BN9: 648761.89 | BO9: 674874.74 | BP9: 436958.46 | BQ9: 800000 | BR9: 612890.55
B10: CMO-US MILL | C10: MT | D10: 750000 | E10: 62000 | F10: 44122.7 | G10: 65000 | H10: 57716 | I10: =+E10+G10 -> 127000 | J10: =+F10+H10 -> 101838.7 | K10: 62500 | L10: 56720.68 | M10: =+E10+G10+K10 -> 189500 | N10: =+F10+H10+L10 -> 158559.38 | O10: 65000 | P10: 57264.83 | Q10: =+M10+O10 -> 254500 | R10: =+N10+P10 -> 215824.21 | S10: 65000 | T10: 47224.14 | U10: =+Q10+S10 -> 319500 | V10: =+R10+T10 -> 263048.35 | W10: 33500 | X10: 45948.12 | Y10: =+O10+S10+W10 -> 163500 | Z10: =+P10+T10+X10 -> 150437.09 | AA10: =+M10+Y10 -> 353000 | AB10: =+N10+Z10 -> 308996.47 | AC10: 67000 | AD10: 30215.88 | AE10: =+AA10+AC10 -> 420000 | AF10: =+AB10+AD10 -> 339212.35 | AG10: 65000 | AH10: 49444.75 | AI10: =+AE10+AG10 -> 485000 | AJ10: =+AF10+AH10 -> 388657.1 | AK10: 67500 | AL10: 51538.881 | AM10: =+AC10+AG10+AK10 -> 199500 | AN10: =+AD10+AH10+AL10 -> 131199.51 | AO10: =AI10+AK10 -> 552500 | AP10: =AJ10+AL10 -> 440195.98 | AQ10: 68000 | AR10: 55396.94 | AS10: =+AO10+AQ10 -> 620500 | AT10: =+AP10+AR10 -> 495592.92 | AU10: 61000 | AV10: 53071.49 | AW10: =+AS10+AU10 -> 681500 | AX10: =+AT10+AV10 -> 548664.41 | AY10: 68500 | AZ10: 58800.212 | BA10: =+AQ10+AU10+AY10 -> 197500 | BB10: =+AR10+AV10+AZ10 -> 167268.64 | BC10: =AM10+BA10 -> 397000 | BD10: =AN10+BB10 -> 298468.15 | BE10: =+AW10+AY10 -> 750000 | BF10: =+AX10+AZ10 -> 607464.62 | BG10: 560000 | BH10: 502052.01 | BI10: 525000 | BJ10: 452802.59 | BK10: 470000 | BL10: 357334.79 | BM10: 445000 | BN10: 214319.65 | BO10: 220000 | BP10: 100400.4 | BQ10: 535000 | BR10: 167166.99
