Workbook
Name _1: #REF!
Name _1: #REF!
Name _1: #REF!
Name _1: #REF!
Name _1: #REF!
Name _2: #REF!
Name _2: #REF!
Name _2: #REF!
Name _2: #REF!
Name _3: #REF!
Name _3: #REF!
Name _3: #REF!
Name _3: #REF!
Name _4: #REF!
Name a: #REF!
Name a: #REF!
Name AA: #REF!
Name AA: #REF!
Name AB: #REF!
Name AB: #REF!
Name AC: #REF!
Name AD: #REF!
Name AE: #REF!
Name AF: #REF!
Name AG: #REF!
Name AH: #REF!
Name AI: #REF!
Name AK: #REF!
Name AL: #REF!
Name AM: #REF!
Name AN: #REF!
Name AS: #REF!
Name CL: #REF!
Name D: #REF!
Name E: #REF!
Name F: #REF!
Name G: #REF!
Name H: #REF!
Name I: #REF!
Name J: #REF!
Name K: #REF!
Name L: #REF!
Name M: #REF!
Name N: #REF!
Name O: #REF!
Name P: #REF!
Name Q: #REF!
Name Q: #REF!
Name RL: #REF!
Name RL: #REF!
Name RM: #REF!
Name rmisp: #REF!
Name S: #REF!
Name S: #REF!
Name T: #REF!
Name U: #REF!
Name V: #REF!
Name W: #REF!
Name X: #REF!
Name Y: #REF!

Sheet Maj Production Summ
B1: MAJOR PRODUCTION SUMMARY | D1: 365 | E1: 30 | F1: 30 | G1: 31 | H1: 31 | I1: =+E1+G1 -> 61 | J1: =+F1+H1 -> 61 | K1: 30 | L1: 30 | M1: =+I1+K1 -> 91 | N1: =+J1+L1 -> 91 | O1: 31 | P1: 31 | Q1: =+M1+O1 -> 122 | R1: =+N1+P1 -> 122 | S1: 31 | T1: 31 | U1: =+Q1+S1 -> 153 | V1: =+R1+T1 -> 153 | W1: 30 | X1: 30 | Y1: =+O1+S1+W1 -> 92 | Z1: =+P1+T1+X1 -> 92 | AA1: =+U1+W1 -> 183 | AB1: =+V1+X1 -> 183 | AC1: 31 | AD1: 31 | AE1: =+AA1+AC1 -> 214 | AF1: =+AB1+AD1 -> 214 | AG1: 30 | AH1: 30 | AI1: =+AE1+AG1 -> 244 | AJ1: =+AF1+AH1 -> 244 | AK1: 31 | AL1: 31 | AM1: =+AC1+AG1+AK1 -> 92 | AN1: =+AD1+AH1+AL1 -> 92 | AO1: =+AI1+AK1 -> 275 | AP1: =+AJ1+AL1 -> 275 | AQ1: 31 | AR1: 31 | AS1: =+AO1+AQ1 -> 306 | AT1: =+AP1+AR1 -> 306 | AU1: 28 | AV1: 28 | AW1: =+AS1+AU1 -> 334 | AX1: =+AT1+AV1 -> 334 | AY1: 31 | AZ1: 31 | BA1: =+AQ1+AU1+AY1 -> 90 | BB1: =+AR1+AV1+AZ1 -> 90 | BC1: =+BA1+AM1 -> 182 | BD1: =+BB1+AN1 -> 182 | BE1: =+AW1+AY1 -> 365 | BF1: =+AX1+AZ1 -> 365 | BG1: 365 | BH1: 365 | BI1: 366 | BJ1: 366
D2: 365 | E2: 30 | F2: 30 | G2: 31 | H2: 31 | I2: =+E2+G2 -> 61 | J2: =+F2+H2 -> 61 | K2: 30 | L2: 30 | M2: =+I2+K2 -> 91 | N2: =+J2+L2 -> 91 | O2: 31 | P2: 31 | Q2: =+M2+O2 -> 122 | R2: =+N2+P2 -> 122 | S2: 31 | T2: 31 | U2: =+Q2+S2 -> 153 | V2: =+R2+T2 -> 153 | W2: 30 | X2: 30 | Y2: =+O2+S2+W2 -> 92 | Z2: =+P2+T2+X2 -> 92 | AA2: =+U2+W2 -> 183 | AB2: =+V2+X2 -> 183 | AC2: 31 | AD2: 31 | AE2: =+AA2+AC2 -> 214 | AF2: =+AB2+AD2 -> 214 | AG2: 30 | AH2: 30 | AI2: =+AE2+AG2 -> 244 | AJ2: =+AF2+AH2 -> 244 | AK2: 31 | AL2: 31 | AM2: =+AC2+AG2+AK2 -> 92 | AN2: =+AD2+AH2+AL2 -> 92 | AO2: =+AI2+AK2 -> 275 | AP2: =+AJ2+AL2 -> 275 | AQ2: 31 | AR2: 31 | AS2: =+AO2+AQ2 -> 306 | AT2: =+AP2+AR2 -> 306 | AU2: 28 | AV2: 28 | AW2: =+AS2+AU2 -> 334 | AX2: =+AT2+AV2 -> 334 | AY2: 31 | AZ2: 31 | BA2: =+AQ2+AU2+AY2 -> 90 | BB2: =+AR2+AV2+AZ2 -> 90 | BC2: =+BA2+AM2 -> 182 | BD2: =+BB2+AN2 -> 182 | BE2: =+AW2+AY2 -> 365 | BF2: =+AX2+AZ2 -> 365 | BG2: 365 | BH2: 365 | BI2: 366 | BJ2: 366
B3: ITEM | C3: Unit | D3: 2021-22 ABP | E3: Apr'21 | G3: May'21 | I3: 2M | K3: Jun'21 | M3: QTR-1 | O3: Jul'21 | Q3: 4M | S3: Aug'21 | U3: 5M | W3: Sep'21 | Y3: QTR 2 | AA3: H1 | AC3: Oct'21 | AE3: 7M | AG3: Nov'21 | AI3: 8M | AK3: Dec'21 | AM3: QTR 3 | AO3: 9 M | AQ3: Jan'22 | AS3: 10M | AU3: Feb'22 | AW3: 11M | AY3: Mar'22 | BA3: QTR 4 | BC3: H2 | BE3: 2021-22 | BG3: 2020-21 | BI3: 2019-20 | BL3: 350 | BM3: =2.7*1000000 -> 2700000
E4: ABP | F4: ACT | G4: ABP | H4: ACT | I4: ABP | J4: ACT | K4: ABP | L4: ACT | M4: ABP | N4: ACT | O4: ABP | P4: ACT | Q4: ABP | R4: ACT | S4: ABP | T4: ACT | U4: ABP | V4: ACT | W4: ABP | X4: ACT | Y4: ABP | Z4: ACT | AA4: ABP | AB4: ACT | AC4: ABP | AD4: ACT | AE4: ABP | AF4: ACT | AG4: ABP | AH4: ACT | AI4: ABP | AJ4: ACT | AK4: ABP | AL4: ACT | AM4: ABP | AN4: ACT | AO4: ABP | AP4: ACT | AQ4: ABP | AR4: ACT | AS4: ABP | AT4: ACT | AU4: ABP | AV4: ACT | AW4: ABP | AX4: ACT | AY4: ABP | AZ4: ACT | BA4: ABP | BB4: ACT | BC4: ABP | BD4: ACT | BE4: ABP | BF4: ACT | BG4: ABP | BH4: ACT | BI4: ABP | BJ4: ACT | BL4: 1 | BM4: =+BM3/BL3 -> 7714.2857
B5: COKE OVENS PUSHING | BL5: 336 | BM5: =+BM4*BL5 -> 2592000
B6: (COB#10) | C6: Nos/ day | D6: 99 | E6: 99 | F6: =+F9/F2 -> 97.666667 | G6: 99 | H6: =+H9/H2 -> 97.83871 | I6: =+((E6*$E$2)+(G6*$G$2))/$I$2 -> 99 | J6: =+((F6*$F$2)+(H6*$H$2))/$J$2 -> 97.754098 | K6: 99 | L6: =+L9/L2 -> 96.266667 | M6: =+((I6*$I$2)+(K6*$K$2))/$M$2 -> 99 | N6: =+((J6*$J$2)+(L6*$L$2))/$N$2 -> 97.263736 | O6: 99 | P6: =+P9/P2 -> 97.677419 | Q6: =+((M6*M$2)+(O6*O$2))/Q$2 -> 99 | R6: =+((N6*N$2)+(P6*P$2))/R$2 -> 97.368852 | S6: 99 | T6: =+T9/T2 -> 98.967742 | U6: =+((Q6*Q$2)+(S6*S$2))/U$2 -> 99 | V6: =+((R6*R$2)+(T6*T$2))/V$2 -> 97.69281 | W6: 99 | X6: =+X9/X2 -> 97.266667 | Y6: =+((O$6*O$1)+(S$6*S$1)+(W$6*W$1))/Y$1 -> 99 | Z6: =+((P$6*P$1)+(T$6*T$1)+(X$6*X$1))/Z$1 -> 97.978261 | AA6: =+((U6*U$2)+(W6*W$2))/AA$2 -> 99 | AB6: =+((V6*V$2)+(X6*X$2))/AB$2 -> 97.622951 | AC6: 99 | AD6: =+AD9/AD2 -> 95.193548 | AE6: =+((AA6*AA$2)+(AC6*AC$2))/AE$2 -> 99 | AF6: =+((AB6*AB$2)+(AD6*AD$2))/AF$2 -> 97.271028 | AG6: 99 | AH6: =+AH9/AH2 -> 98.533333 | AI6: =+((AE6*AE$2)+(AG6*AG$2))/AI$2 -> 99 | AJ6: =+((AF6*AF$2)+(AH6*AH$2))/AJ$2 -> 97.42623 | AK6: 99 | AL6: =+AL9/AL2 -> 99.096774 | AM6: =+((AC$6*AC$1)+(AG$6*AG$1)+(AK$6*AK$1))/AM$1 -> 99 | AN6: =+((AD$6*AD$1)+(AH$6*AH$1)+(AL$6*AL$1))/AN$1 -> 97.597826 | AO6: =+((AI6*AI$2)+(AK6*AK$2))/AO$2 -> 99 | AP6: =+((AJ6*AJ$2)+(AL6*AL$2))/AP$2 -> 97.614545 | AQ6: 99 | AR6: =+AR9/AR2 -> 99 | AS6: =+((AO6*AO$2)+(AQ6*AQ$2))/AS$2 -> 99 | AT6: =+((AP6*AP$2)+(AR6*AR$2))/AT$2 -> 97.754902 | AU6: 99 | AV6: =+AV9/AV2 -> 98.892857 | AW6: =+((AS6*AS$2)+(AU6*AU$2))/AW$2 -> 99 | AX6: =+((AT6*AT$2)+(AV6*AV$2))/AX$2 -> 97.850299 | AY6: 99 | AZ6: =+AZ9/AZ2 -> 97.548387 | BA6: =+((AQ$6*AQ$1)+(AU$6*AU$1)+(AY$6*AY$1))/BA$1 -> 99 | BB6: =+((AR$6*AR$1)+(AV$6*AV$1)+(AZ$6*AZ$1))/BB$1 -> 98.466667 | BC6: =+((AM6*AM$2)+(BA6*BA$2))/BC$2 -> 99 | BD6: =+((AN6*AN$2)+(BB6*BB$2))/BD$2 -> 98.027473 | BE6: =+((AW6*AW$2)+(AY6*AY$2))/BE$2 -> 99 | BF6: =+((AX6*AX$2)+(AZ6*AZ$2))/BF$2 -> 97.824658 | BG6: 95.547945 | BH6: 95.342466 | BI6: 97 | BJ6: 97.10959
B7: (COB#11) | C7: Nos/ day | D7: 99 | E7: 99 | F7: =+F10/F2 -> 92.033333 | G7: 99 | H7: =+H10/H2 -> 93.225806 | I7: =+((E7*$E$2)+(G7*$G$2))/$I$2 -> 99 | J7: =+((F7*$F$2)+(H7*$H$2))/$J$2 -> 92.639344 | K7: 99 | L7: =+L10/L2 -> 95.133333 | M7: =+((I7*$I$2)+(K7*$K$2))/$M$2 -> 99 | N7: =+((J7*$J$2)+(L7*$L$2))/$N$2 -> 93.461538 | O7: 99 | P7: =+P10/P2 -> 92.935484 | Q7: =+((M7*M$2)+(O7*O$2))/Q$2 -> 99 | R7: =+((N7*N$2)+(P7*P$2))/R$2 -> 93.327869 | S7: 99 | T7: =+T10/T2 -> 97.967742 | U7: =+((Q7*Q$2)+(S7*S$2))/U$2 -> 99 | V7: =+((R7*R$2)+(T7*T$2))/V$2 -> 94.267974 | W7: 99 | X7: =+X10/X2 -> 98.133333 | Y7: =+((O$7*O$1)+(S$7*S$1)+(W$7*W$1))/Y$1 -> 99 | Z7: =+((P$7*P$1)+(T$7*T$1)+(X$7*X$1))/Z$1 -> 96.326087 | AA7: =+((U7*U$2)+(W7*W$2))/AA$2 -> 99 | AB7: =+((V7*V$2)+(X7*X$2))/AB$2 -> 94.901639 | AC7: 99 | AD7: =+AD10/AD2 -> 98.83871 | AE7: =+((AA7*AA$2)+(AC7*AC$2))/AE$2 -> 99 | AF7: =+((AB7*AB$2)+(AD7*AD$2))/AF$2 -> 95.471963 | AG7: 99 | AH7: =+AH10/AH2 -> 98.8 | AI7: =+((AE7*AE$2)+(AG7*AG$2))/AI$2 -> 99 | AJ7: =+((AF7*AF$2)+(AH7*AH$2))/AJ$2 -> 95.881148 | AK7: 99 | AL7: =+AL10/AL2 -> 98.387097 | AM7: =+((AC$7*AC$1)+(AG$7*AG$1)+(AK$7*AK$1))/AM$1 -> 99 | AN7: =+((AD$7*AD$1)+(AH$7*AH$1)+(AL$7*AL$1))/AN$1 -> 98.673913 | AO7: =+((AI7*AI$2)+(AK7*AK$2))/AO$2 -> 99 | AP7: =+((AJ7*AJ$2)+(AL7*AL$2))/AP$2 -> 96.163636 | AQ7: 99 | AR7: =+AR10/AR2 -> 98.709677 | AS7: =+((AO7*AO$2)+(AQ7*AQ$2))/AS$2 -> 99 | AT7: =+((AP7*AP$2)+(AR7*AR$2))/AT$2 -> 96.421569 | AU7: 99 | AV7: =+AV10/AV2 -> 98.857143 | AW7: =+((AS7*AS$2)+(AU7*AU$2))/AW$2 -> 99 | AX7: =+((AT7*AT$2)+(AV7*AV$2))/AX$2 -> 96.625749 | AY7: 99 | AZ7: =+AZ10/AZ2 -> 98.870968 | BA7: =+((AQ$7*AQ$1)+(AU$7*AU$1)+(AY$7*AY$1))/BA$1 -> 99 | BB7: =+((AR$7*AR$1)+(AV$7*AV$1)+(AZ$7*AZ$1))/BB$1 -> 98.811111 | BC7: =+((AM7*AM$2)+(BA7*BA$2))/BC$2 -> 99 | BD7: =+((AN7*AN$2)+(BB7*BB$2))/BD$2 -> 98.741758 | BE7: =+((AW7*AW$2)+(AY7*AY$2))/BE$2 -> 99 | BF7: =+((AX7*AX$2)+(AZ7*AZ$2))/BF$2 -> 96.816438 | BG7: 94.2 | BH7: 90.778082 | BI7: 97 | BJ7: 95.710246
B8: Overall Equiv. Ovens Pushed/ Day | C8: Nos/ day | D8: 281 | E8: =E6+(E7*1.8343023255814) -> 280.59593 | F8: =F6+(F7*1.8343023255814) -> 266.48362 | G8: =G6+(G7*1.8343023255814) -> 280.59593 | H8: =H6+(H7*1.8343023255814) -> 268.84302 | I8: =I6+(I7*1.8343023255814) -> 280.59593 | J8: =J6+(J7*1.8343023255814) -> 267.68266 | K8: =K6+(K7*1.8343023255814) -> 280.59593 | L8: =L6+(L7*1.8343023255814) -> 270.76996 | ... BF8: =BF6+(BF7*1.8343023255814) -> 275.41528 | BG8: 268.33922 | BH8: 261.85691 | BI8: 274.92733 | BJ8: 272.67112
B9: (COB#10) | C9: Nos | D9: =+D6*D2 -> 36135 | E9: =+E6*E2 -> 2970 | F9: 2930 | G9: =+G6*G2 -> 3069 | H9: 3033 | I9: =+I6*I2 -> 6039 | J9: =+F9+H9 -> 5963 | K9: =+K6*K2 -> 2970 | L9: 2888 | M9: =+I9+K9 -> 9009 | N9: =+J9+L9 -> 8851 | O9: =+O6*O2 -> 3069 | P9: 3028 | Q9: =+M9+O9 -> 12078 | R9: =+N9+P9 -> 11879 | S9: =+S6*S2 -> 3069 | T9: 3068 | U9: =+Q9+S9 -> 15147 | V9: =+R9+T9 -> 14947 | W9: =+W6*W2 -> 2970 | X9: 2918 | Y9: =+O9+S9+W9 -> 9108 | Z9: =+P9+T9+X9 -> 9014 | AA9: =+U9+W9 -> 18117 | AB9: =+V9+X9 -> 17865 | AC9: =+AC6*AC2 -> 3069 | AD9: 2951 | AE9: =+AA9+AC9 -> 21186 | AF9: =+AB9+AD9 -> 20816 | AG9: =+AG6*AG2 -> 2970 | AH9: 2956 | AI9: =+AE9+AG9 -> 24156 | AJ9: =+AF9+AH9 -> 23772 | AK9: =+AK6*AK2 -> 3069 | AL9: 3072 | AM9: =+AC9+AG9+AK9 -> 9108 | AN9: =+AD9+AH9+AL9 -> 8979 | AO9: =+AI9+AK9 -> 27225 | AP9: =+AJ9+AL9 -> 26844 | AQ9: =+AQ6*AQ2 -> 3069 | AR9: 3069 | AS9: =+AO9+AQ9 -> 30294 | AT9: =+AP9+AR9 -> 29913 | AU9: =+AU6*AU2 -> 2772 | AV9: 2769 | AW9: =+AS9+AU9 -> 33066 | AX9: =+AT9+AV9 -> 32682 | AY9: =+AY6*AY2 -> 3069 | AZ9: 3024 | BA9: =+AQ9+AU9+AY9 -> 8910 | BB9: =+AR9+AV9+AZ9 -> 8862 | BC9: =+AM9+BA9 -> 18018 | BD9: =+AN9+BB9 -> 17841 | BE9: =+AW9+AY9 -> 36135 | BF9: =+AX9+AZ9 -> 35706 | BG9: 34875 | BH9: 34800 | BI9: 35502 | BJ9: 35543 | BL9: =+BF17/BM5 -> 0.92854387
B10: (COB#11) | C10: Nos | D10: =+D7*D2 -> 36135 | E10: =+E7*E2 -> 2970 | F10: 2761 | G10: =+G7*G2 -> 3069 | H10: 2890 | I10: =+I7*I2 -> 6039 | J10: =+F10+H10 -> 5651 | K10: =+K7*K2 -> 2970 | L10: 2854 | M10: =+I10+K10 -> 9009 | N10: =+J10+L10 -> 8505 | O10: =+O7*O2 -> 3069 | P10: 2881 | Q10: =+M10+O10 -> 12078 | R10: =+N10+P10 -> 11386 | S10: =+S7*S2 -> 3069 | T10: 3037 | U10: =+Q10+S10 -> 15147 | V10: =+R10+T10 -> 14423 | W10: =+W7*W2 -> 2970 | X10: 2944 | Y10: =+O10+S10+W10 -> 9108 | Z10: =+P10+T10+X10 -> 8862 | AA10: =+U10+W10 -> 18117 | AB10: =+V10+X10 -> 17367 | AC10: =+AC7*AC2 -> 3069 | AD10: 3064 | AE10: =+AA10+AC10 -> 21186 | AF10: =+AB10+AD10 -> 20431 | AG10: =+AG7*AG2 -> 2970 | AH10: 2964 | AI10: =+AE10+AG10 -> 24156 | AJ10: =+AF10+AH10 -> 23395 | AK10: =+AK7*AK2 -> 3069 | AL10: 3050 | AM10: =+AC10+AG10+AK10 -> 9108 | AN10: =+AD10+AH10+AL10 -> 9078 | AO10: =+AI10+AK10 -> 27225 | AP10: =+AJ10+AL10 -> 26445 | AQ10: =+AQ7*AQ2 -> 3069 | AR10: 3060 | AS10: =+AO10+AQ10 -> 30294 | AT10: =+AP10+AR10 -> 29505 | AU10: =+AU7*AU2 -> 2772 | AV10: 2768 | AW10: =+AS10+AU10 -> 33066 | AX10: =+AT10+AV10 -> 32273 | AY10: =+AY7*AY2 -> 3069 | AZ10: 3065 | BA10: =+AQ10+AU10+AY10 -> 8910 | BB10: =+AR10+AV10+AZ10 -> 8893 | BC10: =+AM10+BA10 -> 18018 | BD10: =+AN10+BB10 -> 17971 | BE10: =+AW10+AY10 -> 36135 | BF10: =+AX10+AZ10 -> 35338 | BG10: 34383 | BH10: 33134 | BI10: 35502 | BJ10: 35030 | BL10: 350 | BM10: 2500000
B11: Overall Equiv. Ovens Pushed | C11: Nos | D11: =D9+(D10*1.8343023255814) -> 102417.51 | E11: =E9+(E10*1.8343023255814) -> 8417.8779 | F11: =F9+(F10*1.8343023255814) -> 7994.5087 | G11: =G9+(G10*1.8343023255814) -> 8698.4738 | H11: =H9+(H10*1.8343023255814) -> 8334.1337 | I11: =I9+(I10*1.8343023255814) -> 17116.352 | J11: =J9+(J10*1.8343023255814) -> 16328.642 | K11: =K9+(K10*1.8343023255814) -> 8417.8779 | ... BB11: =BB9+(BB10*1.8343023255814) -> 25174.451 | BE11: =BE9+(BE10*1.8343023255814) -> 102417.51 | BF11: =BF9+(BF10*1.8343023255814) -> 100526.58 | BG11: 97943.817 | BH11: 95577.773 | BI11: 100623.4 | BJ11: 99798.61 | BL11: 1 | BM11: =+BM10/BL10 -> 7142.8571
B12: BF COKE | BL12: 336 | BM12: =+BL12*BM11 -> 2400000
B13: COB#10 | C13: Mt | D13: =+D9*0.705*17.2 -> 438173.01 | E13: =+E9*0.705*17.2 -> 36014.22 | F13: 36261 | G13: =+G9*17.2*0.705 -> 37214.694 | H13: 37251 | I13: =+E13+G13 -> 73228.914 | J13: =+F13+H13 -> 73512 | K13: 36014 | L13: 35020 | M13: =+I13+K13 -> 109242.91 | N13: =+J13+L13 -> 108532 | O13: 37214.694 | P13: 36719 | Q13: =+M13+O13 -> 146457.61 | R13: =+N13+P13 -> 145251 | S13: 37214.694 | T13: 36826 | U13: =+Q13+S13 -> 183672.3 | V13: =+R13+T13 -> 182077 | W13: 36014.22 | X13: 34880 | Y13: =+O13+S13+W13 -> 110443.61 | Z13: =+P13+T13+X13 -> 108425 | AA13: =+U13+W13 -> 219686.52 | AB13: =+V13+X13 -> 216957 | AC13: 37214.694 | AD13: 34994 | AE13: =+AA13+AC13 -> 256901.22 | AF13: =+AB13+AD13 -> 251951 | AG13: 36014.22 | AH13: 35102 | AI13: =+AE13+AG13 -> 292915.44 | AJ13: =+AF13+AH13 -> 287053 | AK13: 37214.694 | AL13: 36508 | AM13: =+AC13+AG13+AK13 -> 110443.61 | AN13: =+AD13+AH13+AL13 -> 106604 | AO13: =+AI13+AK13 -> 330130.13 | AP13: =+AJ13+AL13 -> 323561 | AQ13: 37214.694 | AR13: 36437 | AS13: =+AO13+AQ13 -> 367344.82 | AT13: =+AP13+AR13 -> 359998 | AU13: 33613.272 | AV13: 32896 | AW13: =+AS13+AU13 -> 400958.1 | AX13: =+AT13+AV13 -> 392894 | AY13: 37214.694 | AZ13: 35912 | BA13: =+AQ13+AU13+AY13 -> 108042.66 | BB13: =+AR13+AV13+AZ13 -> 105245 | BC13: =+AM13+BA13 -> 218486.27 | BD13: =+AN13+BB13 -> 211849 | BE13: =+AW13+AY13 -> 438172.79 | BF13: =+AX13+AZ13 -> 428806 | BG13: 425506 | BH13: 430922.2 | BI13: 406071.88 | BJ13: 412610.14 | BM13: =+BF18/BM12 -> 0.92827792
B14: COB#11 | C14: Mt | D14: =+D10*31.55*0.705 -> 803741.77 | E14: =+E10*31.55*0.705 -> 66060.967 | F14: 62677 | G14: =+G10*31.55*0.705 -> 68263 | H14: 65108 | I14: =+E14+G14 -> 134323.97 | J14: =+F14+H14 -> 127785 | K14: 66061 | L14: 63481 | M14: =+I14+K14 -> 200384.97 | N14: =+J14+L14 -> 191266 | O14: 68263 | P14: 64084 | Q14: =+M14+O14 -> 268647.97 | R14: =+N14+P14 -> 255350 | S14: 68263 | T14: 66868 | U14: =+Q14+S14 -> 336910.97 | V14: =+R14+T14 -> 322218 | W14: 66060.967 | X14: 64551 | Y14: =+O14+S14+W14 -> 202586.97 | Z14: =+P14+T14+X14 -> 195503 | AA14: =+U14+W14 -> 402971.93 | AB14: =+V14+X14 -> 386769 | AC14: 68263 | AD14: 66648 | AE14: =+AA14+AC14 -> 471234.93 | AF14: =+AB14+AD14 -> 453417 | AG14: 66060.967 | AH14: 64562 | AI14: =+AE14+AG14 -> 537295.9 | AJ14: =+AF14+AH14 -> 517979 | AK14: 68263 | AL14: 66487 | AM14: =+AC14+AG14+AK14 -> 202586.97 | AN14: =+AD14+AH14+AL14 -> 197697 | AO14: =+AI14+AK14 -> 605558.9 | AP14: =+AJ14+AL14 -> 584466 | AQ14: 68263 | AR14: 66640 | AS14: =+AO14+AQ14 -> 673821.9 | AT14: =+AP14+AR14 -> 651106 | AU14: 61656.903 | AV14: 60320 | AW14: =+AS14+AU14 -> 735478.8 | AX14: =+AT14+AV14 -> 711426 | AY14: 68263 | AZ14: 66766 | BA14: =+AQ14+AU14+AY14 -> 198182.9 | BB14: =+AR14+AV14+AZ14 -> 193726 | BC14: =+AM14+BA14 -> 400769.87 | BD14: =+AN14+BB14 -> 391423 | BE14: =+AW14+AY14 -> 803741.8 | BF14: =+AX14+AZ14 -> 778192 | BG14: 770203 | BH14: 752591.4 | BI14: 744858.59 | BJ14: 745859.84
B15: TOTAL | C15: Mt | D15: =SUM(D13:D14) -> 1241914.8 | E15: =SUM(E13:E14) -> 102075.19 | F15: =SUM(F13:F14) -> 98938 | G15: =SUM(G13:G14) -> 105477.69 | H15: =SUM(H13:H14) -> 102359 | I15: =SUM(I13:I14) -> 207552.88 | J15: =SUM(J13:J14) -> 201297 | K15: =SUM(K13:K14) -> 102075 | ... BB15: =SUM(BB13:BB14) -> 298971 | BE15: =SUM(BE13:BE14) -> 1241914.6 | BF15: =SUM(BF13:BF14) -> 1206998 | BG15: 1195709 | BH15: 1183513.6 | BI15: 1150930.5 | BJ15: 1158470
B16: SINTER | C16: Mt | D16: 4183927.5 | E16: 244596 | F16: =+SINTER!F54 -> 273488 | G16: 249804 | H16: 243436 | I16: =+E16+G16 -> 494400 | J16: =+F16+H16 -> 516924 | K16: 363179 | L16: 376032 | M16: =+I16+K16 -> 857579 | N16: =+J16+L16 -> 892956 | O16: 375490.41 | P16: 375866 | Q16: =+M16+O16 -> 1233069.4 | R16: =+N16+P16 -> 1268822 | S16: 375490.41 | T16: 372177 | U16: =+Q16+S16 -> 1608559.8 | V16: =+R16+T16 -> 1640999 | W16: 365208.18 | X16: 349453 | Y16: =+O16+S16+W16 -> 1116189 | Z16: =+P16+T16+X16 -> 1097496 | AA16: =+U16+W16 -> 1973768 | AB16: =+V16+X16 -> 1990452 | AC16: 377588.12 | AD16: 372810 | AE16: =+AA16+AC16 -> 2351356.1 | AF16: =+AB16+AD16 -> 2363262 | AG16: 365208.18 | AH16: 360415 | AI16: =+AE16+AG16 -> 2716564.3 | AJ16: =+AF16+AH16 -> 2723677 | AK16: 377588.12 | AL16: 390769 | AM16: =+AC16+AG16+AK16 -> 1120384.4 | AN16: =+AD16+AH16+AL16 -> 1123994 | AO16: =+AI16+AK16 -> 3094152.4 | AP16: =+AJ16+AL16 -> 3114446 | AQ16: 377588.12 | AR16: 395037 | AS16: =+AO16+AQ16 -> 3471740.5 | AT16: =+AP16+AR16 -> 3509483 | AU16: 334599.12 | AV16: 361024 | AW16: =+AS16+AU16 -> 3806339.7 | AX16: =+AT16+AV16 -> 3870507 | AY16: 377588.12 | AZ16: 407324 | BA16: =+AQ16+AU16+AY16 -> 1089775.4 | BB16: =+AR16+AV16+AZ16 -> 1163385 | BC16: =+AM16+BA16 -> 2210159.8 | BD16: =+AN16+BB16 -> 2287379 | BE16: =+AW16+AY16 -> 4183927.8 | BF16: =+AX16+AZ16 -> 4277831 | BG16: 3665891.3 | BH16: 3629577 | BI16: 3903932.5 | BJ16: 3709525 | BK16: =+BF16/1000000 -> 4.277831 | BL16: =+BF16/BK16 -> 1000000
B17: HOT METAL | C17: Mt | D17: 2650000.5 | E17: 102000 | F17: 109815 | G17: 134000 | H17: 103466.6 | I17: =+E17+G17 -> 236000 | J17: =+F17+H17 -> 213281.6 | K17: 237623 | L17: 206937 | M17: =+I17+K17 -> 473623 | N17: =+J17+L17 -> 420218.6 | O17: 245677.5 | P17: 200202 | Q17: =+M17+O17 -> 719300.5 | R17: =+N17+P17 -> 620420.6 | S17: 245677.5 | T17: 220172 | U17: =+Q17+S17 -> 964978 | V17: =+R17+T17 -> 840592.6 | W17: 238950 | X17: 213015 | Y17: =+O17+S17+W17 -> 730305 | Z17: =+P17+T17+X17 -> 633389 | AA17: =+U17+W17 -> 1203928 | AB17: =+V17+X17 -> 1053607.6 | AC17: 247050 | AD17: 232652 | AE17: =+AA17+AC17 -> 1450978 | AF17: =+AB17+AD17 -> 1286259.6 | AG17: 238950 | AH17: 207019 | AI17: =+AE17+AG17 -> 1689928 | AJ17: =+AF17+AH17 -> 1493278.6 | AK17: 247050 | AL17: 230306 | AM17: =+AC17+AG17+AK17 -> 733050 | AN17: =+AD17+AH17+AL17 -> 669977 | AO17: =+AI17+AK17 -> 1936978 | AP17: =+AJ17+AL17 -> 1723584.6 | AQ17: 247050 | AR17: 235117 | AS17: =+AO17+AQ17 -> 2184028 | AT17: =+AP17+AR17 -> 1958701.6 | AU17: 218922.97 | AV17: 210229 | AW17: =+AS17+AU17 -> 2402951 | AX17: =+AT17+AV17 -> 2168930.6 | AY17: 247050 | AZ17: 237855.1 | BA17: =+AQ17+AU17+AY17 -> 713022.97 | BB17: =+AR17+AV17+AZ17 -> 683201.1 | BC17: =+AM17+BA17 -> 1446073 | BD17: =+AN17+BB17 -> 1353178.1 | BE17: =+AW17+AY17 -> 2650001 | BF17: =+AX17+AZ17 -> 2406785.7 | BG17: 2496672.2 | BH17: 2092798 | BI17: 2700000 | BJ17: 2505193 | BK17: =+BF17/1000000 -> 2.4067857 | BL17: =+BK17/BH17 -> 1.1500325e-06
B18: CRUDE STEEL | C18: Mt | D18: 2451737.5 | E18: 93897 | F18: 99859 | G18: 97183 | H18: 79982 | I18: =+E18+G18 -> 191080 | J18: =+F18+H18 -> 179841 | K18: 222369 | L18: 195203 | M18: =+I18+K18 -> 413449 | N18: =+J18+L18 -> 375044 | O18: 229931.92 | P18: 188123 | Q18: =+M18+O18 -> 643380.92 | R18: =+N18+P18 -> 563167 | S18: 230119.72 | T18: 204220 | U18: =+Q18+S18 -> 873500.64 | V18: =+R18+T18 -> 767387 | W18: 223802.82 | X18: 198425 | Y18: =+O18+S18+W18 -> 683854.46 | Z18: =+P18+T18+X18 -> 590768 | AA18: =+U18+W18 -> 1097303.5 | AB18: =+V18+X18 -> 965812 | AC18: 231408.45 | AD18: 211320 | AE18: =+AA18+AC18 -> 1328711.9 | AF18: =+AB18+AD18 -> 1177132 | AG18: 223802.82 | AH18: 194791 | AI18: =+AE18+AG18 -> 1552514.7 | AJ18: =+AF18+AH18 -> 1371923 | AK18: 231408 | AL18: 216681 | AM18: =+AC18+AG18+AK18 -> 686619.27 | AN18: =+AD18+AH18+AL18 -> 622792 | AO18: =+AI18+AK18 -> 1783922.7 | AP18: =+AJ18+AL18 -> 1588604 | AQ18: 231408.45 | AR18: 221653 | AS18: =+AO18+AQ18 -> 2015331.2 | AT18: =+AP18+AR18 -> 1810257 | AU18: 204998.09 | AV18: 197600 | AW18: =+AS18+AU18 -> 2220329.3 | AX18: =+AT18+AV18 -> 2007857 | AY18: 231408.45 | AZ18: 220010 | BA18: =+AQ18+AU18+AY18 -> 667815 | BB18: =+AR18+AV18+AZ18 -> 639263 | BC18: =+AM18+BA18 -> 1354434.3 | BD18: =+AN18+BB18 -> 1262055 | BE18: =+AW18+AY18 -> 2451737.7 | BF18: =+AX18+AZ18 -> 2227867 | BG18: 2297163.5 | BH18: 1847433 | BI18: 2500000 | BJ18: 2083412 | BK18: =+BF18/1000000 -> 2.227867 | BL18: =+BK18/BH18 -> 1.2059257e-06
B19: Avg Heats Cast per Day | C19: Nos. / day | D19: 48.77187 | E19: =+E48/E1 -> 20.866667 | F19: =+F48/F1 -> 21.766667 | G19: =+G48/G1 -> 20.903226 | H19: =+H48/H1 -> 16.806452 | I19: =+I48/I1 -> 20.885246 | J19: =+J48/J1 -> 19.245902 | K19: =+K48/K1 -> 49.4 | L19: =+L48/L1 -> 42.2 | ... BF19: =+BF48/BF1 -> 40.065753 | BG19: 41.920046 | BH19: 33.309589 | BI19: 47.014645 | BJ19: 38.663934
B20: Cold Pig & Pig Equivalent
B21: MOG | C21: Mt | D21: 34535.234 | E21: 1935 | F21: 3131.2 | G21: 11609 | H21: 5506.5882 | I21: =+E21+G21 -> 13544 | J21: =+F21+H21 -> 8637.7882 | K21: 774 | L21: 337 | M21: =+I21+K21 -> 14318 | N21: =+J21+L21 -> 8974.7882 | O21: 773.93075 | P21: 1227 | Q21: =+M21+O21 -> 15091.931 | R21: =+N21+P21 -> 10201.788 | S21: 580.44807 | T21: 2129 | U21: =+Q21+S21 -> 15672.379 | V21: =+R21+T21 -> 12330.788 | W21: 580.44807 | X21: 1360 | Y21: =+O21+S21+W21 -> 1934.8269 | Z21: =+P21+T21+X21 -> 4716 | AA21: =+U21+W21 -> 16252.827 | AB21: =+V21+X21 -> 13690.788 | AC21: 580.44807 | AD21: 3785 | AE21: =+AA21+AC21 -> 16833.275 | AF21: =+AB21+AD21 -> 17475.788 | AG21: 580.44807 | AH21: 947 | AI21: =+AE21+AG21 -> 17413.723 | AJ21: =+AF21+AH21 -> 18422.788 | AK21: 580.44807 | AL21: 706.9909 | AM21: =+AC21+AG21+AK21 -> 1741.3442 | AN21: =+AD21+AH21+AL21 -> 5438.9909 | AO21: =+AI21+AK21 -> 17994.171 | AP21: =+AJ21+AL21 -> 19129.779 | AQ21: 580.44807 | AR21: 0 | AS21: =+AO21+AQ21 -> 18574.619 | AT21: =+AP21+AR21 -> 19129.779 | AU21: 580.44807 | AV21: 337 | AW21: =+AS21+AU21 -> 19155.067 | AX21: =+AT21+AV21 -> 19466.779 | AY21: 580.44807 | AZ21: 2894.2933 | BA21: =+AQ21+AU21+AY21 -> 1741.3442 | BB21: =+AR21+AV21+AZ21 -> 3231.2933 | BC21: =+AM21+BA21 -> 3482.6884 | BD21: =+AN21+BB21 -> 8670.2843 | BE21: =+AW21+AY21 -> 19735.515 | BF21: =+AX21+AZ21 -> 22361.072 | BG21: 20755.018 | BH21: 58220.7 | BI21: 29957.856 | BJ21: 134629.18
B22: UPIS | C22: Mt | D22: 0 | E22: 0 | F22: 206.5 | G22: 0 | H22: 655.8483 | I22: =+E22+G22 -> 0 | J22: =+F22+H22 -> 862.3483 | K22: 0 | L22: 22 | M22: =+I22+K22 -> 0 | N22: =+J22+L22 -> 884.3483 | O22: 0 | P22: 173 | Q22: =+M22+O22 -> 0 | R22: =+N22+P22 -> 1057.3483 | S22: 0 | T22: 301 | U22: =+Q22+S22 -> 0 | V22: =+R22+T22 -> 1358.3483 | W22: 0 | X22: 192 | Y22: =+O22+S22+W22 -> 0 | Z22: =+P22+T22+X22 -> 666 | AA22: =+U22+W22 -> 0 | AB22: =+V22+X22 -> 1550.3483 | AC22: 0 | AD22: 534 | AE22: =+AA22+AC22 -> 0 | AF22: =+AB22+AD22 -> 2084.3483 | AG22: 0 | AH22: 134 | AI22: =+AE22+AG22 -> 0 | AJ22: =+AF22+AH22 -> 2218.3483 | AK22: 0 | AL22: 99.81048 | AM22: =+AC22+AG22+AK22 -> 0 | AN22: =+AD22+AH22+AL22 -> 767.81048 | AO22: =+AI22+AK22 -> 0 | AP22: =+AJ22+AL22 -> 2318.1588 | AQ22: 0 | AR22: 0 | AS22: =+AO22+AQ22 -> 0 | AT22: =+AP22+AR22 -> 2318.1588 | AU22: 0 | AV22: 48 | AW22: =+AS22+AU22 -> 0 | AX22: =+AT22+AV22 -> 2366.1588 | AY22: 0 | AZ22: 408.60612 | BA22: =+AQ22+AU22+AY22 -> 0 | BB22: =+AR22+AV22+AZ22 -> 456.60612 | BC22: =+AM22+BA22 -> 0 | BD22: =+AN22+BB22 -> 1224.4166 | BE22: =+AW22+AY22 -> 0 | BF22: =+AX22+AZ22 -> 2774.7649 | BG22: 392 | BH22: 3852.3 | BI22: 1419.0563 | BJ22: 8272.9783
B23: (Equiv. Pig Iron @ 80% of HM sent to Sand Pit. (Ref to Fax Msg from ED (O), vide SAIL/OPRNS/ PPMS/33 dt. 05.02.15) | C23: Mt | D23: 0 | E23: 0 | F23: 0 | G23: =18500*0.8 -> 14800 | H23: =11518*0.8 -> 9214.4 | I23: =+E23+G23 -> 14800 | J23: =+F23+H23 -> 9214.4 | K23: 0 | L23: 0 | M23: =+I23+K23 -> 14800 | N23: =+J23+L23 -> 9214.4 | O23: 0 | P23: 0 | Q23: =+M23+O23 -> 14800 | R23: =+N23+P23 -> 9214.4 | S23: 0 | T23: 0 | U23: =+Q23+S23 -> 14800 | V23: =+R23+T23 -> 9214.4 | W23: 0 | X23: 0 | Y23: =+O23+S23+W23 -> 0 | Z23: =+P23+T23+X23 -> 0 | AA23: =+U23+W23 -> 14800 | AB23: =+V23+X23 -> 9214.4 | AC23: 0 | AD23: 0 | AE23: =+AA23+AC23 -> 14800 | AF23: =+AB23+AD23 -> 9214.4 | AG23: 0 | AH23: 0 | AI23: =+AE23+AG23 -> 14800 | AJ23: =+AF23+AH23 -> 9214.4 | AK23: 0 | AL23: 0 | AM23: =+AC23+AG23+AK23 -> 0 | AN23: =+AD23+AH23+AL23 -> 0 | AO23: =+AI23+AK23 -> 14800 | AP23: =+AJ23+AL23 -> 9214.4 | AQ23: 0 | AR23: 0 | AS23: =+AO23+AQ23 -> 14800 | AT23: =+AP23+AR23 -> 9214.4 | AU23: 0 | AV23: 0 | AW23: =+AS23+AU23 -> 14800 | AX23: =+AT23+AV23 -> 9214.4 | AY23: 0 | AZ23: 0 | BA23: =+AQ23+AU23+AY23 -> 0 | BB23: =+AR23+AV23+AZ23 -> 0 | BC23: =+AM23+BA23 -> 0 | BD23: =+AN23+BB23 -> 0 | BE23: =+AW23+AY23 -> 14800 | BF23: =+AX23+AZ23 -> 9214.4 | BG23: 0 | BH23: 0 | BI23: 0 | BJ23: 26220.8
B24: TOTAL EQUIVALENT PIG IRON | C24: Mt | D24: =SUM(D21:D23) -> 34535.234 | E24: =SUM(E21:E23) -> 1935 | F24: =SUM(F21:F23) -> 3337.7 | G24: =SUM(G21:G23) -> 26409 | H24: =SUM(H21:H23) -> 15376.836 | I24: =SUM(I21:I23) -> 28344 | J24: =SUM(J21:J23) -> 18714.536 | K24: =SUM(K21:K23) -> 774 | ... BB24: =SUM(BB21:BB23) -> 3687.8995 | BC24: =+AM24+BA24 -> 3482.6884 | BD24: =+AN24+BB24 -> 9894.7008 | BE24: =SUM(BE21:BE23) -> 34535.515 | BF24: =SUM(BF21:BF23) -> 34350.237 | BG24: 21147.018 | BH24: 62073 | BI24: 31376.912 | BJ24: 169122.96
B25: Net PCI Production | C25: Mt | D25: 2399.04 | E25: 235 | F25: 3262 | G25: 1411 | H25: 1898.93 | I25: =+E25+G25 -> 1646 | J25: =+F25+H25 -> 5160.93 | K25: 94 | L25: 2544 | M25: =+I25+K25 -> 1740 | N25: =+J25+L25 -> 7704.93 | O25: 94.08 | P25: 2390 | Q25: =+M25+O25 -> 1834.08 | R25: =+N25+P25 -> 10094.93 | S25: 70.56 | T25: 1428 | U25: =+Q25+S25 -> 1904.64 | V25: =+R25+T25 -> 11522.93 | W25: 70.56 | X25: 243 | Y25: =+O25+S25+W25 -> 235.2 | Z25: =+P25+T25+X25 -> 4061 | AA25: =+U25+W25 -> 1975.2 | AB25: =+V25+X25 -> 11765.93 | AC25: 70.56 | AD25: 403 | AE25: =+AA25+AC25 -> 2045.76 | AF25: =+AB25+AD25 -> 12168.93 | AG25: 70.56 | AH25: 487 | AI25: =+AE25+AG25 -> 2116.32 | AJ25: =+AF25+AH25 -> 12655.93 | AK25: 70.56 | AL25: 0 | AM25: =+AC25+AG25+AK25 -> 211.68 | AN25: =+AD25+AH25+AL25 -> 890 | AO25: =+AI25+AK25 -> 2186.88 | AP25: =+AJ25+AL25 -> 12655.93 | AQ25: 70.56 | AR25: 0 | AS25: =+AO25+AQ25 -> 2257.44 | AT25: =+AP25+AR25 -> 12655.93 | AU25: 70.56 | AV25: 145.026 | AW25: =+AS25+AU25 -> 2328 | AX25: =+AT25+AV25 -> 12800.956 | AY25: 70.56 | AZ25: 576.723 | BA25: =+AQ25+AU25+AY25 -> 211.68 | BB25: =+AR25+AV25+AZ25 -> 721.749 | BC25: =+AM25+BA25 -> 423.36 | BD25: =+AN25+BB25 -> 1611.749 | BE25: =+AW25+AY25 -> 2398.56 | BF25: =+AX25+AZ25 -> 13377.679 | BG25: 11568.99 | BH25: 41093.9 | BI25: 0 | BJ25: 44255.19
B26: Net Granulated Slag Production | C26: Mt | D26: 953450.92 | E26: 36985 | F26: 45318 | G26: 46750 | H26: 37351.758 | I26: =+E26+G26 -> 83735 | J26: =+F26+H26 -> 82669.758 | K26: 91932 | L26: 110633 | M26: =+I26+K26 -> 175667 | N26: =+J26+L26 -> 193302.76 | O26: 95048.257 | P26: 80624 | Q26: =+M26+O26 -> 270715.26 | R26: =+N26+P26 -> 273926.76 | S26: 95048.257 | T26: 79299 | U26: =+Q26+S26 -> 365763.51 | V26: =+R26+T26 -> 353225.76 | W26: 92445.507 | X26: 76095 | Y26: =+O26+S26+W26 -> 282542.02 | Z26: =+P26+T26+X26 -> 236018 | AA26: =+U26+W26 -> 458209.02 | AB26: =+V26+X26 -> 429320.76 | AC26: 88165.904 | AD26: 90979 | AE26: =+AA26+AC26 -> 546374.93 | AF26: =+AB26+AD26 -> 520299.76 | AG26: 82970.483 | AH26: 74191 | AI26: =+AE26+AG26 -> 629345.41 | AJ26: =+AF26+AH26 -> 594490.76 | AK26: 83400.179 | AL26: 87939 | AM26: =+AC26+AG26+AK26 -> 254536.57 | AN26: =+AD26+AH26+AL26 -> 253109 | AO26: =+AI26+AK26 -> 712745.59 | AP26: =+AJ26+AL26 -> 682429.76 | AQ26: 83400.179 | AR26: 68221.321 | AT26: =+AP26+AR26 -> 750651.08 | AU26: 73904.938 | AV26: 73109 | AW26: =+AS26+AU26 -> 73904.938 | AX26: =+AT26+AV26 -> 823760.08 | AY26: 83400.179 | AZ26: 96369.221 | BA26: =+AQ26+AU26+AY26 -> 240705.3 | BB26: =+AR26+AV26+AZ26 -> 237699.54 | BC26: =+AM26+BA26 -> 495241.86 | BD26: =+AN26+BB26 -> 490808.54 | BE26: =+AW26+AY26 -> 157305.12 | BF26: =+AX26+AZ26 -> 920129.3 | BG26: 882599.97 | BH26: 776699 | BI26: 854658 | BJ26: 809638.21
B27: Saleable Steel Production (Mill Wise)
B28: WR Mill | C28: Mt | D28: 500000 | E28: 33000 | F28: =+WRM!F116 -> 32270.342 | G28: 41500 | H28: =+WRM!H116 -> 24699.074 | I28: =+E28+G28 -> 74500 | J28: =+F28+H28 -> 56969.416 | K28: 41500 | L28: =+WRM!L116 -> 38759.35 | M28: =+I28+K28 -> 116000 | N28: =+J28+L28 -> 95728.766 | O28: 43500 | P28: =+WRM!P116 -> 38136.15 | Q28: =+M28+O28 -> 159500 | R28: =+N28+P28 -> 133864.92 | S28: 43500 | T28: =+WRM!T116 -> 41256.25 | U28: =+Q28+S28 -> 203000 | V28: =+R28+T28 -> 175121.17 | W28: 42000 | X28: =+WRM!X116 -> 40057 | Y28: =+O28+S28+W28 -> 129000 | Z28: =+P28+T28+X28 -> 119449.4 | AA28: =+U28+W28 -> 245000 | AB28: =+V28+X28 -> 215178.17 | AC28: 43500 | AD28: 43248.85 | AE28: =+AA28+AC28 -> 288500 | AF28: =+AB28+AD28 -> 258427.02 | AG28: 42000 | AH28: 37008.65 | AI28: =+AE28+AG28 -> 330500 | AJ28: =+AF28+AH28 -> 295435.67 | AK28: 43500 | AL28: 40005.75 | AM28: =+AC28+AG28+AK28 -> 129000 | AN28: =+AD28+AH28+AL28 -> 120263.25 | AO28: =+AI28+AK28 -> 374000 | AP28: =+AJ28+AL28 -> 335441.42 | AQ28: 43500 | AR28: 40182.05 | AS28: =+AO28+AQ28 -> 417500 | AT28: =+AP28+AR28 -> 375623.47 | AU28: 39000 | AV28: 43710.1 | AW28: =+AS28+AU28 -> 456500 | AX28: =+AT28+AV28 -> 419333.57 | AY28: 43500 | AZ28: 46010.2 | BA28: =+AQ28+AU28+AY28 -> 126000 | BB28: =+AR28+AV28+AZ28 -> 129902.35 | BC28: =+AM28+BA28 -> 255000 | BD28: =+AN28+BB28 -> 250165.6 | BE28: =+AW28+AY28 -> 500000 | BF28: =+AX28+AZ28 -> 465343.77 | BG28: 435965.96 | BH28: 356518.66 | BI28: 500000 | BJ28: 412025.22 | BK28: 465.95759 | BM28: =+BK28*1000 -> 465957.59 | BN28: =+BM28-BF28 -> 613.824
B29: Bar Mill | C29: Mt | D29: 750000 | E29: 44000 | F29: =+BM!F53 -> 31471.35 | G29: 50000 | H29: =+BM!H53 -> 40050.68 | I29: =+E29+G29 -> 94000 | J29: =+F29+H29 -> 71522.03 | K29: 65000 | L29: =+BM!L53 -> 51899.88 | M29: =+I29+K29 -> 159000 | N29: =+J29+L29 -> 123421.91 | O29: 67000 | P29: =+BM!P53 -> 50651.53 | Q29: =+M29+O29 -> 226000 | R29: =+N29+P29 -> 174073.44 | S29: 67000 | T29: =+BM!T53 -> 49962.73 | U29: =+Q29+S29 -> 293000 | V29: =+R29+T29 -> 224036.17 | W29: 65000 | X29: =+BM!X53 -> 55089.31 | Y29: =+O29+S29+W29 -> 199000 | Z29: =+P29+T29+X29 -> 155703.57 | AA29: =+U29+W29 -> 358000 | AB29: =+V29+X29 -> 279125.48 | AC29: 67000 | AD29: 62348.195 | AE29: =+AA29+AC29 -> 425000 | AF29: =+AB29+AD29 -> 341473.67 | AG29: 65000 | AH29: 54525.3 | AI29: =+AE29+AG29 -> 490000 | AJ29: =+AF29+AH29 -> 395998.97 | AK29: 67000 | AL29: 68121.11 | AM29: =+AC29+AG29+AK29 -> 199000 | AN29: =+AD29+AH29+AL29 -> 184994.6 | AO29: =+AI29+AK29 -> 557000 | AP29: =+AJ29+AL29 -> 464120.08 | AQ29: 67000 | AR29: 70032.181 | AS29: =+AO29+AQ29 -> 624000 | AT29: =+AP29+AR29 -> 534152.27 | AU29: 59000 | AV29: 48122.458 | AW29: =+AS29+AU29 -> 683000 | AX29: =+AT29+AV29 -> 582274.72 | AY29: 67000 | AZ29: 67566.24 | BA29: =+AQ29+AU29+AY29 -> 193000 | BB29: =+AR29+AV29+AZ29 -> 185720.88 | BC29: =+AM29+BA29 -> 392000 | BD29: =+AN29+BB29 -> 370715.48 | BE29: =+AW29+AY29 -> 750000 | BF29: =+AX29+AZ29 -> 649840.96 | BG29: 674875.14 | BH29: 440547.27 | BI29: 800000 | BJ29: 632220.18 | BK29: 649.98881 | BM29: =+BK29*1000 -> 649988.81 | BN29: =+BM29-BF29 -> 147.85
B30: US Mill | C30: Mt | D30: 450000 | E30: 10000 | F30: =+USM!G43 -> 7869.3199 | G30: 0 | H30: =+USM!I43 -> 2728.5069 | I30: =+E30+G30 -> 10000 | J30: =+F30+H30 -> 10597.827 | K30: 40000 | L30: =+USM!M43 -> 9446.279 | M30: =+I30+K30 -> 50000 | N30: =+J30+L30 -> 20044.106 | O30: 40000 | P30: =+USM!Q43 -> 23283.083 | Q30: =+M30+O30 -> 90000 | R30: =+N30+P30 -> 43327.188 | S30: 45000 | T30: =+USM!U43 -> 18608.685 | U30: =+Q30+S30 -> 135000 | V30: =+R30+T30 -> 61935.873 | W30: 45000 | X30: =+USM!Y43 -> 7999.4363 | Y30: =+O30+S30+W30 -> 130000 | Z30: =+P30+T30+X30 -> 49891.204 | AA30: =+U30+W30 -> 180000 | AB30: =+V30+X30 -> 69935.31 | AC30: 45000 | AD30: 22485.667 | AE30: =+AA30+AC30 -> 225000 | AF30: =+AB30+AD30 -> 92420.977 | AG30: 45000 | AH30: 20909.542 | AI30: =+AE30+AG30 -> 270000 | AJ30: =+AF30+AH30 -> 113330.52 | AK30: 45000 | AL30: 29545.813 | AM30: =+AC30+AG30+AK30 -> 135000 | AN30: =+AD30+AH30+AL30 -> 72941.023 | AO30: =+AI30+AK30 -> 315000 | AP30: =+AJ30+AL30 -> 142876.33 | AQ30: 45000 | AR30: 20382.502 | AS30: =+AO30+AQ30 -> 360000 | AT30: =+AP30+AR30 -> 163258.83 | AU30: 45000 | AV30: 24125.901 | AW30: =+AS30+AU30 -> 405000 | AX30: =+AT30+AV30 -> 187384.74 | AY30: 45000 | AZ30: 25841.429 | BA30: =+AQ30+AU30+AY30 -> 135000 | BB30: =+AR30+AV30+AZ30 -> 70349.832 | BC30: =+AM30+BA30 -> 270000 | BD30: =+AN30+BB30 -> 143290.85 | BE30: =+AW30+AY30 -> 450000 | BF30: =+AX30+AZ30 -> 213226.16 | BG30: 220000 | BH30: 88943.894 | BI30: 535000 | BJ30: 171634.81 | BK30: 214.02766 | BM30: =+BK30*1000 -> 214027.66 | BN30: =+BM30-BF30 -> 801.4932
B31: Finished Steel | C31: Mt | D31: =SUM(D28:D30) -> 1700000 | E31: =SUM(E28:E30) -> 87000 | F31: =SUM(F28:F30) -> 71611.012 | G31: =SUM(G28:G30) -> 91500 | H31: =SUM(H28:H30) -> 67478.261 | I31: =SUM(I28:I30) -> 178500 | J31: =SUM(J28:J30) -> 139089.27 | K31: =SUM(K28:K30) -> 146500 | ... BB31: =SUM(BB28:BB30) -> 385973.06 | BC31: =+AM31+BA31 -> 917000 | BD31: =+AN31+BB31 -> 764171.94 | BE31: =SUM(BE28:BE30) -> 1700000 | BF31: =SUM(BF28:BF30) -> 1328410.9 | BG31: 1330841.1 | BH31: 886009.82 | BI31: =SUM(BI28:BI30) -> 1835000 | BJ31: =SUM(BJ28:BJ30) -> 1215880.2 | BN31: =SUM(BN28:BN30) -> 1563.1672
B32: 150x150 mm | C32: Mt | D32: 516407.45 | E32: 0 | F32: 12964.029 | G32: 0 | H32: 26813.326 | I32: =+E32+G32 -> 0 | J32: =+F32+H32 -> 39777.355 | K32: 51671 | L32: 59699.5 | M32: =+I32+K32 -> 51671 | N32: =+J32+L32 -> 99476.855 | O32: 52407.448 | P32: 58438.57 | Q32: =+M32+O32 -> 104078.45 | R32: =+N32+P32 -> 157915.42 | S32: 52407.448 | T32: 64215.629 | U32: =+Q32+S32 -> 156485.9 | V32: =+R32+T32 -> 222131.05 | W32: 51342.487 | X32: 60476.32 | Y32: =+O32+S32+W32 -> 156157.38 | Z32: =+P32+T32+X32 -> 183130.52 | AA32: =+U32+W32 -> 207828.38 | AB32: =+V32+X32 -> 282607.37 | AC32: 52407.448 | AD32: 59249.44 | AE32: =+AA32+AC32 -> 260235.83 | AF32: =+AB32+AD32 -> 341856.81 | AG32: 50342.487 | AH32: 58958.782 | AI32: =+AE32+AG32 -> 310578.32 | AJ32: =+AF32+AH32 -> 400815.6 | AK32: 52907.448 | AL32: 56991.49 | AM32: =+AC32+AG32+AK32 -> 155657.38 | AN32: =+AD32+AH32+AL32 -> 175199.71 | AO32: =+AI32+AK32 -> 363485.77 | AP32: =+AJ32+AL32 -> 457807.09 | AQ32: 53407.448 | AR32: 55521.43 | AS32: =+AO32+AQ32 -> 416893.22 | AT32: =+AP32+AR32 -> 513328.52 | AU32: 46106.104 | AV32: 58910.317 | AW32: =+AS32+AU32 -> 462999.32 | AX32: =+AT32+AV32 -> 572238.83 | AY32: 53407.448 | AZ32: 55445.74 | BA32: =+AQ32+AU32+AY32 -> 152921 | BB32: =+AR32+AV32+AZ32 -> 169877.49 | BC32: =+AM32+BA32 -> 308578.38 | BD32: =+AN32+BB32 -> 345077.2 | BE32: =+AW32+AY32 -> 516406.77 | BF32: =+AX32+AZ32 -> 627684.57 | BG32: 533055.82 | BH32: 608495.73 | BI32: 304999.74 | BJ32: 629438.96 | BM32: 629120.82
B33: 200x280 mm | C33: Mt | D33: 153592.7 | E33: 0 | F33: =+SMS!F41+SMS!F43 -> 5563.18 | G33: 0 | H33: =+SMS!H41+SMS!H43 -> 9537.6667 | I33: =+E33+G33 -> 0 | J33: =+F33+H33 -> 15100.847 | K33: 18121 | L33: =+SMS!L41+SMS!L43 -> 25254.5 | M33: =+I33+K33 -> 18121 | N33: =+J33+L33 -> 40355.347 | O33: 19484.642 | P33: =+SMS!P41+SMS!P43 -> 12425.84 | Q33: =+M33+O33 -> 37605.642 | R33: =+N33+P33 -> 52781.187 | S33: 14947.775 | T33: =+SMS!T41+SMS!T43 -> 24124.885 | U33: =+Q33+S33 -> 52553.416 | V33: =+R33+T33 -> 76906.072 | W33: 14330.873 | X33: =+SMS!X41+SMS!X43 -> 26955.68 | Y33: =+O33+S33+W33 -> 48763.29 | Z33: =+P33+T33+X33 -> 63506.405 | AA33: =+U33+W33 -> 66884.29 | AB33: =+V33+X33 -> 103861.75 | AC33: 16236.507 | AD33: =+SMS!AD41+SMS!AD43 -> 7598.86 | AE33: =+AA33+AC33 -> 83120.797 | AF33: =+AB33+AD33 -> 111460.61 | AG33: 13330.873 | AH33: =+SMS!AH41+SMS!AH43 -> 21760.9 | AI33: =+AE33+AG33 -> 96451.67 | AJ33: =+AF33+AH33 -> 133221.51 | AK33: 16062.507 | AL33: =+SMS!AL41+SMS!AL43 -> 15709.11 | AM33: =+AC33+AG33+AK33 -> 45629.888 | AN33: =+AD33+AH33+AL33 -> 45068.87 | AO33: =+AI33+AK33 -> 112514.18 | AP33: =+AJ33+AL33 -> 148930.62 | AQ33: 15736.507 | AR33: =+SMS!AR41+SMS!AR43 -> 24394.61 | AS33: =+AO33+AQ33 -> 128250.68 | AT33: =+AP33+AR33 -> 173325.23 | AU33: 9605.1503 | AV33: =+SMS!AV41+SMS!AV43-1782 -> 15419.12 | AW33: =+AS33+AU33 -> 137855.83 | AX33: =+AT33+AV33 -> 188744.35 | AY33: 15736.507 | AZ33: =+SMS!AZ41+SMS!AZ43-1809 -> 15586 | BA33: =+AQ33+AU33+AY33 -> 41078.165 | BB33: =+AR33+AV33+AZ33 -> 55399.73 | BC33: =+AM33+BA33 -> 86708.052 | BD33: =+AN33+BB33 -> 100468.6 | BE33: =+AW33+AY33 -> 153592.34 | BF33: =+AX33+AZ33 -> 204330.35 | BG33: 371378.01 | BH33: 329378.8 | BI33: 267000 | BJ33: 248401 | BM33: 202894.11
B34: Saleable Semis | C34: Mt | D34: =SUM(D32:D33) -> 670000.15 | E34: =SUM(E32:E33) -> 0 | F34: =SUM(F32:F33) -> 18527.209 | G34: =SUM(G32:G33) -> 0 | H34: =SUM(H32:H33) -> 36350.993 | I34: =SUM(I32:I33) -> 0 | J34: =SUM(J32:J33) -> 54878.202 | K34: =SUM(K32:K33) -> 69792 | ... BB34: =SUM(BB32:BB33) -> 225277.22 | BC34: =+AM34+BA34 -> 395286.44 | BD34: =+AN34+BB34 -> 445545.8 | BE34: =SUM(BE32:BE33) -> 669999.11 | BF34: =SUM(BF32:BF33) -> 832014.92 | BG34: 904433.83 | BH34: 937874.53 | BI34: =SUM(BI32:BI33) -> 571999.74 | BJ34: =SUM(BJ32:BJ33) -> 877839.96 | BM34: =SUM(BM28:BM33) -> 2161989 | BN34: =+BM34-BF34 -> 1329974.1
B35: TOTAL | C35: Mt | D35: =+D31+D34 -> 2370000.2 | E35: =+E31+E34 -> 87000 | F35: =+F31+F34 -> 90138.22 | G35: =+G31+G34 -> 91500 | H35: =+H31+H34 -> 103829.25 | I35: =+I31+I34 -> 178500 | J35: =+J31+J34 -> 193967.47 | K35: =+K31+K34 -> 216292 | ... BB35: =+BB31+BB34 -> 611250.28 | BC35: =+AM35+BA35 -> 1312286.4 | BD35: =+AN35+BB35 -> 1209717.7 | BE35: =+BE31+BE34 -> 2369999.1 | BF35: =+BF31+BF34 -> 2160425.8 | BG35: 2235274.9 | BH35: 1823884.4 | BI35: =+BI31+BI34 -> 2406999.7 | BJ35: =+BJ31+BJ34 -> 2093720.2 | BK35: =+BF35/1000000 -> 2.1604258
B36: SAL STEEL PRODN (CATEGORY WISE)
B37: Wire Rod Plain Coils | C37: Mt | D37: =+D28 -> 500000 | E37: =+E28 -> 33000 | F37: 32270.342 | G37: =+G28 -> 41500 | H37: 21668.994 | I37: =+E37+G37 -> 74500 | J37: =+F37+H37 -> 53939.336 | K37: =+K28 -> 41500 | L37: 38759.35 | M37: =+I37+K37 -> 116000 | N37: =+J37+L37 -> 92698.686 | O37: =+O28 -> 43500 | P37: 38136.15 | Q37: =+M37+O37 -> 159500 | R37: =+N37+P37 -> 130834.84 | S37: =+S28 -> 43500 | T37: 41256.25 | U37: =+Q37+S37 -> 203000 | V37: =+R37+T37 -> 172091.09 | W37: =+W28 -> 42000 | X37: 40057 | Y37: =+O37+S37+W37 -> 129000 | Z37: =+P37+T37+X37 -> 119449.4 | AA37: =+U37+W37 -> 245000 | AB37: =+V37+X37 -> 212148.09 | AC37: =+AC28 -> 43500 | AD37: 43248.85 | AE37: =+AA37+AC37 -> 288500 | AF37: =+AB37+AD37 -> 255396.94 | AG37: =+AG28 -> 42000 | AH37: 37008.65 | AI37: =+AE37+AG37 -> 330500 | AJ37: =+AF37+AH37 -> 292405.59 | AK37: =+AK28 -> 43500 | AL37: 34066.9 | AM37: =+AC37+AG37+AK37 -> 129000 | AN37: =+AD37+AH37+AL37 -> 114324.4 | AO37: =+AI37+AK37 -> 374000 | AP37: =+AJ37+AL37 -> 326472.49 | AQ37: =+AQ28 -> 43500 | AR37: 40182.05 | AS37: =+AO37+AQ37 -> 417500 | AT37: =+AP37+AR37 -> 366654.54 | AU37: =+AU28 -> 39000 | AV37: =+AV28 -> 43710.1 | AW37: =+AS37+AU37 -> 456500 | AX37: =+AT37+AV37 -> 410364.64 | AY37: =+AY28 -> 43500 | AZ37: =+AZ28 -> 46010.2 | BA37: =+AQ37+AU37+AY37 -> 126000 | BB37: =+AR37+AV37+AZ37 -> 129902.35 | BC37: =+AM37+BA37 -> 255000 | BD37: =+AN37+BB37 -> 244226.75 | BE37: =+AW37+AY37 -> 500000 | BF37: =+AX37+AZ37 -> 456374.84 | BG37: 435965.96 | BH37: 337036.56 | BI37: =+BI28 -> 500000 | BJ37: 270654.57 | BM37: =+BM34-BF35 -> 1563.1741
B38: TMT Coils | C38: Mt | F38: 0 | H38: 3030.08 | J38: =+F38+H38 -> 3030.08 | L38: 0 | N38: =+J38+L38 -> 3030.08 | P38: 0 | R38: =+N38+P38 -> 3030.08 | T38: 0 | V38: =+R38+T38 -> 3030.08 | X38: 0 | Z38: =+P38+T38+X38 -> 0 | AB38: =+V38+X38 -> 3030.08 | AD38: 0 | AF38: =+AB38+AD38 -> 3030.08 | AH38: 0 | AJ38: =+AF38+AH38 -> 3030.08 | AL38: 5938.85 | AN38: =+AD38+AH38+AL38 -> 5938.85 | AP38: =+AJ38+AL38 -> 8968.93 | AR38: 0 | AT38: =+AP38+AR38 -> 8968.93 | AV38: 0 | AX38: =+AT38+AV38 -> 8968.93 | AZ38: 0 | BB38: =+AR38+AV38+AZ38 -> 0 | BC38: =+AM38+BA38 -> 0 | BD38: =+AN38+BB38 -> 5938.85 | BF38: =+AX38+AZ38 -> 8968.93 | BH38: 19481.814 | BJ38: 141370.65
B39: TMT Bars | C39: Mt | D39: =+D29 -> 750000 | E39: =+E29 -> 44000 | F39: =+F29 -> 31471.35 | G39: =+G29 -> 50000 | H39: =+H29 -> 40050.68 | I39: =+E39+G39 -> 94000 | J39: =+F39+H39 -> 71522.03 | K39: =+K29 -> 65000 | L39: =+L29 -> 51899.88 | M39: =+I39+K39 -> 159000 | N39: =+J39+L39 -> 123421.91 | O39: =+O29 -> 67000 | P39: =+P29 -> 50651.53 | Q39: =+M39+O39 -> 226000 | R39: =+N39+P39 -> 174073.44 | S39: =+S29 -> 67000 | T39: =+T29 -> 49962.73 | U39: =+Q39+S39 -> 293000 | V39: =+R39+T39 -> 224036.17 | W39: =+W29 -> 65000 | X39: =+X29 -> 55089.31 | Y39: =+O39+S39+W39 -> 199000 | Z39: =+P39+T39+X39 -> 155703.57 | AA39: =+U39+W39 -> 358000 | AB39: =+V39+X39 -> 279125.48 | AC39: =+AC29 -> 67000 | AD39: =AD29 -> 62348.195 | AE39: =+AA39+AC39 -> 425000 | AF39: =+AB39+AD39 -> 341473.67 | AG39: =+AG29 -> 65000 | AH39: =AH29 -> 54525.3 | AI39: =+AE39+AG39 -> 490000 | AJ39: =+AF39+AH39 -> 395998.97 | AK39: =+AK29 -> 67000 | AL39: =AL29 -> 68121.11 | AM39: =+AC39+AG39+AK39 -> 199000 | AN39: =+AD39+AH39+AL39 -> 184994.6 | AO39: =+AI39+AK39 -> 557000 | AP39: =+AJ39+AL39 -> 464120.08 | AQ39: =+AQ29 -> 67000 | AR39: =+AR29 -> 70032.181 | AS39: =+AO39+AQ39 -> 624000 | AT39: =+AP39+AR39 -> 534152.27 | AU39: =+AU29 -> 59000 | AV39: =+AV29 -> 48122.458 | AW39: =+AS39+AU39 -> 683000 | AX39: =+AT39+AV39 -> 582274.72 | AY39: =+AY29 -> 67000 | AZ39: =+AZ29 -> 67566.24 | BA39: =+AQ39+AU39+AY39 -> 193000 | BB39: =+AR39+AV39+AZ39 -> 185720.88 | BC39: =+AM39+BA39 -> 392000 | BD39: =+AN39+BB39 -> 370715.48 | BE39: =+AW39+AY39 -> 750000 | BF39: =+AX39+AZ39 -> 649840.96 | BG39: 674875.14 | BH39: 440547.14 | BI39: =+BI29 -> 800000 | BJ39: 632220.18
B40: Parallel Flange Beams | C40: Mt | D40: =+D30 -> 450000 | E40: =+E30 -> 10000 | F40: =6276.41-98.6 -> 6177.81 | G40: =+G30 -> 0 | H40: =1415.21-24.18 -> 1391.03 | I40: =+E40+G40 -> 10000 | J40: =+F40+H40 -> 7568.84 | K40: =+K30 -> 40000 | L40: =7983.23416703449-7.1-135.16 -> 7840.9742 | M40: =+I40+K40 -> 50000 | N40: =+J40+L40 -> 15409.814 | O40: =+O30 -> 40000 | P40: =19195.0787899673-313.98 -> 18881.099 | Q40: =+M40+O40 -> 90000 | R40: =+N40+P40 -> 34290.913 | S40: =+S30 -> 45000 | T40: =15219.8668473+4.8 -> 15224.667 | U40: =+Q40+S40 -> 135000 | V40: =+R40+T40 -> 49515.58 | W40: =+W30 -> 45000 | X40: =7068.013821-19 -> 7049.0138 | Y40: =+O40+S40+W40 -> 130000 | Z40: =+P40+T40+X40 -> 41154.779 | AA40: =+U40+W40 -> 180000 | AB40: =+V40+X40 -> 56564.594 | AC40: =+AC30 -> 45000 | AD40: 17875.446 | AE40: =+AA40+AC40 -> 225000 | AF40: =+AB40+AD40 -> 74440.039 | AG40: =+AG30 -> 45000 | AH40: 12302.024 | AI40: =+AE40+AG40 -> 270000 | AJ40: =+AF40+AH40 -> 86742.064 | AK40: =+AK30 -> 45000 | AL40: 22613.71 | AM40: =+AC40+AG40+AK40 -> 135000 | AN40: =+AD40+AH40+AL40 -> 52791.18 | AO40: =+AI40+AK40 -> 315000 | AP40: =+AJ40+AL40 -> 109355.77 | AQ40: =+AQ30 -> 45000 | AR40: 15435.383 | AS40: =+AO40+AQ40 -> 360000 | AT40: =+AP40+AR40 -> 124791.16 | AU40: =+AU30 -> 45000 | AV40: 20418.945 | AW40: =+AS40+AU40 -> 405000 | AX40: =+AT40+AV40 -> 145210.1 | AY40: =+AY30 -> 45000 | AZ40: 22909.409 | BA40: =+AQ40+AU40+AY40 -> 135000 | BB40: =+AR40+AV40+AZ40 -> 58763.737 | BC40: =+AM40+BA40 -> 270000 | BD40: =+AN40+BB40 -> 111554.92 | BE40: =+AW40+AY40 -> 450000 | BF40: =+AX40+AZ40 -> 168119.51 | BG40: 220000 | BH40: 73866.149 | BI40: =+BI30 -> 535000 | BJ40: 171635 | BL40: =+BF35-BH35 -> 336541.46
...

Sheet Maj Despatch Summ
B1: MAJOR DESPATCH SUMMARY 2021-22(As per Finance CENVAT report)
E2: 30 | F2: 30 | G2: 31 | H2: 31 | I2: =+G2+E2 -> 61 | J2: =+H2+F2 -> 61 | K2: 30 | L2: 30 | M2: =+E2+G2+K2 -> 91 | N2: =+F2+H2+L2 -> 91 | O2: 31 | P2: 31 | Q2: =+M2+O2 -> 122 | R2: =+N2+P2 -> 122 | S2: 31 | T2: 31 | U2: =+Q2+S2 -> 153 | V2: =+R2+T2 -> 153 | W2: 30 | X2: 30 | Y2: =+O2+S2+W2 -> 92 | Z2: =+P2+T2+X2 -> 92 | AA2: =+M2+Y2 -> 183 | AB2: =+N2+Z2 -> 183 | AC2: 31 | AD2: 31 | AE2: =+AA2+AC2 -> 214 | AF2: =+AB2+AD2 -> 214 | AG2: 30 | AH2: 30 | AI2: =+AE2+AG2 -> 244 | AJ2: =+AF2+AH2 -> 244 | AK2: 31 | AL2: 31 | AM2: =+AC2+AG2+AK2 -> 92 | AN2: =+AD2+AH2+AL2 -> 92 | AO2: =+AI2+AK2 -> 275 | AP2: =+AJ2+AL2 -> 275 | AQ2: 31 | AR2: 31 | AS2: =+AO2+AQ2 -> 306 | AT2: =+AP2+AR2 -> 306 | AU2: 28 | AV2: 28 | AW2: =+AS2+AU2 -> 334 | AX2: =+AT2+AV2 -> 334 | AY2: 31 | AZ2: 31 | BA2: =+AQ2+AU2+AY2 -> 90 | BB2: =+AR2+AV2+AZ2 -> 90 | BC2: =+AM2+BA2 -> 182 | BD2: =+AN2+BB2 -> 182 | BE2: =+AW2+AY2 -> 365 | BF2: =+AX2+AZ2 -> 365 | BG2: 365 | BH2: 365 | BI2: 366 | BJ2: 366
B3: ITEM | C3: Unit | D3: 2021-22 ABP | E3: Apr'21 | G3: May'21 | I3: 2M | K3: Jun'21 | M3: QTR-1 | O3: Jul'21 | Q3: 4M | S3: Aug'21 | U3: 5M | W3: Sep'21 | Y3: QTR-2 | AA3: H1 | AC3: Oct'21 | AE3: 7M | AG3: Nov'21 | AI3: 8M | AK3: Dec'21 | AM3: QTR-3 | AO3: 9M | AQ3: Jan'22 | AS3: 10M | AU3: Feb'22 | AW3: 11M | AY3: Mar'22 | BA3: QTR-4 | BC3: H2 | BE3: 2021-22 | BG3: 2020-21 | BI3: 2019-20
E4: ABP | F4: ACT | G4: ABP | H4: ACT | I4: ABP | J4: ACT | K4: ABP | L4: ACT | M4: ABP | N4: ACT | O4: ABP | P4: ACT | Q4: ABP | R4: ACT | S4: ABP | T4: ACT | U4: ABP | V4: ACT | W4: ABP | X4: ACT | Y4: ABP | Z4: ACT | AA4: ABP | AB4: ACT | AC4: ABP | AD4: ACT | AE4: ABP | AF4: ACT | AG4: ABP | AH4: ACT | AI4: ABP | AJ4: ACT | AK4: ABP | AL4: ACT | AM4: ABP | AN4: ACT | AO4: ABP | AP4: ACT | AQ4: ABP | AR4: ACT | AS4: ABP | AT4: ACT | AU4: ABP | AV4: ACT | AW4: ABP | AX4: ACT | AY4: ABP | AZ4: ACT | BA4: ABP | BB4: ACT | BC4: ABP | BD4: ACT | BE4: ABP | BF4: ACT | BG4: ABP | BH4: ACT | BI4: ABP | BJ4: ACT
B5: Saleable Steel (mill-wise)
B6: MKTG-MILL DEFECTIVES (ARISINGS) | C6: MT | D6: 15050 | E6: 0 | F6: 2956.91 | G6: 500 | H6: 4274.74 | I6: =+E6+G6 -> 500 | J6: =+F6+H6 -> 7231.65 | K6: 1500 | L6: 1722.87 | M6: =+I6+K6 -> 2000 | N6: =+J6+L6 -> 8954.52 | O6: 1500 | P6: 2943.97 | Q6: =+M6+O6 -> 3500 | R6: =+N6+P6 -> 11898.49 | S6: 2000 | T6: 3275.94 | U6: =+Q6+S6 -> 5500 | V6: =+R6+T6 -> 15174.43 | W6: 1500 | X6: 1628.47 | Y6: =+O6+S6+W6 -> 5000 | Z6: =+P6+T6+X6 -> 7848.38 | AA6: =+M6+Y6 -> 7000 | AB6: =+N6+Z6 -> 16802.9 | AC6: 1500 | AD6: 3324.25 | AE6: =+AA6+AC6 -> 8500 | AF6: =+AB6+AD6 -> 20127.15 | AG6: 1500 | AH6: 2214.32 | AI6: =+AE6+AG6 -> 10000 | AJ6: =+AF6+AH6 -> 22341.47 | AK6: 1500 | AL6: 2437.96 | AM6: =+AC6+AG6+AK6 -> 4500 | AN6: =+AD6+AH6+AL6 -> 7976.53 | AO6: =+AI6+AK6 -> 11500 | AP6: =+AJ6+AL6 -> 24779.43 | AQ6: 1500 | AR6: 17.6 | AS6: =+AO6+AQ6 -> 13000 | AT6: =+AP6+AR6 -> 24797.03 | AU6: 1500 | AV6: 2076.14 | AW6: =+AS6+AU6 -> 14500 | AX6: =+AT6+AV6 -> 26873.17 | AY6: 1550 | AZ6: 6327.98 | BA6: =+AQ6+AU6+AY6 -> 4550 | BB6: =+AR6+AV6+AZ6 -> 8421.72 | BC6: =+AM6+BA6 -> 9050 | BD6: =+AN6+BB6 -> 16398.25 | BE6: =+AW6+AY6 -> 16050 | BF6: =+AX6+AZ6 -> 33201.15 | BG6: 0 | BH6: 35268.25 | BI6: 2000 | BJ6: 28405.85
B7: IPT | C7: MT | D7: 0 | E7: 0 | F7: 0 | G7: 0 | H7: 5712.02 | I7: =+E7+G7 -> 0 | J7: =+F7+H7 -> 5712.02 | K7: 0 | L7: 0 | M7: =+I7+K7 -> 0 | N7: =+J7+L7 -> 5712.02 | O7: 0 | P7: 2863.68 | Q7: =+M7+O7 -> 0 | R7: =+N7+P7 -> 8575.7 | S7: 0 | T7: 8333.58 | U7: =+Q7+S7 -> 0 | V7: =+R7+T7 -> 16909.28 | W7: 0 | X7: 5479.16 | Y7: =+O7+S7+W7 -> 0 | Z7: =+P7+T7+X7 -> 16676.42 | AA7: =+M7+Y7 -> 0 | AB7: =+N7+Z7 -> 22388.44 | AC7: 0 | AD7: 11475.78 | AE7: =+AA7+AC7 -> 0 | AF7: =+AB7+AD7 -> 33864.22 | AG7: 0 | AH7: 2870.48 | AI7: =+AE7+AG7 -> 0 | AJ7: =+AF7+AH7 -> 36734.7 | AK7: 0 | AL7: 10720.04 | AM7: =+AC7+AG7+AK7 -> 0 | AN7: =+AD7+AH7+AL7 -> 25066.3 | AO7: =+AI7+AK7 -> 0 | AP7: =+AJ7+AL7 -> 47454.74 | AQ7: 0 | AR7: 5342.76 | AS7: =+AO7+AQ7 -> 0 | AT7: =+AP7+AR7 -> 52797.5 | AU7: 0 | AV7: 8560.92 | AW7: =+AS7+AU7 -> 0 | AX7: =+AT7+AV7 -> 61358.42 | AY7: 0 | AZ7: 10349 | BA7: =+AQ7+AU7+AY7 -> 0 | BB7: =+AR7+AV7+AZ7 -> 24252.68 | BC7: =+AM7+BA7 -> 0 | BD7: =+AN7+BB7 -> 49318.98 | BE7: =+AW7+AY7 -> 0 | BF7: =+AX7+AZ7 -> 71707.42 | BG7: 10800 | BH7: 9758.51 | BI7: 24210 | BJ7: 5928.095
B8: CMO-WR MILL | C8: MT | D8: 498500 | E8: 33000 | F8: 32479.46 | G8: 41000 | H8: 29307.43 | I8: =+E8+G8 -> 74000 | J8: =+F8+H8 -> 61786.89 | K8: 41500 | L8: =36293.25-127.26 -> 36165.99 | M8: =+I8+K8 -> 115500 | N8: =+J8+L8 -> 97952.88 | O8: 43500 | P8: =39274.56+127.26 -> 39401.82 | Q8: =+M8+O8 -> 159000 | R8: =+N8+P8 -> 137354.7 | S8: 43000 | T8: 41652.3 | U8: =+Q8+S8 -> 202000 | V8: =+R8+T8 -> 179007 | W8: 42000 | X8: 40286.89 | Y8: =+O8+S8+W8 -> 128500 | Z8: =+P8+T8+X8 -> 121341.01 | AA8: =+M8+Y8 -> 244000 | AB8: =+N8+Z8 -> 219293.89 | AC8: 43500 | AD8: 41035.01 | AE8: =+AA8+AC8 -> 287500 | AF8: =+AB8+AD8 -> 260328.9 | AG8: 42000 | AH8: 36699.67 | AI8: =+AE8+AG8 -> 329500 | AJ8: =+AF8+AH8 -> 297028.57 | AK8: 43000 | AL8: 37448.32 | AM8: =+AC8+AG8+AK8 -> 128500 | AN8: =+AD8+AH8+AL8 -> 115183 | AO8: =+AI8+AK8 -> 372500 | AP8: =+AJ8+AL8 -> 334476.89 | AQ8: 43500 | AR8: 41962.08 | AS8: =+AO8+AQ8 -> 416000 | AT8: =+AP8+AR8 -> 376438.97 | AU8: 39000 | AV8: 44216.67 | AW8: =+AS8+AU8 -> 455000 | AX8: =+AT8+AV8 -> 420655.64 | AY8: 43500 | AZ8: 47298 | BA8: =+AQ8+AU8+AY8 -> 126000 | BB8: =+AR8+AV8+AZ8 -> 133476.75 | BC8: =+AM8+BA8 -> 254500 | BD8: =+AN8+BB8 -> 248659.75 | BE8: =+AW8+AY8 -> 498500 | BF8: =+AX8+AZ8 -> 467953.64 | BG8: 435166.29 | BH8: 351267.02 | BI8: 498000 | BJ8: 399090.26 | BL8: =+BL10/BH12 -> 0.16009368
B9: CMO-BAR MILL | C9: MT | D9: 750000 | E9: 44000 | F9: 35076.64 | G9: 50000 | H9: 34586.76 | I9: =+E9+G9 -> 94000 | J9: =+F9+H9 -> 69663.4 | K9: 65000 | L9: 51668.42 | M9: =+I9+K9 -> 159000 | N9: =+J9+L9 -> 121331.82 | O9: 67000 | P9: 53901.93 | Q9: =+M9+O9 -> 226000 | R9: =+N9+P9 -> 175233.75 | S9: 67000 | T9: 50809.85 | U9: =+Q9+S9 -> 293000 | V9: =+R9+T9 -> 226043.6 | W9: 65000 | X9: 54227.87 | Y9: =+O9+S9+W9 -> 199000 | Z9: =+P9+T9+X9 -> 158939.65 | AA9: =+M9+Y9 -> 358000 | AB9: =+N9+Z9 -> 280271.47 | AC9: 67000 | AD9: 58924.31 | AE9: =+AA9+AC9 -> 425000 | AF9: =+AB9+AD9 -> 339195.78 | AG9: 65000 | AH9: 49365.07 | AI9: =+AE9+AG9 -> 490000 | AJ9: =+AF9+AH9 -> 388560.85 | AK9: 67000 | AL9: 75504.19 | AM9: =+AC9+AG9+AK9 -> 199000 | AN9: =+AD9+AH9+AL9 -> 183793.57 | AO9: =+AI9+AK9 -> 557000 | AP9: =+AJ9+AL9 -> 464065.04 | AQ9: 67000 | AR9: 66658.32 | AS9: =+AO9+AQ9 -> 624000 | AT9: =+AP9+AR9 -> 530723.36 | AU9: 59000 | AV9: 46901.53 | AW9: =+AS9+AU9 -> 683000 | AX9: =+AT9+AV9 -> 577624.89 | AY9: 67000 | AZ9: 71137 | BA9: =+AQ9+AU9+AY9 -> 193000 | BB9: =+AR9+AV9+AZ9 -> 184696.85 | BC9: =+AM9+BA9 -> 392000 | BD9: =+AN9+BB9 -> 368490.42 | BE9: =+AW9+AY9 -> 750000 | BF9: =+AX9+AZ9 -> 648761.89 | BG9: 674874.74 | BH9: 436958.46 | BI9: 800000 | BJ9: 612890.55
B10: CMO-US MILL | C10: MT | D10: 445000 | E10: 10000 | F10: 9066.34 | G10: 0 | H10: 2525.46 | I10: =+E10+G10 -> 10000 | J10: =+F10+H10 -> 11591.8 | K10: 39500 | L10: 7751.21 | M10: =+I10+K10 -> 49500 | N10: =+J10+L10 -> 19343.01 | O10: 39500 | P10: 22732.9 | Q10: =+M10+O10 -> 89000 | R10: =+N10+P10 -> 42075.91 | S10: 44500 | T10: 19016.82 | U10: =+Q10+S10 -> 133500 | V10: =+R10+T10 -> 61092.73 | W10: 44500 | X10: 9271.7 | Y10: =+O10+S10+W10 -> 128500 | Z10: =+P10+T10+X10 -> 51021.42 | AA10: =+M10+Y10 -> 178000 | AB10: =+N10+Z10 -> 70364.43 | AC10: 44500 | AD10: 21321.12 | AE10: =+AA10+AC10 -> 222500 | AF10: =+AB10+AD10 -> 91685.55 | AG10: 44500 | AH10: 21142.22 | AI10: =+AE10+AG10 -> 267000 | AJ10: =+AF10+AH10 -> 112827.77 | AK10: 44500 | AL10: 28432.32 | AM10: =+AC10+AG10+AK10 -> 133500 | AN10: =+AD10+AH10+AL10 -> 70895.66 | AO10: =+AI10+AK10 -> 311500 | AP10: =+AJ10+AL10 -> 141260.09 | AQ10: 44500 | AR10: 20928.53 | AS10: =+AO10+AQ10 -> 356000 | AT10: =+AP10+AR10 -> 162188.62 | AU10: 44500 | AV10: 23604.03 | AW10: =+AS10+AU10 -> 400500 | AX10: =+AT10+AV10 -> 185792.65 | AY10: 44500 | AZ10: 28527 | BA10: =+AQ10+AU10+AY10 -> 133500 | BB10: =+AR10+AV10+AZ10 -> 73059.56 | BC10: =+AM10+BA10 -> 267000 | BD10: =+AN10+BB10 -> 143955.22 | BE10: =+AW10+AY10 -> 445000 | BF10: =+AX10+AZ10 -> 214319.65 | BG10: 220000 | BH10: 100400.4 | BI10: 535000 | BJ10: 167166.99 | BL10: =+BF12-BH12 -> 300600.67
B11: CMO-SEMIS | C11: MT | D11: 659950.15 | E11: -0.0001014047 | F11: 26014.07 | G11: 0.46042229 | H11: 28054.78 | I11: =+E11+G11 -> 0.46032089 | J11: =+F11+H11 -> 54068.85 | K11: 68792.582 | L11: 76797.38 | M11: =+I11+K11 -> 68793.042 | N11: =+J11+L11 -> 130866.23 | O11: 70892.09 | P11: 66760.81 | Q11: =+M11+O11 -> 139685.13 | R11: =+N11+P11 -> 197627.04 | S11: 66355.223 | T11: 71305.95 | U11: =+Q11+S11 -> 206040.35 | V11: =+R11+T11 -> 268932.99 | W11: 64673.36 | X11: 88791.79 | Y11: =+O11+S11+W11 -> 201920.67 | Z11: =+P11+T11+X11 -> 226858.55 | AA11: =+M11+Y11 -> 270713.72 | AB11: =+N11+Z11 -> 357724.78 | AC11: 67643.955 | AD11: 48239.77 | AE11: =+AA11+AC11 -> 338357.67 | AF11: =+AB11+AD11 -> 405964.55 | AG11: 62673.36 | AH11: 73495.39 | AI11: =+AE11+AG11 -> 401031.03 | AJ11: =+AF11+AH11 -> 479459.94 | AK11: 67969.955 | AL11: 68439.61 | AM11: =+AC11+AG11+AK11 -> 198287.27 | AN11: =+AD11+AH11+AL11 -> 190174.77 | AO11: =+AI11+AK11 -> 469000.99 | AP11: =+AJ11+AL11 -> 547899.55 | AQ11: 68143.955 | AR11: 70955.83 | AS11: =+AO11+AQ11 -> 537144.94 | AT11: =+AP11+AR11 -> 618855.38 | AU11: 54711.254 | AV11: 61093.39 | AW11: =+AS11+AU11 -> 591856.2 | AX11: =+AT11+AV11 -> 679948.77 | AY11: 68093.955 | AZ11: 62363 | BA11: =+AQ11+AU11+AY11 -> 190949.16 | BB11: =+AR11+AV11+AZ11 -> 194412.22 | BC11: =+AM11+BA11 -> 389236.44 | BD11: =+AN11+BB11 -> 384586.99 | BE11: =+AW11+AY11 -> 659950.15 | BF11: =+AX11+AZ11 -> 742311.77 | BG11: 893633.78 | BH11: 944002.21 | BI11: 547789.74 | BJ11: 836451 | BL11: =+BF12-'Maj Production Summ'!BF35 -> 17829.701
B12: TOTAL | C12: MT | D12: =SUM(D6:D11) -> 2368500.2 | E12: =SUM(E6:E11) -> 87000 | F12: =SUM(F6:F11) -> 105593.42 | G12: =SUM(G6:G11) -> 91500.46 | H12: =SUM(H6:H11) -> 104461.19 | I12: =SUM(I6:I11) -> 178500.46 | J12: =SUM(J6:J11) -> 210054.61 | K12: =SUM(K6:K11) -> 216292.58 | ... BF12: =SUM(BF6:BF11) -> 2178255.5 | BG12: 2234474.8 | BH12: 1877654.8 | BI12: 2406999.7 | BJ12: 2049932.7
B13: Consideration in internal consumption | D13: Saleable production Plan: 2370000 (1500 T has been kept in plan for Internal consumption) | G13: Saleable production Plan: 91500 (500 T has been kept in plan for Internal consumption) | S13: Saleable production Plan: 222855 (500 T has been kept in plan for Internal consumption) | AK13: Saleable production Plan: 224470 (500 T has been kept in plan for Internal consumption) | AX13: =+AX12-AX6-AX7 -> 1864022 | AZ13: =+AZ12-AZ17 -> 179557.98
B14: Saleable Steel (Sale type-wise)
B15: IPT | C15: MT | D15: =+D12 -> 2368500.2 | E15: =+E12 -> 87000 | F15: 0 | G15: =+G12 -> 91500.46 | H15: =+H7 -> 5712.02 | I15: =+E15+G15 -> 178500.46 | J15: =+F15+H15 -> 5712.02 | K15: =+K12 -> 216292.58 | L15: 0 | M15: =+I15+K15 -> 394793.04 | N15: =+J15+L15 -> 5712.02 | O15: =+O12 -> 222392.09 | P15: 2863.68 | Q15: =+M15+O15 -> 617185.13 | R15: =+N15+P15 -> 8575.7 | S15: =+S12 -> 222855.22 | T15: =+T7 -> 8333.58 | U15: =+Q15+S15 -> 840040.35 | V15: =+R15+T15 -> 16909.28 | W15: =+W12 -> 217673.36 | X15: =+X7 -> 5479.16 | Y15: =+O15+S15+W15 -> 662920.67 | Z15: =+P15+T15+X15 -> 16676.42 | AA15: =+M15+Y15 -> 1057713.7 | AB15: =+N15+Z15 -> 22388.44 | AC15: =+AC12 -> 224143.96 | AD15: =+AD7 -> 11475.78 | AE15: =+AA15+AC15 -> 1281857.7 | AF15: =+AB15+AD15 -> 33864.22 | AG15: =+AG12 -> 215673.36 | AH15: =+AH7 -> 2870.48 | AI15: =+AE15+AG15 -> 1497531 | AJ15: =+AF15+AH15 -> 36734.7 | AK15: =+AK12 -> 223969.96 | AL15: =+AL7 -> 10720.04 | AM15: =+AC15+AG15+AK15 -> 663787.27 | AN15: =+AD15+AH15+AL15 -> 25066.3 | AO15: =+AI15+AK15 -> 1721501 | AP15: =+AJ15+AL15 -> 47454.74 | AQ15: =+AQ12 -> 224643.96 | AR15: =+AR7 -> 5342.76 | AS15: =+AO15+AQ15 -> 1946144.9 | AT15: =+AP15+AR15 -> 52797.5 | AU15: =+AU12 -> 198711.25 | AV15: =+AV7 -> 8560.92 | AW15: =+AS15+AU15 -> 2144856.2 | AX15: =+AT15+AV15 -> 61358.42 | AY15: =+AY12 -> 224643.96 | AZ15: =+AZ7 -> 10349 | BA15: =+AQ15+AU15+AY15 -> 647999.16 | BB15: =+AR15+AV15+AZ15 -> 24252.68 | BC15: =+AM15+BA15 -> 1311786.4 | BD15: =+AN15+BB15 -> 49318.98 | BE15: =+AW15+AY15 -> 2369500.2 | BF15: =+AX15+AZ15 -> 71707.42 | BG15: 2234474.8 | BH15: 9758.51 | BI15: =+BI12 -> 2406999.7 | BJ15: 5928.249
B16: CMO DIR | C16: MT | F16: 53811.41 | H16: 55157.91 | J16: =+F16+H16 -> 108969.32 | L16: =65178.53-127.26 -> 65051.27 | N16: =+J16+L16 -> 174020.59 | P16: =82528.9+127.26 -> 82656.16 | R16: =+N16+P16 -> 256676.75 | T16: 97004.97 | V16: =+R16+T16 -> 353681.72 | X16: 102219.46 | Z16: =+P16+T16+X16 -> 281880.59 | AB16: =+N16+Z16 -> 455901.18 | AD16: 101716.5 | AF16: =+AB16+AD16 -> 557617.68 | AH16: 81658.61 | AJ16: =+AF16+AH16 -> 639276.29 | AL16: 95716.89 | AN16: =+AD16+AH16+AL16 -> 279092 | AP16: =+AJ16+AL16 -> 734993.18 | AR16: 114017.2 | AT16: =+AP16+AR16 -> 849010.38 | AV16: 103913.77 | AX16: =+AT16+AV16 -> 952924.15 | AZ16: 144169 | BB16: =+AR16+AV16+AZ16 -> 362099.97 | BD16: =+AN16+BB16 -> 641191.97 | BF16: =+AX16+AZ16 -> 1097093.1 | BH16: 691326.52 | BJ16: 569419.83 | BL16: =+BF16/BF12 -> 0.50365677
B17: CMO SYD | C17: MT | F17: 29580.3 | H17: 23511.71 | J17: =+F17+H17 -> 53092.01 | L17: 50006.46 | N17: =+J17+L17 -> 103098.47 | P17: 57970.83 | R17: =+N17+P17 -> 161069.3 | T17: 42991.69 | V17: =+R17+T17 -> 204060.99 | X17: 36485.47 | Z17: =+P17+T17+X17 -> 137447.99 | AB17: =+N17+Z17 -> 240546.46 | AD17: 44126.7 | AF17: =+AB17+AD17 -> 284673.16 | AH17: 55003.57 | AJ17: =+AF17+AH17 -> 339676.73 | AL17: 93671.32 | AN17: =+AD17+AH17+AL17 -> 192801.59 | AP17: =+AJ17+AL17 -> 433348.05 | AR17: 52992.64 | AT17: =+AP17+AR17 -> 486340.69 | AV17: 34486.53 | AX17: =+AT17+AV17 -> 520827.22 | AZ17: 46444 | BB17: =+AR17+AV17+AZ17 -> 133923.17 | BD17: =+AN17+BB17 -> 326724.76 | BF17: =+AX17+AZ17 -> 567271.22 | BH17: 479205.15 | BJ17: 909567
B18: MKTG DIR (DEF) | C18: MT | F18: =+F6 -> 2956.91 | H18: =+H6 -> 4274.74 | J18: =+F18+H18 -> 7231.65 | L18: 1722.87 | N18: =+J18+L18 -> 8954.52 | P18: 2943.97 | R18: =+N18+P18 -> 11898.49 | T18: =+T6 -> 3275.94 | V18: =+R18+T18 -> 15174.43 | X18: =+X6 -> 1628.47 | Z18: =+P18+T18+X18 -> 7848.38 | AB18: =+N18+Z18 -> 16802.9 | AD18: =+AD6 -> 3324.25 | AF18: =+AB18+AD18 -> 20127.15 | AH18: =+AH6 -> 2214.32 | AJ18: =+AF18+AH18 -> 22341.47 | AL18: =+AL6 -> 2437.96 | AN18: =+AD18+AH18+AL18 -> 7976.53 | AP18: =+AJ18+AL18 -> 24779.43 | AR18: =+AR6 -> 17.6 | AT18: =+AP18+AR18 -> 24797.03 | AV18: =+AV6 -> 2076.14 | AX18: =+AT18+AV18 -> 26873.17 | AZ18: =+AZ6 -> 6327.98 | BB18: =+AR18+AV18+AZ18 -> 8421.72 | BD18: =+AN18+BB18 -> 16398.25 | BF18: =+AX18+AZ18 -> 33201.15 | BH18: 35268.25 | BJ18: 28405.85
B19: EXPORT DIR | C19: MT | F19: 19244.8 | H19: 15804.81 | J19: =+F19+H19 -> 35049.61 | L19: 57325.27 | N19: =+J19+L19 -> 92374.88 | P19: 42170.47 | R19: =+N19+P19 -> 134545.35 | T19: 42788.26 | V19: =+R19+T19 -> 177333.61 | X19: 53873.32 | Z19: =+P19+T19+X19 -> 138832.05 | AB19: =+N19+Z19 -> 231206.93 | AD19: 23677.01 | AF19: =+AB19+AD19 -> 254883.94 | AH19: 44040.17 | AJ19: =+AF19+AH19 -> 298924.11 | AL19: 20436.23 | AN19: =+AD19+AH19+AL19 -> 88153.41 | AP19: =+AJ19+AL19 -> 319360.34 | AR19: 33494.92 | AT19: =+AP19+AR19 -> 352855.26 | AV19: 37415.32 | AX19: =+AT19+AV19 -> 390270.58 | AZ19: 18712 | BB19: =+AR19+AV19+AZ19 -> 89622.24 | BD19: =+AN19+BB19 -> 177775.65 | BF19: =+AX19+AZ19 -> 408982.58 | BH19: 662096.98 | BJ19: 536611.98
