Workbook

Sheet 2019-20 MASTER
D2: FOR THE YEAR 2019-20
D3: SL. NO. | F3: Apr | G3: May | H3: 2M | I3: June | J3: Q-I | K3: July | L3: 4M | M3: Aug | N3: 5M | O3: Sep | P3: Q-II | Q3: H-I | R3: Oct | S3: 7M | T3: Nov | U3: 8M | V3: Dec | W3: Q-III | X3: 9M | Y3: Jan | Z3: 10M | AA3: Feb | AB3: 11M | AC3: Mar | AD3: Q-IV | AE3: H-II | AF3: 12M
E4: I T E M S
E6: Days | F6: 30 | G6: 31 | H6: =+F6+G6 -> 61 | I6: 30 | J6: =+H6+I6 -> 91 | K6: 31 | L6: =+J6+K6 -> 122 | M6: 31 | N6: =+L6+M6 -> 153 | O6: 30 | P6: =+K6+M6+O6 -> 92 | Q6: =+J6+P6 -> 183 | R6: 31 | S6: =+Q6+R6 -> 214 | T6: 30 | U6: =+S6+T6 -> 244 | V6: 31 | W6: =+R6+T6+V6 -> 92 | X6: =+U6+V6 -> 275 | Y6: 31 | Z6: =+X6+Y6 -> 306 | AA6: 29 | AB6: =+Z6+AA6 -> 335 | AC6: 31 | AD6: =+Y6+AA6+AC6 -> 91 | AE6: =+W6+AD6 -> 183 | AF6: =+Q6+AE6 -> 366
D7: PRODUCTION
D8: 1 | E8: No.of Ovens Pushed (COB#10) | F8: 2336 | G8: 2647 | H8: =+F8+G8 -> 4983 | I8: 2766 | J8: =+H8+I8 -> 7749 | K8: 3009 | L8: =+J8+K8 -> 10758 | M8: 3024 | N8: =+L8+M8 -> 13782 | O8: 2780 | P8: =+K8+M8+O8 -> 8813 | Q8: =+N8+O8 -> 16562 | R8: 3008 | S8: =+Q8+R8 -> 19570 | T8: 2937 | U8: =+S8+T8 -> 22507 | V8: 3042 | W8: =+R8+T8+V8 -> 8987 | X8: =+U8+V8 -> 25549 | Y8: 3077 | Z8: =+X8+Y8 -> 28626 | AA8: 2882 | AB8: =+Z8+AA8 -> 31508 | AC8: 2920 | AD8: =+Y8+AA8+AC8 -> 8879 | AE8: =+W8+AD8 -> 17866 | AF8: =+AB8+AC8 -> 34428
E9: No.of Ovens Pushed/ Day (COB#10) | F9: =+F8/F6 -> 77.866667 | G9: =+G8/G6 -> 85.387097 | H9: =+H8/H6 -> 81.688525 | I9: =+I8/I6 -> 92.2 | J9: =+J8/J6 -> 85.153846 | K9: =+K8/K6 -> 97.064516 | L9: =+L8/L6 -> 88.180328 | M9: =+M8/M6 -> 97.548387 | ... O9: =+O8/O6 -> 92.666667 | P9: =+P8/$P$6 -> 95.793478 | Q9: =+Q8/$Q$6 -> 90.502732 | R9: =+R8/R6 -> 97.032258 | S9: =+S8/S6 -> 91.448598 | T9: =+T8/T6 -> 97.9 | U9: =+U8/U6 -> 92.241803 | V9: =+V8/V6 -> 98.129032 | W9: =+W8/W6 -> 97.684783 | X9: =+X8/X6 -> 92.905455 | Y9: =+Y8/Y6 -> 99.258065 | ... AF9: =+AF8/AF6 -> 94.065574
D10: 2 | E10: Nos.of Ovens Pushed (COB#11) | F10: 2333 | G10: 2329 | H10: =+F10+G10 -> 4662 | I10: 2595 | J10: =+H10+I10 -> 7257 | K10: 2816 | L10: =+J10+K10 -> 10073 | M10: 3052 | N10: =+L10+M10 -> 13125 | O10: 2775 | P10: =+K10+M10+O10 -> 8643 | Q10: =+N10+O10 -> 15900 | R10: 3008 | S10: =+Q10+R10 -> 18908 | T10: 2912 | U10: =+S10+T10 -> 21820 | V10: 3047 | W10: =+R10+T10+V10 -> 8967 | X10: =+U10+V10 -> 24867 | Y10: 2914 | Z10: =+X10+Y10 -> 27781 | AA10: 2811 | AB10: =+Z10+AA10 -> 30592 | AC10: 2858 | AD10: =+Y10+AA10+AC10 -> 8583 | AE10: =+W10+AD10 -> 17550 | AF10: =+AB10+AC10 -> 33450
E11: Nos.of Ovens Pushed/ Day (COB#11) | F11: =+F10/F6 -> 77.766667 | G11: =+G10/G6 -> 75.129032 | H11: =+H10/H6 -> 76.42623 | I11: =+I10/I6 -> 86.5 | J11: =+J10/J6 -> 79.747253 | K11: =+K10/K6 -> 90.83871 | L11: =+L10/L6 -> 82.565574 | M11: =+M10/M6 -> 98.451613 | ... O11: =+O10/O6 -> 92.5 | P11: =+P10/$P$6 -> 93.945652 | Q11: =+Q10/Q6 -> 86.885246 | R11: =+R10/R6 -> 97.032258 | S11: =+S10/S6 -> 88.35514 | T11: =+T10/T6 -> 97.066667 | U11: =+U10/U6 -> 89.42623 | V11: =+V10/V6 -> 98.290323 | W11: =+W10/W6 -> 97.467391 | X11: =+X10/X6 -> 90.425455 | ... AF11: =+AF10/AF6 -> 91.393443
E12: Total No.of Equiv. Ovens Pushed | F12: =F8+(F10*1.8343023255814) -> 6615.4273 | G12: =G8+(G10*1.8343023255814) -> 6919.0901 | H12: =+F12+G12 -> 13534.517 | I12: =I8+(I10*1.8343023255814) -> 7526.0145 | J12: =+H12+I12 -> 21060.532 | K12: =K8+(K10*1.8343023255814) -> 8174.3953 | L12: =+J12+K12 -> 29234.927 | M12: =M8+(M10*1.8343023255814) -> 8622.2907 | N12: =+L12+M12 -> 37857.218 | O12: =O8+(O10*1.8343023255814) -> 7870.189 | P12: =+K12+M12+O12 -> 24666.875 | Q12: =+N12+O12 -> 45727.407 | R12: =R8+(R10*1.8343023255814) -> 8525.5814 | S12: =+Q12+R12 -> 54252.988 | T12: =T8+(T10*1.8343023255814) -> 8278.4884 | U12: =+S12+T12 -> 62531.477 | V12: =V8+(V10*1.8343023255814) -> 8631.1192 | W12: =+R12+T12+V12 -> 25435.189 | X12: =+U12+V12 -> 71162.596 | Y12: =Y8+(Y10*1.8343023255814) -> 8422.157 | Z12: =+X12+Y12 -> 79584.753 | AA12: =AA8+(AA10*1.8343023255814) -> 8038.2238 | AB12: =+Z12+AA12 -> 87622.977 | AC12: =AC8+(AC10*1.8343023255814) -> 8162.436 | AD12: =+Y12+AA12+AC12 -> 24622.817 | AE12: =+W12+AD12 -> 50058.006 | AF12: =+AB12+AC12 -> 95785.413
E13: Overall Equiv. Ovens Pushed/ Day | F13: =+F12/F6 -> 220.51424 | G13: =+G12/G6 -> 223.19646 | H13: =+H12/H6 -> 221.87734 | I13: =+I12/I6 -> 250.86715 | J13: =+J12/J6 -> 231.43442 | K13: =+K12/K6 -> 263.69017 | L13: =+L12/L6 -> 239.63055 | M13: =+M12/M6 -> 278.13841 | ... O13: =+O12/O6 -> 262.33963 | P13: =+P12/$P$6 -> 268.11821 | Q13: =+Q12/$Q$6 -> 249.87654 | R13: =+R12/R6 -> 275.01875 | S13: =+S12/S6 -> 253.51864 | T13: =+T12/T6 -> 275.94961 | U13: =+U12/U6 -> 256.27654 | V13: =+V12/V6 -> 278.4232 | W13: =+W12/W6 -> 276.46945 | X13: =+X12/X6 -> 258.77308 | Y13: =+Y12/Y6 -> 271.68248 | ... AF13: =+AF12/AF6 -> 261.70878
E14: OVEN AVAILABILITY (COB #10) | F14: 77.43 | G14: 77.29 | H14: =+((F14*$F$6)+(G14*$G$6))/$H$6 -> 77.358852 | I14: 77.46 | J14: =+((H14*$H$6)+(I14*$I$6))/$J$6 -> 77.392198 | K14: 77.74 | L14: =+((J14*$J$6)+(K14*$K$6))/$L$6 -> 77.480574 | M14: 77.7 | N14: =+((L14*$L$6)+(M14*$M$6))/$N$6 -> 77.525033 | O14: 77.7 | P14: =+((K14*$K$6)+(M14*$M$6)+(O14*$O$6))/$P$6 -> 77.713478 | Q14: =+((N14*$N$6)+(O14*$O$6))/$Q$6 -> 77.553716 | R14: 77.6 | S14: =+((Q14*$Q$6)+(R14*$R$6))/$S$6 -> 77.560421 | T14: 77.73 | U14: =+((S14*$S$6)+(T14*$T$6))/$U$6 -> 77.58127 | V14: 76.71 | W14: =+((R14*$R$6)+(T14*$T$6)+(V14*$V$6))/$W$6 -> 77.3425 | X14: =+((U14*$U$6)+(V14*$V$6))/$X$6 -> 77.483055 | Y14: 77.77 | Z14: =+((X14*$X$6)+(Y14*$Y$6))/$Z$6 -> 77.512124 | AA14: 77.51 | AB14: =+((Z14*$Z$6)+(AA14*$AA$6))/$AB$6 -> 77.51194 | AC14: 77.58 | AD14: =+((Y14*$Y$6)+(AA14*$AA$6)+(AC14*$AC$6))/$AD$6 -> 77.622418 | AE14: =+((W14*$W$6)+(AD14*$AD$6))/$AE$6 -> 77.481694 | AF14: =+((AB14*$AB$6)+(AC14*$AC$6))/$AF$6 -> 77.517705
E15: OVEN AVAILABILITY (COB #11) | F15: 74 | G15: 74 | H15: =+((F15*$F$6)+(G15*$G$6))/$H$6 -> 74 | I15: 74 | J15: =+((H15*$H$6)+(I15*$I$6))/$J$6 -> 74 | K15: 73.9 | L15: =+((J15*$J$6)+(K15*$K$6))/$L$6 -> 73.97459 | M15: 74 | N15: =+((L15*$L$6)+(M15*$M$6))/$N$6 -> 73.979739 | O15: 73.9 | P15: =+((K15*$K$6)+(M15*$M$6)+(O15*$O$6))/$P$6 -> 73.933696 | Q15: =+((N15*$N$6)+(O15*$O$6))/$Q$6 -> 73.966667 | R15: 74 | S15: =+((Q15*$Q$6)+(R15*$R$6))/$S$6 -> 73.971495 | T15: 73.9 | U15: =+((S15*$S$6)+(T15*$T$6))/$U$6 -> 73.962705 | V15: 74 | W15: =+((R15*$R$6)+(T15*$T$6)+(V15*$V$6))/$W$6 -> 73.967391 | X15: =+((U15*$U$6)+(V15*$V$6))/$X$6 -> 73.966909 | Y15: 74 | Z15: =+((X15*$X$6)+(Y15*$Y$6))/$Z$6 -> 73.970261 | AA15: 74 | AB15: =+((Z15*$Z$6)+(AA15*$AA$6))/$AB$6 -> 73.972836 | AC15: 74 | AD15: =+((Y15*$Y$6)+(AA15*$AA$6)+(AC15*$AC$6))/$AD$6 -> 74 | AE15: =+((W15*$W$6)+(AD15*$AD$6))/$AE$6 -> 73.983607 | AF15: =+((AB15*$AB$6)+(AC15*$AC$6))/$AF$6 -> 73.975137
E16: PUSHING CO-EFFICIENT (BASED ON ACTUAL OVEN AVAILABILITY)
C17: =5575.09+47146.97 -> 52722.06 | E17: COB#10 | F17: =+F8/(F14*F6) -> 1.0056395 | G17: =+G8/(G14*G6) -> 1.1047625 | H17: =+H8/(H14*H6) -> 1.0559687 | I17: =+I8/(I14*I6) -> 1.1902918 | J17: =+J8/(J14*J6) -> 1.1002898 | K17: =+K8/(K14*K6) -> 1.2485788 | L17: =+L8/(L14*L6) -> 1.138096 | M17: =+M8/(M14*M6) -> 1.255449 | ... AF17: =+AF8/(AF14*AF6) -> 1.2134721
E18: COB#11 | F18: =+F10/(F15*F6) -> 1.0509009 | G18: =+G10/(G15*G6) -> 1.0152572 | H18: =+H10/(H15*H6) -> 1.0327869 | I18: =+I10/(I15*I6) -> 1.1689189 | J18: =+J10/(J15*J6) -> 1.0776656 | K18: =+K10/(K15*K6) -> 1.2292112 | L18: =+L10/(L15*L6) -> 1.1161343 | M18: =+M10/(M15*M6) -> 1.3304272 | ... AF18: =+AF10/(AF15*AF6) -> 1.2354616
E19: Dry Coal Charge (Old Batts) | F19: =+F8*17.2 -> 40179.2 | G19: =+G8*17.2 -> 45528.4 | H19: =+F19+G19 -> 85707.6 | I19: =+I8*17.2 -> 47575.2 | J19: =+H19+I19 -> 133282.8 | K19: =+K8*17.2 -> 51754.8 | L19: =SUM(J19:K19) -> 185037.6 | M19: =+M8*17.2 -> 52012.8 | N19: =SUM(L19:M19) -> 237050.4 | O19: =+O8*17.2 -> 47816 | P19: =+K19+M19+O19 -> 151583.6 | Q19: =+N19+O19 -> 284866.4 | R19: =+R8*17.2 -> 51737.6 | S19: =SUM(Q19:R19) -> 336604 | T19: =+T8*17.2 -> 50516.4 | U19: =SUM(S19:T19) -> 387120.4 | V19: =+V8*17.2 -> 52322.4 | W19: =+R19+T19+V19 -> 154576.4 | X19: =+U19+V19 -> 439442.8 | Y19: =+Y8*17.2 -> 52924.4 | Z19: =SUM(X19:Y19) -> 492367.2 | AA19: =+AA8*17.2 -> 49570.4 | AB19: =+Z19+AA19 -> 541937.6 | AC19: =+AC8*17.2 -> 50224 | AD19: =+Y19+AA19+AC19 -> 152718.8 | AE19: =+W19+AD19 -> 307295.2 | AF19: =+AB19+AC19 -> 592161.6
E20: Dry Coal Charge (New Batt) | F20: =+F10*31.55 -> 73606.15 | G20: =+G10*31.55 -> 73479.95 | H20: =SUM(F20:G20) -> 147086.1 | I20: =+I10*31.55 -> 81872.25 | J20: =+H20+I20 -> 228958.35 | K20: =+K10*31.55 -> 88844.8 | L20: =SUM(J20:K20) -> 317803.15 | M20: =+M10*31.55 -> 96290.6 | N20: =SUM(L20:M20) -> 414093.75 | O20: =+O10*31.55 -> 87551.25 | P20: =+K20+M20+O20 -> 272686.65 | Q20: =+N20+O20 -> 501645 | R20: =+R10*31.55 -> 94902.4 | S20: =SUM(Q20:R20) -> 596547.4 | T20: =+T10*31.55 -> 91873.6 | U20: =SUM(S20:T20) -> 688421 | V20: =+V10*31.55 -> 96132.85 | W20: =+R20+T20+V20 -> 282908.85 | X20: =+U20+V20 -> 784553.85 | Y20: =+Y10*31.55 -> 91936.7 | Z20: =SUM(X20:Y20) -> 876490.55 | AA20: =+AA10*31.55 -> 88687.05 | AB20: =+Z20+AA20 -> 965177.6 | AC20: =+AC10*31.55 -> 90169.9 | AD20: =+Y20+AA20+AC20 -> 270793.65 | AE20: =+W20+AD20 -> 553702.5 | AF20: =+AB20+AC20 -> 1055347.5
E21: Total Dry Coal Charge | F21: =SUM(F19:F20) -> 113785.35 | G21: =SUM(G19:G20) -> 119008.35 | H21: =SUM(H19:H20) -> 232793.7 | I21: =SUM(I19:I20) -> 129447.45 | J21: =SUM(J19:J20) -> 362241.15 | K21: =SUM(K19:K20) -> 140599.6 | L21: =SUM(L19:L20) -> 502840.75 | M21: =SUM(M19:M20) -> 148303.4 | ... AF21: =SUM(AF19:AF20) -> 1647509.1
D22: 5. | E22: B.F.Coke (Old Batts) | F22: 27936.6 | G22: 31876 | H22: =+F22+G22 -> 59812.6 | I22: 33669.6 | J22: =+H22+I22 -> 93482.2 | K22: 36675 | L22: =+J22+K22 -> 130157.2 | M22: 34692.54 | N22: =+L22+M22 -> 164849.74 | O22: 31931.5 | P22: =+K22+M22+O22 -> 103299.04 | Q22: =+N22+O22 -> 196781.24 | R22: 34545.2 | S22: =+Q22+R22 -> 231326.44 | T22: 34351.2 | U22: =+S22+T22 -> 265677.64 | V22: 35840.8 | W22: =+R22+T22+V22 -> 104737.2 | X22: =+U22+V22 -> 301518.44 | Y22: 36285 | Z22: =+X22+Y22 -> 337803.44 | AA22: 34074.7 | AB22: =+Z22+AA22 -> 371878.14 | AC22: 34659.6 | AD22: =+Y22+AA22+AC22 -> 105019.3 | AE22: =+W22+AD22 -> 209756.5 | AF22: =+AB22+AC22 -> 406537.74
E23: B.F Coke (New Batt) | F23: =+F626 -> 51175.3 | G23: =+G626 -> 51446 | H23: =SUM(F23:G23) -> 102621.3 | I23: =+I626 -> 57942.1 | J23: =+H23+I23 -> 160563.4 | K23: =+K626 -> 62959 | L23: =+J23+K23 -> 223522.4 | M23: =+M626 -> 64223.17 | N23: =+L23+M23 -> 287745.57 | O23: =+O626 -> 58471.09 | P23: =+K23+M23+O23 -> 185653.26 | Q23: =+N23+O23 -> 346216.66 | R23: =+R626 -> 63365.36 | S23: =+Q23+R23 -> 409582.02 | T23: =+T626 -> 62474 | U23: =SUM(S23:T23) -> 472056.02 | V23: =+V626 -> 65847 | W23: =+R23+T23+V23 -> 191686.36 | X23: =+U23+V23 -> 537903.02 | Y23: =+Y626 -> 63029 | Z23: =+X23+Y23 -> 600932.02 | AA23: =+AA626 -> 60966 | AB23: =+Z23+AA23 -> 661898.02 | AC23: =+AC626 -> 62225 | AD23: =+Y23+AA23+AC23 -> 186220 | AE23: =+W23+AD23 -> 377906.36 | AF23: =+AB23+AC23 -> 724123.02
E24: Total B.F.Coke | F24: =SUM(F22:F23) -> 79111.9 | G24: =SUM(G22:G23) -> 83322 | H24: =SUM(H22:H23) -> 162433.9 | I24: =SUM(I22:I23) -> 91611.7 | J24: =SUM(J22:J23) -> 254045.6 | K24: =SUM(K22:K23) -> 99634 | L24: =SUM(L22:L23) -> 353679.6 | M24: =SUM(M22:M23) -> 98915.71 | ... Y24: =SUM(Y22:Y23) -> 99314 | Z24: =+X24+Y24 -> 938735.46 | AA24: =SUM(AA22:AA23) -> 95040.7 | AB24: =+Z24+AA24 -> 1033776.2 | AC24: =SUM(AC22:AC23) -> 96884.6 | AD24: =SUM(AD22:AD23) -> 291239.3 | AE24: =SUM(AE22:AE23) -> 587662.86 | AF24: =SUM(AF22:AF23) -> 1130660.8
E25: Nut Coke (Old Batts) | F25: 317.4 | G25: 184 | H25: =+F25+G25 -> 501.4 | I25: 149.8 | J25: =+H25+I25 -> 651.2 | K25: 427 | L25: =+J25+K25 -> 1078.2 | M25: 1607.2 | N25: =+L25+M25 -> 2685.4 | O25: 1601.8 | P25: =+K25+M25+O25 -> 3636 | Q25: =+N25+O25 -> 4287.2 | R25: 1536.6 | S25: =+Q25+R25 -> 5823.8 | T25: 1262.9 | U25: =+S25+T25 -> 7086.7 | V25: 1339.5 | W25: =+R25+T25+V25 -> 4139 | X25: =+U25+V25 -> 8426.2 | Y25: 1122 | Z25: =+X25+Y25 -> 9548.2 | AA25: 931.9 | AB25: =+Z25+AA25 -> 10480.1 | AC25: 999.5 | AD25: =+Y25+AA25+AC25 -> 3053.4 | AE25: =+W25+AD25 -> 7192.4 | AF25: =+AB25+AC25 -> 11479.6
E26: Nut Coke (New Batt) | F26: =+F627 -> 582.6 | G26: =+G627 -> 297 | H26: =SUM(F26:G26) -> 879.6 | I26: =+I627 -> 257.8 | J26: =+H26+I26 -> 1137.4 | K26: =+K627 -> 733 | L26: =+J26+K26 -> 1870.4 | M26: =+M627 -> 2979.15 | N26: =+L26+M26 -> 4849.55 | O26: =+O627 -> 2932.95 | P26: =+K26+M26+O26 -> 6645.1 | Q26: =+N26+O26 -> 7782.5 | R26: =+R627 -> 2819.91 | S26: =+Q26+R26 -> 10602.41 | T26: =+T627 -> 2296.8 | U26: =SUM(S26:T26) -> 12899.21 | V26: =+V627 -> 2463 | W26: =+R26+T26+V26 -> 7579.71 | X26: =+U26+V26 -> 15362.21 | Y26: =+Y627 -> 1945 | Z26: =+X26+Y26 -> 17307.21 | AA26: =+AA627 -> 1670 | AB26: =+Z26+AA26 -> 18977.21 | AC26: =+AC627 -> 1795 | AD26: =+Y26+AA26+AC26 -> 5410 | AE26: =+W26+AD26 -> 12989.71 | AF26: =+AB26+AC26 -> 20772.21
E27: Total Nut Coke | F27: =SUM(F25:F26) -> 900 | G27: =SUM(G25:G26) -> 481 | H27: =SUM(H25:H26) -> 1381 | I27: =SUM(I25:I26) -> 407.6 | J27: =SUM(J25:J26) -> 1788.6 | K27: =SUM(K25:K26) -> 1160 | L27: =SUM(L25:L26) -> 2948.6 | M27: =SUM(M25:M26) -> 4586.35 | ... Y27: =SUM(Y25:Y26) -> 3067 | Z27: =+X27+Y27 -> 26855.41 | AA27: =SUM(AA25:AA26) -> 2601.9 | AB27: =+Z27+AA27 -> 29457.31 | AC27: =SUM(AC25:AC26) -> 2794.5 | AD27: =SUM(AD25:AD26) -> 8463.4 | AE27: =SUM(AE25:AE26) -> 20182.11 | AF27: =SUM(AF25:AF26) -> 32251.81
E28: Coke Breeze (Old Batts) | F28: 1884.4 | G28: 2091 | H28: =+F28+G28 -> 3975.4 | I28: 1871.5 | J28: =+H28+I28 -> 5846.9 | K28: 1715 | L28: =+J28+K28 -> 7561.9 | M28: 2735.87 | N28: =+L28+M28 -> 10297.77 | O28: 2390.8 | P28: =+K28+M28+O28 -> 6841.67 | Q28: =+N28+O28 -> 12688.57 | R28: 2773.1 | S28: =+Q28+R28 -> 15461.67 | T28: 2273.2 | U28: =+S28+T28 -> 17734.87 | V28: 2150.5 | W28: =+R28+T28+V28 -> 7196.8 | X28: =+U28+V28 -> 19885.37 | Y28: 2281 | Z28: =+X28+Y28 -> 22166.37 | AA28: 2171.2 | AB28: =+Z28+AA28 -> 24337.57 | AC28: 2009 | AD28: =+Y28+AA28+AC28 -> 6461.2 | AE28: =+W28+AD28 -> 13658 | AF28: =+AB28+AC28 -> 26346.57
E29: Coke Breeze (New Batt) | F29: =+F628 -> 3452.5 | G29: =+G628 -> 3374 | H29: =SUM(F29:G29) -> 6826.5 | I29: =+I628 -> 3220.7 | J29: =+H29+I29 -> 10047.2 | K29: =+K628 -> 2945 | L29: =+J29+K29 -> 12992.2 | M29: =+M628 -> 5068.85 | N29: =+L29+M29 -> 18061.05 | O29: =+O628 -> 4373.49 | P29: =+K29+M29+O29 -> 12387.34 | Q29: =+N29+O29 -> 22434.54 | R29: =+R628 -> 5085.66 | S29: =+Q29+R29 -> 27520.2 | T29: =+T628 -> 4134.3 | U29: =SUM(S29:T29) -> 31654.5 | V29: =+V628 -> 3947 | W29: =+R29+T29+V29 -> 13166.96 | X29: =+U29+V29 -> 35601.5 | Y29: =+Y628 -> 3965 | Z29: =+X29+Y29 -> 39566.5 | AA29: =+AA628 -> 3887 | AB29: =+Z29+AA29 -> 43453.5 | AC29: =+AC628 -> 3610 | AD29: =+Y29+AA29+AC29 -> 11462 | AE29: =+W29+AD29 -> 24628.96 | AF29: =+AB29+AC29 -> 47063.5
E30: Total Coke Breeze | F30: =SUM(F28:F29) -> 5336.9 | G30: =SUM(G28:G29) -> 5465 | H30: =SUM(H28:H29) -> 10801.9 | I30: =SUM(I28:I29) -> 5092.2 | J30: =SUM(J28:J29) -> 15894.1 | K30: =SUM(K28:K29) -> 4660 | L30: =SUM(L28:L29) -> 20554.1 | M30: =SUM(M28:M29) -> 7804.72 | ... Y30: =SUM(Y28:Y29) -> 6246 | Z30: =+X30+Y30 -> 61732.87 | AA30: =SUM(AA28:AA29) -> 6058.2 | AB30: =+Z30+AA30 -> 67791.07 | AC30: =SUM(AC28:AC29) -> 5619 | AD30: =SUM(AD28:AD29) -> 17923.2 | AE30: =SUM(AE28:AE29) -> 38286.96 | AF30: =SUM(AF28:AF29) -> 73410.07
E31: Coke Dust (Old Batts) | F31: 397.8 | G31: 451 | H31: =+F31+G31 -> 848.8 | I31: 466.2 | J31: =+H31+I31 -> 1315 | K31: 516 | L31: =+J31+K31 -> 1831 | M31: 488.92 | N31: =+L31+M31 -> 2319.92 | O31: 416 | P31: =+K31+M31+O31 -> 1420.92 | Q31: =+N31+O31 -> 2735.92 | R31: 465.6 | S31: =+Q31+R31 -> 3201.52 | T31: 505.2 | U31: =+S31+T31 -> 3706.72 | V31: 439.5 | W31: =+R31+T31+V31 -> 1410.3 | X31: =+U31+V31 -> 4146.22 | Y31: 539.8 | Z31: =+X31+Y31 -> 4686.02 | AA31: 490.7 | AB31: =+Z31+AA31 -> 5176.72 | AC31: 502.2 | AD31: =+Y31+AA31+AC31 -> 1532.7 | AE31: =+W31+AD31 -> 2943 | AF31: =+AB31+AC31 -> 5678.92
E32: Coke Dust (New Batt) | F32: =+F629 -> 730.3 | G32: =+G629 -> 728 | H32: =SUM(F32:G32) -> 1458.3 | I32: =+I629 -> 802.3 | J32: =+H32+I32 -> 2260.6 | K32: =+K629 -> 886 | L32: =+J32+K32 -> 3146.6 | M32: =+M629 -> 909.69 | N32: =+L32+M32 -> 4056.29 | O32: =+O629 -> 761.42 | P32: =+K32+M32+O32 -> 2557.11 | Q32: =+N32+O32 -> 4817.71 | R32: =+R629 -> 854.89 | S32: =+Q32+R32 -> 5672.6 | T32: =+T629 -> 918.7 | U32: =SUM(S32:T32) -> 6591.3 | V32: =+V629 -> 803 | W32: =+R32+T32+V32 -> 2576.59 | X32: =+U32+V32 -> 7394.3 | Y32: =+Y629 -> 933 | Z32: =+X32+Y32 -> 8327.3 | AA32: =+AA629 -> 879 | AB32: =+Z32+AA32 -> 9206.3 | AC32: =+AC629 -> 898 | AD32: =+Y32+AA32+AC32 -> 2710 | AE32: =+W32+AD32 -> 5286.59 | AF32: =+AB32+AC32 -> 10104.3
E33: Total Coke Dust | F33: =SUM(F31:F32) -> 1128.1 | G33: =SUM(G31:G32) -> 1179 | H33: =SUM(H31:H32) -> 2307.1 | I33: =SUM(I31:I32) -> 1268.5 | J33: =SUM(J31:J32) -> 3575.6 | K33: =SUM(K31:K32) -> 1402 | L33: =SUM(L31:L32) -> 4977.6 | M33: =SUM(M31:M32) -> 1398.61 | ... Y33: =SUM(Y31:Y32) -> 1472.8 | Z33: =+X33+Y33 -> 13013.32 | AA33: =SUM(AA31:AA32) -> 1369.7 | AB33: =+Z33+AA33 -> 14383.02 | AC33: =SUM(AC31:AC32) -> 1400.2 | AD33: =SUM(AD31:AD32) -> 4242.7 | AE33: =SUM(AE31:AE32) -> 8229.59 | AF33: =SUM(AF31:AF32) -> 15783.22
E34: Gross Coke (Old Batts) | F34: =+F22+F25+F28+F31 -> 30536.2 | G34: =+G22+G25+G28+G31 -> 34602 | H34: =+F34+G34 -> 65138.2 | I34: =+I22+I25+I28+I31 -> 36157.1 | J34: =+H34+I34 -> 101295.3 | K34: =+K22+K25+K28+K31 -> 39333 | L34: =+J34+K34 -> 140628.3 | M34: =+M22+M25+M28+M31 -> 39524.53 | N34: =+L34+M34 -> 180152.83 | O34: =+O22+O25+O28+O31 -> 36340.1 | P34: =+K34+M34+O34 -> 115197.63 | Q34: =+N34+O34 -> 216492.93 | R34: =+R22+R25+R28+R31 -> 39320.5 | S34: =+Q34+R34 -> 255813.43 | T34: =+T22+T25+T28+T31 -> 38392.5 | U34: =+S34+T34 -> 294205.93 | V34: =+V22+V25+V28+V31 -> 39770.3 | W34: =+R34+T34+V34 -> 117483.3 | X34: =+U34+V34 -> 333976.23 | Y34: =+Y22+Y25+Y28+Y31 -> 40227.8 | Z34: =+X34+Y34 -> 374204.03 | AA34: =+AA22+AA25+AA28+AA31 -> 37668.5 | AB34: =+Z34+AA34 -> 411872.53 | AC34: =+AC22+AC25+AC28+AC31 -> 38170.3 | AD34: =+Y34+AA34+AC34 -> 116066.6 | AE34: =+W34+AD34 -> 233549.9 | AF34: =+AB34+AC34 -> 450042.83
E35: Gross Coke (New Batt) | F35: =+F23+F26+F29+F32 -> 55940.7 | G35: =+G23+G26+G29+G32 -> 55845 | H35: =SUM(F35:G35) -> 111785.7 | I35: =+I23+I26+I29+I32 -> 62222.9 | J35: =+H35+I35 -> 174008.6 | K35: =+K23+K26+K29+K32 -> 67523 | L35: =+J35+K35 -> 241531.6 | M35: =+M23+M26+M29+M32 -> 73180.86 | N35: =+L35+M35 -> 314712.46 | O35: =+O23+O26+O29+O32 -> 66538.95 | P35: =+K35+M35+O35 -> 207242.81 | Q35: =+N35+O35 -> 381251.41 | R35: =+R23+R26+R29+R32 -> 72125.82 | S35: =+Q35+R35 -> 453377.23 | T35: =+T23+T26+T29+T32 -> 69823.8 | U35: =SUM(S35:T35) -> 523201.03 | V35: =+V23+V26+V29+V32 -> 73060 | W35: =+R35+T35+V35 -> 215009.62 | X35: =+U35+V35 -> 596261.03 | Y35: =+Y23+Y26+Y29+Y32 -> 69872 | Z35: =+X35+Y35 -> 666133.03 | AA35: =+AA23+AA26+AA29+AA32 -> 67402 | AB35: =+Z35+AA35 -> 733535.03 | AC35: =+AC23+AC26+AC29+AC32 -> 68528 | AD35: =+Y35+AA35+AC35 -> 205802 | AE35: =+W35+AD35 -> 420811.62 | AF35: =+AB35+AC35 -> 802063.03
E36: Total Gross Coke | F36: =SUM(F34:F35) -> 86476.9 | G36: =SUM(G34:G35) -> 90447 | H36: =SUM(H34:H35) -> 176923.9 | I36: =SUM(I34:I35) -> 98380 | J36: =SUM(J34:J35) -> 275303.9 | K36: =SUM(K34:K35) -> 106856 | L36: =SUM(L34:L35) -> 382159.9 | M36: =SUM(M34:M35) -> 112705.39 | ... Y36: =SUM(Y34:Y35) -> 110099.8 | Z36: =+X36+Y36 -> 1040337.1 | AA36: =SUM(AA34:AA35) -> 105070.5 | AB36: =+Z36+AA36 -> 1145407.6 | AC36: =SUM(AC34:AC35) -> 106698.3 | AD36: =SUM(AD34:AD35) -> 321868.6 | AE36: =SUM(AE34:AE35) -> 654361.52 | AF36: =SUM(AF34:AF35) -> 1252105.9
D37: 6. | E37: Sinter | F37: =+F717 -> 235289 | G37: =+G717 -> 239020 | H37: =+F37+G37 -> 474309 | I37: =+I717 -> 260541 | J37: =+H37+I37 -> 734850 | K37: =+K717 -> 0 | L37: =+J37+K37 -> 734850 | M37: =+M717 -> 335875 | N37: =+L37+M37 -> 1070725 | O37: =+O717 -> 248691 | P37: =+K37+M37+O37 -> 584566 | Q37: =+N37+O37 -> 1319416 | R37: =+R717 -> 276292 | S37: =+Q37+R37 -> 1595708 | T37: =+T717 -> 310927 | U37: =+S37+T37 -> 1906635 | V37: =+V717 -> 366651 | W37: =+R37+T37+V37 -> 953870 | X37: =+U37+V37 -> 2273286 | Y37: =+Y717 -> 347065 | Z37: =+X37+Y37 -> 2620351 | AA37: =+AA717 -> 341012 | AB37: =+Z37+AA37 -> 2961363 | AC37: =+AC717 -> 320002 | AD37: =+Y37+AA37+AC37 -> 1008079 | AE37: =+W37+AD37 -> 1961949 | AF37: =+AB37+AC37 -> 3281365
D38: 7. | E38: Hot Metal
E39: BF #5 | F39: 143766 | G39: 152132 | H39: =+F39+G39 -> 295898 | I39: 167381 | J39: =+H39+I39 -> 463279 | K39: 190559 | L39: =+J39+K39 -> 653838 | M39: 229309 | N39: =+L39+M39 -> 883147 | O39: 166018 | P39: =+K39+M39+O39 -> 585886 | Q39: =+N39+O39 -> 1049165 | R39: 195036 | S39: =+Q39+R39 -> 1244201 | T39: 211077 | U39: =+S39+T39 -> 1455278 | V39: 250305 | W39: =+R39+T39+V39 -> 656418 | X39: =+U39+V39 -> 1705583 | Y39: 240311 | Z39: =+X39+Y39 -> 1945894 | AA39: 234647 | AB39: =+Z39+AA39 -> 2180541 | AC39: 219210 | AD39: =+Y39+AA39+AC39 -> 694168 | AE39: =+W39+AD39 -> 1350586 | AF39: =+AB39+AC39 -> 2399751
E40: Total | F40: =SUM(F39:F39) -> 143766 | G40: =SUM(G39:G39) -> 152132 | H40: =SUM(H39:H39) -> 295898 | I40: =SUM(I39:I39) -> 167381 | J40: =SUM(J39:J39) -> 463279 | K40: =SUM(K39:K39) -> 190559 | L40: =SUM(L39:L39) -> 653838 | M40: =SUM(M39:M39) -> 229309 | ... AF40: =SUM(AF39:AF39) -> 2399751
C41: 26.52498 | D41: 8. | E41: Cold Pig & Pig Equivalent
C42: 15.8304 | E42: BF #5 (Pig ) Net | F42: 3047 | G42: 2899 | H42: =SUM(F42:G42) -> 5946 | I42: 2804 | J42: =+H42+I42 -> 8750 | K42: 8503 | L42: =+J42+K42 -> 17253 | M42: 5056 | N42: =+L42+M42 -> 22309 | O42: =3479+1178 -> 4657 | P42: =+K42+M42+O42 -> 18216 | Q42: =+N42+O42 -> 26966 | R42: 6703 | S42: =+Q42+R42 -> 33669 | T42: 13729 | U42: =+S42+T42 -> 47398 | V42: 12623 | W42: =+R42+T42+V42 -> 33055 | X42: =+U42+V42 -> 60021 | Y42: 8529 | Z42: =+X42+Y42 -> 68550 | AA42: 9429 | AB42: =+Z42+AA42 -> 77979 | AC42: 13226 | AD42: =+Y42+AA42+AC42 -> 31184 | AE42: =+W42+AD42 -> 64239 | AF42: =+AB42+AC42 -> 91205
...

Sheet Maj Prod Summ
B1: MAJOR PRODUCTION SUMMARY | D1: 30 | E1: 30 | F1: 31 | G1: 31 | H1: =+D1+F1 -> 61 | I1: =+E1+G1 -> 61 | J1: 30 | K1: 30 | L1: =+H1+J1 -> 91 | M1: =+I1+K1 -> 91 | N1: 31 | O1: 31 | P1: =+L1+N1 -> 122 | Q1: =+M1+O1 -> 122 | R1: 31 | S1: 31 | T1: =+P1+R1 -> 153 | U1: =+Q1+S1 -> 153 | V1: 30 | W1: 30 | X1: =+N1+R1+V1 -> 92 | Y1: =+O1+S1+W1 -> 92 | Z1: =+T1+V1 -> 183 | AA1: =+U1+W1 -> 183 | AB1: 31 | AC1: 31 | AD1: =+Z1+AB1 -> 214 | AE1: =+AA1+AC1 -> 214 | AF1: 30 | AG1: 30 | AH1: =+AD1+AF1 -> 244 | AI1: =+AE1+AG1 -> 244 | AJ1: 31 | AK1: 31 | AL1: =+AB1+AF1+AJ1 -> 92 | AM1: =+AC1+AG1+AK1 -> 92 | AN1: =+AH1+AJ1 -> 275 | AO1: =+AI1+AK1 -> 275 | AP1: 31 | AQ1: 31 | AR1: =+AN1+AP1 -> 306 | AS1: =+AO1+AQ1 -> 306 | AT1: 28 | AU1: 28 | AV1: =+AR1+AT1 -> 334 | AW1: =+AS1+AU1 -> 334 | AX1: 31 | AY1: 31 | AZ1: =+AP1+AT1+AX1 -> 90 | BA1: =+AQ1+AU1+AY1 -> 90 | BB1: =+AZ1+AL1 -> 182 | BC1: =+BA1+AM1 -> 182 | BD1: =+AV1+AX1 -> 365 | BE1: =+AW1+AY1 -> 365 | BF1: 366 | BG1: 366
D2: 30 | E2: 30 | F2: 31 | G2: 31 | H2: =+D2+F2 -> 61 | I2: =+E2+G2 -> 61 | J2: 30 | K2: 30 | L2: =+H2+J2 -> 91 | M2: =+I2+K2 -> 91 | N2: 31 | O2: 31 | P2: =+L2+N2 -> 122 | Q2: =+M2+O2 -> 122 | R2: 31 | S2: 31 | T2: =+P2+R2 -> 153 | U2: =+Q2+S2 -> 153 | V2: 30 | W2: 30 | X2: =+N2+R2+V2 -> 92 | Y2: =+O2+S2+W2 -> 92 | Z2: =+T2+V2 -> 183 | AA2: =+U2+W2 -> 183 | AB2: 31 | AC2: 31 | AD2: =+Z2+AB2 -> 214 | AE2: =+AA2+AC2 -> 214 | AF2: 30 | AG2: 30 | AH2: =+AD2+AF2 -> 244 | AI2: =+AE2+AG2 -> 244 | AJ2: 31 | AK2: 31 | AL2: =+AB2+AF2+AJ2 -> 92 | AM2: =+AC2+AG2+AK2 -> 92 | AN2: =+AH2+AJ2 -> 275 | AO2: =+AI2+AK2 -> 275 | AP2: 31 | AQ2: 31 | AR2: =+AN2+AP2 -> 306 | AS2: =+AO2+AQ2 -> 306 | AT2: 28 | AU2: 28 | AV2: =+AR2+AT2 -> 334 | AW2: =+AS2+AU2 -> 334 | AX2: 31 | AY2: 31 | AZ2: =+AP2+AT2+AX2 -> 90 | BA2: =+AQ2+AU2+AY2 -> 90 | BB2: =+AZ2+AL2 -> 182 | BC2: =+BA2+AM2 -> 182 | BD2: =+AV2+AX2 -> 365 | BE2: =+AW2+AY2 -> 365 | BF2: 366 | BG2: 366
B3: ITEM | C3: Unit | D3: Apr'20 | F3: May'20 | H3: 2M | J3: Jun'20 | L3: QRT-1 | N3: Jul'20 | P3: 4M | R3: Aug'20 | T3: 5M | V3: Sep'20 | X3: QTR 2 | Z3: H1 | AB3: Oct'20 | AD3: 7M | AF3: Nov'20 | AH3: 8M | AJ3: Dec'20 | AL3: QTR 3 | AN3: 9 M | AP3: Jan'21 | AR3: 10M | AT3: Feb'21 | AV3: 11M | AX3: Mar'21 | AZ3: QTR 4 | BB3: H2 | BD3: 2020-21 | BF3: 2019-20
D4: ABP | E4: ACT | F4: ABP | G4: ACT | H4: ABP | I4: ACT | J4: ABP | K4: ACT | L4: ABP | M4: ACT | N4: ABP | O4: ACT | P4: ABP | Q4: ACT | R4: ABP | S4: ACT | T4: ABP | U4: ACT | V4: ABP | W4: ACT | X4: ABP | Y4: ACT | Z4: ABP | AA4: ACT | AB4: ABP | AC4: ACT | AD4: ABP | AE4: ACT | AF4: ABP | AG4: ACT | AH4: ABP | AI4: ACT | AJ4: ABP | AK4: ACT | AL4: ABP | AM4: ACT | AN4: ABP | AO4: ACT | AP4: ABP | AQ4: ACT | AR4: ABP | AS4: ACT | AT4: ABP | AU4: ACT | AV4: ABP | AW4: ACT | AX4: ABP | AY4: ACT | AZ4: ABP | BA4: ACT | BB4: ABP | BC4: ACT | BD4: ABP | BE4: ACT | BF4: ABP | BG4: ACT
B5: COKE OVENS PUSHING
B6: (COB#10) | C6: Nos/ day | D6: 77.866667 | E6: =+E9/E2 -> 77.866667 | F6: 85.387097 | G6: =+G9/G2 -> 85.387097 | H6: =+((D6*$D$2)+(F6*$F$2))/$H$2 -> 81.688525 | I6: =+((E6*$E$2)+(G6*$G$2))/$I$2 -> 81.688525 | J6: 92.2 | K6: =+K9/K2 -> 92.2 | L6: =+((H6*$H$2)+(J6*$J$2))/$L$2 -> 85.153846 | M6: =+((I6*$I$2)+(K6*$K$2))/$M$2 -> 85.153846 | N6: 99 | O6: =+O9/O2 -> 97.064516 | P6: =+((L6*L$2)+(N6*N$2))/P$2 -> 88.672131 | Q6: =+((M6*M$2)+(O6*O$2))/Q$2 -> 88.180328 | R6: 99 | S6: =+S9/S2 -> 98.935484 | T6: =+((P6*P$2)+(R6*R$2))/T$2 -> 90.764706 | U6: =+((Q6*Q$2)+(S6*S$2))/U$2 -> 90.359477 | V6: 99 | W6: =+W9/W2 -> 97.833333 | X6: =+((N$6*N$1)+(R$6*R$1)+(V$6*V$1))/X$1 -> 99 | Y6: =+((O$6*O$1)+(S$6*S$1)+(W$6*W$1))/Y$1 -> 97.945652 | Z6: =+((T6*T$2)+(V6*V$2))/Z$2 -> 92.114754 | AA6: =+((U6*U$2)+(W6*W$2))/AA$2 -> 91.584699 | AB6: 99 | AC6: =+AC9/AC2 -> 98.677419 | AD6: =+((Z6*Z$2)+(AB6*AB$2))/AD$2 -> 93.11215 | AE6: =+((AA6*AA$2)+(AC6*AC$2))/AE$2 -> 92.61215 | AF6: 99 | AG6: =+AG9/AG2 -> 99.366667 | AH6: =+((AD6*AD$2)+(AF6*AF$2))/AH$2 -> 93.836066 | AI6: =+((AE6*AE$2)+(AG6*AG$2))/AI$2 -> 93.442623 | AJ6: 99 | AK6: =+AK9/AK2 -> 99.129032 | AL6: =+((AB$6*AB$1)+(AF$6*AF$1)+(AJ$6*AJ$1))/AL$1 -> 99 | AM6: =+((AC$6*AC$1)+(AG$6*AG$1)+(AK$6*AK$1))/AM$1 -> 99.054348 | AN6: =+((AH6*AH$2)+(AJ6*AJ$2))/AN$2 -> 94.418182 | AO6: =+((AI6*AI$2)+(AK6*AK$2))/AO$2 -> 94.083636 | AP6: 99 | AQ6: =+AQ9/AQ2 -> 99.129032 | AR6: =+((AN6*AN$2)+(AP6*AP$2))/AR$2 -> 94.882353 | AS6: =+((AO6*AO$2)+(AQ6*AQ$2))/AS$2 -> 94.594771 | AT6: 99 | AU6: =+AU9/AU2 -> 99.142857 | AV6: =+((AR6*AR$2)+(AT6*AT$2))/AV$2 -> 95.227545 | AW6: =+((AS6*AS$2)+(AU6*AU$2))/AW$2 -> 94.976048 | AX6: 99 | AY6: =+AY9/AY2 -> 99.290323 | AZ6: =+((AP$6*AP$1)+(AT$6*AT$1)+(AX$6*AX$1))/AZ$1 -> 99 | BA6: =+((AQ$6*AQ$1)+(AU$6*AU$1)+(AY$6*AY$1))/BA$1 -> 99.188889 | BB6: =+((AL6*AL$2)+(AZ6*AZ$2))/BB$2 -> 99 | BC6: =+((AM6*AM$2)+(BA6*BA$2))/BC$2 -> 99.120879 | BD6: =+((AV6*AV$2)+(AX6*AX$2))/BD$2 -> 95.547945 | BE6: =+((AW6*AW$2)+(AY6*AY$2))/BE$2 -> 95.342466 | BF6: 97 | BG6: 97.10959
B7: (COB#11) | C7: Nos/ day | D7: 77.766667 | E7: =+E10/E2 -> 77.766667 | F7: 75.129032 | G7: =+G10/G2 -> 75.129032 | H7: =+((D7*$D$2)+(F7*$F$2))/$H$2 -> 76.42623 | I7: =+((E7*$E$2)+(G7*$G$2))/$I$2 -> 76.42623 | J7: 86.5 | K7: =+K10/K2 -> 86.5 | L7: =+((H7*$H$2)+(J7*$J$2))/$L$2 -> 79.747253 | M7: =+((I7*$I$2)+(K7*$K$2))/$M$2 -> 79.747253 | N7: 99 | O7: =+O10/O2 -> 90.83871 | P7: =+((L7*L$2)+(N7*N$2))/P$2 -> 84.639344 | Q7: =+((M7*M$2)+(O7*O$2))/Q$2 -> 82.565574 | R7: 99 | S7: =+S10/S2 -> 98.935484 | T7: =+((P7*P$2)+(R7*R$2))/T$2 -> 87.54902 | U7: =+((Q7*Q$2)+(S7*S$2))/U$2 -> 85.882353 | V7: 99 | W7: =+W10/W2 -> 83.6 | X7: =+((N$7*N$1)+(R$7*R$1)+(V$7*V$1))/X$1 -> 99 | Y7: =+((O$7*O$1)+(S$7*S$1)+(W$7*W$1))/Y$1 -> 91.206522 | Z7: =+((T7*T$2)+(V7*V$2))/Z$2 -> 89.42623 | AA7: =+((U7*U$2)+(W7*W$2))/AA$2 -> 85.508197 | AB7: 99 | AC7: =+AC10/AC2 -> 92 | AD7: =+((Z7*Z$2)+(AB7*AB$2))/AD$2 -> 90.813084 | AE7: =+((AA7*AA$2)+(AC7*AC$2))/AE$2 -> 86.448598 | AF7: 99 | AG7: =+AG10/AG2 -> 88.633333 | AH7: =+((AD7*AD$2)+(AF7*AF$2))/AH$2 -> 91.819672 | AI7: =+((AE7*AE$2)+(AG7*AG$2))/AI$2 -> 86.717213 | AJ7: 99 | AK7: =+AK10/AK2 -> 98.83871 | AL7: =+((AB$7*AB$1)+(AF$7*AF$1)+(AJ$7*AJ$1))/AL$1 -> 99 | AM7: =+((AC$7*AC$1)+(AG$7*AG$1)+(AK$7*AK$1))/AM$1 -> 93.206522 | AN7: =+((AH7*AH$2)+(AJ7*AJ$2))/AN$2 -> 92.629091 | AO7: =+((AI7*AI$2)+(AK7*AK$2))/AO$2 -> 88.083636 | AP7: 99 | AQ7: =+AQ10/AQ2 -> 99 | AR7: =+((AN7*AN$2)+(AP7*AP$2))/AR$2 -> 93.27451 | AS7: =+((AO7*AO$2)+(AQ7*AQ$2))/AS$2 -> 89.189542 | AT7: 99 | AU7: =+AU10/AU2 -> 99 | AV7: =+((AR7*AR$2)+(AT7*AT$2))/AV$2 -> 93.754491 | AW7: =+((AS7*AS$2)+(AU7*AU$2))/AW$2 -> 90.011976 | AX7: 99 | AY7: =+AY10/AY2 -> 99.032258 | AZ7: =+((AP$7*AP$1)+(AT$7*AT$1)+(AX$7*AX$1))/AZ$1 -> 99 | BA7: =+((AQ$7*AQ$1)+(AU$7*AU$1)+(AY$7*AY$1))/BA$1 -> 99.011111 | BB7: =+((AL7*AL$2)+(AZ7*AZ$2))/BB$2 -> 99 | BC7: =+((AM7*AM$2)+(BA7*BA$2))/BC$2 -> 96.076923 | BD7: =+((AV7*AV$2)+(AX7*AX$2))/BD$2 -> 94.2 | BE7: =+((AW7*AW$2)+(AY7*AY$2))/BE$2 -> 90.778082 | BF7: 97 | BG7: 95.710246
B8: Overall Equiv. Ovens Pushed/ Day | C8: Nos/ day | D8: =D6+(D7*1.8343023255814) -> 220.51424 | E8: =E6+(E7*1.8343023255814) -> 220.51424 | F8: =F6+(F7*1.8343023255814) -> 223.19646 | G8: =G6+(G7*1.8343023255814) -> 223.19646 | H8: =H6+(H7*1.8343023255814) -> 221.87734 | I8: =I6+(I7*1.8343023255814) -> 221.87734 | J8: =J6+(J7*1.8343023255814) -> 250.86715 | K8: =K6+(K7*1.8343023255814) -> 250.86715 | ... BE8: =BE6+(BE7*1.8343023255814) -> 261.85691 | BF8: 274.92733 | BG8: 272.67112
B9: (COB#10) | C9: Nos | D9: =+D6*D2 -> 2336 | E9: 2336 | F9: =+F6*F2 -> 2647 | G9: 2647 | H9: =+H6*H2 -> 4983 | I9: =+E9+G9 -> 4983 | J9: =+J6*J2 -> 2766 | K9: 2766 | L9: =+H9+J9 -> 7749 | M9: =+I9+K9 -> 7749 | N9: =+N6*N2 -> 3069 | O9: 3009 | P9: =+L9+N9 -> 10818 | Q9: =+M9+O9 -> 10758 | R9: =+R6*R2 -> 3069 | S9: 3067 | T9: =+P9+R9 -> 13887 | U9: =+Q9+S9 -> 13825 | V9: =+V6*V2 -> 2970 | W9: 2935 | X9: =+N9+R9+V9 -> 9108 | Y9: =+O9+S9+W9 -> 9011 | Z9: =+T9+V9 -> 16857 | AA9: =+U9+W9 -> 16760 | AB9: =+AB6*AB2 -> 3069 | AC9: 3059 | AD9: =+Z9+AB9 -> 19926 | AE9: =+AA9+AC9 -> 19819 | AF9: =+AF6*AF2 -> 2970 | AG9: 2981 | AH9: =+AD9+AF9 -> 22896 | AI9: =+AE9+AG9 -> 22800 | AJ9: =+AJ6*AJ2 -> 3069 | AK9: 3073 | AL9: =+AB9+AF9+AJ9 -> 9108 | AM9: =+AC9+AG9+AK9 -> 9113 | AN9: =+AH9+AJ9 -> 25965 | AO9: =+AI9+AK9 -> 25873 | AP9: =+AP6*AP2 -> 3069 | AQ9: 3073 | AR9: =+AN9+AP9 -> 29034 | AS9: =+AO9+AQ9 -> 28946 | AT9: =+AT6*AT2 -> 2772 | AU9: 2776 | AV9: =+AR9+AT9 -> 31806 | AW9: =+AS9+AU9 -> 31722 | AX9: =+AX6*AX2 -> 3069 | AY9: 3078 | AZ9: =+AP9+AT9+AX9 -> 8910 | BA9: =+AQ9+AU9+AY9 -> 8927 | BB9: =+AL9+AZ9 -> 18018 | BC9: =+AM9+BA9 -> 18040 | BD9: =+AV9+AX9 -> 34875 | BE9: =+AW9+AY9 -> 34800 | BF9: 35502 | BG9: 35543
B10: (COB#11) | C10: Nos | D10: =+D7*D2 -> 2333 | E10: 2333 | F10: =+F7*F2 -> 2329 | G10: 2329 | H10: =+H7*H2 -> 4662 | I10: =+E10+G10 -> 4662 | J10: =+J7*J2 -> 2595 | K10: 2595 | L10: =+H10+J10 -> 7257 | M10: =+I10+K10 -> 7257 | N10: =+N7*N2 -> 3069 | O10: 2816 | P10: =+L10+N10 -> 10326 | Q10: =+M10+O10 -> 10073 | R10: =+R7*R2 -> 3069 | S10: 3067 | T10: =+P10+R10 -> 13395 | U10: =+Q10+S10 -> 13140 | V10: =+V7*V2 -> 2970 | W10: 2508 | X10: =+N10+R10+V10 -> 9108 | Y10: =+O10+S10+W10 -> 8391 | Z10: =+T10+V10 -> 16365 | AA10: =+U10+W10 -> 15648 | AB10: =+AB7*AB2 -> 3069 | AC10: 2852 | AD10: =+Z10+AB10 -> 19434 | AE10: =+AA10+AC10 -> 18500 | AF10: =+AF7*AF2 -> 2970 | AG10: 2659 | AH10: =+AD10+AF10 -> 22404 | AI10: =+AE10+AG10 -> 21159 | AJ10: =+AJ7*AJ2 -> 3069 | AK10: 3064 | AL10: =+AB10+AF10+AJ10 -> 9108 | AM10: =+AC10+AG10+AK10 -> 8575 | AN10: =+AH10+AJ10 -> 25473 | AO10: =+AI10+AK10 -> 24223 | AP10: =+AP7*AP2 -> 3069 | AQ10: =2871+198 -> 3069 | AR10: =+AN10+AP10 -> 28542 | AS10: =+AO10+AQ10 -> 27292 | AT10: =+AT7*AT2 -> 2772 | AU10: 2772 | AV10: =+AR10+AT10 -> 31314 | AW10: =+AS10+AU10 -> 30064 | AX10: =+AX7*AX2 -> 3069 | AY10: 3070 | AZ10: =+AP10+AT10+AX10 -> 8910 | BA10: =+AQ10+AU10+AY10 -> 8911 | BB10: =+AL10+AZ10 -> 18018 | BC10: =+AM10+BA10 -> 17486 | BD10: =+AV10+AX10 -> 34383 | BE10: =+AW10+AY10 -> 33134 | BF10: 35502 | BG10: 35030
B11: Overall Equiv. Ovens Pushed | C11: Nos | D11: =D9+(D10*1.8343023255814) -> 6615.4273 | E11: =E9+(E10*1.8343023255814) -> 6615.4273 | F11: =F9+(F10*1.8343023255814) -> 6919.0901 | G11: =G9+(G10*1.8343023255814) -> 6919.0901 | H11: =H9+(H10*1.8343023255814) -> 13534.517 | I11: =I9+(I10*1.8343023255814) -> 13534.517 | J11: =J9+(J10*1.8343023255814) -> 7526.0145 | K11: =K9+(K10*1.8343023255814) -> 7526.0145 | ... BA11: =BA9+(BA10*1.8343023255814) -> 25272.468 | BD11: =BD9+(BD10*1.8343023255814) -> 97943.817 | BE11: =BE9+(BE10*1.8343023255814) -> 95577.773 | BF11: 100623.4 | BG11: 99798.61
B12: BF COKE
B13: COB#10 | C13: Mt | D13: 28527 | E13: 27936.6 | F13: 31935 | G13: 31876 | H13: =+D13+F13 -> 60462 | I13: =+E13+G13 -> 59812.6 | J13: 33778 | K13: 33669.6 | L13: =+H13+J13 -> 94240 | M13: =+I13+K13 -> 93482.2 | N13: 37479 | O13: 36675 | P13: =+L13+N13 -> 131719 | Q13: =+M13+O13 -> 130157.2 | R13: 37479 | S13: 37836 | T13: =+P13+R13 -> 169198 | U13: =+Q13+S13 -> 167993.2 | V13: 36270 | W13: 36979 | X13: =+N13+R13+V13 -> 111228 | Y13: =+O13+S13+W13 -> 111490 | Z13: =+T13+V13 -> 205468 | AA13: =+U13+W13 -> 204972.2 | AB13: 37479 | AC13: 38591 | AD13: =+Z13+AB13 -> 242947 | AE13: =+AA13+AC13 -> 243563.2 | AF13: 36270 | AG13: 37324 | AH13: =+AD13+AF13 -> 279217 | AI13: =+AE13+AG13 -> 280887.2 | AJ13: 37479 | AK13: 38071 | AL13: =+AB13+AF13+AJ13 -> 111228 | AM13: =+AC13+AG13+AK13 -> 113986 | AN13: =+AH13+AJ13 -> 316696 | AO13: =+AI13+AK13 -> 318958.2 | AP13: 37479 | AQ13: 38030 | AR13: =+AN13+AP13 -> 354175 | AS13: =+AO13+AQ13 -> 356988.2 | AT13: 33852 | AU13: 34628 | AV13: =+AR13+AT13 -> 388027 | AW13: =+AS13+AU13 -> 391616.2 | AX13: 37479 | AY13: 39306 | AZ13: =+AP13+AT13+AX13 -> 108810 | BA13: =+AQ13+AU13+AY13 -> 111964 | BB13: =+AL13+AZ13 -> 220038 | BC13: =+AM13+BA13 -> 225950 | BD13: =+AV13+AX13 -> 425506 | BE13: =+AW13+AY13 -> 430922.2 | BF13: 406071.88 | BG13: 412610.14
B14: COB#11 | C14: Mt | D14: 52260 | E14: 51175.3 | F14: 52180 | G14: 51446 | H14: =+D14+F14 -> 104440 | I14: =+E14+G14 -> 102621.3 | J14: 58129 | K14: 57942.1 | L14: =+H14+J14 -> 162569 | M14: =+I14+K14 -> 160563.4 | N14: 68747 | O14: 62959 | P14: =+L14+N14 -> 231316 | Q14: =+M14+O14 -> 223522.4 | R14: 68747 | S14: 69404 | T14: =+P14+R14 -> 300063 | U14: =+Q14+S14 -> 292926.4 | V14: 66529 | W14: 57963 | X14: =+N14+R14+V14 -> 204023 | Y14: =+O14+S14+W14 -> 190326 | Z14: =+T14+V14 -> 366592 | AA14: =+U14+W14 -> 350889.4 | AB14: 68747 | AC14: 65998 | AD14: =+Z14+AB14 -> 435339 | AE14: =+AA14+AC14 -> 416887.4 | AF14: 66529 | AG14: 61068 | AH14: =+AD14+AF14 -> 501868 | AI14: =+AE14+AG14 -> 477955.4 | AJ14: 68747 | AK14: 69629 | AL14: =+AB14+AF14+AJ14 -> 204023 | AM14: =+AC14+AG14+AK14 -> 196695 | AN14: =+AH14+AJ14 -> 570615 | AO14: =+AI14+AK14 -> 547584.4 | AP14: 68747 | AQ14: 69668 | AR14: =+AN14+AP14 -> 639362 | AS14: =+AO14+AQ14 -> 617252.4 | AT14: 62094 | AU14: 63427 | AV14: =+AR14+AT14 -> 701456 | AW14: =+AS14+AU14 -> 680679.4 | AX14: 68747 | AY14: 71912 | AZ14: =+AP14+AT14+AX14 -> 199588 | BA14: =+AQ14+AU14+AY14 -> 205007 | BB14: =+AL14+AZ14 -> 403611 | BC14: =+AM14+BA14 -> 401702 | BD14: =+AV14+AX14 -> 770203 | BE14: =+AW14+AY14 -> 752591.4 | BF14: 744858.59 | BG14: 745859.84
B15: TOTAL | C15: Mt | D15: =SUM(D13:D14) -> 80787 | E15: =SUM(E13:E14) -> 79111.9 | F15: =SUM(F13:F14) -> 84115 | G15: =SUM(G13:G14) -> 83322 | H15: =SUM(H13:H14) -> 164902 | I15: =SUM(I13:I14) -> 162433.9 | J15: =SUM(J13:J14) -> 91907 | K15: =SUM(K13:K14) -> 91611.7 | ... BA15: =SUM(BA13:BA14) -> 316971 | BD15: =SUM(BD13:BD14) -> 1195709 | BE15: =SUM(BE13:BE14) -> 1183513.6 | BF15: 1150930.5 | BG15: 1158470
B16: SINTER | C16: Mt | D16: 235289 | E16: 235289 | F16: 239020 | G16: 239020 | H16: =+D16+F16 -> 474309 | I16: =+E16+G16 -> 474309 | J16: 261844 | K16: 260541 | L16: =+H16+J16 -> 736153 | M16: =+I16+K16 -> 734850 | N16: 348705.09 | O16: 297604 | P16: =+L16+N16 -> 1084858.1 | Q16: =+M16+O16 -> 1032454 | R16: 346672.77 | S16: 287210 | T16: =+P16+R16 -> 1431530.9 | U16: =+Q16+S16 -> 1319664 | V16: 342110.41 | W16: 217308 | X16: =+N16+R16+V16 -> 1037488.3 | Y16: =+O16+S16+W16 -> 802122 | Z16: =+T16+V16 -> 1773641.3 | AA16: =+U16+W16 -> 1536972 | AB16: 181250 | AC16: 294485 | AD16: =+Z16+AB16 -> 1954891.3 | AE16: =+AA16+AC16 -> 1831457 | AF16: =336.4*1000 -> 336400 | AG16: 320285 | AH16: =+AD16+AF16 -> 2291291.3 | AI16: =+AE16+AG16 -> 2151742 | AJ16: =353.8*1000 -> 353800 | AK16: 354168 | AL16: =+AB16+AF16+AJ16 -> 871450 | AM16: =+AC16+AG16+AK16 -> 968938 | AN16: =+AH16+AJ16 -> 2645091.3 | AO16: =+AI16+AK16 -> 2505910 | AP16: 348000 | AQ16: 377726 | AR16: =+AN16+AP16 -> 2993091.3 | AS16: =+AO16+AQ16 -> 2883636 | AT16: 319000 | AU16: =+SINTER!AU54 -> 345006 | AV16: =+AR16+AT16 -> 3312091.3 | AW16: =+AS16+AU16 -> 3228642 | AX16: 353800 | AY16: =+SINTER!AY54 -> 400935 | AZ16: =+AP16+AT16+AX16 -> 1020800 | BA16: =+AQ16+AU16+AY16 -> 1123667 | BB16: =+AL16+AZ16 -> 1892250 | BC16: =+AM16+BA16 -> 2092605 | BD16: =+AV16+AX16 -> 3665891.3 | BE16: =+AW16+AY16 -> 3629577 | BF16: 3903932.5 | BG16: 3709525 | BH16: 1008079 | BI16: =+AO16+BH16 -> 3513989 | BJ16: =+BI16/1000000 -> 3.513989
B17: HOT METAL | C17: Mt | D17: 143766 | E17: 143766 | F17: 152132 | G17: 152132 | H17: =+D17+F17 -> 295898 | I17: =+E17+G17 -> 295898 | J17: 180265 | K17: 167381 | L17: =+H17+J17 -> 476163 | M17: =+I17+K17 -> 463279 | N17: 240486.27 | O17: 190559 | P17: =+L17+N17 -> 716649.27 | Q17: =+M17+O17 -> 653838 | R17: 239084.67 | S17: 195518 | T17: =+P17+R17 -> 955733.94 | U17: =+Q17+S17 -> 849356 | V17: 235938.22 | W17: 107327 | X17: =+N17+R17+V17 -> 715509.15 | Y17: =+O17+S17+W17 -> 493404 | Z17: =+T17+V17 -> 1191672.2 | AA17: =+U17+W17 -> 956683 | AB17: 125000 | AC17: 125039 | AD17: =+Z17+AB17 -> 1316672.2 | AE17: =+AA17+AC17 -> 1081722 | AF17: =232*1000 -> 232000 | AG17: 154255 | AH17: =+AD17+AF17 -> 1548672.2 | AI17: =+AE17+AG17 -> 1235977 | AJ17: =244*1000 -> 244000 | AK17: 198815 | AL17: =+AB17+AF17+AJ17 -> 601000 | AM17: =+AC17+AG17+AK17 -> 478109 | AN17: =+AH17+AJ17 -> 1792672.2 | AO17: =+AI17+AK17 -> 1434792 | AP17: 240000 | AQ17: 221321 | AR17: =+AN17+AP17 -> 2032672.2 | AS17: =+AO17+AQ17 -> 1656113 | AT17: 220000 | AU17: 198514 | AV17: =+AR17+AT17 -> 2252672.2 | AW17: =+AS17+AU17 -> 1854627 | AX17: 244000 | AY17: 238171 | AZ17: =+AP17+AT17+AX17 -> 704000 | BA17: =+AQ17+AU17+AY17 -> 658006 | BB17: =+AL17+AZ17 -> 1305000 | BC17: =+AM17+BA17 -> 1136115 | BD17: =+AV17+AX17 -> 2496672.2 | BE17: =+AW17+AY17 -> 2092798 | BF17: 2700000 | BG17: 2505193 | BH17: 694168 | BI17: =+AO17+BH17 -> 2128960 | BJ17: =+BI17/1000000 -> 2.12896
B18: CRUDE STEEL | C18: Mt | D18: 129292 | E18: 129292 | F18: 134303 | G18: 134303 | H18: =+D18+F18 -> 263595 | I18: =+E18+G18 -> 263595 | J18: 161947 | K18: 147382 | L18: =+H18+J18 -> 425542 | M18: =+I18+K18 -> 410977 | N18: 221247 | O18: 160929 | P18: =+L18+N18 -> 646789 | Q18: =+M18+O18 -> 571906 | R18: 219958 | S18: 172012 | T18: =+P18+R18 -> 866747 | U18: =+Q18+S18 -> 743918 | V18: 217063 | W18: 83590 | X18: =+N18+R18+V18 -> 658268 | Y18: =+O18+S18+W18 -> 416531 | Z18: =+T18+V18 -> 1083810 | AA18: =+U18+W18 -> 827508 | AB18: 114155 | AC18: 98775 | AD18: =+Z18+AB18 -> 1197965 | AE18: =+AA18+AC18 -> 926283 | AF18: =215.955*1000 -> 215955 | AG18: 139620 | AH18: =+AD18+AF18 -> 1413920 | AI18: =+AE18+AG18 -> 1065903 | AJ18: =226.59*1000 -> 226590 | AK18: 167995 | AL18: =+AB18+AF18+AJ18 -> 556700 | AM18: =+AC18+AG18+AK18 -> 406390 | AN18: =+AH18+AJ18 -> 1640510 | AO18: =+AI18+AK18 -> 1233898 | AP18: 222957.5 | AQ18: 201367 | AR18: =+AN18+AP18 -> 1863467.5 | AS18: =+AO18+AQ18 -> 1435265 | AT18: 206078 | AU18: 189148 | AV18: =+AR18+AT18 -> 2069545.5 | AW18: =+AS18+AU18 -> 1624413 | AX18: 227618 | AY18: 223020 | AZ18: =+AP18+AT18+AX18 -> 656653.5 | BA18: =+AQ18+AU18+AY18 -> 613535 | BB18: =+AL18+AZ18 -> 1213353.5 | BC18: =+AM18+BA18 -> 1019925 | BD18: =+AV18+AX18 -> 2297163.5 | BE18: =+AW18+AY18 -> 1847433 | BF18: 2500000 | BG18: 2083412 | BH18: 589289 | BI18: =+AO18+BH18 -> 1823187 | BJ18: =+BI18/1000000 -> 1.823187
B19: Avg Heats Cast per Day | C19: Nos. / day | D19: =+D138/D1 -> 28.566667 | E19: =+E138/E1 -> 28.566667 | F19: =+F138/F1 -> 28.612903 | G19: =+G138/G1 -> 28.612903 | H19: =+H138/H1 -> 28.590164 | I19: =+I138/I1 -> 28.590164 | J19: =+J138/J1 -> 35.988222 | K19: =+K138/K1 -> 32.266667 | ... BE19: =+BE138/BE1 -> 33.309589 | BF19: 47.014645 | BG19: 38.663934
B20: Cold Pig & Pig Equivalent
A21: =+#REF!+#REF! -> #REF! | B21: MOG | C21: Mt | D21: 3047 | E21: 3047 | F21: 2899 | G21: 2899 | H21: =+D21+F21 -> 5946 | I21: =+E21+G21 -> 5946 | J21: 3951.4399 | K21: 2804 | L21: =+H21+J21 -> 9897.4399 | M21: =+I21+K21 -> 8750 | N21: 0.3735936 | O21: 8503 | P21: =+L21+N21 -> 9897.8135 | Q21: =+M21+O21 -> 17253 | R21: 0 | S21: 4172 | T21: =+P21+R21 -> 9897.8135 | U21: =+Q21+S21 -> 21425 | V21: 0 | W21: 7042 | X21: =+N21+R21+V21 -> 0.3735936 | Y21: =+O21+S21+W21 -> 19717 | Z21: =+T21+V21 -> 9897.8135 | AA21: =+U21+W21 -> 28467 | AB21: 2130.1605 | AC21: 9461 | AD21: =+Z21+AB21 -> 12027.974 | AE21: =+AA21+AC21 -> 37928 | AF21: 1873.1932 | AG21: 4903 | AH21: =+AD21+AF21 -> 13901.167 | AI21: =+AE21+AG21 -> 42831 | AJ21: 2501.7113 | AK21: 7314 | AL21: =+AB21+AF21+AJ21 -> 6505.0651 | AM21: =+AC21+AG21+AK21 -> 21678 | AN21: =+AH21+AJ21 -> 16402.879 | AO21: =+AI21+AK21 -> 50145 | AP21: 2379.1399 | AQ21: 4628 | AR21: =+AN21+AP21 -> 18782.018 | AS21: =+AO21+AQ21 -> 54773 | AT21: 492 | AU21: 643.3 | AV21: =+AR21+AT21 -> 19274.018 | AW21: =+AS21+AU21 -> 55416.3 | AX21: 1481 | AY21: 2804.4 | AZ21: =+AP21+AT21+AX21 -> 4352.1399 | BA21: =+AQ21+AU21+AY21 -> 8075.7 | BB21: =+AL21+AZ21 -> 10857.205 | BC21: =+AM21+BA21 -> 29753.7 | BD21: =+AV21+AX21 -> 20755.018 | BE21: =+AW21+AY21 -> 58220.7 | BF21: 29957.856 | BG21: 134629.18
A22: =+#REF!+#REF! -> #REF! | B22: UPIS | C22: Mt | D22: 201 | E22: 201 | F22: 191 | G22: 191 | H22: =+D22+F22 -> 392 | I22: =+E22+G22 -> 392 | J22: 0 | K22: 185 | L22: =+H22+J22 -> 392 | M22: =+I22+K22 -> 577 | N22: 0 | O22: 561 | P22: =+L22+N22 -> 392 | Q22: =+M22+O22 -> 1138 | R22: 0 | S22: 275 | T22: =+P22+R22 -> 392 | U22: =+Q22+S22 -> 1413 | V22: 0 | W22: 464 | X22: =+N22+R22+V22 -> 0 | Y22: =+O22+S22+W22 -> 1300 | Z22: =+T22+V22 -> 392 | AA22: =+U22+W22 -> 1877 | AB22: 0 | AC22: 638 | AD22: =+Z22+AB22 -> 392 | AE22: =+AA22+AC22 -> 2515 | AF22: 0 | AG22: 323 | AH22: =+AD22+AF22 -> 392 | AI22: =+AE22+AG22 -> 2838 | AJ22: 0 | AK22: 482 | AL22: =+AB22+AF22+AJ22 -> 0 | AM22: =+AC22+AG22+AK22 -> 1443 | AN22: =+AH22+AJ22 -> 392 | AO22: =+AI22+AK22 -> 3320 | AP22: 0 | AQ22: 305 | AR22: =+AN22+AP22 -> 392 | AS22: =+AO22+AQ22 -> 3625 | AT22: 0 | AU22: 42.4 | AV22: =+AR22+AT22 -> 392 | AW22: =+AS22+AU22 -> 3667.4 | AX22: 0 | AY22: 184.9 | AZ22: =+AP22+AT22+AX22 -> 0 | BA22: =+AQ22+AU22+AY22 -> 532.3 | BB22: =+AL22+AZ22 -> 0 | BC22: =+AM22+BA22 -> 1975.3 | BD22: =+AV22+AX22 -> 392 | BE22: =+AW22+AY22 -> 3852.3 | BF22: 1419.0563 | BG22: 8272.9783
B23: (Equiv. Pig Iron @ 80% of HM sent to Sand Pit. (Ref to Fax Msg from ED (O), vide SAIL/OPRNS/ PPMS/33 dt. 05.02.15) | C23: Mt | D23: 0 | E23: =0.8*0 -> 0 | F23: 0 | G23: =0.8*0 -> 0 | H23: =+D23+F23 -> 0 | I23: =+E23+G23 -> 0 | J23: 0 | K23: 0 | L23: =+H23+J23 -> 0 | M23: =+I23+K23 -> 0 | N23: 0 | O23: =0.8*0 -> 0 | P23: =+L23+N23 -> 0 | Q23: =+M23+O23 -> 0 | R23: 0 | S23: 0 | T23: =+P23+R23 -> 0 | U23: =+Q23+S23 -> 0 | V23: 0 | W23: 0 | X23: =+N23+R23+V23 -> 0 | Y23: =+O23+S23+W23 -> 0 | Z23: =+T23+V23 -> 0 | AA23: =+U23+W23 -> 0 | AB23: 0 | AC23: 0 | AD23: =+Z23+AB23 -> 0 | AE23: =+AA23+AC23 -> 0 | AF23: 0 | AG23: 0 | AH23: =+AD23+AF23 -> 0 | AI23: =+AE23+AG23 -> 0 | AJ23: 0 | AK23: 0 | AL23: =+AB23+AF23+AJ23 -> 0 | AM23: =+AC23+AG23+AK23 -> 0 | AN23: =+AH23+AJ23 -> 0 | AO23: =+AI23+AK23 -> 0 | AP23: 0 | AQ23: 0 | AR23: =+AN23+AP23 -> 0 | AS23: =+AO23+AQ23 -> 0 | AT23: 0 | AU23: 0 | AV23: =+AR23+AT23 -> 0 | AW23: =+AS23+AU23 -> 0 | AX23: 0 | AY23: 0 | AZ23: =+AP23+AT23+AX23 -> 0 | BA23: =+AQ23+AU23+AY23 -> 0 | BB23: =+AL23+AZ23 -> 0 | BC23: =+AM23+BA23 -> 0 | BD23: =+AV23+AX23 -> 0 | BE23: =+AW23+AY23 -> 0 | BF23: 0 | BG23: 26220.8
B24: TOTAL EQUIVALENT PIG IRON | C24: Mt | D24: =SUM(D21:D23) -> 3248 | E24: =SUM(E21:E23) -> 3248 | F24: =SUM(F21:F23) -> 3090 | G24: =SUM(G21:G23) -> 3090 | H24: =SUM(H21:H23) -> 6338 | I24: =SUM(I21:I23) -> 6338 | J24: =SUM(J21:J23) -> 3951.4399 | K24: =SUM(K21:K23) -> 2989 | ... BA24: =SUM(BA21:BA23) -> 8608 | BB24: =+AL24+AZ24 -> 10857.205 | BC24: =+AM24+BA24 -> 31729 | BD24: =SUM(BD21:BD23) -> 21147.018 | BE24: =SUM(BE21:BE23) -> 62073 | BF24: 31376.912 | BG24: 169122.96
B25: Net PCI Production | C25: Mt | D25: 1693 | E25: 1693 | F25: 4190 | G25: 4190 | H25: =+D25+F25 -> 5883 | I25: =+E25+G25 -> 5883 | J25: 807.0194 | K25: 4452 | L25: =+H25+J25 -> 6690.0194 | M25: =+I25+K25 -> 10335 | N25: 416.569 | O25: 2813 | P25: =+L25+N25 -> 7106.5884 | Q25: =+M25+O25 -> 13148 | R25: 414.19888 | S25: 2290 | T25: =+P25+R25 -> 7520.7873 | U25: =+Q25+S25 -> 15438 | V25: 408.66504 | W25: 1311 | X25: =+N25+R25+V25 -> 1239.4329 | Y25: =+O25+S25+W25 -> 6414 | Z25: =+T25+V25 -> 7929.4523 | AA25: =+U25+W25 -> 16749 | AB25: 484.30665 | AC25: 3244 | AD25: =+Z25+AB25 -> 8413.759 | AE25: =+AA25+AC25 -> 19993 | AF25: 640.09373 | AG25: 1716 | AH25: =+AD25+AF25 -> 9053.8527 | AI25: =+AE25+AG25 -> 21709 | AJ25: 739.76354 | AK25: 2856 | AL25: =+AB25+AF25+AJ25 -> 1864.1639 | AM25: =+AC25+AG25+AK25 -> 7816 | AN25: =+AH25+AJ25 -> 9793.6162 | AO25: =+AI25+AK25 -> 24565 | AP25: 717.42475 | AQ25: 4003 | AR25: =+AN25+AP25 -> 10511.041 | AS25: =+AO25+AQ25 -> 28568 | AT25: 446 | AU25: 5717.9 | AV25: =+AR25+AT25 -> 10957.041 | AW25: =+AS25+AU25 -> 34285.9 | AX25: 611.9487 | AY25: 6808 | AZ25: =+AP25+AT25+AX25 -> 1775.3734 | BA25: =+AQ25+AU25+AY25 -> 16528.9 | BB25: =+AL25+AZ25 -> 3639.5374 | BC25: =+AM25+BA25 -> 24344.9 | BD25: =+AV25+AX25 -> 11568.99 | BE25: =+AW25+AY25 -> 41093.9 | BF25: 0 | BG25: 44255.19
B26: Net Granulated Slag Production | C26: Mt | D26: 55719 | E26: 55719 | F26: 52052 | G26: 52052 | H26: =+D26+F26 -> 107771 | I26: =+E26+G26 -> 107771 | J26: 67868.386 | K26: 61691 | L26: =+H26+J26 -> 175639.39 | M26: =+I26+K26 -> 169462 | N26: 84144.296 | O26: 63617 | P26: =+L26+N26 -> 259783.68 | Q26: =+M26+O26 -> 233079 | R26: 83653.886 | S26: 75389 | T26: =+P26+R26 -> 343437.57 | U26: =+Q26+S26 -> 308468 | V26: 82552.967 | W26: 40763 | X26: =+N26+R26+V26 -> 250351.15 | Y26: =+O26+S26+W26 -> 179769 | Z26: =+T26+V26 -> 425990.53 | AA26: =+U26+W26 -> 349231 | AB26: 43736.538 | AC26: 47916 | AD26: =+Z26+AB26 -> 469727.07 | AE26: =+AA26+AC26 -> 397147 | AF26: 81175.015 | AG26: 57141 | AH26: =+AD26+AF26 -> 550902.09 | AI26: =+AE26+AG26 -> 454288 | AJ26: 85373.723 | AK26: 68072 | AL26: =+AB26+AF26+AJ26 -> 210285.28 | AM26: =+AC26+AG26+AK26 -> 173129 | AN26: =+AH26+AJ26 -> 636275.81 | AO26: =+AI26+AK26 -> 522360 | AP26: 83974.154 | AQ26: 81284 | AR26: =+AN26+AP26 -> 720249.97 | AS26: =+AO26+AQ26 -> 603644 | AT26: 76976 | AU26: 80505 | AV26: =+AR26+AT26 -> 797225.97 | AW26: =+AS26+AU26 -> 684149 | AX26: 85374 | AY26: 92550 | AZ26: =+AP26+AT26+AX26 -> 246324.15 | BA26: =+AQ26+AU26+AY26 -> 254339 | BB26: =+AL26+AZ26 -> 456609.43 | BC26: =+AM26+BA26 -> 427468 | BD26: =+AV26+AX26 -> 882599.97 | BE26: =+AW26+AY26 -> 776699 | BF26: 854658 | BG26: 809638.21
B27: Saleable Steel Production (Mill Wise)
B28: WR Mill | C28: Mt | D28: 14366.4 | E28: 14366.4 | F28: 17668 | G28: 17668 | H28: =+D28+F28 -> 32034.4 | I28: =+E28+G28 -> 32034.4 | J28: 35910 | K28: 31338.144 | L28: =+H28+J28 -> 67944.4 | M28: =+I28+K28 -> 63372.544 | N28: 35000 | O28: 32647.336 | P28: =+L28+N28 -> 102944.4 | Q28: =+M28+O28 -> 96019.88 | R28: 35000 | S28: 34032.42 | T28: =+P28+R28 -> 137944.4 | U28: =+Q28+S28 -> 130052.3 | V28: 32000 | W28: 27037.868 | X28: =+N28+R28+V28 -> 102000 | Y28: =+O28+S28+W28 -> 93717.624 | Z28: =+T28+V28 -> 169944.4 | AA28: =+U28+W28 -> 157090.17 | AB28: 40000 | AC28: 26925.816 | AD28: =+Z28+AB28 -> 209944.4 | AE28: =+AA28+AC28 -> 184015.98 | AF28: 45249.811 | AG28: 32756.97 | AH28: =+AD28+AF28 -> 255194.21 | AI28: =+AE28+AG28 -> 216772.95 | AJ28: 46294.038 | AK28: 34721.176 | AL28: =+AB28+AF28+AJ28 -> 131543.85 | AM28: =+AC28+AG28+AK28 -> 94403.962 | AN28: =+AH28+AJ28 -> 301488.25 | AO28: =+AI28+AK28 -> 251494.13 | AP28: 46294.038 | AQ28: 36021.128 | AR28: =+AN28+AP28 -> 347782.29 | AS28: =+AO28+AQ28 -> 287515.26 | AT28: 41769 | AU28: 31000.4 | AV28: =+AR28+AT28 -> 389551.29 | AW28: =+AS28+AU28 -> 318515.66 | AX28: 46414.675 | AY28: 38003 | AZ28: =+AP28+AT28+AX28 -> 134477.71 | BA28: =+AQ28+AU28+AY28 -> 105024.53 | BB28: =+AL28+AZ28 -> 266021.56 | BC28: =+AM28+BA28 -> 199428.49 | BD28: =+AV28+AX28 -> 435965.96 | BE28: =+AW28+AY28 -> 356518.66 | BF28: 500000 | BG28: 412025.22 | BH28: 106766.46 | BI28: =+AO28+BH28 -> 358260.59 | BJ28: =+BI28/1000000 -> 0.35826059
B29: Bar Mill | C29: Mt | D29: 8073.14 | E29: 8073.14 | F29: 43712 | G29: 43712 | H29: =+D29+F29 -> 51785.14 | I29: =+E29+G29 -> 51785.14 | J29: 41998 | K29: 32149.445 | L29: =+H29+J29 -> 93783.14 | M29: =+I29+K29 -> 83934.585 | N29: 59600 | O29: 24173.96 | P29: =+L29+N29 -> 153383.14 | Q29: =+M29+O29 -> 108108.54 | R29: 55000 | S29: 30791.565 | T29: =+P29+R29 -> 208383.14 | U29: =+Q29+S29 -> 138900.11 | V29: 58000 | W29: 31774.47 | X29: =+N29+R29+V29 -> 172600 | Y29: =+O29+S29+W29 -> 86739.995 | Z29: =+T29+V29 -> 266383.14 | AA29: =+U29+W29 -> 170674.58 | AB29: 50000 | AC29: 29425.245 | AD29: =+Z29+AB29 -> 316383.14 | AE29: =+AA29+AC29 -> 200099.82 | AF29: 72144 | AG29: 39377.085 | AH29: =+AD29+AF29 -> 388527.14 | AI29: =+AE29+AG29 -> 239476.91 | AJ29: 72945.6 | AK29: 55325.43 | AL29: =+AB29+AF29+AJ29 -> 195089.6 | AM29: =+AC29+AG29+AK29 -> 124127.76 | AN29: =+AH29+AJ29 -> 461472.74 | AO29: =+AI29+AK29 -> 294802.34 | AP29: 73480 | AQ29: 46008.41 | AR29: =+AN29+AP29 -> 534952.74 | AS29: =+AO29+AQ29 -> 340810.75 | AT29: 66800 | AU29: 48785.52 | AV29: =+AR29+AT29 -> 601752.74 | AW29: =+AS29+AU29 -> 389596.27 | AX29: 73122.4 | AY29: 50951 | AZ29: =+AP29+AT29+AX29 -> 213402.4 | BA29: =+AQ29+AU29+AY29 -> 145744.93 | BB29: =+AL29+AZ29 -> 408492 | BC29: =+AM29+BA29 -> 269872.69 | BD29: =+AV29+AX29 -> 674875.14 | BE29: =+AW29+AY29 -> 440547.27 | BF29: 800000 | BG29: 632220.18 | BH29: 164556.92 | BI29: =+AO29+BH29 -> 459359.26 | BJ29: =+BI29/1000000 -> 0.45935926
B30: US Mill | C30: Mt | D30: 0 | E30: 0 | F30: 0 | G30: 0 | H30: =+D30+F30 -> 0 | I30: =+E30+G30 -> 0 | J30: 0 | K30: 0 | L30: =+H30+J30 -> 0 | M30: =+I30+K30 -> 0 | N30: 7000 | O30: 0 | P30: =+L30+N30 -> 7000 | Q30: =+M30+O30 -> 0 | R30: 8000 | S30: 0 | T30: =+P30+R30 -> 15000 | U30: =+Q30+S30 -> 0 | V30: 10000 | W30: 0 | X30: =+N30+R30+V30 -> 25000 | Y30: =+O30+S30+W30 -> 0 | Z30: =+T30+V30 -> 25000 | AA30: =+U30+W30 -> 0 | AB30: 10000 | AC30: 16462.166 | AD30: =+Z30+AB30 -> 35000 | AE30: =+AA30+AC30 -> 16462.166 | AF30: 40000 | AG30: 18653.11 | AH30: =+AD30+AF30 -> 75000 | AI30: =+AE30+AG30 -> 35115.276 | AJ30: 30000 | AK30: 10177.08 | AL30: =+AB30+AF30+AJ30 -> 80000 | AM30: =+AC30+AG30+AK30 -> 45292.356 | AN30: =+AH30+AJ30 -> 105000 | AO30: =+AI30+AK30 -> 45292.356 | AP30: 35000 | AQ30: 13495.918 | AR30: =+AN30+AP30 -> 140000 | AS30: =+AO30+AQ30 -> 58788.274 | AT30: 35000 | AU30: 19064.62 | AV30: =+AR30+AT30 -> 175000 | AW30: =+AS30+AU30 -> 77852.894 | AX30: 45000 | AY30: 11091 | AZ30: =+AP30+AT30+AX30 -> 115000 | BA30: =+AQ30+AU30+AY30 -> 43651.538 | BB30: =+AL30+AZ30 -> 195000 | BC30: =+AM30+BA30 -> 88943.894 | BD30: =+AV30+AX30 -> 220000 | BE30: =+AW30+AY30 -> 88943.894 | BF30: 535000 | BG30: 171634.81 | BH30: 51262.006 | BI30: =+AO30+BH30 -> 96554.362 | BJ30: =+BI30/1000000 -> 0.096554362
B31: Finished Steel | C31: Mt | D31: =SUM(D28:D30) -> 22439.54 | E31: =SUM(E28:E30) -> 22439.54 | F31: =SUM(F28:F30) -> 61380 | G31: =SUM(G28:G30) -> 61380 | H31: =SUM(H28:H30) -> 83819.54 | I31: =SUM(I28:I30) -> 83819.54 | J31: =SUM(J28:J30) -> 77908 | K31: =SUM(K28:K30) -> 63487.589 | ... BA31: =SUM(BA28:BA30) -> 294421 | BB31: =+AL31+AZ31 -> 869513.56 | BC31: =+AM31+BA31 -> 558245.07 | BD31: =SUM(BD28:BD30) -> 1330841.1 | BE31: =SUM(BE28:BE30) -> 886009.82 | BF31: =SUM(BF28:BF30) -> 1835000 | BG31: =SUM(BG28:BG30) -> 1215880.2
B32: 150x150 mm | C32: Mt | D32: 73040 | E32: 73040 | F32: 29860 | G32: 29860 | H32: =+D32+F32 -> 102900 | I32: =+E32+G32 -> 102900 | J32: 33200 | K32: 28297 | L32: =+H32+J32 -> 136100 | M32: =+I32+K32 -> 131197 | N32: 70000 | O32: 63899.25 | P32: =+L32+N32 -> 206100 | Q32: =+M32+O32 -> 195096.25 | R32: 72000 | S32: =67757.59+2 -> 67759.59 | T32: =+P32+R32 -> 278100 | U32: =+Q32+S32 -> 262855.84 | V32: 75000 | W32: 25573.64 | X32: =+N32+R32+V32 -> 217000 | Y32: =+O32+S32+W32 -> 157232.48 | Z32: =+T32+V32 -> 353100 | AA32: =+U32+W32 -> 288429.48 | AB32: 0 | AC32: 7100 | AD32: =+Z32+AB32 -> 353100 | AE32: =+AA32+AC32 -> 295529.48 | AF32: 31910.882 | AG32: =33228.37+22 -> 33250.37 | AH32: =+AD32+AF32 -> 385010.88 | AI32: =+AE32+AG32 -> 328779.85 | AJ32: 38425.609 | AK32: 49987.88 | AL32: =+AB32+AF32+AJ32 -> 70336.491 | AM32: =+AC32+AG32+AK32 -> 90338.25 | AN32: =+AH32+AJ32 -> 423436.49 | AO32: =+AI32+AK32 -> 378767.73 | AP32: 38089.326 | AQ32: 71742 | AR32: =+AN32+AP32 -> 461525.82 | AS32: =+AO32+AQ32 -> 450509.73 | AT32: 34053 | AU32: 72217 | AV32: =+AR32+AT32 -> 495578.82 | AW32: =+AS32+AU32 -> 522726.73 | AX32: 37477 | AY32: 85769 | AZ32: =+AP32+AT32+AX32 -> 109619.33 | BA32: =+AQ32+AU32+AY32 -> 229728 | BB32: =+AL32+AZ32 -> 179955.82 | BC32: =+AM32+BA32 -> 320066.25 | BD32: =+AV32+AX32 -> 533055.82 | BE32: =+AW32+AY32 -> 608495.73 | BF32: 304999.74 | BG32: 629438.96
B33: 200x280 mm | C33: Mt | D33: 21768 | E33: 21768 | F33: 36077 | G33: 36077 | H33: =+D33+F33 -> 57845 | I33: =+E33+G33 -> 57845 | J33: 44642 | K33: 43155.668 | L33: =+H33+J33 -> 102487 | M33: =+I33+K33 -> 101000.67 | N33: 49500 | O33: 59289.8 | P33: =+L33+N33 -> 151987 | Q33: =+M33+O33 -> 160290.47 | R33: 50000 | S33: 40294.224 | T33: =+P33+R33 -> 201987 | U33: =+Q33+S33 -> 200584.69 | V33: 46000 | W33: 11235.674 | X33: =+N33+R33+V33 -> 145500 | Y33: =+O33+S33+W33 -> 110819.7 | Z33: =+T33+V33 -> 247987 | AA33: =+U33+W33 -> 211820.37 | AB33: 9175.3772 | AC33: 7360 | AD33: =+Z33+AB33 -> 257162.38 | AE33: =+AA33+AC33 -> 219180.37 | AF33: 20595.217 | AG33: 7790 | AH33: =+AD33+AF33 -> 277757.59 | AI33: =+AE33+AG33 -> 226970.37 | AJ33: 31252.038 | AK33: 19962.438 | AL33: =+AB33+AF33+AJ33 -> 61022.632 | AM33: =+AC33+AG33+AK33 -> 35112.438 | AN33: =+AH33+AJ33 -> 309009.63 | AO33: =+AI33+AK33 -> 246932.8 | AP33: 23177.377 | AQ33: 23925 | AR33: =+AN33+AP33 -> 332187.01 | AS33: =+AO33+AQ33 -> 270857.8 | AT33: 21445 | AU33: 19587 | AV33: =+AR33+AT33 -> 353632.01 | AW33: =+AS33+AU33 -> 290444.8 | AX33: 17746 | AY33: =+SMS!AY40+SMS!AY42 -> 38934 | AZ33: =+AP33+AT33+AX33 -> 62368.377 | BA33: =+AQ33+AU33+AY33 -> 82446 | BB33: =+AL33+AZ33 -> 123391.01 | BC33: =+AM33+BA33 -> 117558.44 | BD33: =+AV33+AX33 -> 371378.01 | BE33: =+AW33+AY33 -> 329378.8 | BF33: 267000 | BG33: 248401
B34: Saleable Semis | C34: Mt | D34: =SUM(D32:D33) -> 94808 | E34: =SUM(E32:E33) -> 94808 | F34: =SUM(F32:F33) -> 65937 | G34: =SUM(G32:G33) -> 65937 | H34: =SUM(H32:H33) -> 160745 | I34: =SUM(I32:I33) -> 160745 | J34: =SUM(J32:J33) -> 77842 | K34: =SUM(K32:K33) -> 71452.668 | ... BA34: =SUM(BA32:BA33) -> 312174 | BB34: =+AL34+AZ34 -> 303346.83 | BC34: =+AM34+BA34 -> 437624.69 | BD34: =SUM(BD32:BD33) -> 904433.83 | BE34: =SUM(BE32:BE33) -> 937874.53 | BF34: =SUM(BF32:BF33) -> 571999.74 | BG34: =SUM(BG32:BG33) -> 877839.96 | BH34: 247541.93 | BI34: =+AO34+BH34 -> 873242.46 | BJ34: =+BI34/1000000 -> 0.87324246
B35: TOTAL | C35: Mt | D35: =+D31+D34 -> 117247.54 | E35: =+E31+E34 -> 117247.54 | F35: =+F31+F34 -> 127317 | G35: =+G31+G34 -> 127317 | H35: =+H31+H34 -> 244564.54 | I35: =+I31+I34 -> 244564.54 | J35: =+J31+J34 -> 155750 | K35: =+K31+K34 -> 134940.26 | ... BA35: =+BA31+BA34 -> 606595 | BB35: =+AL35+AZ35 -> 1172860.4 | BC35: =+AM35+BA35 -> 995869.76 | BD35: =+BD31+BD34 -> 2235274.9 | BE35: =+BE31+BE34 -> 1823884.4 | BF35: =+BF31+BF34 -> 2406999.7 | BG35: =+BG31+BG34 -> 2093720.2 | BH35: =+BH28+BH29+BH30+BH34 -> 570127.31 | BI35: =+AO35+BH35 -> 1787416.7 | BJ35: =+BI35/1000000 -> 1.7874167
B36: SAL STEEL PRODN (CATEGORY WISE) | AJ36: =+AJ28+AJ29 -> 119239.64 | AK36: =+AK28+AK29 -> 90046.606
B37: Wire Rod Plain Coils | C37: Mt | D37: =+D28 -> 14366.4 | E37: 8786.3 | F37: =+F28 -> 17668 | G37: 16479.612 | H37: =+D37+F37 -> 32034.4 | I37: =+E37+G37 -> 25265.912 | J37: =+J28 -> 35910 | K37: 25935.228 | L37: =+H37+J37 -> 67944.4 | M37: =+I37+K37 -> 51201.14 | N37: =+N28 -> 35000 | O37: 32647.336 | P37: =+L37+N37 -> 102944.4 | Q37: =+M37+O37 -> 83848.476 | R37: =+R28 -> 35000 | S37: 34032.42 | T37: =+P37+R37 -> 137944.4 | U37: =+Q37+S37 -> 117880.9 | V37: =+V28 -> 32000 | W37: 27037.868 | X37: =+N37+R37+V37 -> 102000 | Y37: =+O37+S37+W37 -> 93717.624 | Z37: =+T37+V37 -> 169944.4 | AA37: =+U37+W37 -> 144918.76 | AB37: =+AB28 -> 40000 | AC37: 26925.816 | AD37: =+Z37+AB37 -> 209944.4 | AE37: =+AA37+AC37 -> 171844.58 | AF37: =+AF28 -> 45249.811 | AG37: 32756.97 | AH37: =+AD37+AF37 -> 255194.21 | AI37: =+AE37+AG37 -> 204601.55 | AJ37: =+AJ28 -> 46294.038 | AK37: 34721.176 | AL37: =+AB37+AF37+AJ37 -> 131543.85 | AM37: =+AC37+AG37+AK37 -> 94403.962 | AN37: =+AH37+AJ37 -> 301488.25 | AO37: =+AI37+AK37 -> 239322.73 | AP37: =+AP28 -> 46294.038 | AQ37: 36021.128 | AR37: =+AN37+AP37 -> 347782.29 | AS37: =+AO37+AQ37 -> 275343.85 | AT37: =+AT28 -> 41769 | AU37: =+AU28-AU38 -> 23689.71 | AV37: =+AR37+AT37 -> 389551.29 | AW37: =+AS37+AU37 -> 299033.56 | AX37: =+AX28 -> 46414.675 | AY37: =+AY28-AY38 -> 38003 | AZ37: =+AP37+AT37+AX37 -> 134477.71 | BA37: =+AQ37+AU37+AY37 -> 97713.838 | BB37: =+AL37+AZ37 -> 266021.56 | BC37: =+AM37+BA37 -> 192117.8 | BD37: =+AV37+AX37 -> 435965.96 | BE37: =+AW37+AY37 -> 337036.56 | BF37: =+BF28 -> 500000 | BG37: 270654.57
B38: TMT Coils | C38: Mt | E38: 5580.1 | G38: 1188.108 | I38: =+E38+G38 -> 6768.208 | K38: 5402.916 | M38: =+I38+K38 -> 12171.124 | O38: 0 | Q38: =+M38+O38 -> 12171.124 | S38: 0 | U38: =+Q38+S38 -> 12171.124 | W38: 0 | Y38: =+O38+S38+W38 -> 0 | AA38: =+U38+W38 -> 12171.124 | AC38: 0 | AE38: =+AA38+AC38 -> 12171.124 | AG38: 0 | AI38: =+AE38+AG38 -> 12171.124 | AK38: 0 | AM38: =+AC38+AG38+AK38 -> 0 | AO38: =+AI38+AK38 -> 12171.124 | AQ38: 0 | AS38: =+AO38+AQ38 -> 12171.124 | AU38: 7310.69 | AW38: =+AS38+AU38 -> 19481.814 | BA38: =+AQ38+AU38+AY38 -> 7310.69 | BB38: =+AL38+AZ38 -> 0 | BC38: =+AM38+BA38 -> 7310.69 | BE38: =+AW38+AY38 -> 19481.814 | BG38: 141370.65
