Workbook
Name _1: #REF!
Name _1: #REF!
Name _1: #REF!
Name _1: #REF!
Name _1: #REF!
Name _1: #REF!
Name _1: #REF!
Name _1: #REF!
Name _1: #REF!
Name _2: #REF!
Name _2: #REF!
Name _2: #REF!
Name _2: #REF!
Name _2: #REF!
Name _2: #REF!
Name _2: #REF!
Name _2: #REF!
Name _2: #REF!
Name _3: #REF!
Name _3: #REF!
Name _3: #REF!
Name _3: #REF!
Name _3: #REF!
Name _3: #REF!
Name _3: #REF!
Name _3: #REF!
Name _4: #REF!
Name _4: #REF!
Name _4: #REF!
Name a: #REF!
Name a: #REF!
Name a: #REF!
Name a: #REF!
Name a: #REF!
Name AA: #REF!
Name AA: #REF!
Name AA: #REF!
Name AA: #REF!
Name AB: #REF!
Name AB: #REF!
Name AB: #REF!
Name AB: #REF!
Name AC: #REF!
Name AC: #REF!
Name AC: #REF!
Name AD: #REF!
Name AD: #REF!
Name AD: #REF!
Name AE: #REF!
Name AE: #REF!
Name AE: #REF!
Name AF: #REF!
Name AF: #REF!
Name AF: #REF!
Name AG: #REF!
Name AG: #REF!
Name AG: #REF!
Name AH: #REF!
Name AH: #REF!
Name AH: #REF!

Sheet Maj Production Summ
B1: MAJOR PRODUCTION SUMMARY | D1: 322.5 | E1: 29 | F1: 30 | G1: 30 | H1: 29.375 | I1: 59 | J1: 59.375 | K1: 19 | L1: 25.083333 | M1: 78 | N1: 84.458333 | O1: 9.5 | P1: 30.25 | Q1: 87.5 | R1: 114.70833 | S1: 30 | T1: 29.583333 | U1: 117.5 | V1: 144.29167 | W1: 29 | X1: 29.916667 | Y1: 68.5 | Z1: 89.75 | AA1: 146.5 | AB1: 174.20833 | AC1: 30 | AD1: 29.965417 | AE1: 176.5 | AF1: 204.17375 | AG1: 29 | AH1: 1 | AI1: 205.5 | AJ1: 205.17375 | AK1: 30 | AL1: 30.75 | AM1: 89 | AN1: 61.715417 | AO1: 235.5 | AP1: 235.92375 | AQ1: 30 | AR1: 29.875 | AS1: 265.5 | AT1: 265.79875 | AU1: 27 | AV1: 27.1875 | AW1: 292.5 | AX1: 292.98625 | AY1: 30 | AZ1: 30.229167 | BA1: 87 | BB1: 87.291667 | BC1: 176 | BD1: 149.00708 | BE1: 322.5 | BF1: 323.21542
D2: 365 | E2: 30 | F2: 30 | G2: 31 | H2: 31 | I2: 61 | J2: 61 | K2: 30 | L2: 30 | M2: 91 | N2: 91 | O2: 31 | P2: 31 | Q2: 122 | R2: 122 | S2: 31 | T2: 31 | U2: 153 | V2: 153 | W2: 30 | X2: 30 | Y2: 92 | Z2: 92 | AA2: 183 | AB2: 183 | AC2: 31 | AD2: 31 | AE2: 214 | AF2: 214 | AG2: 30 | AH2: 30 | AI2: 244 | AJ2: 244 | AK2: 31 | AL2: 31 | AM2: 92 | AN2: 92 | AO2: 275 | AP2: 275 | AQ2: 31 | AR2: 31 | AS2: 306 | AT2: 306 | AU2: 28 | AV2: 28 | AW2: 334 | AX2: 334 | AY2: 31 | AZ2: 31 | BA2: 90 | BB2: 90 | BC2: 182 | BD2: 182 | BE2: 365 | BF2: 365 | BL2: 365 | BM2: 365 | BN2: 366 | BO2: 366
B3: ITEM | C3: Unit | D3: 2024-25 ABP | E3: Apr'24 | G3: May'24 | I3: 2M | K3: Jun'24 | M3: QTR-1 | O3: Jul'24 | Q3: 4M | S3: Aug'24 | U3: 5M | W3: Sep'24 | Y3: QTR 2 | AA3: H1 | AC3: Oct'24 | AE3: 7M | AG3: Nov'24 | AI3: 8M | AK3: Dec'24 | AM3: QTR 3 | AO3: 9M | AQ3: Jan'25 | AS3: 10M | AU3: Feb'25 | AW3: 11M | AY3: Mar'25 | BA3: QTR 4 | BC3: H2 | BE3: 2024-25 | BG3: 2023-24 | BI3: 2022-23 | BJ3: 2021-22 | BL3: 2020-21 | BN3: 2019-20
E4: ABP | F4: ACT | G4: ABP | H4: ACT | I4: ABP | J4: ACT | K4: ABP | L4: ACT | M4: ABP | N4: ACT | O4: ABP | P4: ACT | Q4: ABP | R4: ACT | S4: ABP | T4: ACT | U4: ABP | V4: ACT | W4: ABP | X4: ACT | Y4: ABP | Z4: ACT | AA4: ABP | AB4: ACT | AC4: ABP | AD4: ACT | AE4: ABP | AF4: ACT | AG4: ABP | AH4: ACT | AI4: ABP | AJ4: ACT | AK4: ABP | AL4: ACT | AM4: ABP | AN4: ACT | AO4: ABP | AP4: ACT | AQ4: ABP | AR4: ACT | AS4: ABP | AT4: ACT | AU4: ABP | AV4: ACT | AW4: ABP | AX4: ACT | AY4: ABP | AZ4: ACT | BA4: ABP | BB4: ACT | BC4: ABP | BD4: ACT | BE4: ABP | BF4: ACT | BG4: ABP | BH4: ACT | BI4: ACT | BJ4: ABP | BK4: ACT | BL4: ABP | BM4: ACT | BN4: ABP | BO4: ACT
B5: COKE OVENS PUSHING
B6: (COB#10) | C6: Nos/ day | D6: 96.420548 | E6: 97.8 | F6: 98.766667 | G6: 97.8 | H6: 98.709677 | I6: 97.8 | J6: 98.737705 | K6: 97.456667 | L6: 97.4 | M6: 97.686813 | N6: 98.296703 | O6: 96 | P6: 97.580645 | Q6: 97.258197 | R6: 98.114754 | S6: 96 | T6: 98 | U6: 97.003268 | V6: 98.091503 | W6: 96 | X6: 98 | Y6: 96 | Z6: 97.858696 | AA6: 96.838798 | AB6: 98.076503 | AC6: 96 | AD6: 98 | AE6: 96.71729 | AF6: 98.065421 | AG6: 96 | AH6: 94.3 | AI6: 96.629098 | AJ6: 97.602459 | AK6: 96 | AL6: 98 | AM6: 96 | AN6: 96.793478 | AO6: 96.558182 | AP6: 97.647273 | AQ6: 96 | AR6: 98 | AS6: 96.501634 | AT6: 97.683007 | AU6: 96 | AV6: 97.678571 | AW6: 96.459581 | AX6: 97.682635 | AY6: 96 | AZ6: 98 | BA6: 96 | BB6: 97.9 | BC6: 96 | BD6: 97.340659 | BE6: 96.420548 | BF6: 97.709589 | BG6: 99 | BH6: 98.976067 | BI6: 98.783562 | BJ6: 99 | BK6: 97.824658 | BL6: 95.547945 | BM6: 95.342466 | BN6: 97 | BO6: 97.10959
B7: (COB#11) | C7: Nos/ day | D7: 98.167671 | E7: 98 | F7: 99 | G7: 98 | H7: 98.516129 | I7: 98 | J7: 98.754098 | K7: 96.006667 | L7: 96.7 | M7: 97.342857 | N7: 98.076923 | O7: 94.064516 | P7: 98.806452 | Q7: 96.509836 | R7: 98.262295 | S7: 99 | T7: 98.645161 | U7: 97.014379 | V7: 98.339869 | W7: 99 | X7: 98.3 | Y7: 97.336957 | Z7: 98.586957 | AA7: 97.339891 | AB7: 98.333333 | AC7: 99 | AD7: 97.83871 | AE7: 97.580374 | AF7: 98.261682 | AG7: 99 | AH7: 94 | AI7: 97.754918 | AJ7: 97.737705 | AK7: 99 | AL7: 98.483871 | AM7: 99 | AN7: 96.804348 | AO7: 97.895273 | AP7: 97.821818 | AQ7: 99 | AR7: 98.483871 | AS7: 98.00719 | AT7: 97.888889 | AU7: 99 | AV7: 98.392857 | AW7: 98.090419 | AX7: 97.931138 | AY7: 99 | AZ7: 98.645161 | BA7: 99 | BB7: 98.511111 | BC7: 99 | BD7: 97.648352 | BE7: 98.167671 | BF7: 97.991781 | BG7: 98.000061 | BH7: 96.670251 | BI7: 92.210959 | BJ7: 99 | BK7: 96.816438 | BL7: 94.2 | BM7: 90.778082 | BN7: 97 | BO7: 95.710246
B8: Overall Equiv. Ovens Pushed/ Day | C8: Nos/ day | D8: 276.48974 | E8: 277.56163 | F8: 280.3626 | G8: 277.56163 | H8: 279.41804 | I8: 277.56163 | J8: 279.88258 | K8: 273.56192 | L8: 274.77703 | M8: 276.24304 | N8: 278.19943 | O8: 268.54276 | P8: 278.82155 | Q8: 274.28641 | R8: 278.35751 | S8: 277.59593 | T8: 278.94505 | U8: 274.95697 | V8: 278.47655 | W8: 277.59593 | X8: 278.31192 | Y8: 274.54541 | Z8: 278.69698 | AA8: 275.38959 | AB8: 278.44956 | AC8: 277.59593 | AD8: 277.46577 | AE8: 275.7092 | AF8: 278.30705 | AG8: 277.59593 | AH8: 266.72442 | AI8: 275.94117 | AJ8: 276.88296 | AK8: 277.59593 | AL8: 278.64919 | AM8: 277.59593 | AN8: 274.36192 | AO8: 276.12771 | AP8: 277.08206 | AQ8: 277.59593 | AR8: 278.64919 | AS8: 276.27645 | AT8: 277.24082 | AU8: 277.59593 | AV8: 278.16082 | AW8: 276.38706 | AX8: 277.31795 | AY8: 277.59593 | AZ8: 278.94505 | BA8: 277.59593 | BB8: 278.59916 | BC8: 277.59593 | BD8: 276.45726 | BE8: 276.48974 | BF8: 277.45614 | BG8: 278.76174 | BH8: 276.29853 | BI8: 267.92634 | BJ8: 280.59593 | BK8: 275.41528 | BL8: 268.33922 | BM8: 261.85691 | BN8: 274.92733 | BO8: 272.67112
B9: (COB#10) | C9: Nos | D9: 35193.5 | E9: 2934 | F9: 2963 | G9: 3031.8 | H9: 3060 | I9: 5965.8 | J9: 6023 | K9: 2923.7 | L9: 2922 | M9: 8889.5 | N9: 8945 | O9: 2976 | P9: 3025 | Q9: 11865.5 | R9: 11970 | S9: 2976 | T9: 3038 | U9: 14841.5 | V9: 15008 | W9: 2880 | X9: 2940 | Y9: 8832 | Z9: 9003 | AA9: 17721.5 | AB9: 17948 | AC9: 2976 | AD9: 3038 | AE9: 20697.5 | AF9: 20986 | AG9: 2880 | AH9: 2829 | AI9: 23577.5 | AJ9: 23815 | AK9: 2976 | AL9: 3038 | AM9: 8832 | AN9: 8905 | AO9: 26553.5 | AP9: 26853 | AQ9: 2976 | AR9: 3038 | AS9: 29529.5 | AT9: 29891 | AU9: 2688 | AV9: 2735 | AW9: 32217.5 | AX9: 32626 | AY9: 2976 | AZ9: 3038 | BA9: 8640 | BB9: 8811 | BC9: 17472 | BD9: 17716 | BE9: 35193.5 | BF9: 35664 | BG9: 36234 | BH9: 36225 | BI9: 36056 | BJ9: 36135 | BK9: 35706 | BL9: 34875 | BM9: 34800 | BN9: 35502 | BO9: 35543
B10: (COB#11) | C10: Nos | D10: 35831.2 | E10: 2940 | F10: 2970 | G10: 3038 | H10: 3054 | I10: 5978 | J10: 6024 | K10: 2880.2 | L10: 2901 | M10: 8858.2 | N10: 8925 | O10: 2916 | P10: 3063 | Q10: 11774.2 | R10: 11988 | S10: 3069 | T10: 3058 | U10: 14843.2 | V10: 15046 | W10: 2970 | X10: 2949 | Y10: 8955 | Z10: 9070 | AA10: 17813.2 | AB10: 17995 | AC10: 3069 | AD10: 3033 | AE10: 20882.2 | AF10: 21028 | AG10: 2970 | AH10: 2820 | AI10: 23852.2 | AJ10: 23848 | AK10: 3069 | AL10: 3053 | AM10: 9108 | AN10: 8906 | AO10: 26921.2 | AP10: 26901 | AQ10: 3069 | AR10: 3053 | AS10: 29990.2 | AT10: 29954 | AU10: 2772 | AV10: 2755 | AW10: 32762.2 | AX10: 32709 | AY10: 3069 | AZ10: 3058 | BA10: 8910 | BB10: 8866 | BC10: 18018 | BD10: 17772 | BE10: 35831.2 | BF10: 35767 | BG10: 35868.022 | BH10: 35382 | BI10: 33657 | BJ10: 36135 | BK10: 35338 | BL10: 34383 | BM10: 33134 | BN10: 35502 | BO10: 35030
B11: Overall Equiv. Ovens Pushed | C11: Nos | D11: 100918.75 | E11: 8326.8488 | F11: 8410.8779 | G11: 8604.4105 | H11: 8661.9593 | I11: 16931.259 | J11: 17072.837 | K11: 8206.8576 | L11: 8243.311 | M11: 25138.117 | N11: 25316.148 | O11: 8324.8256 | P11: 8643.468 | Q11: 33462.942 | R11: 33959.616 | S11: 8605.4738 | T11: 8647.2965 | U11: 42068.416 | V11: 42606.913 | W11: 8327.8779 | X11: 8349.3576 | Y11: 25258.177 | Z11: 25640.122 | AA11: 50396.294 | AB11: 50956.27 | AC11: 8605.4738 | AD11: 8601.439 | AE11: 59001.768 | AF11: 59557.709 | AG11: 8327.8779 | AH11: 8001.7326 | AI11: 67329.646 | AJ11: 67559.442 | AK11: 8605.4738 | AL11: 8638.125 | AM11: 25538.826 | AN11: 25241.297 | AO11: 75935.12 | AP11: 76197.567 | AQ11: 8605.4738 | AR11: 8638.125 | AS11: 84540.594 | AT11: 84835.692 | AU11: 7772.686 | AV11: 7788.5029 | AW11: 92313.28 | AX11: 92624.195 | AY11: 8605.4738 | AZ11: 8647.2965 | BA11: 24983.634 | BB11: 25073.924 | BC11: 50522.459 | BD11: 50315.221 | BE11: 100918.75 | BF11: 101271.49 | BG11: 102026.8 | BH11: 101126.28 | BI11: 97793.113 | BJ11: 102417.51 | BK11: 100526.58 | BL11: 97943.817 | BM11: 95577.773 | BN11: 100623.4 | BO11: 99798.61
B12: BF COKE
B13: COB#10 | C13: Mt | D13: 423729.74 | E13: 35325.36 | F13: 35684.713 | G13: 36502.872 | H13: 36852.926 | I13: 71828.232 | J13: 72537.639 | K13: 35201.348 | L13: 35185.906 | M13: 107029.58 | N13: 107723.54 | O13: 35831.04 | P13: 36682.905 | Q13: 142860.62 | R13: 144406.45 | S13: 35831.04 | T13: 36838.788 | U13: 178691.66 | V13: 181245.24 | W13: 34675.2 | X13: 35650.44 | Y13: 106337.28 | Z13: 109172.13 | AA13: 213366.86 | AB13: 216895.68 | AC13: 35831.04 | AD13: 36839 | AE13: 249197.9 | AF13: 253734.68 | AG13: 34675.2 | AH13: 34299.588 | AI13: 283873.1 | AJ13: 288034.27 | AK13: 35831.04 | AL13: 36582.745 | AM13: 106337.28 | AN13: 107721.33 | AO13: 319704.14 | AP13: 324617.01 | AQ13: 35831.04 | AR13: 36888.429 | AS13: 355535.18 | AT13: 361505.44 | AU13: 32363.52 | AV13: 33164.61 | AW13: 387898.7 | AX13: 394670.05 | AY13: 35831.04 | AZ13: 36838.788 | BA13: 104025.6 | BB13: 106891.83 | BC13: 210362.88 | BD13: 214613.16 | BE13: 423729.74 | BF13: 431508.84 | BG13: 433141.24 | BH13: 432382.85 | BI13: 430769.03 | BJ13: 438172.79 | BK13: 428806 | BL13: 425506 | BM13: 430922.2 | BN13: 406071.88 | BO13: 412610.14
B14: COB#11 | C14: Mt | D14: 791332.05 | E14: 64929.9 | F14: 65611.191 | G14: 67094.23 | H14: 67466.861 | I14: 132024.13 | J14: 133078.05 | K14: 63609.217 | L14: 64077.738 | M14: 195633.35 | N14: 197155.79 | O14: 64399.86 | P14: 68132.803 | Q14: 260033.21 | R14: 265288.59 | S14: 67778.865 | T14: 68018.33 | U14: 327812.07 | V14: 333306.92 | W14: 65592.45 | X14: 65593.87 | Y14: 197771.17 | Z14: 201745 | AA14: 393404.52 | AB14: 398900.79 | AC14: 67778.865 | AD14: 67418 | AE14: 461183.39 | AF14: 466318.79 | AG14: 65592.45 | AH14: 62715.658 | AI14: 526775.84 | AJ14: 529034.45 | AK14: 67778.865 | AL14: 67435.137 | AM14: 201150.18 | AN14: 197568.8 | AO14: 594554.7 | AP14: 596469.59 | AQ14: 67778.865 | AR14: 67998.622 | AS14: 662333.57 | AT14: 664468.21 | AU14: 61219.62 | AV14: 61278.776 | AW14: 723553.19 | AX14: 725746.98 | AY14: 67778.865 | AZ14: 68018.33 | BA14: 196777.35 | BB14: 197295.73 | BC14: 397927.53 | BD14: 394864.52 | BE14: 791332.05 | BF14: 793765.31 | BG14: 786486.6 | BH14: 774691.65 | BI14: 737579.38 | BJ14: 803741.8 | BK14: 778192 | BL14: 770203 | BM14: 752591.4 | BN14: 744858.59 | BO14: 745859.84
B15: Total BF COKE | C15: Mt | D15: 1215061.8 | E15: 100255.26 | F15: 101295.9 | G15: 103597.1 | H15: 104319.79 | I15: 203852.36 | J15: 205615.69 | K15: 98810.565 | L15: 99263.643 | M15: 302662.93 | N15: 304879.33 | O15: 100230.9 | P15: 104815.71 | Q15: 402893.83 | R15: 409695.04 | S15: 103609.9 | T15: 104857.12 | U15: 506503.73 | V15: 514552.16 | W15: 100267.65 | X15: 101244.31 | Y15: 304108.45 | Z15: 310917.14 | AA15: 606771.38 | AB15: 615796.47 | AC15: 103609.9 | AD15: 104257 | AE15: 710381.29 | AF15: 720053.47 | AG15: 100267.65 | AH15: 97015.246 | AI15: 810648.94 | AJ15: 817068.72 | AK15: 103609.9 | AL15: 104017.88 | AM15: 307487.46 | AN15: 305290.13 | AO15: 914258.84 | AP15: 921086.6 | AQ15: 103609.9 | AR15: 104887.05 | AS15: 1017868.7 | AT15: 1025973.6 | AU15: 93583.14 | AV15: 94443.386 | AW15: 1111451.9 | AX15: 1120417 | AY15: 103609.9 | AZ15: 104857.12 | BA15: 300802.95 | BB15: 304187.55 | BC15: 608290.41 | BD15: 609477.68 | BE15: 1215061.8 | BF15: 1225274.2 | BG15: 1219627.8 | BH15: 1207074.5 | BI15: 1168348.4 | BJ15: 1241914.6 | BK15: 1206998 | BL15: 1195709 | BM15: 1183513.6 | BN15: 1150930.5 | BO15: 1158470
B16: SINTER | C16: Mt | D16: 4387544.5 | E16: 387249.31 | F16: 364112 | G16: 403890.95 | H16: 343877 | I16: 791140.26 | J16: 707989 | K16: 287450.61 | L16: 260737 | M16: 1078590.9 | N16: 968726 | O16: 172935.2 | P16: 393033 | Q16: 1251526.1 | R16: 1361759 | S16: 391249.31 | T16: 367891 | U16: 1642775.4 | V16: 1729650 | W16: 374607.67 | X16: 370427 | Y16: 938792.18 | Z16: 1131351 | AA16: 2017383.1 | AB16: 2100077 | AC16: 403051.36 | AD16: 372857 | AE16: 2420434.4 | AF16: 2472934 | AG16: 392409.72 | AH16: 24407 | AI16: 2812844.1 | AJ16: 2497341 | AK16: 403051.36 | AL16: 361604 | AM16: 1198512.4 | AN16: 758868 | AO16: 3215895.5 | AP16: 2858945 | AQ16: 403051.36 | AR16: 369250 | AS16: 3618946.9 | AT16: 3228195 | AU16: 365546.23 | AV16: 342499 | AW16: 3984493.1 | AX16: 3570694 | AY16: 403051.36 | AZ16: 410020 | BA16: 1171649 | BB16: 1121769 | BC16: 2370161.4 | BD16: 1880637 | BE16: 4387544.5 | BF16: 3980714 | BG16: 4499999.9 | BH16: 4398445 | BI16: 4395665 | BJ16: 4183927.8 | BK16: 4277831 | BL16: 3665891.3 | BM16: 3629577 | BN16: 3903932.5 | BO16: 3709525
B17: HOT METAL | C17: Mt | D17: 2650000 | E17: 240000 | F17: 236134 | G17: 248000 | H17: 209171.6 | I17: 488000 | J17: 445305.6 | K17: 149000 | L17: 167351.5 | M17: 637000 | N17: 612657.1 | O17: 74000 | P17: 250033.8 | Q17: 711000 | R17: 862690.9 | S17: 240000 | T17: 245401.9 | U17: 951000 | V17: 1108092.8 | W17: 232000 | X17: 245769.8 | Y17: 546000 | Z17: 741205.5 | AA17: 1183000 | AB17: 1353862.6 | AC17: 250000 | AD17: 237886.3 | AE17: 1433000 | AF17: 1591748.9 | AG17: 242000 | AH17: 8246.5 | AI17: 1675000 | AJ17: 1599995.4 | AK17: 250000 | AL17: 257290.9 | AM17: 742000 | AN17: 503423.7 | AO17: 1925000 | AP17: 1857286.3 | AQ17: 250000 | AR17: 261845.4 | AS17: 2175000 | AT17: 2119131.7 | AU17: 225000 | AV17: 239624 | AW17: 2400000 | AX17: 2358755.7 | AY17: 250000 | AZ17: 263830 | BA17: 725000 | BB17: 765299.4 | BC17: 1467000 | BD17: 1268723.1 | BE17: 2650000 | BF17: 2622585.7 | BG17: 2800000 | BH17: 2721268.1 | BI17: 2592119.6 | BJ17: 2650001 | BK17: 2406785.7 | BL17: 2496672.2 | BM17: 2092798 | BN17: 2700000 | BO17: 2505193
B18: CRUDE STEEL | C18: Mt | D18: 2489528.3 | E18: 226056.6 | F18: 220127 | G18: 233603.77 | H18: 197854 | I18: 459660.38 | J18: 417981 | K18: 139811.32 | L18: 144189 | M18: 599471.7 | N18: 562170 | O18: 63679.245 | P18: 234513 | Q18: 663150.94 | R18: 796683 | S18: 226056.6 | T18: 231517 | U18: 889207.55 | V18: 1028200 | W18: 218509.43 | X18: 231269 | Y18: 508245.28 | Z18: 697299 | AA18: 1107717 | AB18: 1259469 | AC18: 235490.57 | AD18: 222138 | AE18: 1343207.5 | AF18: 1481607 | AG18: 227943.4 | AH18: 7935 | AI18: 1571150.9 | AJ18: 1489542 | AK18: 235490.57 | AL18: 234930 | AM18: 698924.53 | AN18: 465003 | AO18: 1806641.5 | AP18: 1724472 | AQ18: 235490.57 | AR18: 246040 | AS18: 2042132.1 | AT18: 1970512 | AU18: 211905.66 | AV18: 222895 | AW18: 2254037.7 | AX18: 2193407 | AY18: 235490.57 | AZ18: 243552 | BA18: 682886.79 | BB18: 712487 | BC18: 1381811.3 | BD18: 1177490 | BE18: 2489528.3 | BF18: 2436959 | BG18: 2620075.5 | BH18: 2528925 | BI18: 2422324.3 | BJ18: 2451737.7 | BK18: 2227867 | BL18: 2297163.5 | BM18: 1847433 | BN18: 2500000 | BO18: 2083412
B19: Caster #(1+2 ) | C19: Mt | D19: 1880445.4 | E19: 171825 | F19: 167017 | G19: 177750 | H19: 142026 | I19: 349575 | J19: 309043 | K19: 106020 | L19: 113537 | M19: 455595 | N19: 422580 | O19: 50085 | P19: 175693.36 | Q19: 505680 | R19: 598273.36 | S19: 168750 | T19: 173992 | U19: 674430 | V19: 772265.36 | W19: 163125 | X19: 174717 | Y19: 381960 | Z19: 524402.36 | AA19: 837555 | AB19: 946982.36 | AC19: 177750 | AD19: 168140 | AE19: 1015305 | AF19: 1115122.4 | AG19: 171825 | AH19: 7935 | AI19: 1187130 | AJ19: 1123057.4 | AK19: 177840.45 | AL19: 176215.37 | AM19: 527415.45 | AN19: 352290.37 | AO19: 1364970.4 | AP19: 1299272.7 | AQ19: 177750 | AR19: 183526 | AS19: 1542720.4 | AT19: 1482798.7 | AU19: 159975 | AV19: 163924 | AW19: 1702695.4 | AX19: 1646722.7 | AY19: 177750 | AZ19: 171866 | BA19: 515475 | BB19: 519316 | BC19: 1042890.4 | BD19: 871606.37 | BE19: 1880445.4 | BF19: 1818588.7 | BH19: 1922629.6 | BI19: 1903696 | BK19: 1777963.7
B20: Caster #3 | C20: Mt | D20: 609082.85 | E20: 54231.604 | F20: 53110 | G20: 55854 | H20: 55827.86 | I20: 110085.6 | J20: 108937.86 | K20: 33791.32 | L20: 30651.96 | M20: 143876.92 | N20: 139589.82 | O20: 13594.245 | P20: 58819.91 | Q20: 157471.17 | R20: 198409.73 | S20: 57306.6 | T20: 57524.85 | U20: 214777.77 | V20: 255934.58 | W20: 55384.43 | X20: 56551.8 | Y20: 126285.28 | Z20: 172896.56 | AA20: 270162.2 | AB20: 312486.38 | AC20: 57740.566 | AD20: 53997.96 | AE20: 327902.77 | AF20: 366484.34 | AG20: 56118.396 | AH20: 0 | AI20: 384021.16 | AJ20: 366484.34 | AK20: 57650.116 | AL20: 58714.36 | AM20: 171509.08 | AN20: 112712.32 | AO20: 441671.28 | AP20: 425198.7 | AQ20: 57740.566 | AR20: 62514.11 | AS20: 499411.84 | AT20: 487712.81 | AU20: 51930.66 | AV20: 58971.81 | AW20: 551342.5 | AX20: 546684.62 | AY20: 57740.566 | AZ20: 71685.7 | BA20: 167411.79 | BB20: 193171.62 | BC20: 338920.87 | BD20: 305883.94 | BE20: 609083.07 | BF20: 618370.32 | BH20: 606294.79 | BI20: 518629.33 | BK20: 449903.88
B21: Avg Heats Cast per Day | C21: Nos. / day | D21: 51.463117 | E21: 51.967035 | F21: 48.6 | G21: 51.91195 | H21: 44.187234 | I21: 51.939026 | J21: 46.416842 | K21: 49.056604 | L21: 37.79402 | M21: 51.236897 | N21: 43.855945 | O21: 44.68719 | P21: 51.041322 | Q21: 50.525786 | R21: 45.750817 | S21: 50.234801 | T21: 51.346479 | U21: 50.451492 | V21: 46.898065 | W21: 50.232053 | X21: 50.473538 | Y21: 49.464261 | Z21: 50.952646 | AA21: 50.408054 | AB21: 47.512078 | AC21: 52.331237 | AD21: 48.422487 | AE21: 50.73494 | AF21: 47.645694 | AG21: 52.400781 | AH21: 52 | AI21: 50.970022 | AJ21: 47.666916 | AK21: 52.331237 | AL21: 49.788618 | AM21: 52.353897 | AN21: 49.161136 | AO21: 51.143425 | AP21: 47.943456 | AQ21: 52.331237 | AR21: 53.523013 | AS21: 51.277641 | AT21: 48.570582 | AU21: 52.322385 | AV21: 53.075862 | AW21: 51.374079 | AX21: 48.988647 | AY21: 52.331237 | AZ21: 52.002757 | BA21: 52.32849 | BB21: 52.857279 | BC21: 52.341338 | BD21: 51.326419 | BE21: 51.463117 | BF21: 49.270546 | BG21: 50.337665 | BH21: 48.130368 | BI21: 45.269663 | BJ21: 44.780041 | BK21: 40.065753 | BL21: 41.920046 | BM21: 33.309589 | BN21: 47.014645 | BO21: 38.663934
B22: Cold Pig & Pig Equivalent
B23: MOG | C23: Mt | D23: 7740 | E23: 342 | F23: 556.07714 | G23: 342 | H23: 318.18764 | I23: 684 | J23: 874.26478 | K23: 720 | L23: 3128.8729 | M23: 1404 | N23: 4003.1377 | O23: 3600 | P23: 314.93231 | Q23: 5004 | R23: 4318.07 | S23: 342 | T23: 392.89329 | U23: 5346 | V23: 4710.9633 | W23: 342 | X23: 569 | Y23: 4284 | Z23: 1276.8256 | AA23: 5688 | AB23: 5279.9633 | AC23: 342 | AD23: 264.68337 | AE23: 6030 | AF23: 5544.6467 | AG23: 342 | AH23: 25.041 | AI23: 6372 | AJ23: 5569.6877 | AK23: 342 | AL23: 2134.9957 | AM23: 1026 | AN23: 2424.72 | AO23: 6714 | AP23: 7704.6834 | AQ23: 342 | AR23: 495.31098 | AS23: 7056 | AT23: 8199.9943 | AU23: 342 | AV23: 324.53136 | AW23: 7398 | AX23: 8524.5257 | AY23: 342 | AZ23: 4393.36 | BA23: 1026 | BB23: 5213.2023 | BC23: 2052 | BD23: 7637.9223 | BE23: 7740 | BF23: 12917.886 | BG23: 19561.1 | BH23: 7548.2756 | BI23: 9129.3344 | BJ23: 19735.515 | BK23: 22361.072 | BL23: 20755.018 | BM23: 58220.7 | BN23: 29957.856 | BO23: 134629.18
A24: 1000 | B24: UPIS | C24: Mt | D24: 0 | E24: 0 | F24: 78.505008 | G24: 0 | H24: 44.920608 | I24: 0 | J24: 123.42562 | K24: 0 | L24: 441.72324 | M24: 0 | N24: 565.14886 | O24: 0 | P24: 44.461032 | Q24: 0 | R24: 609.60989 | S24: 0 | T24: 55.467288 | U24: 0 | V24: 665.07718 | W24: 0 | X24: 80.319744 | Y24: 0 | Z24: 180.24806 | AA24: 0 | AB24: 745.39692 | AC24: 0 | AD24: 37.367064 | AE24: 0 | AF24: 782.76398 | AG24: 0 | AH24: 3.5352 | AI24: 0 | AJ24: 786.29918 | AK24: 0 | AL24: 301.41115 | AM24: 0 | AN24: 342.31342 | AO24: 0 | AP24: 1087.7103 | AQ24: 0 | AR24: 70 | AS24: 0 | AT24: 1157.7103 | AU24: 0 | AV24: 45.816192 | AW24: 0 | AX24: 1203.5265 | AY24: 0 | AZ24: 620.23906 | BA24: 0 | BB24: 736.05525 | BC24: 0 | BD24: 1078.3687 | BE24: 0 | BF24: 1823.7656 | BG24: 0 | BH24: 1026.6221 | BI24: 2541.6495 | BJ24: 0 | BK24: 2774.7649 | BL24: 392 | BM24: 3852.3 | BN24: 1419.0563 | BO24: 8272.9783
B25: Equiv. Pig Iron @ 65% of HM sent to Sand Pit | C25: Mt | D25: 1625 | E25: 0 | F25: 0 | G25: 0 | H25: 0 | I25: 0 | J25: 0 | K25: 0 | L25: 5978.4 | M25: 0 | N25: 5978.4 | O25: 1625 | P25: 0 | Q25: 1625 | R25: 5978.4 | S25: 0 | T25: 0 | U25: 1625 | V25: 5978.4 | W25: 0 | X25: 0 | Y25: 1625 | Z25: 0 | AA25: 1625 | AB25: 5978.4 | AC25: 0 | AD25: 0 | AE25: 1625 | AF25: 5978.4 | AG25: 0 | AH25: 1512.9 | AI25: 1625 | AJ25: 7491.3 | AK25: 0 | AL25: 2513.5 | AM25: 0 | AN25: 4026.4 | AO25: 1625 | AP25: 10004.8 | AQ25: 0 | AR25: 0 | AS25: 1625 | AT25: 10004.8 | AU25: 0 | AV25: 630 | AW25: 1625 | AX25: 10634.8 | AY25: 0 | AZ25: 480 | BA25: 0 | BB25: 1110 | BC25: 0 | BD25: 5136.4 | BE25: 1625 | BF25: 11114.8 | BG25: 2000 | BH25: 5022 | BI25: 4664.8 | BJ25: 14800 | BK25: 9214.4 | BL25: 0 | BM25: 0 | BN25: 0 | BO25: 26220.8
B26: TOTAL EQUIVALENT PIG IRON | C26: Mt | D26: 9365 | E26: 342 | F26: 634.58215 | G26: 342 | H26: 363.10825 | I26: 684 | J26: 997.6904 | K26: 720 | L26: 9548.9962 | M26: 1404 | N26: 10546.687 | O26: 5225 | P26: 359.39334 | Q26: 6629 | R26: 10906.08 | S26: 342 | T26: 448.36058 | U26: 6971 | V26: 11354.441 | W26: 342 | X26: 649.31974 | Y26: 5909 | Z26: 1457.0737 | AA26: 7313 | AB26: 12003.76 | AC26: 342 | AD26: 302.05043 | AE26: 7655 | AF26: 12305.811 | AG26: 342 | AH26: 1541.4762 | AI26: 7997 | AJ26: 13847.287 | AK26: 342 | AL26: 4949.9068 | AM26: 1026 | AN26: 6793.4334 | AO26: 8339 | AP26: 18797.194 | AQ26: 342 | AR26: 565.31098 | AS26: 8681 | AT26: 19362.505 | AU26: 342 | AV26: 1000.3476 | AW26: 9023 | AX26: 20362.852 | AY26: 342 | AZ26: 5493.599 | BA26: 1026 | BB26: 7059.2576 | BC26: 2052 | BD26: 13852.691 | BE26: 9365 | BF26: 25856.451 | BG26: 21561.1 | BH26: 13596.898 | BI26: 16335.784 | BJ26: 34535.515 | BK26: 34350.237 | BL26: 21147.018 | BM26: 62073 | BN26: 31376.912 | BO26: 169122.96
B27: Net PCI Production | C27: Mt | E27: 219 | F27: 0 | G27: 224.58 | H27: 64.519 | I27: 443.58 | J27: 64.519 | K27: 189.24 | L27: 1153.005 | M27: 632.82 | N27: 1217.524 | O27: 436.24 | P27: 1162.399 | Q27: 1069.06 | R27: 2379.923 | S27: 218.5 | T27: 1097.691 | U27: 1287.56 | V27: 3477.614 | W27: 212.42 | X27: 183 | Y27: 867.16 | Z27: 2443.09 | AA27: 1499.98 | AB27: 3660.614 | AC27: 226.1 | AD27: 0 | AE27: 1726.08 | AF27: 3660.614 | AG27: 220.02 | AH27: 1174.369 | AI27: 1946.1 | AJ27: 4834.983 | AK27: 226.1 | AL27: 1177.785 | AM27: 672.22 | AN27: 2352.154 | AO27: 2172.2 | AP27: 6012.768 | AQ27: 226.1 | AR27: 766.241 | AS27: 2398.3 | AT27: 6779.009 | AU27: 207.1 | AV27: 658.147 | AW27: 2605.4 | AX27: 7437.156 | AY27: 226.1 | AZ27: 554.33 | BA27: 659.3 | BB27: 1978.718 | BC27: 1331.52 | BD27: 4330.872 | BE27: 2831.5 | BF27: 7991.486 | BG27: 2377.872 | BH27: 6141.395 | BI27: 5885.734 | BJ27: 2398.56 | BK27: 13377.679 | BL27: 11568.99 | BM27: 41093.9 | BN27: 0 | BO27: 44255.19
B28: Net Granulated Slag Production | C28: Mt | D28: 987899.89 | E28: 89470.179 | F28: 81032.918 | G28: 92452.518 | H28: 71605.173 | I28: 181922.7 | J28: 152638.09 | K28: 55546.07 | L28: 55334.635 | M28: 237468.77 | N28: 207972.73 | O28: 27586.639 | P28: 84498.305 | Q28: 265055.41 | R28: 292471.03 | S28: 89470.179 | T28: 84615.104 | U28: 354525.58 | V28: 377086.13 | W28: 86487.84 | X28: 81116 | Y28: 203544.66 | Z28: 250229.41 | AA28: 441013.42 | AB28: 458202.13 | AC28: 93198.103 | AD28: 81673.877 | AE28: 534211.53 | AF28: 539876.01 | AG28: 90215.764 | AH28: 2328.2551 | AI28: 624427.29 | AJ28: 542204.27 | AK28: 93198.103 | AL28: 92452.296 | AM28: 276611.97 | AN28: 176454.43 | AO28: 717625.4 | AP28: 634656.56 | AQ28: 93198.103 | AR28: 94062.296 | AS28: 810823.5 | AT28: 728718.86 | AU28: 83878.293 | AV28: 80273.363 | AW28: 894701.79 | AX28: 808992.22 | AY28: 93198.103 | AZ28: 90266.534 | BA28: 270274.5 | BB28: 264602.19 | BC28: 546886.47 | BD28: 441056.62 | BE28: 987899.89 | BF28: 899258.76 | BG28: 1063047 | BH28: 1075244.6 | BI28: 1065593 | BJ28: 157305.12 | BK28: 920129.3 | BL28: 882599.97 | BM28: 776699 | BN28: 854658 | BO28: 809638.21
B29: Saleable Steel Production (Mill Wise)
B30: WR Mill | C30: Mt | D30: 500000 | E30: 43500 | F30: 36717.55 | G30: 45500 | H30: 38183.18 | I30: 89000 | J30: 74900.73 | K30: 30000 | L30: 38310.4 | M30: 119000 | N30: 113211.13 | O30: 25000 | P30: 42041.4 | Q30: 144000 | R30: 155252.53 | S30: 45500 | T30: 41559.65 | U30: 189500 | V30: 196812.18 | W30: 44000 | X30: 42947.5 | Y30: 114500 | Z30: 126548.55 | AA30: 233500 | AB30: 239759.68 | AC30: 45500 | AD30: 42384.76 | AE30: 279000 | AF30: 282144.44 | AG30: 44000 | AH30: 19981.35 | AI30: 323000 | AJ30: 302125.79 | AK30: 45500 | AL30: 39200.1 | AM30: 135000 | AN30: 101566.21 | AO30: 368500 | AP30: 341325.89 | AQ30: 45500 | AR30: 40296.85 | AS30: 414000 | AT30: 381622.74 | AU30: 40500 | AV30: 34335.35 | AW30: 454500 | AX30: 415958.09 | AY30: 45500 | AZ30: 43072.55 | BA30: 131500 | BB30: 117704.75 | BC30: 266500 | BD30: 219270.96 | BE30: 500000 | BF30: 459030.64 | BG30: 500000 | BH30: 478528.39 | BI30: 466114.65 | BJ30: 500000 | BK30: 465343.77 | BL30: 435965.96 | BM30: 356518.66 | BN30: 500000 | BO30: 412025.22
B31: Bar Mill | C31: Mt | D31: 870000 | E31: 77000 | F31: 69574.102 | G31: 80000 | H31: 65238.015 | I31: 157000 | J31: 134812.12 | K31: 48000 | L31: 49675.968 | M31: 205000 | N31: 184488.09 | O31: 37500 | P31: 70097.135 | Q31: 242500 | R31: 254585.22 | S31: 80000 | T31: 71164.143 | U31: 322500 | V31: 325749.36 | W31: 77500 | X31: 70484.61 | Y31: 195000 | Z31: 211745.89 | AA31: 400000 | AB31: 396233.97 | AC31: 80000 | AD31: 66747.8 | AE31: 480000 | AF31: 462981.77 | AG31: 77500 | AH31: 3169.72 | AI31: 557500 | AJ31: 466151.49 | AK31: 80000 | AL31: 70630.63 | AM31: 237500 | AN31: 140548.15 | AO31: 637500 | AP31: 536782.12 | AQ31: 80000 | AR31: 70085.115 | AS31: 717500 | AT31: 606867.24 | AU31: 72500 | AV31: 65990 | AW31: 790000 | AX31: 672857.24 | AY31: 80000 | AZ31: 78010.61 | BA31: 232500 | BB31: 214085.73 | BC31: 470000 | BD31: 354633.88 | BE31: 870000 | BF31: 750867.85 | BG31: 850000 | BH31: 795322.27 | BI31: 775906.63 | BJ31: 750000 | BK31: 649840.96 | BL31: 674875.14 | BM31: 440547.27 | BN31: 800000 | BO31: 632220.18
B32: US Mill | C32: Mt | D32: 560000 | E32: 46000 | F32: 47018.297 | G32: 47500 | H32: 44548.076 | I32: 93500 | J32: 91566.373 | K32: 35000 | L32: 27879.333 | M32: 128500 | N32: 119445.71 | O32: 12500 | P32: 44707.993 | Q32: 141000 | R32: 164153.7 | S32: 49000 | T32: 34390.132 | U32: 190000 | V32: 198543.83 | W32: 48000 | X32: 43670.795 | Y32: 109500 | Z32: 122768.92 | AA32: 238000 | AB32: 242214.63 | AC32: 54000 | AD32: 44900.301 | AE32: 292000 | AF32: 287114.93 | AG32: 52000 | AH32: 8584.984 | AI32: 344000 | AJ32: 295699.91 | AK32: 54000 | AL32: 40066.768 | AM32: 160000 | AN32: 93552.053 | AO32: 398000 | AP32: 335766.68 | AQ32: 54000 | AR32: 51039.179 | AS32: 452000 | AT32: 386805.86 | AU32: 48000 | AV32: 51009.48 | AW32: 500000 | AX32: 437815.34 | AY32: 60000 | AZ32: 62071.89 | BA32: 162000 | BB32: 164120.55 | BC32: 322000 | BD32: 257672.6 | BE32: 560000 | BF32: 499887.23 | BG32: 525000 | BH32: 459141.95 | BI32: 361987.56 | BJ32: 450000 | BK32: 213226.16 | BL32: 220000 | BM32: 88943.894 | BN32: 535000 | BO32: 171634.81
B33: Finished Steel | C33: Mt | D33: 1930000 | E33: 166500 | F33: 153309.95 | G33: 173000 | H33: 147969.27 | I33: 339500 | J33: 301279.22 | K33: 113000 | L33: 115865.7 | M33: 452500 | N33: 417144.92 | O33: 75000 | P33: 156846.53 | Q33: 527500 | R33: 573991.45 | S33: 174500 | T33: 147113.93 | U33: 702000 | V33: 721105.37 | W33: 169500 | X33: 157102.91 | Y33: 419000 | Z33: 461063.36 | AA33: 871500 | AB33: 878208.28 | AC33: 179500 | AD33: 154032.86 | AE33: 1051000 | AF33: 1032241.1 | AG33: 173500 | AH33: 31736.054 | AI33: 1224500 | AJ33: 1063977.2 | AK33: 179500 | AL33: 149897.5 | AM33: 532500 | AN33: 335666.41 | AO33: 1404000 | AP33: 1213874.7 | AQ33: 179500 | AR33: 161421.14 | AS33: 1583500 | AT33: 1375295.8 | AU33: 161000 | AV33: 151334.83 | AW33: 1744500 | AX33: 1526630.7 | AY33: 185500 | AZ33: 183155.05 | BA33: 526000 | BB33: 495911.02 | BC33: 1058500 | BD33: 831577.44 | BE33: 1930000 | BF33: 1709785.7 | BG33: 1875000 | BH33: 1732992.6 | BI33: 1604008.8 | BJ33: 1700000 | BK33: 1328410.9 | BL33: 1330841.1 | BM33: 886009.82 | BN33: 1835000 | BO33: 1215880.2
B34: 150x150 mm | C34: Mt | D34: 461999.71 | E34: 40719.754 | F34: 57019 | G34: 36952.46 | H34: 31956 | I34: 77672.214 | J34: 88975 | K34: 29529.067 | L34: 25895 | M34: 107201.28 | N34: 114870 | O34: 6183.2297 | P34: 58992 | Q34: 113384.51 | R34: 173862 | S34: 38452.612 | T34: 55648 | U34: 151837.12 | V34: 229510 | W34: 35980.786 | X34: 52843 | Y34: 80616.628 | Z34: 167483 | AA34: 187817.91 | AB34: 282353 | AC34: 47340.612 | AD34: 25418 | AE34: 235158.52 | AF34: 307771 | AG34: 45680.786 | AH34: 7935 | AI34: 280839.31 | AJ34: 315706 | AK34: 45710.062 | AL34: 64493 | AM34: 138731.46 | AN34: 97846 | AO34: 326549.37 | AP34: 380199 | AQ34: 47339.612 | AR34: 63074.18 | AS34: 373888.98 | AT34: 443273.18 | AU34: 42657.966 | AV34: 57481.27 | AW34: 416546.95 | AX34: 500754.45 | AY34: 45452.612 | AZ34: 57620 | BA34: 135450.19 | BB34: 178175.45 | BC34: 274181.65 | BD34: 276021.45 | BE34: 461999.56 | BF34: 558374.45 | BG34: 592000 | BH34: 574823.37 | BI34: 595119.91 | BJ34: 516406.77 | BK34: 627684.57 | BL34: 533055.82 | BM34: 608495.73 | BN34: 304999.74 | BO34: 629438.96
B35: 200x280 mm | C35: Mt | D35: 17999.828 | E35: 4999.7911 | F35: 4432 | G35: 0 | H35: 1377 | I35: 4999.7911 | J35: 5809 | K35: 0 | L35: 5866 | M35: 4999.7911 | N35: 11675 | O35: 0 | P35: 5431.48 | Q35: 4999.7911 | R35: 17106.48 | S35: 4999.5642 | T35: 8492 | U35: 9999.3553 | V35: 25598.48 | W35: 0 | X35: 6231 | Y35: 4999.5642 | Z35: 20154.48 | AA35: 9999.3553 | AB35: 31829.48 | AC35: 0.48160502 | AD35: 7379.5262 | AE35: 9999.8369 | AF35: 39209.006 | AG35: 4000.1297 | AH35: 637 | AI35: 13999.967 | AJ35: 39846.006 | AK35: 0 | AL35: 12910 | AM35: 4000.6113 | AN35: 20926.526 | AO35: 13999.967 | AP35: 52756.006 | AQ35: 0 | AR35: 10907.843 | AS35: 13999.967 | AT35: 63663.849 | AU35: 4000.0298 | AV35: 0 | AW35: 17999.996 | AX35: 63663.849 | AY35: 0 | AZ35: 0 | BA35: 4000.0298 | BB35: 10907.843 | BC35: 8000.6411 | BD35: 31834.369 | BE35: 17999.996 | BF35: 63663.849 | BG35: 57999.916 | BH35: 101828.14 | BI35: 116079.05 | BJ35: 153592.34 | BK35: 204330.35 | BL35: 371378.01 | BM35: 329378.8 | BN35: 267000 | BO35: 248401
B36: Saleable Semis | C36: Mt | D36: 479999.54 | E36: 45719.545 | F36: 61451 | G36: 36952.46 | H36: 33333 | I36: 82672.005 | J36: 94784 | K36: 29529.067 | L36: 31761 | M36: 112201.07 | N36: 126545 | O36: 6183.2297 | P36: 64423.48 | Q36: 118384.3 | R36: 190968.48 | S36: 43452.176 | T36: 64140 | U36: 161836.48 | V36: 255108.48 | W36: 35980.786 | X36: 59074 | Y36: 85616.192 | Z36: 187637.48 | AA36: 197817.26 | AB36: 314182.48 | AC36: 47341.094 | AD36: 32797.526 | AE36: 245158.36 | AF36: 346980.01 | AG36: 49680.916 | AH36: 8572 | AI36: 294839.27 | AJ36: 355552.01 | AK36: 45710.062 | AL36: 77403 | AM36: 142732.07 | AN36: 118772.53 | AO36: 340549.34 | AP36: 432955.01 | AQ36: 47339.612 | AR36: 73982.023 | AS36: 387888.95 | AT36: 506937.03 | AU36: 46657.996 | AV36: 57481.27 | AW36: 434546.94 | AX36: 564418.3 | AY36: 45452.612 | AZ36: 57620 | BA36: 139450.22 | BB36: 189083.29 | BC36: 282182.29 | BD36: 307855.82 | BE36: 479999.56 | BF36: 622038.3 | BG36: 649999.92 | BH36: 676651.51 | BI36: 711198.96 | BJ36: 669999.11 | BK36: 832014.92 | BL36: 904433.83 | BM36: 937874.53 | BN36: 571999.74 | BO36: 877839.96
B37: TOTAL SALEABLE STEEL | C37: Mt | D37: 2409999.5 | E37: 212219.54 | F37: 214760.95 | G37: 209952.46 | H37: 181302.27 | I37: 422172 | J37: 396063.22 | K37: 142529.07 | L37: 147626.7 | M37: 564701.07 | N37: 543689.92 | O37: 81183.23 | P37: 221270.01 | Q37: 645884.3 | R37: 764959.93 | S37: 217952.18 | T37: 211253.93 | U37: 863836.48 | V37: 976213.85 | W37: 205480.79 | X37: 216176.91 | Y37: 504616.19 | Z37: 648700.84 | AA37: 1069317.3 | AB37: 1192390.8 | AC37: 226841.09 | AD37: 186830.39 | AE37: 1296158.4 | AF37: 1379221.1 | AG37: 223180.92 | AH37: 40308.054 | AI37: 1519339.3 | AJ37: 1419529.2 | AK37: 225210.06 | AL37: 227300.5 | AM37: 675232.07 | AN37: 454438.94 | AO37: 1744549.3 | AP37: 1646829.7 | AQ37: 226839.61 | AR37: 235403.17 | AS37: 1971388.9 | AT37: 1882232.9 | AU37: 207658 | AV37: 208816.1 | AW37: 2179046.9 | AX37: 2091049 | AY37: 230952.61 | AZ37: 240775.05 | BA37: 665450.22 | BB37: 684994.32 | BC37: 1340682.3 | BD37: 1139433.3 | BE37: 2409999.6 | BF37: 2331824 | BG37: 2524999.9 | BH37: 2409644.1 | BI37: 2315207.8 | BJ37: 2369999.1 | BK37: 2160425.8 | BL37: 2235274.9 | BM37: 1823884.4 | BN37: 2406999.7 | BO37: 2093720.2
B38: SAL STEEL PRODN (CATEGORY WISE)
B39: Wire Rod Plain Coils | C39: Mt | D39: 500000 | E39: 43500 | F39: 36717.55 | G39: 45500 | H39: 38183.18 | I39: 89000 | J39: 74900.73 | K39: 30000 | L39: 38310.4 | M39: 119000 | N39: 113211.13 | O39: 25000 | P39: 42041.4 | Q39: 144000 | R39: 155252.53 | S39: 45500 | T39: 41559.65 | U39: 189500 | V39: 196812.18 | W39: 44000 | X39: 42947.5 | Y39: 114500 | Z39: 126548.55 | AA39: 233500 | AB39: 239759.68 | AC39: 45500 | AD39: 42384.76 | AE39: 279000 | AF39: 282144.44 | AG39: 44000 | AH39: 19981.35 | AI39: 323000 | AJ39: 302125.79 | AK39: 45500 | AL39: 39200.1 | AM39: 135000 | AN39: 101566.21 | AO39: 368500 | AP39: 341325.89 | AQ39: 45500 | AR39: 40296.85 | AS39: 414000 | AT39: 381622.74 | AU39: 40500 | AV39: 34335.35 | AW39: 454500 | AX39: 415958.09 | AY39: 45500 | AZ39: 43072.55 | BA39: 131500 | BB39: 117704.75 | BC39: 266500 | BD39: 219270.96 | BE39: 500000 | BF39: 459030.64 | BG39: 500000 | BH39: 471802.34 | BI39: 410762.6 | BJ39: 500000 | BK39: 456374.84 | BL39: 435965.96 | BM39: 333534.61 | BN39: 500000 | BO39: 270654.57
B40: TMT Coils | C40: Mt | F40: 0 | H40: 0 | J40: 0 | L40: 0 | N40: 0 | P40: 0 | R40: 0 | T40: 0 | V40: 0 | X40: 0 | Z40: 0 | AB40: 0 | AD40: 0 | AF40: 0 | AH40: 0 | AJ40: 0 | AL40: 0 | AN40: 0 | AP40: 0 | AR40: 0 | AT40: 0 | AV40: 0 | AX40: 0 | AZ40: 0 | BB40: 0 | BD40: 0 | BF40: 0 | BH40: 6726.05 | BI40: 55352.05 | BK40: 8968.93 | BM40: 22983.766 | BO40: 141370.65
...

Sheet Maj Despatch Summ
B1: MAJOR DESPATCH SUMMARY 2024-25 (As per Finance CENVAT report)
E2: 30 | F2: 30 | G2: 31 | H2: 31 | I2: 61 | J2: 61 | K2: 30 | L2: 30 | M2: 91 | N2: 91 | O2: 31 | P2: 31 | Q2: 122 | R2: 122 | S2: 31 | T2: 31 | U2: 153 | V2: 153 | W2: 30 | X2: 30 | Y2: 92 | Z2: 92 | AA2: 183 | AB2: 183 | AC2: 31 | AD2: 31 | AE2: 214 | AF2: 214 | AG2: 30 | AH2: 30 | AI2: 244 | AJ2: 244 | AK2: 31 | AL2: 31 | AM2: 92 | AN2: 92 | AO2: 275 | AP2: 275 | AQ2: 31 | AR2: 31 | AS2: 306 | AT2: 306 | AU2: 28 | AV2: 28 | AW2: 334 | AX2: 334 | AY2: 31 | AZ2: 31 | BA2: 90 | BB2: 90 | BC2: 182 | BD2: 182 | BE2: 365 | BF2: 365 | BM2: 365 | BN2: 365 | BO2: 366 | BP2: 366
B3: ITEM | C3: Unit | D3: 2024-25 ABP | E3: Apr'24 | G3: May'24 | I3: 2M | K3: Jun'24 | M3: QTR-1 | O3: Jul'24 | Q3: 4M | S3: Aug'24 | U3: 5M | W3: Sep'24 | Y3: QTR-2 | AA3: H1 | AC3: Oct'24 | AE3: 7M | AG3: Nov'24 | AI3: 8M | AK3: Dec'24 | AM3: QTR-3 | AO3: 9M | AQ3: Jan'25 | AS3: 10M | AU3: Feb'25 | AW3: 11M | AY3: Mar'25 | BA3: QTR-4 | BC3: H2 | BE3: 2024-25 | BG3: 2023-24 | BI3: 2022-23 | BK3: 2021-22 | BM3: 2020-21 | BO3: 2019-20
E4: ABP | F4: ACT | G4: ABP | H4: ACT | I4: ABP | J4: ACT | K4: ABP | L4: ACT | M4: ABP | N4: ACT | O4: ABP | P4: ACT | Q4: ABP | R4: ACT | S4: ABP | T4: ACT | U4: ABP | V4: ACT | W4: ABP | X4: ACT | Y4: ABP | Z4: ACT | AA4: ABP | AB4: ACT | AC4: ABP | AD4: ACT | AE4: ABP | AF4: ACT | AG4: ABP | AH4: ACT | AI4: ABP | AJ4: ACT | AK4: ABP | AL4: ACT | AM4: ABP | AN4: ACT | AO4: ABP | AP4: ACT | AQ4: ABP | AR4: ACT | AS4: ABP | AT4: ACT | AU4: ABP | AV4: ACT | AW4: ABP | AX4: ACT | AY4: ABP | AZ4: ACT | BA4: ABP | BB4: ACT | BC4: ABP | BD4: ACT | BE4: ABP | BF4: ACT | BG4: ABP | BH4: ACT | BI4: ABP | BJ4: ACT | BK4: ABP | BL4: ACT | BM4: ABP | BN4: ACT | BO4: ABP | BP4: ACT
B5: Saleable Steel (mill-wise)
B6: MKTG-Plant sales | C6: MT | D6: 21500 | E6: 2200 | F6: 3578.87 | G6: 2100 | H6: 8742.4 | I6: 4300 | J6: 12321.27 | K6: 100 | L6: 4335 | M6: 4400 | N6: 16656.27 | O6: 100 | P6: 2363.09 | Q6: 4500 | R6: 19019.36 | S6: 2100 | T6: 4615.5 | U6: 6600 | V6: 23634.86 | W6: 2200 | X6: 5085 | Y6: 4400 | Z6: 12063.59 | AA6: 8800 | AB6: 28719.86 | AC6: 2100 | AD6: 4044.21 | AE6: 10900 | AF6: 32764.07 | AG6: 2100 | AH6: 5778.35 | AI6: 13000 | AJ6: 38542.42 | AK6: 2100 | AL6: 3912 | AM6: 6300 | AN6: 13734.56 | AO6: 15100 | AP6: 42454.42 | AQ6: 2200 | AR6: 3486.44 | AS6: 17300 | AT6: 45940.86 | AU6: 2100 | AV6: 1080.89 | AW6: 19400 | AX6: 47021.75 | AY6: 2100 | AZ6: 6965.79 | BA6: 6400 | BB6: 11533.12 | BC6: 12700 | BD6: 25267.68 | BE6: 21500 | BF6: 53987.54 | BG6: 21500 | BH6: 30649.84 | BI6: 25500 | BJ6: 34807.22 | BK6: 16050 | BL6: 33201.15 | BM6: 0 | BN6: 35268.25 | BO6: 2000 | BP6: 28405.85
B7: IPT | C7: MT | D7: 0 | E7: 0 | F7: 0 | G7: 0 | H7: 322.72 | I7: 0 | J7: 322.72 | K7: 0 | L7: 0 | M7: 0 | N7: 322.72 | O7: 0 | P7: 0 | Q7: 0 | R7: 322.72 | S7: 0 | T7: 0 | U7: 0 | V7: 322.72 | W7: 0 | Y7: 0 | Z7: 0 | AA7: 0 | AB7: 322.72 | AC7: 0 | AD7: 0 | AE7: 0 | AF7: 322.72 | AG7: 0 | AH7: 0 | AI7: 0 | AJ7: 322.72 | AK7: 0 | AL7: 0 | AM7: 0 | AN7: 0 | AO7: 0 | AP7: 322.72 | AQ7: 0 | AR7: 0 | AS7: 0 | AT7: 322.72 | AU7: 0 | AV7: 0 | AW7: 0 | AX7: 322.72 | AY7: 0 | AZ7: 0 | BA7: 0 | BB7: 0 | BC7: 0 | BD7: 0 | BE7: 0 | BF7: 322.72 | BG7: 0 | BH7: 3076.2 | BI7: 123000 | BJ7: 42263.08 | BK7: 0 | BL7: 71707.42 | BM7: 10800 | BN7: 9758.51 | BO7: 24210 | BP7: 5928.095
B8: CMO-WR MILL | C8: MT | D8: 498500 | E8: 43300 | F8: 38606.76 | G8: 45400 | H8: 38320.77 | I8: 88700 | J8: 76927.53 | K8: 29900 | L8: 38679.25 | M8: 118600 | N8: 115606.78 | O8: 24900 | P8: 41309.15 | Q8: 143500 | R8: 156915.93 | S8: 45400 | T8: 40737.79 | U8: 188900 | V8: 197653.72 | W8: 43800 | X8: 42134.22 | Y8: 114100 | Z8: 124181.16 | AA8: 232700 | AB8: 239787.94 | AC8: 45400 | AD8: 37048.14 | AE8: 278100 | AF8: 276836.08 | AG8: 43900 | AH8: 30159.91 | AI8: 322000 | AJ8: 306995.99 | AK8: 45400 | AL8: 37390 | AM8: 134700 | AN8: 104598.05 | AO8: 367400 | AP8: 344385.99 | AQ8: 45300 | AR8: 37025.61 | AS8: 412700 | AT8: 381411.6 | AU8: 40400 | AV8: 32967.39 | AW8: 453100 | AX8: 414378.99 | AY8: 45400 | AZ8: 44837.42 | BA8: 131100 | BB8: 114830.42 | BC8: 265800 | BD8: 219428.47 | BE8: 498500 | BF8: 459216.41 | BG8: 498500 | BH8: 473494.21 | BI8: 498500 | BJ8: 453432.75 | BK8: 498500 | BL8: 467953.64 | BM8: 435166.29 | BN8: 351267.02 | BO8: 498000 | BP8: 399090.26
B9: CMO-BAR MILL | C9: MT | D9: 870000 | E9: 77000 | F9: 72159.95 | G9: 80000 | H9: 67613.13 | I9: 157000 | J9: 139773.08 | K9: 48000 | L9: 45346.21 | M9: 205000 | N9: 185119.29 | O9: 37500 | P9: 69331.99 | Q9: 242500 | R9: 254451.28 | S9: 80000 | T9: 73713.89 | U9: 322500 | V9: 328165.17 | W9: 77500 | X9: 66573.36 | Y9: 195000 | Z9: 209619.24 | AA9: 400000 | AB9: 394738.53 | AC9: 80000 | AD9: 64076.47 | AE9: 480000 | AF9: 458815 | AG9: 77500 | AH9: 10813.23 | AI9: 557500 | AJ9: 469628.23 | AK9: 80000 | AL9: 67253 | AM9: 237500 | AN9: 142142.7 | AO9: 637500 | AP9: 536881.23 | AQ9: 80000 | AR9: 70877.68 | AS9: 717500 | AT9: 607758.91 | AU9: 72500 | AV9: 58216.86 | AW9: 790000 | AX9: 665975.77 | AY9: 80000 | AZ9: 84208.42 | BA9: 232500 | BB9: 213302.96 | BC9: 470000 | BD9: 355445.66 | BE9: 870000 | BF9: 750184.19 | BG9: 850000 | BH9: 781402.45 | BI9: 780000 | BJ9: 768402.31 | BK9: 750000 | BL9: 648761.89 | BM9: 674874.74 | BN9: 436958.46 | BO9: 800000 | BP9: 612890.55
B10: CMO-US MILL | C10: MT | D10: 560000 | E10: 46000 | F10: 51397.78 | G10: 47500 | H10: 45578.34 | I10: 93500 | J10: 96976.12 | K10: 35000 | L10: 23860.35 | M10: 128500 | N10: 120836.47 | O10: 12500 | P10: 45789.59 | Q10: 141000 | R10: 166626.06 | S10: 49000 | T10: 38854.43 | U10: 190000 | V10: 205480.49 | W10: 48000 | X10: 43924.95 | Y10: 109500 | Z10: 128568.97 | AA10: 238000 | AB10: 249405.44 | AC10: 54000 | AD10: 43303.75 | AE10: 292000 | AF10: 292709.19 | AG10: 52000 | AH10: 15465.42 | AI10: 344000 | AJ10: 308174.61 | AK10: 54000 | AL10: 33463 | AM10: 160000 | AN10: 92232.17 | AO10: 398000 | AP10: 341637.61 | AQ10: 54000 | AR10: 44656.88 | AS10: 452000 | AT10: 386294.49 | AU10: 48000 | AV10: 47339.01 | AW10: 500000 | AX10: 433633.5 | AY10: 60000 | AZ10: 68418.51 | BA10: 162000 | BB10: 160414.4 | BC10: 322000 | BD10: 252646.57 | BE10: 560000 | BF10: 502052.01 | BG10: 525000 | BH10: 452802.59 | BI10: 470000 | BJ10: 357334.79 | BK10: 445000 | BL10: 214319.65 | BM10: 220000 | BN10: 100400.4 | BO10: 535000 | BP10: 167166.99
B11: CMO-SEMIS | C11: MT | D11: 459999.54 | E11: 43719.545 | F11: 65083.85 | G11: 34952.46 | H11: 37872.88 | I11: 78672.005 | J11: 102956.73 | K11: 29529.074 | L11: 22528.51 | M11: 108201.08 | N11: 125485.24 | O11: 6182.8629 | P11: 55129.39 | Q11: 114383.94 | R11: 180614.63 | S11: 41452.176 | T11: 58121.89 | U11: 155836.12 | V11: 238736.52 | W11: 33980.589 | X11: 53428.72 | Y11: 81615.629 | Z11: 166680 | AA11: 189816.71 | AB11: 292165.24 | AC11: 45341.094 | AD11: 31038.07 | AE11: 235157.8 | AF11: 323203.31 | AG11: 47680.916 | AH11: 11905.3 | AI11: 282838.72 | AJ11: 335108.61 | AK11: 43710.094 | AL11: 56100 | AM11: 136732.1 | AN11: 99043.37 | AO11: 326548.81 | AP11: 391208.61 | AQ11: 45340.094 | AR11: 82929.73 | AS11: 371888.9 | AT11: 474138.34 | AU11: 44657.996 | AV11: 49136.17 | AW11: 416546.9 | AX11: 523274.51 | AY11: 43452.64 | AZ11: 61705.96 | BA11: 133450.73 | BB11: 193771.86 | BC11: 270182.83 | BD11: 292815.23 | BE11: 459999.54 | BF11: 584980.47 | BG11: 630000.01 | BH11: 623466.17 | BI11: 513000.01 | BJ11: 641816.63 | BK11: 659950.15 | BL11: 742311.77 | BM11: 893633.78 | BN11: 944002.21 | BO11: 547789.74 | BP11: 836451
B12: TOTAL | C12: MT | D12: 2409999.5 | E12: 212219.54 | F12: 230827.21 | G12: 209952.46 | H12: 198450.24 | I12: 422172 | J12: 429277.45 | K12: 142529.07 | L12: 134749.32 | M12: 564701.08 | N12: 564026.77 | O12: 81182.863 | P12: 213923.21 | Q12: 645883.94 | R12: 777949.98 | S12: 217952.18 | T12: 216043.5 | U12: 863836.12 | V12: 993993.48 | W12: 205480.59 | X12: 211146.25 | Y12: 504615.63 | Z12: 641112.96 | AA12: 1069316.7 | AB12: 1205139.7 | AC12: 226841.09 | AD12: 179510.64 | AE12: 1296157.8 | AF12: 1384650.4 | AG12: 223180.92 | AH12: 74122.21 | AI12: 1519338.7 | AJ12: 1458772.6 | AK12: 225210.09 | AL12: 198118 | AM12: 675232.1 | AN12: 451750.85 | AO12: 1744548.8 | AP12: 1656890.6 | AQ12: 226840.09 | AR12: 238976.34 | AS12: 1971388.9 | AT12: 1895866.9 | AU12: 207658 | AV12: 188740.32 | AW12: 2179046.9 | AX12: 2084607.2 | AY12: 230952.64 | AZ12: 266136.1 | BA12: 665450.73 | BB12: 693852.76 | BC12: 1340682.8 | BD12: 1145603.6 | BE12: 2409999.5 | BF12: 2350743.3 | BG12: 2525000 | BH12: 2364891.5 | BI12: 2410000 | BJ12: 2298056.8 | BK12: 2369500.2 | BL12: 2178255.5 | BM12: 2234474.8 | BN12: 1877654.8 | BO12: 2406999.7 | BP12: 2049932.7
B13: Consideration in internal consumption | D13: Saleable production Plan: 2410000 (1500 T has been kept in plan for Internal consumption) | E13: Saleable production Plan: 201135 (200 T has been kept in plan for Internal consumption) | G13: Saleable production Plan: 201135 (200 T has been kept in plan for Internal consumption) | K13: Saleable production Plan: 201135 (200 T has been kept in plan for Internal consumption) | O13: Saleable production Plan: 201135 (200 T has been kept in plan for Internal consumption) | S13: Saleable production Plan: 201135 (200 T has been kept in plan for Internal consumption) | W13: Saleable production Plan: 201135 (200 T has been kept in plan for Internal consumption) | AC13: Saleable production Plan: 201135 (200 T has been kept in plan for Internal consumption) | AG13: Saleable production Plan: 201135 (200 T has been kept in plan for Internal consumption) | AK13: Saleable production Plan: 201135 (200 T has been kept in plan for Internal consumption) | AQ13: Saleable production Plan: 201135 (200 T has been kept in plan for Internal consumption) | AU13: Saleable production Plan: 201135 (200 T has been kept in plan for Internal consumption) | AY13: Saleable production Plan: 201135 (200 T has been kept in plan for Internal consumption)
B14: Saleable Steel (Sale type-wise)
B15: IPT | C15: MT | D15: 2409999.5 | E15: 212219.54 | F15: 0 | G15: 209952.46 | H15: 322.72 | I15: 422172 | J15: 322.72 | K15: 142529.07 | L15: 0 | M15: 564701.08 | N15: 322.72 | O15: 81182.863 | P15: 0 | Q15: 645883.94 | R15: 322.72 | S15: 217952.18 | T15: 0 | U15: 863836.12 | V15: 322.72 | W15: 205480.59 | X15: 0 | Y15: 504615.63 | Z15: 0 | AA15: 1069316.7 | AB15: 322.72 | AC15: 226841.09 | AD15: 0 | AE15: 1296157.8 | AF15: 322.72 | AG15: 223180.92 | AH15: 0 | AI15: 1519338.7 | AJ15: 322.72 | AK15: 225210.09 | AL15: 0 | AM15: 675232.1 | AN15: 0 | AO15: 1744548.8 | AP15: 322.72 | AQ15: 226840.09 | AR15: 0 | AS15: 1971388.9 | AT15: 322.72 | AU15: 207658 | AV15: 0 | AW15: 2179046.9 | AX15: 322.72 | AY15: 230952.64 | AZ15: 0 | BA15: 665450.73 | BB15: 0 | BC15: 1340682.8 | BD15: 0 | BE15: 2409999.5 | BF15: 322.72 | BG15: 2525000 | BH15: 3076.2 | BI15: 2410000 | BJ15: 42263.08 | BK15: 2369500.2 | BL15: 71707.42 | BM15: 2234474.8 | BN15: 9758.51 | BO15: 2406999.7 | BP15: 5928.249
B16: CMO DIR | C16: MT | F16: 163487.96 | H16: 137432.14 | J16: 300920.1 | L16: 93749.81 | N16: 394669.91 | P16: 132453.96 | R16: 527123.87 | T16: 130382.84 | V16: 657506.71 | X16: 153397.97 | Z16: 416234.77 | AB16: 810904.68 | AD16: 116531.94 | AF16: 927436.62 | AH16: 55204.14 | AJ16: 982640.76 | AL16: 139405.21 | AN16: 311141.29 | AP16: 1122046 | AR16: 171765.58 | AT16: 1293811.6 | AV16: 136540.59 | AX16: 1430352.1 | AZ16: 189752.74 | BB16: 498058.91 | BD16: 809200.2 | BF16: 1620104.9 | BH16: 1443296 | BJ16: 1325226.7 | BL16: 1097093.1 | BN16: 691326.52 | BP16: 569419.83
B17: CMO SYD | C17: MT | F17: 63760.38 | H17: 49193.61 | J17: 112953.99 | L17: 36624.69 | N17: 149578.68 | P17: 79067.16 | R17: 228645.84 | T17: 77925.77 | V17: 306571.61 | X17: 51623.67 | Z17: 208616.6 | AB17: 358195.28 | AD17: 56105 | AF17: 414300.28 | AH17: 12954.53 | AJ17: 427254.81 | AL17: 54572.32 | AN17: 123631.85 | AP17: 481827.13 | AR17: 60538.11 | AT17: 542365.24 | AV17: 51118.84 | AX17: 593484.08 | AZ17: 68622.95 | BB17: 180279.9 | BD17: 303911.75 | BF17: 662107.03 | BH17: 829404.4 | BJ17: 809005.31 | BL17: 567271.22 | BN17: 479205.15 | BP17: 909567
B18: MKTG DIR | C18: MT | F18: 3578.87 | H18: 8742.4 | J18: 12321.27 | L18: 4335 | N18: 16656.27 | P18: 2363.09 | R18: 19019.36 | T18: 4615.5 | V18: 23634.86 | X18: 5085 | Z18: 12063.59 | AB18: 28719.86 | AD18: 4044.21 | AF18: 32764.07 | AH18: 5778.35 | AJ18: 38542.42 | AL18: 3912 | AN18: 13734.56 | AP18: 42454.42 | AR18: 3486.44 | AT18: 45940.86 | AV18: 1080.89 | AX18: 47021.75 | AZ18: 6965.79 | BB18: 11533.12 | BD18: 25267.68 | BF18: 53987.54 | BH18: 30649.84 | BJ18: 34807.22 | BL18: 33201.15 | BN18: 35268.25 | BP18: 28405.85
B19: EXPORT | C19: MT | F19: 0 | H19: 2759.37 | J19: 2759.37 | L19: 39.82 | N19: 2799.19 | P19: 39 | R19: 2838.19 | T19: 3119.39 | V19: 5957.58 | X19: 1039.61 | Z19: 4198 | AB19: 6997.19 | AD19: 2829.49 | AF19: 9826.68 | AH19: 185.19 | AJ19: 10011.87 | AL19: 228.3 | AN19: 3242.98 | AP19: 10240.17 | AR19: 3186.21 | AT19: 13426.38 | AV19: 0 | AX19: 13426.38 | AZ19: 794.62 | BB19: 3980.83 | BD19: 7223.81 | BF19: 14221 | BH19: 58464.99 | BJ19: 86754.52 | BL19: 408982.58 | BN19: 662096.98 | BP19: 536611.98
B20: % DIRECT (IPT+CMO DIR+ EXPORT+ PLANT SALES) | C20: % | F20: 72.377442 | H20: 75.211111 | J20: 73.687416 | L20: 72.82013 | N20: 73.480216 | P20: 63.039466 | R20: 70.609185 | T20: 63.930519 | V20: 69.157583 | X20: 75.550752 | Z20: 67.460243 | AB20: 70.277697 | AD20: 68.745585 | AF20: 70.079069 | AH20: 82.522742 | AJ20: 70.711349 | AL20: 72.454552 | AN20: 72.632698 | AP20: 70.919788 | AR20: 74.667739 | AT20: 71.392221 | AV20: 72.915782 | AX20: 71.530165 | AZ20: 74.215091 | BB20: 74.017557 | BD20: 73.471459 | BF20: 71.834135 | BH20: 64.928437 | BJ20: 64.796113 | BL20: 70.665579 | BN20: 74.478558 | BP20: 55.62943
B21: Saleable Steel (Shipping Mode-wise)
B22: RAIL | C22: MT | D22: 2409999.5 | E22: 212219.54 | F22: 177654.4 | G22: 209952.46 | H22: 159975.22 | I22: 422172 | J22: 337629.62 | K22: 142529.07 | L22: 110092.96 | M22: 564701.08 | N22: 447722.58 | O22: 81182.863 | P22: 180420.56 | Q22: 645883.94 | R22: 628143.14 | S22: 217952.18 | T22: 173433.78 | U22: 863836.12 | V22: 801576.92 | W22: 205480.59 | X22: 170345.16 | Y22: 504615.63 | Z22: 524199.5 | AA22: 1069316.7 | AB22: 971922.08 | AC22: 226841.09 | AD22: 148158.06 | AE22: 1296157.8 | AF22: 1120080.1 | AG22: 223180.92 | AH22: 62803.84 | AI22: 1519338.7 | AJ22: 1182884 | AK22: 225210.09 | AL22: 157996.8 | AM22: 675232.1 | AN22: 368958.7 | AO22: 1744548.8 | AP22: 1340880.8 | AQ22: 226840.09 | AR22: 197810 | AS22: 1971388.9 | AT22: 1538690.8 | AU22: 207658 | AV22: 141082.9 | AW22: 2179046.9 | AX22: 1679773.7 | AY22: 230952.64 | AZ22: 218617.3 | BA22: 665450.73 | BB22: 557510.2 | BC22: 1340682.8 | BD22: 926468.9 | BE22: 2409999.5 | BF22: 1898391 | BG22: 2525000 | BH22: 1848504.3 | BI22: 2410000 | BJ22: 1959110.7 | BK22: 2369500.2 | BL22: 1882591.4 | BM22: 2234474.8 | BN22: 1557181.9 | BO22: 2406999.7 | BP22: 1655527.4
B23: ROAD | C23: MT | F23: 53172.81 | H23: 38475.02 | J23: 91647.83 | L23: 24656.36 | N23: 116304.19 | P23: 33502.65 | R23: 149806.84 | T23: 42609.72 | V23: 192416.56 | X23: 40801.09 | Z23: 116913.46 | AB23: 233217.65 | AD23: 31352.58 | AF23: 264570.23 | AH23: 11318.37 | AJ23: 275888.6 | AL23: 40121.52 | AN23: 82792.47 | AP23: 316010.12 | AR23: 41165.9 | AT23: 357176.02 | AV23: 47657.42 | AX23: 404833.44 | AZ23: 47518.8 | BB23: 136342.12 | BD23: 219134.59 | BF23: 452352.24 | BH23: 516386.89 | BJ23: 338946.25 | BL23: 295664.13 | BN23: 320472.9 | BP23: 394405.54
B24: TOTAL | C24: MT | F24: 230827.21 | H24: 198450.24 | J24: 429277.45 | L24: 134749.32 | N24: 564026.77 | P24: 213923.21 | R24: 777949.98 | T24: 216043.5 | V24: 993993.48 | X24: 211146.25 | Z24: 641112.96 | AB24: 1205139.7 | AD24: 179510.64 | AF24: 1384650.4 | AH24: 74122.21 | AJ24: 1458772.6 | AL24: 198118.32 | AN24: 451751.17 | AP24: 1656890.9 | AR24: 238975.9 | AT24: 1895866.8 | AV24: 188740.32 | AX24: 2084607.1 | AZ24: 266136.1 | BB24: 693852.32 | BD24: 1145603.5 | BF24: 2350743.2 | BH24: 2364891.2 | BJ24: 2298057 | BL24: 2178255.5 | BN24: 1877654.8 | BP24: 2049932.9
B25: ROAD CO-EFFICIENT (%) | C25: % | F25: 23.035763 | H25: 19.387742 | J25: 21.349323 | L25: 18.297948 | N25: 20.620332 | P25: 15.661064 | R25: 19.256616 | T25: 19.72275 | V25: 19.35793 | X25: 19.323616 | Z25: 18.236016 | AB25: 19.351918 | AD25: 17.465583 | AF25: 19.107367 | AH25: 15.269877 | AJ25: 18.912379 | AL25: 20.251292 | AN25: 18.327007 | AP25: 19.072476 | AR25: 17.225963 | AT25: 18.839721 | AV25: 25.250259 | AX25: 19.420131 | AZ25: 17.855075 | BB25: 19.65002 | BD25: 19.12831 | BF25: 19.242946 | BH25: 21.835546 | BJ25: 14.749254 | BL25: 13.573438 | BN25: 17.067721 | BP25: 19.239924
B26: Pig Iron | C26: MT | D26: 9365 | E26: 342 | F26: 298.84 | G26: 342 | H26: 0 | I26: 684 | J26: 298.84 | K26: 720 | L26: 598.73 | M26: 1404 | N26: 897.57 | O26: 5225 | P26: 2594.6 | Q26: 6629 | R26: 3492.17 | S26: 342 | T26: 499.34 | U26: 6971 | V26: 3991.51 | W26: 342 | X26: 0 | Y26: 5909 | Z26: 3093.94 | AA26: 7313 | AB26: 3991.51 | AC26: 342 | AD26: 748.03 | AE26: 7655 | AF26: 4739.54 | AG26: 342 | AH26: 298.97 | AI26: 7997 | AJ26: 5038.51 | AK26: 342 | AL26: 499.24 | AM26: 1026 | AN26: 1546.24 | AO26: 8339 | AP26: 5537.75 | AQ26: 342 | AR26: 1595.84 | AS26: 8681 | AT26: 7133.59 | AU26: 342 | AV26: 249.07 | AW26: 9023 | AX26: 7382.66 | AY26: 342 | AZ26: 1297.13 | BA26: 1026 | BB26: 3142.04 | BC26: 2052 | BD26: 4688.28 | BE26: 9365 | BF26: 8679.79 | BG26: 20742.204 | BH26: 7537.1 | BI26: 16929.735 | BJ26: 8801.74 | BK26: 19251.635 | BL26: 20488.86 | BM26: 20754.645 | BN26: 80002.18 | BO26: 29958.272 | BP26: 124050.8
B27: PCIS Plant Sales | C27: MT | D27: 0 | E27: 219 | F27: 259.35 | G27: 224.58 | H27: 150.17 | I27: 443.58 | J27: 409.52 | K27: 189.24 | L27: 167.22 | M27: 632.82 | N27: 576.74 | O27: 436.24 | P27: 1598.69 | Q27: 1069.06 | R27: 2175.43 | S27: 218.5 | T27: 1092.55 | U27: 1287.56 | V27: 3267.98 | W27: 212.42 | X27: 499.76 | Y27: 867.16 | Z27: 3191 | AA27: 1499.98 | AB27: 3767.74 | AC27: 226.1 | AD27: 0 | AE27: 1726.08 | AF27: 3767.74 | AG27: 220.02 | AH27: 198.57 | AI27: 1946.1 | AJ27: 3966.31 | AK27: 226.1 | AL27: 298.71 | AM27: 672.22 | AN27: 497.28 | AO27: 2172.2 | AP27: 4265.02 | AQ27: 226.1 | AR27: 499.09 | AS27: 2398.3 | AT27: 4764.11 | AU27: 207.1 | AV27: 0 | AW27: 2605.4 | AX27: 4764.11 | AY27: 226.1 | AZ27: 998.41 | BA27: 659.3 | BB27: 1497.5 | BC27: 1331.52 | BD27: 1994.78 | BE27: 2831.5 | BF27: 5762.52 | BG27: 2236.752 | BH27: 5991.84 | BI27: 2057.6 | BJ27: 5429.83 | BK27: 2163.56 | BL27: 17862.58 | BM27: 6973.7102 | BN27: 29483.78 | BO27: 8472.5251 | BP27: 59555.1
B28: Total Pig & Pig Equiv | C28: MT | D28: 9365 | E28: 561 | F28: 558.19 | G28: 566.58 | H28: 150.17 | I28: 1127.58 | J28: 708.36 | K28: 909.24 | L28: 765.95 | M28: 2036.82 | N28: 1474.31 | O28: 5661.24 | P28: 4193.29 | Q28: 7698.06 | R28: 5667.6 | S28: 560.5 | T28: 1591.89 | U28: 8258.56 | V28: 7259.49 | W28: 554.42 | X28: 499.76 | Y28: 6776.16 | Z28: 6284.94 | AA28: 8812.98 | AB28: 7759.25 | AC28: 568.1 | AD28: 748.03 | AE28: 9381.08 | AF28: 8507.28 | AG28: 562.02 | AH28: 497.54 | AI28: 9943.1 | AJ28: 9004.82 | AK28: 568.1 | AL28: 797.95 | AM28: 1698.22 | AN28: 2043.52 | AO28: 10511.2 | AP28: 9802.77 | AQ28: 568.1 | AR28: 2094.93 | AS28: 11079.3 | AT28: 11897.7 | AU28: 549.1 | AV28: 249.07 | AW28: 11628.4 | AX28: 12146.77 | AY28: 568.1 | AZ28: 2295.54 | BA28: 1685.3 | BB28: 4639.54 | BC28: 3383.52 | BD28: 6683.06 | BE28: 12196.5 | BF28: 14442.31 | BG28: 22978.956 | BH28: 13528.94 | BI28: 18987.335 | BJ28: 14231.57 | BK28: 21415.195 | BL28: 38351.44 | BM28: 27728.355 | BN28: 109485.96 | BO28: 38430.797 | BP28: 183605.9

Sheet Maj Techno Summ
A1: MAJOR TECHNO PARAMETERS 2024-2025
C2: 365 | D2: 30 | E2: 30 | F2: 31 | G2: 31 | H2: 61 | I2: 61 | J2: 30 | K2: 30 | L2: 91 | M2: 91 | N2: 31 | O2: 31 | P2: 122 | Q2: 122 | R2: 31 | S2: 31 | T2: 153 | U2: 153 | V2: 30 | W2: 30 | X2: 92 | Y2: 92 | Z2: 183 | AA2: 183 | AB2: 31 | AC2: 31 | AD2: 214 | AE2: 214 | AF2: 30 | AG2: 30 | AH2: 244 | AI2: 244 | AJ2: 31 | AK2: 31 | AL2: 92 | AM2: 92 | AN2: 275 | AO2: 275 | AP2: 31 | AQ2: 31 | AR2: 306 | AS2: 306 | AT2: 28 | AU2: 28 | AV2: 334 | AW2: 334 | AX2: 31 | AY2: 31 | AZ2: 90 | BA2: 90 | BB2: 182 | BC2: 182 | BD2: 365 | BE2: 365 | BL2: 365 | BM2: 365 | BN2: 366 | BO2: 366 | BP2: 365
A3: ITEM | B3: Unit | C3: 2024-25 Norm | D3: Apr'24 | F3: May'24 | H3: 2M | J3: Jun'24 | L3: QTR-1 | N3: Jul'24 | P3: 4M | R3: Aug'24 | T3: 5M | V3: Sep'24 | X3: QTR-2 | Z3: H1 | AB3: Oct'24 | AD3: 7M | AF3: Nov'24 | AH3: 8M | AJ3: Dec'24 | AL3: QTR-3 | AN3: 9 M | AP3: Jan'25 | AR3: 10M | AT3: Feb'25 | AV3: 11M | AX3: Mar'25 | AZ3: QTR-4 | BB3: H2 | BD3: 2024-25 | BF3: 2023-24 | BH3: 2022-23 | BJ3: 2021-22 | BL3: 2020-21 | BN3: 2019-20 | BP3: 2018-19
D4: ABP | E4: ACT | F4: ABP | G4: ACT | H4: ABP | I4: ACT | J4: ABP | K4: ACT | L4: ABP | M4: ACT | N4: ABP | O4: ACT | P4: ABP | Q4: ACT | R4: ABP | S4: ACT | T4: ABP | U4: ACT | V4: ABP | W4: ACT | X4: ABP | Y4: ACT | Z4: ABP | AA4: ACT | AB4: ABP | AC4: ACT | AD4: ABP | AE4: ACT | AF4: ABP | AG4: ACT | AH4: ABP | AI4: ACT | AJ4: ABP | AK4: ACT | AL4: ABP | AM4: ACT | AN4: ABP | AO4: ACT | AP4: ABP | AQ4: ACT | AR4: ABP | AS4: ACT | AT4: ABP | AU4: ACT | AV4: ABP | AW4: ACT | AX4: ABP | AY4: ACT | AZ4: ABP | BA4: ACT | BB4: ABP | BC4: ACT | BD4: ABP | BE4: ACT | BF4: ABP | BG4: ACT | BH4: ABP | BI4: ACT | BJ4: ABP | BK4: ACT | BL4: ABP | BM4: ACT | BN4: ABP | BO4: ACT | BP4: ACT
A5: B.F.Coke Yield | B5: % | C5: 70 | D5: 70 | E5: 70.02 | F5: 70 | G5: 70.02 | H5: 70 | I5: 70.02 | J5: 70 | K5: 70.01 | L5: 70 | M5: 70.01675 | N5: 70 | O5: 70.503373 | P5: 70 | Q5: 70.141085 | R5: 70 | S5: 70.5 | T5: 70 | U5: 70.214032 | V5: 70 | W5: 70.5 | X5: 70 | Y5: 70.501139 | Z5: 70 | AA5: 70.260896 | AB5: 70 | AC5: 70.453746 | AD5: 70 | AE5: 70.288712 | AF5: 70 | AG5: 70.49 | AH5: 70 | AI5: 70.312514 | AJ5: 70 | AK5: 70.01 | AL5: 70 | AM5: 70.313108 | AN5: 70 | AO5: 70.278182 | AP5: 70 | AQ5: 70.595 | AR5: 70 | AS5: 70.310473 | AT5: 70 | AU5: 70.5 | AV5: 70 | AW5: 70.326436 | AX5: 70 | AY5: 70.5 | AZ5: 70 | BA5: 70.532713 | BB5: 70 | BC5: 70.422664 | BD5: 70 | BE5: 70.341275 | BF5: 69.5 | BG5: 69.398029 | BH5: 69.5 | BI5: 69.459875 | BJ5: 70.500003 | BK5: 69.798394 | BL5: 70.999787 | BM5: 72.813877 | BN5: 66.5 | BO5: 67.48567 | BP5: 67.015011
A6: ICC in Coal Blend
A7: (COB#10) | B7: % | C7: 95 | D7: 95 | E7: 93.3 | F7: 95 | G7: 95 | H7: 95 | I7: 94.163689 | J7: 95 | K7: 94.999982 | L7: 95 | M7: 94.436875 | N7: 95 | O7: 95.000052 | P7: 95 | Q7: 94.579199 | R7: 95 | S7: 93.451695 | T7: 95 | U7: 94.348083 | V7: 95 | W7: 92.000071 | X7: 95 | Y7: 93.489976 | Z7: 95 | AA7: 93.959413 | AB7: 95 | AC7: 92.000348 | AD7: 95 | AE7: 93.676577 | AF7: 95 | AG7: 90.270086 | AH7: 95 | AI7: 93.273632 | AJ7: 95 | AK7: 91.999923 | AL7: 95 | AM7: 91.450919 | AN7: 95 | AO7: 93.130074 | AP7: 95 | AQ7: 91.999923 | AR7: 95 | AS7: 93.015598 | AT7: 95 | AU7: 90.285714 | AV7: 95 | AW7: 92.787463 | AX7: 95 | AY7: 89.032227 | AZ7: 95 | BA7: 90.444569 | BB7: 95 | BC7: 90.950596 | BD7: 95 | BE7: 92.468484 | BF7: 92 | BG7: 90.939873 | BH7: 92 | BI7: 89.651306 | BJ7: 95 | BK7: 93.865972 | BL7: 94.377235 | BM7: 95.478511 | BN7: 90 | BO7: 91.425995 | BP7: 91.808306
A8: (COB#11) | B8: % | C8: 100 | D8: 100 | E8: 97.166665 | F8: 100 | G8: 100 | H8: 100 | I8: 98.603087 | J8: 100 | K8: 100 | L8: 100 | M8: 99.057142 | N8: 100 | O8: 100 | P8: 100 | Q8: 99.298048 | R8: 100 | S8: 100 | T8: 100 | U8: 99.440715 | V8: 100 | W8: 97.799999 | X8: 100 | Y8: 99.28486 | Z8: 100 | AA8: 99.171912 | AB8: 100 | AC8: 96.999629 | AD8: 100 | AE8: 98.858749 | AF8: 100 | AG8: 95.266663 | AH8: 100 | AI8: 98.433936 | AJ8: 100 | AK8: 96.999996 | AL8: 100 | AM8: 96.450906 | AN8: 100 | AO8: 98.27118 | AP8: 100 | AQ8: 96.999996 | AR8: 100 | AS8: 98.141604 | AT8: 100 | AU8: 97.000003 | AV8: 100 | AW8: 98.045441 | AX8: 100 | AY8: 95.387093 | AZ8: 100 | BA8: 96.443687 | BB8: 100 | BC8: 96.447304 | BD8: 100 | BE8: 97.818139 | BF8: 94 | BG8: 93.889004 | BH8: 94 | BI8: 92.198587 | BJ8: 95 | BK8: 94.753433 | BL8: 94.836589 | BM8: 95.080613 | BN8: 90 | BO8: 96.370935 | BP8: 94.117213
