Workbook
Name _1: #REF!
Name _1: #REF!
Name _1: #REF!
Name _1: #REF!
Name _1: #REF!
Name _1: #REF!
Name _1: #REF!
Name _1: #REF!
Name _2: #REF!
Name _2: #REF!
Name _2: #REF!
Name _2: #REF!
Name _2: #REF!
Name _2: #REF!
Name _2: #REF!
Name _2: #REF!
Name _3: #REF!
Name _3: #REF!
Name _3: #REF!
Name _3: #REF!
Name _3: #REF!
Name _3: #REF!
Name _3: #REF!
Name _4: #REF!
Name _4: #REF!
Name a: #REF!
Name a: #REF!
Name a: #REF!
Name a: #REF!
Name a: #REF!
Name AA: #REF!
Name AA: #REF!
Name AA: #REF!
Name AB: #REF!
Name AB: #REF!
Name AB: #REF!
Name AC: #REF!
Name AC: #REF!
Name AD: #REF!
Name AD: #REF!
Name AE: #REF!
Name AE: #REF!
Name AF: #REF!
Name AF: #REF!
Name AG: #REF!
Name AG: #REF!
Name AH: #REF!
Name AH: #REF!
Name AI: #REF!
Name AI: #REF!
Name AK: #REF!
Name AK: #REF!
Name AL: #REF!
Name AL: #REF!
Name AM: #REF!
Name AM: #REF!
Name AN: #REF!
Name AN: #REF!
Name AS: #REF!
Name AS: #REF!

Sheet Maj Production Summ
B1: MAJOR PRODUCTION SUMMARY | D1: 347 | E1: 29 | F1: =30-'B-FCE'!F3 -> 29.5 | G1: 25 | H1: =27-'B-FCE'!H3 -> 26.791667 | I1: =E1+G1 -> 54 | J1: =F1+H1 -> 56.291667 | K1: 27 | L1: =26-'B-FCE'!L3 -> 24.708333 | M1: =+E1+G1+K1 -> 81 | N1: =+F1+H1+L1 -> 81 | O1: 30 | P1: =31-'B-FCE'!P3 -> 30.5 | Q1: =+M1+O1 -> 111 | R1: =+N1+P1 -> 111.5 | S1: 30 | T1: =31-'B-FCE'!T3 -> 31 | U1: =+Q1+S1 -> 141 | V1: =+R1+T1 -> 142.5 | W1: 29 | X1: =30-'B-FCE'!X3 -> 28.458333 | Y1: =+O1+S1+W1 -> 89 | Z1: =+P1+T1+X1 -> 89.958333 | AA1: =+U1+W1 -> 170 | AB1: =+V1+X1 -> 170.95833 | AC1: 30 | AD1: =31-'B-FCE'!AD3 -> 30.5 | AE1: =AA1+AC1 -> 200 | AF1: =AB1+AD1 -> 201.45833 | AG1: 29 | AH1: =30-'B-FCE'!AH3 -> 29 | AI1: =AE1+AG1 -> 229 | AJ1: =AF1+AH1 -> 230.45833 | AK1: 30 | AL1: =31-'B-FCE'!AL3 -> 30.541667 | AM1: =+AC1+AG1+AK1 -> 89 | AN1: =+AD1+AH1+AL1 -> 90.041667 | AO1: =AI1+AK1 -> 259 | AP1: =AJ1+AL1 -> 261 | AQ1: 30 | AR1: =30-'B-FCE'!AR3 -> 30 | AS1: =AO1+AQ1 -> 289 | AT1: =AP1+AR1 -> 291 | AU1: 28 | AV1: =29-'B-FCE'!AV3 -> 29 | AW1: =AS1+AU1 -> 317 | AX1: =AT1+AV1 -> 320 | AY1: 30 | AZ1: =31-'B-FCE'!AZ3 -> 29.779167 | BA1: =+AQ1+AU1+AY1 -> 88 | BB1: =+AR1+AV1+AZ1 -> 88.779167 | BC1: =+AM1+BA1 -> 177 | BD1: =+AN1+BB1 -> 178.82083 | BE1: =AW1+AY1 -> 347 | BF1: =AX1+AZ1 -> 349.77917
D2: 366 | E2: 30 | F2: 30 | G2: 31 | H2: 31 | I2: =+E2+G2 -> 61 | J2: =+F2+H2 -> 61 | K2: 30 | L2: 30 | M2: =+I2+K2 -> 91 | N2: =+J2+L2 -> 91 | O2: 31 | P2: 31 | Q2: =+M2+O2 -> 122 | R2: =+N2+P2 -> 122 | S2: 31 | T2: 31 | U2: =+Q2+S2 -> 153 | V2: =+R2+T2 -> 153 | W2: 30 | X2: 30 | Y2: =+O2+S2+W2 -> 92 | Z2: =+P2+T2+X2 -> 92 | AA2: =+U2+W2 -> 183 | AB2: =+V2+X2 -> 183 | AC2: 31 | AD2: 31 | AE2: =AA2+AC2 -> 214 | AF2: =AB2+AD2 -> 214 | AG2: 30 | AH2: 30 | AI2: =AE2+AG2 -> 244 | AJ2: =AF2+AH2 -> 244 | AK2: 31 | AL2: 31 | AM2: =+AC2+AG2+AK2 -> 92 | AN2: =+AD2+AH2+AL2 -> 92 | AO2: =AI2+AK2 -> 275 | AP2: =AJ2+AL2 -> 275 | AQ2: 31 | AR2: 31 | AS2: =AO2+AQ2 -> 306 | AT2: =AP2+AR2 -> 306 | AU2: 29 | AV2: 29 | AW2: =AS2+AU2 -> 335 | AX2: =AT2+AV2 -> 335 | AY2: 31 | AZ2: 31 | BA2: =+AQ2+AU2+AY2 -> 91 | BB2: =+AR2+AV2+AZ2 -> 91 | BC2: =+AM2+BA2 -> 183 | BD2: =+AN2+BB2 -> 183 | BE2: =AW2+AY2 -> 366 | BF2: =AX2+AZ2 -> 366 | BK2: 365 | BL2: 365 | BM2: 366 | BN2: 366
B3: ITEM | C3: Unit | D3: 2023-24 ABP | E3: Apr'23 | G3: May'23 | I3: 2M | K3: Jun'23 | M3: QTR-1 | O3: Jul'23 | Q3: 4M | S3: Aug'23 | U3: 5M | W3: Sep'23 | Y3: QTR 2 | AA3: H1 | AC3: Oct'23 | AE3: 7M | AG3: Nov'23 | AI3: 8M | AK3: Dec'23 | AM3: QTR 3 | AO3: 9M | AQ3: Jan'24 | AS3: 10M | AU3: Feb'24 | AW3: 11M | AY3: Mar'24 | BA3: QTR 4 | BC3: H2 | BE3: 2023-24 | BG3: 2022-23 | BI3: 2021-22 | BK3: 2020-21 | BM3: 2019-20
E4: ABP | F4: ACT | G4: ABP | H4: ACT | I4: ABP | J4: ACT | K4: ABP | L4: ACT | M4: ABP | N4: ACT | O4: ABP | P4: ACT | Q4: ABP | R4: ACT | S4: ABP | T4: ACT | U4: ABP | V4: ACT | W4: ABP | X4: ACT | Y4: ABP | Z4: ACT | AA4: ABP | AB4: ACT | AC4: ABP | AD4: ACT | AE4: ABP | AF4: ACT | AG4: ABP | AH4: ACT | AI4: ABP | AJ4: ACT | AK4: ABP | AL4: ACT | AM4: ABP | AN4: ACT | AO4: ABP | AP4: ACT | AQ4: ABP | AR4: ACT | AS4: ABP | AT4: ACT | AU4: ABP | AV4: ACT | AW4: ABP | AX4: ACT | AY4: ABP | AZ4: ACT | BA4: ABP | BB4: ACT | BC4: ABP | BD4: ACT | BE4: ABP | BF4: ACT | BG4: ABP | BH4: ACT | BI4: ABP | BJ4: ACT | BK4: ABP | BL4: ACT | BM4: ABP | BN4: ACT
B5: COKE OVENS PUSHING
B6: (COB#10) | C6: Nos/ day | D6: 99 | E6: 99 | F6: =+F9/F2 -> 99.133333 | G6: 99 | H6: =+H9/H2 -> 99.096774 | I6: =+((E6*$E$2)+(G6*$G$2))/$I$2 -> 99 | J6: =+((F6*$F$2)+(H6*$H$2))/$J$2 -> 99.114754 | K6: 99 | L6: =+L9/L2 -> 99.133333 | M6: =+((E6*$E$2)+(G6*$G$2)+(K6*$K$2))/$M$2 -> 99 | N6: =+((F6*$F$2)+(H6*$H$2)+(L6*$L$2))/$N$2 -> 99.120879 | O6: 99 | P6: =+P9/P2 -> 99.064516 | Q6: =+((M6*M$2)+(O6*O$2))/Q$2 -> 99 | R6: =+((N6*N$2)+(P6*P$2))/R$2 -> 99.106557 | S6: 99 | T6: =+T9/T2 -> 99.451613 | U6: =+((Q6*Q$2)+(S6*S$2))/U$2 -> 99 | V6: =+((R6*R$2)+(T6*T$2))/V$2 -> 99.176471 | W6: 99 | X6: =X9/X2 -> 99.1 | Y6: =+((O$6*O$1)+(S$6*S$1)+(W$6*W$1))/Y$1 -> 99 | Z6: =+((P$6*P$1)+(T$6*T$1)+(X$6*X$1))/Z$1 -> 99.209137 | AA6: =+((M6*M$2)+(Y6*Y$2))/AA$2 -> 99 | AB6: =+((N6*N$2)+(Z6*Z$2))/AB$2 -> 99.165249 | AC6: 99 | AD6: =+AD9/AD2 -> 97.677419 | AE6: =+((AA6*$AA$2)+(AC6*$AC$2))/$AE$2 -> 99 | AF6: =+((AB6*$AB$2)+(AD6*$AD$2))/$AF$2 -> 98.949722 | AG6: 99 | AH6: =+AH9/AH2 -> 99 | AI6: =+((AE6*$AE$2)+(AG6*$AG$2))/$AI$2 -> 99 | AJ6: =+((AF6*$AF$2)+(AH6*$AH$2))/$AJ$2 -> 98.955904 | AK6: 99 | AL6: =AL9/AL2 -> 99 | AM6: =+((AC$6*AC$1)+(AG$6*AG$1)+(AK$6*AK$1))/AM$1 -> 99 | AN6: =+((AD$6*AD$1)+(AH$6*AH$1)+(AL$6*AL$1))/AN$1 -> 98.552 | AO6: =+((AK6*$AK$2)+(AI6*$AI$2))/$AO$2 -> 99 | AP6: =+((AL6*$AL$2)+(AJ6*$AJ$2))/$AP$2 -> 98.960875 | AQ6: 99 | AR6: =+AR9/AR2 -> 99 | AS6: =+((AO6*$AO$2)+(AQ6*$AQ$2))/$AS$2 -> 99 | AT6: =+((AP6*$AP$2)+(AR6*$AR$2))/$AT$2 -> 98.964838 | AU6: 99 | AV6: =+AV9/AV2 -> 99 | AW6: =+((AS6*$AS$2)+(AU6*$AU$2))/$AW$2 -> 99 | AX6: =+((AT6*$AT$2)+(AV6*$AV$2))/$AX$2 -> 98.967882 | AY6: 99 | AZ6: =+AZ9/AZ2 -> 99.064516 | BA6: =+((AQ$6*AQ$1)+(AU$6*AU$1)+(AY$6*AY$1))/BA$1 -> 99 | BB6: =+((AR$6*AR$1)+(AV$6*AV$1)+(AZ$6*AZ$1))/BB$1 -> 99.021641 | BC6: =+((AM6*AM$2)+(BA6*BA$2))/BC$2 -> 99 | BD6: =+((AN6*AN$2)+(BB6*BB$2))/BD$2 -> 98.785537 | BE6: =+((AW6*$AW$2)+(AY6*$AY$2))/$BE$2 -> 99 | BF6: =+((AZ6*$AZ$2)+(AX6*$AX$2))/$BF$2 -> 98.976067 | BG6: 99 | BH6: 98.783562 | BI6: 99 | BJ6: 97.824658 | BK6: 95.547945 | BL6: 95.342466 | BM6: 97 | BN6: 97.10959
B7: (COB#11) | C7: Nos/ day | D7: 98 | E7: 98.333333 | F7: =+F10/F2 -> 97.8 | G7: 98.333333 | H7: =+H10/H2 -> 91.741935 | I7: =+((E7*$E$2)+(G7*$G$2))/$I$2 -> 98.333333 | J7: =+((F7*$F$2)+(H7*$H$2))/$J$2 -> 94.721311 | K7: 98.333333 | L7: =+L10/L2 -> 93.766667 | M7: =+((E7*$E$2)+(G7*$G$2)+(K7*$K$2))/$M$2 -> 98.333333 | N7: =+((F7*$F$2)+(H7*$H$2)+(L7*$L$2))/$N$2 -> 94.406593 | O7: 98.333333 | P7: =+P10/P2 -> 95.645161 | Q7: =+((M7*M$2)+(O7*O$2))/Q$2 -> 98.333333 | R7: =+((N7*N$2)+(P7*P$2))/R$2 -> 94.721311 | S7: 96.333333 | T7: =+T10/T2 -> 95.16129 | U7: =+((Q7*Q$2)+(S7*S$2))/U$2 -> 97.928105 | V7: =+((R7*R$2)+(T7*T$2))/V$2 -> 94.810458 | W7: 96.333333 | X7: =X10/X2 -> 96.033333 | Y7: =+((O$7*O$1)+(S$7*S$1)+(W$7*W$1))/Y$1 -> 97.007491 | Z7: =+((P$7*P$1)+(T$7*T$1)+(X$7*X$1))/Z$1 -> 95.601216 | AA7: =+((M7*M$2)+(Y7*Y$2))/AA$2 -> 97.666789 | AB7: =+((N7*N$2)+(Z7*Z$2))/AB$2 -> 95.007169 | AC7: 98.333333 | AD7: =+AD10/AD2 -> 97.806452 | AE7: =+((AA7*$AA$2)+(AC7*$AC$2))/$AE$2 -> 97.763345 | AF7: =+((AB7*$AB$2)+(AD7*$AD$2))/$AF$2 -> 95.412672 | AG7: 98.333333 | AH7: =+AH10/AH2 -> 97.333333 | AI7: =+((AE7*$AE$2)+(AG7*$AG$2))/$AI$2 -> 97.833425 | AJ7: =+((AF7*$AF$2)+(AH7*$AH$2))/$AJ$2 -> 95.648819 | AK7: 98.333333 | AL7: =AL10/AL2 -> 98.83871 | AM7: =+((AC$7*AC$1)+(AG$7*AG$1)+(AK$7*AK$1))/AM$1 -> 98.333333 | AN7: =+((AD$7*AD$1)+(AH$7*AH$1)+(AL$7*AL$1))/AN$1 -> 98.00421 | AO7: =+((AK7*$AK$2)+(AI7*$AI$2))/$AO$2 -> 97.889779 | AP7: =+((AL7*$AL$2)+(AJ7*$AJ$2))/$AP$2 -> 96.008407 | AQ7: 98.333333 | AR7: =+AR10/AR2 -> 98.612903 | AS7: =+((AO7*$AO$2)+(AQ7*$AQ$2))/$AS$2 -> 97.934714 | AT7: =+((AP7*$AP$2)+(AR7*$AR$2))/$AT$2 -> 96.272261 | AU7: 98.333333 | AV7: =+AV10/AV2 -> 98.758621 | AW7: =+((AS7*$AS$2)+(AU7*$AU$2))/$AW$2 -> 97.969221 | AX7: =+((AT7*$AT$2)+(AV7*$AV$2))/$AX$2 -> 96.487498 | AY7: 98.333333 | AZ7: =+AZ10/AZ2 -> 98.645161 | BA7: =+((AQ$7*AQ$1)+(AU$7*AU$1)+(AY$7*AY$1))/BA$1 -> 98.333333 | BB7: =+((AR$7*AR$1)+(AV$7*AV$1)+(AZ$7*AZ$1))/BB$1 -> 98.671323 | BC7: =+((AM7*AM$2)+(BA7*BA$2))/BC$2 -> 98.333333 | BD7: =+((AN7*AN$2)+(BB7*BB$2))/BD$2 -> 98.335943 | BE7: =+((AW7*$AW$2)+(AY7*$AY$2))/$BE$2 -> 98.000061 | BF7: =+((AZ7*$AZ$2)+(AX7*$AX$2))/$BF$2 -> 96.670251 | BG7: 99 | BH7: 92.210959 | BI7: 99 | BJ7: 96.816438 | BK7: 94.2 | BL7: 90.778082 | BM7: 97 | BN7: 95.710246
B8: Overall Equiv. Ovens Pushed/ Day | C8: Nos/ day | D8: =+D6+(D7*(31.55/17.2)) -> 278.76163 | E8: =+E6+(E7*(31.55/17.2)) -> 279.37306 | F8: =+F6+(F7*(31.55/17.2)) -> 278.5281 | G8: =+G6+(G7*(31.55/17.2)) -> 279.37306 | H8: =+H6+(H7*(31.55/17.2)) -> 267.37922 | I8: =+I6+(I7*(31.55/17.2)) -> 279.37306 | J8: =+J6+(J7*(31.55/17.2)) -> 272.86228 | K8: =+K6+(K7*(31.55/17.2)) -> 279.37306 | ... X8: =+X6+(X7*(31.55/17.2)) -> 275.25417 | Y8: =Y6+(Y7*31.55/17.2) -> 276.94107 | Z8: =Z6+(Z7*31.55/17.2) -> 274.57067 | AA8: =AA6+(AA7*31.55/17.2) -> 278.15042 | AB8: =AB6+(AB7*31.55/17.2) -> 273.43712 | AC8: =+AC6+(AC7*(31.55/17.2)) -> 279.37306 | AD8: =+AD6+(AD7*(31.55/17.2)) -> 277.08402 | AE8: =+AE6+(AE7*(31.55/17.2)) -> 278.32753 | AF8: =+AF6+(AF7*(31.55/17.2)) -> 273.96541 | AG8: =+AG6+(AG7*(31.55/17.2)) -> 279.37306 | AH8: =+AH6+(AH7*(31.55/17.2)) -> 277.53876 | AI8: =+AI6+(AI7*(31.55/17.2)) -> 278.45608 | AJ8: =+AJ6+(AJ7*(31.55/17.2)) -> 274.40476 | ... AL8: =+AL6+(AL7*(31.55/17.2)) -> 280.30008 | AM8: =AM6+(AM7*31.55/17.2) -> 279.37306 | AN8: =AN6+(AN7*31.55/17.2) -> 278.32135 | AO8: =+AO6+(AO7*(31.55/17.2)) -> 278.55945 | AP8: =+AP6+(AP7*(31.55/17.2)) -> 275.06932 | AQ8: =+AQ6+(AQ7*(31.55/17.2)) -> 279.37306 | AR8: =+AR6+(AR7*(31.55/17.2)) -> 279.88588 | AS8: =+AS6+(AS7*(31.55/17.2)) -> 278.64187 | AT8: =+AT6+(AT7*(31.55/17.2)) -> 275.55727 | AU8: =+AU6+(AU7*(31.55/17.2)) -> 279.37306 | AV8: =+AV6+(AV7*(31.55/17.2)) -> 280.15317 | ... AZ8: =+AZ6+(AZ7*(31.55/17.2)) -> 280.00956 | BA8: =BA6+(BA7*31.55/17.2) -> 279.37306 | BB8: =BB6+(BB7*31.55/17.2) -> 280.01468 | BC8: =BC6+(BC7*31.55/17.2) -> 279.37306 | BD8: =BD6+(BD7*31.55/17.2) -> 279.16339 | BE8: =+BE6+(BE7*(31.55/17.2)) -> 278.76174 | BF8: =+BF6+(BF7*(31.55/17.2)) -> 276.29853 | BG8: 280.59593 | BH8: 267.92634 | BI8: 280.59593 | BJ8: 275.41528 | BK8: 268.33922 | BL8: 261.85691 | BM8: 274.92733 | BN8: 272.67112
B9: (COB#10) | C9: Nos | D9: =+D6*D2 -> 36234 | E9: =+E6*E2 -> 2970 | F9: 2974 | G9: =+G6*G2 -> 3069 | H9: 3072 | I9: =+I6*I2 -> 6039 | J9: =+F9+H9 -> 6046 | K9: =+K6*K2 -> 2970 | L9: 2974 | M9: =+E9+G9+K9 -> 9009 | N9: =+F9+H9+L9 -> 9020 | O9: =+O6*O2 -> 3069 | P9: 3071 | Q9: =+M9+O9 -> 12078 | R9: =+N9+P9 -> 12091 | S9: =+S6*S2 -> 3069 | T9: 3083 | U9: =+Q9+S9 -> 15147 | V9: =+R9+T9 -> 15174 | W9: =+W6*W2 -> 2970 | X9: 2973 | Y9: =+O9+S9+W9 -> 9108 | Z9: =+P9+T9+X9 -> 9127 | AA9: =M9+Y9 -> 18117 | AB9: =+N9+Z9 -> 18147 | AC9: =+AC6*AC2 -> 3069 | AD9: 3028 | AE9: =+AE6*AE2 -> 21186 | AF9: =+AB9+AD9 -> 21175 | AG9: =+AG6*AG2 -> 2970 | AH9: 2970 | AI9: =+AI6*AI2 -> 24156 | AJ9: =+AF9+AH9 -> 24145 | AK9: =+AK6*AK2 -> 3069 | AL9: 3069 | AM9: =+AC9+AG9+AK9 -> 9108 | AN9: =+AD9+AH9+AL9 -> 9067 | AO9: =AI9+AK9 -> 27225 | AP9: =AJ9+AL9 -> 27214 | AQ9: =+AQ6*AQ2 -> 3069 | AR9: 3069 | AS9: =+AS6*AS2 -> 30294 | AT9: =+AP9+AR9 -> 30283 | AU9: =+AU6*AU2 -> 2871 | AV9: 2871 | AW9: =+AW6*AW2 -> 33165 | AX9: =+AT9+AV9 -> 33154 | AY9: =+AY6*AY2 -> 3069 | AZ9: 3071 | BA9: =+AQ9+AU9+AY9 -> 9009 | BB9: =+AR9+AV9+AZ9 -> 9011 | BC9: =AM9+BA9 -> 18117 | BD9: =AN9+BB9 -> 18078 | BE9: =AW9+AY9 -> 36234 | BF9: =AX9+AZ9 -> 36225 | BG9: 36135 | BH9: 36056 | BI9: 36135 | BJ9: 35706 | BK9: 34875 | BL9: 34800 | BM9: 35502 | BN9: 35543
B10: (COB#11) | C10: Nos | D10: =+D7*D2 -> 35868 | E10: =+E7*E2 -> 2950 | F10: 2934 | G10: =+G7*G2 -> 3048.3333 | H10: 2844 | I10: =+I7*I2 -> 5998.3333 | J10: =+F10+H10 -> 5778 | K10: =+K7*K2 -> 2950 | L10: 2813 | M10: =+E10+G10+K10 -> 8948.3333 | N10: =+F10+H10+L10 -> 8591 | O10: =+O7*O2 -> 3048.3333 | P10: 2965 | Q10: =+M10+O10 -> 11996.667 | R10: =+N10+P10 -> 11556 | S10: =+S7*S2 -> 2986.3333 | T10: 2950 | U10: =+Q10+S10 -> 14983 | V10: =+R10+T10 -> 14506 | W10: =+W7*W2 -> 2890 | X10: 2881 | Y10: =+O10+S10+W10 -> 8924.6667 | Z10: =+P10+T10+X10 -> 8796 | AA10: =+M10+Y10 -> 17873 | AB10: =+N10+Z10 -> 17387 | AC10: =+AC7*AC2 -> 3048.3333 | AD10: 3032 | AE10: =+AE7*AE2 -> 20921.356 | AF10: =+AB10+AD10 -> 20419 | AG10: =+AG7*AG2 -> 2950 | AH10: 2920 | AI10: =+AI7*AI2 -> 23871.356 | AJ10: =+AF10+AH10 -> 23339 | AK10: =+AK7*AK2 -> 3048.3333 | AL10: 3064 | AM10: =+AC10+AG10+AK10 -> 9046.6667 | AN10: =+AD10+AH10+AL10 -> 9016 | AO10: =AI10+AK10 -> 26919.689 | AP10: =AJ10+AL10 -> 26403 | AQ10: =+AQ7*AQ2 -> 3048.3333 | AR10: 3057 | AS10: =+AS7*AS2 -> 29968.022 | AT10: =+AP10+AR10 -> 29460 | AU10: =+AU7*AU2 -> 2851.6667 | AV10: 2864 | AW10: =+AW7*AW2 -> 32819.689 | AX10: =+AT10+AV10 -> 32324 | AY10: =+AY7*AY2 -> 3048.3333 | AZ10: 3058 | BA10: =+AQ10+AU10+AY10 -> 8948.3333 | BB10: =+AR10+AV10+AZ10 -> 8979 | BC10: =AM10+BA10 -> 17995 | BD10: =AN10+BB10 -> 17995 | BE10: =AW10+AY10 -> 35868.022 | BF10: =AX10+AZ10 -> 35382 | BG10: 36135 | BH10: 33657 | BI10: 36135 | BJ10: 35338 | BK10: 34383 | BL10: 33134 | BM10: 35502 | BN10: 35030
B11: Overall Equiv. Ovens Pushed | C11: Nos | D11: =+D9+(D10*(31.55/17.2)) -> 102026.76 | E11: =+E9+(E10*(31.55/17.2)) -> 8381.1919 | F11: =+F9+(F10*(31.55/17.2)) -> 8355.843 | G11: =+G9+(G10*(31.55/17.2)) -> 8660.5649 | H11: =+H9+(H10*(31.55/17.2)) -> 8288.7558 | I11: =+I9+(I10*(31.55/17.2)) -> 17041.757 | J11: =+J9+(J10*(31.55/17.2)) -> 16644.599 | K11: =+K9+(K10*(31.55/17.2)) -> 8381.1919 | ... X11: =+X9+(X10*(31.55/17.2)) -> 8257.625 | Y11: =Y9+(Y10*31.55/17.2) -> 25478.537 | Z11: =Z9+(Z10*31.55/17.2) -> 25261.523 | AA11: =AA9+(AA10*31.55/17.2) -> 50901.485 | AB11: =AB9+(AB10*31.55/17.2) -> 50040.015 | AC11: =+AC9+(AC10*(31.55/17.2)) -> 8660.5649 | AD11: =+AD9+(AD10*(31.55/17.2)) -> 8589.6047 | AE11: =+AE9+(AE10*(31.55/17.2)) -> 59562.092 | AF11: =+AF9+(AF10*(31.55/17.2)) -> 58629.619 | AG11: =+AG9+(AG10*(31.55/17.2)) -> 8381.1919 | AH11: =+AH9+(AH10*(31.55/17.2)) -> 8326.1628 | AI11: =+AI9+(AI10*(31.55/17.2)) -> 67943.283 | AJ11: =+AJ9+(AJ10*(31.55/17.2)) -> 66955.782 | ... AL11: =+AL9+(AL10*(31.55/17.2)) -> 8689.3023 | AM11: =AM9+(AM10*31.55/17.2) -> 25702.322 | AN11: =AN9+(AN10*31.55/17.2) -> 25605.07 | AO11: =+AO9+(AO10*(31.55/17.2)) -> 76603.848 | AP11: =+AP9+(AP10*(31.55/17.2)) -> 75645.084 | AQ11: =+AQ9+(AQ10*(31.55/17.2)) -> 8660.5649 | AR11: =+AR9+(AR10*(31.55/17.2)) -> 8676.4622 | AS11: =+AS9+(AS10*(31.55/17.2)) -> 85264.413 | AT11: =+AT9+(AT10*(31.55/17.2)) -> 84321.547 | AU11: =+AU9+(AU10*(31.55/17.2)) -> 8101.8188 | AV11: =+AV9+(AV10*(31.55/17.2)) -> 8124.4419 | ... AZ11: =+AZ9+(AZ10*(31.55/17.2)) -> 8680.2965 | BA11: =BA9+(BA10*31.55/17.2) -> 25422.949 | BB11: =BB9+(BB10*31.55/17.2) -> 25481.201 | BC11: =BC9+(BC10*31.55/17.2) -> 51125.27 | BD11: =BD9+(BD10*31.55/17.2) -> 51086.27 | BE11: =+BE9+(BE10*(31.55/17.2)) -> 102026.8 | BF11: =+BF9+(BF10*(31.55/17.2)) -> 101126.28 | BG11: 102417.51 | BH11: 97793.113 | BI11: 102417.51 | BJ11: 100526.58 | BK11: 97943.817 | BL11: 95577.773 | BM11: 100623.4 | BN11: 99798.61
B12: BF COKE
B13: COB#10 | C13: Mt | D13: =+D9*0.695*17.2 -> 433141.24 | E13: =+E9*0.695*17.2 -> 35503.38 | F13: ='COKE OVENS'!F17 -> 35508.019 | G13: =+G9*0.695*17.2 -> 36686.826 | H13: ='COKE OVENS'!H17 -> 36403.897 | I13: =+E13+G13 -> 72190.206 | J13: =+F13+H13 -> 71911.915 | K13: =+K9*0.695*17.2 -> 35503.38 | L13: ='COKE OVENS'!L17 -> 35495.568 | M13: =+E13+G13+K13 -> 107693.59 | N13: =+F13+H13+L13 -> 107407.48 | O13: =+O9*0.695*17.2 -> 36686.826 | P13: ='COKE OVENS'!P17 -> 36666.024 | Q13: =+M13+O13 -> 144380.41 | R13: =+N13+P13 -> 144073.51 | S13: =+S9*0.695*17.2 -> 36686.826 | T13: ='COKE OVENS'!T17 -> 36801.599 | U13: =+Q13+S13 -> 181067.24 | V13: =+R13+T13 -> 180875.11 | W13: =+W9*0.695*17.2 -> 35503.38 | X13: ='COKE OVENS'!X17 -> 35479.971 | Y13: =+O13+S13+W13 -> 108877.03 | Z13: =+P13+T13+X13 -> 108947.59 | AA13: =+M13+Y13 -> 216570.62 | AB13: =+N13+Z13 -> 216355.08 | AC13: =+AC9*0.695*17.2 -> 36686.826 | AD13: ='COKE OVENS'!AD17 -> 36145.99 | AE13: =+AA13+AC13 -> 253257.44 | AF13: =+AB13+AD13 -> 252501.07 | AG13: =+AG9*0.695*17.2 -> 35503.38 | AH13: ='COKE OVENS'!AH17 -> 35697.791 | AI13: =+AE13+AG13 -> 288760.82 | AJ13: =+AF13+AH13 -> 288198.86 | AK13: =+AK9*0.695*17.2 -> 36686.826 | AL13: ='COKE OVENS'!AL17 -> 36631.214 | AM13: =+AC13+AG13+AK13 -> 108877.03 | AN13: =+AD13+AH13+AL13 -> 108475 | AO13: =AI13+AK13 -> 325447.65 | AP13: =AJ13+AL13 -> 324830.07 | AQ13: =+AQ9*0.695*17.2 -> 36686.826 | AR13: ='COKE OVENS'!AR17 -> 36627.85 | AS13: =+AO13+AQ13 -> 362134.48 | AT13: =+AP13+AR13 -> 361457.92 | AU13: =+AU9*0.695*17.2 -> 34319.934 | AV13: ='COKE OVENS'!AV17 -> 34268.545 | AW13: =+AS13+AU13 -> 396454.41 | AX13: =+AT13+AV13 -> 395726.47 | AY13: =+AY9*0.695*17.2 -> 36686.826 | AZ13: ='COKE OVENS'!AZ17 -> 36656.379 | BA13: =+AQ13+AU13+AY13 -> 107693.59 | BB13: =+AR13+AV13+AZ13 -> 107552.77 | BC13: =AM13+BA13 -> 216570.62 | BD13: =AN13+BB13 -> 216027.77 | BE13: =AW13+AY13 -> 433141.24 | BF13: =AX13+AZ13 -> 432382.85 | BG13: 431957.79 | BH13: 430769.03 | BI13: 438172.79 | BJ13: 428806 | BK13: 425506 | BL13: 430922.2 | BM13: 406071.88 | BN13: 412610.14
B14: COB#11 | C14: Mt | D14: =+D10*0.695*31.55 -> 786486.6 | E14: =+E10*31.55*0.695 -> 64685.387 | F14: ='COKE OVENS'!F18 -> 64256.416 | G14: =+G10*31.55*0.695 -> 66841.567 | H14: ='COKE OVENS'!H18 -> 61819.739 | I14: =+E14+G14 -> 131526.95 | J14: =+F14+H14 -> 126076.16 | K14: =+K10*31.55*0.695 -> 64685.387 | L14: ='COKE OVENS'!L18 -> 61584.84 | M14: =+E14+G14+K14 -> 196212.34 | N14: =+F14+H14+L14 -> 187661 | O14: =+O10*31.55*0.695 -> 66841.567 | P14: ='COKE OVENS'!P18 -> 64935.116 | Q14: =+M14+O14 -> 263053.91 | R14: =+N14+P14 -> 252596.11 | S14: =+S10*31.55*0.695 -> 65482.078 | T14: ='COKE OVENS'!T18 -> 64593.095 | U14: =+Q14+S14 -> 328535.99 | V14: =+R14+T14 -> 317189.21 | W14: =+W10*31.55*0.695 -> 63369.752 | X14: ='COKE OVENS'!X18 -> 63067.05 | Y14: =+O14+S14+W14 -> 195693.4 | Z14: =+P14+T14+X14 -> 192595.26 | AA14: =+M14+Y14 -> 391905.74 | AB14: =+N14+Z14 -> 380256.26 | AC14: =+AC10*31.55*0.695 -> 66841.567 | AD14: ='COKE OVENS'!AD18 -> 66390.26 | AE14: =+AA14+AC14 -> 458747.31 | AF14: =+AB14+AD14 -> 446646.52 | AG14: =+AG10*31.55*0.695 -> 64685.387 | AH14: ='COKE OVENS'!AH18 -> 64378.175 | AI14: =+AE14+AG14 -> 523432.69 | AJ14: =+AF14+AH14 -> 511024.69 | AK14: =+AK10*31.55*0.695 -> 66841.567 | AL14: ='COKE OVENS'!AL18 -> 67083.252 | AM14: =+AC14+AG14+AK14 -> 198368.52 | AN14: =+AD14+AH14+AL14 -> 197851.69 | AO14: =AI14+AK14 -> 590274.26 | AP14: =AJ14+AL14 -> 578107.94 | AQ14: =+AQ10*31.55*0.695 -> 66841.567 | AR14: ='COKE OVENS'!AR18 -> 66923.846 | AS14: =+AO14+AQ14 -> 657115.83 | AT14: =+AP14+AR14 -> 645031.79 | AU14: =+AU10*31.55*0.695 -> 62529.208 | AV14: ='COKE OVENS'!AV18 -> 62705.61 | AW14: =+AS14+AU14 -> 719645.04 | AX14: =+AT14+AV14 -> 707737.4 | AY14: =+AY10*31.55*0.695 -> 66841.567 | AZ14: ='COKE OVENS'!AZ18 -> 66954.249 | BA14: =+AQ14+AU14+AY14 -> 196212.34 | BB14: =+AR14+AV14+AZ14 -> 196583.71 | BC14: =AM14+BA14 -> 394580.86 | BD14: =AN14+BB14 -> 394435.39 | BE14: =AW14+AY14 -> 786486.6 | BF14: =AX14+AZ14 -> 774691.65 | BG14: 792341.18 | BH14: 737579.38 | BI14: 803741.8 | BJ14: 778192 | BK14: 770203 | BL14: 752591.4 | BM14: 744858.59 | BN14: 745859.84
B15: Total BF COKE | C15: Mt | D15: =SUM(D13:D14) -> 1219627.8 | E15: =SUM(E13:E14) -> 100188.77 | F15: =SUM(F13:F14) -> 99764.435 | G15: =SUM(G13:G14) -> 103528.39 | H15: =SUM(H13:H14) -> 98223.636 | I15: =SUM(I13:I14) -> 203717.16 | J15: =SUM(J13:J14) -> 197988.07 | K15: =SUM(K13:K14) -> 100188.77 | ... BF15: =SUM(BF13:BF14) -> 1207074.5 | BG15: 1224299 | BH15: 1168348.4 | BI15: 1241914.6 | BJ15: 1206998 | BK15: 1195709 | BL15: 1183513.6 | BM15: 1150930.5 | BN15: 1158470
B16: SINTER | C16: Mt | D16: =4499.99991230893*1000 -> 4499999.9 | E16: =377.584105466039*1000 -> 377584.11 | F16: 384170 | G16: =306.849799901736*1000 -> 306849.8 | H16: 311568 | I16: =+E16+G16 -> 684433.91 | J16: =+F16+H16 -> 695738 | K16: =312.959344062177*1000 -> 312959.34 | L16: 329870 | M16: =+E16+G16+K16 -> 997393.25 | N16: =+F16+H16+L16 -> 1025608 | O16: =386.18051358637*1000 -> 386180.51 | P16: 386985 | Q16: =+M16+O16 -> 1383573.8 | R16: =+N16+P16 -> 1412593 | S16: 386180.51 | T16: 373273 | U16: =+Q16+S16 -> 1769754.3 | V16: =+R16+T16 -> 1785866 | W16: 375455.56 | X16: 373826 | Y16: =+O16+S16+W16 -> 1147816.6 | Z16: =+P16+T16+X16 -> 1134084 | AA16: =+M16+Y16 -> 2145209.8 | AB16: =+N16+Z16 -> 2159692 | AC16: =392.905465867142*1000 -> 392905.47 | AD16: 395455 | AE16: =+AA16+AC16 -> 2538115.3 | AF16: =+AB16+AD16 -> 2555147 | AG16: =384.648377546259*1000 -> 384648.38 | AH16: 372411 | AI16: =+AE16+AG16 -> 2922763.7 | AJ16: =+AF16+AH16 -> 2927558 | AK16: =398.437601907252*1000 -> 398437.6 | AL16: 378682 | AM16: =+AC16+AG16+AK16 -> 1175991.4 | AN16: =+AD16+AH16+AL16 -> 1146548 | AO16: =AI16+AK16 -> 3321201.3 | AP16: =AJ16+AL16 -> 3306240 | AQ16: 402437.6 | AR16: 359440 | AS16: =+AO16+AQ16 -> 3723638.9 | AT16: =+AP16+AR16 -> 3665680 | AU16: 372391.29 | AV16: 372508 | AW16: =+AS16+AU16 -> 4096030.2 | AX16: =+AT16+AV16 -> 4038188 | AY16: 403969.74 | AZ16: 360257 | BA16: =+AQ16+AU16+AY16 -> 1178798.6 | BB16: =+AR16+AV16+AZ16 -> 1092205 | BC16: =AM16+BA16 -> 2354790.1 | BD16: =AN16+BB16 -> 2238753 | BE16: =AW16+AY16 -> 4499999.9 | BF16: =AX16+AZ16 -> 4398445 | BG16: 4270000.1 | BH16: 4395665 | BI16: 4183927.8 | BJ16: 4277831 | BK16: 3665891.3 | BL16: 3629577 | BM16: 3903932.5 | BN16: 3709525
B17: HOT METAL | C17: Mt | D17: =2800*1000 -> 2800000 | E17: =236*1000 -> 236000 | F17: 231705 | G17: 197000 | H17: 186324.9 | I17: =+E17+G17 -> 433000 | J17: =+F17+H17 -> 418029.9 | K17: 201000 | L17: 213361 | M17: =+E17+G17+K17 -> 634000 | N17: =+F17+H17+L17 -> 631390.9 | O17: 239000 | P17: 245255 | Q17: =+M17+O17 -> 873000 | R17: =+N17+P17 -> 876645.9 | S17: 239000 | T17: 240285 | U17: =+Q17+S17 -> 1112000 | V17: =+R17+T17 -> 1116930.9 | W17: 232000 | X17: 229120 | Y17: =+O17+S17+W17 -> 710000 | Z17: =+P17+T17+X17 -> 714660 | AA17: =+M17+Y17 -> 1344000 | AB17: =+N17+Z17 -> 1346050.9 | AC17: =246*1000 -> 246000 | AD17: 243314 | AE17: =+AA17+AC17 -> 1590000 | AF17: =+AB17+AD17 -> 1589364.9 | AG17: 238000 | AH17: 206094 | AI17: =+AE17+AG17 -> 1828000 | AJ17: =+AF17+AH17 -> 1795458.9 | AK17: 247000 | AL17: 228212.7 | AM17: =+AC17+AG17+AK17 -> 731000 | AN17: =+AD17+AH17+AL17 -> 677620.7 | AO17: =AI17+AK17 -> 2075000 | AP17: =AJ17+AL17 -> 2023671.6 | AQ17: 247000 | AR17: 232525.2 | AS17: =+AO17+AQ17 -> 2322000 | AT17: =+AP17+AR17 -> 2256196.8 | AU17: 230000 | AV17: 230199.2 | AW17: =+AS17+AU17 -> 2552000 | AX17: =+AT17+AV17 -> 2486396 | AY17: 248000 | AZ17: 234872.1 | BA17: =+AQ17+AU17+AY17 -> 725000 | BB17: =+AR17+AV17+AZ17 -> 697596.5 | BC17: =AM17+BA17 -> 1456000 | BD17: =AN17+BB17 -> 1375217.2 | BE17: =AW17+AY17 -> 2800000 | BF17: =AX17+AZ17 -> 2721268.1 | BG17: 2680000 | BH17: 2592119.6 | BI17: 2650001 | BJ17: 2406785.7 | BK17: 2496672.2 | BL17: 2092798 | BM17: 2700000 | BN17: 2505193
B18: CRUDE STEEL | C18: Mt | D18: =2620.07547169811*1000 -> 2620075.5 | E18: =221.509433962264*1000 -> 221509.43 | F18: 215539 | G18: =184.716981132075*1000 -> 184716.98 | H18: 175895 | I18: =+E18+G18 -> 406226.42 | J18: =+F18+H18 -> 391434 | K18: =180.641509433962*1000 -> 180641.51 | L18: 187063 | M18: =+E18+G18+K18 -> 586867.92 | N18: =+F18+H18+L18 -> 578497 | O18: =224.339622641509*1000 -> 224339.62 | P18: 230148 | Q18: =+M18+O18 -> 811207.55 | R18: =+N18+P18 -> 808645 | S18: 224339.62 | T18: 224642 | U18: =+Q18+S18 -> 1035547.2 | V18: =+R18+T18 -> 1033287 | W18: 217735.85 | X18: 210766 | Y18: =+O18+S18+W18 -> 666415.09 | Z18: =+P18+T18+X18 -> 665556 | AA18: =+M18+Y18 -> 1253283 | AB18: =+N18+Z18 -> 1244053 | AC18: =230.943396226415*1000 -> 230943.4 | AD18: 223439 | AE18: =+AA18+AC18 -> 1484226.4 | AF18: =+AB18+AD18 -> 1467492 | AG18: =223.396226415094*1000 -> 223396.23 | AH18: 192334 | AI18: =+AE18+AG18 -> 1707622.6 | AJ18: =+AF18+AH18 -> 1659826 | AK18: =231.88679245283*1000 -> 231886.79 | AL18: 217585 | AM18: =+AC18+AG18+AK18 -> 686226.42 | AN18: =+AD18+AH18+AL18 -> 633358 | AO18: =AI18+AK18 -> 1939509.4 | AP18: =AJ18+AL18 -> 1877411 | AQ18: 231886.79 | AR18: 217679 | AS18: =+AO18+AQ18 -> 2171396.2 | AT18: =+AP18+AR18 -> 2095090 | AU18: 215849.06 | AV18: 214408 | AW18: =+AS18+AU18 -> 2387245.3 | AX18: =+AT18+AV18 -> 2309498 | AY18: =232.830188679245*1000 -> 232830.19 | AZ18: 219427 | BA18: =+AQ18+AU18+AY18 -> 680566.04 | BB18: =+AR18+AV18+AZ18 -> 651514 | BC18: =AM18+BA18 -> 1366792.5 | BD18: =AN18+BB18 -> 1284872 | BE18: =AW18+AY18 -> 2620075.5 | BF18: =AX18+AZ18 -> 2528925 | BG18: 2500000 | BH18: 2422324.3 | BI18: 2451737.7 | BJ18: 2227867 | BK18: 2297163.5 | BL18: 1847433 | BM18: 2500000 | BN18: 2083412
B19: Avg Heats Cast per Day | C19: Nos. / day | D19: =D49/D1 -> 50.337665 | E19: =+E49/E1 -> 50.921709 | F19: =+F49/F1 -> 48.881356 | G19: =+G49/G1 -> 49.257862 | H19: =+H49/H1 -> 43.670295 | I19: =+I49/I1 -> 50.151409 | J19: =+J49/J1 -> 46.401184 | K19: =+K49/K1 -> 44.602842 | L19: =+L49/L1 -> 50.671164 | ... BF19: =+BF49/BF1 -> 48.130368 | BG19: 46.816479 | BH19: 45.269663 | BI19: 44.780041 | BJ19: 40.065753 | BK19: 41.920046 | BL19: 33.309589 | BM19: 47.014645 | BN19: 38.663934
B20: Cold Pig & Pig Equivalent
B21: MOG | C21: Mt | D21: 19561 | E21: 1160.8961 | F21: 302.9961 | G21: =1.16089613034623*1000 -> 1160.8961 | H21: 888.9555 | I21: =+E21+G21 -> 2321.7923 | J21: =+F21+H21 -> 1191.9516 | K21: =6.79124236252546*1000 -> 6791.2424 | L21: 5386.3191 | M21: =+E21+G21+K21 -> 9113.0346 | N21: =+F21+H21+L21 -> 6578.2707 | O21: =1.16089613034623*1000 -> 1160.8961 | P21: 151.0807 | Q21: =+M21+O21 -> 10273.931 | R21: =+N21+P21 -> 6729.3514 | S21: 1160.8961 | T21: 0 | U21: =+Q21+S21 -> 11434.827 | V21: =+R21+T21 -> 6729.3514 | W21: 1160.8961 | X21: 0 | Y21: =+O21+S21+W21 -> 3482.6884 | Z21: =+P21+T21+X21 -> 151.0807 | AA21: =+M21+Y21 -> 12595.723 | AB21: =+N21+Z21 -> 6729.3514 | AC21: 1160.8961 | AD21: 0 | AE21: =+AA21+AC21 -> 13756.619 | AF21: =+AB21+AD21 -> 6729.3514 | AG21: 1160.8961 | AH21: 397.3172 | AI21: =+AE21+AG21 -> 14917.515 | AJ21: =+AF21+AH21 -> 7126.6686 | AK21: =1.16089613034623*1000 -> 1160.8961 | AL21: 145.2378 | AM21: =+AC21+AG21+AK21 -> 3482.6884 | AN21: =+AD21+AH21+AL21 -> 542.555 | AO21: =AI21+AK21 -> 16078.411 | AP21: =AJ21+AL21 -> 7271.9064 | AQ21: 1160.8961 | AR21: 0 | AS21: =+AO21+AQ21 -> 17239.308 | AT21: =+AP21+AR21 -> 7271.9064 | AU21: 1160.8961 | AV21: 0 | AW21: =+AS21+AU21 -> 18400.204 | AX21: =+AT21+AV21 -> 7271.9064 | AY21: =1.16089613034623*1000 -> 1160.8961 | AZ21: 276.36917 | BA21: =+AQ21+AU21+AY21 -> 3482.6884 | BB21: =+AR21+AV21+AZ21 -> 276.36917 | BC21: =AM21+BA21 -> 6965.3768 | BD21: =AN21+BB21 -> 818.92417 | BE21: =AW21+AY21 -> 19561.1 | BF21: =AX21+AZ21 -> 7548.2756 | BG21: 16929.735 | BH21: 9129.3344 | BI21: 19735.515 | BJ21: 22361.072 | BK21: 20755.018 | BL21: 58220.7 | BM21: 29957.856 | BN21: 134629.18
A22: 1000 | B22: UPIS | C22: Mt | D22: 0 | E22: 0 | F22: 42.77592 | G22: 0 | H22: 125.4996 | I22: =+E22+G22 -> 0 | J22: =+F22+H22 -> 168.27552 | K22: 0 | L22: 760.42152 | M22: =+E22+G22+K22 -> 0 | N22: =+F22+H22+L22 -> 928.69704 | O22: 0 | P22: 21.32904 | Q22: =+M22+O22 -> 0 | R22: =+N22+P22 -> 950.02608 | S22: 0 | T22: 0 | U22: =+Q22+S22 -> 0 | V22: =+R22+T22 -> 950.02608 | W22: 0 | X22: 0 | Y22: =+O22+S22+W22 -> 0 | Z22: =+P22+T22+X22 -> 21.32904 | AA22: =+M22+Y22 -> 0 | AB22: =+N22+Z22 -> 950.02608 | AC22: 0 | AD22: 0 | AE22: =+AA22+AC22 -> 0 | AF22: =+AB22+AD22 -> 950.02608 | AG22: 0 | AH22: 56.09184 | AI22: =+AE22+AG22 -> 0 | AJ22: =+AF22+AH22 -> 1006.1179 | AK22: 0 | AL22: 20.50416 | AM22: =+AC22+AG22+AK22 -> 0 | AN22: =+AD22+AH22+AL22 -> 76.596 | AO22: =AI22+AK22 -> 0 | AP22: =AJ22+AL22 -> 1026.6221 | AQ22: 0 | AR22: 0 | AS22: =+AO22+AQ22 -> 0 | AT22: =+AP22+AR22 -> 1026.6221 | AU22: 0 | AV22: 0 | AW22: =+AS22+AU22 -> 0 | AX22: =+AT22+AV22 -> 1026.6221 | AY22: 0 | AZ22: 0 | BA22: =+AQ22+AU22+AY22 -> 0 | BB22: =+AR22+AV22+AZ22 -> 0 | BC22: =AM22+BA22 -> 0 | BD22: =AN22+BB22 -> 76.596 | BE22: =AW22+AY22 -> 0 | BF22: =AX22+AZ22 -> 1026.6221 | BG22: 0 | BH22: 2541.6495 | BI22: 0 | BJ22: 2774.7649 | BK22: 392 | BL22: 3852.3 | BM22: 1419.0563 | BN22: 8272.9783
B23: (Equiv. Pig Iron @ 80% of HM sent to Sand Pit. (Ref to Fax Msg from ED (O), vide SAIL/OPRNS/ PPMS/33 dt. 05.02.15) | C23: Mt | D23: 2000 | E23: 0 | F23: 0 | G23: 0 | H23: 0 | I23: =+E23+G23 -> 0 | J23: =+F23+H23 -> 0 | K23: 2000 | L23: 5022 | M23: =+E23+G23+K23 -> 2000 | N23: =+F23+H23+L23 -> 5022 | O23: 0 | P23: 0 | Q23: =+M23+O23 -> 2000 | R23: =+N23+P23 -> 5022 | S23: 0 | T23: 0 | U23: =+Q23+S23 -> 2000 | V23: =+R23+T23 -> 5022 | W23: 0 | X23: 0 | Y23: =+O23+S23+W23 -> 0 | Z23: =+P23+T23+X23 -> 0 | AA23: =+M23+Y23 -> 2000 | AB23: =+N23+Z23 -> 5022 | AC23: 0 | AD23: 0 | AE23: =+AA23+AC23 -> 2000 | AF23: =+AB23+AD23 -> 5022 | AG23: 0 | AH23: 0 | AI23: =+AE23+AG23 -> 2000 | AJ23: =+AF23+AH23 -> 5022 | AK23: 0 | AL23: 0 | AM23: =+AC23+AG23+AK23 -> 0 | AN23: =+AD23+AH23+AL23 -> 0 | AO23: =AI23+AK23 -> 2000 | AP23: =AJ23+AL23 -> 5022 | AQ23: 0 | AR23: 0 | AS23: =+AO23+AQ23 -> 2000 | AT23: =+AP23+AR23 -> 5022 | AU23: 0 | AV23: 0 | AW23: =+AS23+AU23 -> 2000 | AX23: =+AT23+AV23 -> 5022 | AY23: 0 | AZ23: 0 | BA23: =+AQ23+AU23+AY23 -> 0 | BB23: =+AR23+AV23+AZ23 -> 0 | BC23: =AM23+BA23 -> 0 | BD23: =AN23+BB23 -> 0 | BE23: =AW23+AY23 -> 2000 | BF23: =AX23+AZ23 -> 5022 | BG23: 6000 | BH23: 4664.8 | BI23: 14800 | BJ23: 9214.4 | BK23: 0 | BL23: 0 | BM23: 0 | BN23: 26220.8
B24: TOTAL EQUIVALENT PIG IRON | C24: Mt | D24: =SUM(D21:D23) -> 21561 | E24: =SUM(E21:E23) -> 1160.8961 | F24: =SUM(F21:F23) -> 345.77202 | G24: =SUM(G21:G23) -> 1160.8961 | H24: =SUM(H21:H23) -> 1014.4551 | I24: =SUM(I21:I23) -> 2321.7923 | J24: =SUM(J21:J23) -> 1360.2271 | K24: =SUM(K21:K23) -> 8791.2424 | ... BF24: =SUM(BF21:BF23) -> 13596.898 | BG24: 22929.735 | BH24: 16335.784 | BI24: 34535.515 | BJ24: 34350.237 | BK24: 21147.018 | BL24: 62073 | BM24: 31376.912 | BN24: 169122.96
B25: Net PCI Production | C25: Mt | D25: 2377.872 | E25: 141.12 | F25: 226.856 | G25: 141.12 | H25: 721 | I25: =+E25+G25 -> 282.24 | J25: =+F25+H25 -> 947.856 | K25: 825.552 | L25: 1000 | M25: =+E25+G25+K25 -> 1107.792 | N25: =+F25+H25+L25 -> 1947.856 | O25: 141.12 | P25: 1119.16 | Q25: =+M25+O25 -> 1248.912 | R25: =+N25+P25 -> 3067.016 | S25: 141.12 | T25: 1304.1 | U25: =+Q25+S25 -> 1390.032 | V25: =+R25+T25 -> 4371.116 | W25: 141.12 | X25: 670.208 | Y25: =+O25+S25+W25 -> 423.36 | Z25: =+P25+T25+X25 -> 3093.468 | AA25: =+M25+Y25 -> 1531.152 | AB25: =+N25+Z25 -> 5041.324 | AC25: 141.12 | AD25: 763.147 | AE25: =+AA25+AC25 -> 1672.272 | AF25: =+AB25+AD25 -> 5804.471 | AG25: 141.12 | AH25: 0 | AI25: =+AE25+AG25 -> 1813.392 | AJ25: =+AF25+AH25 -> 5804.471 | AK25: 141.12 | AL25: 0 | AM25: =+AC25+AG25+AK25 -> 423.36 | AN25: =+AD25+AH25+AL25 -> 763.147 | AO25: =AI25+AK25 -> 1954.512 | AP25: =AJ25+AL25 -> 5804.471 | AQ25: 141.12 | AR25: 110.775 | AS25: =+AO25+AQ25 -> 2095.632 | AT25: =+AP25+AR25 -> 5915.246 | AU25: 141.12 | AV25: 0 | AW25: =+AS25+AU25 -> 2236.752 | AX25: =+AT25+AV25 -> 5915.246 | AY25: 141.12 | AZ25: 226.149 | BA25: =+AQ25+AU25+AY25 -> 423.36 | BB25: =+AR25+AV25+AZ25 -> 336.924 | BC25: =AM25+BA25 -> 846.72 | BD25: =AN25+BB25 -> 1100.071 | BE25: =AW25+AY25 -> 2377.872 | BF25: =AX25+AZ25 -> 6141.395 | BG25: 2057.6 | BH25: 5885.734 | BI25: 2398.56 | BJ25: 13377.679 | BK25: 11568.99 | BL25: 41093.9 | BM25: 0 | BN25: 44255.19
B26: Net Granulated Slag Production | C26: Mt | D26: 1063047 | E26: 89599.675 | F26: 104981.63 | G26: 74792.949 | H26: 89191.765 | I26: =+E26+G26 -> 164392.62 | J26: =+F26+H26 -> 194173.39 | K26: 76311.588 | L26: 82961.954 | M26: =+E26+G26+K26 -> 240704.21 | N26: =+F26+H26+L26 -> 277135.35 | O26: 90738.654 | P26: 104404.72 | Q26: =+M26+O26 -> 331442.87 | R26: =+N26+P26 -> 381540.07 | S26: 90738.654 | T26: 120487.19 | U26: =+Q26+S26 -> 422181.52 | V26: =+R26+T26 -> 502027.26 | W26: 88081.037 | X26: 99564.148 | Y26: =+O26+S26+W26 -> 269558.35 | Z26: =+P26+T26+X26 -> 324456.06 | AA26: =+M26+Y26 -> 510262.56 | AB26: =+N26+Z26 -> 601591.41 | AC26: 93396.272 | AD26: 103143.64 | AE26: =+AA26+AC26 -> 603658.83 | AF26: =+AB26+AD26 -> 704735.05 | AG26: 90358.995 | AH26: 82013.501 | AI26: =+AE26+AG26 -> 694017.83 | AJ26: =+AF26+AH26 -> 786748.55 | AK26: 93775.932 | AL26: 71167.549 | AM26: =+AC26+AG26+AK26 -> 277531.2 | AN26: =+AD26+AH26+AL26 -> 256324.69 | AO26: =AI26+AK26 -> 787793.76 | AP26: =AJ26+AL26 -> 857916.1 | AQ26: 93775.932 | AR26: 58850.349 | AS26: =+AO26+AQ26 -> 881569.69 | AT26: =+AP26+AR26 -> 916766.45 | AU26: 87321.718 | AV26: 76969.95 | AW26: =+AS26+AU26 -> 968891.41 | AX26: =+AT26+AV26 -> 993736.4 | AY26: 94155.591 | AZ26: 81508.241 | BA26: =+AQ26+AU26+AY26 -> 275253.24 | BB26: =+AR26+AV26+AZ26 -> 217328.54 | BC26: =AM26+BA26 -> 552784.44 | BD26: =AN26+BB26 -> 473653.23 | BE26: =AW26+AY26 -> 1063047 | BF26: =AX26+AZ26 -> 1075244.6 | BG26: 887402.68 | BH26: 1065593 | BI26: 157305.12 | BJ26: 920129.3 | BK26: 882599.97 | BL26: 776699 | BM26: 854658 | BN26: 809638.21
B27: Saleable Steel Production (Mill Wise)
B28: WR Mill | C28: Mt | D28: 500000 | E28: =42.5*1000 -> 42500 | F28: =+WRM!F125 -> 38790.1 | G28: =36.5*1000 -> 36500 | H28: =+WRM!H125 -> 31436.75 | I28: =+E28+G28 -> 79000 | J28: =+F28+H28 -> 70226.85 | K28: 34000 | L28: =+WRM!L125 -> 32975.4 | M28: =+E28+G28+K28 -> 113000 | N28: =+F28+H28+L28 -> 103202.25 | O28: =43.5*1000 -> 43500 | P28: =+WRM!P125 -> 41411.41 | Q28: =+M28+O28 -> 156500 | R28: =+N28+P28 -> 144613.66 | S28: 43500 | T28: =+WRM!T125 -> 46120.9 | U28: =+Q28+S28 -> 200000 | V28: =+R28+T28 -> 190734.56 | W28: 42500 | X28: 44910.375 | Y28: =+O28+S28+W28 -> 129500 | Z28: =+P28+T28+X28 -> 132442.69 | AA28: =+M28+Y28 -> 242500 | AB28: =+N28+Z28 -> 235644.94 | AC28: =43.5*1000 -> 43500 | AD28: 42767.05 | AE28: =+AA28+AC28 -> 286000 | AF28: =+AB28+AD28 -> 278411.99 | AG28: =42.5*1000 -> 42500 | AH28: 40266.1 | AI28: =+AE28+AG28 -> 328500 | AJ28: =+AF28+AH28 -> 318678.09 | AK28: =43.5*1000 -> 43500 | AL28: 41541.2 | AM28: =+AC28+AG28+AK28 -> 129500 | AN28: =+AD28+AH28+AL28 -> 124574.35 | AO28: =AI28+AK28 -> 372000 | AP28: =AJ28+AL28 -> 360219.29 | AQ28: 43500 | AR28: 43760.85 | AS28: =+AO28+AQ28 -> 415500 | AT28: =+AP28+AR28 -> 403980.14 | AU28: 41000 | AV28: 36414.15 | AW28: =+AS28+AU28 -> 456500 | AX28: =+AT28+AV28 -> 440394.29 | AY28: 43500 | AZ28: 38134.1 | BA28: =+AQ28+AU28+AY28 -> 128000 | BB28: =+AR28+AV28+AZ28 -> 118309.1 | BC28: =AM28+BA28 -> 257500 | BD28: =AN28+BB28 -> 242883.45 | BE28: =AW28+AY28 -> 500000 | BF28: =AX28+AZ28 -> 478528.39 | BG28: 500000 | BH28: 466114.65 | BI28: 500000 | BJ28: 465343.77 | BK28: 435965.96 | BL28: 356518.66 | BM28: 500000 | BN28: 412025.22
B29: Bar Mill | C29: Mt | D29: 850000 | E29: =72.5*1000 -> 72500 | F29: =+BM!F52 -> 70044.755 | G29: =62.5*1000 -> 62500 | H29: =+BM!H52 -> 56061.496 | I29: =+E29+G29 -> 135000 | J29: =+F29+H29 -> 126106.25 | K29: 47000 | L29: =+BM!L52 -> 54192.347 | M29: =+E29+G29+K29 -> 182000 | N29: =+F29+H29+L29 -> 180298.6 | O29: =75*1000 -> 75000 | P29: =+BM!P52 -> 73996.973 | Q29: =+M29+O29 -> 257000 | R29: =+N29+P29 -> 254295.57 | S29: 75000 | T29: =+BM!T52 -> 81550.701 | U29: =+Q29+S29 -> 332000 | V29: =+R29+T29 -> 335846.27 | W29: 73000 | X29: 66170.788 | Y29: =+O29+S29+W29 -> 223000 | Z29: =+P29+T29+X29 -> 221718.46 | AA29: =+M29+Y29 -> 405000 | AB29: =+N29+Z29 -> 402017.06 | AC29: =75.5*1000 -> 75500 | AD29: 61010.23 | AE29: =+AA29+AC29 -> 480500 | AF29: =+AB29+AD29 -> 463027.29 | AG29: 73000 | AH29: 59054.402 | AI29: =+AE29+AG29 -> 553500 | AJ29: =+AF29+AH29 -> 522081.69 | AK29: =75.5*1000 -> 75500 | AL29: 67544.47 | AM29: =+AC29+AG29+AK29 -> 224000 | AN29: =+AD29+AH29+AL29 -> 187609.1 | AO29: =AI29+AK29 -> 629000 | AP29: =AJ29+AL29 -> 589626.16 | AQ29: 75500 | AR29: 70905.326 | AS29: =+AO29+AQ29 -> 704500 | AT29: =+AP29+AR29 -> 660531.49 | AU29: 70000 | AV29: 65231.44 | AW29: =+AS29+AU29 -> 774500 | AX29: =+AT29+AV29 -> 725762.93 | AY29: 75500 | AZ29: 69559.345 | BA29: =+AQ29+AU29+AY29 -> 221000 | BB29: =+AR29+AV29+AZ29 -> 205696.11 | BC29: =AM29+BA29 -> 445000 | BD29: =AN29+BB29 -> 393305.21 | BE29: =AW29+AY29 -> 850000 | BF29: =AX29+AZ29 -> 795322.27 | BG29: 780000 | BH29: 775906.63 | BI29: 750000 | BJ29: 649840.96 | BK29: 674875.14 | BL29: 440547.27 | BM29: 800000 | BN29: 632220.18
B30: US Mill | C30: Mt | D30: 525000 | E30: =44.5*1000 -> 44500 | F30: =+USM!G73 -> 34411.017 | G30: =37.5*1000 -> 37500 | H30: =+USM!I73 -> 29035.71 | I30: =+E30+G30 -> 82000 | J30: =+F30+H30 -> 63446.727 | K30: 36000 | L30: =+USM!M73 -> 29014.605 | M30: =+E30+G30+K30 -> 118000 | N30: =+F30+H30+L30 -> 92461.332 | O30: =46*1000 -> 46000 | P30: =+USM!Q73 -> 33200.704 | Q30: =+M30+O30 -> 164000 | R30: =+N30+P30 -> 125662.04 | S30: 46000 | T30: =+USM!U73 -> 44285.714 | U30: =+Q30+S30 -> 210000 | V30: =+R30+T30 -> 169947.75 | W30: 44500 | X30: 37549.827 | Y30: =+O30+S30+W30 -> 136500 | Z30: =+P30+T30+X30 -> 115036.24 | AA30: =+M30+Y30 -> 254500 | AB30: =+N30+Z30 -> 207497.58 | AC30: =46*1000 -> 46000 | AD30: 38658.05 | AE30: =+AA30+AC30 -> 300500 | AF30: =+AB30+AD30 -> 246155.63 | AG30: =44.5*1000 -> 44500 | AH30: 41612.207 | AI30: =+AE30+AG30 -> 345000 | AJ30: =+AF30+AH30 -> 287767.83 | AK30: 46000 | AL30: 41025.187 | AM30: =+AC30+AG30+AK30 -> 136500 | AN30: =+AD30+AH30+AL30 -> 121295.44 | AO30: =AI30+AK30 -> 391000 | AP30: =AJ30+AL30 -> 328793.02 | AQ30: 46000 | AR30: 41204.778 | AS30: =+AO30+AQ30 -> 437000 | AT30: =+AP30+AR30 -> 369997.8 | AU30: 42000 | AV30: 42591.4 | AW30: =+AS30+AU30 -> 479000 | AX30: =+AT30+AV30 -> 412589.2 | AY30: =46*1000 -> 46000 | AZ30: 46552.753 | BA30: =+AQ30+AU30+AY30 -> 134000 | BB30: =+AR30+AV30+AZ30 -> 130348.93 | BC30: =AM30+BA30 -> 270500 | BD30: =AN30+BB30 -> 251644.38 | BE30: =AW30+AY30 -> 525000 | BF30: =AX30+AZ30 -> 459141.95 | BG30: 470000 | BH30: 361987.56 | BI30: 450000 | BJ30: 213226.16 | BK30: 220000 | BL30: 88943.894 | BM30: 535000 | BN30: 171634.81
B31: Finished Steel | C31: Mt | D31: =SUM(D28:D30) -> 1875000 | E31: =SUM(E28:E30) -> 159500 | F31: =SUM(F28:F30) -> 143245.87 | G31: =SUM(G28:G30) -> 136500 | H31: =SUM(H28:H30) -> 116533.96 | I31: =SUM(I28:I30) -> 296000 | J31: =SUM(J28:J30) -> 259779.83 | K31: =SUM(K28:K30) -> 117000 | ... BF31: =SUM(BF28:BF30) -> 1732992.6 | BG31: 1750000 | BH31: 1604008.8 | BI31: 1700000 | BJ31: 1328410.9 | BK31: 1330841.1 | BL31: 886009.82 | BM31: =SUM(BM28:BM30) -> 1835000 | BN31: =SUM(BN28:BN30) -> 1215880.2
B32: 150x150 mm | C32: Mt | D32: =592.000000270625*1000 -> 592000 | E32: =49.9999999999102*1000 -> 50000 | F32: 49376 | G32: =38.0000000004283*1000 -> 38000 | H32: 41843 | I32: =+E32+G32 -> 88000 | J32: =+F32+H32 -> 91219 | K32: =53.9999999998981*1000 -> 54000 | L32: =46513+23.4 -> 46536.4 | M32: =+E32+G32+K32 -> 142000 | N32: =+F32+H32+L32 -> 137755.4 | O32: =49.000000270114*1000 -> 49000 | P32: 54670 | Q32: =+M32+O32 -> 191000 | R32: =+N32+P32 -> 192425.4 | S32: 49000 | T32: 43042 | U32: =+Q32+S32 -> 240000 | V32: =+R32+T32 -> 235467.4 | W32: 46000 | X32: 48357 | Y32: =+O32+S32+W32 -> 144000 | Z32: =+P32+T32+X32 -> 146069 | AA32: =+M32+Y32 -> 286000 | AB32: =+N32+Z32 -> 283824.4 | AC32: =52.0000000000881*1000 -> 52000 | AD32: =54787.2-16.23+94 -> 54864.97 | AE32: =+AA32+AC32 -> 338000 | AF32: =+AB32+AD32 -> 338689.37 | AG32: =49.9999999998843*1000 -> 50000 | AH32: =43278+118-43 -> 43353 | AI32: =+AE32+AG32 -> 388000 | AJ32: =+AF32+AH32 -> 382042.37 | AK32: =52.0000000000881*1000 -> 52000 | AL32: 47527 | AM32: =+AC32+AG32+AK32 -> 154000 | AN32: =+AD32+AH32+AL32 -> 145744.97 | AO32: =AI32+AK32 -> 440000 | AP32: =AJ32+AL32 -> 429569.37 | AQ32: 52000 | AR32: 41110 | AS32: =+AO32+AQ32 -> 492000 | AT32: =+AP32+AR32 -> 470679.37 | AU32: 48000 | AV32: 54846 | AW32: =+AS32+AU32 -> 540000 | AX32: =+AT32+AV32 -> 525525.37 | AY32: =52.0000000000881*1000 -> 52000 | AZ32: 49298 | BA32: =+AQ32+AU32+AY32 -> 152000 | BB32: =+AR32+AV32+AZ32 -> 145254 | BC32: =AM32+BA32 -> 306000 | BD32: =AN32+BB32 -> 290998.97 | BE32: =AW32+AY32 -> 592000 | BF32: =AX32+AZ32 -> 574823.37 | BG32: 544999.51 | BH32: 595119.91 | BI32: 516406.77 | BJ32: 627684.57 | BK32: 533055.82 | BL32: 608495.73 | BM32: 304999.74 | BN32: 629438.96
B33: 200x280 mm | C33: Mt | D33: =57.9999161425576*1000 -> 57999.916 | E33: =4.00048687231707*1000 -> 4000.4869 | F33: 13419.07 | G33: =3.50044144953577*1000 -> 3500.4414 | H33: 4696 | I33: =+E33+G33 -> 7500.9283 | J33: =+F33+H33 -> 18115.07 | K33: =2.50027133872416*1000 -> 2500.2713 | L33: 16270.81 | M33: =+E33+G33+K33 -> 10001.2 | N33: =+F33+H33+L33 -> 34385.88 | O33: =3.00037396426075*1000 -> 3000.374 | P33: 12217 | Q33: =+M33+O33 -> 13001.574 | R33: =+N33+P33 -> 46602.88 | S33: 3000.374 | T33: 1476.4208 | U33: =+Q33+S33 -> 16001.948 | V33: =+R33+T33 -> 48079.301 | W33: 3999.902 | X33: 9032.5434 | Y33: =+O33+S33+W33 -> 10000.65 | Z33: =+P33+T33+X33 -> 22725.964 | AA33: =+M33+Y33 -> 20001.85 | AB33: =+N33+Z33 -> 57111.844 | AC33: =5.49914754916641*1000 -> 5499.1475 | AD33: 12963.3 | AE33: =+AA33+AC33 -> 25500.997 | AF33: =+AB33+AD33 -> 70075.144 | AG33: =5.50027932514725*1000 -> 5500.2793 | AH33: 691 | AI33: =+AE33+AG33 -> 31001.276 | AJ33: =+AF33+AH33 -> 70766.144 | AK33: =6.4995437755815*1000 -> 6499.5438 | AL33: 9126 | AM33: =+AC33+AG33+AK33 -> 17498.971 | AN33: =+AD33+AH33+AL33 -> 22780.3 | AO33: =AI33+AK33 -> 37500.82 | AP33: =AJ33+AL33 -> 79892.144 | AQ33: 6499.5438 | AR33: 12121 | AS33: =+AO33+AQ33 -> 44000.364 | AT33: =+AP33+AR33 -> 92013.144 | AU33: 6999.6122 | AV33: 6079 | AW33: =+AS33+AU33 -> 50999.976 | AX33: =+AT33+AV33 -> 98092.144 | AY33: =6.99994000199659*1000 -> 6999.94 | AZ33: 3736 | BA33: =+AQ33+AU33+AY33 -> 20499.096 | BB33: =+AR33+AV33+AZ33 -> 21936 | BC33: =AM33+BA33 -> 37998.067 | BD33: =AN33+BB33 -> 44716.3 | BE33: =AW33+AY33 -> 57999.916 | BF33: =AX33+AZ33 -> 101828.14 | BG33: 115000.5 | BH33: 116079.05 | BI33: 153592.34 | BJ33: 204330.35 | BK33: 371378.01 | BL33: 329378.8 | BM33: 267000 | BN33: 248401
B34: Saleable Semis | C34: Mt | D34: =SUM(D32:D33) -> 649999.92 | E34: =SUM(E32:E33) -> 54000.487 | F34: =SUM(F32:F33) -> 62795.07 | G34: =SUM(G32:G33) -> 41500.441 | H34: =SUM(H32:H33) -> 46539 | I34: =SUM(I32:I33) -> 95500.928 | J34: =SUM(J32:J33) -> 109334.07 | K34: =SUM(K32:K33) -> 56500.271 | ... BF34: =SUM(BF32:BF33) -> 676651.51 | BG34: 660000.01 | BH34: 711198.96 | BI34: 669999.11 | BJ34: 832014.92 | BK34: 904433.83 | BL34: 937874.53 | BM34: =SUM(BM32:BM33) -> 571999.74 | BN34: =SUM(BN32:BN33) -> 877839.96
B35: TOTAL SALEABLE STEEL | C35: Mt | D35: =+D31+D34 -> 2524999.9 | E35: =+E31+E34 -> 213500.49 | F35: =+F31+F34 -> 206040.94 | G35: =+G31+G34 -> 178000.44 | H35: =+H31+H34 -> 163072.96 | I35: =+I31+I34 -> 391500.93 | J35: =+J31+J34 -> 369113.9 | K35: =+K31+K34 -> 173500.27 | ... BF35: =+BF31+BF34 -> 2409644.1 | BG35: 2410000 | BH35: 2315207.8 | BI35: 2369999.1 | BJ35: 2160425.8 | BK35: 2235274.9 | BL35: 1823884.4 | BM35: =+BM31+BM34 -> 2406999.7 | BN35: =+BN31+BN34 -> 2093720.2
B36: SAL STEEL PRODN (CATEGORY WISE)
B37: Wire Rod Plain Coils | C37: Mt | D37: =+D28 -> 500000 | E37: =+E28 -> 42500 | F37: =+WRM!F165 -> 38790.1 | G37: =+G28 -> 36500 | H37: =+WRM!H165 -> 24710.7 | I37: =+E37+G37 -> 79000 | J37: =+F37+H37 -> 63500.8 | K37: =+K28 -> 34000 | L37: =+WRM!L165 -> 32975.4 | M37: =+E37+G37+K37 -> 113000 | N37: =+F37+H37+L37 -> 96476.2 | O37: =+O28 -> 43500 | P37: =+WRM!P165 -> 41411.41 | Q37: =+M37+O37 -> 156500 | R37: =+N37+P37 -> 137887.61 | S37: =+S28 -> 43500 | T37: =+WRM!T165 -> 46120.9 | U37: =+Q37+S37 -> 200000 | V37: =+R37+T37 -> 184008.51 | W37: =+W28 -> 42500 | X37: =+WRM!X165 -> 44910.375 | Y37: =+O37+S37+W37 -> 129500 | Z37: =+P37+T37+X37 -> 132442.69 | AA37: =+M37+Y37 -> 242500 | AB37: =+N37+Z37 -> 228918.89 | AC37: =+AC28 -> 43500 | AD37: =+WRM!AD165 -> 42767.05 | AE37: =+AA37+AC37 -> 286000 | AF37: =+AB37+AD37 -> 271685.94 | AG37: =+AG28 -> 42500 | AH37: =+WRM!AH165 -> 40266.1 | AI37: =+AE37+AG37 -> 328500 | AJ37: =+AF37+AH37 -> 311952.04 | AK37: =+AK28 -> 43500 | AL37: 41541.2 | AM37: =+AC37+AG37+AK37 -> 129500 | AN37: =+AD37+AH37+AL37 -> 124574.35 | AO37: =AI37+AK37 -> 372000 | AP37: =AJ37+AL37 -> 353493.24 | AQ37: =+AQ28 -> 43500 | AR37: 43760.85 | AS37: =+AO37+AQ37 -> 415500 | AT37: =+AP37+AR37 -> 397254.09 | AU37: =+AU28 -> 41000 | AV37: 36414.15 | AW37: =+AS37+AU37 -> 456500 | AX37: =+AT37+AV37 -> 433668.24 | AY37: =+AY28 -> 43500 | AZ37: 38134.1 | BA37: =+AQ37+AU37+AY37 -> 128000 | BB37: =+AR37+AV37+AZ37 -> 118309.1 | BC37: =AM37+BA37 -> 257500 | BD37: =AN37+BB37 -> 242883.45 | BE37: =AW37+AY37 -> 500000 | BF37: =AX37+AZ37 -> 471802.34 | BG37: 500000 | BH37: 410762.6 | BI37: =+BI28 -> 500000 | BJ37: 456374.84 | BK37: =+BK28 -> 435965.96 | BL37: 333534.61 | BM37: 500000 | BN37: 270654.57
B38: TMT Coils | C38: Mt | F38: =+WRM!F166 -> 0 | H38: =+WRM!H166 -> 6726.05 | J38: =+F38+H38 -> 6726.05 | L38: =+WRM!L166 -> 0 | N38: =+F38+H38+L38 -> 6726.05 | P38: =+WRM!P166 -> 0 | R38: =+N38+P38 -> 6726.05 | T38: =+WRM!T166 -> 0 | V38: =+R38+T38 -> 6726.05 | X38: =+WRM!X166 -> 0 | Z38: =+P38+T38+X38 -> 0 | AB38: =+N38+Z38 -> 6726.05 | AD38: =+WRM!AD166 -> 0 | AF38: =+AB38+AD38 -> 6726.05 | AH38: =+WRM!AH166 -> 0 | AJ38: =+AF38+AH38 -> 6726.05 | AL38: 0 | AN38: =+AD38+AH38+AL38 -> 0 | AP38: =AJ38+AL38 -> 6726.05 | AR38: 0 | AT38: =+AP38+AR38 -> 6726.05 | AV38: 0 | AX38: =+AT38+AV38 -> 6726.05 | AZ38: 0 | BB38: =+AR38+AV38+AZ38 -> 0 | BD38: =AN38+BB38 -> 0 | BF38: =AX38+AZ38 -> 6726.05 | BH38: 55352.05 | BJ38: 8968.93 | BL38: 22983.766 | BN38: 141370.65
B39: TMT Bars | C39: Mt | D39: =+D29 -> 850000 | E39: =+E29 -> 72500 | F39: =+F29 -> 70044.755 | G39: =+G29 -> 62500 | H39: =+H29 -> 56061.496 | I39: =+E39+G39 -> 135000 | J39: =+F39+H39 -> 126106.25 | K39: =+K29 -> 47000 | L39: =+L29 -> 54192.347 | M39: =+E39+G39+K39 -> 182000 | N39: =+F39+H39+L39 -> 180298.6 | O39: =+O29 -> 75000 | P39: =+P29 -> 73996.973 | Q39: =+M39+O39 -> 257000 | R39: =+N39+P39 -> 254295.57 | S39: =+S29 -> 75000 | T39: =+T29 -> 81550.701 | U39: =+Q39+S39 -> 332000 | V39: =+R39+T39 -> 335846.27 | W39: =+W29 -> 73000 | X39: =+X29 -> 66170.788 | Y39: =+O39+S39+W39 -> 223000 | Z39: =+P39+T39+X39 -> 221718.46 | AA39: =+M39+Y39 -> 405000 | AB39: =+N39+Z39 -> 402017.06 | AC39: =+AC29 -> 75500 | AD39: =+AD29 -> 61010.23 | AE39: =+AA39+AC39 -> 480500 | AF39: =+AB39+AD39 -> 463027.29 | AG39: =+AG29 -> 73000 | AH39: 59054.402 | AI39: =+AE39+AG39 -> 553500 | AJ39: =+AF39+AH39 -> 522081.69 | AK39: =+AK29 -> 75500 | AL39: =+AL29 -> 67544.47 | AM39: =+AC39+AG39+AK39 -> 224000 | AN39: =+AD39+AH39+AL39 -> 187609.1 | AO39: =AI39+AK39 -> 629000 | AP39: =AJ39+AL39 -> 589626.16 | AQ39: =+AQ29 -> 75500 | AR39: 70905.326 | AS39: =+AO39+AQ39 -> 704500 | AT39: =+AP39+AR39 -> 660531.49 | AU39: =+AU29 -> 70000 | AV39: 65231.44 | AW39: =+AS39+AU39 -> 774500 | AX39: =+AT39+AV39 -> 725762.93 | AY39: =+AY29 -> 75500 | AZ39: 69559.345 | BA39: =+AQ39+AU39+AY39 -> 221000 | BB39: =+AR39+AV39+AZ39 -> 205696.11 | BC39: =AM39+BA39 -> 445000 | BD39: =AN39+BB39 -> 393305.21 | BE39: =AW39+AY39 -> 850000 | BF39: =AX39+AZ39 -> 795322.27 | BG39: 780000 | BH39: 775906.63 | BI39: 750000 | BJ39: 649840.96 | BK39: =+BK29 -> 674875.14 | BL39: 440547.14 | BM39: 800000 | BN39: 632220.18
B40: NPB | C40: Mt | D40: =+D30 -> 525000 | E40: =+E30 -> 44500 | F40: 26875 | G40: =+G30 -> 37500 | H40: 14939.49 | I40: =+G40+E40 -> 82000 | J40: =+F40+H40 -> 41814.49 | K40: =+K30 -> 36000 | L40: 21806.96 | M40: =+K40+G40+E40 -> 118000 | N40: =+F40+H40+L40 -> 63621.45 | O40: =+O30 -> 46000 | P40: 21694.56 | Q40: =+M40+O40 -> 164000 | R40: =+N40+P40 -> 85316.01 | S40: =+S30 -> 46000 | T40: 33615.366 | U40: =+Q40+S40 -> 210000 | V40: =+R40+T40 -> 118931.38 | W40: =+W30 -> 44500 | X40: 26746.403 | Y40: =+W40+S40+O40 -> 136500 | Z40: =+P40+T40+X40 -> 82056.329 | AA40: =+M40+Y40 -> 254500 | AB40: =+N40+Z40 -> 145677.78 | AC40: =+AC30 -> 46000 | AD40: 26323.05 | AE40: =+AC40+AA40 -> 300500 | AF40: =+AB40+AD40 -> 172000.83 | AG40: =+AG30 -> 44500 | AH40: 33154.34 | AI40: =+AG40+AE40 -> 345000 | AJ40: =+AF40+AH40 -> 205155.17 | AK40: =+AK30 -> 46000 | AL40: 27743.84 | AM40: =+AK40+AG40+AC40 -> 136500 | AN40: =+AD40+AH40+AL40 -> 87221.23 | AO40: =AI40+AK40 -> 391000 | AP40: =AJ40+AL40 -> 232899.01 | AQ40: =+AQ30 -> 46000 | AR40: 28609.52 | AS40: =+AQ40+AO40 -> 437000 | AT40: =+AP40+AR40 -> 261508.53 | AU40: =+AU30 -> 42000 | AV40: 28117.57 | AW40: =+AU40+AS40 -> 479000 | AX40: =+AT40+AV40 -> 289626.1 | AY40: =+AY30 -> 46000 | AZ40: 33322.32 | BA40: =+AY40+AU40+AQ40 -> 134000 | BB40: =+AR40+AV40+AZ40 -> 90049.41 | BC40: =AM40+BA40 -> 270500 | BD40: =AN40+BB40 -> 177270.64 | BE40: =AW40+AY40 -> 525000 | BF40: =AX40+AZ40 -> 322948.42 | BG40: 470000 | BH40: 273627.65 | BI40: =+BI30 -> 450000 | BJ40: 168120 | BK40: =+BK30 -> 220000 | BL40: 78790 | BM40: 535000 | BN40: =+BN30 -> 171634.81
...

Sheet Maj Despatch Summ
B1: MAJOR DESPATCH SUMMARY 2023-24 (As per Finance CENVAT report)
E2: 30 | F2: 30 | G2: 31 | H2: 31 | I2: =+G2+E2 -> 61 | J2: =+H2+F2 -> 61 | K2: 30 | L2: 30 | M2: =+E2+G2+K2 -> 91 | N2: =+F2+H2+L2 -> 91 | O2: 31 | P2: 31 | Q2: =+M2+O2 -> 122 | R2: =+N2+P2 -> 122 | S2: 31 | T2: 31 | U2: =+Q2+S2 -> 153 | V2: =+R2+T2 -> 153 | W2: 30 | X2: 30 | Y2: =+O2+S2+W2 -> 92 | Z2: =+P2+T2+X2 -> 92 | AA2: =+M2+Y2 -> 183 | AB2: =+N2+Z2 -> 183 | AC2: 31 | AD2: 31 | AE2: =AA2+AC2 -> 214 | AF2: =AB2+AD2 -> 214 | AG2: 30 | AH2: 30 | AI2: =AE2+AG2 -> 244 | AJ2: =AF2+AH2 -> 244 | AK2: 31 | AL2: 31 | AM2: =+AC2+AG2+AK2 -> 92 | AN2: =+AD2+AH2+AL2 -> 92 | AO2: =AI2+AK2 -> 275 | AP2: =AJ2+AL2 -> 275 | AQ2: 31 | AR2: 31 | AS2: =AO2+AQ2 -> 306 | AT2: =AP2+AR2 -> 306 | AU2: 29 | AV2: 29 | AW2: =AS2+AU2 -> 335 | AX2: =AT2+AV2 -> 335 | AY2: 31 | AZ2: 31 | BA2: =+AQ2+AU2+AY2 -> 91 | BB2: =+AR2+AV2+AZ2 -> 91 | BC2: =AM2+BA2 -> 183 | BD2: =AN2+BB2 -> 183 | BE2: =AW2+AY2 -> 366 | BF2: =AX2+AZ2 -> 366 | BK2: 365 | BL2: 365 | BM2: 366 | BN2: 366
B3: ITEM | C3: Unit | D3: 2023-24 ABP | E3: Apr'23 | G3: May'23 | I3: 2M | K3: Jun'23 | M3: QTR-1 | O3: Jul'23 | Q3: 4M | S3: Aug'23 | U3: 5M | W3: Sep'23 | Y3: QTR-2 | AA3: H1 | AC3: Oct'23 | AE3: 7M | AG3: Nov'23 | AI3: 8M | AK3: Dec'23 | AM3: QTR-3 | AO3: 9M | AQ3: Jan'24 | AS3: 10M | AU3: Feb'24 | AW3: 11M | AY3: Mar'24 | BA3: QTR-4 | BC3: H2 | BE3: 2023-24 | BG3: 2022-23 | BI3: 2021-22 | BK3: 2020-21 | BM3: 2019-20
E4: ABP | F4: ACT | G4: ABP | H4: ACT | I4: ABP | J4: ACT | K4: ABP | L4: ACT | M4: ABP | N4: ACT | O4: ABP | P4: ACT | Q4: ABP | R4: ACT | S4: ABP | T4: ACT | U4: ABP | V4: ACT | W4: ABP | X4: ACT | Y4: ABP | Z4: ACT | AA4: ABP | AB4: ACT | AC4: ABP | AD4: ACT | AE4: ABP | AF4: ACT | AG4: ABP | AH4: ACT | AI4: ABP | AJ4: ACT | AK4: ABP | AL4: ACT | AM4: ABP | AN4: ACT | AO4: ABP | AP4: ACT | AQ4: ABP | AR4: ACT | AS4: ABP | AT4: ACT | AU4: ABP | AV4: ACT | AW4: ABP | AX4: ACT | AY4: ABP | AZ4: ACT | BA4: ABP | BB4: ACT | BC4: ABP | BD4: ACT | BE4: ABP | BF4: ACT | BG4: ABP | BH4: ACT | BI4: ABP | BJ4: ACT | BK4: ABP | BL4: ACT | BM4: ABP | BN4: ACT
B5: Saleable Steel (mill-wise)
B6: MKTG-Plant sales | C6: MT | D6: =20000+1500 -> 21500 | E6: =1500+200 -> 1700 | F6: 1921.85 | G6: =1500+100 -> 1600 | H6: 4260.13 | I6: =+E6+G6 -> 3300 | J6: =+F6+H6 -> 6181.98 | K6: 2100 | L6: 1412.02 | M6: =+E6+G6+K6 -> 5400 | N6: =+F6+H6+L6 -> 7594 | O6: 2100 | P6: 1785.37 | Q6: =+M6+O6 -> 7500 | R6: =+N6+P6 -> 9379.37 | S6: 1600 | T6: 1518.53 | U6: =+Q6+S6 -> 9100 | V6: =+R6+T6 -> 10897.9 | W6: 1700 | X6: 2496.45 | Y6: =+O6+S6+W6 -> 5400 | Z6: =+P6+T6+X6 -> 5800.35 | AA6: =+M6+Y6 -> 10800 | AB6: =+N6+Z6 -> 13394.35 | AC6: 1600 | AD6: 2994.67 | AE6: =+AA6+AC6 -> 12400 | AF6: =+AB6+AD6 -> 16389.02 | AG6: 1600 | AH6: 2457.06 | AI6: =+AE6+AG6 -> 14000 | AJ6: =+AF6+AH6 -> 18846.08 | AK6: 1600 | AL6: 1302.1 | AM6: =+AC6+AG6+AK6 -> 4800 | AN6: =+AD6+AH6+AL6 -> 6753.83 | AO6: =AI6+AK6 -> 15600 | AP6: =AJ6+AL6 -> 20148.18 | AQ6: 2200 | AR6: 2913.06 | AS6: =+AO6+AQ6 -> 17800 | AT6: =+AP6+AR6 -> 23061.24 | AU6: 1600 | AV6: 2516.6 | AW6: =+AS6+AU6 -> 19400 | AX6: =+AT6+AV6 -> 25577.84 | AY6: 2100 | AZ6: 5072 | BA6: =+AQ6+AU6+AY6 -> 5900 | BB6: =+AR6+AV6+AZ6 -> 10501.66 | BC6: =AM6+BA6 -> 10700 | BD6: =AN6+BB6 -> 17255.49 | BE6: =+AW6+AY6 -> 21500 | BF6: =+AX6+AZ6 -> 30649.84 | BG6: 25500 | BH6: 34807.22 | BI6: 16050 | BJ6: 33201.15 | BK6: 0 | BL6: 35268.25 | BM6: 2000 | BN6: 28405.85
B7: IPT | C7: MT | D7: 0 | E7: 0 | F7: 0 | G7: 0 | H7: 103 | I7: =+E7+G7 -> 0 | J7: =+F7+H7 -> 103 | K7: 0 | L7: 0 | M7: =+E7+G7+K7 -> 0 | N7: =+F7+H7+L7 -> 103 | O7: 0 | P7: 2735.94 | Q7: =+M7+O7 -> 0 | R7: =+N7+P7 -> 2838.94 | S7: 0 | T7: 237.26 | U7: =+Q7+S7 -> 0 | V7: =+R7+T7 -> 3076.2 | W7: 0 | X7: 0 | Y7: =+O7+S7+W7 -> 0 | Z7: =+P7+T7+X7 -> 2973.2 | AA7: =+M7+Y7 -> 0 | AB7: =+N7+Z7 -> 3076.2 | AC7: 0 | AD7: 0 | AE7: =+AA7+AC7 -> 0 | AF7: =+AB7+AD7 -> 3076.2 | AG7: 0 | AH7: 0 | AI7: =+AE7+AG7 -> 0 | AJ7: =+AF7+AH7 -> 3076.2 | AK7: 0 | AL7: 0 | AM7: =+AC7+AG7+AK7 -> 0 | AN7: =+AD7+AH7+AL7 -> 0 | AO7: =AI7+AK7 -> 0 | AP7: =AJ7+AL7 -> 3076.2 | AQ7: 0 | AR7: 0 | AS7: =+AO7+AQ7 -> 0 | AT7: =+AP7+AR7 -> 3076.2 | AU7: 0 | AV7: 0 | AW7: =+AS7+AU7 -> 0 | AX7: =+AT7+AV7 -> 3076.2 | AY7: 0 | AZ7: 0 | BA7: =+AQ7+AU7+AY7 -> 0 | BB7: =+AR7+AV7+AZ7 -> 0 | BC7: =AM7+BA7 -> 0 | BD7: =AN7+BB7 -> 0 | BE7: =+AW7+AY7 -> 0 | BF7: =+AX7+AZ7 -> 3076.2 | BG7: 123000 | BH7: 42263.08 | BI7: 0 | BJ7: 71707.42 | BK7: 10800 | BL7: 9758.51 | BM7: 24210 | BN7: 5928.095
B8: CMO-WR MILL | C8: MT | D8: 498500 | E8: 42300 | F8: 36663.08 | G8: 36400 | H8: 32908.66 | I8: =+E8+G8 -> 78700 | J8: =+F8+H8 -> 69571.74 | K8: 33900 | L8: 32223.46 | M8: =+E8+G8+K8 -> 112600 | N8: =+F8+H8+L8 -> 101795.2 | O8: 43400 | P8: 41040.98 | Q8: =+M8+O8 -> 156000 | R8: =+N8+P8 -> 142836.18 | S8: 43400 | T8: 48167.69 | U8: =+Q8+S8 -> 199400 | V8: =+R8+T8 -> 191003.87 | W8: 42300 | X8: 43039.34 | Y8: =+O8+S8+W8 -> 129100 | Z8: =+P8+T8+X8 -> 132248.01 | AA8: =+M8+Y8 -> 241700 | AB8: =+N8+Z8 -> 234043.21 | AC8: 43400 | AD8: 41924.59 | AE8: =+AA8+AC8 -> 285100 | AF8: =+AB8+AD8 -> 275967.8 | AG8: 42400 | AH8: 38006.17 | AI8: =+AE8+AG8 -> 327500 | AJ8: =+AF8+AH8 -> 313973.97 | AK8: 43400 | AL8: 39686.53 | AM8: =+AC8+AG8+AK8 -> 129200 | AN8: =+AD8+AH8+AL8 -> 119617.29 | AO8: =AI8+AK8 -> 370900 | AP8: =AJ8+AL8 -> 353660.5 | AQ8: 43300 | AR8: 43617.43 | AS8: =+AO8+AQ8 -> 414200 | AT8: =+AP8+AR8 -> 397277.93 | AU8: 40900 | AV8: 35011.66 | AW8: =+AS8+AU8 -> 455100 | AX8: =+AT8+AV8 -> 432289.59 | AY8: 43400 | AZ8: 41204.62 | BA8: =+AQ8+AU8+AY8 -> 127600 | BB8: =+AR8+AV8+AZ8 -> 119833.71 | BC8: =AM8+BA8 -> 256800 | BD8: =AN8+BB8 -> 239451 | BE8: =+AW8+AY8 -> 498500 | BF8: =+AX8+AZ8 -> 473494.21 | BG8: 498500 | BH8: 453432.75 | BI8: 498500 | BJ8: 467953.64 | BK8: 435166.29 | BL8: 351267.02 | BM8: 498000 | BN8: 399090.26
B9: CMO-BAR MILL | C9: MT | D9: 850000 | E9: 72500 | F9: 67261.57 | G9: 62500 | H9: 58474.66 | I9: =+E9+G9 -> 135000 | J9: =+F9+H9 -> 125736.23 | K9: 47000 | L9: 43079.61 | M9: =+E9+G9+K9 -> 182000 | N9: =+F9+H9+L9 -> 168815.84 | O9: 75000 | P9: 76651.34 | Q9: =+M9+O9 -> 257000 | R9: =+N9+P9 -> 245467.18 | S9: 75000 | T9: 86324.79 | U9: =+Q9+S9 -> 332000 | V9: =+R9+T9 -> 331791.97 | W9: 73000 | X9: 63071.09 | Y9: =+O9+S9+W9 -> 223000 | Z9: =+P9+T9+X9 -> 226047.22 | AA9: =+M9+Y9 -> 405000 | AB9: =+N9+Z9 -> 394863.06 | AC9: 75500 | AD9: 60175.53 | AE9: =+AA9+AC9 -> 480500 | AF9: =+AB9+AD9 -> 455038.59 | AG9: 73000 | AH9: 58175.82 | AI9: =+AE9+AG9 -> 553500 | AJ9: =+AF9+AH9 -> 513214.41 | AK9: 75500 | AL9: 69407.98 | AM9: =+AC9+AG9+AK9 -> 224000 | AN9: =+AD9+AH9+AL9 -> 187759.33 | AO9: =AI9+AK9 -> 629000 | AP9: =AJ9+AL9 -> 582622.39 | AQ9: 75500 | AR9: 65803.18 | AS9: =+AO9+AQ9 -> 704500 | AT9: =+AP9+AR9 -> 648425.57 | AU9: 70000 | AV9: 64969.65 | AW9: =+AS9+AU9 -> 774500 | AX9: =+AT9+AV9 -> 713395.22 | AY9: 75500 | AZ9: 68007.23 | BA9: =+AQ9+AU9+AY9 -> 221000 | BB9: =+AR9+AV9+AZ9 -> 198780.06 | BC9: =AM9+BA9 -> 445000 | BD9: =AN9+BB9 -> 386539.39 | BE9: =+AW9+AY9 -> 850000 | BF9: =+AX9+AZ9 -> 781402.45 | BG9: 780000 | BH9: 768402.31 | BI9: 750000 | BJ9: 648761.89 | BK9: 674874.74 | BL9: 436958.46 | BM9: 800000 | BN9: 612890.55
B10: CMO-US MILL | C10: MT | D10: 525000 | E10: 44500 | F10: 37547.6 | G10: 37500 | H10: 29799.49 | I10: =+E10+G10 -> 82000 | J10: =+F10+H10 -> 67347.09 | K10: 36000 | L10: 23668.07 | M10: =+E10+G10+K10 -> 118000 | N10: =+F10+H10+L10 -> 91015.16 | O10: 46000 | P10: 38466.17 | Q10: =+M10+O10 -> 164000 | R10: =+N10+P10 -> 129481.33 | S10: 46000 | T10: 44584.21 | U10: =+Q10+S10 -> 210000 | V10: =+R10+T10 -> 174065.54 | W10: 44500 | X10: 33234.17 | Y10: =+O10+S10+W10 -> 136500 | Z10: =+P10+T10+X10 -> 116284.55 | AA10: =+M10+Y10 -> 254500 | AB10: =+N10+Z10 -> 207299.71 | AC10: 46000 | AD10: 40148.93 | AE10: =+AA10+AC10 -> 300500 | AF10: =+AB10+AD10 -> 247448.64 | AG10: 44500 | AH10: 39586.21 | AI10: =+AE10+AG10 -> 345000 | AJ10: =+AF10+AH10 -> 287034.85 | AK10: 46000 | AL10: 40554.65 | AM10: =+AC10+AG10+AK10 -> 136500 | AN10: =+AD10+AH10+AL10 -> 120289.79 | AO10: =AI10+AK10 -> 391000 | AP10: =AJ10+AL10 -> 327589.5 | AQ10: 46000 | AR10: 40291.74 | AS10: =+AO10+AQ10 -> 437000 | AT10: =+AP10+AR10 -> 367881.24 | AU10: 42000 | AV10: 38561.13 | AW10: =+AS10+AU10 -> 479000 | AX10: =+AT10+AV10 -> 406442.37 | AY10: 46000 | AZ10: 46360.22 | BA10: =+AQ10+AU10+AY10 -> 134000 | BB10: =+AR10+AV10+AZ10 -> 125213.09 | BC10: =AM10+BA10 -> 270500 | BD10: =AN10+BB10 -> 245502.88 | BE10: =+AW10+AY10 -> 525000 | BF10: =+AX10+AZ10 -> 452802.59 | BG10: 470000 | BH10: 357334.79 | BI10: 445000 | BJ10: 214319.65 | BK10: 220000 | BL10: 100400.4 | BM10: 535000 | BN10: 167166.99
B11: CMO-SEMIS | C11: MT | D11: 629999.92 | E11: 52500.487 | F11: 53555.83 | G11: 40000.441 | H11: 44868.35 | I11: =+E11+G11 -> 92500.928 | J11: =+F11+H11 -> 98424.18 | K11: 54500.271 | L11: 46793.86 | M11: =+E11+G11+K11 -> 147001.2 | N11: =+F11+H11+L11 -> 145218.04 | O11: 50000.374 | P11: 63562.36 | Q11: =+M11+O11 -> 197001.57 | R11: =+N11+P11 -> 208780.4 | S11: 50500.374 | T11: 55744.74 | U11: =+Q11+S11 -> 247501.95 | V11: =+R11+T11 -> 264525.14 | W11: 48500 | X11: 55406.37 | Y11: =+O11+S11+W11 -> 149000.75 | Z11: =+P11+T11+X11 -> 174713.47 | AA11: =+M11+Y11 -> 296001.95 | AB11: =+N11+Z11 -> 319931.51 | AC11: 55999.148 | AD11: 59697.33 | AE11: =+AA11+AC11 -> 352001.1 | AF11: =+AB11+AD11 -> 379628.84 | AG11: 54000.279 | AH11: 44349.57 | AI11: =+AE11+AG11 -> 406001.37 | AJ11: =+AF11+AH11 -> 423978.41 | AK11: 56999.544 | AL11: 54537.14 | AM11: =+AC11+AG11+AK11 -> 166998.97 | AN11: =+AD11+AH11+AL11 -> 158584.04 | AO11: =AI11+AK11 -> 463000.92 | AP11: =AJ11+AL11 -> 478515.55 | AQ11: 56499.544 | AR11: 44164.2 | AS11: =+AO11+AQ11 -> 519500.46 | AT11: =+AP11+AR11 -> 522679.75 | AU11: 53499.612 | AV11: 46507.46 | AW11: =+AS11+AU11 -> 573000.07 | AX11: =+AT11+AV11 -> 569187.21 | AY11: 56999.94 | AZ11: 54278.96 | BA11: =+AQ11+AU11+AY11 -> 166999.1 | BB11: =+AR11+AV11+AZ11 -> 144950.62 | BC11: =AM11+BA11 -> 333998.07 | BD11: =AN11+BB11 -> 303534.66 | BE11: =+AW11+AY11 -> 630000.01 | BF11: =+AX11+AZ11 -> 623466.17 | BG11: 513000.01 | BH11: 641816.63 | BI11: 659950.15 | BJ11: 742311.77 | BK11: 893633.78 | BL11: 944002.21 | BM11: 547789.74 | BN11: 836451
B12: TOTAL | C12: MT | D12: =SUM(D6:D11) -> 2524999.9 | E12: =SUM(E6:E11) -> 213500.49 | F12: =SUM(F6:F11) -> 196949.93 | G12: =SUM(G6:G11) -> 178000.44 | H12: =SUM(H6:H11) -> 170414.29 | I12: =SUM(I6:I11) -> 391500.93 | J12: =SUM(J6:J11) -> 367364.22 | K12: =SUM(K6:K11) -> 173500.27 | ... BF12: =SUM(BF6:BF11) -> 2364891.5 | BG12: 2410000 | BH12: 2298056.8 | BI12: 2369500.2 | BJ12: 2178255.5 | BK12: 2234474.8 | BL12: 1877654.8 | BM12: 2406999.7 | BN12: 2049932.7
