Workbook
Name _1: #REF!
Name _1: #REF!
Name _1: #REF!
Name _1: #REF!
Name _1: #REF!
Name _1: #REF!
Name _1: #REF!
Name _1: #REF!
Name _1: #REF!
Name _2: #REF!
Name _2: #REF!
Name _2: #REF!
Name _2: #REF!
Name _2: #REF!
Name _2: #REF!
Name _2: #REF!
Name _2: #REF!
Name _2: #REF!
Name _3: #REF!
Name _3: #REF!
Name _3: #REF!
Name _3: #REF!
Name _3: #REF!
Name _3: #REF!
Name _3: #REF!
Name _3: #REF!
Name _4: #REF!
Name _4: #REF!
Name a: #REF!
Name a: #REF!
Name a: #REF!
Name a: #REF!
Name AA: #REF!
Name AA: #REF!
Name AA: #REF!
Name AB: #REF!
Name AB: #REF!
Name AB: #REF!
Name AC: #REF!
Name AC: #REF!
Name AD: #REF!
Name AD: #REF!
Name AE: #REF!
Name AE: #REF!
Name AF: #REF!
Name AF: #REF!
Name AG: #REF!
Name AG: #REF!
Name AH: #REF!
Name AH: #REF!
Name AI: #REF!
Name AI: #REF!
Name AK: #REF!
Name AK: #REF!
Name AL: #REF!
Name AL: #REF!
Name AM: #REF!
Name AM: #REF!
Name AN: #REF!
Name AN: #REF!

Sheet Maj Production Summ
B1: MAJOR PRODUCTION SUMMARY | D1: 340 | E1: 26 | F1: =F2-'B-FCE'!F3 -> 29.538194 | G1: 20 | H1: =H2-'B-FCE'!H3-3 -> 14.055556 | I1: =E1+G1 -> 46 | J1: =F1+H1 -> 43.59375 | K1: 29 | L1: =L2-'B-FCE'!L3 -> 29.61125 | M1: =+E1+G1+K1 -> 75 | N1: =+F1+H1+L1 -> 73.205 | O1: 30 | P1: =P2-'B-FCE'!P3 -> 31 | Q1: =+M1+O1 -> 105 | R1: =+N1+P1 -> 104.205 | S1: 30 | T1: =T2-'B-FCE'!T3 -> 30.024306 | U1: =+Q1+S1 -> 135 | V1: =+R1+T1 -> 134.22931 | W1: 17.016867 | X1: =X2-'B-FCE'!X3 -> 29.67375 | Y1: =+O1+S1+W1 -> 77.016867 | Z1: =+P1+T1+X1 -> 90.698056 | AA1: =+U1+W1 -> 152.01687 | AB1: =+V1+X1 -> 163.90306 | AC1: 30 | AD1: =AD2-'B-FCE'!AD3-2 -> 24.930556 | AE1: =AA1+AC1 -> 182.01687 | AF1: =AB1+AD1 -> 188.83361 | AG1: 29 | AH1: =AH2-'B-FCE'!AH3 -> 29.1075 | AI1: =AE1+AG1 -> 211.01687 | AJ1: =AF1+AH1 -> 217.94111 | AK1: 30 | AL1: =31-'B-FCE'!AL3 -> 30.697917 | AM1: =+AC1+AG1+AK1 -> 89 | AN1: =+AD1+AH1+AL1 -> 84.735972 | AO1: =AI1+AK1 -> 241.01687 | AP1: =AJ1+AL1 -> 248.63903 | AQ1: 30 | AR1: =31-'B-FCE'!AR3 -> 30.413194 | AS1: =AO1+AQ1 -> 271.01687 | AT1: =AP1+AR1 -> 279.05222 | AU1: 27 | AV1: =28-'B-FCE'!AV3 -> 27.57625 | AW1: =AS1+AU1 -> 298.01687 | AX1: =AT1+AV1 -> 306.62847 | AY1: 30 | AZ1: =31-'B-FCE'!AZ3 -> 29.972222 | BA1: =+AQ1+AU1+AY1 -> 87 | BB1: =+AR1+AV1+AZ1 -> 87.961667 | BC1: =+AM1+BA1 -> 176 | BD1: =+AN1+BB1 -> 172.69764 | BE1: =AW1+AY1 -> 328.01687 | BF1: =AX1+AZ1 -> 336.60069
A2: 1000 | D2: 365 | E2: 30 | F2: 30 | G2: 31 | H2: 31 | I2: =+E2+G2 -> 61 | J2: =+F2+H2 -> 61 | K2: 30 | L2: 30 | M2: =+I2+K2 -> 91 | N2: =+J2+L2 -> 91 | O2: 31 | P2: 31 | Q2: =+M2+O2 -> 122 | R2: =+N2+P2 -> 122 | S2: 31 | T2: 31 | U2: =+Q2+S2 -> 153 | V2: =+R2+T2 -> 153 | W2: 30 | X2: 30 | Y2: =+O2+S2+W2 -> 92 | Z2: =+P2+T2+X2 -> 92 | AA2: =+U2+W2 -> 183 | AB2: =+V2+X2 -> 183 | AC2: 31 | AD2: 31 | AE2: =AA2+AC2 -> 214 | AF2: =AB2+AD2 -> 214 | AG2: 30 | AH2: 30 | AI2: =AE2+AG2 -> 244 | AJ2: =AF2+AH2 -> 244 | AK2: 31 | AL2: 31 | AM2: =+AC2+AG2+AK2 -> 92 | AN2: =+AD2+AH2+AL2 -> 92 | AO2: =AI2+AK2 -> 275 | AP2: =AJ2+AL2 -> 275 | AQ2: 31 | AR2: 31 | AS2: =AO2+AQ2 -> 306 | AT2: =AP2+AR2 -> 306 | AU2: 28 | AV2: 28 | AW2: =AS2+AU2 -> 334 | AX2: =AT2+AV2 -> 334 | AY2: 31 | AZ2: 31 | BA2: =+AQ2+AU2+AY2 -> 90 | BB2: =+AR2+AV2+AZ2 -> 90 | BC2: =+AM2+BA2 -> 182 | BD2: =+AN2+BB2 -> 182 | BE2: =AW2+AY2 -> 365 | BF2: =AX2+AZ2 -> 365 | BQ2: 365 | BR2: 365 | BS2: 366 | BT2: 366
A3: 1000 | B3: ITEM | C3: Unit | D3: 2026-27 ABP | E3: Apr'26 | G3: May'26 | I3: 2M | K3: Jun'25 | M3: QTR-1 | O3: Jul'25 | Q3: 4M | S3: Aug'25 | U3: 5M | W3: Sep'25 | Y3: QTR 2 | AA3: H1 | AC3: Oct'25 | AE3: 7M | AG3: Nov'25 | AI3: 8M | AK3: Dec'25 | AM3: QTR 3 | AO3: 9M | AQ3: Jan'26 | AS3: 10M | AU3: Feb'26 | AW3: 11M | AY3: Mar'26 | BA3: QTR 4 | BC3: H2 | BE3: 2026-27 | BH3: 2025-26 | BJ3: 2024-25 | BL3: 2023-24 | BN3: 2022-23 | BO3: 2021-22 | BQ3: 2020-21 | BS3: 2019-20
E4: ABP | F4: ACT | G4: ABP | H4: ACT | I4: ABP | J4: ACT | K4: ABP | L4: ACT | M4: ABP | N4: ACT | O4: ABP | P4: ACT | Q4: ABP | R4: ACT | S4: ABP | T4: ACT | U4: ABP | V4: ACT | W4: ABP | X4: ACT | Y4: ABP | Z4: ACT | AA4: ABP | AB4: ACT | AC4: ABP | AD4: ACT | AE4: ABP | AF4: ACT | AG4: ABP | AH4: ACT | AI4: ABP | AJ4: ACT | AK4: ABP | AL4: ACT | AM4: ABP | AN4: ACT | AO4: ABP | AP4: ACT | AQ4: ABP | AR4: ACT | AS4: ABP | AT4: ACT | AU4: ABP | AV4: ACT | AW4: ABP | AX4: ACT | AY4: ABP | AZ4: ACT | BA4: ABP | BB4: ACT | BC4: ABP | BD4: ACT | BE4: ABP | BF4: ACT | BH4: ABP | BI4: ACT | BJ4: ABP | BK4: ACT | BL4: ABP | BM4: ACT | BN4: ACT | BO4: ABP | BP4: ACT | BQ4: ABP | BR4: ACT | BS4: ABP | BT4: ACT
B5: COKE OVENS PUSHING
B6: (COB#10) | C6: Nos/ day | D6: 96.509589 | E6: 98 | F6: =+F9/F2 -> 98 | G6: 98 | H6: =+H9/H2 -> 97.064516 | I6: =+((E6*$E$2)+(G6*$G$2))/$I$2 -> 98 | J6: =+((F6*$F$2)+(H6*$H$2))/$J$2 -> 97.52459 | K6: 94 | L6: =+L9/L2 -> 96.066667 | M6: =+((E6*$E$2)+(G6*$G$2)+(K6*$K$2))/$M$2 -> 96.681319 | N6: =+((F6*$F$2)+(H6*$H$2)+(L6*$L$2))/$N$2 -> 97.043956 | O6: 94 | P6: =+P9/P2 -> 95.419355 | Q6: =+((M6*M$2)+(O6*O$2))/Q$2 -> 96 | R6: =+((N6*N$2)+(P6*P$2))/R$2 -> 96.631148 | S6: 94 | T6: =+T9/T2 -> 98 | U6: =+((Q6*Q$2)+(S6*S$2))/U$2 -> 95.594771 | V6: =+((R6*R$2)+(T6*T$2))/V$2 -> 96.908497 | W6: 92.1 | X6: =+X9/X2 -> 98 | Y6: =+((O$6*O$2)+(S$6*S$2)+(W$6*W$2))/Y$2 -> 93.380435 | Z6: =+((P$6*P$2)+(T$6*T$2)+(X$6*X$2))/Z$2 -> 97.130435 | AA6: =+((M6*M$2)+(Y6*Y$2))/AA$2 -> 95.021858 | AB6: =+((N6*N$2)+(Z6*Z$2))/AB$2 -> 97.087432 | AC6: 94 | AD6: =+AD9/AD2 -> 96.548387 | AE6: =+((AA6*$AA$2)+(AC6*$AC$2))/$AE$2 -> 94.873832 | AF6: =+((AB6*$AB$2)+(AD6*$AD$2))/$AF$2 -> 97.009346 | AG6: 94 | AH6: =+AH9/AH2 -> 94.233333 | AI6: =+((AE6*$AE$2)+(AG6*$AG$2))/$AI$2 -> 94.766393 | AJ6: =+((AF6*$AF$2)+(AH6*$AH$2))/$AJ$2 -> 96.668033 | AK6: 94 | AL6: =+AL9/AL2 -> 94.096774 | AM6: =+((AC$6*AC$2)+(AG$6*AG$2)+(AK$6*AK$2))/AM$2 -> 94 | AN6: =+((AD$6*AD$2)+(AH$6*AH$2)+(AL$6*AL$2))/AN$2 -> 94.967391 | AO6: =+((AK6*$AK$2)+(AI6*$AI$2))/$AO$2 -> 94.68 | AP6: =+((AL6*$AL$2)+(AJ6*$AJ$2))/$AP$2 -> 96.378182 | AQ6: 94 | AR6: =+AR9/AR2 -> 94.83871 | AS6: =+((AO6*$AO$2)+(AQ6*$AQ$2))/$AS$2 -> 94.611111 | AT6: =+((AP6*$AP$2)+(AR6*$AR$2))/$AT$2 -> 96.222222 | AU6: 94 | AV6: =+AV9/AV2 -> 94.428571 | AW6: =+((AS6*$AS$2)+(AU6*$AU$2))/$AW$2 -> 94.55988 | AX6: =+((AT6*$AT$2)+(AV6*$AV$2))/$AX$2 -> 96.071856 | AY6: 94 | AZ6: =+AZ9/AZ2 -> 98 | BA6: =+((AQ$6*AQ$2)+(AU$6*AU$2)+(AY$6*AY$2))/BA$2 -> 94 | BB6: =+((AR$6*AR$2)+(AV$6*AV$2)+(AZ$6*AZ$2))/BB$2 -> 95.8 | BC6: =+((AM6*AM$2)+(BA6*BA$2))/BC$2 -> 94 | BD6: =+((AN6*AN$2)+(BB6*BB$2))/BD$2 -> 95.379121 | BE6: =+((AW6*$AW$2)+(AY6*$AY$2))/$BE$2 -> 94.512329 | BF6: =+((AZ6*$AZ$2)+(AX6*$AX$2))/$BF$2 -> 96.235616 | BH6: 94.512329 | BI6: 96.216438 | BJ6: 96.420548 | BK6: 97.709589 | BL6: 99 | BM6: 98.976067 | BN6: 98.783562 | BO6: 99 | BP6: 97.824658 | BQ6: 95.547945 | BR6: 95.342466 | BS6: 97 | BT6: 97.10959
B7: (COB#11) | C7: Nos/ day | D7: 97.717616 | E7: 96.6 | F7: =+F10/F2 -> 98.433333 | G7: 96.03 | H7: =+H10/H2 -> 93.677419 | I7: =+((E7*$E$2)+(G7*$G$2))/$I$2 -> 96.310328 | J7: =+((F7*$F$2)+(H7*$H$2))/$J$2 -> 96.016393 | K7: 98 | L7: =+L10/L2 -> 98.466667 | M7: =+((E7*$E$2)+(G7*$G$2)+(K7*$K$2))/$M$2 -> 96.867363 | N7: =+((F7*$F$2)+(H7*$H$2)+(L7*$L$2))/$N$2 -> 96.824176 | O7: 98 | P7: =+P10/P2 -> 99 | Q7: =+((M7*M$2)+(O7*O$2))/Q$2 -> 97.155164 | R7: =+((N7*N$2)+(P7*P$2))/R$2 -> 97.377049 | S7: 98 | T7: =+T10/T2 -> 98.516129 | U7: =+((Q7*Q$2)+(S7*S$2))/U$2 -> 97.32634 | V7: =+((R7*R$2)+(T7*T$2))/V$2 -> 97.607843 | W7: 93.5 | X7: =+X10/X2 -> 98.766667 | Y7: =((O7*O2)+(S7*S2)+(W7*W2))/Y2 -> 96.532609 | Z7: =+((P$7*P$2)+(T$7*T$2)+(X$7*X$2))/Z$2 -> 98.76087 | AA7: =+((M7*M$2)+(Y7*Y$2))/AA$2 -> 96.699071 | AB7: =+((N7*N$2)+(Z7*Z$2))/AB$2 -> 97.797814 | AC7: 98 | AD7: =+AD10/AD2 -> 97.193548 | AE7: =+((AA7*$AA$2)+(AC7*$AC$2))/$AE$2 -> 96.887523 | AF7: =+((AB7*$AB$2)+(AD7*$AD$2))/$AF$2 -> 97.71028 | AG7: 98 | AH7: =+AH10/AH2 -> 98.666667 | AI7: =+((AE7*$AE$2)+(AG7*$AG$2))/$AI$2 -> 97.024303 | AJ7: =+((AF7*$AF$2)+(AH7*$AH$2))/$AJ$2 -> 97.827869 | AK7: 98 | AL7: =+AL10/AL2 -> 98.741935 | AM7: =+((AC$7*AC$2)+(AG$7*AG$2)+(AK$7*AK$2))/AM$2 -> 98 | AN7: =+((AD$7*AD$2)+(AH$7*AH$2)+(AL$7*AL$2))/AN$2 -> 98.195652 | AO7: =+((AK7*$AK$2)+(AI7*$AI$2))/$AO$2 -> 97.134291 | AP7: =+((AL7*$AL$2)+(AJ7*$AJ$2))/$AP$2 -> 97.930909 | AQ7: 98 | AR7: =+AR10/AR2 -> 97.870968 | AS7: =+((AO7*$AO$2)+(AQ7*$AQ$2))/$AS$2 -> 97.221993 | AT7: =+((AP7*$AP$2)+(AR7*$AR$2))/$AT$2 -> 97.924837 | AU7: 98 | AV7: =+AV10/AV2 -> 98.035714 | AW7: =+((AS7*$AS$2)+(AU7*$AU$2))/$AW$2 -> 97.287216 | AX7: =+((AT7*$AT$2)+(AV7*$AV$2))/$AX$2 -> 97.934132 | AY7: 98 | AZ7: =+AZ10/AZ2 -> 98.677419 | BA7: =+((AQ$7*AQ$2)+(AU$7*AU$2)+(AY$7*AY$2))/BA$2 -> 98 | BB7: =+((AR$7*AR$2)+(AV$7*AV$2)+(AZ$7*AZ$2))/BB$2 -> 98.2 | BC7: =+((AM7*AM$2)+(BA7*BA$2))/BC$2 -> 98 | BD7: =+((AN7*AN$2)+(BB7*BB$2))/BD$2 -> 98.197802 | BE7: =+((AW7*$AW$2)+(AY7*$AY$2))/$BE$2 -> 97.347753 | BF7: =+((AZ7*$AZ$2)+(AX7*$AX$2))/$BF$2 -> 97.99726 | BH7: 97.630137 | BI7: 98.210959 | BJ7: 98.167671 | BK7: 97.991781 | BL7: 98.000061 | BM7: 96.670251 | BN7: 92.210959 | BO7: 99 | BP7: 96.816438 | BQ7: 94.2 | BR7: 90.778082 | BS7: 97 | BT7: 95.710246
B8: Overall Equiv. Ovens Pushed/ Day | C8: Nos/ day | D8: =+D6+(D7*(31.55/17.2)) -> 275.75324 | E8: =+E6+(E7*(31.55/17.2)) -> 275.1936 | F8: =+F6+(F7*(31.55/17.2)) -> 278.55649 | G8: =+G6+(G7*(31.55/17.2)) -> 274.14805 | H8: =+H6+(H7*(31.55/17.2)) -> 268.89722 | I8: =+I6+(I7*(31.55/17.2)) -> 274.66226 | J8: =+J6+(J7*(31.55/17.2)) -> 273.64768 | K8: =+K6+(K7*(31.55/17.2)) -> 273.76163 | ... X8: =+X6+(X7*(31.55/17.2)) -> 279.16793 | Y8: =Y6+(Y7*31.55/17.2) -> 270.45042 | Z8: =Z6+(Z7*31.55/17.2) -> 278.28773 | AA8: =AA6+(AA7*31.55/17.2) -> 272.39719 | AB8: =AB6+(AB7*31.55/17.2) -> 276.47819 | AC8: =+AC6+(AC7*(31.55/17.2)) -> 273.76163 | AD8: =+AD6+(AD7*(31.55/17.2)) -> 274.83074 | AE8: =+AE6+(AE7*(31.55/17.2)) -> 272.59484 | AF8: =+AF6+(AF7*(31.55/17.2)) -> 276.23954 | AG8: =+AG6+(AG7*(31.55/17.2)) -> 273.76163 | AH8: =+AH6+(AH7*(31.55/17.2)) -> 275.21783 | AI8: =+AI6+(AI7*(31.55/17.2)) -> 272.7383 | AJ8: =+AJ6+(AJ7*(31.55/17.2)) -> 276.11392 | ... AL8: =+AL6+(AL7*(31.55/17.2)) -> 275.21934 | AM8: =AM6+(AM7*31.55/17.2) -> 273.76163 | AN8: =AN6+(AN7*31.55/17.2) -> 275.0879 | AO8: =+AO6+(AO7*(31.55/17.2)) -> 272.85366 | AP8: =+AP6+(AP7*(31.55/17.2)) -> 276.01308 | AQ8: =+AQ6+(AQ7*(31.55/17.2)) -> 273.76163 | AR8: =+AR6+(AR7*(31.55/17.2)) -> 274.36365 | AS8: =+AS6+(AS7*(31.55/17.2)) -> 272.94564 | AT8: =+AT6+(AT7*(31.55/17.2)) -> 275.84598 | AU8: =+AU6+(AU7*(31.55/17.2)) -> 273.76163 | AV8: =+AV6+(AV7*(31.55/17.2)) -> 274.25571 | ... AZ8: =+AZ6+(AZ7*(31.55/17.2)) -> 279.00422 | BA8: =BA6+(BA7*31.55/17.2) -> 273.76163 | BB8: =BB6+(BB7*31.55/17.2) -> 275.92849 | BC8: =BC6+(BC7*31.55/17.2) -> 273.76163 | BD8: =BD6+(BD7*31.55/17.2) -> 275.50358 | BE8: =+BE6+(BE7*(31.55/17.2)) -> 273.07754 | BF8: =+BF6+(BF7*(31.55/17.2)) -> 275.99222 | BH8: 273.59552 | BI8: 276.36503 | BJ8: 276.48974 | BK8: 277.45614 | BL8: 278.76174 | BM8: 276.29853 | BN8: 267.92634 | BO8: 280.59593 | BP8: 275.41528 | BQ8: 268.33922 | BR8: 261.85691 | BS8: 274.92733 | BT8: 272.67112
B9: (COB#10) | C9: Nos | D9: =+D6*D2 -> 35226 | E9: =+E6*E2 -> 2940 | F9: 2940 | G9: =+G6*G2 -> 3038 | H9: 3009 | I9: =+I6*I2 -> 5978 | J9: =+F9+H9 -> 5949 | K9: =+K6*K2 -> 2820 | L9: 2882 | M9: =+E9+G9+K9 -> 8798 | N9: =+F9+H9+L9 -> 8831 | O9: =+O6*O2 -> 2914 | P9: 2958 | Q9: =+M9+O9 -> 11712 | R9: =+N9+P9 -> 11789 | S9: =+S6*S2 -> 2914 | T9: 3038 | U9: =+Q9+S9 -> 14626 | V9: =+R9+T9 -> 14827 | W9: =+W6*W2 -> 2763 | X9: 2940 | Y9: =+O9+S9+W9 -> 8591 | Z9: =+P9+T9+X9 -> 8936 | AA9: =M9+Y9 -> 17389 | AB9: =+N9+Z9 -> 17767 | AC9: =+AC6*AC2 -> 2914 | AD9: 2993 | AE9: =+AE6*AE2 -> 20303 | AF9: =+AB9+AD9 -> 20760 | AG9: =+AG6*AG2 -> 2820 | AH9: 2827 | AI9: =+AI6*AI2 -> 23123 | AJ9: =+AF9+AH9 -> 23587 | AK9: =+AK6*AK2 -> 2914 | AL9: 2917 | AM9: =+AC9+AG9+AK9 -> 8648 | AN9: =+AD9+AH9+AL9 -> 8737 | AO9: =AI9+AK9 -> 26037 | AP9: =AJ9+AL9 -> 26504 | AQ9: =+AQ6*AQ2 -> 2914 | AR9: 2940 | AS9: =+AS6*AS2 -> 28951 | AT9: =+AP9+AR9 -> 29444 | AU9: =+AU6*AU2 -> 2632 | AV9: 2644 | AW9: =+AW6*AW2 -> 31583 | AX9: =+AT9+AV9 -> 32088 | AY9: =+AY6*AY2 -> 2914 | AZ9: 3038 | BA9: =+AQ9+AU9+AY9 -> 8460 | BB9: =+AR9+AV9+AZ9 -> 8622 | BC9: =AM9+BA9 -> 17108 | BD9: =AN9+BB9 -> 17359 | BE9: =AW9+AY9 -> 34497 | BF9: =AX9+AZ9 -> 35126 | BH9: 34497 | BI9: 35119 | BJ9: 35193.5 | BK9: 35664 | BL9: 36234 | BM9: 36225 | BN9: 36056 | BO9: 36135 | BP9: 35706 | BQ9: 34875 | BR9: 34800 | BS9: 35502 | BT9: 35543
B10: (COB#11) | C10: Nos | D10: =+D7*D2 -> 35666.93 | E10: =+E7*E2 -> 2898 | F10: 2953 | G10: =+G7*G2 -> 2976.93 | H10: 2904 | I10: =+I7*I2 -> 5874.93 | J10: =+F10+H10 -> 5857 | K10: =+K7*K2 -> 2940 | L10: 2954 | M10: =+E10+G10+K10 -> 8814.93 | N10: =+F10+H10+L10 -> 8811 | O10: =+O7*O2 -> 3038 | P10: 3069 | Q10: =+M10+O10 -> 11852.93 | R10: =+N10+P10 -> 11880 | S10: =+S7*S2 -> 3038 | T10: 3054 | U10: =+Q10+S10 -> 14890.93 | V10: =+R10+T10 -> 14934 | W10: =+W7*W2 -> 2805 | X10: 2963 | Y10: =+O10+S10+W10 -> 8881 | Z10: =+P10+T10+X10 -> 9086 | AA10: =+M10+Y10 -> 17695.93 | AB10: =+N10+Z10 -> 17897 | AC10: =+AC7*AC2 -> 3038 | AD10: 3013 | AE10: =+AE7*AE2 -> 20733.93 | AF10: =+AB10+AD10 -> 20910 | AG10: =+AG7*AG2 -> 2940 | AH10: 2960 | AI10: =+AI7*AI2 -> 23673.93 | AJ10: =+AF10+AH10 -> 23870 | AK10: =+AK7*AK2 -> 3038 | AL10: 3061 | AM10: =+AC10+AG10+AK10 -> 9016 | AN10: =+AD10+AH10+AL10 -> 9034 | AO10: =AI10+AK10 -> 26711.93 | AP10: =AJ10+AL10 -> 26931 | AQ10: =+AQ7*AQ2 -> 3038 | AR10: 3034 | AS10: =+AS7*AS2 -> 29749.93 | AT10: =+AP10+AR10 -> 29965 | AU10: =+AU7*AU2 -> 2744 | AV10: 2745 | AW10: =+AW7*AW2 -> 32493.93 | AX10: =+AT10+AV10 -> 32710 | AY10: =+AY7*AY2 -> 3038 | AZ10: 3059 | BA10: =+AQ10+AU10+AY10 -> 8820 | BB10: =+AR10+AV10+AZ10 -> 8838 | BC10: =AM10+BA10 -> 17836 | BD10: =AN10+BB10 -> 17872 | BE10: =AW10+AY10 -> 35531.93 | BF10: =AX10+AZ10 -> 35769 | BH10: 35635 | BI10: 35847 | BJ10: 35831.2 | BK10: 35767 | BL10: 35868.022 | BM10: 35382 | BN10: 33657 | BO10: 36135 | BP10: 35338 | BQ10: 34383 | BR10: 33134 | BS10: 35502 | BT10: 35030
B11: Overall Equiv. Ovens Pushed | C11: Nos | D11: =+D9+(D10*(31.55/17.2)) -> 100649.93 | E11: =+E9+(E10*(31.55/17.2)) -> 8255.8081 | F11: =+F9+(F10*(31.55/17.2)) -> 8356.6948 | G11: =+G9+(G10*(31.55/17.2)) -> 8498.5896 | H11: =+H9+(H10*(31.55/17.2)) -> 8335.814 | I11: =+I9+(I10*(31.55/17.2)) -> 16754.398 | J11: =+J9+(J10*(31.55/17.2)) -> 16692.509 | K11: =+K9+(K10*(31.55/17.2)) -> 8212.8488 | ... X11: =+X9+(X10*(31.55/17.2)) -> 8375.0378 | Y11: =Y9+(Y10*31.55/17.2) -> 24881.439 | Z11: =Z9+(Z10*31.55/17.2) -> 25602.471 | AA11: =AA9+(AA10*31.55/17.2) -> 49848.686 | AB11: =AB9+(AB10*31.55/17.2) -> 50595.509 | AC11: =+AC9+(AC10*(31.55/17.2)) -> 8486.6105 | AD11: =+AD9+(AD10*(31.55/17.2)) -> 8519.7529 | AE11: =+AE9+(AE10*(31.55/17.2)) -> 58335.296 | AF11: =+AF9+(AF10*(31.55/17.2)) -> 59115.262 | AG11: =+AG9+(AG10*(31.55/17.2)) -> 8212.8488 | AH11: =+AH9+(AH10*(31.55/17.2)) -> 8256.5349 | AI11: =+AI9+(AI10*(31.55/17.2)) -> 66548.145 | AJ11: =+AJ9+(AJ10*(31.55/17.2)) -> 67371.797 | ... AL11: =+AL9+(AL10*(31.55/17.2)) -> 8531.7994 | AM11: =AM9+(AM10*31.55/17.2) -> 25186.07 | AN11: =AN9+(AN10*31.55/17.2) -> 25308.087 | AO11: =+AO9+(AO10*(31.55/17.2)) -> 75034.755 | AP11: =+AP9+(AP10*(31.55/17.2)) -> 75903.596 | AQ11: =+AQ9+(AQ10*(31.55/17.2)) -> 8486.6105 | AR11: =+AR9+(AR10*(31.55/17.2)) -> 8505.2733 | AS11: =+AS9+(AS10*(31.55/17.2)) -> 83521.366 | AT11: =+AT9+(AT10*(31.55/17.2)) -> 84408.869 | AU11: =+AU9+(AU10*(31.55/17.2)) -> 7665.3256 | AV11: =+AV9+(AV10*(31.55/17.2)) -> 7679.1599 | ... AZ11: =+AZ9+(AZ10*(31.55/17.2)) -> 8649.1308 | BA11: =BA9+(BA10*31.55/17.2) -> 24638.547 | BB11: =BB9+(BB10*31.55/17.2) -> 24833.564 | BC11: =BC9+(BC10*31.55/17.2) -> 49824.616 | BD11: =BD9+(BD10*31.55/17.2) -> 50141.651 | BE11: =+BE9+(BE10*(31.55/17.2)) -> 99673.302 | BF11: =+BF9+(BF10*(31.55/17.2)) -> 100737.16 | BH11: 99862.363 | BI11: 100873.24 | BJ11: 100918.75 | BK11: 101271.49 | BL11: 102026.8 | BM11: 101126.28 | BN11: 97793.113 | BO11: 102417.51 | BP11: 100526.58 | BQ11: 97943.817 | BR11: 95577.773 | BS11: 100623.4 | BT11: 99798.61
B12: BF COKE
B13: COB#10 | C13: Mt | D13: =+D9*0.7*17.2 -> 424121.04 | E13: =+E9*0.7*17.2 -> 35397.6 | F13: ='COKE OVENS'!F21 -> 35144.76 | G13: =+G9*0.7*17.2 -> 36577.52 | H13: ='COKE OVENS'!H21 -> 35969.586 | I13: =+E13+G13 -> 71975.12 | J13: =+F13+H13 -> 71114.346 | K13: =+K9*0.7*17.2 -> 33952.8 | L13: ='COKE OVENS'!L21 -> 34699.28 | M13: =+E13+G13+K13 -> 105927.92 | N13: =+F13+H13+L13 -> 105813.63 | O13: =+O9*0.7*17.2 -> 35084.56 | P13: ='COKE OVENS'!P21 -> 35614.32 | Q13: =+M13+O13 -> 141012.48 | R13: =+N13+P13 -> 141427.95 | S13: =+S9*0.7*17.2 -> 35084.56 | T13: ='COKE OVENS'!T21 -> 36577.52 | U13: =+Q13+S13 -> 176097.04 | V13: =+R13+T13 -> 178005.47 | W13: =+W9*0.7*17.2 -> 33266.52 | X13: ='COKE OVENS'!X21 -> 35397.6 | Y13: =+O13+S13+W13 -> 103435.64 | Z13: =+P13+T13+X13 -> 107589.44 | AA13: =+M13+Y13 -> 209363.56 | AB13: =+N13+Z13 -> 213403.07 | AC13: =+AC9*0.7*17.2 -> 35084.56 | AD13: ='COKE OVENS'!AD21 -> 35881.281 | AE13: =+AA13+AC13 -> 244448.12 | AF13: =+AB13+AD13 -> 249284.35 | AG13: =+AG9*0.7*17.2 -> 33952.8 | AH13: ='COKE OVENS'!AH21 -> 33793.958 | AI13: =+AE13+AG13 -> 278400.92 | AJ13: =+AF13+AH13 -> 283078.31 | AK13: =+AK9*0.7*17.2 -> 35084.56 | AL13: ='COKE OVENS'!AL21 -> 34869.818 | AM13: =+AC13+AG13+AK13 -> 104121.92 | AN13: =+AD13+AH13+AL13 -> 104545.06 | AO13: =AI13+AK13 -> 313485.48 | AP13: =AJ13+AL13 -> 317948.12 | AQ13: =+AQ9*0.7*17.2 -> 35084.56 | AR13: ='COKE OVENS'!AR21 -> 35144.76 | AS13: =+AO13+AQ13 -> 348570.04 | AT13: =+AP13+AR13 -> 353092.88 | AU13: =+AU9*0.7*17.2 -> 31689.28 | AV13: ='COKE OVENS'!AV21 -> 31606.376 | AW13: =+AS13+AU13 -> 380259.32 | AX13: =+AT13+AV13 -> 384699.26 | AY13: =+AY9*0.7*17.2 -> 35084.56 | AZ13: ='COKE OVENS'!AZ21 -> 36316.252 | BA13: =+AQ13+AU13+AY13 -> 101858.4 | BB13: =+AR13+AV13+AZ13 -> 103067.39 | BC13: =AM13+BA13 -> 205980.32 | BD13: =AN13+BB13 -> 207612.45 | BE13: =AW13+AY13 -> 415343.88 | BF13: =AX13+AZ13 -> 421015.51 | BH13: 415343.88 | BI13: 421442.85 | BJ13: 423729.74 | BK13: 431508.84 | BL13: 433141.24 | BM13: 432382.85 | BN13: 430769.03 | BO13: 438172.79 | BP13: 428806 | BQ13: 425506 | BR13: 430922.2 | BS13: 406071.88 | BT13: 412610.14
B14: COB#11 | C14: Mt | D14: =+D10*0.7*31.55 -> 787704.15 | E14: =+E10*31.55*0.7 -> 64002.33 | F14: ='COKE OVENS'!F22 -> 64751.169 | G14: =+G10*31.55*0.7 -> 65745.499 | H14: ='COKE OVENS'!H22 -> 63676.734 | I14: =+E14+G14 -> 129747.83 | J14: =+F14+H14 -> 128427.9 | K14: =+K10*31.55*0.7 -> 64929.9 | L14: ='COKE OVENS'!L22 -> 65239.09 | M14: =+E14+G14+K14 -> 194677.73 | N14: =+F14+H14+L14 -> 193666.99 | O14: =+O10*31.55*0.7 -> 67094.23 | P14: ='COKE OVENS'!P22 -> 67778.865 | Q14: =+M14+O14 -> 261771.96 | R14: =+N14+P14 -> 261445.86 | S14: =+S10*31.55*0.7 -> 67094.23 | T14: ='COKE OVENS'!T22 -> 67447.59 | U14: =+Q14+S14 -> 328866.19 | V14: =+R14+T14 -> 328893.45 | W14: =+W10*31.55*0.7 -> 61948.425 | X14: ='COKE OVENS'!X22 -> 64963.855 | Y14: =+O14+S14+W14 -> 196136.88 | Z14: =+P14+T14+X14 -> 200190.31 | AA14: =+M14+Y14 -> 390814.61 | AB14: =+N14+Z14 -> 393857.3 | AC14: =+AC10*31.55*0.7 -> 67094.23 | AD14: ='COKE OVENS'!AD22 -> 66256.925 | AE14: =+AA14+AC14 -> 457908.84 | AF14: =+AB14+AD14 -> 460114.23 | AG14: =+AG10*31.55*0.7 -> 64929.9 | AH14: ='COKE OVENS'!AH22 -> 64904.66 | AI14: =+AE14+AG14 -> 522838.74 | AJ14: =+AF14+AH14 -> 525018.89 | AK14: =+AK10*31.55*0.7 -> 67094.23 | AL14: ='COKE OVENS'!AL22 -> 67119.312 | AM14: =+AC14+AG14+AK14 -> 199118.36 | AN14: =+AD14+AH14+AL14 -> 198280.9 | AO14: =AI14+AK14 -> 589932.97 | AP14: =AJ14+AL14 -> 592138.2 | AQ14: =+AQ10*31.55*0.7 -> 67094.23 | AR14: ='COKE OVENS'!AR22 -> 66527.276 | AS14: =+AO14+AQ14 -> 657027.2 | AT14: =+AP14+AR14 -> 658665.48 | AU14: =+AU10*31.55*0.7 -> 60601.24 | AV14: ='COKE OVENS'!AV22 -> 60190.301 | AW14: =+AS14+AU14 -> 717628.44 | AX14: =+AT14+AV14 -> 718855.78 | AY14: =+AY10*31.55*0.7 -> 67094.23 | AZ14: ='COKE OVENS'!AZ22 -> 67075.458 | BA14: =+AQ14+AU14+AY14 -> 194789.7 | BB14: =+AR14+AV14+AZ14 -> 193793.04 | BC14: =AM14+BA14 -> 393908.06 | BD14: =AN14+BB14 -> 392073.93 | BE14: =AW14+AY14 -> 784722.67 | BF14: =AX14+AZ14 -> 785931.24 | BH14: 786998.97 | BI14: 788577.81 | BJ14: 791332.05 | BK14: 793765.31 | BL14: 786486.6 | BM14: 774691.65 | BN14: 737579.38 | BO14: 803741.8 | BP14: 778192 | BQ14: 770203 | BR14: 752591.4 | BS14: 744858.59 | BT14: 745859.84
B15: Total BF COKE | C15: Mt | D15: =SUM(D13:D14) -> 1211825.2 | E15: =SUM(E13:E14) -> 99399.93 | F15: =SUM(F13:F14) -> 99895.929 | G15: =SUM(G13:G14) -> 102323.02 | H15: =SUM(H13:H14) -> 99646.32 | I15: =SUM(I13:I14) -> 201722.95 | J15: =SUM(J13:J14) -> 199542.25 | K15: =SUM(K13:K14) -> 98882.7 | ... BF15: =SUM(BF13:BF14) -> 1206946.7 | BH15: 1202342.9 | BI15: 1210020.7 | BJ15: 1215061.8 | BK15: 1225274.2 | BL15: 1219627.8 | BM15: 1207074.5 | BN15: 1168348.4 | BO15: 1241914.6 | BP15: 1206998 | BQ15: 1195709 | BR15: 1183513.6 | BS15: 1150930.5 | BT15: 1158470
B16: SINTER | C16: Mt | D16: 4206886.4 | E16: 291677.45 | F16: 353508 | G16: 262229.25 | H16: 154593 | I16: =+E16+G16 -> 553906.71 | J16: =+F16+H16 -> 508101 | K16: =372.191438188584*1000 -> 372191.44 | L16: 376274 | M16: =+E16+G16+K16 -> 926098.14 | N16: =+F16+H16+L16 -> 884375 | O16: =376.384193405115*1000 -> 376384.19 | P16: 397960 | Q16: =+M16+O16 -> 1302482.3 | R16: =+N16+P16 -> 1282335 | S16: =376.384193405115*1000 -> 376384.19 | T16: 383179 | U16: =+Q16+S16 -> 1678866.5 | V16: =+R16+T16 -> 1665514 | W16: =207.661910104769*1000 -> 207661.91 | X16: 374784 | Y16: =+O16+S16+W16 -> 960430.3 | Z16: =+P16+T16+X16 -> 1155923 | AA16: =+M16+Y16 -> 1886528.4 | AB16: =+N16+Z16 -> 2040298 | AC16: =383.372118766*1000 -> 383372.12 | AD16: 301448 | AE16: =+AA16+AC16 -> 2269900.6 | AF16: =+AB16+AD16 -> 2341746 | AG16: =376.191438188584*1000 -> 376191.44 | AH16: 366206 | AI16: =+AE16+AG16 -> 2646092 | AJ16: =+AF16+AH16 -> 2707952 | AK16: =387.372118766*1000 -> 387372.12 | AL16: 360713 | AM16: =+AC16+AG16+AK16 -> 1146935.7 | AN16: =+AD16+AH16+AL16 -> 1028367 | AO16: =AI16+AK16 -> 3033464.1 | AP16: =AJ16+AL16 -> 3068665 | AQ16: 388962.46 | AR16: 366580 | AS16: =+AO16+AQ16 -> 3422426.6 | AT16: =+AP16+AR16 -> 3435245 | AU16: 349830.08 | AV16: 314846 | AW16: =+AS16+AU16 -> 3772256.7 | AX16: =+AT16+AV16 -> 3750091 | AY16: 388962.46 | AZ16: 379828 | BA16: =+AQ16+AU16+AY16 -> 1127755 | BB16: =+AR16+AV16+AZ16 -> 1061254 | BC16: =AM16+BA16 -> 2274690.7 | BD16: =AN16+BB16 -> 2089621 | BE16: =AW16+AY16 -> 4161219.1 | BF16: =AX16+AZ16 -> 4129919 | BH16: 4362876 | BI16: 4298954 | BJ16: 4387544.5 | BK16: 3980714 | BL16: 4499999.9 | BM16: 4398445 | BN16: 4395665 | BO16: 4183927.8 | BP16: 4277831 | BQ16: 3665891.3 | BR16: 3629577 | BS16: 3903932.5 | BT16: 3709525
B17: HOT METAL | C17: Mt | D17: 3000000 | E17: 208000 | F17: 237076.8 | G17: 187000 | H17: 110658.1 | I17: =+E17+G17 -> 395000 | J17: =+F17+H17 -> 347734.9 | K17: =252*1000 -> 252000 | L17: 261489.9 | M17: =+E17+G17+K17 -> 647000 | N17: =+F17+H17+L17 -> 609224.8 | O17: 255000 | P17: 268142.3 | Q17: =+M17+O17 -> 902000 | R17: =+N17+P17 -> 877367.1 | S17: 255000 | T17: 253263.6 | U17: =+Q17+S17 -> 1157000 | V17: =+R17+T17 -> 1130630.7 | W17: 140000 | X17: 243297.4 | Y17: =+O17+S17+W17 -> 650000 | Z17: =+P17+T17+X17 -> 764703.3 | AA17: =+M17+Y17 -> 1297000 | AB17: =+N17+Z17 -> 1373928.1 | AC17: 260000 | AD17: 202962.1 | AE17: =+AA17+AC17 -> 1557000 | AF17: =+AB17+AD17 -> 1576890.2 | AG17: 252000 | AH17: 244148.2 | AI17: =+AE17+AG17 -> 1809000 | AJ17: =+AF17+AH17 -> 1821038.4 | AK17: 260000 | AL17: 251561 | AM17: =+AC17+AG17+AK17 -> 772000 | AN17: =+AD17+AH17+AL17 -> 698671.3 | AO17: =AI17+AK17 -> 2069000 | AP17: =AJ17+AL17 -> 2072599.4 | AQ17: 264000 | AR17: 244851.4 | AS17: =+AO17+AQ17 -> 2333000 | AT17: =+AP17+AR17 -> 2317450.8 | AU17: 236000 | AV17: 196575.3 | AW17: =+AS17+AU17 -> 2569000 | AX17: =+AT17+AV17 -> 2514026.1 | AY17: 264000 | AZ17: 251871.7 | BA17: =+AQ17+AU17+AY17 -> 764000 | BB17: =+AR17+AV17+AZ17 -> 693298.4 | BC17: =AM17+BA17 -> 1536000 | BD17: =AN17+BB17 -> 1391969.7 | BE17: =AW17+AY17 -> 2833000 | BF17: =AX17+AZ17 -> 2765897.8 | BH17: 2950000 | BI17: 2900019.4 | BJ17: 2650000 | BK17: 2622585.7 | BL17: 2800000 | BM17: 2721268.1 | BN17: 2592119.6 | BO17: 2650001 | BP17: 2406785.7 | BQ17: 2496672.2 | BR17: 2092798 | BS17: 2700000 | BT17: 2505193
B18: CRUDE STEEL | C18: Mt | D18: 2817514.1 | E18: 193691.15 | F18: 223226 | G18: 170903.95 | H18: 97961 | I18: =+E18+G18 -> 364595.1 | J18: =+F18+H18 -> 321187 | K18: =237.110481586402*1000 -> 237110.48 | L18: 243453 | M18: =+E18+G18+K18 -> 601705.59 | N18: =+F18+H18+L18 -> 564640 | O18: =239.943342776204*1000 -> 239943.34 | P18: 253662 | Q18: =+M18+O18 -> 841648.93 | R18: =+N18+P18 -> 818302 | S18: =239.943342776204*1000 -> 239943.34 | T18: 237622 | U18: =+Q18+S18 -> 1081592.3 | V18: =+R18+T18 -> 1055924 | W18: =125.920679886686*1000 -> 125920.68 | X18: 226847 | Y18: =+O18+S18+W18 -> 605807.37 | Z18: =+P18+T18+X18 -> 718131 | AA18: =+M18+Y18 -> 1207513 | AB18: =+N18+Z18 -> 1282771 | AC18: =244.66477809254*1000 -> 244664.78 | AD18: 179201 | AE18: =+AA18+AC18 -> 1452177.7 | AF18: =+AB18+AD18 -> 1461972 | AG18: =237.110481586402*1000 -> 237110.48 | AH18: 229502 | AI18: =+AE18+AG18 -> 1689288.2 | AJ18: =+AF18+AH18 -> 1691474 | AK18: =244.66477809254*1000 -> 244664.78 | AL18: 234365 | AM18: =+AC18+AG18+AK18 -> 726440.04 | AN18: =+AD18+AH18+AL18 -> 643068 | AO18: =AI18+AK18 -> 1933953 | AP18: =AJ18+AL18 -> 1925839 | AQ18: 248441.93 | AR18: 228047 | AS18: =+AO18+AQ18 -> 2182394.9 | AT18: =+AP18+AR18 -> 2153886 | AU18: 222001.89 | AV18: 185016 | AW18: =+AS18+AU18 -> 2404396.8 | AX18: =+AT18+AV18 -> 2338902 | AY18: 248441.93 | AZ18: 241240 | BA18: =+AQ18+AU18+AY18 -> 718885.74 | BB18: =+AR18+AV18+AZ18 -> 654303 | BC18: =AM18+BA18 -> 1445325.8 | BD18: =AN18+BB18 -> 1297371 | BE18: =AW18+AY18 -> 2652838.7 | BF18: =AX18+AZ18 -> 2580142 | BH18: 2770018.9 | BI18: 2702613 | BJ18: 2489528.3 | BK18: 2436959 | BL18: 2620075.5 | BM18: 2528925 | BN18: 2422324.3 | BO18: 2451737.7 | BP18: 2227867 | BQ18: 2297163.5 | BR18: 1847433 | BS18: 2500000 | BT18: 2083412
B19: Caster #(1+2 ) | C19: Mt | D19: 1920416.1 | E19: =SMS!E29 -> 134587.97 | F19: =SMS!F37 -> 166745.17 | G19: =SMS!G29 -> 108106.99 | H19: =SMS!H37 -> 76500.33 | I19: =+E19+G19 -> 242694.96 | J19: =SMS!J37 -> 243245.5 | K19: =SMS!K29 -> 171147.42 | L19: =SMS!L37 -> 182735 | M19: =+E19+G19+K19 -> 413842.38 | N19: =+F19+H19+L19 -> 425980.5 | O19: =SMS!O29 -> 171341.76 | P19: =SMS!P37 -> 189077 | Q19: =+M19+O19 -> 585184.14 | R19: =+N19+P19 -> 615057.5 | S19: =SMS!S29 -> 171341.76 | T19: =SMS!T37 -> 179543 | U19: =+Q19+S19 -> 756525.9 | V19: =+R19+T19 -> 794600.5 | W19: =SMS!W29 -> 90564.479 | X19: =SMS!X37 -> 172339.6 | Y19: =+O19+S19+W19 -> 433248 | Z19: =+P19+T19+X19 -> 540959.6 | AA19: =+M19+Y19 -> 847090.38 | AB19: =+N19+Z19 -> 966940.1 | AC19: =SMS!AC29 -> 173952.38 | AD19: =SMS!AD37 -> 135241 | AE19: =+AA19+AC19 -> 1021042.8 | AF19: =+AB19+AD19 -> 1102181.1 | AG19: =SMS!AG29 -> 168508.9 | AH19: =SMS!AH37 -> 178010.44 | AI19: =SMS!AI29 -> 1189551.7 | AJ19: =SMS!AJ37 -> 1280191.5 | AK19: =SMS!AK29 -> 173424.67 | AL19: =SMS!AL37 -> 168781 | AM19: =SMS!AM29 -> 515885.95 | AN19: =SMS!AN37 -> 482032.44 | AO19: =SMS!AO29 -> 1362976.3 | AP19: =SMS!AP37 -> 1448972.5 | AQ19: =SMS!AQ29 -> 176674.12 | AR19: =SMS!AR37 -> 164934.28 | AS19: =+AO19+AQ19 -> 1539650.4 | AT19: =+AP19+AR19 -> 1613906.8 | AU19: =SMS!AU29 -> 157621.94 | AV19: =SMS!AV37 -> 135607.79 | AW19: =+AS19+AU19 -> 1697272.4 | AX19: =+AT19+AV19 -> 1749514.6 | AY19: =SMS!AY29 -> 176146.41 | AZ19: =SMS!AZ37 -> 176644.91 | BA19: =+AQ19+AU19+AY19 -> 510442.47 | BB19: =+AR19+AV19+AZ19 -> 477186.98 | BC19: =AM19+BA19 -> 1026328.4 | BD19: =AN19+BB19 -> 959219.42 | BE19: =AW19+AY19 -> 1873418.8 | BF19: =AX19+AZ19 -> 1926159.5 | BH19: 1978462.2 | BI19: 2007374.6 | BJ19: 1880445.4 | BK19: 1818588.7 | BM19: 1922629.6 | BN19: 1903696 | BP19: 1777963.7
B20: Caster #3 | C20: Mt | D20: 897098.03 | E20: =SMS!E38 -> 59103.176 | F20: =SMS!F46 -> 56481.07 | G20: =SMS!G38 -> 62796.968 | H20: =SMS!H46 -> 21460.42 | I20: =+E20+G20 -> 121900.14 | J20: =SMS!J46 -> 77941.49 | K20: =SMS!K38 -> 65963.061 | L20: =SMS!L46 -> 60718.3 | M20: =+E20+G20+K20 -> 187863.2 | N20: =+F20+H20+L20 -> 138659.79 | O20: =SMS!O38 -> 68601.583 | P20: =SMS!P46 -> 64584.79 | Q20: =+M20+O20 -> 256464.79 | R20: =+N20+P20 -> 203244.58 | S20: =SMS!S38 -> 68601.583 | T20: =SMS!T46 -> 58078.79 | U20: =+Q20+S20 -> 325066.37 | V20: =+R20+T20 -> 261323.37 | W20: =SMS!W38 -> 35356.201 | X20: =SMS!X46 -> 54507 | Y20: =+O20+S20+W20 -> 172559.37 | Z20: =+P20+T20+X20 -> 177170.58 | AA20: =+M20+Y20 -> 360422.57 | AB20: =+N20+Z20 -> 315830.37 | AC20: =SMS!AC38 -> 70712.4 | AD20: =SMS!AD46 -> 43960.31 | AE20: =+AA20+AC20 -> 431134.97 | AF20: =+AB20+AD20 -> 359790.68 | AG20: =SMS!AG38 -> 68601.583 | AH20: =SMS!AH46 -> 51491.21 | AI20: =SMS!AI38 -> 499736.55 | AJ20: =SMS!AJ46 -> 411281.89 | AK20: =SMS!AK38 -> 71240.106 | AL20: =SMS!AL46 -> 65584.38 | AM20: =SMS!AM38 -> 210554.09 | AN20: =SMS!AN46 -> 161035.9 | AO20: =SMS!AO38 -> 570976.66 | AP20: =SMS!AP46 -> 476866.27 | AQ20: =SMS!AQ38 -> 71767.81 | AR20: =SMS!AR46 -> 63113.1 | AS20: =+AO20+AQ20 -> 642744.47 | AT20: =+AP20+AR20 -> 539979.37 | AU20: =SMS!AU38 -> 64379.947 | AV20: =SMS!AV46 -> 49408.38 | AW20: =+AS20+AU20 -> 707124.42 | AX20: =+AT20+AV20 -> 589387.75 | AY20: =SMS!AY38 -> 72295.515 | AZ20: =SMS!AZ46 -> 64595.04 | BA20: =+AQ20+AU20+AY20 -> 208443.27 | BB20: =+AR20+AV20+AZ20 -> 177116.52 | BC20: =AM20+BA20 -> 418997.36 | BD20: =AN20+BB20 -> 338152.42 | BE20: =AW20+AY20 -> 779419.93 | BF20: =AX20+AZ20 -> 653982.79 | BH20: 791556.73 | BI20: 695238.43 | BJ20: 609083.07 | BK20: 618370.32 | BM20: 606294.79 | BN20: 518629.33 | BP20: 449903.88
B21: Avg Heats Cast per Day | C21: Nos. / day | D21: =D53/D1 -> 53.120553 | E21: =+E53/E1 -> 47.754228 | F21: =+F53/F1 -> 48.005642 | G21: =+G53/G1 -> 54.776909 | H21: =+H53/H1 -> 44.679842 | I21: =+I53/I1 -> 50.807567 | J21: =+J53/J1 -> 46.933333 | K21: =+K53/K1 -> 54.508157 | L21: =+L53/L1 -> 52.547596 | ... BF21: =+BF53/BF1 -> 48.879875 | BH21: 54.152138 | BI21: 49.349681 | BJ21: 51.463117 | BK21: 49.270546 | BL21: 50.337665 | BM21: 48.130368 | BN21: 45.269663 | BO21: 44.780041 | BP21: 40.065753 | BQ21: 41.920046 | BR21: 33.309589 | BS21: 47.014645 | BT21: 38.663934
B22: Cold Pig & Pig Equivalent
B23: MOG | C23: Mt | D23: 3420 | E23: 1620 | F23: 246.31997 | G23: 1800 | H23: 1995.0165 | I23: =+E23+G23 -> 3420 | J23: =+F23+H23 -> 2241.3364 | K23: =0.81*1000 -> 810 | L23: 902.97846 | M23: =+E23+G23+K23 -> 4230 | N23: =+F23+H23+L23 -> 3144.3149 | O23: 810 | P23: 0 | Q23: =+M23+O23 -> 5040 | R23: =+N23+P23 -> 3144.3149 | S23: =0.81*1000 -> 810 | T23: 144.06922 | U23: =+Q23+S23 -> 5850 | V23: =+R23+T23 -> 3288.3841 | W23: =5360-1625 -> 3735 | X23: 256.58678 | Y23: =+O23+S23+W23 -> 5355 | Z23: =+P23+T23+X23 -> 400.656 | AA23: =+M23+Y23 -> 9585 | AB23: =+N23+Z23 -> 3544.9709 | AC23: 810 | AD23: 3014.2686 | AE23: =+AA23+AC23 -> 10395 | AF23: =+AB23+AD23 -> 6559.2395 | AG23: 810 | AH23: 135.13793 | AI23: =+AE23+AG23 -> 11205 | AJ23: =+AF23+AH23 -> 6694.3775 | AK23: 810 | AL23: 35.72516 | AM23: =+AC23+AG23+AK23 -> 2430 | AN23: =+AD23+AH23+AL23 -> 3185.1317 | AO23: =AI23+AK23 -> 12015 | AP23: =AJ23+AL23 -> 6730.1026 | AQ23: 810 | AR23: 662.91874 | AS23: =+AO23+AQ23 -> 12825 | AT23: =+AP23+AR23 -> 7393.0214 | AU23: 810 | AV23: 0 | AW23: =+AS23+AU23 -> 13635 | AX23: =+AT23+AV23 -> 7393.0214 | AY23: 810 | AZ23: 80.29814 | BA23: =+AQ23+AU23+AY23 -> 2430 | BB23: =+AR23+AV23+AZ23 -> 743.21688 | BC23: =AM23+BA23 -> 4860 | BD23: =AN23+BB23 -> 3928.3486 | BE23: =AW23+AY23 -> 14445 | BF23: =AX23+AZ23 -> 7473.3195 | BH23: 12645 | BI23: 11530.128 | BJ23: 7740 | BK23: 12917.886 | BL23: 19561.1 | BM23: 7548.2756 | BN23: 9129.3344 | BO23: 19735.515 | BP23: 22361.072 | BQ23: 20755.018 | BR23: 58220.7 | BS23: 29957.856 | BT23: 134629.18
B24: UPIS | C24: Mt | D24: 0 | E24: 0 | F24: 34.774584 | G24: 0 | H24: 281.64938 | I24: =+E24+G24 -> 0 | J24: =+F24+H24 -> 316.42397 | K24: 0 | L24: 127.47931 | M24: =+E24+G24+K24 -> 0 | N24: =+F24+H24+L24 -> 443.90328 | O24: 0 | P24: 0 | Q24: =+M24+O24 -> 0 | R24: =+N24+P24 -> 443.90328 | S24: 0 | T24: 20.339184 | U24: =+Q24+S24 -> 0 | V24: =+R24+T24 -> 464.24246 | W24: 0 | X24: 36.224016 | Y24: =+O24+S24+W24 -> 0 | Z24: =+P24+T24+X24 -> 56.5632 | AA24: =+M24+Y24 -> 0 | AB24: =+N24+Z24 -> 500.46648 | AC24: 0 | AD24: 426 | AE24: =+AA24+AC24 -> 0 | AF24: =+AB24+AD24 -> 926.46648 | AG24: 0 | AH24: 19.078296 | AI24: =+AE24+AG24 -> 0 | AJ24: =+AF24+AH24 -> 945.54478 | AK24: 0 | AL24: 5 | AM24: =+AC24+AG24+AK24 -> 0 | AN24: =+AD24+AH24+AL24 -> 450.0783 | AO24: =AI24+AK24 -> 0 | AP24: =AJ24+AL24 -> 950.54478 | AQ24: 0 | AR24: 93.588528 | AS24: =+AO24+AQ24 -> 0 | AT24: =+AP24+AR24 -> 1044.1333 | AU24: 0 | AV24: 0 | AW24: =+AS24+AU24 -> 0 | AX24: =+AT24+AV24 -> 1044.1333 | AY24: 0 | AZ24: 11.336208 | BA24: =+AQ24+AU24+AY24 -> 0 | BB24: =+AR24+AV24+AZ24 -> 104.92474 | BC24: =AM24+BA24 -> 0 | BD24: =AN24+BB24 -> 555.00303 | BE24: =AW24+AY24 -> 0 | BF24: =AX24+AZ24 -> 1055.4695 | BH24: 0 | BI24: 1628.1955 | BJ24: 0 | BK24: 1823.7656 | BL24: 0 | BM24: 1026.6221 | BN24: 2541.6495 | BO24: 0 | BP24: 2774.7649 | BQ24: 392 | BR24: 3852.3 | BS24: 1419.0563 | BT24: 8272.9783
B25: Equiv. Pig Iron @ 65% of HM sent to Sand Pit | C25: Mt | D25: 2600 | E25: 325 | F25: 190 | G25: 2275 | H25: 4005 | I25: =+E25+G25 -> 2600 | J25: =+F25+H25 -> 4195 | K25: 0 | L25: 0 | M25: =+E25+G25+K25 -> 2600 | N25: =+F25+H25+L25 -> 4195 | O25: 0 | P25: 0 | Q25: =+M25+O25 -> 2600 | R25: =+N25+P25 -> 4195 | S25: 0 | T25: 0 | U25: =+Q25+S25 -> 2600 | V25: =+R25+T25 -> 4195 | W25: =2500*0.65 -> 1625 | X25: 0 | Y25: =+O25+S25+W25 -> 1625 | Z25: =+P25+T25+X25 -> 0 | AA25: =+M25+Y25 -> 4225 | AB25: =+N25+Z25 -> 4195 | AC25: 0 | AD25: 5603 | AE25: =+AA25+AC25 -> 4225 | AF25: =+AB25+AD25 -> 9798 | AG25: 0 | AH25: 0 | AI25: =+AE25+AG25 -> 4225 | AJ25: =+AF25+AH25 -> 9798 | AK25: 0 | AL25: 0 | AM25: =+AC25+AG25+AK25 -> 0 | AN25: =+AD25+AH25+AL25 -> 5603 | AO25: =AI25+AK25 -> 4225 | AP25: =AJ25+AL25 -> 9798 | AQ25: 0 | AR25: 800.6 | AS25: =+AO25+AQ25 -> 4225 | AT25: =+AP25+AR25 -> 10598.6 | AU25: 0 | AV25: 920 | AW25: =+AS25+AU25 -> 4225 | AX25: =+AT25+AV25 -> 11518.6 | AY25: 0 | AZ25: 310 | BA25: =+AQ25+AU25+AY25 -> 0 | BB25: =+AR25+AV25+AZ25 -> 2030.6 | BC25: =AM25+BA25 -> 0 | BD25: =AN25+BB25 -> 7633.6 | BE25: =AW25+AY25 -> 4225 | BF25: =AX25+AZ25 -> 11828.6 | BH25: 1625 | BI25: 8058.2 | BJ25: 1625 | BK25: 11114.8 | BL25: 2000 | BM25: 5022 | BN25: 4664.8 | BO25: 14800 | BP25: 9214.4 | BQ25: 0 | BR25: 0 | BS25: 0 | BT25: 26220.8
B26: TOTAL EQUIVALENT PIG IRON | C26: Mt | D26: =SUM(D23:D25) -> 6020 | E26: =SUM(E23:E25) -> 1945 | F26: =SUM(F23:F25) -> 471.09455 | G26: =SUM(G23:G25) -> 4075 | H26: =SUM(H23:H25) -> 6281.6659 | I26: =SUM(I23:I25) -> 6020 | J26: =SUM(J23:J25) -> 6752.7604 | K26: =SUM(K23:K25) -> 810 | ... BF26: =SUM(BF23:BF25) -> 20357.389 | BH26: 14270 | BI26: 21216.524 | BJ26: 9365 | BK26: 25856.451 | BL26: 21561.1 | BM26: 13596.898 | BN26: 16335.784 | BO26: 34535.515 | BP26: 34350.237 | BQ26: 21147.018 | BR26: 62073 | BS26: 31376.912 | BT26: 169122.96
B27: Net PCI Production | C27: Mt | D27: 5103 | E27: 644.512 | F27: 160.65 | G27: 2598.518 | H27: 162.365 | I27: =+E27+G27 -> 3243.03 | J27: =+F27+H27 -> 323.015 | K27: 273.996 | L27: 0 | M27: =+E27+G27+K27 -> 3517.026 | N27: =+F27+H27+L27 -> 323.015 | O27: 276.24 | P27: 0 | Q27: =+M27+O27 -> 3793.266 | R27: =+N27+P27 -> 323.015 | S27: 276.24 | T27: 0 | U27: =+Q27+S27 -> 4069.506 | V27: =+R27+T27 -> 323.015 | W27: 498.97 | X27: 0 | Y27: =+O27+S27+W27 -> 1051.45 | Z27: =+P27+T27+X27 -> 0 | AA27: =+M27+Y27 -> 4568.476 | AB27: =+N27+Z27 -> 323.015 | AC27: 279.98 | AD27: 549.087 | AE27: =+AA27+AC27 -> 4848.456 | AF27: =+AB27+AD27 -> 872.102 | AG27: 273.996 | AH27: 833.469 | AI27: =+AE27+AG27 -> 5122.452 | AJ27: =+AF27+AH27 -> 1705.571 | AK27: 279.98 | AL27: 1510.747 | AM27: =+AC27+AG27+AK27 -> 833.956 | AN27: =+AD27+AH27+AL27 -> 2893.303 | AO27: =AI27+AK27 -> 5402.432 | AP27: =AJ27+AL27 -> 3216.318 | AQ27: 282.972 | AR27: 1549.45 | AS27: =+AO27+AQ27 -> 5685.404 | AT27: =+AP27+AR27 -> 4765.768 | AU27: 262.028 | AV27: 755.405 | AW27: =+AS27+AU27 -> 5947.432 | AX27: =+AT27+AV27 -> 5521.173 | AY27: 282.972 | AZ27: 209.86 | BA27: =+AQ27+AU27+AY27 -> 827.972 | BB27: =+AR27+AV27+AZ27 -> 2514.715 | BC27: =AM27+BA27 -> 1661.928 | BD27: =AN27+BB27 -> 5408.018 | BE27: =AW27+AY27 -> 6230.404 | BF27: =AX27+AZ27 -> 5731.033 | BH27: 3541.35 | BI27: 6386.38 | BJ27: 2831.5 | BK27: 7991.486 | BL27: 2377.872 | BM27: 6141.395 | BN27: 5885.734 | BO27: 2398.56 | BP27: 13377.679 | BQ27: 11568.99 | BR27: 41093.9 | BS27: 0 | BT27: 44255.19
B28: Net Granulated Slag Production | C28: Mt | D28: 1049580 | E28: 72770.88 | F28: 73016.796 | G28: 63421.05 | H28: 34000.934 | I28: =+E28+G28 -> 136191.93 | J28: =+F28+H28 -> 107017.73 | K28: 92363.04 | L28: 72846.055 | M28: =+E28+G28+K28 -> 228554.97 | N28: =+F28+H28+L28 -> 179863.79 | O28: 93462.6 | P28: 75682.97 | Q28: =+M28+O28 -> 322017.57 | R28: =+N28+P28 -> 255546.76 | S28: 93462.6 | T28: 80832.023 | U28: =+Q28+S28 -> 415480.17 | V28: =+R28+T28 -> 336378.78 | W28: 51312.8 | X28: 79584.049 | Y28: =+O28+S28+W28 -> 238238 | Z28: =+P28+T28+X28 -> 236099.04 | AA28: =+M28+Y28 -> 466792.97 | AB28: =+N28+Z28 -> 415962.83 | AC28: 95295.2 | AD28: 63840.922 | AE28: =+AA28+AC28 -> 562088.17 | AF28: =+AB28+AD28 -> 479803.75 | AG28: 92363.04 | AH28: 88321.763 | AI28: =+AE28+AG28 -> 654451.21 | AJ28: =+AF28+AH28 -> 568125.51 | AK28: 95295.2 | AL28: 84104.855 | AM28: =+AC28+AG28+AK28 -> 282953.44 | AN28: =+AD28+AH28+AL28 -> 236267.54 | AO28: =AI28+AK28 -> 749746.41 | AP28: =AJ28+AL28 -> 652230.37 | AQ28: 96761.28 | AR28: 81040.671 | AS28: =+AO28+AQ28 -> 846507.69 | AT28: =+AP28+AR28 -> 733271.04 | AU28: 86498.72 | AV28: 67236.848 | AW28: =+AS28+AU28 -> 933006.41 | AX28: =+AT28+AV28 -> 800507.89 | AY28: 96761.28 | AZ28: 71373.052 | BA28: =+AQ28+AU28+AY28 -> 280021.28 | BB28: =+AR28+AV28+AZ28 -> 219650.57 | BC28: =AM28+BA28 -> 562974.72 | BD28: =AN28+BB28 -> 455918.11 | BE28: =AW28+AY28 -> 1029767.7 | BF28: =AX28+AZ28 -> 871880.94 | BH28: 1081234 | BI28: 911237.59 | BJ28: 987899.89 | BK28: 899258.76 | BL28: 1063047 | BM28: 1075244.6 | BN28: 1065593 | BO28: 157305.12 | BP28: 920129.3 | BQ28: 882599.97 | BR28: 776699 | BS28: 854658 | BT28: 809638.21
B29: Saleable Steel Production (Mill Wise)
B30: WR Mill | C30: Mt | D30: 520000 | E30: 36500 | F30: =+WRM!F159 -> 41533 | G30: 37500 | H30: =+WRM!H159 -> 21522.95 | I30: =+E30+G30 -> 74000 | J30: =+F30+H30 -> 63055.95 | K30: 42500 | L30: =+WRM!L159 -> 38291.35 | M30: =+E30+G30+K30 -> 116500 | N30: =+F30+H30+L30 -> 101347.3 | O30: 44000 | P30: =+WRM!P159 -> 47063.9 | Q30: =+M30+O30 -> 160500 | R30: =+N30+P30 -> 148411.2 | S30: 44000 | T30: =+WRM!T159 -> 38718.35 | U30: =+Q30+S30 -> 204500 | V30: =+R30+T30 -> 187129.55 | W30: 25000 | X30: =+WRM!X159 -> 41006.15 | Y30: =+O30+S30+W30 -> 113000 | Z30: =+P30+T30+X30 -> 126788.4 | AA30: =+M30+Y30 -> 229500 | AB30: =+N30+Z30 -> 228135.7 | AC30: 42500 | AD30: =+WRM!AD159 -> 30034.55 | AE30: =+AA30+AC30 -> 272000 | AF30: =+AB30+AD30 -> 258170.25 | AG30: 42500 | AH30: =+WRM!AH159 -> 34614.25 | AI30: =+AE30+AG30 -> 314500 | AJ30: =+AF30+AH30 -> 292784.5 | AK30: 44000 | AL30: =+WRM!AL159 -> 44007.35 | AM30: =+AC30+AG30+AK30 -> 129000 | AN30: =+AD30+AH30+AL30 -> 108656.15 | AO30: =AI30+AK30 -> 358500 | AP30: =AJ30+AL30 -> 336791.85 | AQ30: 44500 | AR30: =+WRM!AR159 -> 44589.55 | AS30: =+AO30+AQ30 -> 403000 | AT30: =+AP30+AR30 -> 381381.4 | AU30: 40000 | AV30: =+WRM!AV159 -> 37420.7 | AW30: =+AS30+AU30 -> 443000 | AX30: =+AT30+AV30 -> 418802.1 | AY30: 44500 | AZ30: =+WRM!AZ159 -> 46692.85 | BA30: =+AQ30+AU30+AY30 -> 129000 | BB30: =+AR30+AV30+AZ30 -> 128703.1 | BC30: =AM30+BA30 -> 258000 | BD30: =AN30+BB30 -> 237359.25 | BE30: =AW30+AY30 -> 487500 | BF30: =AX30+AZ30 -> 465494.95 | BH30: 500000 | BI30: 478532.93 | BJ30: 500000 | BK30: 459030.64 | BL30: 500000 | BM30: 478528.39 | BN30: 466114.65 | BO30: 500000 | BP30: 465343.77 | BQ30: 435965.96 | BR30: 356518.66 | BS30: 500000 | BT30: 412025.22
B31: Bar Mill | C31: Mt | D31: 990000 | E31: 68500 | F31: =+BM!F56 -> 74661.04 | G31: 71000 | H31: =+BM!H56 -> 33192.92 | I31: =+E31+G31 -> 139500 | J31: =+F31+H31 -> 107853.96 | K31: 76000 | L31: =+BM!L56 -> 73644.015 | M31: =+E31+G31+K31 -> 215500 | N31: =+F31+H31+L31 -> 181497.98 | O31: 79000 | P31: =+BM!P56 -> 88056.49 | Q31: =+M31+O31 -> 294500 | R31: =+N31+P31 -> 269554.47 | S31: 79000 | T31: =+BM!T56 -> 75853.695 | U31: =+Q31+S31 -> 373500 | V31: =+R31+T31 -> 345408.16 | W31: =47.5*1000 -> 47500 | X31: =+BM!X56 -> 76319.035 | Y31: =+O31+S31+W31 -> 205500 | Z31: =+P31+T31+X31 -> 240229.22 | AA31: =+M31+Y31 -> 421000 | AB31: =+N31+Z31 -> 421727.2 | AC31: 78000 | AD31: =+BM!AD56 -> 50950.275 | AE31: =+AA31+AC31 -> 499000 | AF31: =+AB31+AD31 -> 472677.47 | AG31: 76000 | AH31: =+BM!AH56 -> 69720.765 | AI31: =+AE31+AG31 -> 575000 | AJ31: =+AF31+AH31 -> 542398.24 | AK31: 79000 | AL31: =+BM!AL56 -> 81616.765 | AM31: =+AC31+AG31+AK31 -> 233000 | AN31: =+AD31+AH31+AL31 -> 202287.81 | AO31: =AI31+AK31 -> 654000 | AP31: =AJ31+AL31 -> 624015 | AQ31: 79000 | AR31: =+BM!AR56 -> 85804.6 | AS31: =+AO31+AQ31 -> 733000 | AT31: =+AP31+AR31 -> 709819.6 | AU31: 71500 | AV31: =+BM!AV56 -> 74058.32 | AW31: =+AS31+AU31 -> 804500 | AX31: =+AT31+AV31 -> 783877.92 | AY31: 80000 | AZ31: =+BM!AZ56 -> 81200 | BA31: =+AQ31+AU31+AY31 -> 230500 | BB31: =+AR31+AV31+AZ31 -> 241062.92 | BC31: =AM31+BA31 -> 463500 | BD31: =AN31+BB31 -> 443350.73 | BE31: =AW31+AY31 -> 884500 | BF31: =AX31+AZ31 -> 865077.92 | BH31: 900000 | BI31: 900295.05 | BJ31: 870000 | BK31: 750867.85 | BL31: 850000 | BM31: 795322.27 | BN31: 775906.63 | BO31: 750000 | BP31: 649840.96 | BQ31: 674875.14 | BR31: 440547.27 | BS31: 800000 | BT31: 632220.18
B32: US Mill | C32: Mt | D32: 850000 | E32: 56000 | F32: =+USM!G121 -> 52520.054 | G32: 59500 | H32: =+USM!I121 -> 10535.918 | I32: =+E32+G32 -> 115500 | J32: =+F32+H32 -> 63055.972 | K32: 62500 | L32: =+USM!M121 -> 58674.633 | M32: =+E32+G32+K32 -> 178000 | N32: =+F32+H32+L32 -> 121730.61 | O32: 65000 | P32: =+USM!Q121 -> 57327.387 | Q32: =+M32+O32 -> 243000 | R32: =+N32+P32 -> 179057.99 | S32: 65000 | T32: =+USM!U121 -> 44406.293 | U32: =+Q32+S32 -> 308000 | V32: =+R32+T32 -> 223464.29 | W32: 33500 | X32: =+USM!Y121 -> 49996.716 | Y32: =+O32+S32+W32 -> 163500 | Z32: =+P32+T32+X32 -> 151730.4 | AA32: =+M32+Y32 -> 341500 | AB32: =+N32+Z32 -> 273461 | AC32: 67000 | AD32: =+USM!AE121 -> 29659.897 | AE32: =+AA32+AC32 -> 408500 | AF32: =+AB32+AD32 -> 303120.9 | AG32: 65000 | AH32: =+USM!AI121 -> 49060.044 | AI32: =+AE32+AG32 -> 473500 | AJ32: =+AF32+AH32 -> 352180.94 | AK32: =67.5*1000 -> 67500 | AL32: =+USM!AM121 -> 52987.18 | AM32: =+AC32+AG32+AK32 -> 199500 | AN32: =+AD32+AH32+AL32 -> 131707.12 | AO32: =AI32+AK32 -> 541000 | AP32: =AJ32+AL32 -> 405168.12 | AQ32: 68000 | AR32: =+USM!AS121 -> 56169.978 | AS32: =+AO32+AQ32 -> 609000 | AT32: =+AP32+AR32 -> 461338.1 | AU32: 61000 | AV32: =+USM!AW121 -> 54279.398 | AW32: =+AS32+AU32 -> 670000 | AX32: =+AT32+AV32 -> 515617.5 | AY32: 68500 | AZ32: =+USM!BA121 -> 63120.146 | BA32: =+AQ32+AU32+AY32 -> 197500 | BB32: =+AR32+AV32+AZ32 -> 173569.52 | BC32: =AM32+BA32 -> 397000 | BD32: =AN32+BB32 -> 305276.64 | BE32: =AW32+AY32 -> 738500 | BF32: =AX32+AZ32 -> 578737.64 | BH32: 750000 | BI32: 622444.59 | BJ32: 560000 | BK32: 499887.23 | BL32: 525000 | BM32: 459141.95 | BN32: 361987.56 | BO32: 450000 | BP32: 213226.16 | BQ32: 220000 | BR32: 88943.894 | BS32: 535000 | BT32: 171634.81
B33: Finished Steel | C33: Mt | D33: =SUM(D30:D32) -> 2360000 | E33: =SUM(E30:E32) -> 161000 | F33: =SUM(F30:F32) -> 168714.09 | G33: =SUM(G30:G32) -> 168000 | H33: =SUM(H30:H32) -> 65251.788 | I33: =SUM(I30:I32) -> 329000 | J33: =SUM(J30:J32) -> 233965.88 | K33: =SUM(K30:K32) -> 181000 | ... BF33: =SUM(BF30:BF32) -> 1909310.5 | BH33: 2150000 | BI33: 2001272.6 | BJ33: 1930000 | BK33: 1709785.7 | BL33: 1875000 | BM33: 1732992.6 | BN33: 1604008.8 | BO33: 1700000 | BP33: 1328410.9 | BQ33: 1330841.1 | BR33: 886009.82 | BS33: =SUM(BS30:BS32) -> 1835000 | BT33: =SUM(BT30:BT32) -> 1215880.2
B34: 150x150 mm | C34: Mt | D34: 349999.99 | E34: 20999.684 | F34: =38395.02-12 -> 38383.02 | G34: 0.3568633 | H34: =19481.02-67 -> 19414.02 | I34: =+E34+G34 -> 21000.041 | J34: =+F34+H34 -> 57797.04 | K34: =48.0001108831152*1000 -> 48000.111 | L34: 56218 | M34: =+E34+G34+K34 -> 69000.151 | N34: =+F34+H34+L34 -> 114015.04 | O34: =43.5001413553209*1000 -> 43500.141 | P34: 50303 | Q34: =+M34+O34 -> 112500.29 | R34: =+N34+P34 -> 164318.04 | S34: =43.5001413553209*1000 -> 43500.141 | T34: 51235.42 | U34: =+Q34+S34 -> 156000.43 | V34: =+R34+T34 -> 215553.46 | W34: =15.3000147648532*1000 -> 15300.015 | X34: 54076 | Y34: =+O34+S34+W34 -> 102300.3 | Z34: =+P34+T34+X34 -> 155614.42 | AA34: =+M34+Y34 -> 171300.45 | AB34: =+N34+Z34 -> 269629.46 | AC34: =48.9995281597563*1000 -> 48999.528 | AD34: 54595 | AE34: =+AA34+AC34 -> 220299.98 | AF34: =+AB34+AD34 -> 324224.46 | AG34: =45.4995884556746*1000 -> 45499.588 | AH34: 61080 | AI34: =+AE34+AG34 -> 265799.57 | AJ34: =+AF34+AH34 -> 385304.46 | AK34: =46.0000542442164*1000 -> 46000.054 | AL34: 52347.66 | AM34: =+AC34+AG34+AK34 -> 140499.17 | AN34: =+AD34+AH34+AL34 -> 168022.66 | AO34: =AI34+AK34 -> 311799.62 | AP34: =AJ34+AL34 -> 437652.12 | AQ34: 48499.665 | AR34: 30958 | AS34: =+AO34+AQ34 -> 360299.28 | AT34: =+AP34+AR34 -> 468610.12 | AU34: 41500.01 | AV34: 16550 | AW34: =+AS34+AU34 -> 401799.29 | AX34: =+AT34+AV34 -> 485160.12 | AY34: 46999.691 | AZ34: =38139.639-111 -> 38028.639 | BA34: =+AQ34+AU34+AY34 -> 136999.37 | BB34: =+AR34+AV34+AZ34 -> 85536.639 | BC34: =AM34+BA34 -> 277498.54 | BD34: =AN34+BB34 -> 253559.3 | BE34: =AW34+AY34 -> 448798.99 | BF34: =AX34+AZ34 -> 523188.76 | BH34: 524798.34 | BI34: 563564.31 | BJ34: 461999.56 | BK34: 558374.45 | BL34: 592000 | BM34: 574823.37 | BN34: 595119.91 | BO34: 516406.77 | BP34: 627684.57 | BQ34: 533055.82 | BR34: 608495.73 | BS34: 304999.74 | BT34: 629438.96
B35: 200x280 mm | C35: Mt | D35: 0.40803377 | E35: 0.27340158 | F35: 1625.08 | G35: 0.13463219 | H35: =3617.44+67 -> 3684.44 | I35: =+E35+G35 -> 0.40803377 | J35: =+F35+H35 -> 5309.52 | K35: 0 | L35: 1066 | M35: =+E35+G35+K35 -> 0.40803377 | N35: =+F35+H35+L35 -> 6375.52 | O35: 0 | P35: 463 | Q35: =+M35+O35 -> 0.40803377 | R35: =+N35+P35 -> 6838.52 | S35: 0 | T35: 8811.77 | U35: =+Q35+S35 -> 0.40803377 | V35: =+R35+T35 -> 15650.29 | W35: 0 | X35: 1414 | Y35: =+O35+S35+W35 -> 0 | Z35: =+P35+T35+X35 -> 10688.77 | AA35: =+M35+Y35 -> 0.40803377 | AB35: =+N35+Z35 -> 17064.29 | AC35: 0 | AD35: =11175+37 -> 11212 | AE35: =+AA35+AC35 -> 0.40803377 | AF35: =+AB35+AD35 -> 28276.29 | AG35: 0 | AH35: 0 | AI35: =+AE35+AG35 -> 0.40803377 | AJ35: =+AF35+AH35 -> 28276.29 | AK35: 0 | AL35: 703.34 | AM35: =+AC35+AG35+AK35 -> 0 | AN35: =+AD35+AH35+AL35 -> 11915.34 | AO35: =AI35+AK35 -> 0.40803377 | AP35: =AJ35+AL35 -> 28979.63 | AQ35: 0 | AR35: 7040 | AS35: =+AO35+AQ35 -> 0.40803377 | AT35: =+AP35+AR35 -> 36019.63 | AU35: 0 | AV35: 1892 | AW35: =+AS35+AU35 -> 0.40803377 | AX35: =+AT35+AV35 -> 37911.63 | AY35: 0 | AZ35: =4180.26+111 -> 4291.26 | BA35: =+AQ35+AU35+AY35 -> 0 | BB35: =+AR35+AV35+AZ35 -> 13223.26 | BC35: =AM35+BA35 -> 0 | BD35: =AN35+BB35 -> 25138.6 | BE35: =AW35+AY35 -> 0.40803377 | BF35: =AX35+AZ35 -> 42202.89 | BH35: 0 | BI35: 39893.37 | BJ35: 17999.996 | BK35: 63663.849 | BL35: 57999.916 | BM35: 101828.14 | BN35: 116079.05 | BO35: 153592.34 | BP35: 204330.35 | BQ35: 371378.01 | BR35: 329378.8 | BS35: 267000 | BT35: 248401
B36: Saleable Semis | C36: Mt | D36: =SUM(D34:D35) -> 350000.4 | E36: =SUM(E34:E35) -> 20999.957 | F36: =SUM(F34:F35) -> 40008.1 | G36: =SUM(G34:G35) -> 0.49149549 | H36: =SUM(H34:H35) -> 23098.46 | I36: =SUM(I34:I35) -> 21000.449 | J36: =SUM(J34:J35) -> 63106.56 | K36: =SUM(K34:K35) -> 48000.111 | ... BF36: =SUM(BF34:BF35) -> 565391.65 | BH36: 524798.34 | BI36: 603457.68 | BJ36: 479999.56 | BK36: 622038.3 | BL36: 649999.92 | BM36: 676651.51 | BN36: 711198.96 | BO36: 669999.11 | BP36: 832014.92 | BQ36: 904433.83 | BR36: 937874.53 | BS36: =SUM(BS34:BS35) -> 571999.74 | BT36: =SUM(BT34:BT35) -> 877839.96
B37: TOTAL SALEABLE STEEL | C37: Mt | D37: =+D33+D36 -> 2710000.4 | E37: =+E33+E36 -> 181999.96 | F37: =+F33+F36 -> 208722.19 | G37: =+G33+G36 -> 168000.49 | H37: =+H33+H36 -> 88350.248 | I37: =+I33+I36 -> 350000.45 | J37: =+J33+J36 -> 297072.44 | K37: =+K33+K36 -> 229000.11 | ... BF37: =+BF33+BF36 -> 2474702.2 | BH37: 2674798.3 | BI37: 2604730.3 | BJ37: 2409999.6 | BK37: 2331824 | BL37: 2524999.9 | BM37: 2409644.1 | BN37: 2315207.8 | BO37: 2369999.1 | BP37: 2160425.8 | BQ37: 2235274.9 | BR37: 1823884.4 | BS37: =+BS33+BS36 -> 2406999.7 | BT37: =+BT33+BT36 -> 2093720.2
B38: SAL STEEL PRODN (CATEGORY WISE)
B39: Wire Rod Plain Coils | C39: Mt | D39: =+D30 -> 520000 | E39: =+E30 -> 36500 | F39: =+WRM!F199 -> 41533 | G39: =+G30 -> 37500 | H39: =+WRM!H199 -> 21522.95 | I39: =+E39+G39 -> 74000 | J39: =+F39+H39 -> 63055.95 | K39: =+K30 -> 42500 | L39: =+WRM!L199 -> 28929.6 | M39: =+E39+G39+K39 -> 116500 | N39: =+F39+H39+L39 -> 91985.55 | O39: =+O30 -> 44000 | P39: =+WRM!P199 -> 35815.55 | Q39: =+M39+O39 -> 160500 | R39: =+N39+P39 -> 127801.1 | S39: =+S30 -> 44000 | T39: =+WRM!T199 -> 38718.35 | U39: =+Q39+S39 -> 204500 | V39: =+R39+T39 -> 166519.45 | W39: =+W30 -> 25000 | X39: =+WRM!X199 -> 41006.15 | Y39: =+O39+S39+W39 -> 113000 | Z39: =+P39+T39+X39 -> 115540.05 | AA39: =+M39+Y39 -> 229500 | AB39: =+N39+Z39 -> 207525.6 | AC39: =+AC30 -> 42500 | AD39: =+WRM!AD199 -> 30034.55 | AE39: =+AA39+AC39 -> 272000 | AF39: =+AB39+AD39 -> 237560.15 | AG39: =+AG30 -> 42500 | AH39: =+WRM!AH199 -> 34614.25 | AI39: =+AE39+AG39 -> 314500 | AJ39: =+AF39+AH39 -> 272174.4 | AK39: =+AK30 -> 44000 | AL39: =+WRM!AL199 -> 44007.35 | AM39: =+AC39+AG39+AK39 -> 129000 | AN39: =+AD39+AH39+AL39 -> 108656.15 | AO39: =AI39+AK39 -> 358500 | AP39: =AJ39+AL39 -> 316181.75 | AQ39: =+AQ30 -> 44500 | AR39: =+WRM!AR199 -> 44589.55 | AS39: =+AO39+AQ39 -> 403000 | AT39: =+AP39+AR39 -> 360771.3 | AU39: =+AU30 -> 40000 | AV39: =+WRM!AV199 -> 37420.7 | AW39: =+AS39+AU39 -> 443000 | AX39: =+AT39+AV39 -> 398192 | AY39: =+AY30 -> 44500 | AZ39: =+WRM!AZ199 -> 46692.85 | BA39: =+AQ39+AU39+AY39 -> 129000 | BB39: =+AR39+AV39+AZ39 -> 128703.1 | BC39: =AM39+BA39 -> 258000 | BD39: =AN39+BB39 -> 237359.25 | BE39: =AW39+AY39 -> 487500 | BF39: =AX39+AZ39 -> 444884.85 | BH39: 500000 | BI39: 457922.83 | BJ39: 500000 | BK39: 459030.64 | BL39: 500000 | BM39: 471802.34 | BN39: 410762.6 | BO39: =+BO30 -> 500000 | BP39: 456374.84 | BQ39: =+BQ30 -> 435965.96 | BR39: 333534.61 | BS39: 500000 | BT39: 270654.57
B40: TMT Coils | C40: Mt | F40: =+WRM!F200 -> 0 | H40: =+WRM!H200 -> 0 | J40: =+F40+H40 -> 0 | L40: =+WRM!L200 -> 9361.75 | N40: =+F40+H40+L40 -> 9361.75 | P40: =+WRM!P200 -> 11248.35 | R40: =+N40+P40 -> 20610.1 | T40: =+WRM!T200 -> 0 | V40: =+R40+T40 -> 20610.1 | X40: =+WRM!X200 -> 0 | Z40: =+P40+T40+X40 -> 11248.35 | AB40: =+N40+Z40 -> 20610.1 | AD40: =+WRM!AD200 -> 0 | AF40: =+AB40+AD40 -> 20610.1 | AH40: =+WRM!AH200 -> 0 | AJ40: =+AF40+AH40 -> 20610.1 | AL40: =+WRM!AL200 -> 0 | AN40: =+AD40+AH40+AL40 -> 0 | AP40: =AJ40+AL40 -> 20610.1 | AR40: =+WRM!AR200 -> 0 | AT40: =+AP40+AR40 -> 20610.1 | AV40: =+WRM!AV200 -> 0 | AX40: =+AT40+AV40 -> 20610.1 | AZ40: =+WRM!AZ200 -> 0 | BA40: =+AQ40+AU40+AY40 -> 0 | BB40: =+AR40+AV40+AZ40 -> 0 | BC40: =AM40+BA40 -> 0 | BD40: =AN40+BB40 -> 0 | BF40: =AX40+AZ40 -> 20610.1 | BI40: 20610.1 | BK40: 0 | BM40: 6726.05 | BN40: 55352.05 | BP40: 8968.93 | BR40: 22983.766 | BT40: 141370.65
...

Sheet Maj Despatch Summ
B1: MAJOR DESPATCH SUMMARY 2025-26 (As per Finance CENVAT report)
E2: 30 | F2: 30 | G2: 31 | H2: 31 | I2: =+G2+E2 -> 61 | J2: =+H2+F2 -> 61 | K2: 30 | L2: 30 | M2: =+E2+G2+K2 -> 91 | N2: =+F2+H2+L2 -> 91 | O2: 31 | P2: 31 | Q2: =+M2+O2 -> 122 | R2: =+N2+P2 -> 122 | S2: 31 | T2: 31 | U2: =+Q2+S2 -> 153 | V2: =+R2+T2 -> 153 | W2: 30 | X2: 30 | Y2: =+O2+S2+W2 -> 92 | Z2: =+P2+T2+X2 -> 92 | AA2: =+M2+Y2 -> 183 | AB2: =+N2+Z2 -> 183 | AC2: 31 | AD2: 31 | AE2: =AA2+AC2 -> 214 | AF2: =AB2+AD2 -> 214 | AG2: 30 | AH2: 30 | AI2: =AE2+AG2 -> 244 | AJ2: =AF2+AH2 -> 244 | AK2: 31 | AL2: 31 | AM2: =+AC2+AG2+AK2 -> 92 | AN2: =+AD2+AH2+AL2 -> 92 | AO2: =AI2+AK2 -> 275 | AP2: =AJ2+AL2 -> 275 | AQ2: 31 | AR2: 31 | AS2: =AO2+AQ2 -> 306 | AT2: =AP2+AR2 -> 306 | AU2: 28 | AV2: 28 | AW2: =AS2+AU2 -> 334 | AX2: =AT2+AV2 -> 334 | AY2: 31 | AZ2: 31 | BA2: =+AQ2+AU2+AY2 -> 90 | BB2: =+AR2+AV2+AZ2 -> 90 | BC2: =AM2+BA2 -> 182 | BD2: =AN2+BB2 -> 182 | BE2: =AW2+AY2 -> 365 | BF2: =AX2+AZ2 -> 365 | BR2: 365 | BS2: 365 | BT2: 366 | BU2: 366
B3: ITEM | C3: Unit | D3: 2026-27 ABP | E3: Apr'26 | G3: May'26 | I3: 2M | K3: Jun'25 | M3: QTR-1 | O3: Jul'25 | Q3: 4M | S3: Aug'25 | U3: 5M | W3: Sep'25 | Y3: QTR-2 | AA3: H1 | AC3: Oct'25 | AE3: 7M | AG3: Nov'25 | AI3: 8M | AK3: Dec'25 | AM3: QTR-3 | AO3: 9M | AQ3: Jan'26 | AS3: 10M | AU3: Feb'26 | AW3: 11M | AY3: Mar'26 | BA3: QTR-4 | BC3: H2 | BE3: 2026-27 | BH3: 2025-26 | BJ3: 2024-25 | BL3: 2023-24 | BN3: 2022-23 | BP3: 2021-22 | BR3: 2020-21 | BT3: 2019-20
E4: ABP | F4: ACT | G4: ABP | H4: ACT | I4: ABP | J4: ACT | K4: ABP | L4: ACT | M4: ABP | N4: ACT | O4: ABP | P4: ACT | Q4: ABP | R4: ACT | S4: ABP | T4: ACT | U4: ABP | V4: ACT | W4: ABP | X4: ACT | Y4: ABP | Z4: ACT | AA4: ABP | AB4: ACT | AC4: ABP | AD4: ACT | AE4: ABP | AF4: ACT | AG4: ABP | AH4: ACT | AI4: ABP | AJ4: ACT | AK4: ABP | AL4: ACT | AM4: ABP | AN4: ACT | AO4: ABP | AP4: ACT | AQ4: ABP | AR4: ACT | AS4: ABP | AT4: ACT | AU4: ABP | AV4: ACT | AW4: ABP | AX4: ACT | AY4: ABP | AZ4: ACT | BA4: ABP | BB4: ACT | BC4: ABP | BD4: ACT | BE4: ABP | BF4: ACT | BH4: ABP | BI4: ACT | BJ4: ABP | BK4: ACT | BL4: ABP | BM4: ACT | BN4: ABP | BO4: ACT | BP4: ABP | BQ4: ACT | BR4: ABP | BS4: ACT | BT4: ABP | BU4: ACT
B5: Saleable Steel (mill-wise)
B6: MKTG-Plant sales | C6: MT | D6: 16000 | E6: 83 | F6: 5965.35 | G6: 83 | H6: 1783.23 | I6: =+E6+G6 -> 166 | J6: =+F6+H6 -> 7748.58 | K6: 2083.3333 | L6: 6803.81 | M6: =+E6+G6+K6 -> 2249.3333 | N6: =+F6+H6+L6 -> 14552.39 | O6: 2083.3333 | P6: 3865.36 | Q6: =+M6+O6 -> 4332.6667 | R6: =+N6+P6 -> 18417.75 | S6: 2083.3333 | T6: 6257.93 | U6: =+Q6+S6 -> 6416 | V6: =+R6+T6 -> 24675.68 | W6: 2083 | X6: 5182.59 | Y6: =+O6+S6+W6 -> 6249.6667 | Z6: =+P6+T6+X6 -> 15305.88 | AA6: =+M6+Y6 -> 8499 | AB6: =+N6+Z6 -> 29858.27 | AC6: =83.3333333333333+2000 -> 2083.3333 | AD6: 5221.92 | AE6: =+AA6+AC6 -> 10582.333 | AF6: =+AB6+AD6 -> 35080.19 | AG6: 2083.3333 | AH6: 0 | AI6: =+AE6+AG6 -> 12665.667 | AJ6: =+AF6+AH6 -> 35080.19 | AK6: 2083.3333 | AL6: 2960.73 | AM6: =+AC6+AG6+AK6 -> 6250 | AN6: =+AD6+AH6+AL6 -> 8182.65 | AO6: =AI6+AK6 -> 14749 | AP6: =AJ6+AL6 -> 38040.92 | AQ6: 2083.3333 | AR6: 6204.61 | AS6: =+AO6+AQ6 -> 16832.333 | AT6: =+AP6+AR6 -> 44245.53 | AU6: 2083.3333 | AV6: 3912.15 | AW6: =+AS6+AU6 -> 18915.667 | AX6: =+AT6+AV6 -> 48157.68 | AY6: 2083.3333 | AZ6: 3740.4 | BA6: =+AQ6+AU6+AY6 -> 6250 | BB6: =+AR6+AV6+AZ6 -> 13857.16 | BC6: =AM6+BA6 -> 12500 | BD6: =AN6+BB6 -> 22039.81 | BE6: =+AW6+AY6 -> 20999 | BF6: =+AX6+AZ6 -> 51898.08 | BH6: 24999.667 | BI6: 47950.34 | BJ6: 21500 | BK6: 53987.54 | BL6: 21500 | BM6: 30649.84 | BN6: 25500 | BO6: 34807.22 | BP6: 16050 | BQ6: 33201.15 | BR6: 0 | BS6: 35268.25 | BT6: 2000 | BU6: 28405.85
B7: IPT | C7: MT | D7: 0 | E7: 0 | F7: 0 | G7: 0 | H7: 3857.66 | I7: =+E7+G7 -> 0 | J7: =+F7+H7 -> 3857.66 | K7: 0 | L7: 0 | M7: =+E7+G7+K7 -> 0 | N7: =+F7+H7+L7 -> 3857.66 | O7: 0 | P7: 64.1 | Q7: =+M7+O7 -> 0 | R7: =+N7+P7 -> 3921.76 | S7: 0 | T7: 1485.16 | U7: =+Q7+S7 -> 0 | V7: =+R7+T7 -> 5406.92 | W7: 0 | X7: 694 | Y7: =+O7+S7+W7 -> 0 | Z7: =+P7+T7+X7 -> 2243.26 | AA7: =+M7+Y7 -> 0 | AB7: =+N7+Z7 -> 6100.92 | AC7: 0 | AD7: 747.82 | AE7: =+AA7+AC7 -> 0 | AF7: =+AB7+AD7 -> 6848.74 | AG7: 0 | AH7: 0 | AI7: =+AE7+AG7 -> 0 | AJ7: =+AF7+AH7 -> 6848.74 | AK7: 0 | AL7: 244.1 | AM7: =+AC7+AG7+AK7 -> 0 | AN7: =+AD7+AH7+AL7 -> 991.92 | AO7: =AI7+AK7 -> 0 | AP7: =AJ7+AL7 -> 7092.84 | AQ7: 0 | AR7: 0 | AS7: =+AO7+AQ7 -> 0 | AT7: =+AP7+AR7 -> 7092.84 | AU7: 0 | AV7: 2333.64 | AW7: =+AS7+AU7 -> 0 | AX7: =+AT7+AV7 -> 9426.48 | AY7: 0 | AZ7: 2066.9 | BA7: =+AQ7+AU7+AY7 -> 0 | BB7: =+AR7+AV7+AZ7 -> 4400.54 | BC7: =AM7+BA7 -> 0 | BD7: =AN7+BB7 -> 5392.46 | BE7: =+AW7+AY7 -> 0 | BF7: =+AX7+AZ7 -> 11493.38 | BH7: 0 | BI7: 7635.72 | BJ7: 0 | BK7: 322.72 | BL7: 0 | BM7: 3076.2 | BN7: 123000 | BO7: 42263.08 | BP7: 0 | BQ7: 71707.42 | BR7: 10800 | BS7: 9758.51 | BT7: 24210 | BU7: 5928.095
B8: CMO-WR MILL | C8: MT | D8: 519000 | E8: 36417 | F8: 41076.23 | G8: 37417 | H8: 28878.062 | I8: =+E8+G8 -> 73834 | J8: =+F8+H8 -> 69954.292 | K8: 42416.667 | L8: 37508.06 | M8: =+E8+G8+K8 -> 116250.67 | N8: =+F8+H8+L8 -> 107462.35 | O8: 43916.667 | P8: 44133.19 | Q8: =+M8+O8 -> 160167.33 | R8: =+N8+P8 -> 151595.54 | S8: 43916.667 | T8: 40726.54 | U8: =+Q8+S8 -> 204084 | V8: =+R8+T8 -> 192322.08 | W8: 24916.667 | X8: 36332.97 | Y8: =+O8+S8+W8 -> 112750 | Z8: =+P8+T8+X8 -> 121192.7 | AA8: =+M8+Y8 -> 229000.67 | AB8: =+N8+Z8 -> 228655.05 | AC8: 42416.667 | AD8: 31032.3 | AE8: =+AA8+AC8 -> 271417.33 | AF8: =+AB8+AD8 -> 259687.35 | AG8: 42416.667 | AH8: 38334.736 | AI8: =+AE8+AG8 -> 313834 | AJ8: =+AF8+AH8 -> 298022.09 | AK8: 43916.667 | AL8: 41187.81 | AM8: =+AC8+AG8+AK8 -> 128750 | AN8: =+AD8+AH8+AL8 -> 110554.85 | AO8: =AI8+AK8 -> 357750.67 | AP8: =AJ8+AL8 -> 339209.9 | AQ8: 44416.667 | AR8: 39752.561 | AS8: =+AO8+AQ8 -> 402167.33 | AT8: =+AP8+AR8 -> 378962.46 | AU8: 39916.667 | AV8: 41871.84 | AW8: =+AS8+AU8 -> 442084 | AX8: =+AT8+AV8 -> 420834.3 | AY8: 44416.667 | AZ8: 48073.32 | BA8: =+AQ8+AU8+AY8 -> 128750 | BB8: =+AR8+AV8+AZ8 -> 129697.72 | BC8: =AM8+BA8 -> 257500 | BD8: =AN8+BB8 -> 240252.57 | BE8: =+AW8+AY8 -> 486500.67 | BF8: =+AX8+AZ8 -> 468907.62 | BH8: 499000 | BI8: 471653.15 | BJ8: 498500 | BK8: 459216.41 | BL8: 498500 | BM8: 473494.21 | BN8: 498500 | BO8: 453432.75 | BP8: 498500 | BQ8: 467953.64 | BR8: 435166.29 | BS8: 351267.02 | BT8: 498000 | BU8: 399090.26
B9: CMO-BAR MILL | C9: MT | D9: 990000 | E9: 68500 | F9: 78698.73 | G9: 71000 | H9: 35387.67 | I9: =+E9+G9 -> 139500 | J9: =+F9+H9 -> 114086.4 | K9: 76000 | L9: 73175.63 | M9: =+E9+G9+K9 -> 215500 | N9: =+F9+H9+L9 -> 187262.03 | O9: 79000 | P9: 84102.5 | Q9: =+M9+O9 -> 294500 | R9: =+N9+P9 -> 271364.53 | S9: 79000 | T9: 86905.93 | U9: =+Q9+S9 -> 373500 | V9: =+R9+T9 -> 358270.46 | W9: 47500 | X9: 68689.99 | Y9: =+O9+S9+W9 -> 205500 | Z9: =+P9+T9+X9 -> 239698.42 | AA9: =+M9+Y9 -> 421000 | AB9: =+N9+Z9 -> 426960.45 | AC9: 78000 | AD9: 52260.41 | AE9: =+AA9+AC9 -> 499000 | AF9: =+AB9+AD9 -> 479220.86 | AG9: 76000 | AH9: 70091.169 | AI9: =+AE9+AG9 -> 575000 | AJ9: =+AF9+AH9 -> 549312.03 | AK9: 79000 | AL9: 83237.28 | AM9: =+AC9+AG9+AK9 -> 233000 | AN9: =+AD9+AH9+AL9 -> 205588.86 | AO9: =AI9+AK9 -> 654000 | AP9: =AJ9+AL9 -> 632549.31 | AQ9: 79000 | AR9: 79536.07 | AS9: =+AO9+AQ9 -> 733000 | AT9: =+AP9+AR9 -> 712085.38 | AU9: 71500 | AV9: 77559.29 | AW9: =+AS9+AU9 -> 804500 | AX9: =+AT9+AV9 -> 789644.67 | AY9: 80000 | AZ9: 81642.31 | BA9: =+AQ9+AU9+AY9 -> 230500 | BB9: =+AR9+AV9+AZ9 -> 238737.67 | BC9: =AM9+BA9 -> 463500 | BD9: =AN9+BB9 -> 444326.53 | BE9: =+AW9+AY9 -> 884500 | BF9: =+AX9+AZ9 -> 871286.98 | BH9: 900000 | BI9: 884559.69 | BJ9: 870000 | BK9: 750184.19 | BL9: 850000 | BM9: 781402.45 | BN9: 780000 | BO9: 768402.31 | BP9: 750000 | BQ9: 648761.89 | BR9: 674874.74 | BS9: 436958.46 | BT9: 800000 | BU9: 612890.55
