Workbook
Name _1: #REF!
Name _1: #REF!
Name _1: #REF!
Name _1: #REF!
Name _1: #REF!
Name _1: #REF!
Name _1: #REF!
Name _1: #REF!
Name _1: #REF!
Name _2: #REF!
Name _2: #REF!
Name _2: #REF!
Name _2: #REF!
Name _2: #REF!
Name _2: #REF!
Name _2: #REF!
Name _2: #REF!
Name _2: #REF!
Name _3: #REF!
Name _3: #REF!
Name _3: #REF!
Name _3: #REF!
Name _3: #REF!
Name _3: #REF!
Name _3: #REF!
Name _3: #REF!
Name _4: #REF!
Name _4: #REF!
Name _4: #REF!
Name a: #REF!
Name a: #REF!
Name a: #REF!
Name a: #REF!
Name a: #REF!
Name AA: #REF!
Name AA: #REF!
Name AA: #REF!
Name AA: #REF!
Name AB: #REF!
Name AB: #REF!
Name AB: #REF!
Name AB: #REF!
Name AC: #REF!
Name AC: #REF!
Name AC: #REF!
Name AD: #REF!
Name AD: #REF!
Name AD: #REF!
Name AE: #REF!
Name AE: #REF!
Name AE: #REF!
Name AF: #REF!
Name AF: #REF!
Name AF: #REF!
Name AG: #REF!
Name AG: #REF!
Name AG: #REF!
Name AH: #REF!
Name AH: #REF!
Name AH: #REF!

Sheet Maj Production Summ
B1: MAJOR PRODUCTION SUMMARY | D1: 341.01687 | E1: 29 | F1: =F2-'B-FCE'!F3 -> 26.666667 | G1: 30 | H1: =H2-'B-FCE'!H3 -> 29.791667 | I1: =E1+G1 -> 59 | J1: =F1+H1 -> 56.458333 | K1: 29 | L1: =L2-'B-FCE'!L3 -> 29.61125 | M1: =+E1+G1+K1 -> 88 | N1: =+F1+H1+L1 -> 86.069583 | O1: 30 | P1: =P2-'B-FCE'!P3 -> 31 | Q1: =+M1+O1 -> 118 | R1: =+N1+P1 -> 117.06958 | S1: 30 | T1: =T2-'B-FCE'!T3 -> 30.024306 | U1: =+Q1+S1 -> 148 | V1: =+R1+T1 -> 147.09389 | W1: 17.016867 | X1: =X2-'B-FCE'!X3 -> 29.67375 | Y1: =+O1+S1+W1 -> 77.016867 | Z1: =+P1+T1+X1 -> 90.698056 | AA1: =+U1+W1 -> 165.01687 | AB1: =+V1+X1 -> 176.76764 | AC1: 30 | AD1: =AD2-'B-FCE'!AD3 -> 29.965417 | AE1: =AA1+AC1 -> 195.01687 | AF1: =AB1+AD1 -> 206.73306 | AG1: 29 | AH1: 1 | AI1: =AE1+AG1 -> 224.01687 | AJ1: =AF1+AH1 -> 207.73306 | AK1: 30 | AL1: =31-'B-FCE'!AL3 -> 30.75 | AM1: =+AC1+AG1+AK1 -> 89 | AN1: =+AD1+AH1+AL1 -> 61.715417 | AO1: =AI1+AK1 -> 254.01687 | AP1: =AJ1+AL1 -> 238.48306 | AQ1: 30 | AR1: =31-'B-FCE'!AR3 -> 29.875 | AS1: =AO1+AQ1 -> 284.01687 | AT1: =AP1+AR1 -> 268.35806 | AU1: 27 | AV1: =28-'B-FCE'!AV3 -> 27.1875 | AW1: =AS1+AU1 -> 311.01687 | AX1: =AT1+AV1 -> 295.54556 | AY1: 30 | AZ1: =31-'B-FCE'!AZ3 -> 30.229167 | BA1: =+AQ1+AU1+AY1 -> 87 | BB1: =+AR1+AV1+AZ1 -> 87.291667 | BC1: =+AM1+BA1 -> 176 | BD1: =+AN1+BB1 -> 149.00708 | BE1: =AW1+AY1 -> 341.01687 | BF1: =AX1+AZ1 -> 325.77472
D2: 365 | E2: 30 | F2: 30 | G2: 31 | H2: 31 | I2: =+E2+G2 -> 61 | J2: =+F2+H2 -> 61 | K2: 30 | L2: 30 | M2: =+I2+K2 -> 91 | N2: =+J2+L2 -> 91 | O2: 31 | P2: 31 | Q2: =+M2+O2 -> 122 | R2: =+N2+P2 -> 122 | S2: 31 | T2: 31 | U2: =+Q2+S2 -> 153 | V2: =+R2+T2 -> 153 | W2: 30 | X2: 30 | Y2: =+O2+S2+W2 -> 92 | Z2: =+P2+T2+X2 -> 92 | AA2: =+U2+W2 -> 183 | AB2: =+V2+X2 -> 183 | AC2: 31 | AD2: 31 | AE2: =AA2+AC2 -> 214 | AF2: =AB2+AD2 -> 214 | AG2: 30 | AH2: 30 | AI2: =AE2+AG2 -> 244 | AJ2: =AF2+AH2 -> 244 | AK2: 31 | AL2: 31 | AM2: =+AC2+AG2+AK2 -> 92 | AN2: =+AD2+AH2+AL2 -> 92 | AO2: =AI2+AK2 -> 275 | AP2: =AJ2+AL2 -> 275 | AQ2: 31 | AR2: 31 | AS2: =AO2+AQ2 -> 306 | AT2: =AP2+AR2 -> 306 | AU2: 28 | AV2: 28 | AW2: =AS2+AU2 -> 334 | AX2: =AT2+AV2 -> 334 | AY2: 31 | AZ2: 31 | BA2: =+AQ2+AU2+AY2 -> 90 | BB2: =+AR2+AV2+AZ2 -> 90 | BC2: =+AM2+BA2 -> 182 | BD2: =+AN2+BB2 -> 182 | BE2: =AW2+AY2 -> 365 | BF2: =AX2+AZ2 -> 365 | BN2: 365 | BO2: 365 | BP2: 366 | BQ2: 366
B3: ITEM | C3: Unit | D3: 2025-26 ABP | E3: Apr'25 | G3: May'25 | I3: 2M | K3: Jun'25 | M3: QTR-1 | O3: Jul'25 | Q3: 4M | S3: Aug'25 | U3: 5M | W3: Sep'25 | Y3: QTR 2 | AA3: H1 | AC3: Oct'24 | AE3: 7M | AG3: Nov'24 | AI3: 8M | AK3: Dec'24 | AM3: QTR 3 | AO3: 9M | AQ3: Jan'25 | AS3: 10M | AU3: Feb'25 | AW3: 11M | AY3: Mar'25 | BA3: QTR 4 | BC3: H2 | BE3: 2024-25 | BG3: 2024-25 | BI3: 2023-24 | BK3: 2022-23 | BL3: 2021-22 | BN3: 2020-21 | BP3: 2019-20
E4: ABP | F4: ACT | G4: ABP | H4: ACT | I4: ABP | J4: ACT | K4: ABP | L4: ACT | M4: ABP | N4: ACT | O4: ABP | P4: ACT | Q4: ABP | R4: ACT | S4: ABP | T4: ACT | U4: ABP | V4: ACT | W4: ABP | X4: ACT | Y4: ABP | Z4: ACT | AA4: ABP | AB4: ACT | AC4: ABP | AD4: ACT | AE4: ABP | AF4: ACT | AG4: ABP | AH4: ACT | AI4: ABP | AJ4: ACT | AK4: ABP | AL4: ACT | AM4: ABP | AN4: ACT | AO4: ABP | AP4: ACT | AQ4: ABP | AR4: ACT | AS4: ABP | AT4: ACT | AU4: ABP | AV4: ACT | AW4: ABP | AX4: ACT | AY4: ABP | AZ4: ACT | BA4: ABP | BB4: ACT | BC4: ABP | BD4: ACT | BE4: ABP | BF4: ACT | BG4: ABP | BH4: ACT | BI4: ABP | BJ4: ACT | BK4: ACT | BL4: ABP | BM4: ACT | BN4: ABP | BO4: ACT | BP4: ABP | BQ4: ACT
B5: COKE OVENS PUSHING
B6: (COB#10) | C6: Nos/ day | D6: 94.512329 | E6: 98 | F6: =+F9/F2 -> 97.2 | G6: 98 | H6: =+H9/H2 -> 97.612903 | I6: =+((E6*$E$2)+(G6*$G$2))/$I$2 -> 98 | J6: =+((F6*$F$2)+(H6*$H$2))/$J$2 -> 97.409836 | K6: 94 | L6: =+L9/L2 -> 96.066667 | M6: =+((E6*$E$2)+(G6*$G$2)+(K6*$K$2))/$M$2 -> 96.681319 | N6: =+((F6*$F$2)+(H6*$H$2)+(L6*$L$2))/$N$2 -> 96.967033 | O6: 94 | P6: =+P9/P2 -> 95.419355 | Q6: =+((M6*M$2)+(O6*O$2))/Q$2 -> 96 | R6: =+((N6*N$2)+(P6*P$2))/R$2 -> 96.57377 | S6: 94 | T6: =+T9/T2 -> 98 | U6: =+((Q6*Q$2)+(S6*S$2))/U$2 -> 95.594771 | V6: =+((R6*R$2)+(T6*T$2))/V$2 -> 96.862745 | W6: 92.1 | X6: =+X9/X2 -> 98 | Y6: =+((O$6*O$2)+(S$6*S$2)+(W$6*W$2))/Y$2 -> 93.380435 | Z6: =+((P$6*P$2)+(T$6*T$2)+(X$6*X$2))/Z$2 -> 97.130435 | AA6: =+((M6*M$2)+(Y6*Y$2))/AA$2 -> 95.021858 | AB6: =+((N6*N$2)+(Z6*Z$2))/AB$2 -> 97.04918 | AC6: 96 | AD6: =+AD9/AD2 -> 98 | AE6: =+((AA6*$AA$2)+(AC6*$AC$2))/$AE$2 -> 95.163551 | AF6: =+((AB6*$AB$2)+(AD6*$AD$2))/$AF$2 -> 97.186916 | AG6: 96 | AH6: =+AH9/AH2 -> 94.3 | AI6: =+((AE6*$AE$2)+(AG6*$AG$2))/$AI$2 -> 95.266393 | AJ6: =+((AF6*$AF$2)+(AH6*$AH$2))/$AJ$2 -> 96.831967 | AK6: 96 | AL6: =+AL9/AL2 -> 98 | AM6: =+((AC$6*AC$2)+(AG$6*AG$2)+(AK$6*AK$2))/AM$2 -> 96 | AN6: =+((AD$6*AD$2)+(AH$6*AH$2)+(AL$6*AL$2))/AN$2 -> 96.793478 | AO6: =+((AK6*$AK$2)+(AI6*$AI$2))/$AO$2 -> 95.349091 | AP6: =+((AL6*$AL$2)+(AJ6*$AJ$2))/$AP$2 -> 96.963636 | AQ6: 96 | AR6: =+AR9/AR2 -> 98 | AS6: =+((AO6*$AO$2)+(AQ6*$AQ$2))/$AS$2 -> 95.415033 | AT6: =+((AP6*$AP$2)+(AR6*$AR$2))/$AT$2 -> 97.068627 | AU6: 96 | AV6: =+AV9/AV2 -> 97.678571 | AW6: =+((AS6*$AS$2)+(AU6*$AU$2))/$AW$2 -> 95.464072 | AX6: =+((AT6*$AT$2)+(AV6*$AV$2))/$AX$2 -> 97.11976 | AY6: 96 | AZ6: =+AZ9/AZ2 -> 98 | BA6: =+((AQ$6*AQ$2)+(AU$6*AU$2)+(AY$6*AY$2))/BA$2 -> 96 | BB6: =+((AR$6*AR$2)+(AV$6*AV$2)+(AZ$6*AZ$2))/BB$2 -> 97.9 | BC6: =+((AM6*AM$2)+(BA6*BA$2))/BC$2 -> 96 | BD6: =+((AN6*AN$2)+(BB6*BB$2))/BD$2 -> 97.340659 | BE6: =+((AW6*$AW$2)+(AY6*$AY$2))/$BE$2 -> 95.509589 | BF6: =+((AZ6*$AZ$2)+(AX6*$AX$2))/$BF$2 -> 97.194521 | BG6: 96.420548 | BH6: 97.709589 | BI6: 99 | BJ6: 98.976067 | BK6: 98.783562 | BL6: 99 | BM6: 97.824658 | BN6: 95.547945 | BO6: 95.342466 | BP6: 97 | BQ6: 97.10959
B7: (COB#11) | C7: Nos/ day | D7: 97.630137 | E7: 98 | F7: =+F10/F2 -> 97.1 | G7: 98 | H7: =+H10/H2 -> 97.483871 | I7: =+((E7*$E$2)+(G7*$G$2))/$I$2 -> 98 | J7: =+((F7*$F$2)+(H7*$H$2))/$J$2 -> 97.295082 | K7: 98 | L7: =+L10/L2 -> 98.466667 | M7: =+((E7*$E$2)+(G7*$G$2)+(K7*$K$2))/$M$2 -> 98 | N7: =+((F7*$F$2)+(H7*$H$2)+(L7*$L$2))/$N$2 -> 97.681319 | O7: 98 | P7: =+P10/P2 -> 99 | Q7: =+((M7*M$2)+(O7*O$2))/Q$2 -> 98 | R7: =+((N7*N$2)+(P7*P$2))/R$2 -> 98.016393 | S7: 98 | T7: =+T10/T2 -> 98.516129 | U7: =+((Q7*Q$2)+(S7*S$2))/U$2 -> 98 | V7: =+((R7*R$2)+(T7*T$2))/V$2 -> 98.117647 | W7: 93.5 | X7: =+X10/X2 -> 98.766667 | Y7: =((O7*O2)+(S7*S2)+(W7*W2))/Y2 -> 96.532609 | Z7: =+((P$7*P$2)+(T$7*T$2)+(X$7*X$2))/Z$2 -> 98.76087 | AA7: =+((M7*M$2)+(Y7*Y$2))/AA$2 -> 97.262295 | AB7: =+((N7*N$2)+(Z7*Z$2))/AB$2 -> 98.224044 | AC7: 99 | AD7: =+AD10/AD2 -> 97.83871 | AE7: =+((AA7*$AA$2)+(AC7*$AC$2))/$AE$2 -> 97.514019 | AF7: =+((AB7*$AB$2)+(AD7*$AD$2))/$AF$2 -> 98.168224 | AG7: 99 | AH7: =+AH10/AH2 -> 94 | AI7: =+((AE7*$AE$2)+(AG7*$AG$2))/$AI$2 -> 97.696721 | AJ7: =+((AF7*$AF$2)+(AH7*$AH$2))/$AJ$2 -> 97.655738 | AK7: 99 | AL7: =+AL10/AL2 -> 98.483871 | AM7: =+((AC$7*AC$2)+(AG$7*AG$2)+(AK$7*AK$2))/AM$2 -> 99 | AN7: =+((AD$7*AD$2)+(AH$7*AH$2)+(AL$7*AL$2))/AN$2 -> 96.804348 | AO7: =+((AK7*$AK$2)+(AI7*$AI$2))/$AO$2 -> 97.843636 | AP7: =+((AL7*$AL$2)+(AJ7*$AJ$2))/$AP$2 -> 97.749091 | AQ7: 99 | AR7: =+AR10/AR2 -> 98.483871 | AS7: =+((AO7*$AO$2)+(AQ7*$AQ$2))/$AS$2 -> 97.960784 | AT7: =+((AP7*$AP$2)+(AR7*$AR$2))/$AT$2 -> 97.823529 | AU7: 99 | AV7: =+AV10/AV2 -> 98.392857 | AW7: =+((AS7*$AS$2)+(AU7*$AU$2))/$AW$2 -> 98.047904 | AX7: =+((AT7*$AT$2)+(AV7*$AV$2))/$AX$2 -> 97.871257 | AY7: 99 | AZ7: =+AZ10/AZ2 -> 98.645161 | BA7: =+((AQ$7*AQ$2)+(AU$7*AU$2)+(AY$7*AY$2))/BA$2 -> 99 | BB7: =+((AR$7*AR$2)+(AV$7*AV$2)+(AZ$7*AZ$2))/BB$2 -> 98.511111 | BC7: =+((AM7*AM$2)+(BA7*BA$2))/BC$2 -> 99 | BD7: =+((AN7*AN$2)+(BB7*BB$2))/BD$2 -> 97.648352 | BE7: =+((AW7*$AW$2)+(AY7*$AY$2))/$BE$2 -> 98.128767 | BF7: =+((AZ7*$AZ$2)+(AX7*$AX$2))/$BF$2 -> 97.936986 | BG7: 98.167671 | BH7: 97.991781 | BI7: 98.000061 | BJ7: 96.670251 | BK7: 92.210959 | BL7: 99 | BM7: 96.816438 | BN7: 94.2 | BO7: 90.778082 | BP7: 97 | BQ7: 95.710246
B8: Overall Equiv. Ovens Pushed/ Day | C8: Nos/ day | D8: =+D6+(D7*(31.55/17.2)) -> 273.59552 | E8: =+E6+(E7*(31.55/17.2)) -> 277.76163 | F8: =+F6+(F7*(31.55/17.2)) -> 275.31076 | G8: =+G6+(G7*(31.55/17.2)) -> 277.76163 | H8: =+H6+(H7*(31.55/17.2)) -> 276.42779 | I8: =+I6+(I7*(31.55/17.2)) -> 277.76163 | J8: =+J6+(J7*(31.55/17.2)) -> 275.87843 | K8: =+K6+(K7*(31.55/17.2)) -> 273.76163 | ... X8: =+X6+(X7*(31.55/17.2)) -> 279.16793 | Y8: =Y6+(Y7*31.55/17.2) -> 270.45042 | Z8: =Z6+(Z7*31.55/17.2) -> 278.28773 | AA8: =AA6+(AA7*31.55/17.2) -> 273.43031 | AB8: =AB6+(AB7*31.55/17.2) -> 277.22177 | AC8: =+AC6+(AC7*(31.55/17.2)) -> 277.59593 | AD8: =+AD6+(AD7*(31.55/17.2)) -> 277.46577 | AE8: =+AE6+(AE7*(31.55/17.2)) -> 274.03374 | AF8: =+AF6+(AF7*(31.55/17.2)) -> 277.25712 | AG8: =+AG6+(AG7*(31.55/17.2)) -> 277.59593 | AH8: =+AH6+(AH7*(31.55/17.2)) -> 266.72442 | AI8: =+AI6+(AI7*(31.55/17.2)) -> 274.47172 | AJ8: =+AJ6+(AJ7*(31.55/17.2)) -> 275.96211 | ... AL8: =+AL6+(AL7*(31.55/17.2)) -> 278.64919 | AM8: =AM6+(AM7*31.55/17.2) -> 277.59593 | AN8: =AN6+(AN7*31.55/17.2) -> 274.36192 | AO8: =+AO6+(AO7*(31.55/17.2)) -> 274.8239 | AP8: =+AP6+(AP7*(31.55/17.2)) -> 276.26502 | AQ8: =+AQ6+(AQ7*(31.55/17.2)) -> 277.59593 | AR8: =+AR6+(AR7*(31.55/17.2)) -> 278.64919 | AS8: =+AS6+(AS7*(31.55/17.2)) -> 275.10473 | AT8: =+AT6+(AT7*(31.55/17.2)) -> 276.50655 | AU8: =+AU6+(AU7*(31.55/17.2)) -> 277.59593 | AV8: =+AV6+(AV7*(31.55/17.2)) -> 278.16082 | ... AZ8: =+AZ6+(AZ7*(31.55/17.2)) -> 278.94505 | BA8: =BA6+(BA7*31.55/17.2) -> 277.59593 | BB8: =BB6+(BB7*31.55/17.2) -> 278.59916 | BC8: =BC6+(BC7*31.55/17.2) -> 277.59593 | BD8: =BD6+(BD7*31.55/17.2) -> 276.45726 | BE8: =+BE6+(BE7*(31.55/17.2)) -> 275.50741 | BF8: =+BF6+(BF7*(31.55/17.2)) -> 276.84056 | BG8: 276.48974 | BH8: 277.45614 | BI8: 278.76174 | BJ8: 276.29853 | BK8: 267.92634 | BL8: 280.59593 | BM8: 275.41528 | BN8: 268.33922 | BO8: 261.85691 | BP8: 274.92733 | BQ8: 272.67112
B9: (COB#10) | C9: Nos | D9: =+D6*D2 -> 34497 | E9: =+E6*E2 -> 2940 | F9: 2916 | G9: =+G6*G2 -> 3038 | H9: 3026 | I9: =+I6*I2 -> 5978 | J9: =+F9+H9 -> 5942 | K9: =+K6*K2 -> 2820 | L9: 2882 | M9: =+E9+G9+K9 -> 8798 | N9: =+F9+H9+L9 -> 8824 | O9: =+O6*O2 -> 2914 | P9: 2958 | Q9: =+M9+O9 -> 11712 | R9: =+N9+P9 -> 11782 | S9: =+S6*S2 -> 2914 | T9: 3038 | U9: =+Q9+S9 -> 14626 | V9: =+R9+T9 -> 14820 | W9: =+W6*W2 -> 2763 | X9: 2940 | Y9: =+O9+S9+W9 -> 8591 | Z9: =+P9+T9+X9 -> 8936 | AA9: =M9+Y9 -> 17389 | AB9: =+N9+Z9 -> 17760 | AC9: =+AC6*AC2 -> 2976 | AD9: 3038 | AE9: =+AE6*AE2 -> 20365 | AF9: =+AB9+AD9 -> 20798 | AG9: =+AG6*AG2 -> 2880 | AH9: 2829 | AI9: =+AI6*AI2 -> 23245 | AJ9: =+AF9+AH9 -> 23627 | AK9: =+AK6*AK2 -> 2976 | AL9: 3038 | AM9: =+AC9+AG9+AK9 -> 8832 | AN9: =+AD9+AH9+AL9 -> 8905 | AO9: =AI9+AK9 -> 26221 | AP9: =AJ9+AL9 -> 26665 | AQ9: =+AQ6*AQ2 -> 2976 | AR9: 3038 | AS9: =+AS6*AS2 -> 29197 | AT9: =+AP9+AR9 -> 29703 | AU9: =+AU6*AU2 -> 2688 | AV9: 2735 | AW9: =+AW6*AW2 -> 31885 | AX9: =+AT9+AV9 -> 32438 | AY9: =+AY6*AY2 -> 2976 | AZ9: 3038 | BA9: =+AQ9+AU9+AY9 -> 8640 | BB9: =+AR9+AV9+AZ9 -> 8811 | BC9: =AM9+BA9 -> 17472 | BD9: =AN9+BB9 -> 17716 | BE9: =AW9+AY9 -> 34861 | BF9: =AX9+AZ9 -> 35476 | BG9: 35193.5 | BH9: 35664 | BI9: 36234 | BJ9: 36225 | BK9: 36056 | BL9: 36135 | BM9: 35706 | BN9: 34875 | BO9: 34800 | BP9: 35502 | BQ9: 35543
B10: (COB#11) | C10: Nos | D10: =+D7*D2 -> 35635 | E10: =+E7*E2 -> 2940 | F10: 2913 | G10: =+G7*G2 -> 3038 | H10: 3022 | I10: =+I7*I2 -> 5978 | J10: =+F10+H10 -> 5935 | K10: =+K7*K2 -> 2940 | L10: 2954 | M10: =+E10+G10+K10 -> 8918 | N10: =+F10+H10+L10 -> 8889 | O10: =+O7*O2 -> 3038 | P10: 3069 | Q10: =+M10+O10 -> 11956 | R10: =+N10+P10 -> 11958 | S10: =+S7*S2 -> 3038 | T10: 3054 | U10: =+Q10+S10 -> 14994 | V10: =+R10+T10 -> 15012 | W10: =+W7*W2 -> 2805 | X10: 2963 | Y10: =+O10+S10+W10 -> 8881 | Z10: =+P10+T10+X10 -> 9086 | AA10: =+M10+Y10 -> 17799 | AB10: =+N10+Z10 -> 17975 | AC10: =+AC7*AC2 -> 3069 | AD10: 3033 | AE10: =+AE7*AE2 -> 20868 | AF10: =+AB10+AD10 -> 21008 | AG10: =+AG7*AG2 -> 2970 | AH10: 2820 | AI10: =+AI7*AI2 -> 23838 | AJ10: =+AF10+AH10 -> 23828 | AK10: =+AK7*AK2 -> 3069 | AL10: 3053 | AM10: =+AC10+AG10+AK10 -> 9108 | AN10: =+AD10+AH10+AL10 -> 8906 | AO10: =AI10+AK10 -> 26907 | AP10: =AJ10+AL10 -> 26881 | AQ10: =+AQ7*AQ2 -> 3069 | AR10: 3053 | AS10: =+AS7*AS2 -> 29976 | AT10: =+AP10+AR10 -> 29934 | AU10: =+AU7*AU2 -> 2772 | AV10: 2755 | AW10: =+AW7*AW2 -> 32748 | AX10: =+AT10+AV10 -> 32689 | AY10: =+AY7*AY2 -> 3069 | AZ10: 3058 | BA10: =+AQ10+AU10+AY10 -> 8910 | BB10: =+AR10+AV10+AZ10 -> 8866 | BC10: =AM10+BA10 -> 18018 | BD10: =AN10+BB10 -> 17772 | BE10: =AW10+AY10 -> 35817 | BF10: =AX10+AZ10 -> 35747 | BG10: 35831.2 | BH10: 35767 | BI10: 35868.022 | BJ10: 35382 | BK10: 33657 | BL10: 36135 | BM10: 35338 | BN10: 34383 | BO10: 33134 | BP10: 35502 | BQ10: 35030
B11: Overall Equiv. Ovens Pushed | C11: Nos | D11: =+D9+(D10*(31.55/17.2)) -> 99862.363 | E11: =+E9+(E10*(31.55/17.2)) -> 8332.8488 | F11: =+F9+(F10*(31.55/17.2)) -> 8259.3227 | G11: =+G9+(G10*(31.55/17.2)) -> 8610.6105 | H11: =+H9+(H10*(31.55/17.2)) -> 8569.2616 | I11: =+I9+(I10*(31.55/17.2)) -> 16943.459 | J11: =+J9+(J10*(31.55/17.2)) -> 16828.584 | K11: =+K9+(K10*(31.55/17.2)) -> 8212.8488 | ... X11: =+X9+(X10*(31.55/17.2)) -> 8375.0378 | Y11: =Y9+(Y10*31.55/17.2) -> 24881.439 | Z11: =Z9+(Z10*31.55/17.2) -> 25602.471 | AA11: =AA9+(AA10*31.55/17.2) -> 50037.747 | AB11: =AB9+(AB10*31.55/17.2) -> 50731.584 | AC11: =+AC9+(AC10*(31.55/17.2)) -> 8605.4738 | AD11: =+AD9+(AD10*(31.55/17.2)) -> 8601.439 | AE11: =+AE9+(AE10*(31.55/17.2)) -> 58643.221 | AF11: =+AF9+(AF10*(31.55/17.2)) -> 59333.023 | AG11: =+AG9+(AG10*(31.55/17.2)) -> 8327.8779 | AH11: =+AH9+(AH10*(31.55/17.2)) -> 8001.7326 | AI11: =+AI9+(AI10*(31.55/17.2)) -> 66971.099 | AJ11: =+AJ9+(AJ10*(31.55/17.2)) -> 67334.756 | ... AL11: =+AL9+(AL10*(31.55/17.2)) -> 8638.125 | AM11: =AM9+(AM10*31.55/17.2) -> 25538.826 | AN11: =AN9+(AN10*31.55/17.2) -> 25241.297 | AO11: =+AO9+(AO10*(31.55/17.2)) -> 75576.573 | AP11: =+AP9+(AP10*(31.55/17.2)) -> 75972.881 | AQ11: =+AQ9+(AQ10*(31.55/17.2)) -> 8605.4738 | AR11: =+AR9+(AR10*(31.55/17.2)) -> 8638.125 | AS11: =+AS9+(AS10*(31.55/17.2)) -> 84182.047 | AT11: =+AT9+(AT10*(31.55/17.2)) -> 84611.006 | AU11: =+AU9+(AU10*(31.55/17.2)) -> 7772.686 | AV11: =+AV9+(AV10*(31.55/17.2)) -> 7788.5029 | ... AZ11: =+AZ9+(AZ10*(31.55/17.2)) -> 8647.2965 | BA11: =BA9+(BA10*31.55/17.2) -> 24983.634 | BB11: =BB9+(BB10*31.55/17.2) -> 25073.924 | BC11: =BC9+(BC10*31.55/17.2) -> 50522.459 | BD11: =BD9+(BD10*31.55/17.2) -> 50315.221 | BE11: =+BE9+(BE10*(31.55/17.2)) -> 100560.21 | BF11: =+BF9+(BF10*(31.55/17.2)) -> 101046.81 | BG11: 100918.75 | BH11: 101271.49 | BI11: 102026.8 | BJ11: 101126.28 | BK11: 97793.113 | BL11: 102417.51 | BM11: 100526.58 | BN11: 97943.817 | BO11: 95577.773 | BP11: 100623.4 | BQ11: 99798.61
B12: BF COKE
B13: COB#10 | C13: Mt | D13: =+D9*0.7*17.2 -> 415343.88 | E13: =+E9*0.7*17.2 -> 35397.6 | F13: ='COKE OVENS'!F21 -> 35108.64 | G13: =+G9*0.7*17.2 -> 36577.52 | H13: ='COKE OVENS'!H21 -> 36433.04 | I13: =+E13+G13 -> 71975.12 | J13: =+F13+H13 -> 71541.68 | K13: =+K9*0.7*17.2 -> 33952.8 | L13: ='COKE OVENS'!L21 -> 34699.28 | M13: =+E13+G13+K13 -> 105927.92 | N13: =+F13+H13+L13 -> 106240.96 | O13: =+O9*0.7*17.2 -> 35084.56 | P13: ='COKE OVENS'!P21 -> 35614.32 | Q13: =+M13+O13 -> 141012.48 | R13: =+N13+P13 -> 141855.28 | S13: =+S9*0.7*17.2 -> 35084.56 | T13: ='COKE OVENS'!T21 -> 36577.52 | U13: =+Q13+S13 -> 176097.04 | V13: =+R13+T13 -> 178432.8 | W13: =+W9*0.7*17.2 -> 33266.52 | X13: ='COKE OVENS'!X21 -> 35397.6 | Y13: =+O13+S13+W13 -> 103435.64 | Z13: =+P13+T13+X13 -> 107589.44 | AA13: =+M13+Y13 -> 209363.56 | AB13: =+N13+Z13 -> 213830.4 | AC13: =+AC9*0.7*17.2 -> 35831.04 | AD13: ='COKE OVENS'!AD21 -> 36839 | AE13: =+AA13+AC13 -> 245194.6 | AF13: =+AB13+AD13 -> 250669.4 | AG13: =+AG9*0.7*17.2 -> 34675.2 | AH13: ='COKE OVENS'!AH21 -> 34299.588 | AI13: =+AE13+AG13 -> 279869.8 | AJ13: =+AF13+AH13 -> 284968.99 | AK13: =+AK9*0.7*17.2 -> 35831.04 | AL13: ='COKE OVENS'!AL21 -> 36582.745 | AM13: =+AC13+AG13+AK13 -> 106337.28 | AN13: =+AD13+AH13+AL13 -> 107721.33 | AO13: =AI13+AK13 -> 315700.84 | AP13: =AJ13+AL13 -> 321551.73 | AQ13: =+AQ9*0.7*17.2 -> 35831.04 | AR13: ='COKE OVENS'!AR21 -> 36888.429 | AS13: =+AO13+AQ13 -> 351531.88 | AT13: =+AP13+AR13 -> 358440.16 | AU13: =+AU9*0.7*17.2 -> 32363.52 | AV13: ='COKE OVENS'!AV21 -> 33164.61 | AW13: =+AS13+AU13 -> 383895.4 | AX13: =+AT13+AV13 -> 391604.77 | AY13: =+AY9*0.7*17.2 -> 35831.04 | AZ13: ='COKE OVENS'!AZ21 -> 36838.788 | BA13: =+AQ13+AU13+AY13 -> 104025.6 | BB13: =+AR13+AV13+AZ13 -> 106891.83 | BC13: =AM13+BA13 -> 210362.88 | BD13: =AN13+BB13 -> 214613.16 | BE13: =AW13+AY13 -> 419726.44 | BF13: =AX13+AZ13 -> 428443.56 | BG13: 423729.74 | BH13: 431508.84 | BI13: 433141.24 | BJ13: 432382.85 | BK13: 430769.03 | BL13: 438172.79 | BM13: 428806 | BN13: 425506 | BO13: 430922.2 | BP13: 406071.88 | BQ13: 412610.14
B14: COB#11 | C14: Mt | D14: =+D10*0.7*31.55 -> 786998.97 | E14: =+E10*31.55*0.7 -> 64929.9 | F14: ='COKE OVENS'!F22 -> 64333.605 | G14: =+G10*31.55*0.7 -> 67094.23 | H14: ='COKE OVENS'!H22 -> 66740.87 | I14: =+E14+G14 -> 132024.13 | J14: =+F14+H14 -> 131074.48 | K14: =+K10*31.55*0.7 -> 64929.9 | L14: ='COKE OVENS'!L22 -> 65239.09 | M14: =+E14+G14+K14 -> 196954.03 | N14: =+F14+H14+L14 -> 196313.57 | O14: =+O10*31.55*0.7 -> 67094.23 | P14: ='COKE OVENS'!P22 -> 67778.865 | Q14: =+M14+O14 -> 264048.26 | R14: =+N14+P14 -> 264092.43 | S14: =+S10*31.55*0.7 -> 67094.23 | T14: ='COKE OVENS'!T22 -> 67447.59 | U14: =+Q14+S14 -> 331142.49 | V14: =+R14+T14 -> 331540.02 | W14: =+W10*31.55*0.7 -> 61948.425 | X14: ='COKE OVENS'!X22 -> 64963.855 | Y14: =+O14+S14+W14 -> 196136.88 | Z14: =+P14+T14+X14 -> 200190.31 | AA14: =+M14+Y14 -> 393090.91 | AB14: =+N14+Z14 -> 396503.88 | AC14: =+AC10*31.55*0.7 -> 67778.865 | AD14: ='COKE OVENS'!AD22 -> 67418 | AE14: =+AA14+AC14 -> 460869.78 | AF14: =+AB14+AD14 -> 463921.88 | AG14: =+AG10*31.55*0.7 -> 65592.45 | AH14: ='COKE OVENS'!AH22 -> 62715.658 | AI14: =+AE14+AG14 -> 526462.23 | AJ14: =+AF14+AH14 -> 526637.53 | AK14: =+AK10*31.55*0.7 -> 67778.865 | AL14: ='COKE OVENS'!AL22 -> 67435.137 | AM14: =+AC14+AG14+AK14 -> 201150.18 | AN14: =+AD14+AH14+AL14 -> 197568.8 | AO14: =AI14+AK14 -> 594241.09 | AP14: =AJ14+AL14 -> 594072.67 | AQ14: =+AQ10*31.55*0.7 -> 67778.865 | AR14: ='COKE OVENS'!AR22 -> 67998.622 | AS14: =+AO14+AQ14 -> 662019.96 | AT14: =+AP14+AR14 -> 662071.29 | AU14: =+AU10*31.55*0.7 -> 61219.62 | AV14: ='COKE OVENS'!AV22 -> 61278.776 | AW14: =+AS14+AU14 -> 723239.58 | AX14: =+AT14+AV14 -> 723350.07 | AY14: =+AY10*31.55*0.7 -> 67778.865 | AZ14: ='COKE OVENS'!AZ22 -> 68018.33 | BA14: =+AQ14+AU14+AY14 -> 196777.35 | BB14: =+AR14+AV14+AZ14 -> 197295.73 | BC14: =AM14+BA14 -> 397927.53 | BD14: =AN14+BB14 -> 394864.52 | BE14: =AW14+AY14 -> 791018.44 | BF14: =AX14+AZ14 -> 791368.4 | BG14: 791332.05 | BH14: 793765.31 | BI14: 786486.6 | BJ14: 774691.65 | BK14: 737579.38 | BL14: 803741.8 | BM14: 778192 | BN14: 770203 | BO14: 752591.4 | BP14: 744858.59 | BQ14: 745859.84
B15: Total BF COKE | C15: Mt | D15: =SUM(D13:D14) -> 1202342.9 | E15: =SUM(E13:E14) -> 100327.5 | F15: =SUM(F13:F14) -> 99442.245 | G15: =SUM(G13:G14) -> 103671.75 | H15: =SUM(H13:H14) -> 103173.91 | I15: =SUM(I13:I14) -> 203999.25 | J15: =SUM(J13:J14) -> 202616.15 | K15: =SUM(K13:K14) -> 98882.7 | ... BF15: =SUM(BF13:BF14) -> 1219812 | BG15: 1215061.8 | BH15: 1225274.2 | BI15: 1219627.8 | BJ15: 1207074.5 | BK15: 1168348.4 | BL15: 1241914.6 | BM15: 1206998 | BN15: 1195709 | BO15: 1183513.6 | BP15: 1150930.5 | BQ15: 1158470
B16: SINTER | C16: Mt | D16: =4362.87596292192*1000+124 -> 4363000 | E16: =372.191438188584*1000 -> 372191.44 | F16: 321830 | G16: =383.372118766*1000 -> 383372.12 | H16: 355306 | I16: =+E16+G16 -> 755563.56 | J16: =+F16+H16 -> 677136 | K16: =372.191438188584*1000 -> 372191.44 | L16: 376274 | M16: =+E16+G16+K16 -> 1127755 | N16: =+F16+H16+L16 -> 1053410 | O16: =376.384193405115*1000 -> 376384.19 | P16: 397960 | Q16: =+M16+O16 -> 1504139.2 | R16: =+N16+P16 -> 1451370 | S16: =376.384193405115*1000 -> 376384.19 | T16: 383179 | U16: =+Q16+S16 -> 1880523.4 | V16: =+R16+T16 -> 1834549 | W16: =207.661910104769*1000 -> 207661.91 | X16: 374784 | Y16: =+O16+S16+W16 -> 960430.3 | Z16: =+P16+T16+X16 -> 1155923 | AA16: =+M16+Y16 -> 2088185.3 | AB16: =+N16+Z16 -> 2209333 | AC16: 403051.36 | AD16: 372857 | AE16: =+AA16+AC16 -> 2491236.7 | AF16: =+AB16+AD16 -> 2582190 | AG16: =392.409719810871*1000 -> 392409.72 | AH16: 24407 | AI16: =+AE16+AG16 -> 2883646.4 | AJ16: =+AF16+AH16 -> 2606597 | AK16: =403.051363440982*1000 -> 403051.36 | AL16: 361604 | AM16: =+AC16+AG16+AK16 -> 1198512.4 | AN16: =+AD16+AH16+AL16 -> 758868 | AO16: =AI16+AK16 -> 3286697.7 | AP16: =AJ16+AL16 -> 2968201 | AQ16: =403.051363440982*1000 -> 403051.36 | AR16: 369250 | AS16: =+AO16+AQ16 -> 3689749.1 | AT16: =+AP16+AR16 -> 3337451 | AU16: =365.546227096884*1000 -> 365546.23 | AV16: 342499 | AW16: =+AS16+AU16 -> 4055295.3 | AX16: =+AT16+AV16 -> 3679950 | AY16: =403.051363440982*1000 -> 403051.36 | AZ16: 410020 | BA16: =+AQ16+AU16+AY16 -> 1171649 | BB16: =+AR16+AV16+AZ16 -> 1121769 | BC16: =AM16+BA16 -> 2370161.4 | BD16: =AN16+BB16 -> 1880637 | BE16: =AW16+AY16 -> 4458346.7 | BF16: =AX16+AZ16 -> 4089970 | BG16: 4387544.5 | BH16: 3980714 | BI16: 4499999.9 | BJ16: 4398445 | BK16: 4395665 | BL16: 4183927.8 | BM16: 4277831 | BN16: 3665891.3 | BO16: 3629577 | BP16: 3903932.5 | BQ16: 3709525
B17: HOT METAL | C17: Mt | D17: 2950000 | E17: 252000 | F17: 226125.6 | G17: 260000 | H17: 255730.9 | I17: =+E17+G17 -> 512000 | J17: =+F17+H17 -> 481856.5 | K17: =252*1000 -> 252000 | L17: 261489.9 | M17: =+E17+G17+K17 -> 764000 | N17: =+F17+H17+L17 -> 743346.4 | O17: 255000 | P17: 268142.3 | Q17: =+M17+O17 -> 1019000 | R17: =+N17+P17 -> 1011488.7 | S17: 255000 | T17: 253263.6 | U17: =+Q17+S17 -> 1274000 | V17: =+R17+T17 -> 1264752.3 | W17: 140000 | X17: 243297.4 | Y17: =+O17+S17+W17 -> 650000 | Z17: =+P17+T17+X17 -> 764703.3 | AA17: =+M17+Y17 -> 1414000 | AB17: =+N17+Z17 -> 1508049.7 | AC17: 250000 | AD17: 237886.3 | AE17: =+AA17+AC17 -> 1664000 | AF17: =+AB17+AD17 -> 1745936 | AG17: 242000 | AH17: 8246.5 | AI17: =+AE17+AG17 -> 1906000 | AJ17: =+AF17+AH17 -> 1754182.5 | AK17: 250000 | AL17: 257290.9 | AM17: =+AC17+AG17+AK17 -> 742000 | AN17: =+AD17+AH17+AL17 -> 503423.7 | AO17: =AI17+AK17 -> 2156000 | AP17: =AJ17+AL17 -> 2011473.4 | AQ17: =250*1000 -> 250000 | AR17: 261845.4 | AS17: =+AO17+AQ17 -> 2406000 | AT17: =+AP17+AR17 -> 2273318.8 | AU17: =225*1000 -> 225000 | AV17: 239624 | AW17: =+AS17+AU17 -> 2631000 | AX17: =+AT17+AV17 -> 2512942.8 | AY17: 250000 | AZ17: 263830 | BA17: =+AQ17+AU17+AY17 -> 725000 | BB17: =+AR17+AV17+AZ17 -> 765299.4 | BC17: =AM17+BA17 -> 1467000 | BD17: =AN17+BB17 -> 1268723.1 | BE17: =AW17+AY17 -> 2881000 | BF17: =AX17+AZ17 -> 2776772.8 | BG17: 2650000 | BH17: 2622585.7 | BI17: 2800000 | BJ17: 2721268.1 | BK17: 2592119.6 | BL17: 2650001 | BM17: 2406785.7 | BN17: 2496672.2 | BO17: 2092798 | BP17: 2700000 | BQ17: 2505193
B18: CRUDE STEEL | C18: Mt | D18: =2770.01888574126*1000-19 -> 2769999.9 | E18: =237.110481586402*1000 -> 237110.48 | F18: 207020 | G18: =244.66477809254*1000 -> 244664.78 | H18: 236638 | I18: =+E18+G18 -> 481775.26 | J18: =+F18+H18 -> 443658 | K18: =237.110481586402*1000 -> 237110.48 | L18: 243453 | M18: =+E18+G18+K18 -> 718885.74 | N18: =+F18+H18+L18 -> 687111 | O18: =239.943342776204*1000 -> 239943.34 | P18: 253662 | Q18: =+M18+O18 -> 958829.08 | R18: =+N18+P18 -> 940773 | S18: =239.943342776204*1000 -> 239943.34 | T18: 237622 | U18: =+Q18+S18 -> 1198772.4 | V18: =+R18+T18 -> 1178395 | W18: =125.920679886686*1000 -> 125920.68 | X18: 226847 | Y18: =+O18+S18+W18 -> 605807.37 | Z18: =+P18+T18+X18 -> 718131 | AA18: =+M18+Y18 -> 1324693.1 | AB18: =+N18+Z18 -> 1405242 | AC18: 235490.57 | AD18: 222138 | AE18: =+AA18+AC18 -> 1560183.7 | AF18: =+AB18+AD18 -> 1627380 | AG18: =227.943396226415*1000 -> 227943.4 | AH18: 7935 | AI18: =+AE18+AG18 -> 1788127.1 | AJ18: =+AF18+AH18 -> 1635315 | AK18: =235.490566037736*1000 -> 235490.57 | AL18: 234930 | AM18: =+AC18+AG18+AK18 -> 698924.53 | AN18: =+AD18+AH18+AL18 -> 465003 | AO18: =AI18+AK18 -> 2023617.6 | AP18: =AJ18+AL18 -> 1870245 | AQ18: =235.490566037736*1000 -> 235490.57 | AR18: 246040 | AS18: =+AO18+AQ18 -> 2259108.2 | AT18: =+AP18+AR18 -> 2116285 | AU18: =211.905660377358*1000 -> 211905.66 | AV18: 222895 | AW18: =+AS18+AU18 -> 2471013.9 | AX18: =+AT18+AV18 -> 2339180 | AY18: =235.490566037736*1000 -> 235490.57 | AZ18: 243552 | BA18: =+AQ18+AU18+AY18 -> 682886.79 | BB18: =+AR18+AV18+AZ18 -> 712487 | BC18: =AM18+BA18 -> 1381811.3 | BD18: =AN18+BB18 -> 1177490 | BE18: =AW18+AY18 -> 2706504.4 | BF18: =AX18+AZ18 -> 2582732 | BG18: 2489528.3 | BH18: 2436959 | BI18: 2620075.5 | BJ18: 2528925 | BK18: 2422324.3 | BL18: 2451737.7 | BM18: 2227867 | BN18: 2297163.5 | BO18: 1847433 | BP18: 2500000 | BQ18: 2083412
B19: Caster #(1+2 ) | C19: Mt | D19: =1978.46215750908*1000-2 -> 1978460.2 | E19: =SMS!E29 -> 171675.13 | F19: =SMS!F37 -> 149261 | G19: =SMS!G29 -> 176063.19 | H19: =SMS!H37 -> 175199.54 | I19: =+E19+G19 -> 347738.32 | J19: =SMS!J37 -> 324460.54 | K19: =SMS!K29 -> 171147.42 | L19: =SMS!L37 -> 182735 | M19: =+E19+G19+K19 -> 518885.74 | N19: =+F19+H19+L19 -> 507195.54 | O19: =SMS!O29 -> 171341.76 | P19: =SMS!P37 -> 189077 | Q19: =+M19+O19 -> 690227.5 | R19: =+N19+P19 -> 696272.54 | S19: =SMS!S29 -> 171341.76 | T19: =SMS!T37 -> 179543 | U19: =+Q19+S19 -> 861569.26 | V19: =+R19+T19 -> 875815.54 | W19: =SMS!W29 -> 90564.479 | X19: =SMS!X37 -> 172339.6 | Y19: =+O19+S19+W19 -> 433248 | Z19: =+P19+T19+X19 -> 540959.6 | AA19: =+M19+Y19 -> 952133.74 | AB19: =+N19+Z19 -> 1048155.1 | AC19: =SMS!AC29 -> 177750 | AD19: =SMS!AD37 -> 168140 | AE19: =+AA19+AC19 -> 1129883.7 | AF19: =+AB19+AD19 -> 1216295.1 | AG19: =SMS!AG29 -> 171825 | AH19: =SMS!AH37 -> 7935 | AI19: =SMS!AI29 -> 1301708.7 | AJ19: =SMS!AJ37 -> 1224230.1 | AK19: =SMS!AK29 -> 177840.45 | AL19: =SMS!AL37 -> 176215.37 | AM19: =SMS!AM29 -> 527415.45 | AN19: =SMS!AN37 -> 352290.37 | AO19: =SMS!AO29 -> 1479549.2 | AP19: =SMS!AP37 -> 1400445.5 | AQ19: =SMS!AQ29 -> 177750 | AR19: =SMS!AR37 -> 183526 | AS19: =+AO19+AQ19 -> 1657299.2 | AT19: =+AP19+AR19 -> 1583971.5 | AU19: =SMS!AU29 -> 159975 | AV19: =SMS!AV37 -> 163924 | AW19: =+AS19+AU19 -> 1817274.2 | AX19: =+AT19+AV19 -> 1747895.5 | AY19: =SMS!AY29 -> 177750 | AZ19: =SMS!AZ37 -> 171866 | BA19: =+AQ19+AU19+AY19 -> 515475 | BB19: =+AR19+AV19+AZ19 -> 519316 | BC19: =AM19+BA19 -> 1042890.4 | BD19: =AN19+BB19 -> 871606.37 | BE19: =AW19+AY19 -> 1995024.2 | BF19: =AX19+AZ19 -> 1919761.5 | BG19: 1880445.4 | BH19: 1818588.7 | BJ19: 1922629.6 | BK19: 1903696 | BM19: 1777963.7
B20: Caster #3 | C20: Mt | D20: =791.55672823219*1000-17 -> 791539.73 | E20: =SMS!E38 -> 65435.356 | F20: =SMS!F46 -> 57758.57 | G20: =SMS!G38 -> 68601.583 | H20: =SMS!H46 -> 61438.56 | I20: =+E20+G20 -> 134036.94 | J20: =SMS!J46 -> 119197.13 | K20: =SMS!K38 -> 65963.061 | L20: =SMS!L46 -> 60718.3 | M20: =+E20+G20+K20 -> 200000 | N20: =+F20+H20+L20 -> 179915.43 | O20: =SMS!O38 -> 68601.583 | P20: =SMS!P46 -> 64584.79 | Q20: =+M20+O20 -> 268601.58 | R20: =+N20+P20 -> 244500.22 | S20: =SMS!S38 -> 68601.583 | T20: =SMS!T46 -> 58078.79 | U20: =+Q20+S20 -> 337203.17 | V20: =+R20+T20 -> 302579.01 | W20: =SMS!W38 -> 35356.201 | X20: =SMS!X46 -> 54507 | Y20: =+O20+S20+W20 -> 172559.37 | Z20: =+P20+T20+X20 -> 177170.58 | AA20: =+M20+Y20 -> 372559.37 | AB20: =+N20+Z20 -> 357086.01 | AC20: =SMS!AC38 -> 57740.566 | AD20: =SMS!AD46 -> 53997.96 | AE20: =+AA20+AC20 -> 430299.93 | AF20: =+AB20+AD20 -> 411083.97 | AG20: =SMS!AG38 -> 56118.396 | AH20: =SMS!AH46 -> 0 | AI20: =SMS!AI38 -> 486418.33 | AJ20: =SMS!AJ46 -> 411083.97 | AK20: =SMS!AK38 -> 57650.116 | AL20: =SMS!AL46 -> 58714.36 | AM20: =SMS!AM38 -> 171509.08 | AN20: =SMS!AN46 -> 112712.32 | AO20: =SMS!AO38 -> 544068.45 | AP20: =SMS!AP46 -> 469798.33 | AQ20: =SMS!AQ38 -> 57740.566 | AR20: =SMS!AR46 -> 62514.11 | AS20: =+AO20+AQ20 -> 601809.01 | AT20: =+AP20+AR20 -> 532312.44 | AU20: =SMS!AU38 -> 51930.66 | AV20: =SMS!AV46 -> 58971.81 | AW20: =+AS20+AU20 -> 653739.67 | AX20: =+AT20+AV20 -> 591284.25 | AY20: =SMS!AY38 -> 57740.566 | AZ20: =SMS!AZ46 -> 71685.7 | BA20: =+AQ20+AU20+AY20 -> 167411.79 | BB20: =+AR20+AV20+AZ20 -> 193171.62 | BC20: =AM20+BA20 -> 338920.87 | BD20: =AN20+BB20 -> 305883.94 | BE20: =AW20+AY20 -> 711480.24 | BF20: =AX20+AZ20 -> 662969.95 | BG20: 609083.07 | BH20: 618370.32 | BJ20: 606294.79 | BK20: 518629.33 | BM20: 449903.88
B21: Avg Heats Cast per Day | C21: Nos. / day | D21: =D53/D1 -> 54.152138 | E21: =+E53/E1 -> 54.508157 | F21: =+F53/F1 -> 49.6125 | G21: =+G53/G1 -> 54.369951 | H21: =+H53/H1 -> 50.886713 | I21: =+I53/I1 -> 54.437882 | J21: =+J53/J1 -> 50.284871 | K21: =+K53/K1 -> 54.508157 | L21: =+L53/L1 -> 52.547596 | ... BF21: =+BF53/BF1 -> 51.004571 | BG21: 51.463117 | BH21: 49.270546 | BI21: 50.337665 | BJ21: 48.130368 | BK21: 45.269663 | BL21: 44.780041 | BM21: 40.065753 | BN21: 41.920046 | BO21: 33.309589 | BP21: 47.014645 | BQ21: 38.663934
B22: Cold Pig & Pig Equivalent
B23: MOG | C23: Mt | D23: 12645 | E23: =0.81*1000 -> 810 | F23: 3914.4926 | G23: 810 | H23: 2383.6528 | I23: =+E23+G23 -> 1620 | J23: =+F23+H23 -> 6298.1454 | K23: =0.81*1000 -> 810 | L23: 902.97846 | M23: =+E23+G23+K23 -> 2430 | N23: =+F23+H23+L23 -> 7201.1238 | O23: 810 | P23: 0 | Q23: =+M23+O23 -> 3240 | R23: =+N23+P23 -> 7201.1238 | S23: =0.81*1000 -> 810 | T23: 144.06922 | U23: =+Q23+S23 -> 4050 | V23: =+R23+T23 -> 7345.1931 | W23: =5360-1625 -> 3735 | X23: 256.58678 | Y23: =+O23+S23+W23 -> 5355 | Z23: =+P23+T23+X23 -> 400.656 | AA23: =+M23+Y23 -> 7785 | AB23: =+N23+Z23 -> 7601.7798 | AC23: 342 | AD23: 264.68337 | AE23: =+AA23+AC23 -> 8127 | AF23: =+AB23+AD23 -> 7866.4632 | AG23: 342 | AH23: 25.041 | AI23: =+AE23+AG23 -> 8469 | AJ23: =+AF23+AH23 -> 7891.5042 | AK23: 342 | AL23: 2134.9957 | AM23: =+AC23+AG23+AK23 -> 1026 | AN23: =+AD23+AH23+AL23 -> 2424.72 | AO23: =AI23+AK23 -> 8811 | AP23: =AJ23+AL23 -> 10026.5 | AQ23: 342 | AR23: 495.31098 | AS23: =+AO23+AQ23 -> 9153 | AT23: =+AP23+AR23 -> 10521.811 | AU23: =0.342*1000 -> 342 | AV23: 324.53136 | AW23: =+AS23+AU23 -> 9495 | AX23: =+AT23+AV23 -> 10846.342 | AY23: =0.342*1000 -> 342 | AZ23: 4393.36 | BA23: =+AQ23+AU23+AY23 -> 1026 | BB23: =+AR23+AV23+AZ23 -> 5213.2023 | BC23: =AM23+BA23 -> 2052 | BD23: =AN23+BB23 -> 7637.9223 | BE23: =AW23+AY23 -> 9837 | BF23: =AX23+AZ23 -> 15239.702 | BG23: 7740 | BH23: 12917.886 | BI23: 19561.1 | BJ23: 7548.2756 | BK23: 9129.3344 | BL23: 19735.515 | BM23: 22361.072 | BN23: 20755.018 | BO23: 58220.7 | BP23: 29957.856 | BQ23: 134629.18
B24: UPIS | C24: Mt | D24: 0 | E24: 0 | F24: 194.6 | G24: 0 | H24: 230 | I24: =+E24+G24 -> 0 | J24: =+F24+H24 -> 424.6 | K24: 0 | L24: 127.47931 | M24: =+E24+G24+K24 -> 0 | N24: =+F24+H24+L24 -> 552.07931 | O24: 0 | P24: 0 | Q24: =+M24+O24 -> 0 | R24: =+N24+P24 -> 552.07931 | S24: 0 | T24: 20.339184 | U24: =+Q24+S24 -> 0 | V24: =+R24+T24 -> 572.4185 | W24: 0 | X24: 36.224016 | Y24: =+O24+S24+W24 -> 0 | Z24: =+P24+T24+X24 -> 56.5632 | AA24: =+M24+Y24 -> 0 | AB24: =+N24+Z24 -> 608.64251 | AC24: 0 | AD24: 37.367064 | AE24: =+AA24+AC24 -> 0 | AF24: =+AB24+AD24 -> 646.00958 | AG24: 0 | AH24: 3.5352 | AI24: =+AE24+AG24 -> 0 | AJ24: =+AF24+AH24 -> 649.54478 | AK24: 0 | AL24: 301.41115 | AM24: =+AC24+AG24+AK24 -> 0 | AN24: =+AD24+AH24+AL24 -> 342.31342 | AO24: =AI24+AK24 -> 0 | AP24: =AJ24+AL24 -> 950.95593 | AQ24: 0 | AR24: 70 | AS24: =+AO24+AQ24 -> 0 | AT24: =+AP24+AR24 -> 1020.9559 | AU24: 0 | AV24: 45.816192 | AW24: =+AS24+AU24 -> 0 | AX24: =+AT24+AV24 -> 1066.7721 | AY24: 0 | AZ24: 620.23906 | BA24: =+AQ24+AU24+AY24 -> 0 | BB24: =+AR24+AV24+AZ24 -> 736.05525 | BC24: =AM24+BA24 -> 0 | BD24: =AN24+BB24 -> 1078.3687 | BE24: =AW24+AY24 -> 0 | BF24: =AX24+AZ24 -> 1687.0112 | BG24: 0 | BH24: 1823.7656 | BI24: 0 | BJ24: 1026.6221 | BK24: 2541.6495 | BL24: 0 | BM24: 2774.7649 | BN24: 392 | BO24: 3852.3 | BP24: 1419.0563 | BQ24: 8272.9783
B25: Equiv. Pig Iron @ 65% of HM sent to Sand Pit | C25: Mt | D25: =2500*0.65 -> 1625 | E25: 0 | F25: 552.63425 | G25: 0 | H25: 336.51569 | I25: =+E25+G25 -> 0 | J25: =+F25+H25 -> 889.14994 | K25: 0 | L25: 0 | M25: =+E25+G25+K25 -> 0 | N25: =+F25+H25+L25 -> 889.14994 | O25: 0 | P25: 0 | Q25: =+M25+O25 -> 0 | R25: =+N25+P25 -> 889.14994 | S25: 0 | T25: 0 | U25: =+Q25+S25 -> 0 | V25: =+R25+T25 -> 889.14994 | W25: =2500*0.65 -> 1625 | X25: 0 | Y25: =+O25+S25+W25 -> 1625 | Z25: =+P25+T25+X25 -> 0 | AA25: =+M25+Y25 -> 1625 | AB25: =+N25+Z25 -> 889.14994 | AC25: 0 | AD25: 0 | AE25: =+AA25+AC25 -> 1625 | AF25: =+AB25+AD25 -> 889.14994 | AG25: 0 | AH25: 1512.9 | AI25: =+AE25+AG25 -> 1625 | AJ25: =+AF25+AH25 -> 2402.0499 | AK25: 0 | AL25: 2513.5 | AM25: =+AC25+AG25+AK25 -> 0 | AN25: =+AD25+AH25+AL25 -> 4026.4 | AO25: =AI25+AK25 -> 1625 | AP25: =AJ25+AL25 -> 4915.5499 | AQ25: 0 | AR25: 0 | AS25: =+AO25+AQ25 -> 1625 | AT25: =+AP25+AR25 -> 4915.5499 | AU25: 0 | AV25: 630 | AW25: =+AS25+AU25 -> 1625 | AX25: =+AT25+AV25 -> 5545.5499 | AY25: 0 | AZ25: 480 | BA25: =+AQ25+AU25+AY25 -> 0 | BB25: =+AR25+AV25+AZ25 -> 1110 | BC25: =AM25+BA25 -> 0 | BD25: =AN25+BB25 -> 5136.4 | BE25: =AW25+AY25 -> 1625 | BF25: =AX25+AZ25 -> 6025.5499 | BG25: 1625 | BH25: 11114.8 | BI25: 2000 | BJ25: 5022 | BK25: 4664.8 | BL25: 14800 | BM25: 9214.4 | BN25: 0 | BO25: 0 | BP25: 0 | BQ25: 26220.8
B26: TOTAL EQUIVALENT PIG IRON | C26: Mt | D26: =SUM(D23:D25) -> 14270 | E26: =SUM(E23:E25) -> 810 | F26: =SUM(F23:F25) -> 4661.7268 | G26: =SUM(G23:G25) -> 810 | H26: =SUM(H23:H25) -> 2950.1685 | I26: =SUM(I23:I25) -> 1620 | J26: =SUM(J23:J25) -> 7611.8953 | K26: =SUM(K23:K25) -> 810 | ... BF26: =SUM(BF23:BF25) -> 22952.263 | BG26: 9365 | BH26: 25856.451 | BI26: 21561.1 | BJ26: 13596.898 | BK26: 16335.784 | BL26: 34535.515 | BM26: 34350.237 | BN26: 21147.018 | BO26: 62073 | BP26: 31376.912 | BQ26: 169122.96
B27: Net PCI Production | C27: Mt | D27: 3541.35 | E27: 273.996 | F27: 374.5 | G27: 279.98 | H27: 603.862 | I27: =+E27+G27 -> 553.976 | J27: =+F27+H27 -> 978.362 | K27: 273.996 | L27: 0 | M27: =+E27+G27+K27 -> 827.972 | N27: =+F27+H27+L27 -> 978.362 | O27: 276.24 | P27: 0 | Q27: =+M27+O27 -> 1104.212 | R27: =+N27+P27 -> 978.362 | S27: 276.24 | T27: 0 | U27: =+Q27+S27 -> 1380.452 | V27: =+R27+T27 -> 978.362 | W27: 498.97 | X27: 0 | Y27: =+O27+S27+W27 -> 1051.45 | Z27: =+P27+T27+X27 -> 0 | AA27: =+M27+Y27 -> 1879.422 | AB27: =+N27+Z27 -> 978.362 | AC27: 226.1 | AD27: 0 | AE27: =+AA27+AC27 -> 2105.522 | AF27: =+AB27+AD27 -> 978.362 | AG27: 220.02 | AH27: 1174.369 | AI27: =+AE27+AG27 -> 2325.542 | AJ27: =+AF27+AH27 -> 2152.731 | AK27: 226.1 | AL27: 1177.785 | AM27: =+AC27+AG27+AK27 -> 672.22 | AN27: =+AD27+AH27+AL27 -> 2352.154 | AO27: =AI27+AK27 -> 2551.642 | AP27: =AJ27+AL27 -> 3330.516 | AQ27: 226.1 | AR27: 766.241 | AS27: =+AO27+AQ27 -> 2777.742 | AT27: =+AP27+AR27 -> 4096.757 | AU27: 207.1 | AV27: 658.147 | AW27: =+AS27+AU27 -> 2984.842 | AX27: =+AT27+AV27 -> 4754.904 | AY27: 226.1 | AZ27: 554.33 | BA27: =+AQ27+AU27+AY27 -> 659.3 | BB27: =+AR27+AV27+AZ27 -> 1978.718 | BC27: =AM27+BA27 -> 1331.52 | BD27: =AN27+BB27 -> 4330.872 | BE27: =AW27+AY27 -> 3210.942 | BF27: =AX27+AZ27 -> 5309.234 | BG27: 2831.5 | BH27: 7991.486 | BI27: 2377.872 | BJ27: 6141.395 | BK27: 5885.734 | BL27: 2398.56 | BM27: 13377.679 | BN27: 11568.99 | BO27: 41093.9 | BP27: 0 | BQ27: 44255.19
B28: Net Granulated Slag Production | C28: Mt | D28: 1081234 | E28: 92363.04 | F28: 70955.831 | G28: 95295.2 | H28: 75418.546 | I28: =+E28+G28 -> 187658.24 | J28: =+F28+H28 -> 146374.38 | K28: 92363.04 | L28: 72846.055 | M28: =+E28+G28+K28 -> 280021.28 | N28: =+F28+H28+L28 -> 219220.43 | O28: 93462.6 | P28: 75682.97 | Q28: =+M28+O28 -> 373483.88 | R28: =+N28+P28 -> 294903.4 | S28: 93462.6 | T28: 80832.023 | U28: =+Q28+S28 -> 466946.48 | V28: =+R28+T28 -> 375735.43 | W28: 51312.8 | X28: 79584.049 | Y28: =+O28+S28+W28 -> 238238 | Z28: =+P28+T28+X28 -> 236099.04 | AA28: =+M28+Y28 -> 518259.28 | AB28: =+N28+Z28 -> 455319.47 | AC28: 93198.103 | AD28: 81673.877 | AE28: =+AA28+AC28 -> 611457.38 | AF28: =+AB28+AD28 -> 536993.35 | AG28: 90215.764 | AH28: 2328.2551 | AI28: =+AE28+AG28 -> 701673.15 | AJ28: =+AF28+AH28 -> 539321.61 | AK28: 93198.103 | AL28: 92452.296 | AM28: =+AC28+AG28+AK28 -> 276611.97 | AN28: =+AD28+AH28+AL28 -> 176454.43 | AO28: =AI28+AK28 -> 794871.25 | AP28: =AJ28+AL28 -> 631773.9 | AQ28: 93198.103 | AR28: 94062.296 | AS28: =+AO28+AQ28 -> 888069.35 | AT28: =+AP28+AR28 -> 725836.2 | AU28: 83878.293 | AV28: 80273.363 | AW28: =+AS28+AU28 -> 971947.65 | AX28: =+AT28+AV28 -> 806109.56 | AY28: 93198.103 | AZ28: 90266.534 | BA28: =+AQ28+AU28+AY28 -> 270274.5 | BB28: =+AR28+AV28+AZ28 -> 264602.19 | BC28: =AM28+BA28 -> 546886.47 | BD28: =AN28+BB28 -> 441056.62 | BE28: =AW28+AY28 -> 1065145.7 | BF28: =AX28+AZ28 -> 896376.09 | BG28: 987899.89 | BH28: 899258.76 | BI28: 1063047 | BJ28: 1075244.6 | BK28: 1065593 | BL28: 157305.12 | BM28: 920129.3 | BN28: 882599.97 | BO28: 776699 | BP28: 854658 | BQ28: 809638.21
B29: Saleable Steel Production (Mill Wise)
B30: WR Mill | C30: Mt | D30: 500000 | E30: 42500 | F30: =+WRM!F154 -> 36744.18 | G30: 44000 | H30: =+WRM!H154 -> 39374.35 | I30: =+E30+G30 -> 86500 | J30: =+F30+H30 -> 76118.53 | K30: 42500 | L30: =+WRM!L154 -> 38297.5 | M30: =+E30+G30+K30 -> 129000 | N30: =+F30+H30+L30 -> 114416.03 | O30: 44000 | P30: =+WRM!P154 -> 47070.05 | Q30: =+M30+O30 -> 173000 | R30: =+N30+P30 -> 161486.08 | S30: 44000 | T30: =+WRM!T154 -> 38734.75 | U30: =+Q30+S30 -> 217000 | V30: =+R30+T30 -> 200220.83 | W30: 25000 | X30: =+WRM!X154 -> 41006.15 | Y30: =+O30+S30+W30 -> 113000 | Z30: =+P30+T30+X30 -> 126810.95 | AA30: =+M30+Y30 -> 242000 | AB30: =+N30+Z30 -> 241226.98 | AC30: 45500 | AD30: =+WRM!AD154 -> 42384.76 | AE30: =+AA30+AC30 -> 287500 | AF30: =+AB30+AD30 -> 283611.74 | AG30: 44000 | AH30: =+WRM!AH154 -> 19981.35 | AI30: =+AE30+AG30 -> 331500 | AJ30: =+AF30+AH30 -> 303593.09 | AK30: 45500 | AL30: =+WRM!AL154 -> 39200.1 | AM30: =+AC30+AG30+AK30 -> 135000 | AN30: =+AD30+AH30+AL30 -> 101566.21 | AO30: =AI30+AK30 -> 377000 | AP30: =AJ30+AL30 -> 342793.19 | AQ30: =45.5*1000 -> 45500 | AR30: =+WRM!AR154 -> 40296.85 | AS30: =+AO30+AQ30 -> 422500 | AT30: =+AP30+AR30 -> 383090.04 | AU30: =40.5*1000 -> 40500 | AV30: =+WRM!AV154 -> 34335.35 | AW30: =+AS30+AU30 -> 463000 | AX30: =+AT30+AV30 -> 417425.39 | AY30: =45.5*1000 -> 45500 | AZ30: =+WRM!AZ154 -> 43072.55 | BA30: =+AQ30+AU30+AY30 -> 131500 | BB30: =+AR30+AV30+AZ30 -> 117704.75 | BC30: =AM30+BA30 -> 266500 | BD30: =AN30+BB30 -> 219270.96 | BE30: =AW30+AY30 -> 508500 | BF30: =AX30+AZ30 -> 460497.94 | BG30: 500000 | BH30: 459030.64 | BI30: 500000 | BJ30: 478528.39 | BK30: 466114.65 | BL30: 500000 | BM30: 465343.77 | BN30: 435965.96 | BO30: 356518.66 | BP30: 500000 | BQ30: 412025.22
B31: Bar Mill | C31: Mt | D31: 900000 | E31: 76000 | F31: =+BM!F56 -> 66895.455 | G31: 79000 | H31: =+BM!H56 -> 76175.635 | I31: =+E31+G31 -> 155000 | J31: =+F31+H31 -> 143071.09 | K31: 76000 | L31: =+BM!L56 -> 73644.015 | M31: =+E31+G31+K31 -> 231000 | N31: =+F31+H31+L31 -> 216715.11 | O31: 79000 | P31: =+BM!P56 -> 88056.49 | Q31: =+M31+O31 -> 310000 | R31: =+N31+P31 -> 304771.6 | S31: 79000 | T31: =+BM!T56 -> 75853.695 | U31: =+Q31+S31 -> 389000 | V31: =+R31+T31 -> 380625.29 | W31: =47.5*1000 -> 47500 | X31: =+BM!X56 -> 76319.035 | Y31: =+O31+S31+W31 -> 205500 | Z31: =+P31+T31+X31 -> 240229.22 | AA31: =+M31+Y31 -> 436500 | AB31: =+N31+Z31 -> 456944.33 | AC31: 80000 | AD31: =+BM!AD56 -> 66747.8 | AE31: =+AA31+AC31 -> 516500 | AF31: =+AB31+AD31 -> 523692.13 | AG31: 77500 | AH31: =+BM!AH56 -> 3169.72 | AI31: =+AE31+AG31 -> 594000 | AJ31: =+AF31+AH31 -> 526861.85 | AK31: 80000 | AL31: =+BM!AL56 -> 70630.63 | AM31: =+AC31+AG31+AK31 -> 237500 | AN31: =+AD31+AH31+AL31 -> 140548.15 | AO31: =AI31+AK31 -> 674000 | AP31: =AJ31+AL31 -> 597492.48 | AQ31: 80000 | AR31: =+BM!AR56 -> 70085.115 | AS31: =+AO31+AQ31 -> 754000 | AT31: =+AP31+AR31 -> 667577.59 | AU31: =72.5*1000 -> 72500 | AV31: =+BM!AV56 -> 65990 | AW31: =+AS31+AU31 -> 826500 | AX31: =+AT31+AV31 -> 733567.59 | AY31: 80000 | AZ31: =+BM!AZ56 -> 78010.61 | BA31: =+AQ31+AU31+AY31 -> 232500 | BB31: =+AR31+AV31+AZ31 -> 214085.73 | BC31: =AM31+BA31 -> 470000 | BD31: =AN31+BB31 -> 354633.88 | BE31: =AW31+AY31 -> 906500 | BF31: =AX31+AZ31 -> 811578.2 | BG31: 870000 | BH31: 750867.85 | BI31: 850000 | BJ31: 795322.27 | BK31: 775906.63 | BL31: 750000 | BM31: 649840.96 | BN31: 674875.14 | BO31: 440547.27 | BP31: 800000 | BQ31: 632220.18
B32: US Mill | C32: Mt | D32: 750000 | E32: 62000 | F32: =+USM!G108 -> 49543.777 | G32: 65000 | H32: =+USM!I108 -> 57219.144 | I32: =+E32+G32 -> 127000 | J32: =+F32+H32 -> 106762.92 | K32: 62500 | L32: =+USM!M108 -> 58674.633 | M32: =+E32+G32+K32 -> 189500 | N32: =+F32+H32+L32 -> 165437.55 | O32: 65000 | P32: =+USM!Q108 -> 57327.387 | Q32: =+M32+O32 -> 254500 | R32: =+N32+P32 -> 222764.94 | S32: 65000 | T32: =+USM!U108 -> 44406.293 | U32: =+Q32+S32 -> 319500 | V32: =+R32+T32 -> 267171.23 | W32: 33500 | X32: =+USM!Y108 -> 50010.386 | Y32: =+O32+S32+W32 -> 163500 | Z32: =+P32+T32+X32 -> 151744.07 | AA32: =+M32+Y32 -> 353000 | AB32: =+N32+Z32 -> 317181.62 | AC32: 54000 | AD32: =+USM!AE108 -> 44900.301 | AE32: =+AA32+AC32 -> 407000 | AF32: =+AB32+AD32 -> 362081.92 | AG32: 52000 | AH32: =+USM!AI108 -> 8584.984 | AI32: =+AE32+AG32 -> 459000 | AJ32: =+AF32+AH32 -> 370666.9 | AK32: 54000 | AL32: =+USM!AM108 -> 40066.768 | AM32: =+AC32+AG32+AK32 -> 160000 | AN32: =+AD32+AH32+AL32 -> 93552.053 | AO32: =AI32+AK32 -> 513000 | AP32: =AJ32+AL32 -> 410733.67 | AQ32: 54000 | AR32: =+USM!AS108 -> 51039.179 | AS32: =+AO32+AQ32 -> 567000 | AT32: =+AP32+AR32 -> 461772.85 | AU32: 48000 | AV32: =+USM!AW108 -> 51009.48 | AW32: =+AS32+AU32 -> 615000 | AX32: =+AT32+AV32 -> 512782.33 | AY32: 60000 | AZ32: =+USM!BA108 -> 62071.89 | BA32: =+AQ32+AU32+AY32 -> 162000 | BB32: =+AR32+AV32+AZ32 -> 164120.55 | BC32: =AM32+BA32 -> 322000 | BD32: =AN32+BB32 -> 257672.6 | BE32: =AW32+AY32 -> 675000 | BF32: =AX32+AZ32 -> 574854.22 | BG32: 560000 | BH32: 499887.23 | BI32: 525000 | BJ32: 459141.95 | BK32: 361987.56 | BL32: 450000 | BM32: 213226.16 | BN32: 220000 | BO32: 88943.894 | BP32: 535000 | BQ32: 171634.81
B33: Finished Steel | C33: Mt | D33: =SUM(D30:D32) -> 2150000 | E33: =SUM(E30:E32) -> 180500 | F33: =SUM(F30:F32) -> 153183.41 | G33: =SUM(G30:G32) -> 188000 | H33: =SUM(H30:H32) -> 172769.13 | I33: =SUM(I30:I32) -> 368500 | J33: =SUM(J30:J32) -> 325952.54 | K33: =SUM(K30:K32) -> 181000 | ... BF33: =SUM(BF30:BF32) -> 1846930.4 | BG33: 1930000 | BH33: 1709785.7 | BI33: 1875000 | BJ33: 1732992.6 | BK33: 1604008.8 | BL33: 1700000 | BM33: 1328410.9 | BN33: 1330841.1 | BO33: 886009.82 | BP33: =SUM(BP30:BP32) -> 1835000 | BQ33: =SUM(BQ30:BQ32) -> 1215880.2
B34: 150x150 mm | C34: Mt | D34: =524.79833712911*1000+202 -> 525000.34 | E34: =48.4998153686034*1000 -> 48499.815 | F34: 45616.588 | G34: 48499.577 | H34: 52556 | I34: =+E34+G34 -> 96999.392 | J34: =+F34+H34 -> 98172.588 | K34: =48.0001108831152*1000 -> 48000.111 | L34: 56218 | M34: =+E34+G34+K34 -> 144999.5 | N34: =+F34+H34+L34 -> 154390.59 | O34: =43.5001413553209*1000 -> 43500.141 | P34: 50303 | Q34: =+M34+O34 -> 188499.64 | R34: =+N34+P34 -> 204693.59 | S34: =43.5001413553209*1000 -> 43500.141 | T34: 51235.42 | U34: =+Q34+S34 -> 231999.79 | V34: =+R34+T34 -> 255929.01 | W34: =15.3000147648532*1000 -> 15300.015 | X34: 54076 | Y34: =+O34+S34+W34 -> 102300.3 | Z34: =+P34+T34+X34 -> 155614.42 | AA34: =+M34+Y34 -> 247299.8 | AB34: =+N34+Z34 -> 310005.01 | AC34: 47340.612 | AD34: 25418 | AE34: =+AA34+AC34 -> 294640.41 | AF34: =+AB34+AD34 -> 335423.01 | AG34: =45.6807858376511*1000 -> 45680.786 | AH34: 7935 | AI34: =+AE34+AG34 -> 340321.2 | AJ34: =+AF34+AH34 -> 343358.01 | AK34: =45.7100622625216*1000 -> 45710.062 | AL34: 64493 | AM34: =+AC34+AG34+AK34 -> 138731.46 | AN34: =+AD34+AH34+AL34 -> 97846 | AO34: =AI34+AK34 -> 386031.26 | AP34: =AJ34+AL34 -> 407851.01 | AQ34: =47.3396122625216*1000 -> 47339.612 | AR34: 63074.18 | AS34: =+AO34+AQ34 -> 433370.87 | AT34: =+AP34+AR34 -> 470925.19 | AU34: =42.6579663212435*1000 -> 42657.966 | AV34: 57481.27 | AW34: =+AS34+AU34 -> 476028.84 | AX34: =+AT34+AV34 -> 528406.46 | AY34: =45.4526122625216*1000 -> 45452.612 | AZ34: 57620 | BA34: =+AQ34+AU34+AY34 -> 135450.19 | BB34: =+AR34+AV34+AZ34 -> 178175.45 | BC34: =AM34+BA34 -> 274181.65 | BD34: =AN34+BB34 -> 276021.45 | BE34: =AW34+AY34 -> 521481.45 | BF34: =AX34+AZ34 -> 586026.46 | BG34: 461999.56 | BH34: 558374.45 | BI34: 592000 | BJ34: 574823.37 | BK34: 595119.91 | BL34: 516406.77 | BM34: 627684.57 | BN34: 533055.82 | BO34: 608495.73 | BP34: 304999.74 | BQ34: 629438.96
B35: 200x280 mm | C35: Mt | D35: 0 | E35: 0 | F35: 0 | G35: 0 | H35: 3000 | I35: =+E35+G35 -> 0 | J35: =+F35+H35 -> 3000 | K35: 0 | L35: 1066 | M35: =+E35+G35+K35 -> 0 | N35: =+F35+H35+L35 -> 4066 | O35: 0 | P35: 463 | Q35: =+M35+O35 -> 0 | R35: =+N35+P35 -> 4529 | S35: 0 | T35: 8811.77 | U35: =+Q35+S35 -> 0 | V35: =+R35+T35 -> 13340.77 | W35: 0 | X35: 1414 | Y35: =+O35+S35+W35 -> 0 | Z35: =+P35+T35+X35 -> 10688.77 | AA35: =+M35+Y35 -> 0 | AB35: =+N35+Z35 -> 14754.77 | AC35: 0.48160502 | AD35: 7379.5262 | AE35: =+AA35+AC35 -> 0.48160502 | AF35: =+AB35+AD35 -> 22134.296 | AG35: =4.00012973564992*1000 -> 4000.1297 | AH35: 637 | AI35: =+AE35+AG35 -> 4000.6113 | AJ35: =+AF35+AH35 -> 22771.296 | AK35: 0 | AL35: 12910 | AM35: =+AC35+AG35+AK35 -> 4000.6113 | AN35: =+AD35+AH35+AL35 -> 20926.526 | AO35: =AI35+AK35 -> 4000.6113 | AP35: =AJ35+AL35 -> 35681.296 | AQ35: 0 | AR35: 10907.843 | AS35: =+AO35+AQ35 -> 4000.6113 | AT35: =+AP35+AR35 -> 46589.139 | AU35: =4.00002977049834*1000 -> 4000.0298 | AV35: 0 | AW35: =+AS35+AU35 -> 8000.6411 | AX35: =+AT35+AV35 -> 46589.139 | AY35: 0 | AZ35: 0 | BA35: =+AQ35+AU35+AY35 -> 4000.0298 | BB35: =+AR35+AV35+AZ35 -> 10907.843 | BC35: =AM35+BA35 -> 8000.6411 | BD35: =AN35+BB35 -> 31834.369 | BE35: =AW35+AY35 -> 8000.6411 | BF35: =AX35+AZ35 -> 46589.139 | BG35: 17999.996 | BH35: 63663.849 | BI35: 57999.916 | BJ35: 101828.14 | BK35: 116079.05 | BL35: 153592.34 | BM35: 204330.35 | BN35: 371378.01 | BO35: 329378.8 | BP35: 267000 | BQ35: 248401
B36: Saleable Semis | C36: Mt | D36: =SUM(D34:D35) -> 525000.34 | E36: =SUM(E34:E35) -> 48499.815 | F36: =SUM(F34:F35) -> 45616.588 | G36: =SUM(G34:G35) -> 48499.577 | H36: =SUM(H34:H35) -> 55556 | I36: =SUM(I34:I35) -> 96999.392 | J36: =SUM(J34:J35) -> 101172.59 | K36: =SUM(K34:K35) -> 48000.111 | ... BF36: =SUM(BF34:BF35) -> 632615.6 | BG36: 479999.56 | BH36: 622038.3 | BI36: 649999.92 | BJ36: 676651.51 | BK36: 711198.96 | BL36: 669999.11 | BM36: 832014.92 | BN36: 904433.83 | BO36: 937874.53 | BP36: =SUM(BP34:BP35) -> 571999.74 | BQ36: =SUM(BQ34:BQ35) -> 877839.96
B37: TOTAL SALEABLE STEEL | C37: Mt | D37: =+D33+D36 -> 2675000.3 | E37: =+E33+E36 -> 228999.82 | F37: =+F33+F36 -> 198800 | G37: =+G33+G36 -> 236499.58 | H37: =+H33+H36 -> 228325.13 | I37: =+I33+I36 -> 465499.39 | J37: =+J33+J36 -> 427125.13 | K37: =+K33+K36 -> 229000.11 | ... BF37: =+BF33+BF36 -> 2479546 | BG37: 2409999.6 | BH37: 2331824 | BI37: 2524999.9 | BJ37: 2409644.1 | BK37: 2315207.8 | BL37: 2369999.1 | BM37: 2160425.8 | BN37: 2235274.9 | BO37: 1823884.4 | BP37: =+BP33+BP36 -> 2406999.7 | BQ37: =+BQ33+BQ36 -> 2093720.2
B38: SAL STEEL PRODN (CATEGORY WISE)
B39: Wire Rod Plain Coils | C39: Mt | D39: =+D30 -> 500000 | E39: =+E30 -> 42500 | F39: =+WRM!F200 -> 36744.18 | G39: =+G30 -> 44000 | H39: =+WRM!H200 -> 39374.35 | I39: =+E39+G39 -> 86500 | J39: =+F39+H39 -> 76118.53 | K39: =+K30 -> 42500 | L39: =+WRM!L200 -> 28933.7 | M39: =+E39+G39+K39 -> 129000 | N39: =+F39+H39+L39 -> 105052.23 | O39: =+O30 -> 44000 | P39: =+WRM!P200 -> 35819.65 | Q39: =+M39+O39 -> 173000 | R39: =+N39+P39 -> 140871.88 | S39: =+S30 -> 44000 | T39: =+WRM!T200 -> 38734.75 | U39: =+Q39+S39 -> 217000 | V39: =+R39+T39 -> 179606.63 | W39: =+W30 -> 25000 | X39: =+WRM!X200 -> 41006.15 | Y39: =+O39+S39+W39 -> 113000 | Z39: =+P39+T39+X39 -> 115560.55 | AA39: =+M39+Y39 -> 242000 | AB39: =+N39+Z39 -> 220612.78 | AC39: =+AC30 -> 45500 | AD39: =+WRM!AD200 -> 42384.76 | AE39: =+AA39+AC39 -> 287500 | AF39: =+AB39+AD39 -> 262997.54 | AG39: =+AG30 -> 44000 | AH39: =+WRM!AH200 -> 19981.35 | AI39: =+AE39+AG39 -> 331500 | AJ39: =+AF39+AH39 -> 282978.89 | AK39: =+AK30 -> 45500 | AL39: =+WRM!AL200 -> 39200.1 | AM39: =+AC39+AG39+AK39 -> 135000 | AN39: =+AD39+AH39+AL39 -> 101566.21 | AO39: =AI39+AK39 -> 377000 | AP39: =AJ39+AL39 -> 322178.99 | AQ39: =+AQ30 -> 45500 | AR39: =+WRM!AR200 -> 40296.85 | AS39: =+AO39+AQ39 -> 422500 | AT39: =+AP39+AR39 -> 362475.84 | AU39: =+AU30 -> 40500 | AV39: =+WRM!AV200 -> 34335.35 | AW39: =+AS39+AU39 -> 463000 | AX39: =+AT39+AV39 -> 396811.19 | AY39: =+AY30 -> 45500 | AZ39: =+WRM!AZ200 -> 43072.55 | BA39: =+AQ39+AU39+AY39 -> 131500 | BB39: =+AR39+AV39+AZ39 -> 117704.75 | BC39: =AM39+BA39 -> 266500 | BD39: =AN39+BB39 -> 219270.96 | BE39: =AW39+AY39 -> 508500 | BF39: =AX39+AZ39 -> 439883.74 | BG39: 500000 | BH39: 459030.64 | BI39: 500000 | BJ39: 471802.34 | BK39: 410762.6 | BL39: =+BL30 -> 500000 | BM39: 456374.84 | BN39: =+BN30 -> 435965.96 | BO39: 333534.61 | BP39: 500000 | BQ39: 270654.57
B40: TMT Coils | C40: Mt | F40: =+WRM!F201 -> 0 | H40: =+WRM!H201 -> 0 | J40: =+F40+H40 -> 0 | L40: =+WRM!L201 -> 9363.8 | N40: =+F40+H40+L40 -> 9363.8 | P40: =+WRM!P201 -> 11250.4 | R40: =+N40+P40 -> 20614.2 | T40: =+WRM!T201 -> 0 | V40: =+R40+T40 -> 20614.2 | X40: =+WRM!X201 -> 0 | Z40: =+P40+T40+X40 -> 11250.4 | AB40: =+N40+Z40 -> 20614.2 | AD40: =+WRM!AD201 -> 0 | AF40: =+AB40+AD40 -> 20614.2 | AH40: =+WRM!AH201 -> 0 | AJ40: =+AF40+AH40 -> 20614.2 | AL40: =+WRM!AL201 -> 0 | AN40: =+AD40+AH40+AL40 -> 0 | AP40: =AJ40+AL40 -> 20614.2 | AR40: =+WRM!AR201 -> 0 | AT40: =+AP40+AR40 -> 20614.2 | AV40: =+WRM!AV201 -> 0 | AX40: =+AT40+AV40 -> 20614.2 | AZ40: =+WRM!AZ201 -> 0 | BB40: =+AR40+AV40+AZ40 -> 0 | BD40: =AN40+BB40 -> 0 | BF40: =AX40+AZ40 -> 20614.2 | BH40: 0 | BJ40: 6726.05 | BK40: 55352.05 | BM40: 8968.93 | BO40: 22983.766 | BQ40: 141370.65
...

Sheet Maj Despatch Summ
B1: MAJOR DESPATCH SUMMARY 2025-26 (As per Finance CENVAT report)
E2: 30 | F2: 30 | G2: 31 | H2: 31 | I2: =+G2+E2 -> 61 | J2: =+H2+F2 -> 61 | K2: 30 | L2: 30 | M2: =+E2+G2+K2 -> 91 | N2: =+F2+H2+L2 -> 91 | O2: 31 | P2: 31 | Q2: =+M2+O2 -> 122 | R2: =+N2+P2 -> 122 | S2: 31 | T2: 31 | U2: =+Q2+S2 -> 153 | V2: =+R2+T2 -> 153 | W2: 30 | X2: 30 | Y2: =+O2+S2+W2 -> 92 | Z2: =+P2+T2+X2 -> 92 | AA2: =+M2+Y2 -> 183 | AB2: =+N2+Z2 -> 183 | AC2: 31 | AD2: 31 | AE2: =AA2+AC2 -> 214 | AF2: =AB2+AD2 -> 214 | AG2: 30 | AH2: 30 | AI2: =AE2+AG2 -> 244 | AJ2: =AF2+AH2 -> 244 | AK2: 31 | AL2: 31 | AM2: =+AC2+AG2+AK2 -> 92 | AN2: =+AD2+AH2+AL2 -> 92 | AO2: =AI2+AK2 -> 275 | AP2: =AJ2+AL2 -> 275 | AQ2: 31 | AR2: 31 | AS2: =AO2+AQ2 -> 306 | AT2: =AP2+AR2 -> 306 | AU2: 28 | AV2: 28 | AW2: =AS2+AU2 -> 334 | AX2: =AT2+AV2 -> 334 | AY2: 31 | AZ2: 31 | BA2: =+AQ2+AU2+AY2 -> 90 | BB2: =+AR2+AV2+AZ2 -> 90 | BC2: =AM2+BA2 -> 182 | BD2: =AN2+BB2 -> 182 | BE2: =AW2+AY2 -> 365 | BF2: =AX2+AZ2 -> 365 | BO2: 365 | BP2: 365 | BQ2: 366 | BR2: 366
B3: ITEM | C3: Unit | D3: 2025-26 ABP | E3: Apr'25 | G3: May'25 | I3: 2M | K3: Jun'25 | M3: QTR-1 | O3: Jul'25 | Q3: 4M | S3: Aug'25 | U3: 5M | W3: Sep'25 | Y3: QTR-2 | AA3: H1 | AC3: Oct'24 | AE3: 7M | AG3: Nov'24 | AI3: 8M | AK3: Dec'24 | AM3: QTR-3 | AO3: 9M | AQ3: Jan'25 | AS3: 10M | AU3: Feb'25 | AW3: 11M | AY3: Mar'25 | BA3: QTR-4 | BC3: H2 | BE3: 2024-25 | BG3: 2024-25 | BI3: 2023-24 | BK3: 2022-23 | BM3: 2021-22 | BO3: 2020-21 | BQ3: 2019-20
E4: ABP | F4: ACT | G4: ABP | H4: ACT | I4: ABP | J4: ACT | K4: ABP | L4: ACT | M4: ABP | N4: ACT | O4: ABP | P4: ACT | Q4: ABP | R4: ACT | S4: ABP | T4: ACT | U4: ABP | V4: ACT | W4: ABP | X4: ACT | Y4: ABP | Z4: ACT | AA4: ABP | AB4: ACT | AC4: ABP | AD4: ACT | AE4: ABP | AF4: ACT | AG4: ABP | AH4: ACT | AI4: ABP | AJ4: ACT | AK4: ABP | AL4: ACT | AM4: ABP | AN4: ACT | AO4: ABP | AP4: ACT | AQ4: ABP | AR4: ACT | AS4: ABP | AT4: ACT | AU4: ABP | AV4: ACT | AW4: ABP | AX4: ACT | AY4: ABP | AZ4: ACT | BA4: ABP | BB4: ACT | BC4: ABP | BD4: ACT | BE4: ABP | BF4: ACT | BG4: ABP | BH4: ACT | BI4: ABP | BJ4: ACT | BK4: ABP | BL4: ACT | BM4: ABP | BN4: ACT | BO4: ABP | BP4: ACT | BQ4: ABP | BR4: ACT
B5: Saleable Steel (mill-wise)
B6: MKTG-Plant sales | C6: MT | D6: 25000 | E6: 2083.3333 | F6: 1095.89 | G6: 2083.3333 | H6: 2704.95 | I6: =+E6+G6 -> 4166.6667 | J6: =+F6+H6 -> 3800.84 | K6: 2083.3333 | L6: 6803.81 | M6: =+E6+G6+K6 -> 6250 | N6: =+F6+H6+L6 -> 10604.65 | O6: 2083.3333 | P6: 3865.36 | Q6: =+M6+O6 -> 8333.3333 | R6: =+N6+P6 -> 14470.01 | S6: 2083.3333 | T6: 6257.93 | U6: =+Q6+S6 -> 10416.667 | V6: =+R6+T6 -> 20727.94 | W6: 2083 | X6: 5182.59 | Y6: =+O6+S6+W6 -> 6249.6667 | Z6: =+P6+T6+X6 -> 15305.88 | AA6: =+M6+Y6 -> 12499.667 | AB6: =+N6+Z6 -> 25910.53 | AC6: 2100 | AD6: 4044.21 | AE6: =+AA6+AC6 -> 14599.667 | AF6: =+AB6+AD6 -> 29954.74 | AG6: 2100 | AH6: 5778.35 | AI6: =+AE6+AG6 -> 16699.667 | AJ6: =+AF6+AH6 -> 35733.09 | AK6: 2100 | AL6: 3912 | AM6: =+AC6+AG6+AK6 -> 6300 | AN6: =+AD6+AH6+AL6 -> 13734.56 | AO6: =AI6+AK6 -> 18799.667 | AP6: =AJ6+AL6 -> 39645.09 | AQ6: 2200 | AR6: 3486.44 | AS6: =+AO6+AQ6 -> 20999.667 | AT6: =+AP6+AR6 -> 43131.53 | AU6: 2100 | AV6: 1080.89 | AW6: =+AS6+AU6 -> 23099.667 | AX6: =+AT6+AV6 -> 44212.42 | AY6: 2100 | AZ6: 6965.79 | BA6: =+AQ6+AU6+AY6 -> 6400 | BB6: =+AR6+AV6+AZ6 -> 11533.12 | BC6: =AM6+BA6 -> 12700 | BD6: =AN6+BB6 -> 25267.68 | BE6: =+AW6+AY6 -> 25199.667 | BF6: =+AX6+AZ6 -> 51178.21 | BG6: 21500 | BH6: 53987.54 | BI6: 21500 | BJ6: 30649.84 | BK6: 25500 | BL6: 34807.22 | BM6: 16050 | BN6: 33201.15 | BO6: 0 | BP6: 35268.25 | BQ6: 2000 | BR6: 28405.85
B7: IPT | C7: MT | D7: 0 | E7: 0 | F7: 0 | G7: 0 | H7: 0 | I7: =+E7+G7 -> 0 | J7: =+F7+H7 -> 0 | K7: 0 | L7: 0 | M7: =+E7+G7+K7 -> 0 | N7: =+F7+H7+L7 -> 0 | O7: 0 | P7: 64.1 | Q7: =+M7+O7 -> 0 | R7: =+N7+P7 -> 64.1 | S7: 0 | T7: 1485.16 | U7: =+Q7+S7 -> 0 | V7: =+R7+T7 -> 1549.26 | W7: 0 | X7: 694 | Y7: =+O7+S7+W7 -> 0 | Z7: =+P7+T7+X7 -> 2243.26 | AA7: =+M7+Y7 -> 0 | AB7: =+N7+Z7 -> 2243.26 | AC7: 0 | AD7: 0 | AE7: =+AA7+AC7 -> 0 | AF7: =+AB7+AD7 -> 2243.26 | AG7: 0 | AH7: 0 | AI7: =+AE7+AG7 -> 0 | AJ7: =+AF7+AH7 -> 2243.26 | AK7: 0 | AL7: 0 | AM7: =+AC7+AG7+AK7 -> 0 | AN7: =+AD7+AH7+AL7 -> 0 | AO7: =AI7+AK7 -> 0 | AP7: =AJ7+AL7 -> 2243.26 | AQ7: 0 | AR7: 0 | AS7: =+AO7+AQ7 -> 0 | AT7: =+AP7+AR7 -> 2243.26 | AU7: 0 | AV7: 0 | AW7: =+AS7+AU7 -> 0 | AX7: =+AT7+AV7 -> 2243.26 | AY7: 0 | AZ7: 0 | BA7: =+AQ7+AU7+AY7 -> 0 | BB7: =+AR7+AV7+AZ7 -> 0 | BC7: =AM7+BA7 -> 0 | BD7: =AN7+BB7 -> 0 | BE7: =+AW7+AY7 -> 0 | BF7: =+AX7+AZ7 -> 2243.26 | BG7: 0 | BH7: 322.72 | BI7: 0 | BJ7: 3076.2 | BK7: 123000 | BL7: 42263.08 | BM7: 0 | BN7: 71707.42 | BO7: 10800 | BP7: 9758.51 | BQ7: 24210 | BR7: 5928.095
B8: CMO-WR MILL | C8: MT | D8: 499000 | E8: 42416.667 | F8: 33332.8 | G8: 43916.667 | H8: 39367.02 | I8: =+E8+G8 -> 86333.333 | J8: =+F8+H8 -> 72699.82 | K8: 42416.667 | L8: 37508.06 | M8: =+E8+G8+K8 -> 128750 | N8: =+F8+H8+L8 -> 110207.88 | O8: 43916.667 | P8: 44133.19 | Q8: =+M8+O8 -> 172666.67 | R8: =+N8+P8 -> 154341.07 | S8: 43916.667 | T8: 40726.54 | U8: =+Q8+S8 -> 216583.33 | V8: =+R8+T8 -> 195067.61 | W8: 24916.667 | X8: 36332.97 | Y8: =+O8+S8+W8 -> 112750 | Z8: =+P8+T8+X8 -> 121192.7 | AA8: =+M8+Y8 -> 241500 | AB8: =+N8+Z8 -> 231400.58 | AC8: 45400 | AD8: 37048.14 | AE8: =+AA8+AC8 -> 286900 | AF8: =+AB8+AD8 -> 268448.72 | AG8: 43900 | AH8: 30159.91 | AI8: =+AE8+AG8 -> 330800 | AJ8: =+AF8+AH8 -> 298608.63 | AK8: 45400 | AL8: 37390 | AM8: =+AC8+AG8+AK8 -> 134700 | AN8: =+AD8+AH8+AL8 -> 104598.05 | AO8: =AI8+AK8 -> 376200 | AP8: =AJ8+AL8 -> 335998.63 | AQ8: 45300 | AR8: 37025.61 | AS8: =+AO8+AQ8 -> 421500 | AT8: =+AP8+AR8 -> 373024.24 | AU8: 40400 | AV8: 32967.39 | AW8: =+AS8+AU8 -> 461900 | AX8: =+AT8+AV8 -> 405991.63 | AY8: 45400 | AZ8: 44837.42 | BA8: =+AQ8+AU8+AY8 -> 131100 | BB8: =+AR8+AV8+AZ8 -> 114830.42 | BC8: =AM8+BA8 -> 265800 | BD8: =AN8+BB8 -> 219428.47 | BE8: =+AW8+AY8 -> 507300 | BF8: =+AX8+AZ8 -> 450829.05 | BG8: 498500 | BH8: 459216.41 | BI8: 498500 | BJ8: 473494.21 | BK8: 498500 | BL8: 453432.75 | BM8: 498500 | BN8: 467953.64 | BO8: 435166.29 | BP8: 351267.02 | BQ8: 498000 | BR8: 399090.26
B9: CMO-BAR MILL | C9: MT | D9: 900000 | E9: 76000 | F9: 60011.21 | G9: 79000 | H9: 67347.9 | I9: =+E9+G9 -> 155000 | J9: =+F9+H9 -> 127359.11 | K9: 76000 | L9: 73175.63 | M9: =+E9+G9+K9 -> 231000 | N9: =+F9+H9+L9 -> 200534.74 | O9: 79000 | P9: 84102.5 | Q9: =+M9+O9 -> 310000 | R9: =+N9+P9 -> 284637.24 | S9: 79000 | T9: 86905.93 | U9: =+Q9+S9 -> 389000 | V9: =+R9+T9 -> 371543.17 | W9: 47500 | X9: 68689.99 | Y9: =+O9+S9+W9 -> 205500 | Z9: =+P9+T9+X9 -> 239698.42 | AA9: =+M9+Y9 -> 436500 | AB9: =+N9+Z9 -> 440233.16 | AC9: 80000 | AD9: 64076.47 | AE9: =+AA9+AC9 -> 516500 | AF9: =+AB9+AD9 -> 504309.63 | AG9: 77500 | AH9: 10813.23 | AI9: =+AE9+AG9 -> 594000 | AJ9: =+AF9+AH9 -> 515122.86 | AK9: 80000 | AL9: 67253 | AM9: =+AC9+AG9+AK9 -> 237500 | AN9: =+AD9+AH9+AL9 -> 142142.7 | AO9: =AI9+AK9 -> 674000 | AP9: =AJ9+AL9 -> 582375.86 | AQ9: 80000 | AR9: 70877.68 | AS9: =+AO9+AQ9 -> 754000 | AT9: =+AP9+AR9 -> 653253.54 | AU9: 72500 | AV9: 58216.86 | AW9: =+AS9+AU9 -> 826500 | AX9: =+AT9+AV9 -> 711470.4 | AY9: 80000 | AZ9: 84208.42 | BA9: =+AQ9+AU9+AY9 -> 232500 | BB9: =+AR9+AV9+AZ9 -> 213302.96 | BC9: =AM9+BA9 -> 470000 | BD9: =AN9+BB9 -> 355445.66 | BE9: =+AW9+AY9 -> 906500 | BF9: =+AX9+AZ9 -> 795678.82 | BG9: 870000 | BH9: 750184.19 | BI9: 850000 | BJ9: 781402.45 | BK9: 780000 | BL9: 768402.31 | BM9: 750000 | BN9: 648761.89 | BO9: 674874.74 | BP9: 436958.46 | BQ9: 800000 | BR9: 612890.55
B10: CMO-US MILL | C10: MT | D10: 750000 | E10: 62000 | F10: 44122.7 | G10: 65000 | H10: 57716 | I10: =+E10+G10 -> 127000 | J10: =+F10+H10 -> 101838.7 | K10: 62500 | L10: 56720.68 | M10: =+E10+G10+K10 -> 189500 | N10: =+F10+H10+L10 -> 158559.38 | O10: 65000 | P10: 57264.83 | Q10: =+M10+O10 -> 254500 | R10: =+N10+P10 -> 215824.21 | S10: 65000 | T10: 47224.14 | U10: =+Q10+S10 -> 319500 | V10: =+R10+T10 -> 263048.35 | W10: 33500 | X10: 45948.12 | Y10: =+O10+S10+W10 -> 163500 | Z10: =+P10+T10+X10 -> 150437.09 | AA10: =+M10+Y10 -> 353000 | AB10: =+N10+Z10 -> 308996.47 | AC10: 54000 | AD10: 43303.75 | AE10: =+AA10+AC10 -> 407000 | AF10: =+AB10+AD10 -> 352300.22 | AG10: 52000 | AH10: 15465.42 | AI10: =+AE10+AG10 -> 459000 | AJ10: =+AF10+AH10 -> 367765.64 | AK10: 54000 | AL10: 33463 | AM10: =+AC10+AG10+AK10 -> 160000 | AN10: =+AD10+AH10+AL10 -> 92232.17 | AO10: =AI10+AK10 -> 513000 | AP10: =AJ10+AL10 -> 401228.64 | AQ10: 54000 | AR10: 44656.88 | AS10: =+AO10+AQ10 -> 567000 | AT10: =+AP10+AR10 -> 445885.52 | AU10: 48000 | AV10: 47339.01 | AW10: =+AS10+AU10 -> 615000 | AX10: =+AT10+AV10 -> 493224.53 | AY10: 60000 | AZ10: 68418.51 | BA10: =+AQ10+AU10+AY10 -> 162000 | BB10: =+AR10+AV10+AZ10 -> 160414.4 | BC10: =AM10+BA10 -> 322000 | BD10: =AN10+BB10 -> 252646.57 | BE10: =+AW10+AY10 -> 675000 | BF10: =+AX10+AZ10 -> 561643.04 | BG10: 560000 | BH10: 502052.01 | BI10: 525000 | BJ10: 452802.59 | BK10: 470000 | BL10: 357334.79 | BM10: 445000 | BN10: 214319.65 | BO10: 220000 | BP10: 100400.4 | BQ10: 535000 | BR10: 167166.99
