Workbook
Name _GoBack: 'PERF DASTUR POW. GREEN ST'!#REF!
Name _Hlk158901410: 'MIS MONTH WISE FUEL NMGCAL '!$J$212
Name AA: 'DAILY FLASH'!$X$12

Sheet CM REPORT
A2: GRADE-GROUP WISE MONTH-WISE SALEABLE STEEL FOR CALENDER YEAR 2016
A3: GRD GROUP | B3: JAN'16 | D3: FEB'16 | E3: MARCH'16 | F3: APRIL'16 | G3: MAY'16 | H3: JUNE'16 | I3: JULY'16 | J3: AUG'16 | K3: SEPT'16 | L3: OCT'16 | M3: NOV'16 | N3: DEC'16 | O3: YR. 2016
A4: CARBON STEEL | B4: 4218.38 | D4: 4763.194 | E4: 4615.27 | F4: 4540.125 | G4: 4047.08 | H4: 4494.804 | I4: 5032.362 | J4: 5505.713 | K4: 4782.904 | L4: 4385.475 | M4: 5238.744 | N4: 5486.051 | O4: =SUM(B4:N4) -> 57110.102 | T4: 384 | AL4: 03.09.2020 | BI4: 0
A5: ALLOY STEEL | B5: 958.808 | D5: 1385.374 | E5: 1369.283 | F5: 1730.112 | G5: 2022.85 | H5: 1675.41 | I5: 1410.448 | J5: 725.516 | K5: 1760.083 | L5: 1868.442 | M5: 1188.861 | N5: 701.188 | O5: =SUM(B5:N5) -> 16796.375 | T5: 900
A6: STN. STEEL | B6: 81.34 | D6: 88.39 | E6: 70.31 | F6: 21.88 | G6: 11.95 | H6: 91.83 | I6: 131.489 | J6: 6.68 | K6: 3.351 | L6: 13.44 | M6: 28.89 | N6: 11.49 | O6: =SUM(B6:N6) -> 561.04 | T6: 120
A7: OTHER SPL STEEL | B7: =6061.414-5258.528 -> 802.886 | D7: =7029.995-6236.958 -> 793.037 | E7: =7040.803-6054.863 -> 985.94 | F7: =7166.965-6292.117 -> 874.848 | G7: =7169.078-6081.88 -> 1087.198 | H7: =7167.21-6262.044 -> 905.166 | I7: =7234.295-6574.299 -> 659.996 | J7: =7227.105-6237.909 -> 989.196 | K7: =7359.97-6546.338 -> 813.632 | L7: =7342.006-6267.357 -> 1074.649 | M7: =7225.223-6456.495 -> 768.728 | N7: =7340.383-6198.729 -> 1141.654 | O7: =SUM(B7:N7) -> 10896.93 | T7: 6946
A8: TOTAL | B8: =SUM(B3:B7) -> 6061.414 | D8: =SUM(D3:D7) -> 7029.995 | E8: =SUM(E3:E7) -> 7040.803 | F8: =SUM(F3:F7) -> 7166.965 | G8: =SUM(G3:G7) -> 7169.078 | H8: =SUM(H3:H7) -> 7167.21 | I8: =SUM(I3:I7) -> 7234.295 | J8: =SUM(J3:J7) -> 7227.105 | K8: =SUM(K3:K7) -> 7359.97 | ... N8: =SUM(N3:N7) -> 7340.383 | O8: =SUM(B8:N8) -> 85364.447 | T8: 2100
T9: 2400
A10: SUMMARY OF ABOVE | T10: =SUM(T4:T9) -> 12850
A11: GRRDD GROUP | B11: TOTAL | T11: 643
A12: CARBON STEEL | B12: 57110
A13: STN. STEEL | B13: 561
A14: ALLOY ATEEL | B14: =10897+16796 -> 27693 | BB14: 1
B15: =SUM(B12:B14) -> 85364
A18: GRADE-GROUP WISE MONTH-WISE CRUDE STEEL FOR CALENDER YEAR 2016
A19: GRD GROUP | B19: JAN'16 | D19: FEB'16 | E19: MARCH'16 | F19: APRIL'16 | G19: MAY'16 | H19: JUNE'16 | I19: JULY'16 | J19: AUG'16 | K19: SEPT'16 | L19: OCT'16 | M19: NOV'16 | N19: DEC'16 | O19: YR. 2016
A20: CARBON STEEL | B20: 5667 | D20: 4523 | E20: 3386 | F20: 3687 | G20: 4741 | H20: 5176 | I20: 5147 | J20: 5090 | K20: 4272 | L20: 4136 | M20: 5891 | N20: 4769 | O20: =SUM(B20:N20) -> 56485
A21: STN. STEEL | B21: 0 | D21: 0 | E21: 271 | F21: 0 | G21: 208 | H21: 0 | I21: 41 | J21: 0 | K21: 0 | L21: 0 | M21: 0 | N21: 0 | O21: =SUM(B21:N21) -> 520
A22: ALLOY STEELS | B22: =7603-5667 -> 1936 | D22: =7061-4523 -> 2538 | E22: =7592-3657 -> 3935 | F22: =7397-3687 -> 3710 | G22: =7827-4949 -> 2878 | H22: =7409-5176 -> 2233 | I22: =7487-5188 -> 2299 | J22: =7853-5090 -> 2763 | K22: =7344-4272 -> 3072 | L22: =7565-4136 -> 3429 | M22: =7736-5891 -> 1845 | N22: =7405-4769 -> 2636 | O22: =SUM(B22:N22) -> 33274 | BB22: 1
A23: TOTAL | B23: =SUM(B19:B22) -> 7603 | D23: =SUM(D19:D22) -> 7061 | E23: =SUM(E19:E22) -> 7592 | F23: =SUM(F19:F22) -> 7397 | G23: =SUM(G19:G22) -> 7827 | H23: =SUM(H19:H22) -> 7409 | I23: =SUM(I19:I22) -> 7487 | J23: =SUM(J19:J22) -> 7853 | K23: =SUM(K19:K22) -> 7344 | ... N23: =SUM(N19:N22) -> 7405 | O23: =SUM(B23:N23) -> 90279
A25: SUMMARY OF ABOVE
A26: GRRDD GROUP | B26: TOTAL | BB26: 0
A27: CARBON STEEL | B27: =+O20 -> 56485
A28: STN. STEEL | B28: =O21 -> 520
A29: ALLOY ATEEL | B29: =O22 -> 33274
B30: =SUM(B27:B29) -> 90279
A34: Ref : Tab2_01
A36: YEAR-WISE STN CRUDE & SALEABLE
A37: GRD GROUP | B37: 2010-11 | D37: 2011-12 | E37: 2012-13 | F37: 2013-14 | G37: 2014-15 | H37: 2015-16 | I37: 16-17 TILL DT
A38: CRUDE | B38: 68883 | D38: 31660 | E38: 862 | F38: 1088 | G38: 1114 | H38: 1148 | I38: 296
A39: SALEABLE | B39: 66706 | D39: 29160 | E39: 1019 | F39: 545 | G39: 647 | H39: 776 | I39: 400
A41: Details relating to stainless steel slab despatch to salem
A42: YEAR | B42: 2012-13 | D42: 2013-14 | E42: 2014-15 | F42: 2015-16 | G42: 2016-17 | H42: 2017-18
A43: DESPATCH(T) | B43: NIL | D43: NIL | E43: NIL | F43: NIL | G43: NIL | H43: 87.16
A48: GRADE-GROUP WISE MONTH-WISE CRUDE STEEL FOR CALENDER YEAR 2017
A49: GRD GROUP | B49: JAN'17 | D49: FEB'17 | E49: MARCH'17 | F49: APRIL'17 | G49: MAY'17 | H49: JUNE'17 | I49: JULY'17 | J49: AUG'17 | K49: SEPT'17 | L49: OCT'17 | M49: NOV'17 | N49: DEC'17 | O49: YR. 2017
A50: CARBON STEEL | B50: 4548 | D50: 3708 | E50: 2542 | F50: 4089 | G50: 5748 | H50: 5296 | I50: 5661 | J50: 5240 | K50: 6235 | L50: 4693 | M50: 4182 | N50: 4493 | O50: =SUM(B50:N50) -> 56435
A51: STN. STEEL | B51: 47 | D51: 0 | E51: 0 | F51: 0 | G51: 0 | H51: 0 | I51: 0 | J51: 100 | K51: 0 | L51: 0 | M51: 0 | N51: 45 | O51: =SUM(B51:N51) -> 192
A52: ALLOY STEELS | B52: =7396-4548-47 -> 2801 | D52: =7019-3708 -> 3311 | E52: =5669-2542 -> 3127 | F52: =7314-4089 -> 3225 | G52: =7975-5748 -> 2227 | H52: =7903-5296 -> 2607 | I52: =8016-5661 -> 2355 | J52: =8221-5340 -> 2881 | K52: =8572-6235 -> 2337 | L52: =7136-4693 -> 2443 | M52: =6610-4182 -> 2428 | N52: =8203-4493-45 -> 3665 | O52: =SUM(B52:N52) -> 33407
A53: TOTAL | B53: =SUM(B49:B52) -> 7396 | D53: =SUM(D49:D52) -> 7019 | E53: =SUM(E49:E52) -> 5669 | F53: =SUM(F49:F52) -> 7314 | G53: =SUM(G49:G52) -> 7975 | H53: =SUM(H49:H52) -> 7903 | I53: =SUM(I49:I52) -> 8016 | J53: =SUM(J49:J52) -> 8221 | K53: =SUM(K49:K52) -> 8572 | ... N53: =SUM(N49:N52) -> 8203 | O53: =SUM(B53:N53) -> 90034
...

Sheet DAILY FLASH
AH1: CUMM prev dt | AI1: =AL5 -> 01.06.2026 | AQ1: स्टीळ अ‍ॅथारिटी ऑफ इंडिया लिमिटेड | AW1: UNIT: T | AX1: 2026-27 | AZ1: ABP | BA1: ACT TILL DT | BB1: RATE | BC1: % ABP | BE1: TILL 22/01' | BF1: TILL 23/03
AG2: crude | AH2: 5809565.1 | AJ2: ING SOLID | AK2: =AP14 -> 20339.81 | AL2: एलॉय स्टील प्ळांट | AX2: CRUDE | AZ2: 150797 | BA2: =AI20+AN20 -> 21246.991 | BB2: =BA2/BK2*BH2 -> 127133.63 | BC2: =+BB2/AZ2% -> 84.307801 | BE2: 7085976 | BF2: =7085976+3918+10848+8007 -> 7108749 | BH2: =306+28+31 -> 365 | BI2: 1 | BJ2: 60 | BK2: =BJ2+BI2 -> 61 | BL2: =30+31+30+31+31+30+31+30+31+15 -> 290
AG3: saleable | AH3: 5809310.9 | AJ3: CCS SOLID | AK3: =AP19 -> 907.181 | AL3: PERFORMANCE REPORT FOR 24 HRS. ENDING AT 06:00 HRS. AS ON | AX3: SAL. | AZ3: 146285 | BA3: =AI56+AN56 -> 22620.088 | BB3: =BA3/BK3*BH3 -> 133159.76 | BC3: =+BB3/AZ3% -> 91.027626 | BE3: 5656023 | BF3: =5656023+3800+10677+7788 -> 5678288 | BH3: 312 | BI3: 1 | BJ3: 52 | BK3: =BJ3+BI3 -> 53 | BL3: =27+27+25+27+26+26+27+25+27+13 -> 250 | BR3: =30+31+30-13 -> 78
P4: 131470 | AN4: FIGURES IN TON | AP4: SINCE INCEPTION | AR4: CRUDE | AS4: =+AH2+AL20 -> 5810130.3 | AT4: SALEABLE | AU4: =AH3+AL56 -> 5809770.1 | AX4: BBM CH WT | AZ4: 160480 | BA4: =AP31 -> 25549.399 | BB4: =BA4/BK4*BH4 -> 151349.77 | BC4: =+BB4/AZ4% -> 94.310676 | BH4: 311 | BI4: 0.5 | BJ4: 52 | BK4: =BJ4+BI4 -> 52.5 | BL4: =26+26.5+25.5+26+27+26+25.5+25.5+27+24.5+2.5 -> 262
N5: 50.666667 | P5: =262-46.55 -> 215.45 | AJ5: LIQUID STEEL | AK5: =AP12 -> 22090.47 | AL5: 01.06.2026 | AX5: DESP | AZ5: 148285 | BA5: =AP58 -> 23199.71 | BB5: =BA5/BK5*BH5 -> 136571.88 | BC5: =+BB5/AZ5% -> 92.100939 | BH5: 312 | BI5: 1 | BJ5: 52 | BK5: =BJ5+BI5 -> 53
P6: =+P4/P5 -> 610.21119 | AJ6: CC LIQ | AK6: =AP79 -> 879.53 | AQ6: दैनिक एम आई एस रिपोर्ट | AX6: DSP ING. | AZ6: 6500 | BA6: =AP72 -> 585 | BB6: =BA6/BK6*BH6 -> 3500.4098 | BC6: =+BB6/AZ6% -> 53.852459 | BH6: =306+28+31 -> 365 | BI6: 1 | BJ6: 60 | BK6: =BJ6+BI6 -> 61
AG7: =+V12/7 -> 59.742857 | AI7: =407-465 -> -58 | AJ7: ING LIQ | AK7: =AP80 -> 21206.945 | BN7: =30+31+30+31 -> 122 | BQ7: =13+9 -> 22
A8: - | B8: - | C8: - | D8: - | E8: - | F8: - | G8: - | H8: - | I8: - | J8: - | K8: - | L8: - | M8: - | N8: - | O8: - | P8: - | Q8: - | R8: - | S8: - | T8: - | U8: - | V8: - | W8: - | Y8: - | Z8: - | AA8: - | AB8: - | AC8: - | AD8: - | AE8: - | AF8: - | AG8: - | AK8: ON | AL8: DATE | AM8: TO DATE | AO8: W.R.T | AV8: PREV. | BA8: GRADE-WISE HEATS IN THE MONTH | BM8: =30+30+31+3 -> 94
A9: 1 | B9: =A9+1 -> 2 | C9: =B9+1 -> 3 | D9: =C9+1 -> 4 | E9: =D9+1 -> 5 | F9: =E9+1 -> 6 | G9: =F9+1 -> 7 | H9: =G9+1 -> 8 | I9: =H9+1 -> 9 | ... AE9: =AD9+1 -> 31 | AF9: MAX | AG9: MAY'26 | AJ9: DETAILS | AV9: DAY | AW9: MONTHLY | AX9: MONTH | AY9: YEARLY | AZ9: YEAR | BQ9: =30+30+31-11+3 -> 83
K10: =J10 | L10: AL/AU | P10: AL/AU | T10: AL/AU | X10: AL/AU | AC10: AL/AU | AG10: TILL DATE | AK10: ABP | AL10: ACTUAL | AM10: ABP | AN10: ACTUAL | AO10: APP | AP10: ACTUAL | AQ10: ABP | AR10: RATE | AS10: % | AT10: April'26 | AU10: May'25 | AV10: PERF. | AW10: BEST | AX10: YEAR | AY10: BEST | BA10: GRADES | BB10: ON DATE | BC10: TILL DATE
A11: - | B11: - | C11: - | D11: - | E11: - | F11: - | G11: - | H11: - | I11: - | J11: - | K11: - | L11: - | M11: - | N11: - | O11: - | P11: - | Q11: - | R11: - | S11: - | T11: - | U11: - | V11: - | W11: - | X11: - | Y11: - | Z11: - | AA11: - | AB11: - | AC11: - | AD11: - | AE11: - | AF11: - | AG11: - | AO11: % | AP11: 25-26 | AU11: CPLY | AV11: - | AW11: ALL TIME | AY11: ALL TIME
A12: 211 | B12: 320 | C12: =369 -> 369 | D12: =315-0.45 -> 314.55 | E12: 367.2 | F12: =306+0.65 -> 306.65 | G12: 368.55 | H12: =362 -> 362 | I12: =371+0.78-0.27 -> 371.51 | J12: =152 -> 152 | K12: =411.12 -> 411.12 | L12: =364 -> 364 | M12: =424 -> 424 | N12: =369+0.9 -> 369.9 | O12: 200.35 | P12: =306 -> 306 | Q12: =303 -> 303 | R12: 365.2 | S12: 425.2 | T12: =321 -> 321 | U12: =267 -> 267 | V12: =418+0.2 -> 418.2 | W12: =413 -> 413 | X12: =349 -> 349 | Y12: =352.4 -> 352.4 | Z12: =369 -> 369 | AA12: =315 -> 315 | AB12: =522 -> 522 | AC12: =463 -> 463 | AD12: 515 | AE12: =585 -> 585 | AF12: =MAX(A12:AE12) -> 585 | AG12: =SUM(A12:AE12) -> 11200.83 | AI12: 10889.64 | AJ12: LIQUID STEEL | AK12: =AQ12/BH12*BI12 -> 385.80645 | AL12: =AE12 -> 585 | AM12: =SUM(AQ12/BH12*BK12) -> 11960 | AN12: =AG12 -> 11200.83 | AO12: =+AN12/AM12*100 -> 93.652425 | AP12: =+AN12+AI12 -> 22090.47 | AQ12: 11960 | AR12: =AN12*BH12/BK12 -> 11200.83 | AS12: =SUM(AR12*100/AQ12) -> 93.652425 | AT12: 10885.645 | AU12: 11206.97 | AV12: =AD12 -> 515 | AW12: 26716 | AX12: MAR'97 | AY12: 268353 | AZ12: 96-97 | BA12: SPADE M1 | BB12: 0 | BC12: =BD12+BB12 -> 10 | BD12: 10 | BG12: =+BH12-BK12 -> 0 | BH12: 31 | BI12: =BI2 -> 1 | BJ12: 30 | BK12: =BJ12+BI12 -> 31
A13: 0 | B13: 0 | C13: 0 | D13: 0 | E13: 0 | F13: =53+54.15 -> 107.15 | G13: 0 | H13: 0 | I13: 0 | J13: 0 | K13: 0 | L13: 0 | M13: 0 | N13: 0 | O13: 0 | P13: 0 | Q13: 0 | R13: 0 | S13: 0 | T13: 0 | U13: 0 | V13: 0 | W13: 0 | X13: 0 | Y13: 0 | Z13: 0 | AA13: 0 | AB13: 0 | AC13: 0 | AD13: 0 | AE13: 0 | AF13: =MAX(A13:AE13) -> 107.15 | AG13: =SUM(A13:AE13) -> 107.15 | AI13: 0 | AJ13: STN:LIQ | AK13: =AQ13/BH13*BI13 -> 0 | AL13: =AE13 -> 0 | AM13: =SUM(AQ13/BH13*BK13) -> 0 | AN13: =AG13 -> 107.15 | AP13: =+AN13+AI13 -> 107.15 | AQ13: 0 | AS13: =SUM(AR13*100/AQ13) -> #DIV/0! | AT13: 0 | AU13: 51.6 | AV13: =AD13 -> 0 | AW13: 8768 | AX13: NOV'09 | BA13: DMRL1750 | BB13: 0 | BC13: =BD13+BB13 -> 0 | BD13: 0 | BG13: =+BH13-BK13 -> 0 | BH13: =+BH12 -> 31 | BI13: =BI12 -> 1 | BJ13: 30 | BK13: =BJ13+BI13 -> 31 | BS13: =30+30+31+4 -> 95
A14: 204.4 | B14: =308.15 -> 308.15 | C14: =357.15 -> 357.15 | D14: =304.1 -> 304.1 | E14: 355.2 | F14: =295.65 -> 295.65 | G14: 349.8 | H14: 349.85 | I14: =309.15 -> 309.15 | J14: =146 -> 146 | K14: 338.22 | L14: =352.55 -> 352.55 | M14: =409 -> 409 | N14: =357.15+0.8 -> 357.95 | O14: 192.85 | P14: =246.85 -> 246.85 | Q14: 293.15 | R14: 302.4 | S14: 359.2 | T14: =309.7 -> 309.7 | U14: =258.45 -> 258.45 | V14: =405.5+0.05 -> 405.55 | W14: =349.65 -> 349.65 | X14: =287.5 -> 287.5 | Y14: 340 | Z14: =359.25 -> 359.25 | AA14: =304 -> 304 | AB14: =453.45 -> 453.45 | AC14: 446.45 | AD14: =448.95 -> 448.95 | AE14: =565.15 -> 565.15 | AF14: =MAX(A14:AE14) -> 565.15 | AG14: =SUM(A14:AE14) -> 10359.72 | AI14: 9980.09 | AJ14: INGOT | AK14: =AQ14/BH14*BI14 -> 355 | AL14: =AE14 -> 565.15 | AM14: =SUM(AQ14/BH14*BK14) -> 11005 | AN14: =AG14 -> 10359.72 | AO14: =+AN14/AM14*100 -> 94.136483 | AP14: =AN14+AI14 -> 20339.81 | AQ14: 11005 | AR14: =AN14*BH14/BK14 -> 10359.72 | AS14: =SUM(AR14*100/AQ14) -> 94.136483 | AT14: 9977.07 | AU14: 10052.6 | AV14: =AD14 -> 448.95 | AW14: 15089 | AX14: MAR'89 | AY14: 151556 | AZ14: 88-89 | BA14: Jackal | BB14: 0 | BC14: =BD14+BB14 -> 0 | BD14: 0 | BG14: =+BH14-BK14 -> 0 | BH14: =+BH13 -> 31 | BI14: =BI13 -> 1 | BJ14: 30 | BK14: =BJ14+BI14 -> 31
A15: 0 | B15: 0 | C15: 0 | D15: 0 | E15: 0 | F15: =43.75+52.65 -> 96.4 | G15: 0 | H15: 0 | I15: 0 | J15: 0 | K15: 0 | L15: 0 | M15: 0 | N15: 0 | O15: 0 | P15: 0 | Q15: 0 | R15: 0 | S15: 0 | T15: 0 | U15: 0 | V15: 0 | W15: 0 | X15: 0 | Y15: 0 | Z15: 0 | AA15: 0 | AB15: 0 | AC15: 0 | AD15: 0 | AE15: 0 | AF15: =MAX(A15:AE15) -> 96.4 | AG15: =SUM(A15:AE15) -> 96.4 | AH15: =+AH16/AH17*100 -> 97.418055 | AI15: 0 | AJ15: STN:ING | AK15: =AQ15/BH15*BI15 -> 0 | AL15: =AE15 -> 0 | AM15: =SUM(AQ15/BH15*BK15) -> 0 | AN15: =AG15 -> 96.4 | AP15: 0 | AQ15: 0 | AR15: =AN15*BH15/BK15 -> 96.4 | AT15: 0 | AU15: 48.6 | AV15: =AD15 -> 0 | BA15: SAILRATH | BB15: 0 | BC15: =BD15+BB15 -> 0 | BD15: 0 | BG15: =+BH15-BK15 -> 0 | BH15: =+BH14 -> 31 | BI15: =BI14 -> 1 | BJ15: 30 | BK15: =BJ15+BI15 -> 31 | BP15: =150/23*29 -> 189.13043
A16: 0 | B16: 0 | C16: 0 | D16: 0 | E16: 0 | F16: 0 | G16: 0 | H16: 0 | I16: 51.04 | J16: 0 | K16: 47.39 | L16: 0 | M16: 0 | N16: 0 | O16: 0 | P16: 0 | Q16: 0 | R16: =50.9-0.04 -> 50.86 | S16: 52.01 | T16: 0 | U16: 0 | V16: 0 | W16: =49.5-0.34 -> 49.16 | X16: 49.6 | Y16: 0 | Z16: 0 | AA16: 0 | AB16: 48.79 | AC16: 0 | AD16: 50.621 | AE16: 0 | AG16: =SUM(A16:AE16) -> 399.471 | AH16: =3.65+49.55 -> 53.2 | AI16: 507.71 | AJ16: CC SLAB | AK16: =AQ16/BH16*BI16 -> 19.580645 | AL16: =AE16 -> 0 | AM16: =SUM(AQ16/BH16*BK16) -> 607 | AN16: =AG16 -> 399.471 | AP16: =AN16+AI16 -> 907.181 | AQ16: 607 | AR16: =AN16*BH16/BK16 -> 399.471 | AS16: =SUM(AR16*100/AQ16) -> 65.810708 | AT16: 507.08 | AU16: 733.06 | AV16: =AD16 -> 50.621 | AW16: 13036 | AX16: MAR'94 | AY16: 112288 | AZ16: 10-11 | BB16: 0 | BC16: =BD16+BB16 -> 0 | BD16: 0 | BG16: =+BH16-BK16 -> 0 | BH16: =++BH15 -> 31 | BI16: =BI15 -> 1 | BJ16: 30 | BK16: =BJ16+BI16 -> 31
A17: 0 | B17: 0 | C17: 0 | D17: 0 | E17: 0 | F17: 0 | G17: 0 | H17: 0 | I17: 0 | J17: 0 | K17: 0 | L17: 0 | M17: 0 | N17: 0 | O17: 0 | P17: 0 | Q17: 0 | R17: 0 | S17: 0 | T17: 0 | U17: 0 | V17: 0 | W17: 0 | X17: 0 | Y17: 0 | Z17: 0 | AA17: 0 | AB17: 0 | AC17: 0 | AD17: 0 | AE17: 0 | AF17: 0 | AG17: =SUM(A17:AE17) -> 0 | AH17: =3.65+50.96 -> 54.61 | AI17: 0 | AJ17: CC BLOOM | AK17: 0 | AL17: =AE17 -> 0 | AM17: =SUM(AQ17/BH17*BK17) -> 0 | AN17: =AG17 -> 0 | AP17: =AN17+AI17 -> 0 | AQ17: 0 | AR17: =SUM(AN17*BH17/BK17) -> 0 | AS17: 0 | AT17: 0 | AU17: 0 | AV17: =AD17 -> 0 | BA17: TOTAL CC HTS | BB17: =SUM(BB12:BB15) -> 0 | BC17: =BD17+BB17 -> 11 | BD17: 11 | BH17: =+BH16 -> 31 | BI17: =BI16 -> 1 | BJ17: 30 | BK17: =BJ17+BI17 -> 31
A18: 0 | B18: 0 | C18: 0 | D18: 0 | E18: 0 | F18: 0 | G18: 0 | H18: 0 | I18: 0 | J18: 0 | K18: 0 | L18: 0 | M18: 0 | N18: 0 | O18: 0 | P18: 0 | Q18: 0 | R18: 0 | S18: 0 | T18: 0 | U18: 0 | V18: 0 | W18: 0 | X18: 0 | Y18: 0 | Z18: 0 | AA18: 0 | AB18: 0 | AC18: 0 | AD18: 0 | AE18: 0 | AG18: 0 | AH18: =+AH19-AG18 -> 1254.14 | AI18: 0 | AK18: 0 | AL18: =AE18 -> 0 | AM18: =SUM(AQ18/BH18*BK18) -> 0 | AN18: =AG18 -> 0 | AQ18: 0 | AR18: =SUM(AN18*BH18/BK18) -> 0 | AT18: 0 | AU18: 0 | AV18: =AD18 -> 0 | BA18: HADFIELD | BB18: 0 | BC18: =BD18+BB18 -> 3 | BD18: 3 | BE18: =1+2+3+14+49+17+4 -> 90 | BH18: =+BH17 -> 31 | BI18: =BI17 -> 1 | BJ18: 30 | BK18: =BJ18+BI18 -> 31
A19: =A17+A16 -> 0 | B19: =B17+B16 -> 0 | C19: =C17+C16 -> 0 | D19: =D17+D16 -> 0 | E19: =E17+E16 -> 0 | F19: =F17+F16 -> 0 | G19: =G17+G16 -> 0 | H19: =H17+H16 -> 0 | ... AE19: =AE17+AE16 -> 0 | AF19: =MAX(A19:AE19) -> 52.01 | AG19: =+AG16+AG17 -> 399.471 | AH19: 1254.14 | AI19: 507.71 | AJ19: TOT. CCS PROD | AK19: =AQ19/BH19*BI19 -> 19.580645 | AL19: =AE19 -> 0 | AM19: =SUM(AQ19/BH19*BK19) -> 607 | AN19: =AG19 -> 399.471 | AP19: =AN19+AI19 -> 907.181 | AQ19: =+AQ16 -> 607 | AR19: =AN19*BH19/BK19 -> 399.471 | AS19: =SUM(AR19*100/AQ19) -> 65.810708 | AT19: 507.08 | AU19: 733.06 | AV19: =AD19 -> 50.621 | AW19: 8488 | AX19: NOV'09 | AY19: 112288 | AZ19: 10-11 | BA19: SPADE M2 | BB19: 0 | BC19: =BD19+BB19 -> 0 | BD19: 0 | BH19: =+BH18 -> 31 | BI19: =BI18 -> 1 | BJ19: 30 | BK19: =BJ19+BI19 -> 31
A20: =+A19+A14 -> 204.4 | B20: =+B19+B14 -> 308.15 | C20: =+C19+C14 -> 357.15 | D20: =+D19+D14 -> 304.1 | E20: =+E19+E14 -> 355.2 | F20: =+F19+F14 -> 295.65 | G20: =+G19+G14 -> 349.8 | H20: =+H19+H14 -> 349.85 | ... AE20: =+AE19+AE14 -> 565.15 | AF20: =MAX(A20:AE20) -> 565.15 | AG20: =SUM(A20:AE20) -> 10759.191 | AI20: 10487.8 | AJ20: CRUDE | AK20: =AQ20/BH20*BI20 -> 374.58065 | AL20: =AE20 -> 565.15 | AM20: =SUM(AQ20/BH20*BK20) -> 11612 | AN20: =AG20 -> 10759.191 | AO20: =+AN20/AM20*100 -> 92.655796 | AP20: =AN20+AI20 -> 21246.991 | AQ20: =+AQ19+AQ14 -> 11612 | AR20: =AN20*BH20/BK20 -> 10759.191 | AS20: =SUM(AR20*100/AQ20) -> 92.655796 | AT20: 10484.15 | AU20: 10785.66 | AV20: =AD20 -> 499.571 | AW20: 24735 | AX20: MAR'97 | AY20: 248175 | AZ20: 96-97 | BA20: 9260 | BB20: 0 | BC20: =BD20+BB20 -> 0 | BD20: 0 | BG20: =BH20-BK20 -> 0 | BH20: =BH21 -> 31 | BI20: =BI19 -> 1 | BJ20: 30 | BK20: =BJ20+BI20 -> 31
A21: 5 | B21: 7 | C21: 7 | D21: 6 | E21: 7 | F21: 7 | G21: 6 | H21: 7 | I21: 7 | J21: 4 | K21: 6 | L21: 9 | M21: 7 | N21: 8 | O21: 4 | P21: 6 | Q21: 5 | R21: 7 | S21: 7 | T21: 7 | U21: 7 | V21: 6 | W21: 9 | X21: 7 | Y21: 6 | Z21: 8 | AA21: 8 | AB21: 9 | AC21: 9 | AD21: 9 | AE21: 8 | AF21: =MAX(A21:AE21) -> 9 | AG21: =SUM(A21:AE21) -> 215 | AH21: average( | AI21: 209 | AJ21: HEATS: TOTAL | AK21: 8 | AL21: =AE21 -> 8 | AM21: =AM12/53 -> 225.66038 | AN21: =AG21 -> 215 | AP21: =AN21+AI21 -> 424 | AQ21: =AQ12/52 -> 230 | AR21: =AN21*BH21/BK21 -> 215 | AS21: =SUM(AR21*100/AQ21) -> 93.478261 | AT21: 209 | AU21: 217 | AV21: =AD21 -> 9 | BA21: SSB-27 | BB21: 0 | BC21: =BD21+BB21 -> 0 | BD21: 0 | BH21: =BH15 -> 31 | BI21: =BI20 -> 1 | BJ21: 30 | BK21: =BJ21+BI21 -> 31
A22: 1 | B22: 0 | C22: 0 | D22: 0 | E22: 0 | F22: 0 | G22: 1 | H22: 1 | I22: 2 | J22: 1 | K22: 1 | L22: 2 | M22: 1 | N22: 1 | O22: 2 | P22: 1 | Q22: 1 | R22: 1 | S22: 1 | T22: 0 | U22: 1 | V22: 1 | W22: 2 | X22: 2 | Y22: 1 | Z22: 2 | AA22: 2 | AB22: 2 | AC22: 2 | AD22: 2 | AE22: 2 | AF22: =MAX(A22:AE22) -> 2 | AG22: =SUM(A22:AE22) -> 36 | AI22: 39 | AJ22: DSP HM HEATS | AK22: 2 | AL22: =AE22 -> 2 | AN22: =AG22 -> 36 | AP22: =AN22+AI22 -> 75 | AT22: 39 | AU22: 63 | AV22: =AD22 -> 2 | BA22: EA 1N | BB22: 0 | BC22: =BD22+BB22 -> 1 | BD22: 1
A23: 4 | B23: 6 | C23: 7 | D23: 6 | E23: 7 | F23: 6 | G23: 7 | H23: 7 | I23: 7 | J23: 3 | K23: 8 | L23: 7 | M23: 8 | N23: 7 | O23: 4 | P23: 6 | Q23: 6 | R23: 7 | S23: 8 | T23: 6 | U23: 5 | V23: 8 | W23: 8 | X23: 7 | Y23: 7 | Z23: 7 | AA23: 6 | AB23: 10 | AC23: 9 | AD23: 10 | AE23: 11 | AG23: =SUM(A23:AE23) -> 215 | AI23: 209 | AJ23: TEEMING | AL23: =AE23 -> 11 | AN23: =AG23 -> 215 | AT23: 209 | AU23: 217 | AV23: =AD23 -> 10 | BA23: 1875 CL IV | BB23: 0 | BC23: =BD23+BB23 -> 14 | BD23: 14
A24: 0 | B24: 0 | C24: 0 | D24: 0 | E24: 0 | F24: 0 | G24: 0 | H24: 0 | I24: 1 | J24: 0 | K24: 1 | L24: 0 | M24: 0 | N24: 0 | O24: 0 | P24: 0 | Q24: 0 | R24: 1 | S24: 1 | T24: 0 | U24: 0 | V24: 0 | W24: 1 | X24: 1 | Y24: 0 | Z24: 0 | AA24: 0 | AB24: 1 | AC24: 0 | AD24: 1 | AE24: 0 | AF24: =MAX(A24:AE24) -> 1 | AG24: =SUM(A24:AE24) -> 8 | AH24: =770.573-47.73 -> 722.843 | AI24: 10 | AJ24: :CC | AK24: 3 | AL24: =AE24 -> 0 | AN24: =AG24 -> 8 | AP24: =AN24+AI24 -> 18 | AT24: 10 | AU24: 14 | AV24: =AD24 -> 1 | BA24: B-14 | BB24: 0 | BC24: =BD24+BB24 -> 0 | BD24: 0 | BN24: =30-8 -> 22
A25: 2 | B25: 7 | C25: 7 | D25: 6 | E25: 7 | F25: 6 | G25: 2 | H25: 4 | I25: 6 | J25: 3 | K25: 5 | L25: 5 | M25: 6 | N25: 4 | O25: 2 | P25: 4 | Q25: 2 | R25: 6 | S25: 4 | T25: 5 | U25: 2 | V25: 2 | W25: 5 | X25: 4 | Y25: 1 | Z25: 5 | AA25: 4 | AB25: 2 | AC25: 4 | AD25: 4 | AE25: 5 | AF25: =MAX(A25:AE25) -> 7 | AG25: =SUM(A25:AE25) -> 131 | AI25: 108 | AJ25: :VAD | AK25: 0 | AL25: =AE25 -> 5 | AN25: =AG25 -> 131 | AP25: =AN25+AI25 -> 239 | AT25: 108 | AU25: 114 | AV25: =AD25 -> 4 | BA25: R-16 | BB25: 0 | BC25: =BD25+BB25 -> 11 | BD25: 11
A26: 0 | B26: 0 | C26: 0 | D26: 0 | E26: 0 | F26: 1 | G26: 2 | H26: 2 | I26: 1 | J26: 1 | K26: 1 | L26: 2 | M26: 1 | N26: 2 | O26: 1 | P26: 2 | Q26: 3 | R26: 2 | S26: 3 | T26: 2 | U26: 4 | V26: 5 | W26: 9 | X26: 3 | Y26: 4 | Z26: 3 | AA26: 5 | AB26: 3 | AC26: 3 | AD26: 5 | AE26: 3 | AG26: =SUM(A26:AE26) -> 73 | AI26: 83 | AJ26: :VOD | AK26: 0 | AL26: =AE26 -> 3 | AN26: =AG26 -> 73 | AP26: =AN26+AI26 -> 156 | AT26: 83 | AU26: 81 | AV26: =AD26 -> 5 | BA26: 60SICR8 | BB26: 0 | BC26: =BD26+BB26 -> 0 | BD26: 0
A27: 1 | B27: 0 | C27: 0 | D27: 0 | E27: 0 | F27: 0 | G27: 2 | H27: 0 | I27: 0 | J27: 2 | K27: 0 | L27: 0 | M27: 1 | N27: 1 | O27: 0 | P27: 1 | Q27: 2 | R27: 0 | S27: 1 | T27: 0 | U27: 2 | V27: 2 | W27: 3 | X27: 2 | Y27: 1 | Z27: 1 | AA27: 4 | AB27: 3 | AC27: 2 | AD27: 2 | AE27: 3 | AF27: =MAX(A27:AE27) -> 4 | AG27: =SUM(A27:AE27) -> 36 | AH27: 0 | AI27: 62 | AJ27: LF -2 | AK27: 0 | AL27: =AE27 -> 3 | AN27: =AG27 -> 36 | AP27: =AN27+AI27 -> 98 | AT27: 62 | AU27: 64 | AV27: =AD27 -> 2 | BA27: 45X1 | BB27: 0 | BC27: =BD27+BB27 -> 11 | BD27: 11
A28: 3 | B28: 7 | C28: 6 | D28: 6 | E28: 5 | F28: 6 | G28: 4 | H28: 4 | I28: 6 | J28: 4 | K28: 4 | L28: 5 | M28: 5 | N28: 5 | O28: 2 | P28: 4 | Q28: 3 | R28: 5 | S28: 3 | T28: 5 | U28: 2 | V28: 2 | W28: 4 | X28: 5 | Y28: 5 | Z28: 3 | AA28: 5 | AB28: 2 | AC28: 5 | AD28: 6 | AE28: 6 | AF28: =MAX(B28:AE28) -> 7 | AG28: =SUM(A28:AE28) -> 137 | AH28: =717-467 -> 250 | AI28: 106 | AJ28: :LF | AK28: 0 | AL28: =AE28 -> 6 | AN28: =AG28 -> 137 | AP28: =AN28+AI28 -> 243 | AT28: 106 | AU28: 132 | AV28: =AD28 -> 6 | BA28: WAP1/95 | BB28: 7 | BC28: =BD28+BB28 -> 138 | BD28: 131
A29: =A22 -> 1 | B29: =B22 -> 0 | C29: =C22 -> 0 | D29: =D22 -> 0 | E29: =E22 -> 0 | F29: 2 | G29: =G22 -> 1 | H29: =H22 -> 1 | I29: =I22 -> 2 | J29: =J22 -> 1 | K29: =K22 -> 1 | L29: =L22 -> 2 | M29: =M22 -> 1 | N29: =N22 -> 1 | ... AE29: =AE22 -> 2 | AF29: =MAX(B29:AE29) -> 2 | AG29: =SUM(A29:AE29) -> 38 | AH29: =326-19.6 -> 306.4 | AI29: 39 | AJ29: :AOD - TOTAL | AK29: 0 | AL29: =AE29 -> 2 | AN29: =AG29 -> 38 | AP29: 69 | AT29: 39 | AU29: 62 | AV29: =AD29 -> 2 | BA29: OTHER | BB29: 1 | BC29: 15 | BD29: 15 | BE29: =SUM(BC18:BC28) -> 178 | BH29: =+BH21 -> 31 | BI29: =BI21 -> 1 | BJ29: 30 | BK29: =BJ29+BI29 -> 31
A30: 0 | B30: 0 | C30: 0 | D30: 0 | E30: 0 | F30: 2 | G30: 0 | H30: 0 | I30: 0 | J30: 0 | K30: 0 | L30: 0 | M30: 0 | N30: 0 | O30: 0 | P30: 0 | Q30: 0 | R30: 0 | S30: 0 | T30: 0 | U30: 0 | V30: 0 | W30: 0 | X30: 0 | Y30: 0 | Z30: 0 | AA30: 0 | AB30: 0 | AC30: 0 | AD30: 0 | AE30: 0 | AF30: =MAX(A30:AE30) -> 2 | AG30: =SUM(A30:AE30) -> 2 | AH30: =+AH33-AG32 -> 4063.8 | AI30: 0 | AJ30: :AOD - SS | AK30: 1 | AL30: =AE30 -> 0 | AN30: =AG30 -> 2 | AP30: =AN30+AI30 -> 2 | AT30: 0 | AU30: 1 | AV30: =AD30 -> 0 | BA30: TOT ING HTS | BB30: =SUM(BB18:BB29) -> 8 | BC30: =BD30+BB30 -> 204 | BD30: 196
A31: 500.186 | B31: 488.606 | C31: 260.5 | D31: 457.4 | E31: 526.862 | F31: 458.106 | G31: 300 | H31: 460.106 | I31: 602.671 | J31: 244.606 | K31: 462.356 | L31: 452 | M31: 476.562 | N31: 266.65 | O31: 502.312 | P31: 463.018 | Q31: 192.1 | R31: 503.724 | S31: 376.856 | T31: 342.373 | U31: 229.7 | V31: 457.37 | W31: 214.515 | X31: 179.6 | Y31: 528.85 | Z31: 569.31 | AA31: 471.512 | AB31: 300.606 | AC31: 440.991 | AD31: 652.98 | AE31: 361.281 | AF31: =MAX(A31:AE31) -> 652.98 | AG31: =SUM(A31:AE31) -> 12743.709 | AH31: =4413.8+1820.6 -> 6234.4 | AI31: 12805.69 | AJ31: BBM:CH | AK31: =AQ31/BH31*BI31 -> 230.69811 | AL31: =AE31 -> 361.281 | AM31: =SUM(AQ31/BH31*BK31) -> 12227 | AN31: =AG31 -> 12743.709 | AO31: =+AN31/AM31*100 -> 104.22597 | AP31: =AI31+AN31 -> 25549.399 | AQ31: 12227 | AR31: =AN31*BH31/BK31 -> 12743.709 | AS31: =SUM(AR31*100/AQ31) -> 104.22597 | AT31: 12805.69 | AU31: 12737.398 | AV31: =AD31 -> 652.98 | AW31: 15538 | AX31: AUG'09 | AY31: 154538 | AZ31: 88-89 | BA31: TOTAL HTS | BB31: =BB30+BB17 -> 8 | BC31: =+BC30+BC17 -> 215 | BD31: 207 | BE31: =SUM(BD12:BD29) -> 207 | BG31: =BH31-BK31 -> 0 | BH31: 26.5 | BI31: =+BI4 -> 0.5 | BJ31: 26 | BK31: =BJ31+BI31 -> 26.5
A32: 175 | B32: 138 | C32: 70 | D32: 123 | E32: 153 | F32: 128 | G32: 80 | H32: 128 | I32: 177 | J32: 81 | K32: 172 | L32: 164 | M32: 136 | N32: 70 | O32: 146 | P32: 142 | Q32: 50 | R32: 162 | S32: 127 | T32: 115 | U32: 68 | V32: 163 | W32: 76 | X32: 56 | Y32: 169 | Z32: 175 | AA32: 136 | AB32: 88 | AC32: 136 | AD32: 190 | AE32: 113 | AF32: =MAX(A32:AE32) -> 190 | AG32: =SUM(A32:AE32) -> 3907 | AH32: 7531.7 | AI32: 4003 | AJ32: :PCS | AL32: =AE32 -> 113 | AN32: =AG32 -> 3907 | AP32: =AI32+AN32 -> 7910 | AT32: 4003 | AU32: 3727 | AV32: =AD32 -> 190
A33: 0 | B33: 437 | C33: 0 | D33: 435 | E33: 383 | F33: 600 | G33: 680 | H33: =3021.4-2535 -> 486.4 | I33: 425 | J33: 0 | K33: =4825.3-4274.4 -> 550.9 | L33: 413 | M33: 415 | N33: 368 | O33: 393 | P33: 434 | Q33: 0 | R33: 416 | S33: 375 | T33: 261 | U33: 318 | V33: 0 | W33: 334 | X33: =10289.4-9202.3 -> 1087.1 | Y33: 355 | Z33: 363 | AA33: 418 | AB33: 342 | AC33: 475 | AD33: 465 | AE33: 454 | AF33: =MAX(A33:AE33) -> 1087.1 | AG33: =SUM(A33:AE33) -> 11683.4 | AH33: 7970.8 | AI33: 10724.6 | AJ33: CON:DIR | AK33: 259 | AL33: =AE33 -> 454 | AN33: =AG33 -> 11683.4 | AP33: =AI33+AN33 -> 22408 | AT33: 10724.6 | AU33: 11072.8 | AV33: =AD33 -> 465 | BA33: RWF RELEASE | BN33: =10539/18*26.5 -> 15515.75
A34: 429.021 | B34: 425.659 | C34: 226.596 | D34: 395.48 | E34: 470.151 | F34: 403.266 | G34: 259.519 | H34: 323.007 | I34: 494.632 | J34: 209.922 | K34: 415.953 | L34: 402.943 | M34: 423.764 | N34: 229.946 | O34: 442.159 | P34: 414.819 | Q34: 165.508 | R34: 448.079 | S34: 337.183 | T34: 308.384 | U34: 193.175 | V34: 363.066 | W34: 191 | X34: 159.678 | Y34: 469.112 | Z34: 504.839 | AA34: 417.482 | AB34: 266.083 | AC34: 321.912 | AD34: 532.831 | AE34: 321.489 | AF34: =MAX(A34:AE34) -> 532.831 | AG34: =SUM(A34:AE34) -> 10966.658 | AH34: =AG35+AG36 -> 315 | AI34: 11198.83 | AJ34: FIN:BBM | AK34: =AQ34/BH34*BI34 -> 197.79245 | AL34: =AE34 -> 321.489 | AM34: =SUM(AQ34/BH34*BK34) -> 10483 | AN34: =AG34 -> 10966.658 | AO34: =+AN34/AM34*100 -> 104.61374 | AP34: =AI34+AN34 -> 22165.488 | AQ34: 10483 | AR34: =AN34*BH34/BK34 -> 10966.658 | AS34: =SUM(AR34*100/AQ34) -> 104.61374 | AT34: 11198.83 | AU34: 10869.644 | AV34: =AD34 -> 532.831 | AW34: 12883 | AX34: AUG'09 | AY34: 119996 | AZ34: 07-08 | BB34: 0 | BC34: =+BD34+BB34 -> 0 | BD34: 0 | BG34: =BH34-BK34 -> 0 | BH34: =+BH31 -> 26.5 | BI34: =BI31 -> 0.5 | BJ34: 26 | BK34: =BJ34+BI34 -> 26.5
A35: 16 | B35: 18.8 | C35: 0 | D35: 18.8 | E35: 16 | F35: 24 | G35: 5.575 | H35: 5.225 | I35: 0 | J35: 0 | K35: 0 | L35: 0 | M35: 0 | N35: 9.03 | O35: 0 | P35: 0 | Q35: 19.79 | R35: 0 | S35: 0 | T35: 0 | U35: 0 | V35: 0 | W35: 18.8 | X35: 0 | Y35: 19.2 | Z35: 19.8 | AA35: 20.4 | AB35: 20.4 | AC35: 19.2 | AD35: 19.8 | AE35: 0 | AF35: =MAX(A35:AE35) -> 24 | AG35: =SUM(A35:AE35) -> 270.82 | AH35: =458.55-455.09 -> 3.46 | AI35: 296.79 | AJ35: :PRESS | AK35: =AQ35/BH35*BI35 -> 15.384615 | AL35: =AE35 -> 0 | AM35: =SUM(AQ35/BH35*BK35) -> 400 | AN35: =AG35 -> 270.82 | AO35: =+AN35/AM35*100 -> 67.705 | AP35: =AI35+AN35 -> 567.61 | AQ35: 400 | AR35: =AN35*BH35/BK35 -> 270.82 | AS35: =SUM(AR35*100/AQ35) -> 67.705 | AT35: 296.79 | AU35: 332.819 | AV35: =AD35 -> 19.8 | BA35: WAP1/95/EA | BB35: 222.22 | BC35: =BB35+BD35 -> 5161.1 | BD35: 4938.88 | BH35: 26 | BI35: 1 | BJ35: 25 | BK35: =BJ35+BI35 -> 26 | BM35: =BL35+BK35 -> 26
A36: 8.75 | B36: 5.94 | C36: 0 | D36: 0 | E36: 0 | F36: 0 | G36: 0 | H36: 0 | I36: 0 | J36: 0 | K36: 9.81 | L36: 8.258 | M36: 0 | N36: 0 | O36: 5.432 | P36: 5.99 | Q36: 0 | R36: 0 | S36: 0 | T36: 0 | U36: 0 | V36: 0 | W36: 0 | X36: 0 | Y36: 0 | Z36: 0 | AA36: 0 | AB36: 0 | AC36: 0 | AD36: 0 | AE36: 0 | AF36: =MAX(A36:AE36) -> 9.81 | AG36: =SUM(A36:AE36) -> 44.18 | AH36: =+AG35+AG36 -> 315 | AI36: 34.72 | AJ36: : 5 T HAMMER | AK36: =AQ36/BH36*BI36 -> 8.7307692 | AL36: =AE36 -> 0 | AM36: =SUM(AQ36/BH36*BK36) -> 227 | AN36: =AG36 -> 44.18 | AO36: =+AN36/AM36*100 -> 19.462555 | AP36: =AI36+AN36 -> 78.9 | AQ36: 227 | AR36: =AN36*BH36/BK36 -> 44.18 | AS36: =SUM(AR36*100/AQ36) -> 19.462555 | AT36: 34.72 | AU36: 44.76 | AV36: =AD36 -> 0 | AW36: 1113 | AX36: MAR'06 | AY36: 10524 | AZ36: 05-06 | BA36: 1875 XCL IV | BB36: 0 | BC36: =+BD36+BB36 -> 187.68 | BD36: 187.68 | BH36: 26 | BI36: 1 | BJ36: 25 | BK36: =BJ36+BI36 -> 26
A37: 0 | B37: 0 | C37: 0 | D37: 0 | E37: 0 | F37: 0 | G37: 0 | H37: 0 | I37: 0 | J37: 0 | K37: 0 | L37: 0 | M37: 0 | N37: 0 | O37: 0 | P37: 0 | Q37: 0 | R37: 0 | S37: 0 | T37: 0 | U37: 0 | V37: 0 | W37: 0 | X37: 0 | Y37: 0 | Z37: 0 | AA37: 0 | AB37: 0 | AC37: 0 | AD37: 0 | AE37: 0 | AF37: =MAX(A37:AE37) -> 0 | AG37: =SUM(A37:AE37) -> 0 | AH37: =+AH36+8.47 -> 323.47 | AI37: 0 | AJ37: : 2 T HAMMER | AK37: =AQ37/BH37*BI37 -> 0 | AL37: =AE37 -> 0 | AM37: =SUM(AQ37/BH37*BK37) -> 0 | AN37: =AG37 -> 0 | AP37: =AI37+AN37 -> 0 | AR37: =AN37*BH37/BK37 -> 0 | AT37: 0 | AU37: 0 | AV37: =AD37 -> 0 | BA37: EA 1N | BC37: =+BD37+BB37 -> 0 | BD37: 0 | BH37: 26 | BI37: =+BI36 -> 1 | BJ37: 25 | BK37: =BJ37+BI37 -> 26
A38: 0 | B38: 0 | C38: 0 | D38: 0 | E38: 0 | F38: 30 | G38: 0 | H38: 34 | I38: 0 | J38: 0 | K38: 0 | L38: 0 | M38: 0 | N38: 0 | O38: 44 | P38: 0 | Q38: 0 | R38: 0 | S38: 0 | T38: 0 | U38: 0 | V38: 0 | W38: 0 | X38: 0 | Y38: 32 | Z38: 0 | AA38: 32 | AB38: 0 | AC38: 0 | AD38: 0 | AE38: 0 | AF38: 0 | AG38: =SUM(A38:AE38) -> 172 | AH38: =+AH37+AH36 -> 638.47 | AI38: 94 | AJ38: :PM | AK38: =AQ38/BH38*BI38 -> 8.2307692 | AL38: =AE38 -> 0 | AM38: =SUM(AQ38/BH38*BK38) -> 214 | AN38: =AG38 -> 172 | AO38: =+AN38/AM38*100 -> 80.373832 | AP38: =AI38+AN38 -> 266 | AQ38: 214 | AR38: =AN38*BH38/BK38 -> 172 | AS38: =SUM(AR38*100/AQ38) -> 80.373832 | AT38: 94 | AU38: 160 | AV38: =AD38 -> 0 | AW38: 1534 | AX38: FEB'96 | AY38: 14564 | AZ38: 95-96 | BA38: TOTAL | BC38: =+BC37+BC36+BC35 -> 5348.78 | BD38: 5126.56 | BH38: =+BH35 -> 26 | BI38: 1 | BJ38: 25 | BK38: =BJ38+BI38 -> 26 | BM38: =BL38+BK38 -> 26
A39: =A55 -> 0 | B39: =B55 -> 0 | C39: =C55 -> 0 | D39: =D55 -> 0 | E39: =E55 -> 52.65 | F39: =F55 -> 0 | G39: =G55 -> 0 | H39: =H55 -> 52.65 | ... AE39: =AE55 -> 0 | AF39: =MAX(A39:AE39) -> 52.65 | AG39: =SUM(A39:AE39) -> 105.3 | AH39: 28.3 | AI39: 76.95 | AJ39: :ING | AK39: =AQ39/BH39*BI39 -> 9.6774194 | AL39: =AE39 -> 0 | AM39: =SUM(AQ39/BH39*BK39) -> 300 | AN39: =AG39 -> 105.3 | AO39: =+AN39/AM39*100 -> 35.1 | AP39: =AI39+AN39 -> 182.25 | AQ39: 300 | AR39: =AN39*BH39/BK39 -> 105.3 | AS39: =SUM(AR39*100/AQ39) -> 35.1 | AT39: 76.95 | AU39: 100.3 | AV39: =AD39 -> 0 | AY39: 12593 | AZ39: 98-99 | BA39: R-16 DSP | BB39: 0 | BC39: =+BD39+BB39 -> 489.08 | BD39: 489.08 | BH39: =BH20 -> 31 | BI39: 1 | BJ39: 30 | BK39: =BJ39+BI39 -> 31
A40: 0 | B40: 0 | C40: 0 | D40: 0 | E40: 0 | F40: 0 | G40: 0 | H40: 0 | I40: 0 | J40: 0 | K40: 0 | L40: 0 | M40: 0 | N40: 0 | O40: 0 | P40: 0 | Q40: 0 | R40: 0 | S40: 0 | T40: 0 | U40: 0 | V40: 0 | W40: 0 | X40: 0 | Y40: 0 | Z40: 0 | AA40: 0 | AB40: 0 | AC40: 0 | AD40: 0 | AE40: 0 | AG40: =SUM(A40:AE40) -> 0 | AH40: 103.2 | AI40: 0 | AJ40: CC SLB | AK40: =AQ40/BH40*BI40 -> 19.483871 | AL40: =AE40 -> 0 | AM40: =SUM(AQ40/BH40*BK40) -> 604 | AN40: =AG40 -> 0 | AO40: =+AN40/AM40*100 -> 0 | AP40: =AI40+AN40 -> 0 | AQ40: 604 | AR40: =+AN40/BK40*BH40 -> 0 | AS40: =SUM(AR40*100/AQ40) -> 0 | AT40: 0 | AU40: 733.06 | AV40: =AD40 -> 0 | AW40: 12549 | AX40: MAR'94 | AY40: 111575 | AZ40: 10-11 | BA40: R-16/43 YIL | BB40: 0 | BC40: =+BD40+BB40 -> 0 | BD40: 0 | BH40: =BH20 -> 31 | BI40: 1 | BJ40: 30 | BK40: =BJ40+BI40 -> 31
...

Sheet md cell
A1: ALLOY STEELS PLANT, DURGAPUR | J1: PRODUCTION PERFORMANCE: 2026-27
A2: PRODUCTION PLANNING & CONTROL DEPARTMENT | J2: ITEM | K2: ABP | L2: ACTUAL | M2: RATE | N2: % ABP
A3: =CONCATENATE("DAILY PERFORMANCE SUMMARY REPORT FOR") -> DAILY PERFORMANCE SUMMARY REPORT FOR | E3: 31/05/2026 | J3: CRUDE | K3: ='DAILY FLASH'!AZ2 -> 150797 | L3: ='DAILY FLASH'!BA2 -> 21246.991 | M3: ='DAILY FLASH'!BB2 -> 127133.63 | N3: ='DAILY FLASH'!BC2 -> 84.307801
J4: SAL. ST. | K4: ='DAILY FLASH'!AZ3 -> 146285 | L4: ='DAILY FLASH'!BA3 -> 22620.088 | M4: ='DAILY FLASH'!BB3 -> 133159.76 | N4: ='DAILY FLASH'!BC3 -> 91.027626 | AL4: 03.09.2020 | BI4: 0
A5: PARAMETERS | B5: UNIT | C5: ON DATE | E5: MONTHLY | J5: DESP | K5: ='DAILY FLASH'!AZ5 -> 148285 | L5: ='DAILY FLASH'!BA5 -> 23199.71 | M5: ='DAILY FLASH'!BB5 -> 136571.88 | N5: ='DAILY FLASH'!BC5 -> 92.100939
C7: ABP | D7: ON DT | E7: ABP | F7: CUMM | G7: RATE | H7: %FUL | I7: ='MIS MONTH WISE FUEL NMGCAL '!I14 -> CPLY | J7: Major Delays & Shut Downs
A8: TOTAL HEATS (EAF+H/M) | B8: NO. | C8: ='DAILY FLASH'!AK21 -> 8 | D8: ='DAILY FLASH'!AL21 -> 8 | E8: ='DAILY FLASH'!AQ21 -> 230 | F8: ='DAILY FLASH'!AN21 -> 215 | G8: ='DAILY FLASH'!AR21 -> 215 | H8: =G8/E8% -> 93.478261 | I8: ='DAILY FLASH'!AU21 -> 217 | J8: EQPT. | K8: From | L8: To | M8: Duration | N8: Agency | O8: Reasons
A9: LIQUID | B9: T | C9: ='DAILY FLASH'!AK12 -> 385.80645 | D9: ='DAILY FLASH'!AL12 -> 585 | E9: ='DAILY FLASH'!AQ12 -> 11960 | F9: ='DAILY FLASH'!AN12 -> 11200.83 | G9: ='DAILY FLASH'!AR12 -> 11200.83 | H9: ='DAILY FLASH'!AS12 -> 93.652425 | I9: ='DAILY FLASH'!AU12 -> 11206.97 | J9: CR#6 | K9: 12:15 HRS | L9: 13:15 HRS | M9: 1 HR | N9: CR. MAINT. | O9: AUXILIARY HOIST UP-DOWN PROBLEM, RECTIFIED.
A10: CRUDE | B10: T | C10: ='DAILY FLASH'!AK14 -> 355 | D10: ='DAILY FLASH'!AL20 -> 565.15 | E10: ='DAILY FLASH'!AQ20 -> 11612 | F10: ='DAILY FLASH'!AN20 -> 10759.191 | G10: ='DAILY FLASH'!AR20 -> 10759.191 | H10: ='DAILY FLASH'!AS20 -> 92.655796 | I10: ='DAILY FLASH'!AU20 -> 10785.66 | J10: CR#93 | K10: 13:00 HRS | L10: 20:40 HRS | M10: 7 HRS 40 MIN. | N10: CR. MAINT. | O10: BEARING DAMAGED, RECTIFIED.
A11: TOTAL CC | B11: T | C11: =C9 -> 385.80645 | D11: ='DAILY FLASH'!AL16 -> 0 | E11: ='DAILY FLASH'!AQ16 -> 607 | F11: ='DAILY FLASH'!AN16 -> 399.471 | G11: ='DAILY FLASH'!AR16 -> 399.471 | H11: =G11/E11% -> 65.810708 | I11: ='DAILY FLASH'!AU16 -> 733.06 | J11: VOD | K11: 18:45 HRS | L11: 19:45 HRS | M11: 1 HR | N11: SMS OPERATION | O11: ROOF CHANGED.
A12: INGOT PRODUCTION | B12: T | C12: ='MIS MONTH WISE FUEL NMGCAL '!C18 -> 355 | D12: ='DAILY FLASH'!AL14 -> 565.15 | E12: ='DAILY FLASH'!AQ14 -> 11005 | F12: ='DAILY FLASH'!AN14 -> 10359.72 | G12: ='DAILY FLASH'!AR14 -> 10359.72 | H12: =G12/E12% -> 94.136483 | I12: ='DAILY FLASH'!AU14 -> 10052.6 | J12: CR#5 | K12: 17:10 HRS | L12: 20 HRS | M12: 2 HRS 50 MIN | N12: CR. MAINT. | O12: A.C . DOWN, RECTIFIED.
A13: HOT METAL ROUTE HEATS | B13: NO. | C13: ='MIS MONTH WISE FUEL NMGCAL '!C27 -> 0.99255583 | D13: ='DAILY FLASH'!AL22 -> 2 | F13: ='DAILY FLASH'!AN22 -> 36 | I13: ='DAILY FLASH'!AU22 -> 63 | J13: CURRENT SAL. STOCK -PLANT(T) | O13: PREV DT | P13: CUMM
A14: TOTAL AOD ROUTE HEATS | B14: NO. | C14: ='MIS MONTH WISE FUEL NMGCAL '!C28 -> 0.99255583 | D14: ='DAILY FLASH'!AL29 -> 2 | F14: ='DAILY FLASH'!AN29 -> 38 | I14: ='DAILY FLASH'!AU29 -> 62 | J14: BILLET | L14: ='SAL STOCK'!G6 -> 14889.63 | N14: ABP | O14: ='DAILY FLASH'!P111 -> 2124 | P14: ='DAILY FLASH'!V111 -> 1577 | BB14: 1
A15: STN. STEEL HEATS | B15: NO. | C15: 0 | D15: ='DAILY FLASH'!AL30 -> 0 | F15: ='DAILY FLASH'!AN30 -> 2 | I15: ='DAILY FLASH'!AU30 -> 1 | L15: ='SAL STOCK'!G7 -> 383.137 | M15: DSP COG NM^3/HR | N15: 2500 | O15: ='DAILY FLASH'!P112 -> 2069 | P15: ='DAILY FLASH'!V112 -> 2060 | AD15: Item | AE15: ABP | AF15: Actual | AG15: % | AH15: CPLY(T) | AY15: =708-809 -> -101
A16: NON-STN.STEEL HEATS | B16: NO. | C16: =C8-C15 -> 8 | D16: =D8-D15 -> 8 | F16: =F8-F15 -> 213 | I16: =I8-I15 -> 216 | J16: FORGE | L16: ='SAL STOCK'!G8 -> 1957.769 | N16: 2068 | AE16: (T) | AF16: (T) | AG16: Ach | AH16: (T)
A17: BBM CHARGE WEIGHT | B17: T | C17: ='DAILY FLASH'!AK31 -> 230.69811 | D17: ='DAILY FLASH'!AL31 -> 361.281 | E17: ='DAILY FLASH'!AQ31 -> 12227 | F17: ='DAILY FLASH'!AN31 -> 12743.709 | G17: ='DAILY FLASH'!AR31 -> 12743.709 | H17: =G17/E17% -> 104.22597 | I17: ='DAILY FLASH'!AU31 -> 12737.398 | J17: PLATE | L17: ='SAL STOCK'!G9 -> 1239.4365 | M17: EQUIP. | N17: HEAT PROCESSED | O17: POSITION | AD17: Crude Steel | AE17: 6247 | AF17: 8284 | AG17: =+AF17/AE17*100 -> 132.60765 | AH17: 7122
A18: BBM FINISHING | B18: T | C18: ='DAILY FLASH'!AK34 -> 197.79245 | D18: ='DAILY FLASH'!AL34 -> 321.489 | E18: ='DAILY FLASH'!AQ34 -> 10483 | F18: ='DAILY FLASH'!AN34 -> 10966.658 | G18: ='DAILY FLASH'!AR34 -> 10966.658 | H18: =G18/E18% -> 104.61374 | I18: ='DAILY FLASH'!AU34 -> 10869.644 | J18: INGOT | L18: ='SAL STOCK'!G10 -> 410.103 | M18: EAF#2 | N18: ='DAILY FLASH'!AL82 -> 0 | O18: OK | AD18: Concast Slab | AE18: 460 | AH18: 524
A19: FORGE SHOP FINISHING | B19: T | C19: ='DAILY FLASH'!AK35+'DAILY FLASH'!AK36 -> 24.115385 | D19: ='DAILY FLASH'!AL35+'DAILY FLASH'!AL36+'DAILY FLASH'!AL37 -> 0 | E19: =SUM('DAILY FLASH'!AQ35:AQ36) -> 627 | F19: ='DAILY FLASH'!AN35+'DAILY FLASH'!AN36+'DAILY FLASH'!AN37 -> 315 | G19: ='DAILY FLASH'!AR35+'DAILY FLASH'!AR36+'DAILY FLASH'!AR37 -> 315 | H19: =G19/E19% -> 50.239234 | I19: ='DAILY FLASH'!AU35+'DAILY FLASH'!AU36 -> 377.579 | J19: CC BLOOM | L19: ='SAL STOCK'!G11 -> 125.23 | M19: EAF#3 | N19: ='DAILY FLASH'!AL83 -> 6 | O19: OK | AD19: Concast Bloom | AE19: 237 | AH19: 617
A20: SALEABLE STEEL | B20: T | C20: ='DAILY FLASH'!AK56 -> 420 | D20: ='DAILY FLASH'!AL56 -> 459.245 | E20: ='DAILY FLASH'!AQ56 -> 11340 | F20: ='DAILY FLASH'!AN56 -> 11402.187 | G20: ='DAILY FLASH'!AR56 -> 11402.187 | H20: =G20/E20% -> 100.54839 | I20: ='DAILY FLASH'!AU56 -> 10884.684 | J20: CC SLAB | L20: ='SAL STOCK'!G10 -> 410.103 | M20: CCS | O20: OK | AD20: Total CC | AE20: 697 | AH20: 1141
A21: PLANT DESPATCH | B21: T | C21: ='DAILY FLASH'!AK58 -> 425.55556 | D21: ='DAILY FLASH'!AL58 -> 403.18 | E21: =+'DAILY FLASH'!AQ58 -> 11490 | F21: ='DAILY FLASH'!AN58 -> 11173.28 | G21: ='DAILY FLASH'!AR58 -> 11173.28 | H21: =G21/E21% -> 97.243516 | I21: ='DAILY FLASH'!AU58 -> 10643.65 | J21: FRG SLAB | L21: ='SAL STOCK'!G12 -> 232.627 | M21: LF1 | O21: OK | AD21: Ingot Steel | AE21: 5550 | AF21: 8284 | AG21: =+AF21/AE21*100 -> 149.26126 | AH21: 5981
A22: DSP SPL. STEEL INGOTS | B22: T | C22: ='DAILY FLASH'!AK72 -> 12.903226 | D22: ='DAILY FLASH'!AL72 -> 0 | E22: ='DAILY FLASH'!AQ72 -> 400 | F22: ='DAILY FLASH'!AN72 -> 187.2 | G22: ='DAILY FLASH'!AR72 -> 187.2 | H22: =G22/E22% -> 46.8 | I22: ='DAILY FLASH'!AU72 -> 904.8 | J22: OTHER INGOT | L22: ='SAL STOCK'!G17+'SAL STOCK'!G16 -> 840.66 | M22: LF2 | O22: OK | AD22: BBM Charge Weight | AE22: 9700 | AF22: 10919 | AG22: =+AF22/AE22*100 -> 112.56701 | AH22: 8671 | BB22: 1
A23: DSP HOT METAL ( MT) | B23: T | C23: ='DAILY FLASH'!AK73 -> 64.516129 | D23: ='MIS MONTH WISE FUEL NMGCAL '!D42 -> 138.7 | E23: ='MIS MONTH WISE FUEL NMGCAL '!F42 -> 2000 | F23: ='DAILY FLASH'!AN73 -> 2508.64 | G23: ='DAILY FLASH'!AR73 -> 2508.64 | H23: =G23/E23% -> 125.432 | I23: ='DAILY FLASH'!AU73 -> 4309.99 | J23: ='MIS MONTH WISE FUEL NMGCAL '!M50 -> STN SLAB | L23: 0 | M23: AOD/HOT METAL | N23: =D13 -> 2 | O23: OK | AD23: Total Saleable | AE23: 9245 | AF23: 9426 | AG23: =+AF23/AE23*100 -> 101.95782 | AH23: 8110
J24: STN SLAB | L24: ='SAL STOCK'!G15 -> 0 | M24: VAD | O24: OK | AD24: Dispatch | AE24: 9395 | AF24: 9226 | AG24: =+AF24/AE24*100 -> 98.201171 | AH24: 7653
J25: TOTAL PLANT ST. | L25: =SUM(L14:L24) -> 20488.695 | M25: VOD | O25: OK | AA25: =3221+80 -> 3301 | AD25: Special Steel Ingots – DSP | AE25: 2000 | AF25: 1544 | AG25: =+AF25/AE25*100 -> 77.2 | AH25: 917 | AX25: =11385-304 -> 11081
A26: MAJOR TECHNO ECONOMIC PARAMETERS | J26: STOCKYARD | L26: 200 | AD26: DSP Hot Metal | AE26: 2500 | AF26: 2652 | AG26: =+AF26/AE26*100 -> 106.08 | AH26: 1230 | BB26: 0
A27: AREA | B27: KEY TE PARAMETERS | E27: NORM | F27: UNIT | G27: ON DT | H27: CUM. | I27: =I7 -> CPLY | J27: 25-26PRODUCITON (T) | M27: ALL TIME BEST PRODUCTION (T)
A28: SMS | B28: POWER ON TO TAP TIME | E28: ='MIS MONTH WISE FUEL NMGCAL '!E59 -> 3.5 | F28: HR | G28: ='DAILY FLASH'!AL101 -> 3.8333333 | H28: ='DAILY FLASH'!AF99 -> 3.2807263 | I28: 3.4301948 | K28: ABP25-26 | L28: ACTUAL | M28: FOR A MONTH | N28: MONTH | O28: YEARLY | P28: YEAR | AD28: Item | AE28: ABP | AF28: Actual | AG28: % | AH28: CPLY(T)
B29: HEAT SIZE | E29: 52 | F29: T | G29: ='DAILY FLASH'!AL12/'DAILY FLASH'!AL23 -> 53.181818 | H29: ='DAILY FLASH'!AN12/'DAILY FLASH'!AN23 -> 52.096884 | I29: 51.645023 | J29: TOT CRUDE | K29: 137676 | L29: 125918 | M29: ='DAILY FLASH'!AW20 -> 24735 | N29: ='DAILY FLASH'!AX20 -> MAR'97 | O29: ='DAILY FLASH'!AY20 -> 248175 | P29: ='DAILY FLASH'!AZ20 -> 96-97 | AE29: (T) | AF29: (T) | AG29: Ach | AH29: (T) | AK29: 0.40972222 | AL29: 0.024305556 | AM29: =+AL29-AK29+24 -> 23.614583
B30: POWER CONS. | E30: 650 | F30: KWH/T | G30: 643 | H30: 747 | I30: 717 | J30: INGOT | K30: 133424 | L30: 119330 | M30: ='DAILY FLASH'!AW14 -> 15089 | N30: ='DAILY FLASH'!AX14 -> MAR'89 | O30: ='DAILY FLASH'!AY14 -> 151556 | P30: ='DAILY FLASH'!AZ14 -> 88-89 | AD30: Crude Steel | AE30: 61374 | AF30: 77413 | AG30: =+AF30/AE30*100 -> 126.13322 | AH30: 43743
B31: FUEL CONS | E31: 0.355 | F31: ='MIS MONTH WISE FUEL NMGCAL '!F64 -> GCAL/TON | G31: 0.266 | H31: 0.398 | I31: 0.569 | J31: CC PDN | K31: =+K29-K30 -> 4252 | L31: =+L29-L30 -> 6588 | M31: ='DAILY FLASH'!AW19 -> 8488 | N31: ='DAILY FLASH'!AX19 -> NOV'09 | O31: ='DAILY FLASH'!AY16 -> 112288 | P31: ='DAILY FLASH'!AZ16 -> 10-11 | AD31: Concast Slab | AE31: 4190 | AF31: 1343 | AG31: =+AF31/AE31*100 -> 32.052506 | AH31: 2438 | AS31: =8.33*8.04 -> 66.9732
B32: ELECTRODE CONS. | E32: 5.52 | F32: KG/T | G32: 5.37 | H32: 5.17 | I32: 5.61 | J32: SALEABLE | K32: 139825 | L32: 119127.06 | M32: 19652 | N32: AUG'10 | O32: 202913 | P32: ='MIS MONTH WISE FUEL NMGCAL '!J55 -> 10-11 | AD32: Concast Bloom | AE32: 2010 | AF32: 6043 | AG32: =+AF32/AE32*100 -> 300.64677 | AH32: 5466 | AS32: =+AS31/104.2 -> 0.64273704
B33: YLD: LIQUID TO INGOT | E33: 96.64 | F33: % | G33: 96.66 | H33: 96.45 | I33: 96.18 | J33: DESPATCH | K33: 141825 | L33: 112369 | M33: ='DAILY FLASH'!AW58 -> 20107 | N33: ='DAILY FLASH'!AX58 -> AUG'09 | O33: 200528 | P33: ='MIS MONTH WISE FUEL NMGCAL '!J56 -> 10-11 | AD33: Total CC | AE33: 6200 | AF33: 7386 | AG33: =+AF33/AE33*100 -> 119.12903 | AH33: 7904
B34: AOD FUEL CONS.(Prevous day) | E34: 0.32 | F34: GCAL/TON | G34: ='DAILY FLASH'!M111 -> 0.31674667 | H34: 0.456 | I34: 0.448 | J34: BBM CH WT | K34: 155974 | L34: 143751.71 | M34: 15338 | N34: AUG'09 | O34: ='DAILY FLASH'!AY31 -> 154538 | P34: 88-89
A35: CCS | B35: YIELD | E35: 97.2 | F35: % | G35: N/C | H35: 97.13 | I35: 97.18 | J35: GRADE | K35: RECPT (T) | L35: ROLL.(T) | M35: REL. (T) | N35: DESP.(T) | O35: SAL STOCK | AD35: Ingot Steel | AE35: 55174 | AF35: 70027 | AG35: =+AF35/AE35*100 -> 126.92029 | AH35: 35839
J36: MONTHLY STATUS OF BRC BLOOM | AD36: BBM Charge weight | AE36: 94500 | AF36: 92934 | AG36: =+AF36/AE36*100 -> 98.342857 | AH36: 53335
A37: BBM | B37: POWER CONS. | E37: 93 | F37: KWH/T | G37: =L79 -> 91.527094 | H37: =M79 -> 96.2625 | I37: 95.155631 | J37: 45C8 | K37: 0 | L37: =724.302 -> 724.302 | M37: ='DAILY FLASH'!AN53 -> 694.91 | N37: ='DAILY FLASH'!BC77 -> 356.69 | O37: =205.56+0.98+M37-N37 -> 544.76 | AD37: Total Saleable | AE37: 90479 | AF37: 90133 | AG37: =+AF37/AE37*100 -> 99.617591 | AH37: 52700
B38: ='MIS MONTH WISE FUEL NMGCAL '!B70 -> FUEL CONS | E38: ='MIS MONTH WISE FUEL NMGCAL '!E70 -> 0.44 | F38: ='MIS MONTH WISE FUEL NMGCAL '!F70 -> GCAL/TON | G38: 0.66 | H38: 0.505 | I38: 0.477 | J38: CL II/C-20/R16 | K38: =27*8+24*8+26*2.563 -> 474.638 | L38: =216 -> 216 | M38: =167.22+2.75+8.4 -> 178.37 | N38: =203.1+57.74 -> 260.84 | U38: =28*7.1 -> 198.8 | AD38: Dispatch | AE38: 92129 | AF38: 90091 | AG38: =+AF38/AE38*100 -> 97.787884 | AH38: 56130
B39: YIELD | E39: 88.5 | F39: % | G39: =L76 -> 88.985859 | H39: =M76 -> 88.670156 | I39: 88.540919 | J39: AISI 1018 | K39: 0 | L39: 0 | M39: 0 | N39: =224.13 -> 224.13 | AD39: Special Steel Ingots – DSP | AE39: 20000 | AF39: 8618 | AG39: =+AF39/AE39*100 -> 43.09 | AH39: 7640
T40: =621.51-615.65 -> 5.86 | V40: =409.99-414.13 -> -4.14 | AD40: DSP Hot Metal | AE40: 25000 | AF40: 23701 | AG40: =+AF40/AE40*100 -> 94.804 | AH40: 19654
A41: LOCATION | B41: 01-04-26 | C41: 01-05-26 | D41: 01-06-26 | O41: 26-27 | W41: =307+M35-N35 -> #VALUE! | AE41: 94500 | AF41: 92753 | AG41: =+AF41/AE41*100 -> 98.151323
...

Sheet Seg wise Saleable & desp 24-25
B2: saleable24-25
B3: product | C3: APRIL'24 | D3: MAY'24 | E3: JUNE'24 | F3: JULY'24 | G3: AUG'24 | H3: SEPT'24 | I3: OCT'24 | J3: NOV'24 | K3: DEC'24 | L3: JAN'25 | M3: FEB'25 | N3: MARCH'25 | O3: 24-25
B4: RWF | C4: 3624 | D4: 2505 | E4: 4029 | F4: 3626 | G4: 4203 | H4: 3705 | I4: 3792 | J4: 3406 | K4: 3873 | L4: 4883 | M4: 5524 | N4: 5517 | O4: =SUM(C4:N4) -> 48687
B5: DEFENCE | C5: 1513 | D5: 501 | E5: 1771 | F5: 1437 | G5: 1452 | H5: 1477 | I5: 2129 | J5: 2119 | K5: 1913 | L5: 2089 | M5: 1626 | N5: 1756 | O5: =SUM(C5:N5) -> 19783
B6: PSU | C6: 41 | D6: 299 | E6: 0 | F6: 40 | G6: 117 | H6: 91 | I6: 113 | J6: 149 | K6: 125 | L6: 123 | M6: 24 | N6: 66 | O6: =SUM(C6:N6) -> 1188
B7: IPT | C7: 68 | D7: 217 | E7: 418 | F7: 354 | G7: 363 | H7: 257 | I7: 275 | J7: 479 | K7: 538 | L7: 649 | M7: 492 | N7: 609 | O7: =SUM(C7:N7) -> 4719
B8: BD/FRG | C8: 226 | D8: 181 | E8: 158 | F8: 228 | G8: 158 | H8: 184 | I8: 185 | J8: 330 | K8: 233 | L8: 390 | M8: 307 | N8: 145 | O8: =SUM(C8:N8) -> 2725
B9: BRC | C9: 739 | D9: 739 | E9: 288 | F9: 609 | G9: 926 | H9: 773 | I9: 1608 | J9: 544 | K9: 568 | L9: 49 | N9: 329 | O9: =SUM(C9:N9) -> 7172
B10: SPADE M1 | C10: 416 | D10: 349 | E10: 350 | F10: 348 | G10: 395 | H10: 357 | I10: 292 | J10: 583 | K10: 399 | L10: 233 | M10: 274 | N10: 243 | O10: =SUM(C10:N10) -> 4239
B11: SPADE M1/JKL FRG | C11: 123 | D11: 97 | E11: 139 | F11: 31 | G11: 81 | H11: 102 | I11: 41 | J11: 0 | K11: 0 | L11: 0 | M11: 0 | N11: 0 | O11: =SUM(C11:N11) -> 614
B12: PLATES(HF-MN) | C12: 42 | D12: 86 | E12: 67 | F12: 6 | G12: 0 | H12: 9 | I12: 30 | J12: 74 | K12: 77 | L12: 119 | M12: 136 | N12: 101 | O12: =SUM(C12:N12) -> 747
B13: PLATES(OTHERS) | C13: 72 | D13: 14 | E13: 4 | F13: 61 | G13: 73 | H13: 19 | I13: 7 | J13: 19 | K13: 37 | L13: 13 | M13: 9 | O13: =SUM(C13:N13) -> 328
B14: DSP INGOT-ASP | C14: 474 | D14: 216 | E14: 484 | F14: 813 | G14: 476 | H14: 254 | I14: 312 | J14: 359 | K14: 486 | L14: 484 | M14: 411 | N14: 700 | O14: =SUM(C14:N14) -> 5469
B15: NVD CCB | C15: 1394 | D15: 420 | E15: 822 | F15: 559 | G15: 706 | H15: 745 | I15: 874 | J15: 1260 | K15: 950 | L15: 993 | M15: 739 | N15: 633 | O15: =SUM(C15:N15) -> 10095
B16: EN 19/20MNCR5 | C16: 360 | D16: 221 | E16: 990 | F16: 486 | G16: 630 | H16: 196 | I16: 320 | J16: 93 | K16: 719 | L16: 486 | M16: 926 | N16: 725 | O16: =SUM(C16:N16) -> 6152
B17: PVT | C17: 911 | D17: 906 | E17: 850 | F17: 445 | G17: 449 | H17: 382 | I17: 505 | J17: 724 | K17: 527 | L17: 290 | M17: 208 | N17: 540 | O17: =SUM(C17:N17) -> 6737
B18: Grand total | C18: =SUM(C4:C17) -> 10003 | D18: =SUM(D4:D17) -> 6751 | E18: =SUM(E4:E17) -> 10370 | F18: =SUM(F4:F17) -> 9043 | G18: =SUM(G4:G17) -> 10029 | H18: =SUM(H4:H17) -> 8551 | I18: =SUM(I4:I17) -> 10483 | J18: =SUM(J4:J17) -> 10139 | ... O18: =SUM(O4:O17) -> 118655
B23: Despatch 24-25
B24: product | C24: APRIL'24 | D24: MAY'24 | E24: JUNE'24 | F24: JULY'24 | G24: AUG'24 | H24: SEPT'24 | I24: OCT'24 | J24: NOV'24 | K24: DEC'24 | L24: JAN'25 | M24: FEB'25 | N24: MARCH'25 | O24: 24-25
B25: RWF | C25: 3742 | D25: 3349 | E25: 4127 | F25: 4262 | G25: 4155 | H25: 3699 | I25: 3634 | J25: 3165 | K25: 4264 | L25: 4409 | M25: 5665 | N25: 5665 | O25: =SUM(C25:N25) -> 50136
B26: DEFENCE | C26: 1437 | D26: 630 | E26: 1766 | F26: 1298 | G26: 1545 | H26: 1553 | I26: 1852 | J26: 2173 | K26: 2040 | L26: 2008 | M26: 1622 | N26: 1797 | O26: =SUM(C26:N26) -> 19721
B27: PSU | C27: 35 | D27: 137 | E27: 126 | F27: 61 | G27: 70 | H27: 158 | I27: 30 | J27: 120 | K27: 86 | L27: 161 | M27: 30 | N27: 156 | O27: =SUM(C27:N27) -> 1170
B28: IPT | C28: 74 | D28: 285 | E28: 431 | F28: 446 | G28: 431 | H28: 260 | I28: 266 | J28: 449 | K28: 456 | L28: 723 | M28: 422 | N28: 724 | O28: =SUM(C28:N28) -> 4967
B29: BD/FRG | C29: 375 | D29: 310 | E29: 305 | F29: 324 | G29: 187 | H29: 339 | I29: 221 | J29: 412 | K29: 212 | L29: 491 | M29: 280 | N29: 331 | O29: =SUM(C29:N29) -> 3787
B30: BRC | C30: 982 | D30: 512 | E30: 288 | F30: 1020 | G30: 859 | H30: 684 | I30: 1102 | J30: 526 | K30: 480 | L30: 147 | M30: 48 | N30: 309 | O30: =SUM(C30:N30) -> 6957
B31: SPADE M1 | C31: 478 | D31: 324 | E31: 379 | F31: 318 | G31: 405 | H31: 354 | I31: 306 | J31: 514 | K31: 432 | L31: 97 | M31: 353 | N31: 328 | O31: =SUM(C31:N31) -> 4288
B32: SPADE M1/JKL FRG | C32: 124 | D32: 81 | E32: 140 | F32: 46 | G32: 57 | H32: 120 | I32: 39 | J32: 8 | O32: =SUM(C32:N32) -> 615
B33: PLATES(HF-MN) | C33: 55 | D33: 83 | E33: 15 | F33: 17 | G33: 57 | H33: 59 | I33: 94 | J33: 105 | K33: 100 | L33: 64 | M33: 58 | N33: 232 | O33: =SUM(C33:N33) -> 939
B34: PLATES(OTHERS) | C34: 18 | D34: 20 | F34: 28 | G34: 39 | H34: 24 | I34: 69 | K34: 27 | L34: 9 | N34: 97 | O34: =SUM(C34:N34) -> 331
B35: DSP INGOT-ASP | C35: 768 | D35: 796 | E35: 506 | F35: 804 | G35: 462 | H35: 480 | I35: 333 | J35: 390 | K35: 233 | L35: 555 | M35: 250 | N35: 521 | O35: =SUM(C35:N35) -> 6098
B36: NVD CCB | C36: 1332 | D36: 1130 | E36: 614 | F36: 556 | G36: 1157 | H36: 1033 | I36: 551 | J36: 681 | K36: 1079 | L36: 538 | M36: 469 | N36: 584 | O36: =SUM(C36:N36) -> 9724
B37: EN 19/20MNCR5 | C37: 659 | D37: 636 | E37: 273 | F37: 245 | G37: 406 | H37: 587 | I37: 523 | J37: 469 | K37: 753 | L37: 344 | M37: 598 | N37: 566 | O37: =SUM(C37:N37) -> 6059
B38: PVT | C38: 531 | D38: 870 | E38: 876 | F38: 659 | G38: 368 | H38: 532 | I38: 447 | J38: 603 | K38: 725 | L38: 385 | M38: 401 | N38: 600 | O38: =SUM(C38:N38) -> 6997
B39: Grand total | C39: =SUM(C25:C38) -> 10610 | D39: =SUM(D25:D38) -> 9163 | E39: =SUM(E25:E38) -> 9846 | F39: =SUM(F25:F38) -> 10084 | G39: =SUM(G25:G38) -> 10198 | H39: =SUM(H25:H38) -> 9882 | I39: =SUM(I25:I38) -> 9467 | J39: =SUM(J25:J38) -> 9615 | ... N39: =SUM(N25:N38) -> 11910 | O39: =SUM(C39:N39) -> 121789

Sheet SEGMMENT WISE SAL & DESP 26-27
B4: REL | C4: APRIL'26
B5: RWF | C5: 5362.78
B6: DEFENCE | C6: 1250
B7: PSU | C7: 0
B8: IPT | C8: =36.4+54.7+510.51+12.8+108.2 -> 722.61
B9: BD/FRG | C9: 273.35
B10: BRC | C10: 652.74
B11: SPADE M1 | C11: 556.8
B12: SPADE M1/JKL FRG | C12: 0
B13: PLATES(HF-MN) | C13: 95.672
B14: PLATES(OTHERS) | C14: =144.34-95.672 -> 48.668
B15: DSP INGOT-ASP | C15: 122
B16: NVD CCB | C16: 1363
B17: EN 19/20MNCR5 | C17: 241.25
B18: PVT | C18: 529
C19: =SUM(C5:C18) -> 11217.87
B20: DESPA
B21: RWF | C21: 6155.27
B22: DEFENCE | C22: 891
B23: PSU | C23: 35
B24: IPT | C24: 823
B25: BD/FRG | C25: 277
B26: BRC | C26: 650.35
B27: SPADE M1 | C27: 666.313
B28: SPADE M1/JKL FRG | C28: 3.64
B29: PLATES(HF-MN) | C29: 116.605
B30: PLATES(OTHERS) | C30: =195.375-116.605 -> 78.77
B31: DSP INGOT-ASP | C31: 412
B32: NVD CCB | C32: 933
B33: EN 19/20MNCR5 | C33: 416
B34: PVT | C34: 569
C35: =SUM(C21:C34) -> 12026.948
M39: 11111.5
M40: 12026.43
M41: =+M40-M39 -> 914.93

Sheet SAL STOCK
A1: INTERNAL CALCULATION OF SALEABLE STOCK
A3: PRODUCTS | B3: TILL | C3: SALEABLE | D3: CUM. DESP | H3: OP ST | Q3: SAIL/ASP | S3: FOR INTERNAL CIRCULATION
C4: ON DT. | D4: TILL DT | E4: previous DT | F4: ON DT. | G4: CL. STOCK | H4: 44028 | I4: cumm sal | J4: cummdesp | K4: 0 | P4: =+O4-N4 -> 0
A5: NON-IPT
A6: BLOOM / BILLET | B6: 7551 | C6: ='DAILY FLASH'!#REF! -> #REF! | D6: ='DAILY FLASH'!BC49 -> 9963.152 | E6: 9657.282 | F6: =D6-E6 -> 305.87 | G6: =+H6+I6-J6 -> 14889.63 | H6: 14634.422 | I6: ='DAILY FLASH'!AG44 -> 10218.36 | J6: ='DAILY FLASH'!BC49 -> 9963.152 | Q6: SHOPWISE SALEABLE STOCK AS ON 05.05.2011
A7: BAR | B7: 227 | C7: ='DAILY FLASH'!#REF! -> #REF! | D7: ='DAILY FLASH'!BC50 -> 146.06 | E7: 146.06 | F7: =D7-E7 -> 0 | G7: =+H7+I7-J7 -> 383.137 | H7: 330.107 | I7: ='DAILY FLASH'!AG45 -> 199.09 | J7: =+D7 -> 146.06
A8: FORGE | B8: 1729 | C8: ='DAILY FLASH'!#REF! -> #REF! | D8: ='DAILY FLASH'!BC52 -> 256.635 | E8: 256.635 | F8: =D8-E8 -> 0 | G8: =+H8+I8-J8 -> 1957.769 | H8: 1891.604 | I8: ='DAILY FLASH'!AG46 -> 322.8 | J8: =+D8 -> 256.635 | R8: QUANTITY IN T
A9: PLATE | B9: 1775 | C9: ='DAILY FLASH'!#REF! -> #REF! | D9: ='DAILY FLASH'!BC54 -> 198.397 | E9: 148.163 | F9: =D9-E9 -> 50.234 | G9: =+H9+I9-J9 -> 1239.4365 | H9: 1262.5565 | I9: ='DAILY FLASH'!AG47 -> 175.277 | J9: =+D9 -> 198.397 | Q9: PRODUCT | R9: CONDITIONING | S9: HTF | T9: PLATE MILL | U9: WAREHOUSE | V9: TOTAL
A10: CC SLAB | B10: 1413 | C10: ='DAILY FLASH'!#REF!+'DAILY FLASH'!#REF!+'DAILY FLASH'!#REF! -> #REF! | D10: ='DAILY FLASH'!BC55 -> 517.536 | E10: 470.46 | F10: =D10-E10 -> 47.076 | G10: =+H10+I10-J10 -> 410.103 | H10: 576.779 | I10: ='DAILY FLASH'!AG48 -> 350.86 | J10: =+D10 -> 517.536
A11: CC BLOOM | D11: 0 | E11: 0 | F11: =D11-E11 -> 0 | G11: =+H11+I11-J11 -> 125.23 | H11: 125.23 | I11: ='DAILY FLASH'!AG49 -> 0 | J11: =+D11 -> 0
A12: FRG SLB | D12: ='DAILY FLASH'!BC57 -> 41.42 | E12: 41.42 | F12: =D12-E12 -> 0 | G12: =+H12+I12-J12+8 -> 232.627 | H12: 235.547 | I12: ='DAILY FLASH'!AN51 -> 30.5 | J12: =+D12 -> 41.42
A13: SPD/JACKA SLAB | D13: 0 | E13: 0 | F13: =D13-E13 -> 0 | G13: =+H13+I13-J13 -> 410.103 | H13: 576.779 | I13: ='DAILY FLASH'!AG48 -> 350.86 | J13: ='DAILY FLASH'!BC55 -> 517.536 | L13: =17232-16094 -> 1138
A14: JACKAL INGOT | D14: 0 | E14: 0 | F14: =D14-E14 -> 0 | G14: =+H14+I14-J14 -> 0 | H14: 0 | I14: ='DAILY FLASH'!AN54 -> 0 | J14: =+D14 -> 0
A15: BHEL INGOT | D15: 0 | E15: 0 | F15: =D15-E15 -> 0 | G15: =+H15+I15-J15 -> 0 | H15: 0 | I15: 0 | J15: =+D15 -> 0
A16: STN SLAB | D16: 0 | E16: 0 | F16: =D16-E16 -> 0 | G16: =+H16+I16-J16 -> 184.141 | H16: 184.141 | I16: ='DAILY FLASH'!AG54 -> 0 | J16: =+D16 -> 0
A17: INGOT | D17: ='DAILY FLASH'!BC59 -> 50.08 | E17: 50.08 | F17: =D17-E17 -> 0 | G17: =+H17+I17-J17 -> 656.519 | H17: 601.299 | I17: ='DAILY FLASH'!AG55 -> 105.3 | J17: =+D17 -> 50.08 | Q17: BILLET | R17: =4970+222-218-115.25+259+253-174-8+222-167-221+202+270-46-43+234-123+300+302-2917-142+138 -> 3197.75 | S17: =1114-85+32 -> 1061 | U17: =1212-1-40 -> 1171 | V17: =SUM(R17:U17) -> 5429.75
A18: TOTAL | B18: =SUM(B6:B10) -> 12695 | C18: =SUM(C6:C10) -> #REF! | D18: =SUM(D6:D17) -> 11173.28 | E18: =SUM(E6:E17) -> 10770.1 | F18: =SUM(F6:F17) -> 403.18 | G18: =SUM(G6:G17)-G10 -> 20078.592 | H18: =SUM(H6:H17)-H10 -> 19841.685 | I18: =SUM(I6:I17) -> 11753.047 | J18: =SUM(J6:J17) -> 11690.816
Q19: BAR | S19: =232-20 -> 212 | U19: 21 | V19: =SUM(R19:U19) -> 233
E20: =SUM(E6:E18) -> 21540.2
D21: COPY | E21: PASTE | V21: =SUM(R21:U21) -> 0
V23: =SUM(R23:U23) -> 0
A25: YEAR0WISE SALEABLE | V25: =SUM(R25:U25) -> 0
B26: 2009-10 | C26: 2010-11 | D26: 2011-12 | E26: 2012-13 | F26: 2013-14 | G26: 2014-15 | H26: 2015-16 | I26: 2016-17 | N26: AS ON 01/04/19 | O26: SAL | P26: DESP | Q26: STK 01/06
A27: BILLET | B27: 75524 | C27: =83006+333 -> 83339 | D27: 92912 | E27: 86622 | F27: 92716 | G27: 82253 | H27: 71051 | I27: 70879 | J27: =89073-20678+14 -> 68409 | N27: =11450.1+1792.267+26.461 -> 13268.828 | O27: 13820.904 | P27: 15354.029 | Q27: =+N27+O27-P27 -> 11735.703 | V27: =SUM(V17:V25) -> 5662.75
A28: BAR | B28: 1238 | C28: 761 | D28: 1027 | E28: 457 | F28: 335 | G28: 799 | H28: 263 | I28: 674 | J28: 699.611 | N28: 337.177 | O28: 13.29 | P28: 29.04 | Q28: =+N28+O28-P28 -> 321.427
A29: FORGE | B29: 3731 | C29: 3737 | D29: 4283 | E29: 4558 | F29: 5477 | G29: 4330 | H29: 4350 | I29: =3069+531 -> 3600 | J29: 4150.229 | N29: 1497.055 | O29: 705.43 | P29: 898.255 | Q29: =+N29+O29-P29 -> 1304.23
A30: PLATE | B30: 1831 | C30: 1809 | D30: 1467 | E30: 1428 | F30: 1663 | G30: 1500 | H30: 1303 | I30: 1661 | J30: 1735.072 | N30: 1014.131 | O30: 41.024 | P30: 87.425 | Q30: =+N30+O30-P30 -> 967.73
A31: ING | B31: 3832 | C31: 1692 | D31: =1689+73 -> 1762 | E31: =2411+392 -> 2803 | F31: =2250+42 -> 2292 | G31: 3500 | H31: 2278 | I31: =1383+199 -> 1582 | J31: 1948.5 | N31: 364.73 | O31: 1062.15 | P31: 1088.94 | Q31: =+N31+O31-P31 -> 337.94
A32: CC SLAB | B32: 93889 | C32: 111575 | D32: 82709 | E32: 27572 | F32: 9325 | G32: 1811 | H32: 3233 | I32: =4689.637-1009.76 -> 3679.877 | J32: =11521.395+623.525-8094.635 -> 4050.285 | N32: 1381.124 | O32: 600.129 | P32: 595.52 | Q32: =+N32+O32-P32 -> 1385.733
A33: CCBLOOM | B33: 0 | D33: 324 | E33: 2954 | F33: 2538 | G33: 1771 | I33: 1009.78 | J33: =8041.755+52.88 -> 8094.635 | N33: =SUM(N27:N32) -> 17863.045 | O33: =SUM(O27:O32) -> 16242.927 | P33: =SUM(P27:P32) -> 18053.209 | Q33: =SUM(Q27:Q32) -> 16052.763
A34: TOTAL | B34: =SUM(B27:B33) -> 180045 | C34: =SUM(C27:C33) -> 202913 | D34: =SUM(D27:D33) -> 184484 | E34: =SUM(E27:E33) -> 126394 | F34: =SUM(F27:F33) -> 114346 | G34: =SUM(G27:G33) -> 95964 | H34: =SUM(H27:H33) -> 82478 | I34: =SUM(I27:I33) -> 83085.657 | J34: =SUM(J27:J33) -> 89087.332
A40: YEAR0WISE DESPATCH
B41: 2009-10 | C41: 2010-11 | D41: 2011-12 | E41: 2012-13 | F41: 2013-14 | G41: 2014-15 | H41: 2015-16 | I41: 2016-17 | J41: 2017-18 | N41: 43556 | O41: SAL | P41: DESP | Q41: 43922 | R41: SAL | S41: DESP | T41: 44013
A42: BILLET | B42: 75796 | C42: 80079 | D42: 96892 | E42: 85834 | F42: 87135 | G42: 82533 | H42: 66368 | I42: 68523 | J42: 74455 | N42: =11450.1+1792.267+26.461 -> 13268.828 | O42: 92793.599 | P42: 88459.127 | Q42: =+N42+O42-P42 -> 17603.3 | R42: 5119.007 | S42: 6935.928 | T42: =+Q42+R42-S42 -> 15786.379
A43: BAR | B43: 1377 | C43: 863 | D43: 830 | E43: 560 | F43: 240 | G43: 834 | H43: 281 | I43: 598 | J43: 749.275 | N43: 337.177 | O43: 216.44 | P43: 236.92 | Q43: =+N43+O43-P43 -> 316.697 | S43: 4.98 | T43: =+Q43+R43-S43 -> 311.717
A44: FORGE | B44: 3761 | C44: 4083 | D44: 4349 | E44: 4521 | F44: 4991 | G44: 4557 | H44: 4095 | I44: 3403.5 | J44: 3951.559 | N44: 1497.055 | O44: 5177.324 | P44: 4629.588 | Q44: =+N44+O44-P44 -> 2044.791 | R44: 480.51 | S44: 408.012 | T44: =+Q44+R44-S44 -> 2117.289
A45: PLATE | B45: 1750 | C45: 1638 | D45: 1437 | E45: 1471 | F45: 1647 | G45: 1576 | H45: 1315 | I45: 1517 | J45: 1624.335 | N45: 1014.131 | O45: 1124.21 | P45: 1185.005 | Q45: =+N45+O45-P45 -> 953.336 | R45: 177.287 | S45: 142.55 | T45: =+Q45+R45-S45 -> 988.073
A46: ING | B46: 3786 | C46: 1641 | D46: 1838 | E46: 2628 | F46: 2142 | G46: 3455 | H46: 1986 | I46: =1556+159 -> 1715 | J46: 11647.118 | N46: 364.73 | O46: 2038.05 | P46: 2227.66 | Q46: =+N46+O46-P46 -> 175.12 | R46: 612 | S46: 588.7 | T46: =+Q46+R46-S46 -> 198.42
A47: CC SLAB | B47: 93592 | C47: 112225 | D47: 82387 | E47: 21050 | F47: 12317 | G47: 4260 | H47: 3281 | I47: 3721 | J47: 0 | N47: 1381.124 | O47: 1236.589 | P47: 1235.8 | Q47: =+N47+O47-P47 -> 1381.913 | R47: 339.1 | S47: 305.14 | T47: =+Q47+R47-S47 -> 1415.873
A48: CCBLOOM | B48: 0 | C48: 0 | D48: =214+99 -> 313 | E48: 2614 | F48: 2720 | G48: 1471 | H48: 113 | I48: 938 | J48: 671
...

Sheet DMR GRADE DESPATCHED
C10: DMR-249 & DMR301 DESPATCH
C11: GRADE | D11: 13-14 | E11: 14-15 | F11: 15-16 | G11: 16-17 | H11: 17-18 | I11: 18-19 | J11: 19-20 | K11: 20-21 | L11: 21-22 | M11: 22-23 | N11: 23-24 | O11: 24-25 | P11: 25-26
C12: DNR 249A CERTIFIED | E12: 71.02 | O12: 161.6 | P12: =43.42+67.51 -> 110.93
C13: DMR-249 BK | E13: 72.6
C14: DMR-249BK MAX ALLOYS | D14: 36.855 | E14: 52.94 | F14: 201.4 | G14: 50.78 | H14: 0 | I14: 0 | J14: 0 | K14: 0 | L14: 0 | M14: 0
C15: DMR-249BK-AMIN ALLOY | D15: 40.654 | E15: 49.67 | F15: 94.03 | G15: 50.79 | H15: 0 | I15: 0 | J15: 0 | K15: 0 | L15: 0 | M15: 0
C16: DMR 301 | N16: 143.27
C17: DMR 249B MIN ALLOYS | D17: 98.66
C18: AB3 | N18: 37.47
C19: AB3K | G19: 51.14
C20: AB3K | G20: 98.33
C21: TOTAL | D21: 176.169 | E21: 102.61 | F21: 295.43 | G21: 251.04 | H21: 0 | I21: 0 | J21: 0 | K21: 0 | L21: 0 | M21: 0 | N21: 180.74 | O21: 161.6
C22: From 17-18 to 22-23
C23: No despatch

Sheet MESSAGE
A1: AUTO REPORT GENERATION & MESSAGING PAGE
A2: The following particulars are directly read from the MIS report:
