Workbook
Name AV: #REF!
Name HQ: #REF!
Name IE: #REF!
Name IP: #REF!
Name KQ: #REF!
Name LoadName0: CEOREPORT!$K$105
Name LoadName1: CEOREPORT!$L$106
Name LoadName2: CEOREPORT!$L$107
Name LoadName3: CEOREPORT!$L$108
Name LoadName4: CEOREPORT!$L$109
Name LoadName5: CEOREPORT!$L$110
Name LoadName6: CEOREPORT!$L$111
Name ly: #REF!
Name SLAG: #REF!
Name usmtonnage: #REF!

Sheet CEOREPORT
B3: संयंत्र नियंत्रण | D3: भारतीय इस्पात प्राधिकरण लिमिटेड़ | F3: =18.686*0.7 -> 13.0802 | G3: =34.44*0.7 -> 24.108 | Q3: ASKING
D4: इस्को इस्पात संयंत्र - बर्नपुर | F4: =33*F3 -> 431.6466 | G4: =G3*31 -> 747.348 | K4: निष्पादन प्रतिवेदन | N4: =+#REF! -> #REF! | O4: =+#REF! -> #REF! | Q4: RATE AS ON
Q5: =TODAY() -> 46174
B6: RAWMATERIAL | D6: RECEIPT (T) | F6: CONSUMPTION/DAY | G6: STOCK | H6: REQUIRED STOCK | J6: PRODUCTION | K6: ON DATE | L6: TO DATE | M6: RATE | N6: % FF | O6: ABP | P6: ACTUAL
B7: ITEM | D7: ON DATE | E7: TO DATE | F7: (T) | G7: (T) | J7: COKE OVENS | O7: =+DAILYREPORT1!G7 -> 46143 | P7: =+DAILYREPORT1!H7 -> 45778
B8: COKING COAL-FOR OLD PLANT | H8: (FOR 15 DAYS) | J8: COB-8 | K8: =+#REF! -> #REF! | L8: =+#REF! -> #REF! | M8: =+#REF! -> #REF! | N8: - | O8: =+#REF! -> #REF! | P8: =+#REF! -> #REF!
B9: PCC | C9: =+RAWMATERIALS!B10 -> #REF! | D9: =+RAWMATERIALS!C10 -> 0 | E9: =+RAWMATERIALS!D10 -> #REF! | F9: =+($K$9*18.68*RAWMATERIALS!I10)/100 -> #REF! | G9: =+RAWMATERIALS!E10 -> 200 | H9: =+($K$9*19.4*RAWMATERIALS!I10*15)/100 -> #REF! | J9: COB-10 | K9: =+#REF! -> #REF! | L9: =+#REF! -> #REF! | M9: =+#REF! -> #REF! | N9: =+#REF! -> #REF! | O9: =+#REF! -> #REF! | P9: =+#REF! -> #REF! | Q9: =+#REF! -> #REF!
C10: =+RAWMATERIALS!B11 -> LVHR-HARD | D10: =+RAWMATERIALS!C11 -> 0 | E10: =+RAWMATERIALS!D11 -> #REF! | F10: =+($K$9*18.686*RAWMATERIALS!I11)/100 -> #REF! | G10: =+RAWMATERIALS!E11 -> 3700 | H10: =+($K$9*19.4*RAWMATERIALS!I11*15)/100 -> #REF! | J10: COB-11 | K10: =+#REF! -> #REF! | L10: =+#REF! -> #REF! | M10: =+#REF! -> #REF! | N10: =+#REF! -> #REF! | O10: =+#REF! -> #REF! | P10: =+#REF! -> #REF! | Q10: =+#REF! -> #REF!
B11: ICC | C11: =+RAWMATERIALS!B12 -> #REF! | D11: =+RAWMATERIALS!C12 -> 1800 | E11: =+RAWMATERIALS!D12 -> #REF! | F11: =+($K$9*18.68*RAWMATERIALS!I12)/100 -> #REF! | G11: =+RAWMATERIALS!E12 -> 5400 | H11: =+($K$9*19.4*RAWMATERIALS!I12*15)/100 -> #REF! | J11: TOTAL (EQUIV NO.S) | K11: =+#REF! -> #REF! | L11: =+#REF! -> #REF! | M11: =+#REF! -> #REF! | N11: =+#REF! -> #REF! | O11: =+#REF! -> #REF! | P11: =+#REF! -> #REF! | Q11: =+#REF! -> #REF!
C12: =+RAWMATERIALS!B13 -> #REF! | D12: =+RAWMATERIALS!C13 -> 0 | E12: =+RAWMATERIALS!D13 -> #REF! | F12: =+($K$9*18.68*RAWMATERIALS!I13)/100 -> #REF! | G12: =+RAWMATERIALS!E13 -> 3800 | H12: =+($K$9*19.4*RAWMATERIALS!I13*15)/100 -> #REF! | J12: SINTER PLANT
C13: =+RAWMATERIALS!B14 -> #REF! | D13: =+RAWMATERIALS!C14 -> 0 | E13: =+RAWMATERIALS!D14 -> #REF! | F13: =+($K$9*18.68*RAWMATERIALS!I14)/100 -> #REF! | G13: =+RAWMATERIALS!E14 -> 1100 | H13: =+($K$9*19.4*RAWMATERIALS!I14*15)/100 -> #REF! | J13: SINTER M/C-1 | K13: =+#REF! -> #REF! | L13: =+#REF! -> #REF! | M13: SINTER STOCK
C14: =+RAWMATERIALS!B15 -> #REF! | D14: =+RAWMATERIALS!C15 -> 0 | E14: =+RAWMATERIALS!D15 -> #REF! | F14: =+($K$9*18.68*RAWMATERIALS!I15)/100 -> #REF! | G14: =+RAWMATERIALS!E15 -> 2000 | H14: =+($K$9*19.4*RAWMATERIALS!I15*15)/100 -> #REF! | J14: SINTER M/C-2 | K14: =+#REF! -> #REF! | L14: =+#REF! -> #REF! | M14: =+#REF! -> #REF!
C15: =+RAWMATERIALS!B16 -> #REF! | D15: =+RAWMATERIALS!C16 -> 0 | E15: =+RAWMATERIALS!D16 -> #REF! | F15: =+($K$9*18.68*RAWMATERIALS!I16)/100 -> #REF! | G15: =+RAWMATERIALS!E16 -> 0 | H15: =+($K$9*19.4*RAWMATERIALS!I16*15)/100 -> #REF! | J15: TOTAL SINTER | K15: =+#REF! -> #REF! | L15: =+#REF! -> #REF! | M15: =+#REF! -> #REF! | N15: =+#REF! -> #REF! | O15: =+#REF! -> #REF! | P15: =+#REF! -> #REF! | Q15: =+#REF! -> #REF!
C16: =+RAWMATERIALS!B17 -> #REF! | D16: =+RAWMATERIALS!C17 -> 5280 | E16: =+RAWMATERIALS!D17 -> #REF! | F16: =+($K$9*18.686*RAWMATERIALS!I17)/100 -> #REF! | G16: =+RAWMATERIALS!E17 -> 7600 | H16: =+($K$9*19.4*RAWMATERIALS!I17*15)/100 -> #REF! | J16: SINTER SENT TO BF-5 | K16: =+RAWMATERIALS!N48 -> 11520 | L16: =+RAWMATERIALS!O48 -> #REF! | M16: =+L16/#REF!*#REF! -> #REF!
C17: =+RAWMATERIALS!B18 -> RUS-SOFT | D17: =+RAWMATERIALS!C18 -> 0 | E17: =+RAWMATERIALS!D18 -> #REF! | F17: =+($K$9*18.68*RAWMATERIALS!I18)/100 -> #REF! | G17: =+RAWMATERIALS!E18 -> 1400 | H17: =+($K$9*19.4*RAWMATERIALS!I18*15)/100 -> #REF!
C18: =+RAWMATERIALS!B19 -> #REF! | D18: =+RAWMATERIALS!C19 -> 0 | E18: =+RAWMATERIALS!D19 -> #REF! | F18: =+($K$9*18.686*RAWMATERIALS!I19)/100 -> #REF! | G18: =+RAWMATERIALS!E19 -> 0 | H18: =+($K$9*19.4*RAWMATERIALS!I19*15)/100 -> #REF!
B19: TOTAL COKING COAL | D19: =SUM(D9:D18) -> 7080 | E19: =SUM(E9:E18) -> #REF! | F19: =SUM(F9:F18) -> #REF! | G19: =SUM(G9:G18) -> 25200 | H19: =SUM(H9:H18) -> #REF! | J19: BLAST FURNACE-5
B20: COKING COAL-FOR NEW PLANT | J20: HOT METAL | K20: =+#REF! -> #REF! | L20: =+#REF! -> #REF! | M20: =+#REF! -> #REF! | N20: =+#REF! -> #REF! | O20: =+#REF! -> #REF! | P20: =+#REF! -> #REF! | Q20: =+#REF! -> #REF!
B21: PCC | C21: =+RAWMATERIALS!B22:B22 -> #REF! | D21: =+RAWMATERIALS!C22 -> 0 | E21: =+RAWMATERIALS!D22 -> #REF! | F21: =+($K$10*34.44*RAWMATERIALS!I22)/100 -> #REF! | G21: =+RAWMATERIALS!E22 -> 3890 | H21: =+($K$10*34.44*RAWMATERIALS!I22*15)/100 -> #REF! | J21: DISTRIBUTION : BOF | K21: =+#REF! -> #REF! | L21: =+#REF! -> #REF!
C22: =+RAWMATERIALS!B23:B23 -> #REF! | D22: =+RAWMATERIALS!C23 -> 0 | E22: =+RAWMATERIALS!D23 -> #REF! | F22: =+($K$10*34.44*RAWMATERIALS!I23)/100 -> #REF! | G22: =+RAWMATERIALS!E23 -> 3310 | H22: =+($K$10*34.44*RAWMATERIALS!I23*15)/100 -> #REF! | J22: PCM | K22: =+#REF! -> #REF! | L22: =+#REF! -> #REF!
B23: ICC | C23: =+RAWMATERIALS!B24:B24 -> #REF! | D23: =+RAWMATERIALS!C24 -> 0 | E23: =+RAWMATERIALS!D24 -> #REF! | F23: =+($K$10*34.44*RAWMATERIALS!I24)/100 -> #REF! | G23: =+RAWMATERIALS!E24 -> 10080 | H23: =+($K$10*34.44*RAWMATERIALS!I24*15)/100 -> #REF! | J23: SAND PITS | K23: =+#REF! -> #REF! | L23: =+#REF! -> #REF!
C24: =+RAWMATERIALS!B25 -> #REF! | D24: =+RAWMATERIALS!C25 -> 0 | E24: =+RAWMATERIALS!D25 -> #REF! | F24: =+($K$10*34.44*RAWMATERIALS!I25)/100 -> #REF! | G24: =+RAWMATERIALS!E25 -> 3800 | H24: =+($K$10*34.44*RAWMATERIALS!I25*15)/100 -> #REF!
C25: =+RAWMATERIALS!B26 -> #REF! | D25: =+RAWMATERIALS!C26 -> 0 | E25: =+RAWMATERIALS!D26 -> #REF! | F25: =+($K$10*34.44*RAWMATERIALS!I26)/100 -> #REF! | G25: =+RAWMATERIALS!E26 -> 290 | H25: =+($K$10*34.44*RAWMATERIALS!I26*15)/100 -> #REF!
C26: =+RAWMATERIALS!B27 -> #REF! | D26: =+RAWMATERIALS!C27 -> 0 | E26: =+RAWMATERIALS!D27 -> #REF! | F26: =+($K$10*34.44*RAWMATERIALS!I27)/100 -> #REF! | G26: =+RAWMATERIALS!E27 -> 0 | H26: =+($K$10*34.44*RAWMATERIALS!I27*15)/100 -> #REF! | J26: SMS-2
C27: =+RAWMATERIALS!B28 -> JAMADOBA | D27: =+RAWMATERIALS!C28 -> 0 | E27: =+RAWMATERIALS!D28 -> #REF! | F27: =+($K$10*34.44*RAWMATERIALS!I28)/100 -> #REF! | G27: =+RAWMATERIALS!E28 -> 3080 | H27: =+($K$10*34.44*RAWMATERIALS!I28*15)/100 -> #REF! | J27: BOF : HEATS | K27: =+#REF! -> #REF! | L27: =+#REF! -> #REF!
C28: =+RAWMATERIALS!B29 -> #REF! | D28: =+RAWMATERIALS!C29 -> 0 | E28: =+RAWMATERIALS!D29 -> #REF! | F28: =+($K$10*34.44*RAWMATERIALS!I29)/100 -> #REF! | G28: =+RAWMATERIALS!E29 -> 180 | H28: =+($K$10*34.44*RAWMATERIALS!I29*15)/100 -> #REF! | J28: CCP : CASTS | K28: =+#REF! -> #REF! | L28: =+#REF! -> #REF!
C29: =+RAWMATERIALS!B30 -> #REF! | D29: =+RAWMATERIALS!C30 -> 0 | E29: =+RAWMATERIALS!D30 -> #REF! | F29: =+($K$10*34.44*RAWMATERIALS!I30)/100 -> #REF! | G29: =+RAWMATERIALS!E30 -> 4300 | H29: =+($K$10*34.44*RAWMATERIALS!I30*15)/100 -> #REF! | J29: =+#REF! -> #REF! | K29: =+#REF! -> #REF! | L29: =+#REF! -> #REF! | M29: =+#REF! -> #REF! | N29: =+#REF! -> #REF! | O29: =+#REF! -> #REF! | P29: =+#REF! -> #REF! | Q29: =+#REF! -> #REF!
C30: =+RAWMATERIALS!B31 -> #REF! | D30: =+RAWMATERIALS!C31 -> 0 | E30: =+RAWMATERIALS!D31 -> #REF! | F30: =+($K$10*34.44*RAWMATERIALS!I31)/100 -> #REF! | G30: =+RAWMATERIALS!E31 -> 0 | H30: =+($K$10*34.44*RAWMATERIALS!I31*15)/100 -> #REF! | J30: =+#REF! -> #REF! | K30: =+#REF! -> #REF! | L30: =+#REF! -> #REF! | M30: =+#REF! -> #REF! | N30: =+#REF! -> #REF! | O30: =+#REF! -> #REF! | P30: =+#REF! -> #REF! | Q30: =+#REF! -> #REF!
C31: =+RAWMATERIALS!B32 -> #REF! | D31: =+RAWMATERIALS!C32 -> 0 | E31: =+RAWMATERIALS!D32 -> #REF! | F31: =+($K$10*34.44*RAWMATERIALS!I32)/100 -> #REF! | G31: =+RAWMATERIALS!E32 -> 0 | H31: =+($K$10*34.44*RAWMATERIALS!I32*15)/100 -> #REF! | J31: TOTAL | K31: =SUM(K29:K30) -> #REF! | L31: =SUM(L29:L30) -> #REF! | M31: =SUM(M29:M30) -> #REF! | N31: =+#REF! -> #REF! | O31: =SUM(O29:O30) -> #REF! | P31: =SUM(P29:P30) -> #REF! | Q31: =+#REF! -> #REF!
B32: TOTAL COKING COAL | D32: =SUM(D21:D31) -> 0 | E32: =SUM(E21:E31) -> #REF! | F32: =SUM(F21:F31) -> #REF! | G32: =SUM(G21:G31) -> 28930 | H32: =+($K$10*34.44*RAWMATERIALS!I33*15)/100 -> #REF!
C33: CDI | D33: =+RAWMATERIALS!C34 -> 0 | E33: =+RAWMATERIALS!D34 -> #REF! | F33: =+RAWMATERIALS!F34 -> 1215 | G33: =+RAWMATERIALS!E34 -> 9800 | J33: SALEBLE STEEL PRODUCTION
B34: OLD PLANT | C34: BOILER COAL | J34: WIRE ROD MILL | K34: =+#REF! -> #REF! | L34: =+#REF! -> #REF! | M34: =+#REF! -> #REF! | N34: =+#REF! -> #REF! | O34: =+#REF! -> #REF! | P34: =+#REF! -> #REF! | Q34: =+#REF! -> #REF!
C35: ECL/CCL | D35: =+RAWMATERIALS!C40 -> 0 | E35: =+RAWMATERIALS!D40 -> #REF! | F35: =+RAWMATERIALS!F40 -> 0 | G35: =+RAWMATERIALS!E40 -> 300 | J35: BAR MILL | K35: =+#REF! -> #REF! | L35: =+#REF! -> #REF! | M35: =+#REF! -> #REF! | N35: =+#REF! -> #REF! | O35: =+#REF! -> #REF! | P35: =+#REF! -> #REF! | Q35: =+#REF! -> #REF!
C36: RAMNAGAR (For ISP) | D36: =+RAWMATERIALS!C41 -> 0 | E36: =+RAWMATERIALS!D41 -> 0 | F36: =+RAWMATERIALS!F41 -> 0 | G36: =+RAWMATERIALS!E41 -> 0 | J36: USM | K36: =+#REF! -> #REF! | L36: =+#REF! -> #REF! | M36: =+#REF! -> #REF! | N36: =+#REF! -> #REF! | O36: =+#REF! -> #REF! | P36: =+#REF! -> #REF! | Q36: =+#REF! -> #REF!
C37: TOTAL BOILER COAL | D37: =+SUM(D35:D36) -> 0 | E37: =+SUM(E35:E36) -> #REF! | F37: =+SUM(F35:F36) -> 0 | G37: =+SUM(G35:G36) -> 300 | J37: CC BLOOMS | K37: =+#REF! -> #REF! | L37: =+#REF! -> #REF! | M37: =+#REF! -> #REF! | N37: =+#REF! -> #REF! | O37: =+#REF! -> #REF! | P37: =+#REF! -> #REF! | Q37: =+#REF! -> #REF!
F38: CONSUMPTION (T) | G38: STOCK | H38: STOCK(DAYS) | J38: TOTAL SALEABLE STEEL | K38: =+#REF! -> #REF! | L38: =+#REF! -> #REF! | M38: =+#REF! -> #REF! | N38: =+#REF! -> #REF! | O38: =+#REF! -> #REF! | P38: =+#REF! -> #REF! | Q38: =+#REF! -> #REF!
B39: NEW PLANT | C39: IRONORE FINES(IN SP) | D39: =+RAWMATERIALS!C46 -> 12300 | E39: =+RAWMATERIALS!D46 -> #REF! | F39: =0.8*#REF!-(F41*0.15) -> #REF! | G39: =+RAWMATERIALS!E46 -> 120627 | H39: =IFERROR(G39/F39,"-") -> -
C41: IRONORE LUMPS | D41: =+RAWMATERIALS!C45 -> 2160 | E41: =+RAWMATERIALS!D45 -> #REF! | F41: =0*#REF!+3.72*#REF!*0.071 -> #REF! | G41: =+RAWMATERIALS!E45 -> 63369 | H41: =G41/F41 -> #REF! | J41: DESPATCH OF SALEABLE STEEL
C42: LIMESTONE (SP Grade) | D42: =+RAWMATERIALS!C48 -> 0 | E42: =+RAWMATERIALS!D48 -> #REF! | F42: =+IF(G42=0,"0",((85/1000*DAILYREPORT1!C14))-(((DAILYREPORT1!J83*DAILYREPORT1!C32/1000)/0.65/0.56/0.65)*0.27)) -> 271.25529 | G42: 100 | H42: =IFERROR(G42/F42,"-") -> 0.36865641 | J42: WIRE ROD MILL | K42: =+#REF! -> #REF! | L42: =+#REF! -> #REF! | M42: =+#REF! -> #REF! | N42: =+#REF! -> #REF! | O42: =+#REF! -> #REF! | P42: =+#REF! -> #REF! | Q42: =+#REF! -> #REF!
C43: LIMESTONE (SMS Grade) | D43: =+RAWMATERIALS!C49 -> 0 | E43: =+RAWMATERIALS!D49 -> #REF! | F43: =+(((DAILYREPORT1!I83*DAILYREPORT1!C32/1000)/0.65)/0.56/0.65)+((85/1000*DAILYREPORT1!C14))-(((DAILYREPORT1!I83*DAILYREPORT1!C32/1000)/0.65/0.56/0.65)*0.35)-F42 -> 2284.1412 | G43: =+RAWMATERIALS!E49 -> 5481 | H43: =IFERROR(G43/F43,"-") -> 2.399589 | J43: BAR MILL | K43: =+#REF! -> #REF! | L43: =+#REF! -> #REF! | M43: =+#REF! -> #REF! | N43: =+#REF! -> #REF! | O43: =+#REF! -> #REF! | P43: =+#REF! -> #REF! | Q43: =+#REF! -> #REF!
...

Sheet RAWMATERIALS
T1: =TODAY() -> 46174 | U1: NORTH YARD | V1: SOUTH YARD | W1: jodaburi | X1: COB-12 site | Y1: ECSY | Z1: TOTAL
D2: भारतीय इस्पात प्राधिकरण लिमिटेड़ | N2: संयंत्र नियंत्रण | U2: 100 | V2: 200 | W2: 53983.4 | X2: 0 | Y2: 3079 | Z2: =SUM(U2:Y2) -> 57362.4
D3: इस्को इस्पात संयंत्र - बर्नपुर | T3: 1 | U3: 0 | V3: 100 | X3: 0
C4: RAW MATERIALS REPORT | M4: DATE | N4: =+#REF! -> #REF! | O4: =+#REF! -> #REF! | T4: 2 | U4: 100 | V4: 500 | X4: 0
T5: 3 | U5: -100 | V5: -300 | X5: 0
C6: RECEIPT | T6: 4 | X6: 0
B7: SOURCE | C7: ON DATE | D7: TO DATE | E7: CLOSING STOCK | F7: CONSUMPTION | G7: TIPPLING | H7: ON HAND | I7: COAL BLEND | T7: 5 | X7: 0
I8: =TODAY()-1 -> 46173 | T8: 6 | X8: 0
B9: COKING COAL : | C9: OLD PLANT | F9: OLD PLANT | I9: COB-10 | J9: COB-10 COAL BLEND % | T9: 7 | V9: -200 | X9: 0
B10: =+#REF! -> #REF! | C10: 0 | D10: =+#REF! -> #REF! | E10: 200 | F10: =(#REF!*18.68)*I10/100 -> #REF! | G10: 0 | H10: 0 | I10: 8 | J10: INDIGENOUS | K10: =I19+I14 -> 11 | T10: 8 | X10: 0
B11: LVHR-HARD | C11: 0 | D11: =+#REF! -> #REF! | E11: 3700 | F11: =(#REF!*18.68)*I11/100 -> #REF! | G11: 0 | H11: 0 | I11: 0 | J11: ICC HARD | K11: =I10+I11+I12+I13+I15 -> 64 | T11: 9 | U11: 0 | V11: 300 | X11: 0
B12: =+#REF! -> #REF! | C12: 1800 | D12: =+#REF! -> #REF! | E12: 5400 | F12: =(#REF!*18.68)*I12/100 -> #REF! | G12: 30 | H12: 0 | I12: 40 | J12: ICC SOFT | K12: =+I17+I16+I18 -> 25 | T12: 10 | X12: 0
B13: =+#REF! -> #REF! | C13: 0 | D13: =+#REF! -> #REF! | E13: 3800 | F13: =(#REF!*18.68)*I13/100 -> #REF! | G13: 9 | H13: 0 | I13: 8 | T13: 11 | X13: 0
B14: =+#REF! -> #REF! | C14: 0 | D14: =+#REF! -> #REF! | E14: 1100 | F14: =(#REF!*18.68)*I14/100 -> #REF! | G14: 0 | H14: 0 | I14: 11 | T14: 12 | U14: 0 | V14: 200 | X14: 0
B15: =+#REF! -> #REF! | C15: 0 | D15: =+#REF! -> #REF! | E15: 2000 | F15: =(#REF!*18.68)*I15/100 -> #REF! | G15: 0 | H15: 0 | I15: 8 | T15: 13
B16: =+#REF! -> #REF! | C16: 0 | D16: =+#REF! -> #REF! | E16: 0 | F16: =(#REF!*18.68)*I16/100 -> #REF! | G16: 0 | H16: 0 | I16: 0 | T16: 14
B17: =+#REF! -> #REF! | C17: 5280 | D17: =+#REF! -> #REF! | E17: 7600 | F17: =(#REF!*18.68)*I17/100 -> #REF! | G17: 49 | H17: 39 | I17: 17 | L17: \ | T17: 15
B18: RUS-SOFT | C18: 0 | D18: =+#REF! -> #REF! | E18: 1400 | F18: =(#REF!*18.68)*I18/100 -> #REF! | G18: 0 | H18: 0 | I18: 8 | T18: 16
B19: =+#REF! -> #REF! | C19: 0 | D19: =+#REF! -> #REF! | E19: 0 | F19: =(#REF!*18.68)*I19/100 -> #REF! | G19: 0 | H19: 0 | I19: 0 | T19: 17 | X19: 0
B20: TOTAL | C20: =+SUM(C10:C19) -> 7080 | D20: =+SUM(D10:D19) -> #REF! | E20: =SUM(E10:E19) -> 25200 | F20: =SUM(F10:F19) -> #REF! | G20: =+SUM(G10:G19) -> 88 | H20: =+SUM(H10:H19) -> 39 | I20: =SUM(I10:I19) -> 100 | J20: SILOS STOCK IN COB#11 | T20: 18 | X20: 0
B21: COKING COAL : | C21: NEW PLANT | F21: COB-11 | I21: COB-11 | J21: COKING COAL : | K21: STOCK | L21: COB-11 COAL BLEND % | T21: 19 | X21: 0
B22: =+#REF! -> #REF! | C22: 0 | D22: =+#REF! -> #REF! | E22: 3890 | F22: =(#REF!*34.44)*I22/100 -> #REF! | G22: 0 | H22: 0 | I22: 7 | L22: INDIGENOUS | M22: =I28+I27 -> 5 | T22: 20 | X22: 0
B23: =+#REF! -> #REF! | C23: 0 | D23: =+#REF! -> #REF! | E23: 3310 | F23: =(#REF!*34.44)*I23/100 -> #REF! | G23: 0 | H23: 0 | I23: 10 | J23: =+B23 -> #REF! | K23: 0 | L23: ICC HARD | M23: =I23+I24+I25+I26+I29 -> 70 | T23: 21 | X23: 0
B24: =+#REF! -> #REF! | C24: 0 | D24: =+#REF! -> #REF! | E24: 10080 | F24: =(#REF!*34.44)*I24/100 -> #REF! | G24: 0 | H24: 0 | I24: 41 | J24: =+B24 -> #REF! | K24: 4900 | L24: ICC SOFT | M24: =+I30+I31+I32+I22 -> 25 | T24: 22
B25: =+#REF! -> #REF! | C25: 0 | D25: =+#REF! -> #REF! | E25: 3800 | F25: =(#REF!*34.44)*I25/100 -> #REF! | G25: 0 | H25: 0 | I25: 0 | J25: =+B25 -> #REF! | K25: 1450 | T25: 23
B26: =+#REF! -> #REF! | C26: 0 | D26: =+#REF! -> #REF! | E26: 290 | F26: =(#REF!*34.44)*I26/100 -> #REF! | G26: 0 | H26: 0 | I26: 7 | J26: =+B26 -> #REF! | K26: 1900 | T26: 24
B27: =+#REF! -> #REF! | C27: 0 | D27: =+#REF! -> #REF! | E27: 0 | F27: =(#REF!*34.44)*I27/100 -> #REF! | G27: 0 | H27: 0 | I27: 0 | J27: =+B27 -> #REF! | K27: 200 | T27: 25
B28: JAMADOBA | C28: 0 | D28: =+#REF! -> #REF! | E28: 3080 | F28: =(#REF!*34.44)*I28/100 -> #REF! | G28: 0 | H28: 0 | I28: 5 | J28: =+B28 -> JAMADOBA | K28: 0 | T28: 26
B29: =+#REF! -> #REF! | C29: 0 | D29: =+#REF! -> #REF! | E29: 180 | F29: =(#REF!*34.44)*I29/100 -> #REF! | G29: 0 | H29: 0 | I29: 12 | J29: =+B22 -> #REF! | K29: 650 | T29: 27
B30: =+#REF! -> #REF! | C30: 0 | D30: =+#REF! -> #REF! | E30: 4300 | F30: =(#REF!*34.44)*I30/100 -> #REF! | G30: 0 | H30: 0 | I30: 18 | J30: =+B30 -> #REF! | K30: 1800 | T30: 28
B31: =+#REF! -> #REF! | C31: 0 | D31: =+#REF! -> #REF! | E31: 0 | F31: =(#REF!*34.44)*I31/100 -> #REF! | G31: 0 | H31: 0 | I31: 0 | J31: =+B31 -> #REF! | K31: 0 | T31: 29
B32: =+#REF! -> #REF! | C32: 0 | D32: =+#REF! -> #REF! | E32: 0 | F32: =(#REF!*34.44)*I32/100 -> #REF! | G32: 0 | H32: 0 | I32: 0 | J32: =+B32 -> #REF! | K32: 0 | M32: ON DATE | N32: TO DATE | T32: 30
B33: TOTAL | C33: =+SUM(C22:C32) -> 0 | D33: =+SUM(D22:D32) -> #REF! | E33: =SUM(E22:E32) -> 28930 | F33: =SUM(F22:F32) -> #REF! | G33: =+SUM(G22:G32) -> 0 | H33: =+SUM(H22:H32) -> 0 | I33: =SUM(I22:I32)+I35 -> 100 | J33: TOTAL | K33: =+SUM(K22:K32) -> 10900 | L33: GROUND COKE USED BY BF | T33: 31
B34: CDI COAL | C34: 0 | D34: =+#REF! -> #REF! | E34: 9800 | F34: 1215 | G34: 0 | H34: 0 | J34: RAW MATERIAL TRANSFER TO BASEMIX PLANT | T34: STOCK | U34: =SUM(U2:U33) -> 100 | V34: =SUM(V2:V33) -> 800 | W34: =SUM(W2:W33) -> 53983.4 | X34: =SUM(X2:X33) -> 0
B35: COKING COAL IN BED-4 | E35: 0 | K35: A | L35: B | M35: C | N35: TOTAL | O35: TO DATE | U35: 100 | V35: 1200
B36: BOILER COAL : | E36: STOCK ↓ | G36: UNLOAD | H36: ON HAND | J36: IRONORE FINES | K36: 2850 | L36: 4120 | M36: 3734 | N36: =SUM(K36:M36) -> 10704 | O36: =+#REF! -> #REF! | V36: 44470
B37: BY RAIL : ECL | C37: 0 | D37: =+#REF! -> #REF! | E37: 0 | G37: 0 | H37: 0 | J37: LIMESTONE | K37: 288 | L37: 130 | M37: 126 | N37: =SUM(K37:M37) -> 544 | O37: =+#REF! -> #REF!
B38: BCDL (NMCL) | C38: 0 | D38: =+#REF! -> #REF! | E38: 300 | F38: 19 | G38: 0 | H38: 0 | J38: DOLOMITE | K38: 460 | L38: 540 | M38: 544 | N38: =SUM(K38:M38) -> 1544 | O38: =+#REF! -> #REF!
B39: RAJRAPPA | C39: 0 | D39: =+#REF! -> #REF! | E39: 0 | G39: 0 | H39: 0 | J39: COKE FINES RECEIVED FROM BF-5 | K39: 182 | L39: 140 | M39: 160 | N39: =SUM(K39:M39) -> 482 | O39: =+#REF! -> #REF!
B40: TOTAL ECL | C40: =+SUM(C37:C39) -> 0 | D40: =+SUM(D37:D39) -> #REF! | E40: =+SUM(E37:E39) -> 300 | F40: 0 | G40: =SUM(G37:G39) -> 0 | H40: =SUM(H37:H39) -> 0 | J40: BASE MIX PREPARATION | K40: 2689 | L40: 6656 | M40: 5105 | N40: =SUM(K40:M40) -> 14450 | O40: =+#REF! -> #REF!
...

Sheet DAILYREPORT1
GY2: -55 | HE2: 0 | HK2: -4
C4: स्टील अथॉरिटी ऑफ़ इंडिया लिमिटेड | F4: "MAY-26 IS DESIGNATED AS THE CAPITAL REPAIR MONTH" | J4: संयंत्र नियंत्रण
C5: इस्को इस्पात संयंत्र - बर्नपुर | G5: दैनिक प्रदर्शन प्रतिवेदन | J5: 31 | K5: 46143
B6: उत्पादन | C6: तिथि पर | D6: तिथि तक | E6: मासिक दर | F6: प्रतिशत पूर्ति | G6: ABP | H6: ACTUAL | I6: GROWTH OVER CPLY (%) | J6: ASKING | K6: ACTUAL YEARLY PRODUCTION
G7: 46143 | H7: 45778 | J7: RATE | K7: (2026-27)
B8: COKE OVEN PUSHING COB-8
B9: (OVEN-78) COB-10 | C9: 98 | D9: 3010 | E9: 97.096774 | F9: 99.078341 | G9: 98 | H9: 97.6 | I9: -0.51560021 | J9: #DIV/0! | K9: 5950
B10: (OVEN -74) COB-11 | C10: 99 | D10: 2904 | E10: 93.677419 | F10: 97.580645 | G10: 96 | H10: 97.5 | I10: -3.9205955 | J10: #DIV/0! | K10: 5857
B11: TOTAL (EQUIVALENT. No'S.) | C11: 279.566 | D11: 8335.936 | E11: 268.90116 | F11: 98.116192 | G11: 274.064 | H11: 276.4 | I11: -2.7130386 | J11: #DIV/0! | K11: 16691.738
B12: SINTER M/C-1 PRODUCTION | C12: 5905 | D12: 71200 | E12: 71200 | F12: SINTER STOCK AT ESSB | G12: 9440 | K12: 252637
B13: SINTER M/C-2 PRODUCTION | C13: 6035 | D13: 83384 | E13: 83384 | K13: 255399
B14: TOTAL SINTER PRODUCTION | C14: 11940 | D14: 154584 | E14: 154584 | F14: 58.950002 | G14: 262229 | H14: 355306 | I14: -56.492713 | J14: -7688.9286 | K14: 508036
B16: HOT METAL PRODUCTION | C16: 8804.7 | D16: 110808.6 | E16: 110808.6 | F16: 59.255936 | G16: 187000 | H16: 255731 | I16: -56.66986 | J16: #DIV/0! | K16: 347885.7
B17: DISTRIBUTION : BOF | C17: 8804.7 | D17: 103142 | E17: 103142 | F17: 56.827548 | G17: 181500 | H17: 252875 | I17: -59.212259 | J17: #DIV/0! | K17: 339924.1
B18: PCM | C18: 0 | D18: 2442.6 | E18: 2442.6 | F18: 122.13 | G18: 2000 | H18: 2856 | I18: -14.47479 | J18: #DIV/0! | K18: 2737.6
B19: NET PIG | C19: 0 | D19: 2039.571 | E19: 5224 | F19: 290.22222 | G19: 1800 | H19: 2384.76 | I19: 119.05768 | J19: #DIV/0! | K19: 2285.896
B20: SAND PIT/DRY PIT | C20: 0 | D20: 5224 | E20: 5224 | F20: 149.25714 | G20: 3500 | H20: 0 | J20: #DIV/0! | K20: 5224
B21: GRANULATED SLAG | C21: 2767 | D21: 34419 | E21: 34419 | F21: 52.609134 | G21: 65424 | H21: 75419 | I21: -54.362959 | J21: #DIV/0! | K21: 107390
B22: BOF - 1 :- No. OF HEATS | C22: 23 | D22: 252 | E22: CONVERTER LIFE | F22: 3429 | G22: 0 | H22: तिथि पर | I22: तिथि तक | K22: 594
B23: BOF - 2 :- No. OF HEATS | C23: 14 | D23: 147 | F23: 5981 | G23: RETURN HEATS | H23: 0 | I23: 0.53307692 | K23: 706 | DP23: 184
B24: BOF - 3 :- No. OF HEATS | C24: 18 | D24: 229 | F24: 17463 | G24: DS HEATS | H24: 23 | I24: 204 | K24: 750
B25: TOTAL HEATS | C25: 55 | D25: 628 | E25: AVERAGE HEATS | F25: 0 | G25: RH HEATS | H25: 0 | I25: 10 | K25: 2050
B26: CCP - 1 :- No. OF CASTS | C26: 23 | D26: 241 | E26: 39.25 | G26: AVG CAST WEIGHT | H26: 155.93891 | I26: 156.0153 | K26: 736
B27: CCP - 2 :- No. OF CASTS | C27: 17 | D27: 250 | K27: 814
B28: CCP - 3 :- No. OF CASTS | C28: 15 | D28: 137 | E28: AVERAGE CASTS | K28: 496
B29: TOTAL CASTS | C29: 55 | D29: 628 | E29: 39.25 | F29: प्रतिशत पूर्ति | G29: ABP MAY-26 | H29: ACTUAL MAY-25 | I29: GROWTH OVER CPLY (%) | J29: ASKING RATE | K29: 2046
B30: CCM - 1 & 2 : [150X150X12] | C30: 6236.64 | D30: 76603.65 | E30: 76603.65 | F30: 70.859103 | G30: 108107 | H30: 175200 | I30: -56.276455 | J30: #DIV/0! | K30: 243492.23
B31: CCM-3 : [BB-2] | C31: 2340 | D31: 21373.958 | E31: 21373.958 | F31: 34.036591 | G31: 62797 | H31: 61439 | I31: 0 | J31: #DIV/0! | K31: 77710.238
B32: TOTAL CRUDE STEEL | C32: 8576.64 | D32: 97977.608 | E32: 97977.608 | F32: 57.329031 | G32: 170904 | H32: 236639 | I32: -58.596171 | J32: #DIV/0! | K32: 321202.47
B33: WRM ( 6 mm WRC ) | C33: 1338.65 | D33: 21527.45 | E33: 21527.45 | F33: 57.406533 | G33: 37500 | H33: 39362 | I33: -45.309054 | J33: #DIV/0! | K33: 63061.325
B34: BAR MILL ( 16 mm TMT) | C34: 2341.525 | D34: 33352.684 | E34: 33352.684 | F34: 46.975611 | G34: 71000 | H34: 76176 | I34: -56.216283 | J34: #DIV/0! | K34: 108023.39
B35: USM ( ISMC-250 ) | C35: 681.7 | D35: 10554.693 | E35: 10554.693 | F35: 17.73898 | G35: 59500 | H35: 57219 | I35: -81.553867 | J35: #DIV/0! | K35: 63052.983
B36: FINISHED STEEL | C36: 4361.875 | D36: 65434.827 | E36: 65434.827 | F36: 38.949302 | G36: 168000 | H36: 172757 | I36: -62.123198 | J36: #DIV/0! | K36: 234137.7
B37: CC BILLETS (150 X 150) | C37: 0 | D37: 19329 | E37: 19329 | F37: #DIV/0! | G37: 0 | H37: 52556 | I37: -63.222087 | J37: 19329 | K37: 57724
B38: CC BLOOMS | C38: 0 | D38: 3468 | E38: 3468 | F38: #DIV/0! | G38: 0 | H38: 3000 | I38: 15.6 | J38: 495.42857 | K38: 5080
B39: TOTAL SALEABLE STEEL | C39: 4361.875 | D39: 88231.827 | E39: 88231.827 | F39: 52.518945 | G39: 168000 | H39: 228313 | I39: -61.354883 | J39: #DIV/0! | K39: 296941.72
B40: प्रेषण | C40: तिथि पर | D40: तिथि तक | E40: मासिक दर | F40: प्रतिशत पूर्ति | G40: CMO PLAN MAY-26 | H40: ACTUAL MAY-25 | I40: GROWTH OVER CPLY (%) | J40: ASKING RATE | K40: ACTUAL YEARLY DESPATCH (2025-26)
B41: WR MILL | C41: 677.86 | D41: 29364.5 | E41: 29364.5 | F41: 97.881667 | G41: 30000 | H41: 39367 | I41: -25.408337 | J41: #DIV/0! | K41: 70440.83
B42: BAR MILL | C42: 787.08 | D42: 35191.93 | E42: 35191.93 | F42: 74.876447 | G42: 47000 | H42: 67348 | I42: -47.746139 | J42: #DIV/0! | K42: 113891.19
B43: USM | C43: 1612 | D43: 28875.27 | E43: 28875.27 | F43: 93.146032 | G43: 31000 | H43: 57716 | I43: -49.970078 | J43: #DIV/0! | K43: 79415.94
...

Sheet RAWMATERIAL & CONSTRAINTS
GX2: -55 | HD2: 0 | HJ2: -4
B3: Source | C3: Coal Blend | D3: Opening Stock 01.05.26 | E3: Received on Date | F3: Received To Date | G3: Consumption on Date | H3: Actual Closing Stock | I3: Tippling | J3: STOCK AVAILABILITY (DAYS) | K3: Source | L3: Coal Blend | M3: Opening Stock 01.05.26 | N3: Received on Date | O3: Received To Date | P3: Consumption on Date | Q3: Actual Closing Stock | T3: Tippling | U3: STOCK AVAILABILITY (DAYS)
C4: Old Plant | L4: New Plant
B5: AUS - HARD | C5: 40 | D5: 1300 | E5: 1800 | F5: 28972 | G5: 732.256 | H5: 5400 | I5: 30 | J5: 7.3744701 | K5: AUS - HARD | L5: 41 | M5: 9070 | N5: 0 | O5: 39067 | P5: 1397.9196 | Q5: 10080 | T5: 0 | U5: 7.2107151
B6: USA - HARD | C6: 8 | D6: 200 | E6: 0 | F6: 7412 | G6: 146.4512 | H6: 3800 | I6: 9 | J6: 25.94721 | K6: LVHR | L6: 0 | M6: 0 | N6: 0 | O6: 3803 | P6: 0 | Q6: 3800 | T6: 0 | U6: -
B7: TRIAL MLV HARD | C7: 8 | D7: 3300 | E7: 0 | F7: 4059 | G7: 146.4512 | H7: 2000 | I7: 0 | J7: 13.656426 | K7: MOZ-H/INDO-H/USA-H | L7: 7 | M7: 4950 | N7: 0 | O7: 3754 | P7: 238.6692 | Q7: 290 | T7: 0 | U7: 1.2150709
B8: TRIAL MABU-HARD | C8: 8 | D8: 1200 | E8: 0 | F8: 3726 | G8: 146.4512 | H8: 200 | I8: 0 | J8: 1.3656426 | K8: TRIAL MLV HARD | L8: 12 | M8: 2190 | N8: 0 | O8: 11355 | P8: 409.1472 | Q8: 180 | T8: 0 | U8: 0.43993946
B9: LVHR-HARD | C9: 0 | D9: 0 | E9: 0 | F9: 3836 | G9: 146.4512 | H9: 3700 | I9: 0 | J9: 25.264388 | K9: TRIAL MABU-H | L9: 10 | M9: 1110 | N9: 0 | O9: 12014 | P9: 340.956 | Q9: 3310 | T9: 0 | U9: 9.7079975
B10: ICC Hard | C10: 64 | D10: 6000 | E10: 1800 | F10: 48005 | G10: 1318.0608 | H10: 15100 | I10: 39 | J10: 11.456224 | K10: ICC Hard | L10: 70 | M10: 17320 | N10: 0 | O10: 69993 | P10: 2386.692 | Q10: 17660 | T10: 0 | U10: 7.3993628
B11: AUS- SOFT | C11: 17 | D11: 1600 | E11: 5280 | F11: 12949 | G11: 311.2088 | H11: 7600 | I11: 49 | J11: 24.420903 | K11: AUS- SOFT | L11: 18 | M11: 2720 | N11: 0 | O11: 11996 | P11: 613.7208 | Q11: 4300 | T11: 0 | U11: 7.0064433
B12: USA - SOFT | C12: 0 | D12: 0 | E12: 0 | F12: 0 | G12: 0 | H12: 0 | I12: 0 | J12: - | K12: KESTREL - SOFT | L12: 0 | M12: 0 | N12: 0 | O12: 0 | P12: 0 | Q12: 0 | T12: 0 | U12: -
B13: KESTREL - SOFT | C13: 0 | D13: 0 | E13: 0 | F13: 0 | G13: 0 | H13: 0 | I13: 0 | J13: - | K13: USA-SOFT | L13: 0 | M13: 0 | N13: 0 | O13: 0 | P13: 0 | Q13: 0 | T13: 0 | U13: -
B14: RUS-SOFT | C14: 8 | D14: 6300 | E14: 0 | F14: 0 | G14: 0 | H14: 1400 | I14: 0 | J14: - | K14: RUS-SOFT | L14: 7 | M14: 1430 | N14: 0 | O14: 11512 | P14: 238.6692 | Q14: 3890 | T14: 0 | U14: 16.29871
B15: ICC-Soft | C15: 25 | D15: 7900 | E15: 5280 | F15: 12949 | G15: 311.2088 | H15: 9000 | I15: 49 | J15: 28.919491 | K15: ICC Soft | L15: 25 | M15: 4150 | N15: 0 | O15: 23508 | P15: 852.39 | Q15: 8190 | T15: 0 | U15: 9.6082779
B16: BELHATAND | C16: 0 | D16: 0 | E16: 0 | F16: 0 | G16: 0 | H16: 0 | I16: 0 | J16: - | K16: MUNIDIH | L16: 0 | M16: 0 | N16: 0 | O16: 0 | P16: 0 | Q16: 0 | T16: 0 | U16: -
B17: JAMADOBA | C17: 11 | D17: 3200 | E17: 0 | F17: 3886 | G17: 201.3704 | H17: 1100 | I17: 0 | J17: 5.4625705 | K17: JAMADOBA | L17: 5 | M17: 350 | N17: 0 | O17: 7491 | P17: 170.478 | Q17: 3080 | T17: 0 | U17: 18.066847
B18: Total PCC | C18: 11 | D18: 3200 | E18: 0 | F18: 3886 | G18: 201.3704 | H18: 1100 | I18: 0 | J18: 5.4625705 | K18: Total PCC | L18: 5 | M18: 350 | N18: 0 | O18: 7491 | P18: 170.478 | Q18: 3080 | T18: 0 | U18: 18.066847
B19: Grand Total | C19: 100 | D19: 17100 | E19: 7080 | F19: 64840 | G19: 1830.64 | H19: 25200 | I19: 88 | J19: 13.765678 | K19: Grand Total | L19: 100 | M19: 21820 | N19: 0 | O19: 100992 | P19: 3409.56 | Q19: 28930 | T19: 0 | U19: 8.4849658
B21: RAWMATERIALS | D21: Opening Stock 01.05.26 | E21: Received on Date | F21: Received To Date | G21: Consumption on Date | H21: Actual Closing Stock | I21: Tippling | J21: on Hand | K21: STOCK AVAILABILITY (DAYS) | L21: RAWMATERIALS | N21: Opening Stock 01.05.26 | O21: Received on Date | P21: Received To Date | Q21: Consumption on Date | S21: Closing Stock | T21: Tippling | U21: on Hand | V21: STOCK AVAILABILITY (DAYS)
B22: IRON ORE LUMPS | D22: 54581 | E22: 2160 | F22: 46810 | G22: 2325.4974 | H22: 63369 | I22: 36 | J22: 0 | K22: 31.6845 | L22: CDI | N22: 10250 | O22: 0 | P22: 11354 | Q22: 1215 | S22: 9800 | T22: 0 | U22: 0 | V22: 8.9090909
B23: IRON ORE FINES | D23: 8667 | E23: 12300 | F23: 245012 | G23: 9203.1754 | H23: 120627 | I23: 243 | J23: 0 | K23: 12.0627 | L23: BOILERCOAL | N23: 300 | O23: 0 | P23: 0 | Q23: 0 | S23: 300 | T23: 0 | U23: 0 | V23: - | DO23: 184
B24: LIMESTONE SMS Grade | D24: 2364 | E24: 0 | F24: 32653 | G24: 2284.1412 | H24: 5481 | I24: 0 | J24: 0 | K24: 2.8847368 | L24: QUARTZITE + BHQ | N24: 2549 | O24: 0 | P24: 0 | Q24: 0 | S24: 1750 | T24: 0 | U24: 0 | V24: 14
B25: DOLOMITE SP Grade | D25: 5512 | E25: 0 | F25: 17449 | G25: 784.39111 | H25: 4230 | I25: 0 | J25: 0 | K25: 5.2875 | L25: LIMESTONE SP Grade/LDCP RETURN | N25: 6896 | O25: 0 | P25: 0 | Q25: 0 | S25: 6005 | T25: 0 | U25: 0 | V25: -
B26: DOLOMITE SMS Grade | D26: 10674 | E26: 0 | F26: 11911 | G26: 644.90864 | H26: 19181 | I26: 0 | J26: 0 | K26: 34.874545 | L26: DOLOMITE FINES | N26: 0 | O26: 0 | P26: 0 | Q26: 0 | S26: 0 | T26: 0 | U26: 0 | V26: -
S27: Incoming Other Rawmaterial Status
B28: BF-5 को भेजा गया कच्चा माल | H28: बेस मिक्स प्लांट को भेजा गया कच्चा माल | P28: Base Mix Stock | S28: Item | T28: On Date | U28: To Date | V28: Closing Stock
C29: A | D29: B | E29: C | F29: TOTAL | G29: TO DATE | K29: A | L29: B | M29: C | N29: TOTAL | O29: TO DATE | P29: Location | Q29: Tonnes | S29: JHAMA COAL | T29: 0 | U29: 0 | V29: 0
B30: BF COKE | C30: 1588.55 | D30: 1593.75 | E30: 1472.55 | F30: 4654.85 | G30: 64324.34 | H30: IRONORE FINES | K30: 2850 | L30: 4120 | M30: 3734 | N30: 10704 | O30: 143286 | P30: BED | Q30: 55105 | S30: BF Coke | T30: 0 | U30: 13839.9 | V30: 73850.448
B31: BF SINTER | C31: 4020 | D31: 3631 | E31: 3869 | F31: 11520 | G31: 156282 | H31: LIMESTONE | K31: 288 | L31: 130 | M31: 126 | N31: 544 | O31: 9855 | P31: SP M/C-1 | Q31: 4800 | S31: Coke Breeze | T31: 0 | U31: 0 | V31: 6585
B32: IRON ORE LUMPS | C32: 841 | D32: 1014 | E32: 771 | F32: 2626 | G32: 30331 | H32: DOLOMITE | K32: 460 | L32: 540 | M32: 544 | N32: 1544 | O32: 22286 | P32: SP M/C-2 | Q32: 4100 | S32: Pellet | T32: 0 | U32: 77825 | V32: 49532
B33: QUARTZITE + BHQ | C33: 0 | D33: 0 | E33: 0 | F33: 0 | G33: 1350 | H33: COKE FINES RECEIVED FROM BF-5 | K33: 182 | L33: 140 | M33: 160 | N33: 482 | O33: 8231 | S33: ROLLING HOURS ( HH:MM )
B34: LD SLAG | C34: 0 | D34: 0 | E34: 0 | F34: 0 | G34: 461 | H34: BASE MIX PREPARATION | K34: 2689 | L34: 6656 | M34: 5105 | N34: 14450 | O34: 193476 | P34: Tentative | Q34: Lump | S34: WRM | T34: 0.85416667
B35: Ground Coke sent to BF-5 | C35: 379 | D35: 434 | E35: 263 | F35: 1076 | G35: 9553 | H35: BASE MIX SENT TO SINTER PLANT | K35: 4482 | L35: 5354 | M35: 4100 | N35: 13936 | O35: 175747 | P35: 11.608182 | Q35: 0.34313221 | S35: BAR MILL | T35: 0.8125
B36: PELLET CONSUMPTION | F36: 2714 | G36: 32304 | S36: USM | T36: 0.56944444
B37: BF COKE SENT TO JORABURI | F37: 0 | G37: 42558 | L37: संयंत्र (नये) में प्राप्त रेक विवरण
B38: संयंत्र (पुराना) में प्राप्त तथा बैक लोडिंग रेक विवरण | L38: S.NO | M38: SOURCE | O38: RECEIVED TIME | Q38: OUT TIME | S38: FREE TIME | T38: Σ HRS | U38: UNLOADING (WGNS/HOUR)
A39: : | B39: S.NO | C39: SOURCE | E39: RECEIVED TIME | F39: OUT TIME | G39: FREE TIME | H39: Σ HRS | I39: UNLOADING (WGNS/HOUR) | L39: 1) | M39: 58 N BOLANI (MIXED) | O39: 04:50 H (31.05.26) | Q39: 09:50 H (31.05.26) | S39: 5 H | T39: ∑05°00' | U39: 12
A40: ) | B40: 1) | C40: 59 N USA (H) | E40: 19:35 H (30.05.26) | F40: 09:35 H (31.05.26) | G40: 12 H | H40: ∑14°00' | I40: 4.2142857 | L40: 2) | M40: 58 S GUA (IOF) | O40: 09:25 H (31.05.26) | Q40: 11:25 H (31.05.26) | S40: 2 H | T40: ∑02°00' | U40: 29
B41: 2) | C41: 59 N (AUS-H + AUS-S) | E41: 09:30 H (31.05.26) | F41: 21:30 H (31.05.26) | G41: 12 H | H41: ∑12°00' | I41: 4.9166667 | L41: 3) | M41: 57 S GUA (IOF) | O41: 14:35 H (31.05.26) | Q41: 16:35 H (31.05.26) | S41: 5 H | T41: ∑02°00' | U41: 28.5
B42: 3) | C42: 59 N AUS-S | E42: 21:30 H (31.05.26) | F42: 39 N PENDING | G42: 12 H | H42: AWAITING | L42: 4) | M42: 57 N BOLANI (MIXED) | O42: 15:35 H (31.05.26) | Q42: 23:55 H (31.05.26) | S42: 5 H | T42: ∑08°00' | U42: 7.125
...

Sheet ECR DELHI
A2: Parameter Name | B2: On Date | C2: Cumulative | D2: Remarks
A3: Ov.Pushing (EQ nos.) | B3: =+DAILYREPORT1!C11 -> 279.566 | C3: =+DAILYREPORT1!D11 -> 8335.936
A4: Sinter | B4: =+DAILYREPORT1!$C$14 -> 11940 | C4: =+DAILYREPORT1!$D$14 -> 154584
A5: HOT METAL | B5: =+DAILYREPORT1!$C$16 -> 8804.7 | C5: =+DAILYREPORT1!$D$16 -> 110808.6
A6: PI | B6: =+DAILYREPORT1!$C$18 -> 0 | C6: =+DAILYREPORT1!$D$18 -> 2442.6
A7: Heats | B7: =+DAILYREPORT1!$C$25 -> 55 | C7: =+DAILYREPORT1!$D$25 -> 628
A8: Casts | B8: =+DAILYREPORT1!$C$29 -> 55 | C8: =+DAILYREPORT1!$D$29 -> 628
A9: CRUDE STEEL | B9: =+DAILYREPORT1!$C$32 -> 8576.64 | C9: =+DAILYREPORT1!$D$32 -> 97977.608
A10: WRM | B10: =+DAILYREPORT1!$C$33 -> 1338.65 | C10: =+DAILYREPORT1!$D$33 -> 21527.45 | F10: Cummulative delay of 3 hrs 30 mins for stand pass change & TMB#1 motor coupling allignment jobs.
A11: Bar Mill | B11: =+DAILYREPORT1!$C$34 -> 2341.525 | C11: =+DAILYREPORT1!$D$34 -> 33352.684
A12: USM | B12: =+DAILYREPORT1!$C$35 -> 681.7 | C12: =+DAILYREPORT1!$D$35 -> 10554.693
A13: SEMIS | B13: =+DAILYREPORT1!$C$37+DAILYREPORT1!$C$38 -> 0 | C13: =+DAILYREPORT1!D37+DAILYREPORT1!D38 -> 22797
A14: Finished Steel | B14: =+DAILYREPORT1!C36 -> 4361.875 | C14: =+DAILYREPORT1!D36 -> 65434.827
A15: SS- PROD. | B15: =+DAILYREPORT1!C39 -> 4361.875 | C15: =+DAILYREPORT1!D39 -> 88231.827
A16: SS- DESP | B16: =+DAILYREPORT1!C46 -> 3076.94 | C16: =+DAILYREPORT1!D46 -> 119345
A17: pcc receipt on date | B17: =+'RAWMATERIAL & CONSTRAINTS'!E18+'RAWMATERIAL & CONSTRAINTS'!N18 -> 0 | C17: =+'RAWMATERIAL & CONSTRAINTS'!F18+'RAWMATERIAL & CONSTRAINTS'!O18 -> 11377
A18: total indegenous coal receipt on date | B18: =+B17 -> 0 | C18: =+C17 -> 11377
A19: total indegenous coal stock | B19: {=+'RAWMATERIAL & CONSTRAINTS'!H18+'RAWMATERIAL & CONSTRAINTS'!Q18:S18} -> 4180 | C19: 1100 | D19: 1100
A20: Imported (AH) receipt | B20: =+'RAWMATERIAL & CONSTRAINTS'!E5+'RAWMATERIAL & CONSTRAINTS'!N5 -> 1800 | C20: =+'RAWMATERIAL & CONSTRAINTS'!F5+'RAWMATERIAL & CONSTRAINTS'!O5 -> 68039
A21: Imported (AH) stock | B21: {='RAWMATERIAL & CONSTRAINTS'!H5+'RAWMATERIAL & CONSTRAINTS'!Q5:S5} -> 15480 | C21: 5400 | D21: 5400
A22: Imported (LVHR) receipt | B22: =+'RAWMATERIAL & CONSTRAINTS'!E9+'RAWMATERIAL & CONSTRAINTS'!N6 -> 0 | C22: =+'RAWMATERIAL & CONSTRAINTS'!F9+'RAWMATERIAL & CONSTRAINTS'!O6 -> 7639
A23: Imported (LVHR) stock | B23: {=+'RAWMATERIAL & CONSTRAINTS'!H9+'RAWMATERIAL & CONSTRAINTS'!Q6:S6} -> 7500 | C23: 3700 | D23: 3700
A24: Imported (USH) receipt | B24: =+'RAWMATERIAL & CONSTRAINTS'!E6+'RAWMATERIAL & CONSTRAINTS'!N7 -> 0
A25: Imported (USH + INDO) stock | B25: {=+'RAWMATERIAL & CONSTRAINTS'!Q7:S7+'RAWMATERIAL & CONSTRAINTS'!H6} -> 4090 | C25: 3800 | D25: 3800
A26: Imported (MZH) receipt | B26: 0
A27: Imported (MZH) stock | B27: 0
A28: Imp. (Others) receipt | B28: 0
A29: Imp. (Others) stock | B29: {=+'RAWMATERIAL & CONSTRAINTS'!H8+'RAWMATERIAL & CONSTRAINTS'!Q9:S9+'RAWMATERIAL & CONSTRAINTS'!Q8:S8+'RAWMATERIAL & CONSTRAINTS'!H7} -> 5690 | C29: 2200 | D29: 2200
A30: Imported (Soft) receipt | B30: =+'RAWMATERIAL & CONSTRAINTS'!E15+'RAWMATERIAL & CONSTRAINTS'!N15 -> 5280 | C30: =+'RAWMATERIAL & CONSTRAINTS'!F15+'RAWMATERIAL & CONSTRAINTS'!O15 -> 36457
A31: Imported (Soft) stock | B31: {=+'RAWMATERIAL & CONSTRAINTS'!H15+'RAWMATERIAL & CONSTRAINTS'!Q15:S15} -> 17190 | C31: 9000 | D31: 9000
A32: Total Coking Coal receipt | B32: =+'RAWMATERIAL & CONSTRAINTS'!E19+'RAWMATERIAL & CONSTRAINTS'!N19 -> 7080 | C32: =+'RAWMATERIAL & CONSTRAINTS'!F19+'RAWMATERIAL & CONSTRAINTS'!O19 -> 165832
A33: Total Coking Coal stock | B33: {=+'RAWMATERIAL & CONSTRAINTS'!H19+'RAWMATERIAL & CONSTRAINTS'!Q19:S19} -> 54130 | C33: 25200 | D33: 25200
A34: CDI receipt | B34: =+'RAWMATERIAL & CONSTRAINTS'!O22 -> 0 | C34: =+'RAWMATERIAL & CONSTRAINTS'!P22 -> 11354
A35: CDI stock | B35: =+'RAWMATERIAL & CONSTRAINTS'!S22 -> 9800
A36: Pellet receipt | B36: =+'RAWMATERIAL & CONSTRAINTS'!T32 -> 0 | C36: =+'RAWMATERIAL & CONSTRAINTS'!U32 -> 77825
A37: Pellet stock | B37: =+'RAWMATERIAL & CONSTRAINTS'!V32 -> 49532
A38: Iron Ore Lump receipt | B38: =+'RAWMATERIAL & CONSTRAINTS'!E22 -> 2160 | C38: =+'RAWMATERIAL & CONSTRAINTS'!F22 -> 46810
A39: Iron Ore Lump stock | B39: =+'RAWMATERIAL & CONSTRAINTS'!H22 -> 63369
A40: Iron Ore fines receipt | B40: =+'RAWMATERIAL & CONSTRAINTS'!E23 -> 12300 | C40: =+'RAWMATERIAL & CONSTRAINTS'!F23 -> 245012
A41: Iron Ore fines stock | B41: =+'RAWMATERIAL & CONSTRAINTS'!H23 -> 120627
...

Sheet DIC REPORT-1
B2: DAILY PERFORMANCE SUMMARY
B3: =TODAY()-1 -> 46173 | K3: (In Tons, unless otherwise mentioned)
B4: PRODUCTION SHOP/ITEMS | D4: ISP | K4: DSP
A5: 31 | C5: ASKING RATE W.R.T MP | D5: ON DATE | E5: TILL DATE | F5: M. RATE | G5: APP | H5: MP | I5: %APP | J5: %MP | K5: ON DATE | L5: TILL DATE | M5: M. RATE | N5: APP | O5: MP | P5: %APP | Q5: %MP
A6: =#REF! -> #REF! | B6: CHP TIPPLING (NOS) | C6: =+(H6-E6)/$A$7 -> #REF! | D6: =+RAWMATERIALS!G20+RAWMATERIALS!G33+RAWMATERIALS!G34 -> 88 | E6: =+#REF! -> #REF! | F6: =+(E6/$A$6)*$A$5 -> #REF! | G6: 2974 | H6: 2922 | I6: =+(F6/G6)*100 -> #REF! | J6: =+(F6/H6)*100 -> #REF!
A7: =+A5-A6 -> #REF! | B7: COB#10 PUSHING (NOS) | C7: =+#REF! -> #REF! | D7: =+#REF! -> #REF! | E7: =+#REF! -> #REF! | F7: =+#REF! -> #REF! | G7: 98 | H7: 96.6 | I7: =+(F7/G7)*100 -> #REF! | J7: =+(F7/H7)*100 -> #REF!
B8: COB#11 PUSHING (NOS) | C8: =+#REF! -> #REF! | D8: =+#REF! -> #REF! | E8: =+#REF! -> #REF! | F8: =+#REF! -> #REF! | G8: 96 | H8: 94.2 | I8: =+(F8/G8)*100 -> #REF! | J8: =+(F8/H8)*100 -> #REF!
A9: 31 | B9: EQUIVALENT OVEN PUSHING (NOS.) | C9: =+#REF! -> #REF! | D9: =+D7+D8*(31.55/17.2) -> #REF! | E9: =+#REF! -> #REF! | F9: =+F7+F8*(31.55/17.2) -> #REF! | G9: =+G7+G8*(31.55/17.2) -> 274.09302 | H9: =+H7+H8*(31.55/17.2) -> 269.39128 | I9: =+(F9/G9)*100 -> #REF! | J9: =+(F9/H9)*100 -> #REF! | S9: =1206*356 -> 429336
A10: =+A6 -> #REF! | B10: RMHP TIPPLING (NOS) | C10: =+(H10-E10)/$A$7 -> #REF! | D10: =+RAWMATERIALS!F45+RAWMATERIALS!F46+RAWMATERIALS!F48+RAWMATERIALS!F49+RAWMATERIALS!F50+RAWMATERIALS!F51+RAWMATERIALS!F52+RAWMATERIALS!F53 -> 279 | E10: =+#REF! -> #REF! | F10: =+(E10/$A$6)*$A$5 -> #REF! | G10: 5716 | H10: 3973.6856 | I10: =+(F10/G10)*100 -> #REF! | J10: =+(F10/H10)*100 -> #REF!
A11: =+A9-A10 -> #REF! | B11: BLEND MIX PRODUCTION | C11: =+(H11-E11)/$A$14 -> #REF! | D11: =+'RAWMATERIAL & CONSTRAINTS'!N34 -> 14450 | E11: =+'RAWMATERIAL & CONSTRAINTS'!O34 -> 193476 | F11: =+(E11/A13)*A12 -> #REF! | G11: 311702 | H11: 216691 | I11: =+(F11/G11)*100 -> #REF! | J11: =+(F11/H11)*100 -> #REF!
A12: 31 | B12: BLEND MIX DESPATCH | C12: =+(H12-E12)/$A$14 -> #REF! | D12: =+'RAWMATERIAL & CONSTRAINTS'!N35 -> 13936 | E12: =+'RAWMATERIAL & CONSTRAINTS'!O35 -> 175747 | F12: =+(E12/$A$13)*$A$12 -> #REF! | G12: 311702 | H12: 216691 | I12: =+(F12/G12)*100 -> #REF! | J12: =+(F12/H12)*100 -> #REF!
A13: =A6 -> #REF! | B13: TOTAL SINTER | C13: =+#REF! -> #REF! | D13: =+D14+D15 -> #REF! | E13: =+E14+E15 -> #REF! | F13: =+F14+F15 -> #REF! | G13: =+G14+G15 -> 262229 | H13: =+H14+H15 -> 182298 | I13: =+(F13/G13)*100 -> #REF! | J13: =+(F13/H13)*100 -> #REF!
A14: =A12-A13 -> #REF! | B14: SINTER PLANT -1 | D14: =+#REF! -> #REF! | E14: =+#REF! -> #REF! | F14: =#REF! -> #REF! | G14: 131114.5 | H14: 91149 | I14: =+(F14/G14)*100 -> #REF! | J14: =+(F14/H14)*100 -> #REF! | S14: =+G32-H32 -> 60000
B15: SINTER PLANT -2 | D15: =+#REF! -> #REF! | E15: =+#REF! -> #REF! | F15: =#REF! -> #REF! | G15: 131114.5 | H15: 91149 | I15: =+(F15/G15)*100 -> #REF! | J15: =+(F15/H15)*100 -> #REF!
A16: 31 | B16: HOT METAL | C16: =+#REF! -> #REF! | D16: =+#REF! -> #REF! | E16: =+#REF! -> #REF! | F16: =+#REF! -> #REF! | G16: 187000 | H16: 130000 | I16: =+(F16/G16)*100 -> #REF! | J16: =+(F16/H16)*100 -> #REF!
A17: =A6 -> #REF! | B17: HOT METAL TO BOF | D17: =+#REF! -> #REF! | E17: =+#REF! -> #REF! | F17: =#REF! -> #REF! | G17: =G16-G19-G20 -> 181500 | H17: =H16-H19-H20 -> 120450 | S17: =+G23-221000 -> -50096
A18: =A16-A17 -> #REF! | B18: HOT METAL TO ASP
B19: PIG IRON | D19: =+DAILYREPORT1!C19 -> 0 | E19: =+DAILYREPORT1!D19 -> 2039.571 | G19: 5500 | H19: 9550 | I19: =+(F19/G19)*100 -> 0 | J19: =+(F19/H19)*100 -> 0
B20: DRY PIT/SAND PIT | D20: =+#REF! -> #REF! | E20: =+#REF! -> #REF! | G20: 0 | H20: 0 | I20: =+(F20/G20)*100 -> #DIV/0! | J20: =+(F20/H20)*100 -> #DIV/0!
B21: CRUDE STEEL | C21: =+#REF! -> #REF! | D21: =+D24+D25 -> #REF! | E21: =+E24+E25 -> #REF! | F21: =+F24+F25 -> #REF! | G21: =G23 -> 170904 | H21: =H23 -> 113418 | I21: =+(F21/G21)*100 -> #REF! | J21: =+(F21/H21)*100 -> #REF!
B22: BOTTOM-POURING INGOTS | S22: 220338.98
A23: ` | B23: TOTAL CASTER | C23: =+C21 -> #REF! | D23: =+D24+D25 -> #REF! | E23: =+E24+E25 -> #REF! | F23: =+F24+F25 -> #REF! | G23: =+G24+G25 -> 170904 | H23: =+H24+H25 -> 113418 | I23: =+(F23/G23)*100 -> #REF! | J23: =+(F23/H23)*100 -> #REF! | S23: =+S22-151000 -> 69338.983
B24: BILLET | C24: =+#REF! -> #REF! | D24: =+#REF! -> #REF! | E24: =+#REF! -> #REF! | F24: =#REF! -> #REF! | G24: 108107 | H24: 80700 | I24: =+(F24/G24)*100 -> #REF! | J24: =+(F24/H24)*100 -> #REF!
B25: BLOOM/BEAM BLANK | C25: =+#REF! -> #REF! | D25: =+#REF! -> #REF! | E25: =+#REF! -> #REF! | F25: =#REF! -> #REF! | G25: 62797 | H25: 32718 | I25: =+(F25/G25)*100 -> #REF! | J25: =+(F25/H25)*100 -> #REF!
B26: BRC BLOOM | S26: 213252.95
B27: BRC ROUND | S27: =+S26-151000 -> 62252.953
B28: WRM / SECTION MILL | C28: =+#REF! -> #REF! | D28: =+#REF! -> #REF! | E28: =+#REF! -> #REF! | F28: =#REF! -> #REF! | G28: 37500 | H28: 30000 | I28: =+(F28/G28)*100 -> #REF! | J28: =+(F28/H28)*100 -> #REF!
B29: BAR MILL / MERCHANT MILL | C29: =+#REF! -> #REF! | D29: =+#REF! -> #REF! | E29: =+#REF! -> #REF! | F29: =#REF! -> #REF! | G29: 71000 | H29: 47000 | I29: =+(F29/G29)*100 -> #REF! | J29: =+(F29/H29)*100 -> #REF!
B30: USM / MSM | C30: =+#REF! -> #REF! | D30: =+#REF! -> #REF! | E30: =+#REF! -> #REF! | F30: =#REF! -> #REF! | G30: 59500 | H30: 31000 | I30: =+(F30/G30)*100 -> #REF! | J30: =+(F30/H30)*100 -> #REF! | S30: =+H32-G32 -> -60000
B31: WHEEL & AXLE
B32: SALEABLE STEEL | C32: =+#REF! -> #REF! | D32: =+D33+D34 -> #REF! | E32: =+E33+E34 -> #REF! | F32: =+F33+F34 -> #REF! | G32: =+G33+G34 -> 168000 | H32: =+H33+H34 -> 108000 | I32: =+(F32/G32)*100 -> #REF! | J32: =+(F32/H32)*100 -> #REF!
B33: FINISHED STEEL | C33: =+C28+C29+C30 -> #REF! | D33: =+D28+D29+D30 -> #REF! | E33: =+E28+E29+E30 -> #REF! | F33: =+F28+F29+F30 -> #REF! | G33: =+G28+G29+G30 -> 168000 | H33: =+H28+H29+H30 -> 108000 | I33: =+(F33/G33)*100 -> #REF! | J33: =+(F33/H33)*100 -> #REF! | S33: =339-250 -> 89
B34: SEMI FINISHED STEEL | C34: =+C32-C33 -> #REF! | D34: =+#REF! -> #REF! | E34: =+#REF! -> #REF! | F34: =+#REF! -> #REF! | G34: 0 | H34: 0 | I34: =+(F34/G34)*100 -> #REF! | J34: =+(F34/H34)*100 -> #REF!
B35: DESPATCH ITEMS | C35: ISP | K35: DSP
C36: ASKING RATE W.R.T CMO PLAN | D36: ON DATE | E36: TILL DATE | F36: M. RATE | H36: CMO PLAN | J36: % FF | K36: ON DATE | L36: TILL DATE | M36: M. RATE | O36: CMO PLAN | Q36: % FF
B37: WRM / SECTION MILL | C37: =+(H37-E37)/$A$7 -> #REF! | D37: =+#REF! -> #REF! | E37: =+#REF! -> #REF! | F37: =+#REF! -> #REF! | H37: 30000 | J37: =+(F37/H37)*100 -> #REF!
B38: BAR MILL / MERCHANT MILL | C38: =+(H38-E38)/$A$7 -> #REF! | D38: =+#REF! -> #REF! | E38: =+#REF! -> #REF! | F38: =+#REF! -> #REF! | H38: 47000 | J38: =+(F38/H38)*100 -> #REF!
B39: USM / MSM | C39: =+(H39-E39)/$A$7 -> #REF! | D39: =+#REF! -> #REF! | E39: =+#REF! -> #REF! | F39: =+#REF! -> #REF! | H39: 31000 | J39: =+(F39/H39)*100 -> #REF!
B40: WHEEL & AXLE
B41: FINISHED STEEL | C41: =+C37+C38+C39 -> #REF! | D41: =SUM(D37:D40) -> #REF! | E41: =+E37+E38+E39 -> #REF! | F41: =+F37+F38+F39 -> #REF! | H41: =++H37+H38+H39 -> 108000 | J41: =+(F41/H41)*100 -> #REF!
...

Sheet DIC REPORT-2
B2: DAILY PERFORMANCE SUMMARY
B3: =+'DIC REPORT-1'!B3 -> 46173
B4: TECHNO ECONOMIC PARAMETERS | C4: UNIT | D4: ISP | I4: DSP
D5: APP | E5: ON DATE | F5: TILL DATE | G5: PREV MONTH | I5: APP | J5: ON DATE | K5: TILL DATE | L5: PREV MONTH
B6: COKE OVEN TECHNO PARAMETERS
B7: BF Coke yield | C7: % | D7: 69.5 | E7: =+#REF! -> #REF! | F7: =+#REF! -> #REF! | G7: 69.5
B8: Imported Coal in Blend- COB-10 | C8: % | D8: 89 | E8: =+#REF! -> #REF! | F8: =+#REF! -> #REF! | G8: 90.000035
B9: Imported Coal in Blend-COB-11 | C9: % | D9: 95 | E9: =+#REF! -> #REF! | F9: =+#REF! -> #REF! | G9: 95
B10: BLAST FURNACE TECHNO PARAMETERS
B11: BF Coke Rate | C11: Kg/THM | D11: 356 | E11: =+#REF! -> #REF! | F11: =+#REF! -> #REF! | G11: 370.29487
B12: Nut Coke Rate | C12: Kg/THM | D12: 29 | E12: =+#REF! -> #REF! | F12: =+#REF! -> #REF! | G12: 31.739807
B13: CDI Rate | C13: Kg/THM | D13: 140 | E13: =+#REF! -> #REF! | F13: =+#REF! -> #REF! | G13: 125.22347
B14: Fuel Rate | C14: Kg/THM | D14: 525 | E14: =SUM(E11:E13) -> #REF! | F14: =SUM(F11:F13) -> #REF! | G14: 527.25815
B15: Sinter in Burden | C15: % | D15: 70 | E15: =+#REF! -> #REF! | F15: =+#REF! -> #REF! | G15: 71.411524
B16: Pellet in Burden | C16: % | D16: 17 | E16: =DAILYREPORT1!$I$72 -> 20 | F16: =DAILYREPORT1!$J$72 -> 17.949839 | G16: 15.252492
B17: BF Productivity | C17: T/M³/Day | D17: 2.394 | E17: =+#REF! -> #REF! | F17: =+#REF! -> #REF! | G17: 2.2569069
B18: BF Slag Rate | C18: Kg/THM | D18: 357 | E18: =+#REF! -> #REF! | F18: =+#REF! -> #REF! | G18: 326.93618
B19: Si in Hot Metal | C19: % | D19: 0.53 | E19: =+#REF! -> #REF! | F19: =+#REF! -> #REF! | G19: 0.65666268
B20: S in Hot Metal | C20: % | D20: 0.05 | E20: =D105 -> 0.048 | F20: =E105 -> 0.0519 | G20: 0.0519
B21: Hot Blast Temperature | C21: ⁰C | D21: 1200 | E21: =+#REF! -> #REF! | F21: =+#REF! -> #REF! | G21: 1148.142
B22: Avg. Hot Metal Temperature | C22: ⁰C | D22: 1500 | E22: =+#REF! -> #REF! | F22: =+#REF! -> #REF! | G22: 1513.2473
B23: ALUMINA IN SLAG (%) | C23: % | D23: 15 | E23: =DAILYREPORT1!E76 -> 605.89 | F23: =DAILYREPORT1!E78 -> 555.29 | G23: 18.572
B24: SMS TECHNO PARAMETERS
B25: TMI | C25: Kg/TCS | D25: 1096 | E25: =+E26+E27 -> #REF! | F25: =+F26+F27 -> #REF! | G25: 1096
B26: Gross Hot Metal Consumption | C26: Kg/TCS | D26: 1062 | E26: =+#REF! -> #REF! | F26: =+#REF! -> #REF! | G26: 1055.92
B27: Scrap Consumption | C27: Kg/TCS | D27: 34 | E27: =+#REF! -> #REF! | F27: =+#REF! -> #REF! | G27: 40.08
B28: Sp. Lime Consumption | C28: Kg/TCS | D28: 70 | E28: =+#REF! -> #REF! | F28: =+#REF! -> #REF! | G28: 68.29
B29: BOF Slag Rate | C29: Kg/TLS | D29: 124 | E29: =+#REF! -> #REF! | F29: =+#REF! -> #REF! | G29: 158.78
B30: Sp. Energy Consumption | C30: Gcal/TCS | D30: 6.15 | E30: =+#REF! -> #REF! | F30: =+#REF! -> #REF! | G30: 6.027
B31: Specific Power consumption | C31: KWH/TSS | D31: 516 | E31: =+DAILYREPORT1!I86 -> 798.97 | F31: =+DAILYREPORT1!J86 -> 801.24 | G31: 497.37
B33: ON DATE QUALITY | C33: ISP | H33: DSP
B34: Coke | C34: CSR | D34: CRI | E34: M10 | F34: M40 | G34: % Moist/Ash | H34: CSR | I34: CRI | J34: M10 | K34: M40 | L34: % Moisture
B35: Mixed Coke | C35: =C108 -> 65.49 | D35: =D108 -> 21.93 | E35: =E108 -> 6.29 | F35: =F108 -> 87.52 | G35: =G108 -> 1.9
B36: Ore | C36: Fe | D36: SiO2 | E36: Al2O3 | F36: OS | G36: US | H36: % Fe | I36: % Si | J36: %Al | K36: OS | L36: US
B37: Lump | C37: =+DAILYREPORT1!E89 -> 62.84 | D37: =+DAILYREPORT1!C89 -> 3 | E37: =+DAILYREPORT1!D89 -> 2.31 | F37: =D111 -> 22.266305 | G37: =E111 -> 14.589996
B38: Fines | C38: =+DAILYREPORT1!E88 -> 62.13 | D38: =+DAILYREPORT1!C88 -> 3.69 | E38: =+DAILYREPORT1!D88 -> 2.75 | F38: =D112 -> 6.658051 | G38: =E112 -> 44.703752
B40: RAW MATERIAL DETAILS | C40: ISP | H40: DSP
C41: RECEIVED | E41: STOCK | G41: STOCK LEVEL (DAYS) | H41: RECEIVED | J41: STOCK | L41: STOCK LEVEL (DAYS)
C42: ON DATE | D42: TILL DATE | E42: 1ST DAY | F42: ON DATE | H42: ON DATE | I42: TILL DATE | J42: 1ST DAY | K42: ON DATE
B43: IRON ORE LUMPS | C43: =+'RAWMATERIAL & CONSTRAINTS'!E22 -> 2160 | D43: =+'RAWMATERIAL & CONSTRAINTS'!F22 -> 46810 | E43: =+'RAWMATERIAL & CONSTRAINTS'!D22 -> 54581 | F43: =+'RAWMATERIAL & CONSTRAINTS'!H22 -> 63369 | G43: =+'RAWMATERIAL & CONSTRAINTS'!K22 -> 31.6845
...

Sheet PROCESS FLOW
W3: SAIL - ISP PRODUCTION FLOW | AC3: =TODAY()-1 -> 46173
K6: COB-10 | W6: COB-11
F7: IRON ORE FINES | K7: =+DAILYREPORT1!C9 -> 98 | L7: =+#REF! -> #REF! | W7: =+DAILYREPORT1!C10 -> 99 | X7: =+#REF! -> #REF!
D9: FLUXES | F9: =+RAWMATERIALS!N36 -> 10704 | G9: =+RAWMATERIALS!O36 -> #REF! | H9: COKE FINES | P9: =+RAWMATERIALS!N47 -> 4654.85 | R9: =+RAWMATERIALS!O47 -> #REF!
D11: =+RAWMATERIALS!N37+RAWMATERIALS!N38 -> 2088 | E11: =+RAWMATERIALS!O37+RAWMATERIALS!O38 -> #REF! | H11: =+RAWMATERIALS!N39 -> 482 | I11: =+RAWMATERIALS!O39 -> #REF!
X13: STEEL MELTING SHOP
N14: LD SLAG
K15: IRON ORE LUMPS | N15: =+RAWMATERIALS!N51 -> 0 | O15: =+RAWMATERIALS!O51 -> #REF!
K16: =+RAWMATERIALS!N49 -> 2626 | L16: =+RAWMATERIALS!O49 -> #REF!
M17: QUARTZITE | S17: CDI | AI17: SALEABLE STEEL PRODUCTION | AM17: SALEABLE STEEL DESPATCH | AT17: CLOSING STOCK
I18: SINTER PLANT M/C-1 | M18: =+RAWMATERIALS!N50 -> 0 | N18: =+RAWMATERIALS!O50 -> #REF! | S18: =+RAWMATERIALS!F34 -> 1215 | T18: =+#REF! -> #REF! | AM18: ROAD | AO18: RAIL | AQ18: TOTAL
E19: BASE MIXPLANT | I19: =+DAILYREPORT1!C12 -> 5905 | J19: =+#REF! -> #REF! | X19: BOF-1 | Y19: =+DAILYREPORT1!C22 -> 23 | Z19: =+#REF! -> #REF! | AA19: CCM-1 | AB19: =+DAILYREPORT1!C26 -> 23 | AC19: =+#REF! -> #REF! | AI19: COILS | AJ19: =+DAILYREPORT1!C33 -> 1338.65 | AK19: =+#REF! -> #REF! | AM19: =+#REF!+#REF! -> #REF! | AN19: =+#REF!+#REF! -> #REF! | AO19: =+#REF! -> #REF! | AP19: =+#REF! -> #REF! | AQ19: =+#REF! -> #REF! | AR19: =+#REF! -> #REF! | AT19: =+#REF! -> #REF!
G20: =+RAWMATERIALS!N41 -> 13936 | H20: =+RAWMATERIALS!O41 -> #REF! | K20: TOTAL SINTER | S20: =+DAILYREPORT1!C16 -> 8804.7 | T20: =+#REF! -> #REF! | AB20: 150X150 BILLETS
K21: =+DAILYREPORT1!C14 -> 11940 | L21: =+#REF! -> #REF! | AC21: =+DAILYREPORT1!C30 -> 6236.64 | AD21: =+#REF! -> #REF!
E22: PREPARATION | AI22: BARS | AJ22: =+DAILYREPORT1!C34 -> 2341.525 | AK22: =+#REF! -> #REF! | AM22: =+#REF!+#REF! -> #REF! | AN22: =+#REF!+#REF! -> #REF! | AO22: =+#REF! -> #REF! | AP22: =+#REF! -> #REF! | AQ22: =+#REF! -> #REF! | AR22: =+#REF! -> #REF! | AT22: =+#REF! -> #REF!
E23: =+RAWMATERIALS!N40 -> 14450 | F23: =+RAWMATERIALS!O40 -> #REF! | I23: =+DAILYREPORT1!C13 -> 6035 | J23: =+#REF! -> #REF! | N23: =+RAWMATERIALS!N48 -> 11520 | O23: =+RAWMATERIALS!O48 -> #REF! | S23: =+DAILYREPORT1!C18 -> 0 | T23: =+#REF! -> #REF! | X23: BOF-2 | Y23: =+DAILYREPORT1!C23 -> 14 | Z23: =+#REF! -> #REF! | AA23: CCM-2 | AB23: =+DAILYREPORT1!C27 -> 17 | AC23: =+#REF! -> #REF!
I24: SINTER PLANT M/C-2 | AB24: 200X280 BLOOMS/BB-2/BB-3
AI25: STRUCTURALS
S26: =+DAILYREPORT1!C20 -> 0 | T26: =+#REF! -> #REF! | AC26: =+DAILYREPORT1!C31 -> 2340 | AD26: =+#REF! -> #REF! | AJ26: =+DAILYREPORT1!C35 -> 681.7 | AK26: =+#REF! -> #REF! | AM26: =+#REF!+#REF! -> #REF! | AN26: =+#REF!+#REF! -> #REF! | AO26: =+#REF! -> #REF! | AP26: =+#REF! -> #REF! | AQ26: =+#REF! -> #REF! | AR26: =+#REF! -> #REF! | AT26: =+#REF! -> #REF!
X28: BOF-3 | Y28: =+DAILYREPORT1!C24 -> 18 | Z28: =+#REF! -> #REF! | AA28: CCM-3 | AB28: =+DAILYREPORT1!C28 -> 15 | AC28: =+#REF! -> #REF! | AJ28: =+DAILYREPORT1!C37 -> 0 | AK28: =+DAILYREPORT1!D37 -> 19329 | AT28: =+#REF! -> #REF!
X29: TOTAL HEATS | Y29: =+DAILYREPORT1!C25 -> 55 | Z29: =+Z19+Z23+Z28 -> #REF! | AA29: TOTAL CASTS | AB29: =+DAILYREPORT1!C29 -> 55 | AC29: =+AC19+AC23+AC28 -> #REF! | AI29: SEMIS | AJ29: =+DAILYREPORT1!C38 -> 0 | AK29: =+DAILYREPORT1!D38 -> 3468 | AM29: =+#REF!+#REF! -> #REF! | AN29: =+#REF!+#REF! -> #REF! | AO29: =+#REF! -> #REF! | AP29: =+#REF! -> #REF! | AQ29: =+#REF! -> #REF! | AR29: =+#REF! -> #REF! | AT29: =+#REF! -> #REF!
F30: ON DATE | O30: BLAST FURNACE-5 | Z30: CRUDE STEEL | AC30: =+DAILYREPORT1!C32 -> 8576.64 | AD30: =+#REF! -> #REF!
F31: TO DATE | AG31: SALEBLE STEEL | AJ31: =+DAILYREPORT1!C39 -> 4361.875 | AK31: =+#REF! -> #REF! | AM31: =+#REF!+#REF! -> #REF! | AN31: =SUM(AN19:AN29) -> #REF! | AO31: =+#REF! -> #REF! | AP31: =SUM(AP19:AP29) -> #REF! | AQ31: =+#REF! -> #REF! | AR31: =SUM(AR19:AR29) -> #REF! | AT31: =+#REF! -> #REF!

Sheet SEMIS
F3: SAIL: Semis Stock ( In-process/Sale)- daily report
D5: 46173 | T5: Unit: 'T'
C6: Plant | D6: Blooms/Beam Blanks | G6: Billet | J6: Round | M6: Slab | P6: Ingot | S6: Pig Iron
D7: In process | E7: For sales (incl Non rollable assorted BB) | F7: *Total stock | G7: In process | H7: For sales | I7: *Total stock | J7: In process | K7: For sales | L7: Total stock | M7: In process | N7: For sales/IPT | O7: Total stock | P7: In process | Q7: For sales | R7: Total stock | S7: In process | T7: For sales | U7: Total stock
C8: BSP | F8: 0 | I8: 0 | L8: 0 | O8: 0 | R8: 0 | U8: 0
C9: DSP | F9: 0 | I9: 0 | L9: 0 | O9: 0 | R9: 0 | U9: 0
C10: RSP | F10: 0 | I10: 0 | L10: 0 | O10: 0 | R10: 0 | U10: 0
C11: BSL | F11: 0 | I11: 0 | L11: 0 | O11: 0 | R11: 0 | U11: 0
C12: ISP | D12: 46934.28 | E12: 1060.2 | F12: 48344.48 | G12: 33019.74 | H12: 13320.5 | I12: 49806.24 | T12: 2651.571 | U12: 2651.571
C13: SAIL | I13: includes F/C Discard,Bottom layer billets & DSP billets
I14: 3466
C15: Saleable Semis | E15: Finished Steel | I15: Saleable Steel | M15: ISP
C16: Movable | D16: Non-movable | E16: Movable | F16: On Hold | G16: Non-movable | I16: Movable | J16: Non-movable | M16: In-process | O16: Saleable
C17: 14380.7 | D17: 0 | E17: 17010.627 | F17: 246.5 | G17: 0 | I17: 31391.327 | J17: 0 | M17: Billets | N17: 33019.74 | O17: Billets | P17: 13320.5
M18: Blooms | N18: 3211.28 | O18: Blooms | P18: 670.2
M19: Beam Blank | N19: 43723 | O19: Non rollable assorted beam blank | P19: 390
N28: st (v)
N29: cr
